ERROR|06/Jan/2021 12:51:02|log|25177|140053634209536|Internal Server Error: /emoloyeeinfo/
Traceback (most recent call last):
  File "/home/mobilitysqr/.local/lib/python3.6/site-packages/django/core/handlers/exception.py", line 34, in inner
    response = get_response(request)
  File "/home/mobilitysqr/.local/lib/python3.6/site-packages/django/core/handlers/base.py", line 126, in _get_response
    response = self.process_exception_by_middleware(e, request)
  File "/home/mobilitysqr/.local/lib/python3.6/site-packages/django/core/handlers/base.py", line 124, in _get_response
    response = wrapped_callback(request, *callback_args, **callback_kwargs)
  File "/home/mobilitysqr/.local/lib/python3.6/site-packages/django/views/decorators/csrf.py", line 54, in wrapped_view
    return view_func(*args, **kwargs)
  File "/home/mobilitysqr/.local/lib/python3.6/site-packages/django/views/generic/base.py", line 68, in view
    return self.dispatch(request, *args, **kwargs)
  File "/home/mobilitysqr/.local/lib/python3.6/site-packages/rest_framework/views.py", line 495, in dispatch
    response = self.handle_exception(exc)
  File "/home/mobilitysqr/.local/lib/python3.6/site-packages/rest_framework/views.py", line 455, in handle_exception
    self.raise_uncaught_exception(exc)
  File "/home/mobilitysqr/.local/lib/python3.6/site-packages/rest_framework/views.py", line 492, in dispatch
    response = handler(request, *args, **kwargs)
  File "/var/www/html/mobilitysqr_staging/mobility_apps/employee/views.py", line 103, in post
    with open('emp_serializer.data[0].json') as json_data:
FileNotFoundError: [Errno 2] No such file or directory: 'emp_serializer.data[0].json'
ERROR|06/Jan/2021 12:51:02|basehttp|25177|140053634209536|"POST /emoloyeeinfo/ HTTP/1.1" 500 17377
ERROR|06/Jan/2021 12:52:46|log|25436|140491518629632|Internal Server Error: /emoloyeeinfo/
Traceback (most recent call last):
  File "/home/mobilitysqr/.local/lib/python3.6/site-packages/django/core/handlers/exception.py", line 34, in inner
    response = get_response(request)
  File "/home/mobilitysqr/.local/lib/python3.6/site-packages/django/core/handlers/base.py", line 126, in _get_response
    response = self.process_exception_by_middleware(e, request)
  File "/home/mobilitysqr/.local/lib/python3.6/site-packages/django/core/handlers/base.py", line 124, in _get_response
    response = wrapped_callback(request, *callback_args, **callback_kwargs)
  File "/home/mobilitysqr/.local/lib/python3.6/site-packages/django/views/decorators/csrf.py", line 54, in wrapped_view
    return view_func(*args, **kwargs)
  File "/home/mobilitysqr/.local/lib/python3.6/site-packages/django/views/generic/base.py", line 68, in view
    return self.dispatch(request, *args, **kwargs)
  File "/home/mobilitysqr/.local/lib/python3.6/site-packages/rest_framework/views.py", line 495, in dispatch
    response = self.handle_exception(exc)
  File "/home/mobilitysqr/.local/lib/python3.6/site-packages/rest_framework/views.py", line 455, in handle_exception
    self.raise_uncaught_exception(exc)
  File "/home/mobilitysqr/.local/lib/python3.6/site-packages/rest_framework/views.py", line 492, in dispatch
    response = handler(request, *args, **kwargs)
  File "/var/www/html/mobilitysqr_staging/mobility_apps/employee/views.py", line 104, in post
    del element['password']
TypeError: 'str' object does not support item deletion
ERROR|06/Jan/2021 12:52:46|basehttp|25436|140491518629632|"POST /emoloyeeinfo/ HTTP/1.1" 500 17287
ERROR|06/Jan/2021 12:53:27|log|25477|139857130206976|Internal Server Error: /emoloyeeinfo/
Traceback (most recent call last):
  File "/home/mobilitysqr/.local/lib/python3.6/site-packages/django/core/handlers/exception.py", line 34, in inner
    response = get_response(request)
  File "/home/mobilitysqr/.local/lib/python3.6/site-packages/django/core/handlers/base.py", line 126, in _get_response
    response = self.process_exception_by_middleware(e, request)
  File "/home/mobilitysqr/.local/lib/python3.6/site-packages/django/core/handlers/base.py", line 124, in _get_response
    response = wrapped_callback(request, *callback_args, **callback_kwargs)
  File "/home/mobilitysqr/.local/lib/python3.6/site-packages/django/views/decorators/csrf.py", line 54, in wrapped_view
    return view_func(*args, **kwargs)
  File "/home/mobilitysqr/.local/lib/python3.6/site-packages/django/views/generic/base.py", line 68, in view
    return self.dispatch(request, *args, **kwargs)
  File "/home/mobilitysqr/.local/lib/python3.6/site-packages/rest_framework/views.py", line 495, in dispatch
    response = self.handle_exception(exc)
  File "/home/mobilitysqr/.local/lib/python3.6/site-packages/rest_framework/views.py", line 455, in handle_exception
    self.raise_uncaught_exception(exc)
  File "/home/mobilitysqr/.local/lib/python3.6/site-packages/rest_framework/views.py", line 492, in dispatch
    response = handler(request, *args, **kwargs)
  File "/var/www/html/mobilitysqr_staging/mobility_apps/employee/views.py", line 105, in post
    del element['password']
TypeError: 'str' object does not support item deletion
ERROR|06/Jan/2021 12:53:27|basehttp|25477|139857130206976|"POST /emoloyeeinfo/ HTTP/1.1" 500 17287
ERROR|06/Jan/2021 12:54:47|log|25519|139777116276480|Internal Server Error: /emoloyeeinfo/
Traceback (most recent call last):
  File "/home/mobilitysqr/.local/lib/python3.6/site-packages/django/core/handlers/exception.py", line 34, in inner
    response = get_response(request)
  File "/home/mobilitysqr/.local/lib/python3.6/site-packages/django/core/handlers/base.py", line 126, in _get_response
    response = self.process_exception_by_middleware(e, request)
  File "/home/mobilitysqr/.local/lib/python3.6/site-packages/django/core/handlers/base.py", line 124, in _get_response
    response = wrapped_callback(request, *callback_args, **callback_kwargs)
  File "/home/mobilitysqr/.local/lib/python3.6/site-packages/django/views/decorators/csrf.py", line 54, in wrapped_view
    return view_func(*args, **kwargs)
  File "/home/mobilitysqr/.local/lib/python3.6/site-packages/django/views/generic/base.py", line 68, in view
    return self.dispatch(request, *args, **kwargs)
  File "/home/mobilitysqr/.local/lib/python3.6/site-packages/rest_framework/views.py", line 495, in dispatch
    response = self.handle_exception(exc)
  File "/home/mobilitysqr/.local/lib/python3.6/site-packages/rest_framework/views.py", line 455, in handle_exception
    self.raise_uncaught_exception(exc)
  File "/home/mobilitysqr/.local/lib/python3.6/site-packages/rest_framework/views.py", line 492, in dispatch
    response = handler(request, *args, **kwargs)
  File "/var/www/html/mobilitysqr_staging/mobility_apps/employee/views.py", line 106, in post
    del element['password']
TypeError: 'str' object does not support item deletion
ERROR|06/Jan/2021 12:54:48|basehttp|25519|139777116276480|"POST /emoloyeeinfo/ HTTP/1.1" 500 17287
ERROR|06/Jan/2021 12:58:02|log|25706|139727933998848|Internal Server Error: /emoloyeeinfo/
Traceback (most recent call last):
  File "/home/mobilitysqr/.local/lib/python3.6/site-packages/django/core/handlers/exception.py", line 34, in inner
    response = get_response(request)
  File "/home/mobilitysqr/.local/lib/python3.6/site-packages/django/core/handlers/base.py", line 126, in _get_response
    response = self.process_exception_by_middleware(e, request)
  File "/home/mobilitysqr/.local/lib/python3.6/site-packages/django/core/handlers/base.py", line 124, in _get_response
    response = wrapped_callback(request, *callback_args, **callback_kwargs)
  File "/home/mobilitysqr/.local/lib/python3.6/site-packages/django/views/decorators/csrf.py", line 54, in wrapped_view
    return view_func(*args, **kwargs)
  File "/home/mobilitysqr/.local/lib/python3.6/site-packages/django/views/generic/base.py", line 68, in view
    return self.dispatch(request, *args, **kwargs)
  File "/home/mobilitysqr/.local/lib/python3.6/site-packages/rest_framework/views.py", line 495, in dispatch
    response = self.handle_exception(exc)
  File "/home/mobilitysqr/.local/lib/python3.6/site-packages/rest_framework/views.py", line 455, in handle_exception
    self.raise_uncaught_exception(exc)
  File "/home/mobilitysqr/.local/lib/python3.6/site-packages/rest_framework/views.py", line 492, in dispatch
    response = handler(request, *args, **kwargs)
  File "/var/www/html/mobilitysqr_staging/mobility_apps/employee/views.py", line 103, in post
    emp_serializer.data[0].remove('password')
AttributeError: 'collections.OrderedDict' object has no attribute 'remove'
ERROR|06/Jan/2021 12:58:02|basehttp|25706|139727933998848|"POST /emoloyeeinfo/ HTTP/1.1" 500 17342
ERROR|06/Jan/2021 13:08:55|exception|26371|140060858234624|Invalid HTTP_HOST header: ''. The domain name provided is not valid according to RFC 1034/1035.
ERROR|06/Jan/2021 13:14:49|log|26371|140060896786176|Internal Server Error: /emoloyeeinfo/
Traceback (most recent call last):
  File "/home/mobilitysqr/.local/lib/python3.6/site-packages/django/core/handlers/exception.py", line 34, in inner
    response = get_response(request)
  File "/home/mobilitysqr/.local/lib/python3.6/site-packages/django/core/handlers/base.py", line 126, in _get_response
    response = self.process_exception_by_middleware(e, request)
  File "/home/mobilitysqr/.local/lib/python3.6/site-packages/django/core/handlers/base.py", line 124, in _get_response
    response = wrapped_callback(request, *callback_args, **callback_kwargs)
  File "/home/mobilitysqr/.local/lib/python3.6/site-packages/django/views/decorators/csrf.py", line 54, in wrapped_view
    return view_func(*args, **kwargs)
  File "/home/mobilitysqr/.local/lib/python3.6/site-packages/django/views/generic/base.py", line 68, in view
    return self.dispatch(request, *args, **kwargs)
  File "/home/mobilitysqr/.local/lib/python3.6/site-packages/rest_framework/views.py", line 495, in dispatch
    response = self.handle_exception(exc)
  File "/home/mobilitysqr/.local/lib/python3.6/site-packages/rest_framework/views.py", line 455, in handle_exception
    self.raise_uncaught_exception(exc)
  File "/home/mobilitysqr/.local/lib/python3.6/site-packages/rest_framework/views.py", line 492, in dispatch
    response = handler(request, *args, **kwargs)
  File "/var/www/html/mobilitysqr_staging/mobility_apps/employee/views.py", line 73, in post
    if employees[0]['active_start_date']:
  File "/home/mobilitysqr/.local/lib/python3.6/site-packages/django/db/models/query.py", line 303, in __getitem__
    return qs._result_cache[0]
IndexError: list index out of range
ERROR|06/Jan/2021 13:14:49|basehttp|26371|140060896786176|"POST /emoloyeeinfo/ HTTP/1.1" 500 17399
ERROR|06/Jan/2021 13:32:58|exception|27447|139803324573440|Invalid HTTP_HOST header: ''. The domain name provided is not valid according to RFC 1034/1035.
ERROR|06/Jan/2021 13:47:16|exception|27759|140607049492224|Invalid HTTP_HOST header: ''. The domain name provided is not valid according to RFC 1034/1035.
ERROR|06/Jan/2021 15:26:59|exception|31203|140051702392576|Invalid HTTP_HOST header: ''. The domain name provided is not valid according to RFC 1034/1035.
ERROR|06/Jan/2021 15:26:59|basehttp|31203|140051702392576|"GET /manager/html HTTP/1.1" 500 59
ERROR|06/Jan/2021 16:39:10|exception|31203|140051677214464|Invalid HTTP_HOST header: ''. The domain name provided is not valid according to RFC 1034/1035.
ERROR|06/Jan/2021 18:47:46|exception|31203|140051677214464|Invalid HTTP_HOST header: ''. The domain name provided is not valid according to RFC 1034/1035.
ERROR|06/Jan/2021 19:36:07|exception|6761|139919042275072|Invalid HTTP_HOST header: ''. The domain name provided is not valid according to RFC 1034/1035.
ERROR|06/Jan/2021 21:07:52|exception|6761|139919042275072|Invalid HTTP_HOST header: ''. The domain name provided is not valid according to RFC 1034/1035.
ERROR|06/Jan/2021 22:15:16|exception|6761|139919042275072|Invalid HTTP_HOST header: ''. The domain name provided is not valid according to RFC 1034/1035.
ERROR|06/Jan/2021 22:24:10|exception|6761|139919042275072|Invalid HTTP_HOST header: ''. The domain name provided is not valid according to RFC 1034/1035.
ERROR|06/Jan/2021 22:32:43|exception|6761|139919042275072|Invalid HTTP_HOST header: ''. The domain name provided is not valid according to RFC 1034/1035.
ERROR|06/Jan/2021 23:45:50|exception|6761|139919042275072|Invalid HTTP_HOST header: ''. The domain name provided is not valid according to RFC 1034/1035.
ERROR|07/Jan/2021 00:32:12|exception|6761|139919042275072|Invalid HTTP_HOST header: ''. The domain name provided is not valid according to RFC 1034/1035.
ERROR|07/Jan/2021 00:41:50|exception|6761|139919042275072|Invalid HTTP_HOST header: ''. The domain name provided is not valid according to RFC 1034/1035.
ERROR|07/Jan/2021 01:56:34|exception|6761|139919042275072|Invalid HTTP_HOST header: ''. The domain name provided is not valid according to RFC 1034/1035.
ERROR|07/Jan/2021 02:40:18|exception|6761|139919042275072|Invalid HTTP_HOST header: ''. The domain name provided is not valid according to RFC 1034/1035.
ERROR|07/Jan/2021 02:58:21|exception|6761|139919042275072|Invalid HTTP_HOST header: ''. The domain name provided is not valid according to RFC 1034/1035.
ERROR|07/Jan/2021 02:58:21|basehttp|6761|139919042275072|"GET /script HTTP/1.1" 500 59
ERROR|07/Jan/2021 03:59:33|exception|6761|139918961538816|Invalid HTTP_HOST header: ''. The domain name provided is not valid according to RFC 1034/1035.
ERROR|07/Jan/2021 04:27:12|exception|6761|139918961538816|Invalid HTTP_HOST header: ''. The domain name provided is not valid according to RFC 1034/1035.
ERROR|07/Jan/2021 04:38:02|exception|6761|139918961538816|Invalid HTTP_HOST header: ''. The domain name provided is not valid according to RFC 1034/1035.
ERROR|07/Jan/2021 05:36:19|exception|6761|139918961538816|Invalid HTTP_HOST header: ''. The domain name provided is not valid according to RFC 1034/1035.
ERROR|07/Jan/2021 05:54:34|exception|6761|139918961538816|Invalid HTTP_HOST header: ''. The domain name provided is not valid according to RFC 1034/1035.
ERROR|07/Jan/2021 07:18:47|exception|6761|139918961538816|Invalid HTTP_HOST header: ''. The domain name provided is not valid according to RFC 1034/1035.
ERROR|07/Jan/2021 07:44:25|exception|6761|139918961538816|Invalid HTTP_HOST header: ''. The domain name provided is not valid according to RFC 1034/1035.
ERROR|07/Jan/2021 09:23:50|exception|6761|139918961538816|Invalid HTTP_HOST header: ''. The domain name provided is not valid according to RFC 1034/1035.
ERROR|07/Jan/2021 10:02:13|log|6761|139918961538816|Internal Server Error: /users
Traceback (most recent call last):
  File "/home/mobilitysqr/.local/lib/python3.6/site-packages/django/core/handlers/exception.py", line 34, in inner
    response = get_response(request)
  File "/home/mobilitysqr/.local/lib/python3.6/site-packages/django/utils/deprecation.py", line 90, in __call__
    response = self.process_request(request)
  File "/home/mobilitysqr/.local/lib/python3.6/site-packages/django/middleware/common.py", line 53, in process_request
    path = self.get_full_path_with_slash(request)
  File "/home/mobilitysqr/.local/lib/python3.6/site-packages/django/middleware/common.py", line 93, in get_full_path_with_slash
    'url': request.get_host() + new_path,
RuntimeError: You called this URL via POST, but the URL doesn't end in a slash and you have APPEND_SLASH set. Django can't redirect to the slash URL while maintaining POST data. Change your form to point to 52.165.220.40:8080/users/?page=&size=5 (note the trailing slash), or set APPEND_SLASH=False in your Django settings.
ERROR|07/Jan/2021 10:02:13|basehttp|6761|139918961538816|"POST /users?page=&size=5 HTTP/1.1" 500 65324
ERROR|07/Jan/2021 10:15:40|exception|6761|139918961538816|Invalid HTTP_HOST header: ''. The domain name provided is not valid according to RFC 1034/1035.
ERROR|07/Jan/2021 11:01:59|exception|6761|139918961538816|Invalid HTTP_HOST header: ''. The domain name provided is not valid according to RFC 1034/1035.
ERROR|07/Jan/2021 11:01:59|basehttp|6761|139918961538816|"GET /script HTTP/1.1" 500 59
ERROR|07/Jan/2021 11:23:12|exception|6761|139918961538816|Invalid HTTP_HOST header: ''. The domain name provided is not valid according to RFC 1034/1035.
