ERROR|08/Apr/2021 13:32:59|log|10795|140351296198400|Internal Server Error: /get_post_approve_travelvisa_request/
Traceback (most recent call last):
  File "/media/tspl26/D/raju_python/mobility_env/lib/python3.7/site-packages/django/core/handlers/exception.py", line 34, in inner
    response = get_response(request)
  File "/media/tspl26/D/raju_python/mobility_env/lib/python3.7/site-packages/django/core/handlers/base.py", line 126, in _get_response
    response = self.process_exception_by_middleware(e, request)
  File "/media/tspl26/D/raju_python/mobility_env/lib/python3.7/site-packages/django/core/handlers/base.py", line 124, in _get_response
    response = wrapped_callback(request, *callback_args, **callback_kwargs)
  File "/media/tspl26/D/raju_python/mobility_env/lib/python3.7/site-packages/django/views/decorators/csrf.py", line 54, in wrapped_view
    return view_func(*args, **kwargs)
  File "/media/tspl26/D/raju_python/mobility_env/lib/python3.7/site-packages/django/views/generic/base.py", line 68, in view
    return self.dispatch(request, *args, **kwargs)
  File "/media/tspl26/D/raju_python/mobility_env/lib/python3.7/site-packages/rest_framework/views.py", line 509, in dispatch
    response = self.handle_exception(exc)
  File "/media/tspl26/D/raju_python/mobility_env/lib/python3.7/site-packages/rest_framework/views.py", line 469, in handle_exception
    self.raise_uncaught_exception(exc)
  File "/media/tspl26/D/raju_python/mobility_env/lib/python3.7/site-packages/rest_framework/views.py", line 480, in raise_uncaught_exception
    raise exc
  File "/media/tspl26/D/raju_python/mobility_env/lib/python3.7/site-packages/rest_framework/views.py", line 506, in dispatch
    response = handler(request, *args, **kwargs)
  File "/media/tspl26/D/raju_python/mobility_env/mobilitysqr_live/mobility_apps/travel/views.py", line 1408, in post
    self.nextLevelApproveTravel_if_sameEmp_to_Approve(self, request.data['travel_req_id'],request.data['org_id'],request.data['modified_by'])
TypeError: nextLevelApproveTravel_if_sameEmp_to_Approve() takes 4 positional arguments but 5 were given
ERROR|08/Apr/2021 13:32:59|basehttp|10795|140351296198400|"POST /get_post_approve_travelvisa_request/ HTTP/1.1" 500 19923
ERROR|08/Apr/2021 14:37:03|log|11902|140225440073472|Internal Server Error: /get_post_approve_travelvisa_request/
Traceback (most recent call last):
  File "/media/tspl26/D/raju_python/mobility_env/lib/python3.7/site-packages/django/core/handlers/exception.py", line 34, in inner
    response = get_response(request)
  File "/media/tspl26/D/raju_python/mobility_env/lib/python3.7/site-packages/django/core/handlers/base.py", line 126, in _get_response
    response = self.process_exception_by_middleware(e, request)
  File "/media/tspl26/D/raju_python/mobility_env/lib/python3.7/site-packages/django/core/handlers/base.py", line 124, in _get_response
    response = wrapped_callback(request, *callback_args, **callback_kwargs)
  File "/media/tspl26/D/raju_python/mobility_env/lib/python3.7/site-packages/django/views/decorators/csrf.py", line 54, in wrapped_view
    return view_func(*args, **kwargs)
  File "/media/tspl26/D/raju_python/mobility_env/lib/python3.7/site-packages/django/views/generic/base.py", line 68, in view
    return self.dispatch(request, *args, **kwargs)
  File "/media/tspl26/D/raju_python/mobility_env/lib/python3.7/site-packages/rest_framework/views.py", line 509, in dispatch
    response = self.handle_exception(exc)
  File "/media/tspl26/D/raju_python/mobility_env/lib/python3.7/site-packages/rest_framework/views.py", line 469, in handle_exception
    self.raise_uncaught_exception(exc)
  File "/media/tspl26/D/raju_python/mobility_env/lib/python3.7/site-packages/rest_framework/views.py", line 480, in raise_uncaught_exception
    raise exc
  File "/media/tspl26/D/raju_python/mobility_env/lib/python3.7/site-packages/rest_framework/views.py", line 506, in dispatch
    response = handler(request, *args, **kwargs)
  File "/media/tspl26/D/raju_python/mobility_env/mobilitysqr_live/mobility_apps/travel/views.py", line 1408, in post
    self.nextLevelApproveTravel_if_sameEmp_to_Approve(request.data['travel_req_id'],request.data['org_id'],request.data['modified_by'])
  File "/media/tspl26/D/raju_python/mobility_env/mobilitysqr_live/mobility_apps/travel/views.py", line 1688, in nextLevelApproveTravel_if_sameEmp_to_Approve
    check_data = self.checkTravelRequestTicketOwner(travel_req_id)
TypeError: checkTravelRequestTicketOwner() takes 1 positional argument but 2 were given
ERROR|08/Apr/2021 14:37:03|basehttp|11902|140225440073472|"POST /get_post_approve_travelvisa_request/ HTTP/1.1" 500 20108
ERROR|08/Apr/2021 14:47:58|log|12345|140130067793664|Internal Server Error: /get_post_approve_travelvisa_request/
Traceback (most recent call last):
  File "/media/tspl26/D/raju_python/mobility_env/lib/python3.7/site-packages/django/core/handlers/exception.py", line 34, in inner
    response = get_response(request)
  File "/media/tspl26/D/raju_python/mobility_env/lib/python3.7/site-packages/django/core/handlers/base.py", line 126, in _get_response
    response = self.process_exception_by_middleware(e, request)
  File "/media/tspl26/D/raju_python/mobility_env/lib/python3.7/site-packages/django/core/handlers/base.py", line 124, in _get_response
    response = wrapped_callback(request, *callback_args, **callback_kwargs)
  File "/media/tspl26/D/raju_python/mobility_env/lib/python3.7/site-packages/django/views/decorators/csrf.py", line 54, in wrapped_view
    return view_func(*args, **kwargs)
  File "/media/tspl26/D/raju_python/mobility_env/lib/python3.7/site-packages/django/views/generic/base.py", line 68, in view
    return self.dispatch(request, *args, **kwargs)
  File "/media/tspl26/D/raju_python/mobility_env/lib/python3.7/site-packages/rest_framework/views.py", line 509, in dispatch
    response = self.handle_exception(exc)
  File "/media/tspl26/D/raju_python/mobility_env/lib/python3.7/site-packages/rest_framework/views.py", line 469, in handle_exception
    self.raise_uncaught_exception(exc)
  File "/media/tspl26/D/raju_python/mobility_env/lib/python3.7/site-packages/rest_framework/views.py", line 480, in raise_uncaught_exception
    raise exc
  File "/media/tspl26/D/raju_python/mobility_env/lib/python3.7/site-packages/rest_framework/views.py", line 506, in dispatch
    response = handler(request, *args, **kwargs)
  File "/media/tspl26/D/raju_python/mobility_env/mobilitysqr_live/mobility_apps/travel/views.py", line 1408, in post
    self.nextLevelApproveTravel_if_sameEmp_to_Approve(request.data['travel_req_id'],request.data['org_id'],request.data['modified_by'])
  File "/media/tspl26/D/raju_python/mobility_env/mobilitysqr_live/mobility_apps/travel/views.py", line 1692, in nextLevelApproveTravel_if_sameEmp_to_Approve
    self.travelApproveAutomatic(travel_req_id, org_id, modified_by, check_data)
  File "/media/tspl26/D/raju_python/mobility_env/mobilitysqr_live/mobility_apps/travel/views.py", line 1710, in travelApproveAutomatic
    data = dict()
UnboundLocalError: local variable 'dict' referenced before assignment
ERROR|08/Apr/2021 14:47:58|basehttp|12345|140130067793664|"POST /get_post_approve_travelvisa_request/ HTTP/1.1" 500 20253
ERROR|08/Apr/2021 14:56:56|log|12656|140433612867328|Internal Server Error: /get_post_approve_travelvisa_request/
Traceback (most recent call last):
  File "/media/tspl26/D/raju_python/mobility_env/lib/python3.7/site-packages/django/core/handlers/exception.py", line 34, in inner
    response = get_response(request)
  File "/media/tspl26/D/raju_python/mobility_env/lib/python3.7/site-packages/django/core/handlers/base.py", line 126, in _get_response
    response = self.process_exception_by_middleware(e, request)
  File "/media/tspl26/D/raju_python/mobility_env/lib/python3.7/site-packages/django/core/handlers/base.py", line 124, in _get_response
    response = wrapped_callback(request, *callback_args, **callback_kwargs)
  File "/media/tspl26/D/raju_python/mobility_env/lib/python3.7/site-packages/django/views/decorators/csrf.py", line 54, in wrapped_view
    return view_func(*args, **kwargs)
  File "/media/tspl26/D/raju_python/mobility_env/lib/python3.7/site-packages/django/views/generic/base.py", line 68, in view
    return self.dispatch(request, *args, **kwargs)
  File "/media/tspl26/D/raju_python/mobility_env/lib/python3.7/site-packages/rest_framework/views.py", line 509, in dispatch
    response = self.handle_exception(exc)
  File "/media/tspl26/D/raju_python/mobility_env/lib/python3.7/site-packages/rest_framework/views.py", line 469, in handle_exception
    self.raise_uncaught_exception(exc)
  File "/media/tspl26/D/raju_python/mobility_env/lib/python3.7/site-packages/rest_framework/views.py", line 480, in raise_uncaught_exception
    raise exc
  File "/media/tspl26/D/raju_python/mobility_env/lib/python3.7/site-packages/rest_framework/views.py", line 506, in dispatch
    response = handler(request, *args, **kwargs)
  File "/media/tspl26/D/raju_python/mobility_env/mobilitysqr_live/mobility_apps/travel/views.py", line 1408, in post
    self.nextLevelApproveTravel_if_sameEmp_to_Approve(request.data['travel_req_id'],request.data['org_id'],request.data['modified_by'])
  File "/media/tspl26/D/raju_python/mobility_env/mobilitysqr_live/mobility_apps/travel/views.py", line 1692, in nextLevelApproveTravel_if_sameEmp_to_Approve
    self.travelApproveAutomatic(travel_req_id, org_id, modified_by, check_data)
  File "/media/tspl26/D/raju_python/mobility_env/mobilitysqr_live/mobility_apps/travel/views.py", line 1714, in travelApproveAutomatic
    data['current_ticket_owner'] = travel_data[0]['project_manager']
TypeError: list indices must be integers or slices, not str
ERROR|08/Apr/2021 14:56:56|basehttp|12656|140433612867328|"POST /get_post_approve_travelvisa_request/ HTTP/1.1" 500 20296
