ERROR|23/Nov/2020 11:51:24|log|44339|140492375140096|Internal Server Error: /getassignmentletter/
Traceback (most recent call last):
  File "/home/mobilitysqr/.local/lib/python3.6/site-packages/django/core/handlers/exception.py", line 34, in inner
    response = get_response(request)
  File "/home/mobilitysqr/.local/lib/python3.6/site-packages/django/core/handlers/base.py", line 126, in _get_response
    response = self.process_exception_by_middleware(e, request)
  File "/home/mobilitysqr/.local/lib/python3.6/site-packages/django/core/handlers/base.py", line 124, in _get_response
    response = wrapped_callback(request, *callback_args, **callback_kwargs)
  File "/home/mobilitysqr/.local/lib/python3.6/site-packages/django/views/decorators/csrf.py", line 54, in wrapped_view
    return view_func(*args, **kwargs)
  File "/home/mobilitysqr/.local/lib/python3.6/site-packages/django/views/generic/base.py", line 68, in view
    return self.dispatch(request, *args, **kwargs)
  File "/home/mobilitysqr/.local/lib/python3.6/site-packages/rest_framework/views.py", line 495, in dispatch
    response = self.handle_exception(exc)
  File "/home/mobilitysqr/.local/lib/python3.6/site-packages/rest_framework/views.py", line 455, in handle_exception
    self.raise_uncaught_exception(exc)
  File "/home/mobilitysqr/.local/lib/python3.6/site-packages/rest_framework/views.py", line 492, in dispatch
    response = handler(request, *args, **kwargs)
  File "/var/www/html/mobilitysqrapi/mobility_apps/letter/views.py", line 106, in get
    datas['AssignmentStartDate']=self.date_format(date=data['Actual_Start_Date'])
AttributeError: 'getassignmentletter' object has no attribute 'date_format'
ERROR|23/Nov/2020 11:51:24|basehttp|44339|140492375140096|"GET /getassignmentletter/?travel_req_id=TR185141 HTTP/1.1" 500 17459
ERROR|23/Nov/2020 12:01:16|log|45114|139731990566656|Internal Server Error: /getassignmentletter/
Traceback (most recent call last):
  File "/home/mobilitysqr/.local/lib/python3.6/site-packages/django/core/handlers/exception.py", line 34, in inner
    response = get_response(request)
  File "/home/mobilitysqr/.local/lib/python3.6/site-packages/django/core/handlers/base.py", line 126, in _get_response
    response = self.process_exception_by_middleware(e, request)
  File "/home/mobilitysqr/.local/lib/python3.6/site-packages/django/core/handlers/base.py", line 124, in _get_response
    response = wrapped_callback(request, *callback_args, **callback_kwargs)
  File "/home/mobilitysqr/.local/lib/python3.6/site-packages/django/views/decorators/csrf.py", line 54, in wrapped_view
    return view_func(*args, **kwargs)
  File "/home/mobilitysqr/.local/lib/python3.6/site-packages/django/views/generic/base.py", line 68, in view
    return self.dispatch(request, *args, **kwargs)
  File "/home/mobilitysqr/.local/lib/python3.6/site-packages/rest_framework/views.py", line 495, in dispatch
    response = self.handle_exception(exc)
  File "/home/mobilitysqr/.local/lib/python3.6/site-packages/rest_framework/views.py", line 455, in handle_exception
    self.raise_uncaught_exception(exc)
  File "/home/mobilitysqr/.local/lib/python3.6/site-packages/rest_framework/views.py", line 492, in dispatch
    response = handler(request, *args, **kwargs)
  File "/var/www/html/mobilitysqrapi/mobility_apps/letter/views.py", line 107, in get
    datas['AssignmentStartDate']=self.date_format(date=data['Actual_Start_Date'])
AttributeError: 'getassignmentletter' object has no attribute 'date_format'
ERROR|23/Nov/2020 12:01:16|basehttp|45114|139731990566656|"GET /getassignmentletter/?travel_req_id=TR185141 HTTP/1.1" 500 17459
ERROR|23/Nov/2020 12:06:36|log|45555|139895703463680|Internal Server Error: /getassignmentletter/
Traceback (most recent call last):
  File "/home/mobilitysqr/.local/lib/python3.6/site-packages/django/core/handlers/exception.py", line 34, in inner
    response = get_response(request)
  File "/home/mobilitysqr/.local/lib/python3.6/site-packages/django/core/handlers/base.py", line 126, in _get_response
    response = self.process_exception_by_middleware(e, request)
  File "/home/mobilitysqr/.local/lib/python3.6/site-packages/django/core/handlers/base.py", line 124, in _get_response
    response = wrapped_callback(request, *callback_args, **callback_kwargs)
  File "/home/mobilitysqr/.local/lib/python3.6/site-packages/django/views/decorators/csrf.py", line 54, in wrapped_view
    return view_func(*args, **kwargs)
  File "/home/mobilitysqr/.local/lib/python3.6/site-packages/django/views/generic/base.py", line 68, in view
    return self.dispatch(request, *args, **kwargs)
  File "/home/mobilitysqr/.local/lib/python3.6/site-packages/rest_framework/views.py", line 495, in dispatch
    response = self.handle_exception(exc)
  File "/home/mobilitysqr/.local/lib/python3.6/site-packages/rest_framework/views.py", line 455, in handle_exception
    self.raise_uncaught_exception(exc)
  File "/home/mobilitysqr/.local/lib/python3.6/site-packages/rest_framework/views.py", line 492, in dispatch
    response = handler(request, *args, **kwargs)
  File "/var/www/html/mobilitysqrapi/mobility_apps/letter/views.py", line 106, in get
    datas['AssignmentStartDate']=self.date_format(date=data['Actual_Start_Date'])
  File "/var/www/html/mobilitysqrapi/mobility_apps/letter/views.py", line 512, in date_format
    from_zone = tz.tzutc()
NameError: name 'tz' is not defined
ERROR|23/Nov/2020 12:06:36|basehttp|45555|139895703463680|"GET /getassignmentletter/?travel_req_id=TR185141 HTTP/1.1" 500 17496
ERROR|23/Nov/2020 12:07:25|log|45591|140218457650944|Internal Server Error: /getassignmentletter/
Traceback (most recent call last):
  File "/home/mobilitysqr/.local/lib/python3.6/site-packages/django/core/handlers/exception.py", line 34, in inner
    response = get_response(request)
  File "/home/mobilitysqr/.local/lib/python3.6/site-packages/django/core/handlers/base.py", line 126, in _get_response
    response = self.process_exception_by_middleware(e, request)
  File "/home/mobilitysqr/.local/lib/python3.6/site-packages/django/core/handlers/base.py", line 124, in _get_response
    response = wrapped_callback(request, *callback_args, **callback_kwargs)
  File "/home/mobilitysqr/.local/lib/python3.6/site-packages/django/views/decorators/csrf.py", line 54, in wrapped_view
    return view_func(*args, **kwargs)
  File "/home/mobilitysqr/.local/lib/python3.6/site-packages/django/views/generic/base.py", line 68, in view
    return self.dispatch(request, *args, **kwargs)
  File "/home/mobilitysqr/.local/lib/python3.6/site-packages/rest_framework/views.py", line 495, in dispatch
    response = self.handle_exception(exc)
  File "/home/mobilitysqr/.local/lib/python3.6/site-packages/rest_framework/views.py", line 455, in handle_exception
    self.raise_uncaught_exception(exc)
  File "/home/mobilitysqr/.local/lib/python3.6/site-packages/rest_framework/views.py", line 492, in dispatch
    response = handler(request, *args, **kwargs)
  File "/var/www/html/mobilitysqrapi/mobility_apps/letter/views.py", line 107, in get
    datas['AssignmentStartDate']=self.date_format(date=data['Actual_Start_Date'])
  File "/var/www/html/mobilitysqrapi/mobility_apps/letter/views.py", line 517, in date_format
    utc = datetime.strptime(date, '%Y-%m-%d %H:%M:%S')
  File "/usr/lib/python3.6/_strptime.py", line 565, in _strptime_datetime
    tt, fraction = _strptime(data_string, format)
  File "/usr/lib/python3.6/_strptime.py", line 362, in _strptime
    (data_string, format))
ValueError: time data '2020-11-26T18:30:00' does not match format '%Y-%m-%d %H:%M:%S'
ERROR|23/Nov/2020 12:07:25|basehttp|45591|140218457650944|"GET /getassignmentletter/?travel_req_id=TR185141 HTTP/1.1" 500 17851
ERROR|23/Nov/2020 12:07:28|log|45591|140218457650944|Internal Server Error: /getassignmentletter/
Traceback (most recent call last):
  File "/home/mobilitysqr/.local/lib/python3.6/site-packages/django/core/handlers/exception.py", line 34, in inner
    response = get_response(request)
  File "/home/mobilitysqr/.local/lib/python3.6/site-packages/django/core/handlers/base.py", line 126, in _get_response
    response = self.process_exception_by_middleware(e, request)
  File "/home/mobilitysqr/.local/lib/python3.6/site-packages/django/core/handlers/base.py", line 124, in _get_response
    response = wrapped_callback(request, *callback_args, **callback_kwargs)
  File "/home/mobilitysqr/.local/lib/python3.6/site-packages/django/views/decorators/csrf.py", line 54, in wrapped_view
    return view_func(*args, **kwargs)
  File "/home/mobilitysqr/.local/lib/python3.6/site-packages/django/views/generic/base.py", line 68, in view
    return self.dispatch(request, *args, **kwargs)
  File "/home/mobilitysqr/.local/lib/python3.6/site-packages/rest_framework/views.py", line 495, in dispatch
    response = self.handle_exception(exc)
  File "/home/mobilitysqr/.local/lib/python3.6/site-packages/rest_framework/views.py", line 455, in handle_exception
    self.raise_uncaught_exception(exc)
  File "/home/mobilitysqr/.local/lib/python3.6/site-packages/rest_framework/views.py", line 492, in dispatch
    response = handler(request, *args, **kwargs)
  File "/var/www/html/mobilitysqrapi/mobility_apps/letter/views.py", line 107, in get
    datas['AssignmentStartDate']=self.date_format(date=data['Actual_Start_Date'])
  File "/var/www/html/mobilitysqrapi/mobility_apps/letter/views.py", line 517, in date_format
    utc = datetime.strptime(date, '%Y-%m-%d %H:%M:%S')
  File "/usr/lib/python3.6/_strptime.py", line 565, in _strptime_datetime
    tt, fraction = _strptime(data_string, format)
  File "/usr/lib/python3.6/_strptime.py", line 362, in _strptime
    (data_string, format))
ValueError: time data '2020-11-26T18:30:00' does not match format '%Y-%m-%d %H:%M:%S'
ERROR|23/Nov/2020 12:07:28|basehttp|45591|140218457650944|"GET /getassignmentletter/?travel_req_id=TR185141 HTTP/1.1" 500 17851
ERROR|23/Nov/2020 12:09:04|log|45741|139740161160960|Internal Server Error: /getassignmentletter/
Traceback (most recent call last):
  File "/home/mobilitysqr/.local/lib/python3.6/site-packages/django/core/handlers/exception.py", line 34, in inner
    response = get_response(request)
  File "/home/mobilitysqr/.local/lib/python3.6/site-packages/django/core/handlers/base.py", line 126, in _get_response
    response = self.process_exception_by_middleware(e, request)
  File "/home/mobilitysqr/.local/lib/python3.6/site-packages/django/core/handlers/base.py", line 124, in _get_response
    response = wrapped_callback(request, *callback_args, **callback_kwargs)
  File "/home/mobilitysqr/.local/lib/python3.6/site-packages/django/views/decorators/csrf.py", line 54, in wrapped_view
    return view_func(*args, **kwargs)
  File "/home/mobilitysqr/.local/lib/python3.6/site-packages/django/views/generic/base.py", line 68, in view
    return self.dispatch(request, *args, **kwargs)
  File "/home/mobilitysqr/.local/lib/python3.6/site-packages/rest_framework/views.py", line 495, in dispatch
    response = self.handle_exception(exc)
  File "/home/mobilitysqr/.local/lib/python3.6/site-packages/rest_framework/views.py", line 455, in handle_exception
    self.raise_uncaught_exception(exc)
  File "/home/mobilitysqr/.local/lib/python3.6/site-packages/rest_framework/views.py", line 492, in dispatch
    response = handler(request, *args, **kwargs)
  File "/var/www/html/mobilitysqrapi/mobility_apps/letter/views.py", line 108, in get
    datas['AssignmentStartDate']=self.date_format(date=data['Actual_Start_Date'])
  File "/var/www/html/mobilitysqrapi/mobility_apps/letter/views.py", line 518, in date_format
    utc = datetime.strptime(date, '%Y-%m-%d %H:%M:%S')
  File "/usr/lib/python3.6/_strptime.py", line 565, in _strptime_datetime
    tt, fraction = _strptime(data_string, format)
  File "/usr/lib/python3.6/_strptime.py", line 362, in _strptime
    (data_string, format))
ValueError: time data '2020-11-26T18:30:00' does not match format '%Y-%m-%d %H:%M:%S'
ERROR|23/Nov/2020 12:09:04|basehttp|45741|139740161160960|"GET /getassignmentletter/?travel_req_id=TR185141 HTTP/1.1" 500 17851
ERROR|23/Nov/2020 12:09:06|log|45741|139740161160960|Internal Server Error: /getassignmentletter/
Traceback (most recent call last):
  File "/home/mobilitysqr/.local/lib/python3.6/site-packages/django/core/handlers/exception.py", line 34, in inner
    response = get_response(request)
  File "/home/mobilitysqr/.local/lib/python3.6/site-packages/django/core/handlers/base.py", line 126, in _get_response
    response = self.process_exception_by_middleware(e, request)
  File "/home/mobilitysqr/.local/lib/python3.6/site-packages/django/core/handlers/base.py", line 124, in _get_response
    response = wrapped_callback(request, *callback_args, **callback_kwargs)
  File "/home/mobilitysqr/.local/lib/python3.6/site-packages/django/views/decorators/csrf.py", line 54, in wrapped_view
    return view_func(*args, **kwargs)
  File "/home/mobilitysqr/.local/lib/python3.6/site-packages/django/views/generic/base.py", line 68, in view
    return self.dispatch(request, *args, **kwargs)
  File "/home/mobilitysqr/.local/lib/python3.6/site-packages/rest_framework/views.py", line 495, in dispatch
    response = self.handle_exception(exc)
  File "/home/mobilitysqr/.local/lib/python3.6/site-packages/rest_framework/views.py", line 455, in handle_exception
    self.raise_uncaught_exception(exc)
  File "/home/mobilitysqr/.local/lib/python3.6/site-packages/rest_framework/views.py", line 492, in dispatch
    response = handler(request, *args, **kwargs)
  File "/var/www/html/mobilitysqrapi/mobility_apps/letter/views.py", line 108, in get
    datas['AssignmentStartDate']=self.date_format(date=data['Actual_Start_Date'])
  File "/var/www/html/mobilitysqrapi/mobility_apps/letter/views.py", line 518, in date_format
    utc = datetime.strptime(date, '%Y-%m-%d %H:%M:%S')
  File "/usr/lib/python3.6/_strptime.py", line 565, in _strptime_datetime
    tt, fraction = _strptime(data_string, format)
  File "/usr/lib/python3.6/_strptime.py", line 362, in _strptime
    (data_string, format))
ValueError: time data '2020-11-26T18:30:00' does not match format '%Y-%m-%d %H:%M:%S'
ERROR|23/Nov/2020 12:09:06|basehttp|45741|139740161160960|"GET /getassignmentletter/?travel_req_id=TR185141 HTTP/1.1" 500 17851
ERROR|23/Nov/2020 12:20:16|log|46118|140295976347392|Internal Server Error: /getassignmentletter/
Traceback (most recent call last):
  File "/home/mobilitysqr/.local/lib/python3.6/site-packages/django/core/handlers/exception.py", line 34, in inner
    response = get_response(request)
  File "/home/mobilitysqr/.local/lib/python3.6/site-packages/django/core/handlers/base.py", line 126, in _get_response
    response = self.process_exception_by_middleware(e, request)
  File "/home/mobilitysqr/.local/lib/python3.6/site-packages/django/core/handlers/base.py", line 124, in _get_response
    response = wrapped_callback(request, *callback_args, **callback_kwargs)
  File "/home/mobilitysqr/.local/lib/python3.6/site-packages/django/views/decorators/csrf.py", line 54, in wrapped_view
    return view_func(*args, **kwargs)
  File "/home/mobilitysqr/.local/lib/python3.6/site-packages/django/views/generic/base.py", line 68, in view
    return self.dispatch(request, *args, **kwargs)
  File "/home/mobilitysqr/.local/lib/python3.6/site-packages/rest_framework/views.py", line 495, in dispatch
    response = self.handle_exception(exc)
  File "/home/mobilitysqr/.local/lib/python3.6/site-packages/rest_framework/views.py", line 455, in handle_exception
    self.raise_uncaught_exception(exc)
  File "/home/mobilitysqr/.local/lib/python3.6/site-packages/rest_framework/views.py", line 492, in dispatch
    response = handler(request, *args, **kwargs)
  File "/var/www/html/mobilitysqrapi/mobility_apps/letter/views.py", line 109, in get
    datas['AssignmentEndDate']=self.date_format(date=data['Actual_End_Date'])
  File "/var/www/html/mobilitysqrapi/mobility_apps/letter/views.py", line 518, in date_format
    utc = datetime.strptime(date, '%Y-%m-%d')
  File "/usr/lib/python3.6/_strptime.py", line 565, in _strptime_datetime
    tt, fraction = _strptime(data_string, format)
  File "/usr/lib/python3.6/_strptime.py", line 362, in _strptime
    (data_string, format))
ValueError: time data 'None' does not match format '%Y-%m-%d'
ERROR|23/Nov/2020 12:20:16|basehttp|46118|140295976347392|"GET /getassignmentletter/?travel_req_id=TR185141 HTTP/1.1" 500 17791
ERROR|23/Nov/2020 12:23:02|log|46312|140125338150656|Internal Server Error: /getassignmentletter/
Traceback (most recent call last):
  File "/home/mobilitysqr/.local/lib/python3.6/site-packages/django/core/handlers/exception.py", line 34, in inner
    response = get_response(request)
  File "/home/mobilitysqr/.local/lib/python3.6/site-packages/django/core/handlers/base.py", line 126, in _get_response
    response = self.process_exception_by_middleware(e, request)
  File "/home/mobilitysqr/.local/lib/python3.6/site-packages/django/core/handlers/base.py", line 124, in _get_response
    response = wrapped_callback(request, *callback_args, **callback_kwargs)
  File "/home/mobilitysqr/.local/lib/python3.6/site-packages/django/views/decorators/csrf.py", line 54, in wrapped_view
    return view_func(*args, **kwargs)
  File "/home/mobilitysqr/.local/lib/python3.6/site-packages/django/views/generic/base.py", line 68, in view
    return self.dispatch(request, *args, **kwargs)
  File "/home/mobilitysqr/.local/lib/python3.6/site-packages/rest_framework/views.py", line 495, in dispatch
    response = self.handle_exception(exc)
  File "/home/mobilitysqr/.local/lib/python3.6/site-packages/rest_framework/views.py", line 455, in handle_exception
    self.raise_uncaught_exception(exc)
  File "/home/mobilitysqr/.local/lib/python3.6/site-packages/rest_framework/views.py", line 492, in dispatch
    response = handler(request, *args, **kwargs)
  File "/var/www/html/mobilitysqrapi/mobility_apps/letter/views.py", line 109, in get
    datas['AssignmentEndDate']=self.date_format(date=data['Actual_End_Date'])
  File "/var/www/html/mobilitysqrapi/mobility_apps/letter/views.py", line 518, in date_format
    utc = datetime.strptime(date, '%Y-%m-%dT%H:%M:%S')
  File "/usr/lib/python3.6/_strptime.py", line 565, in _strptime_datetime
    tt, fraction = _strptime(data_string, format)
  File "/usr/lib/python3.6/_strptime.py", line 362, in _strptime
    (data_string, format))
ValueError: time data 'None' does not match format '%Y-%m-%dT%H:%M:%S'
ERROR|23/Nov/2020 12:23:02|basehttp|46312|140125338150656|"GET /getassignmentletter/?travel_req_id=TR185141 HTTP/1.1" 500 17817
ERROR|23/Nov/2020 14:15:56|log|50612|140377932244736|Internal Server Error: /getassignmentletter/
Traceback (most recent call last):
  File "/home/mobilitysqr/.local/lib/python3.6/site-packages/django/core/handlers/exception.py", line 34, in inner
    response = get_response(request)
  File "/home/mobilitysqr/.local/lib/python3.6/site-packages/django/core/handlers/base.py", line 126, in _get_response
    response = self.process_exception_by_middleware(e, request)
  File "/home/mobilitysqr/.local/lib/python3.6/site-packages/django/core/handlers/base.py", line 124, in _get_response
    response = wrapped_callback(request, *callback_args, **callback_kwargs)
  File "/home/mobilitysqr/.local/lib/python3.6/site-packages/django/views/decorators/csrf.py", line 54, in wrapped_view
    return view_func(*args, **kwargs)
  File "/home/mobilitysqr/.local/lib/python3.6/site-packages/django/views/generic/base.py", line 68, in view
    return self.dispatch(request, *args, **kwargs)
  File "/home/mobilitysqr/.local/lib/python3.6/site-packages/rest_framework/views.py", line 495, in dispatch
    response = self.handle_exception(exc)
  File "/home/mobilitysqr/.local/lib/python3.6/site-packages/rest_framework/views.py", line 455, in handle_exception
    self.raise_uncaught_exception(exc)
  File "/home/mobilitysqr/.local/lib/python3.6/site-packages/rest_framework/views.py", line 492, in dispatch
    response = handler(request, *args, **kwargs)
  File "/var/www/html/mobilitysqrapi/mobility_apps/letter/views.py", line 109, in get
    datas['AssignmentEndDate']=self.date_format(date=data['Actual_End_Date'])
  File "/var/www/html/mobilitysqrapi/mobility_apps/letter/views.py", line 517, in date_format
    utc = datetime.strptime(date, '%Y-%m-%dT%H:%M:%S.%fZ')
TypeError: strptime() argument 1 must be str, not None
ERROR|23/Nov/2020 14:15:56|basehttp|50612|140377932244736|"GET /getassignmentletter/?travel_req_id=TR185141 HTTP/1.1" 500 17563
ERROR|23/Nov/2020 14:21:19|log|50612|140377932244736|Internal Server Error: /getassignmentletter/
Traceback (most recent call last):
  File "/home/mobilitysqr/.local/lib/python3.6/site-packages/django/core/handlers/exception.py", line 34, in inner
    response = get_response(request)
  File "/home/mobilitysqr/.local/lib/python3.6/site-packages/django/core/handlers/base.py", line 126, in _get_response
    response = self.process_exception_by_middleware(e, request)
  File "/home/mobilitysqr/.local/lib/python3.6/site-packages/django/core/handlers/base.py", line 124, in _get_response
    response = wrapped_callback(request, *callback_args, **callback_kwargs)
  File "/home/mobilitysqr/.local/lib/python3.6/site-packages/django/views/decorators/csrf.py", line 54, in wrapped_view
    return view_func(*args, **kwargs)
  File "/home/mobilitysqr/.local/lib/python3.6/site-packages/django/views/generic/base.py", line 68, in view
    return self.dispatch(request, *args, **kwargs)
  File "/home/mobilitysqr/.local/lib/python3.6/site-packages/rest_framework/views.py", line 495, in dispatch
    response = self.handle_exception(exc)
  File "/home/mobilitysqr/.local/lib/python3.6/site-packages/rest_framework/views.py", line 455, in handle_exception
    self.raise_uncaught_exception(exc)
  File "/home/mobilitysqr/.local/lib/python3.6/site-packages/rest_framework/views.py", line 492, in dispatch
    response = handler(request, *args, **kwargs)
  File "/var/www/html/mobilitysqrapi/mobility_apps/letter/views.py", line 109, in get
    datas['AssignmentEndDate']=self.date_format(date=data['Actual_End_Date'])
  File "/var/www/html/mobilitysqrapi/mobility_apps/letter/views.py", line 517, in date_format
    utc = datetime.strptime(date, '%Y-%m-%dT%H:%M:%S.%fZ')
TypeError: strptime() argument 1 must be str, not None
ERROR|23/Nov/2020 14:21:19|basehttp|50612|140377932244736|"GET /getassignmentletter/?travel_req_id=TR185141 HTTP/1.1" 500 17563
ERROR|23/Nov/2020 14:21:52|log|50900|140067412211456|Internal Server Error: /getassignmentletter/
Traceback (most recent call last):
  File "/home/mobilitysqr/.local/lib/python3.6/site-packages/django/core/handlers/exception.py", line 34, in inner
    response = get_response(request)
  File "/home/mobilitysqr/.local/lib/python3.6/site-packages/django/core/handlers/base.py", line 126, in _get_response
    response = self.process_exception_by_middleware(e, request)
  File "/home/mobilitysqr/.local/lib/python3.6/site-packages/django/core/handlers/base.py", line 124, in _get_response
    response = wrapped_callback(request, *callback_args, **callback_kwargs)
  File "/home/mobilitysqr/.local/lib/python3.6/site-packages/django/views/decorators/csrf.py", line 54, in wrapped_view
    return view_func(*args, **kwargs)
  File "/home/mobilitysqr/.local/lib/python3.6/site-packages/django/views/generic/base.py", line 68, in view
    return self.dispatch(request, *args, **kwargs)
  File "/home/mobilitysqr/.local/lib/python3.6/site-packages/rest_framework/views.py", line 495, in dispatch
    response = self.handle_exception(exc)
  File "/home/mobilitysqr/.local/lib/python3.6/site-packages/rest_framework/views.py", line 455, in handle_exception
    self.raise_uncaught_exception(exc)
  File "/home/mobilitysqr/.local/lib/python3.6/site-packages/rest_framework/views.py", line 492, in dispatch
    response = handler(request, *args, **kwargs)
  File "/var/www/html/mobilitysqrapi/mobility_apps/letter/views.py", line 109, in get
    datas['AssignmentEndDate']=self.date_format(date=data['Actual_End_Date'])
  File "/var/www/html/mobilitysqrapi/mobility_apps/letter/views.py", line 517, in date_format
    utc = datetime.strptime(str(date), '%Y-%m-%dT%H:%M:%S.%fZ')
  File "/usr/lib/python3.6/_strptime.py", line 565, in _strptime_datetime
    tt, fraction = _strptime(data_string, format)
  File "/usr/lib/python3.6/_strptime.py", line 362, in _strptime
    (data_string, format))
ValueError: time data 'None' does not match format '%Y-%m-%dT%H:%M:%S.%fZ'
ERROR|23/Nov/2020 14:21:52|basehttp|50900|140067412211456|"GET /getassignmentletter/?travel_req_id=TR185141 HTTP/1.1" 500 17834
ERROR|23/Nov/2020 14:22:01|log|50900|140067402245888|Internal Server Error: /getassignmentletter/
Traceback (most recent call last):
  File "/home/mobilitysqr/.local/lib/python3.6/site-packages/django/core/handlers/exception.py", line 34, in inner
    response = get_response(request)
  File "/home/mobilitysqr/.local/lib/python3.6/site-packages/django/core/handlers/base.py", line 126, in _get_response
    response = self.process_exception_by_middleware(e, request)
  File "/home/mobilitysqr/.local/lib/python3.6/site-packages/django/core/handlers/base.py", line 124, in _get_response
    response = wrapped_callback(request, *callback_args, **callback_kwargs)
  File "/home/mobilitysqr/.local/lib/python3.6/site-packages/django/views/decorators/csrf.py", line 54, in wrapped_view
    return view_func(*args, **kwargs)
  File "/home/mobilitysqr/.local/lib/python3.6/site-packages/django/views/generic/base.py", line 68, in view
    return self.dispatch(request, *args, **kwargs)
  File "/home/mobilitysqr/.local/lib/python3.6/site-packages/rest_framework/views.py", line 495, in dispatch
    response = self.handle_exception(exc)
  File "/home/mobilitysqr/.local/lib/python3.6/site-packages/rest_framework/views.py", line 455, in handle_exception
    self.raise_uncaught_exception(exc)
  File "/home/mobilitysqr/.local/lib/python3.6/site-packages/rest_framework/views.py", line 492, in dispatch
    response = handler(request, *args, **kwargs)
  File "/var/www/html/mobilitysqrapi/mobility_apps/letter/views.py", line 109, in get
    datas['AssignmentEndDate']=self.date_format(date=data['Actual_End_Date'])
  File "/var/www/html/mobilitysqrapi/mobility_apps/letter/views.py", line 517, in date_format
    utc = datetime.strptime(str(date), '%Y-%m-%dT%H:%M:%S.%fZ')
  File "/usr/lib/python3.6/_strptime.py", line 565, in _strptime_datetime
    tt, fraction = _strptime(data_string, format)
  File "/usr/lib/python3.6/_strptime.py", line 362, in _strptime
    (data_string, format))
ValueError: time data 'None' does not match format '%Y-%m-%dT%H:%M:%S.%fZ'
ERROR|23/Nov/2020 14:22:01|basehttp|50900|140067402245888|"GET /getassignmentletter/?travel_req_id=TR185141 HTTP/1.1" 500 17835
ERROR|23/Nov/2020 14:23:51|log|51049|139758923753216|Internal Server Error: /getassignmentletter/
Traceback (most recent call last):
  File "/home/mobilitysqr/.local/lib/python3.6/site-packages/django/core/handlers/exception.py", line 34, in inner
    response = get_response(request)
  File "/home/mobilitysqr/.local/lib/python3.6/site-packages/django/core/handlers/base.py", line 126, in _get_response
    response = self.process_exception_by_middleware(e, request)
  File "/home/mobilitysqr/.local/lib/python3.6/site-packages/django/core/handlers/base.py", line 124, in _get_response
    response = wrapped_callback(request, *callback_args, **callback_kwargs)
  File "/home/mobilitysqr/.local/lib/python3.6/site-packages/django/views/decorators/csrf.py", line 54, in wrapped_view
    return view_func(*args, **kwargs)
  File "/home/mobilitysqr/.local/lib/python3.6/site-packages/django/views/generic/base.py", line 68, in view
    return self.dispatch(request, *args, **kwargs)
  File "/home/mobilitysqr/.local/lib/python3.6/site-packages/rest_framework/views.py", line 495, in dispatch
    response = self.handle_exception(exc)
  File "/home/mobilitysqr/.local/lib/python3.6/site-packages/rest_framework/views.py", line 455, in handle_exception
    self.raise_uncaught_exception(exc)
  File "/home/mobilitysqr/.local/lib/python3.6/site-packages/rest_framework/views.py", line 492, in dispatch
    response = handler(request, *args, **kwargs)
  File "/var/www/html/mobilitysqrapi/mobility_apps/letter/views.py", line 109, in get
    datas['AssignmentEndDate']=self.date_format(date=data['Actual_End_Date'])
  File "/var/www/html/mobilitysqrapi/mobility_apps/letter/views.py", line 518, in date_format
    utc = datetime.strptime(date, '%Y-%m-%dT%H:%M:%S.%fZ')
  File "/usr/lib/python3.6/_strptime.py", line 565, in _strptime_datetime
    tt, fraction = _strptime(data_string, format)
  File "/usr/lib/python3.6/_strptime.py", line 362, in _strptime
    (data_string, format))
ValueError: time data 'None' does not match format '%Y-%m-%dT%H:%M:%S.%fZ'
ERROR|23/Nov/2020 14:23:51|basehttp|51049|139758923753216|"GET /getassignmentletter/?travel_req_id=TR185141 HTTP/1.1" 500 17829
ERROR|23/Nov/2020 14:24:00|log|51049|139758923753216|Internal Server Error: /getassignmentletter/
Traceback (most recent call last):
  File "/home/mobilitysqr/.local/lib/python3.6/site-packages/django/core/handlers/exception.py", line 34, in inner
    response = get_response(request)
  File "/home/mobilitysqr/.local/lib/python3.6/site-packages/django/core/handlers/base.py", line 126, in _get_response
    response = self.process_exception_by_middleware(e, request)
  File "/home/mobilitysqr/.local/lib/python3.6/site-packages/django/core/handlers/base.py", line 124, in _get_response
    response = wrapped_callback(request, *callback_args, **callback_kwargs)
  File "/home/mobilitysqr/.local/lib/python3.6/site-packages/django/views/decorators/csrf.py", line 54, in wrapped_view
    return view_func(*args, **kwargs)
  File "/home/mobilitysqr/.local/lib/python3.6/site-packages/django/views/generic/base.py", line 68, in view
    return self.dispatch(request, *args, **kwargs)
  File "/home/mobilitysqr/.local/lib/python3.6/site-packages/rest_framework/views.py", line 495, in dispatch
    response = self.handle_exception(exc)
  File "/home/mobilitysqr/.local/lib/python3.6/site-packages/rest_framework/views.py", line 455, in handle_exception
    self.raise_uncaught_exception(exc)
  File "/home/mobilitysqr/.local/lib/python3.6/site-packages/rest_framework/views.py", line 492, in dispatch
    response = handler(request, *args, **kwargs)
  File "/var/www/html/mobilitysqrapi/mobility_apps/letter/views.py", line 109, in get
    datas['AssignmentEndDate']=self.date_format(date=data['Actual_End_Date'])
  File "/var/www/html/mobilitysqrapi/mobility_apps/letter/views.py", line 518, in date_format
    utc = datetime.strptime(date, '%Y-%m-%dT%H:%M:%S.%fZ')
  File "/usr/lib/python3.6/_strptime.py", line 565, in _strptime_datetime
    tt, fraction = _strptime(data_string, format)
  File "/usr/lib/python3.6/_strptime.py", line 362, in _strptime
    (data_string, format))
ValueError: time data 'None' does not match format '%Y-%m-%dT%H:%M:%S.%fZ'
ERROR|23/Nov/2020 14:24:00|basehttp|51049|139758923753216|"GET /getassignmentletter/?travel_req_id=TR185141 HTTP/1.1" 500 17829
ERROR|23/Nov/2020 14:29:13|log|51367|140222734931712|Internal Server Error: /getassignmentletter/
Traceback (most recent call last):
  File "/home/mobilitysqr/.local/lib/python3.6/site-packages/django/core/handlers/exception.py", line 34, in inner
    response = get_response(request)
  File "/home/mobilitysqr/.local/lib/python3.6/site-packages/django/core/handlers/base.py", line 126, in _get_response
    response = self.process_exception_by_middleware(e, request)
  File "/home/mobilitysqr/.local/lib/python3.6/site-packages/django/core/handlers/base.py", line 124, in _get_response
    response = wrapped_callback(request, *callback_args, **callback_kwargs)
  File "/home/mobilitysqr/.local/lib/python3.6/site-packages/django/views/decorators/csrf.py", line 54, in wrapped_view
    return view_func(*args, **kwargs)
  File "/home/mobilitysqr/.local/lib/python3.6/site-packages/django/views/generic/base.py", line 68, in view
    return self.dispatch(request, *args, **kwargs)
  File "/home/mobilitysqr/.local/lib/python3.6/site-packages/rest_framework/views.py", line 495, in dispatch
    response = self.handle_exception(exc)
  File "/home/mobilitysqr/.local/lib/python3.6/site-packages/rest_framework/views.py", line 455, in handle_exception
    self.raise_uncaught_exception(exc)
  File "/home/mobilitysqr/.local/lib/python3.6/site-packages/rest_framework/views.py", line 492, in dispatch
    response = handler(request, *args, **kwargs)
  File "/var/www/html/mobilitysqrapi/mobility_apps/letter/views.py", line 109, in get
    datas['AssignmentEndDate']=self.date_format(date=data['Actual_End_Date'])
  File "/var/www/html/mobilitysqrapi/mobility_apps/letter/views.py", line 518, in date_format
    utc = datetime.strptime(date, '%Y-%m-%d')
  File "/usr/lib/python3.6/_strptime.py", line 565, in _strptime_datetime
    tt, fraction = _strptime(data_string, format)
  File "/usr/lib/python3.6/_strptime.py", line 362, in _strptime
    (data_string, format))
ValueError: time data 'None' does not match format '%Y-%m-%d'
ERROR|23/Nov/2020 14:29:13|basehttp|51367|140222734931712|"GET /getassignmentletter/?travel_req_id=TR185141 HTTP/1.1" 500 17791
ERROR|23/Nov/2020 14:29:16|log|51367|140222734931712|Internal Server Error: /getassignmentletter/
Traceback (most recent call last):
  File "/home/mobilitysqr/.local/lib/python3.6/site-packages/django/core/handlers/exception.py", line 34, in inner
    response = get_response(request)
  File "/home/mobilitysqr/.local/lib/python3.6/site-packages/django/core/handlers/base.py", line 126, in _get_response
    response = self.process_exception_by_middleware(e, request)
  File "/home/mobilitysqr/.local/lib/python3.6/site-packages/django/core/handlers/base.py", line 124, in _get_response
    response = wrapped_callback(request, *callback_args, **callback_kwargs)
  File "/home/mobilitysqr/.local/lib/python3.6/site-packages/django/views/decorators/csrf.py", line 54, in wrapped_view
    return view_func(*args, **kwargs)
  File "/home/mobilitysqr/.local/lib/python3.6/site-packages/django/views/generic/base.py", line 68, in view
    return self.dispatch(request, *args, **kwargs)
  File "/home/mobilitysqr/.local/lib/python3.6/site-packages/rest_framework/views.py", line 495, in dispatch
    response = self.handle_exception(exc)
  File "/home/mobilitysqr/.local/lib/python3.6/site-packages/rest_framework/views.py", line 455, in handle_exception
    self.raise_uncaught_exception(exc)
  File "/home/mobilitysqr/.local/lib/python3.6/site-packages/rest_framework/views.py", line 492, in dispatch
    response = handler(request, *args, **kwargs)
  File "/var/www/html/mobilitysqrapi/mobility_apps/letter/views.py", line 109, in get
    datas['AssignmentEndDate']=self.date_format(date=data['Actual_End_Date'])
  File "/var/www/html/mobilitysqrapi/mobility_apps/letter/views.py", line 518, in date_format
    utc = datetime.strptime(date, '%Y-%m-%d')
  File "/usr/lib/python3.6/_strptime.py", line 565, in _strptime_datetime
    tt, fraction = _strptime(data_string, format)
  File "/usr/lib/python3.6/_strptime.py", line 362, in _strptime
    (data_string, format))
ValueError: time data 'None' does not match format '%Y-%m-%d'
ERROR|23/Nov/2020 14:29:16|basehttp|51367|140222734931712|"GET /getassignmentletter/?travel_req_id=TR185141 HTTP/1.1" 500 17790
ERROR|23/Nov/2020 14:29:19|log|51367|140222734931712|Internal Server Error: /getassignmentletter/
Traceback (most recent call last):
  File "/home/mobilitysqr/.local/lib/python3.6/site-packages/django/core/handlers/exception.py", line 34, in inner
    response = get_response(request)
  File "/home/mobilitysqr/.local/lib/python3.6/site-packages/django/core/handlers/base.py", line 126, in _get_response
    response = self.process_exception_by_middleware(e, request)
  File "/home/mobilitysqr/.local/lib/python3.6/site-packages/django/core/handlers/base.py", line 124, in _get_response
    response = wrapped_callback(request, *callback_args, **callback_kwargs)
  File "/home/mobilitysqr/.local/lib/python3.6/site-packages/django/views/decorators/csrf.py", line 54, in wrapped_view
    return view_func(*args, **kwargs)
  File "/home/mobilitysqr/.local/lib/python3.6/site-packages/django/views/generic/base.py", line 68, in view
    return self.dispatch(request, *args, **kwargs)
  File "/home/mobilitysqr/.local/lib/python3.6/site-packages/rest_framework/views.py", line 495, in dispatch
    response = self.handle_exception(exc)
  File "/home/mobilitysqr/.local/lib/python3.6/site-packages/rest_framework/views.py", line 455, in handle_exception
    self.raise_uncaught_exception(exc)
  File "/home/mobilitysqr/.local/lib/python3.6/site-packages/rest_framework/views.py", line 492, in dispatch
    response = handler(request, *args, **kwargs)
  File "/var/www/html/mobilitysqrapi/mobility_apps/letter/views.py", line 109, in get
    datas['AssignmentEndDate']=self.date_format(date=data['Actual_End_Date'])
  File "/var/www/html/mobilitysqrapi/mobility_apps/letter/views.py", line 518, in date_format
    utc = datetime.strptime(date, '%Y-%m-%d')
  File "/usr/lib/python3.6/_strptime.py", line 565, in _strptime_datetime
    tt, fraction = _strptime(data_string, format)
  File "/usr/lib/python3.6/_strptime.py", line 362, in _strptime
    (data_string, format))
ValueError: time data 'None' does not match format '%Y-%m-%d'
ERROR|23/Nov/2020 14:29:19|basehttp|51367|140222734931712|"GET /getassignmentletter/?travel_req_id=TR185141 HTTP/1.1" 500 17790
ERROR|23/Nov/2020 14:31:20|log|51532|139838707803904|Internal Server Error: /getassignmentletter/
Traceback (most recent call last):
  File "/home/mobilitysqr/.local/lib/python3.6/site-packages/django/core/handlers/exception.py", line 34, in inner
    response = get_response(request)
  File "/home/mobilitysqr/.local/lib/python3.6/site-packages/django/core/handlers/base.py", line 126, in _get_response
    response = self.process_exception_by_middleware(e, request)
  File "/home/mobilitysqr/.local/lib/python3.6/site-packages/django/core/handlers/base.py", line 124, in _get_response
    response = wrapped_callback(request, *callback_args, **callback_kwargs)
  File "/home/mobilitysqr/.local/lib/python3.6/site-packages/django/views/decorators/csrf.py", line 54, in wrapped_view
    return view_func(*args, **kwargs)
  File "/home/mobilitysqr/.local/lib/python3.6/site-packages/django/views/generic/base.py", line 68, in view
    return self.dispatch(request, *args, **kwargs)
  File "/home/mobilitysqr/.local/lib/python3.6/site-packages/rest_framework/views.py", line 495, in dispatch
    response = self.handle_exception(exc)
  File "/home/mobilitysqr/.local/lib/python3.6/site-packages/rest_framework/views.py", line 455, in handle_exception
    self.raise_uncaught_exception(exc)
  File "/home/mobilitysqr/.local/lib/python3.6/site-packages/rest_framework/views.py", line 492, in dispatch
    response = handler(request, *args, **kwargs)
  File "/var/www/html/mobilitysqrapi/mobility_apps/letter/views.py", line 108, in get
    datas['AssignmentStartDate']=self.date_format(date=data['Actual_Start_Date'])
  File "/var/www/html/mobilitysqrapi/mobility_apps/letter/views.py", line 518, in date_format
    utc = datetime.strptime(date, '%Y-%m-%dT%H:%M:%S')
  File "/usr/lib/python3.6/_strptime.py", line 565, in _strptime_datetime
    tt, fraction = _strptime(data_string, format)
  File "/usr/lib/python3.6/_strptime.py", line 365, in _strptime
    data_string[found.end():])
ValueError: unconverted data remains: .
ERROR|23/Nov/2020 14:31:20|basehttp|51532|139838707803904|"GET /getassignmentletter/?travel_req_id=TR185141 HTTP/1.1" 500 17764
ERROR|23/Nov/2020 14:31:24|log|51532|139838707803904|Internal Server Error: /getassignmentletter/
Traceback (most recent call last):
  File "/home/mobilitysqr/.local/lib/python3.6/site-packages/django/core/handlers/exception.py", line 34, in inner
    response = get_response(request)
  File "/home/mobilitysqr/.local/lib/python3.6/site-packages/django/core/handlers/base.py", line 126, in _get_response
    response = self.process_exception_by_middleware(e, request)
  File "/home/mobilitysqr/.local/lib/python3.6/site-packages/django/core/handlers/base.py", line 124, in _get_response
    response = wrapped_callback(request, *callback_args, **callback_kwargs)
  File "/home/mobilitysqr/.local/lib/python3.6/site-packages/django/views/decorators/csrf.py", line 54, in wrapped_view
    return view_func(*args, **kwargs)
  File "/home/mobilitysqr/.local/lib/python3.6/site-packages/django/views/generic/base.py", line 68, in view
    return self.dispatch(request, *args, **kwargs)
  File "/home/mobilitysqr/.local/lib/python3.6/site-packages/rest_framework/views.py", line 495, in dispatch
    response = self.handle_exception(exc)
  File "/home/mobilitysqr/.local/lib/python3.6/site-packages/rest_framework/views.py", line 455, in handle_exception
    self.raise_uncaught_exception(exc)
  File "/home/mobilitysqr/.local/lib/python3.6/site-packages/rest_framework/views.py", line 492, in dispatch
    response = handler(request, *args, **kwargs)
  File "/var/www/html/mobilitysqrapi/mobility_apps/letter/views.py", line 108, in get
    datas['AssignmentStartDate']=self.date_format(date=data['Actual_Start_Date'])
  File "/var/www/html/mobilitysqrapi/mobility_apps/letter/views.py", line 518, in date_format
    utc = datetime.strptime(date, '%Y-%m-%dT%H:%M:%S')
  File "/usr/lib/python3.6/_strptime.py", line 565, in _strptime_datetime
    tt, fraction = _strptime(data_string, format)
  File "/usr/lib/python3.6/_strptime.py", line 365, in _strptime
    data_string[found.end():])
ValueError: unconverted data remains: .
ERROR|23/Nov/2020 14:31:24|basehttp|51532|139838707803904|"GET /getassignmentletter/?travel_req_id=TR185141 HTTP/1.1" 500 17764
ERROR|23/Nov/2020 14:32:00|log|51567|139702191748864|Internal Server Error: /getassignmentletter/
Traceback (most recent call last):
  File "/home/mobilitysqr/.local/lib/python3.6/site-packages/django/core/handlers/exception.py", line 34, in inner
    response = get_response(request)
  File "/home/mobilitysqr/.local/lib/python3.6/site-packages/django/core/handlers/base.py", line 126, in _get_response
    response = self.process_exception_by_middleware(e, request)
  File "/home/mobilitysqr/.local/lib/python3.6/site-packages/django/core/handlers/base.py", line 124, in _get_response
    response = wrapped_callback(request, *callback_args, **callback_kwargs)
  File "/home/mobilitysqr/.local/lib/python3.6/site-packages/django/views/decorators/csrf.py", line 54, in wrapped_view
    return view_func(*args, **kwargs)
  File "/home/mobilitysqr/.local/lib/python3.6/site-packages/django/views/generic/base.py", line 68, in view
    return self.dispatch(request, *args, **kwargs)
  File "/home/mobilitysqr/.local/lib/python3.6/site-packages/rest_framework/views.py", line 495, in dispatch
    response = self.handle_exception(exc)
  File "/home/mobilitysqr/.local/lib/python3.6/site-packages/rest_framework/views.py", line 455, in handle_exception
    self.raise_uncaught_exception(exc)
  File "/home/mobilitysqr/.local/lib/python3.6/site-packages/rest_framework/views.py", line 492, in dispatch
    response = handler(request, *args, **kwargs)
  File "/var/www/html/mobilitysqrapi/mobility_apps/letter/views.py", line 108, in get
    datas['AssignmentStartDate']=self.date_format(date=data['Actual_Start_Date'])
  File "/var/www/html/mobilitysqrapi/mobility_apps/letter/views.py", line 518, in date_format
    utc = datetime.strptime(date, '%Y-%m-%dT%H:%M:%S')
  File "/usr/lib/python3.6/_strptime.py", line 565, in _strptime_datetime
    tt, fraction = _strptime(data_string, format)
  File "/usr/lib/python3.6/_strptime.py", line 365, in _strptime
    data_string[found.end():])
ValueError: unconverted data remains: .0
ERROR|23/Nov/2020 14:32:00|basehttp|51567|139702191748864|"GET /getassignmentletter/?travel_req_id=TR185141 HTTP/1.1" 500 17766
ERROR|23/Nov/2020 14:32:03|log|51567|139702181783296|Internal Server Error: /getassignmentletter/
Traceback (most recent call last):
  File "/home/mobilitysqr/.local/lib/python3.6/site-packages/django/core/handlers/exception.py", line 34, in inner
    response = get_response(request)
  File "/home/mobilitysqr/.local/lib/python3.6/site-packages/django/core/handlers/base.py", line 126, in _get_response
    response = self.process_exception_by_middleware(e, request)
  File "/home/mobilitysqr/.local/lib/python3.6/site-packages/django/core/handlers/base.py", line 124, in _get_response
    response = wrapped_callback(request, *callback_args, **callback_kwargs)
  File "/home/mobilitysqr/.local/lib/python3.6/site-packages/django/views/decorators/csrf.py", line 54, in wrapped_view
    return view_func(*args, **kwargs)
  File "/home/mobilitysqr/.local/lib/python3.6/site-packages/django/views/generic/base.py", line 68, in view
    return self.dispatch(request, *args, **kwargs)
  File "/home/mobilitysqr/.local/lib/python3.6/site-packages/rest_framework/views.py", line 495, in dispatch
    response = self.handle_exception(exc)
  File "/home/mobilitysqr/.local/lib/python3.6/site-packages/rest_framework/views.py", line 455, in handle_exception
    self.raise_uncaught_exception(exc)
  File "/home/mobilitysqr/.local/lib/python3.6/site-packages/rest_framework/views.py", line 492, in dispatch
    response = handler(request, *args, **kwargs)
  File "/var/www/html/mobilitysqrapi/mobility_apps/letter/views.py", line 108, in get
    datas['AssignmentStartDate']=self.date_format(date=data['Actual_Start_Date'])
  File "/var/www/html/mobilitysqrapi/mobility_apps/letter/views.py", line 518, in date_format
    utc = datetime.strptime(date, '%Y-%m-%dT%H:%M:%S')
  File "/usr/lib/python3.6/_strptime.py", line 565, in _strptime_datetime
    tt, fraction = _strptime(data_string, format)
  File "/usr/lib/python3.6/_strptime.py", line 365, in _strptime
    data_string[found.end():])
ValueError: unconverted data remains: .0
ERROR|23/Nov/2020 14:32:03|basehttp|51567|139702181783296|"GET /getassignmentletter/?travel_req_id=TR185141 HTTP/1.1" 500 17767
ERROR|23/Nov/2020 14:32:32|log|51588|139745024091904|Internal Server Error: /getassignmentletter/
Traceback (most recent call last):
  File "/home/mobilitysqr/.local/lib/python3.6/site-packages/django/core/handlers/exception.py", line 34, in inner
    response = get_response(request)
  File "/home/mobilitysqr/.local/lib/python3.6/site-packages/django/core/handlers/base.py", line 126, in _get_response
    response = self.process_exception_by_middleware(e, request)
  File "/home/mobilitysqr/.local/lib/python3.6/site-packages/django/core/handlers/base.py", line 124, in _get_response
    response = wrapped_callback(request, *callback_args, **callback_kwargs)
  File "/home/mobilitysqr/.local/lib/python3.6/site-packages/django/views/decorators/csrf.py", line 54, in wrapped_view
    return view_func(*args, **kwargs)
  File "/home/mobilitysqr/.local/lib/python3.6/site-packages/django/views/generic/base.py", line 68, in view
    return self.dispatch(request, *args, **kwargs)
  File "/home/mobilitysqr/.local/lib/python3.6/site-packages/rest_framework/views.py", line 495, in dispatch
    response = self.handle_exception(exc)
  File "/home/mobilitysqr/.local/lib/python3.6/site-packages/rest_framework/views.py", line 455, in handle_exception
    self.raise_uncaught_exception(exc)
  File "/home/mobilitysqr/.local/lib/python3.6/site-packages/rest_framework/views.py", line 492, in dispatch
    response = handler(request, *args, **kwargs)
  File "/var/www/html/mobilitysqrapi/mobility_apps/letter/views.py", line 108, in get
    datas['AssignmentStartDate']=self.date_format(date=data['Actual_Start_Date'])
  File "/var/www/html/mobilitysqrapi/mobility_apps/letter/views.py", line 518, in date_format
    utc = datetime.strptime(date, '%Y-%m-%dT%H:%M:%S')
  File "/usr/lib/python3.6/_strptime.py", line 565, in _strptime_datetime
    tt, fraction = _strptime(data_string, format)
  File "/usr/lib/python3.6/_strptime.py", line 365, in _strptime
    data_string[found.end():])
ValueError: unconverted data remains: .00
ERROR|23/Nov/2020 14:32:32|basehttp|51588|139745024091904|"GET /getassignmentletter/?travel_req_id=TR185141 HTTP/1.1" 500 17768
ERROR|23/Nov/2020 14:33:34|basehttp|51588|139744945633024|"GET /getassignmentletter/?travel_req_id=TR185141 HTTP/1.1" 500 59
ERROR|23/Nov/2020 14:33:40|log|51721|139890358712064|Internal Server Error: /getassignmentletter/
Traceback (most recent call last):
  File "/home/mobilitysqr/.local/lib/python3.6/site-packages/django/core/handlers/exception.py", line 34, in inner
    response = get_response(request)
  File "/home/mobilitysqr/.local/lib/python3.6/site-packages/django/core/handlers/base.py", line 126, in _get_response
    response = self.process_exception_by_middleware(e, request)
  File "/home/mobilitysqr/.local/lib/python3.6/site-packages/django/core/handlers/base.py", line 124, in _get_response
    response = wrapped_callback(request, *callback_args, **callback_kwargs)
  File "/home/mobilitysqr/.local/lib/python3.6/site-packages/django/views/decorators/csrf.py", line 54, in wrapped_view
    return view_func(*args, **kwargs)
  File "/home/mobilitysqr/.local/lib/python3.6/site-packages/django/views/generic/base.py", line 68, in view
    return self.dispatch(request, *args, **kwargs)
  File "/home/mobilitysqr/.local/lib/python3.6/site-packages/rest_framework/views.py", line 495, in dispatch
    response = self.handle_exception(exc)
  File "/home/mobilitysqr/.local/lib/python3.6/site-packages/rest_framework/views.py", line 455, in handle_exception
    self.raise_uncaught_exception(exc)
  File "/home/mobilitysqr/.local/lib/python3.6/site-packages/rest_framework/views.py", line 492, in dispatch
    response = handler(request, *args, **kwargs)
  File "/var/www/html/mobilitysqrapi/mobility_apps/letter/views.py", line 109, in get
    datas['AssignmentEndDate']=self.date_format(date=data['Actual_End_Date'])
  File "/var/www/html/mobilitysqrapi/mobility_apps/letter/views.py", line 518, in date_format
    utc = datetime.strptime(date, '%Y-%m-%dT%H:%M:%S')
  File "/usr/lib/python3.6/_strptime.py", line 565, in _strptime_datetime
    tt, fraction = _strptime(data_string, format)
  File "/usr/lib/python3.6/_strptime.py", line 362, in _strptime
    (data_string, format))
ValueError: time data 'None' does not match format '%Y-%m-%dT%H:%M:%S'
ERROR|23/Nov/2020 14:33:40|basehttp|51721|139890358712064|"GET /getassignmentletter/?travel_req_id=TR185141 HTTP/1.1" 500 17817
ERROR|23/Nov/2020 15:09:44|log|53204|140306112575232|Internal Server Error: /getassignmentletter/
Traceback (most recent call last):
  File "/home/mobilitysqr/.local/lib/python3.6/site-packages/django/core/handlers/exception.py", line 34, in inner
    response = get_response(request)
  File "/home/mobilitysqr/.local/lib/python3.6/site-packages/django/core/handlers/base.py", line 126, in _get_response
    response = self.process_exception_by_middleware(e, request)
  File "/home/mobilitysqr/.local/lib/python3.6/site-packages/django/core/handlers/base.py", line 124, in _get_response
    response = wrapped_callback(request, *callback_args, **callback_kwargs)
  File "/home/mobilitysqr/.local/lib/python3.6/site-packages/django/views/decorators/csrf.py", line 54, in wrapped_view
    return view_func(*args, **kwargs)
  File "/home/mobilitysqr/.local/lib/python3.6/site-packages/django/views/generic/base.py", line 68, in view
    return self.dispatch(request, *args, **kwargs)
  File "/home/mobilitysqr/.local/lib/python3.6/site-packages/rest_framework/views.py", line 495, in dispatch
    response = self.handle_exception(exc)
  File "/home/mobilitysqr/.local/lib/python3.6/site-packages/rest_framework/views.py", line 455, in handle_exception
    self.raise_uncaught_exception(exc)
  File "/home/mobilitysqr/.local/lib/python3.6/site-packages/rest_framework/views.py", line 492, in dispatch
    response = handler(request, *args, **kwargs)
  File "/var/www/html/mobilitysqrapi/mobility_apps/letter/views.py", line 108, in get
    datas['AssignmentStartDate']=self.date_format(date=data['Actual_Start_Date'])
  File "/var/www/html/mobilitysqrapi/mobility_apps/letter/views.py", line 518, in date_format
    utc = datetime.date.strftime(date, "%m/%d/%Y")
AttributeError: 'method_descriptor' object has no attribute 'strftime'
ERROR|23/Nov/2020 15:09:44|basehttp|53204|140306112575232|"GET /getassignmentletter/?travel_req_id=TR185141 HTTP/1.1" 500 17591
ERROR|23/Nov/2020 15:11:09|log|53257|139770860238592|Internal Server Error: /getassignmentletter/
Traceback (most recent call last):
  File "/home/mobilitysqr/.local/lib/python3.6/site-packages/django/core/handlers/exception.py", line 34, in inner
    response = get_response(request)
  File "/home/mobilitysqr/.local/lib/python3.6/site-packages/django/core/handlers/base.py", line 126, in _get_response
    response = self.process_exception_by_middleware(e, request)
  File "/home/mobilitysqr/.local/lib/python3.6/site-packages/django/core/handlers/base.py", line 124, in _get_response
    response = wrapped_callback(request, *callback_args, **callback_kwargs)
  File "/home/mobilitysqr/.local/lib/python3.6/site-packages/django/views/decorators/csrf.py", line 54, in wrapped_view
    return view_func(*args, **kwargs)
  File "/home/mobilitysqr/.local/lib/python3.6/site-packages/django/views/generic/base.py", line 68, in view
    return self.dispatch(request, *args, **kwargs)
  File "/home/mobilitysqr/.local/lib/python3.6/site-packages/rest_framework/views.py", line 495, in dispatch
    response = self.handle_exception(exc)
  File "/home/mobilitysqr/.local/lib/python3.6/site-packages/rest_framework/views.py", line 455, in handle_exception
    self.raise_uncaught_exception(exc)
  File "/home/mobilitysqr/.local/lib/python3.6/site-packages/rest_framework/views.py", line 492, in dispatch
    response = handler(request, *args, **kwargs)
  File "/var/www/html/mobilitysqrapi/mobility_apps/letter/views.py", line 108, in get
    datas['AssignmentStartDate']=self.date_format(date=data['Actual_Start_Date'])
  File "/var/www/html/mobilitysqrapi/mobility_apps/letter/views.py", line 518, in date_format
    utc = datetime.date.strftime(date, "%m/%d/%Y")
AttributeError: 'method_descriptor' object has no attribute 'strftime'
ERROR|23/Nov/2020 15:11:09|basehttp|53257|139770860238592|"GET /getassignmentletter/?travel_req_id=TR185141 HTTP/1.1" 500 17590
ERROR|23/Nov/2020 15:12:06|log|53474|140422936786688|Internal Server Error: /getassignmentletter/
Traceback (most recent call last):
  File "/home/mobilitysqr/.local/lib/python3.6/site-packages/django/core/handlers/exception.py", line 34, in inner
    response = get_response(request)
  File "/home/mobilitysqr/.local/lib/python3.6/site-packages/django/core/handlers/base.py", line 126, in _get_response
    response = self.process_exception_by_middleware(e, request)
  File "/home/mobilitysqr/.local/lib/python3.6/site-packages/django/core/handlers/base.py", line 124, in _get_response
    response = wrapped_callback(request, *callback_args, **callback_kwargs)
  File "/home/mobilitysqr/.local/lib/python3.6/site-packages/django/views/decorators/csrf.py", line 54, in wrapped_view
    return view_func(*args, **kwargs)
  File "/home/mobilitysqr/.local/lib/python3.6/site-packages/django/views/generic/base.py", line 68, in view
    return self.dispatch(request, *args, **kwargs)
  File "/home/mobilitysqr/.local/lib/python3.6/site-packages/rest_framework/views.py", line 495, in dispatch
    response = self.handle_exception(exc)
  File "/home/mobilitysqr/.local/lib/python3.6/site-packages/rest_framework/views.py", line 455, in handle_exception
    self.raise_uncaught_exception(exc)
  File "/home/mobilitysqr/.local/lib/python3.6/site-packages/rest_framework/views.py", line 492, in dispatch
    response = handler(request, *args, **kwargs)
  File "/var/www/html/mobilitysqrapi/mobility_apps/letter/views.py", line 108, in get
    datas['AssignmentStartDate']=self.date_format(date=data['Actual_Start_Date'])
  File "/var/www/html/mobilitysqrapi/mobility_apps/letter/views.py", line 518, in date_format
    utc = datetime.date.strftime(date, "%m/%d/%Y")
AttributeError: 'method_descriptor' object has no attribute 'strftime'
ERROR|23/Nov/2020 15:12:06|basehttp|53474|140422936786688|"GET /getassignmentletter/?travel_req_id=TR185141 HTTP/1.1" 500 17590
ERROR|23/Nov/2020 15:12:14|log|53474|140422926296832|Internal Server Error: /getassignmentletter/
Traceback (most recent call last):
  File "/home/mobilitysqr/.local/lib/python3.6/site-packages/django/core/handlers/exception.py", line 34, in inner
    response = get_response(request)
  File "/home/mobilitysqr/.local/lib/python3.6/site-packages/django/core/handlers/base.py", line 126, in _get_response
    response = self.process_exception_by_middleware(e, request)
  File "/home/mobilitysqr/.local/lib/python3.6/site-packages/django/core/handlers/base.py", line 124, in _get_response
    response = wrapped_callback(request, *callback_args, **callback_kwargs)
  File "/home/mobilitysqr/.local/lib/python3.6/site-packages/django/views/decorators/csrf.py", line 54, in wrapped_view
    return view_func(*args, **kwargs)
  File "/home/mobilitysqr/.local/lib/python3.6/site-packages/django/views/generic/base.py", line 68, in view
    return self.dispatch(request, *args, **kwargs)
  File "/home/mobilitysqr/.local/lib/python3.6/site-packages/rest_framework/views.py", line 495, in dispatch
    response = self.handle_exception(exc)
  File "/home/mobilitysqr/.local/lib/python3.6/site-packages/rest_framework/views.py", line 455, in handle_exception
    self.raise_uncaught_exception(exc)
  File "/home/mobilitysqr/.local/lib/python3.6/site-packages/rest_framework/views.py", line 492, in dispatch
    response = handler(request, *args, **kwargs)
  File "/var/www/html/mobilitysqrapi/mobility_apps/letter/views.py", line 108, in get
    datas['AssignmentStartDate']=self.date_format(date=data['Actual_Start_Date'])
  File "/var/www/html/mobilitysqrapi/mobility_apps/letter/views.py", line 518, in date_format
    utc = datetime.date.strftime(date, "%m/%d/%Y")
AttributeError: 'method_descriptor' object has no attribute 'strftime'
ERROR|23/Nov/2020 15:12:14|basehttp|53474|140422926296832|"GET /getassignmentletter/?travel_req_id=TR185141 HTTP/1.1" 500 17591
ERROR|23/Nov/2020 15:13:18|log|53548|139666350372608|Internal Server Error: /getassignmentletter/
Traceback (most recent call last):
  File "/home/mobilitysqr/.local/lib/python3.6/site-packages/django/core/handlers/exception.py", line 34, in inner
    response = get_response(request)
  File "/home/mobilitysqr/.local/lib/python3.6/site-packages/django/core/handlers/base.py", line 126, in _get_response
    response = self.process_exception_by_middleware(e, request)
  File "/home/mobilitysqr/.local/lib/python3.6/site-packages/django/core/handlers/base.py", line 124, in _get_response
    response = wrapped_callback(request, *callback_args, **callback_kwargs)
  File "/home/mobilitysqr/.local/lib/python3.6/site-packages/django/views/decorators/csrf.py", line 54, in wrapped_view
    return view_func(*args, **kwargs)
  File "/home/mobilitysqr/.local/lib/python3.6/site-packages/django/views/generic/base.py", line 68, in view
    return self.dispatch(request, *args, **kwargs)
  File "/home/mobilitysqr/.local/lib/python3.6/site-packages/rest_framework/views.py", line 495, in dispatch
    response = self.handle_exception(exc)
  File "/home/mobilitysqr/.local/lib/python3.6/site-packages/rest_framework/views.py", line 455, in handle_exception
    self.raise_uncaught_exception(exc)
  File "/home/mobilitysqr/.local/lib/python3.6/site-packages/rest_framework/views.py", line 492, in dispatch
    response = handler(request, *args, **kwargs)
  File "/var/www/html/mobilitysqrapi/mobility_apps/letter/views.py", line 108, in get
    datas['AssignmentStartDate']=self.date_format(date=data['Actual_Start_Date'])
  File "/var/www/html/mobilitysqrapi/mobility_apps/letter/views.py", line 518, in date_format
    utc = datetime.strftime(date, "%m/%d/%Y")
TypeError: descriptor 'strftime' requires a 'datetime.date' object but received a 'str'
ERROR|23/Nov/2020 15:13:18|basehttp|53548|139666350372608|"GET /getassignmentletter/?travel_req_id=TR185141 HTTP/1.1" 500 17619
ERROR|23/Nov/2020 18:49:56|log|60074|139808326194944|Internal Server Error: /getassignmentletter/
Traceback (most recent call last):
  File "/home/mobilitysqr/.local/lib/python3.6/site-packages/django/core/handlers/exception.py", line 34, in inner
    response = get_response(request)
  File "/home/mobilitysqr/.local/lib/python3.6/site-packages/django/core/handlers/base.py", line 126, in _get_response
    response = self.process_exception_by_middleware(e, request)
  File "/home/mobilitysqr/.local/lib/python3.6/site-packages/django/core/handlers/base.py", line 124, in _get_response
    response = wrapped_callback(request, *callback_args, **callback_kwargs)
  File "/home/mobilitysqr/.local/lib/python3.6/site-packages/django/views/decorators/csrf.py", line 54, in wrapped_view
    return view_func(*args, **kwargs)
  File "/home/mobilitysqr/.local/lib/python3.6/site-packages/django/views/generic/base.py", line 68, in view
    return self.dispatch(request, *args, **kwargs)
  File "/home/mobilitysqr/.local/lib/python3.6/site-packages/rest_framework/views.py", line 495, in dispatch
    response = self.handle_exception(exc)
  File "/home/mobilitysqr/.local/lib/python3.6/site-packages/rest_framework/views.py", line 455, in handle_exception
    self.raise_uncaught_exception(exc)
  File "/home/mobilitysqr/.local/lib/python3.6/site-packages/rest_framework/views.py", line 492, in dispatch
    response = handler(request, *args, **kwargs)
  File "/var/www/html/mobilitysqrapi/mobility_apps/letter/views.py", line 108, in get
    datas['AssignmentStartDate']=self.date_format(date=data['Actual_Start_Date'])
  File "/var/www/html/mobilitysqrapi/mobility_apps/letter/views.py", line 518, in date_format
    utc = datetime.datetime.strftime(date, "%m/%d/%Y")
AttributeError: type object 'datetime.datetime' has no attribute 'datetime'
ERROR|23/Nov/2020 18:49:56|basehttp|60074|139808326194944|"GET /getassignmentletter/?travel_req_id=TR185141 HTTP/1.1" 500 17605
ERROR|23/Nov/2020 18:50:42|log|60097|139654533359360|Internal Server Error: /getassignmentletter/
Traceback (most recent call last):
  File "/home/mobilitysqr/.local/lib/python3.6/site-packages/django/core/handlers/exception.py", line 34, in inner
    response = get_response(request)
  File "/home/mobilitysqr/.local/lib/python3.6/site-packages/django/core/handlers/base.py", line 126, in _get_response
    response = self.process_exception_by_middleware(e, request)
  File "/home/mobilitysqr/.local/lib/python3.6/site-packages/django/core/handlers/base.py", line 124, in _get_response
    response = wrapped_callback(request, *callback_args, **callback_kwargs)
  File "/home/mobilitysqr/.local/lib/python3.6/site-packages/django/views/decorators/csrf.py", line 54, in wrapped_view
    return view_func(*args, **kwargs)
  File "/home/mobilitysqr/.local/lib/python3.6/site-packages/django/views/generic/base.py", line 68, in view
    return self.dispatch(request, *args, **kwargs)
  File "/home/mobilitysqr/.local/lib/python3.6/site-packages/rest_framework/views.py", line 495, in dispatch
    response = self.handle_exception(exc)
  File "/home/mobilitysqr/.local/lib/python3.6/site-packages/rest_framework/views.py", line 455, in handle_exception
    self.raise_uncaught_exception(exc)
  File "/home/mobilitysqr/.local/lib/python3.6/site-packages/rest_framework/views.py", line 492, in dispatch
    response = handler(request, *args, **kwargs)
  File "/var/www/html/mobilitysqrapi/mobility_apps/letter/views.py", line 108, in get
    datas['AssignmentStartDate']=self.date_format(date=data['Actual_Start_Date'])
  File "/var/www/html/mobilitysqrapi/mobility_apps/letter/views.py", line 518, in date_format
    utc = datetime.datetime.strftime(date, "%m/%d/%Y")
AttributeError: type object 'datetime.datetime' has no attribute 'datetime'
ERROR|23/Nov/2020 18:50:42|basehttp|60097|139654533359360|"GET /getassignmentletter/?travel_req_id=TR185141 HTTP/1.1" 500 17604
ERROR|23/Nov/2020 18:53:28|log|60261|140388530484992|Internal Server Error: /getassignmentletter/
Traceback (most recent call last):
  File "/home/mobilitysqr/.local/lib/python3.6/site-packages/django/core/handlers/exception.py", line 34, in inner
    response = get_response(request)
  File "/home/mobilitysqr/.local/lib/python3.6/site-packages/django/core/handlers/base.py", line 126, in _get_response
    response = self.process_exception_by_middleware(e, request)
  File "/home/mobilitysqr/.local/lib/python3.6/site-packages/django/core/handlers/base.py", line 124, in _get_response
    response = wrapped_callback(request, *callback_args, **callback_kwargs)
  File "/home/mobilitysqr/.local/lib/python3.6/site-packages/django/views/decorators/csrf.py", line 54, in wrapped_view
    return view_func(*args, **kwargs)
  File "/home/mobilitysqr/.local/lib/python3.6/site-packages/django/views/generic/base.py", line 68, in view
    return self.dispatch(request, *args, **kwargs)
  File "/home/mobilitysqr/.local/lib/python3.6/site-packages/rest_framework/views.py", line 495, in dispatch
    response = self.handle_exception(exc)
  File "/home/mobilitysqr/.local/lib/python3.6/site-packages/rest_framework/views.py", line 455, in handle_exception
    self.raise_uncaught_exception(exc)
  File "/home/mobilitysqr/.local/lib/python3.6/site-packages/rest_framework/views.py", line 492, in dispatch
    response = handler(request, *args, **kwargs)
  File "/var/www/html/mobilitysqrapi/mobility_apps/letter/views.py", line 108, in get
    datas['AssignmentStartDate']=self.date_format(date=data['Actual_Start_Date'])
  File "/var/www/html/mobilitysqrapi/mobility_apps/letter/views.py", line 518, in date_format
    utc = datetime.strftime(date, "%m/%d/%Y")
TypeError: descriptor 'strftime' requires a 'datetime.date' object but received a 'str'
ERROR|23/Nov/2020 18:53:28|basehttp|60261|140388530484992|"GET /getassignmentletter/?travel_req_id=TR185141 HTTP/1.1" 500 17619
ERROR|23/Nov/2020 18:54:35|log|60285|140115611240192|Internal Server Error: /getassignmentletter/
Traceback (most recent call last):
  File "/home/mobilitysqr/.local/lib/python3.6/site-packages/django/core/handlers/exception.py", line 34, in inner
    response = get_response(request)
  File "/home/mobilitysqr/.local/lib/python3.6/site-packages/django/core/handlers/base.py", line 126, in _get_response
    response = self.process_exception_by_middleware(e, request)
  File "/home/mobilitysqr/.local/lib/python3.6/site-packages/django/core/handlers/base.py", line 124, in _get_response
    response = wrapped_callback(request, *callback_args, **callback_kwargs)
  File "/home/mobilitysqr/.local/lib/python3.6/site-packages/django/views/decorators/csrf.py", line 54, in wrapped_view
    return view_func(*args, **kwargs)
  File "/home/mobilitysqr/.local/lib/python3.6/site-packages/django/views/generic/base.py", line 68, in view
    return self.dispatch(request, *args, **kwargs)
  File "/home/mobilitysqr/.local/lib/python3.6/site-packages/rest_framework/views.py", line 495, in dispatch
    response = self.handle_exception(exc)
  File "/home/mobilitysqr/.local/lib/python3.6/site-packages/rest_framework/views.py", line 455, in handle_exception
    self.raise_uncaught_exception(exc)
  File "/home/mobilitysqr/.local/lib/python3.6/site-packages/rest_framework/views.py", line 492, in dispatch
    response = handler(request, *args, **kwargs)
  File "/var/www/html/mobilitysqrapi/mobility_apps/letter/views.py", line 108, in get
    datas['AssignmentStartDate']=self.date_format(date=data['Actual_Start_Date'])
  File "/var/www/html/mobilitysqrapi/mobility_apps/letter/views.py", line 518, in date_format
    utc = datetime.strftime(date, "%m/%d/%Y")
TypeError: descriptor 'strftime' requires a 'datetime.date' object but received a 'str'
ERROR|23/Nov/2020 18:54:35|basehttp|60285|140115611240192|"GET /getassignmentletter/?travel_req_id=TR185141 HTTP/1.1" 500 17619
ERROR|23/Nov/2020 18:55:34|log|60404|140473990256384|Internal Server Error: /getassignmentletter/
Traceback (most recent call last):
  File "/home/mobilitysqr/.local/lib/python3.6/site-packages/django/core/handlers/exception.py", line 34, in inner
    response = get_response(request)
  File "/home/mobilitysqr/.local/lib/python3.6/site-packages/django/core/handlers/base.py", line 126, in _get_response
    response = self.process_exception_by_middleware(e, request)
  File "/home/mobilitysqr/.local/lib/python3.6/site-packages/django/core/handlers/base.py", line 124, in _get_response
    response = wrapped_callback(request, *callback_args, **callback_kwargs)
  File "/home/mobilitysqr/.local/lib/python3.6/site-packages/django/views/decorators/csrf.py", line 54, in wrapped_view
    return view_func(*args, **kwargs)
  File "/home/mobilitysqr/.local/lib/python3.6/site-packages/django/views/generic/base.py", line 68, in view
    return self.dispatch(request, *args, **kwargs)
  File "/home/mobilitysqr/.local/lib/python3.6/site-packages/rest_framework/views.py", line 495, in dispatch
    response = self.handle_exception(exc)
  File "/home/mobilitysqr/.local/lib/python3.6/site-packages/rest_framework/views.py", line 455, in handle_exception
    self.raise_uncaught_exception(exc)
  File "/home/mobilitysqr/.local/lib/python3.6/site-packages/rest_framework/views.py", line 492, in dispatch
    response = handler(request, *args, **kwargs)
  File "/var/www/html/mobilitysqrapi/mobility_apps/letter/views.py", line 108, in get
    datas['AssignmentStartDate']=self.date_format(date=data['Actual_Start_Date'])
  File "/var/www/html/mobilitysqrapi/mobility_apps/letter/views.py", line 518, in date_format
    utc = datetime.date.strftime(date, "%m/%d/%Y")
AttributeError: 'method_descriptor' object has no attribute 'strftime'
ERROR|23/Nov/2020 18:55:34|basehttp|60404|140473990256384|"GET /getassignmentletter/?travel_req_id=TR185141 HTTP/1.1" 500 17591
ERROR|23/Nov/2020 18:55:44|log|60404|140473998911232|Internal Server Error: /getassignmentletter/
Traceback (most recent call last):
  File "/home/mobilitysqr/.local/lib/python3.6/site-packages/django/core/handlers/exception.py", line 34, in inner
    response = get_response(request)
  File "/home/mobilitysqr/.local/lib/python3.6/site-packages/django/core/handlers/base.py", line 126, in _get_response
    response = self.process_exception_by_middleware(e, request)
  File "/home/mobilitysqr/.local/lib/python3.6/site-packages/django/core/handlers/base.py", line 124, in _get_response
    response = wrapped_callback(request, *callback_args, **callback_kwargs)
  File "/home/mobilitysqr/.local/lib/python3.6/site-packages/django/views/decorators/csrf.py", line 54, in wrapped_view
    return view_func(*args, **kwargs)
  File "/home/mobilitysqr/.local/lib/python3.6/site-packages/django/views/generic/base.py", line 68, in view
    return self.dispatch(request, *args, **kwargs)
  File "/home/mobilitysqr/.local/lib/python3.6/site-packages/rest_framework/views.py", line 495, in dispatch
    response = self.handle_exception(exc)
  File "/home/mobilitysqr/.local/lib/python3.6/site-packages/rest_framework/views.py", line 455, in handle_exception
    self.raise_uncaught_exception(exc)
  File "/home/mobilitysqr/.local/lib/python3.6/site-packages/rest_framework/views.py", line 492, in dispatch
    response = handler(request, *args, **kwargs)
  File "/var/www/html/mobilitysqrapi/mobility_apps/letter/views.py", line 108, in get
    datas['AssignmentStartDate']=self.date_format(date=data['Actual_Start_Date'])
  File "/var/www/html/mobilitysqrapi/mobility_apps/letter/views.py", line 518, in date_format
    utc = datetime.date.strftime(date, "%m/%d/%Y")
AttributeError: 'method_descriptor' object has no attribute 'strftime'
ERROR|23/Nov/2020 18:55:44|basehttp|60404|140473998911232|"GET /getassignmentletter/?travel_req_id=TR185141 HTTP/1.1" 500 17591
ERROR|23/Nov/2020 18:57:54|log|60437|139932022183680|Internal Server Error: /getassignmentletter/
Traceback (most recent call last):
  File "/home/mobilitysqr/.local/lib/python3.6/site-packages/django/core/handlers/exception.py", line 34, in inner
    response = get_response(request)
  File "/home/mobilitysqr/.local/lib/python3.6/site-packages/django/core/handlers/base.py", line 126, in _get_response
    response = self.process_exception_by_middleware(e, request)
  File "/home/mobilitysqr/.local/lib/python3.6/site-packages/django/core/handlers/base.py", line 124, in _get_response
    response = wrapped_callback(request, *callback_args, **callback_kwargs)
  File "/home/mobilitysqr/.local/lib/python3.6/site-packages/django/views/decorators/csrf.py", line 54, in wrapped_view
    return view_func(*args, **kwargs)
  File "/home/mobilitysqr/.local/lib/python3.6/site-packages/django/views/generic/base.py", line 68, in view
    return self.dispatch(request, *args, **kwargs)
  File "/home/mobilitysqr/.local/lib/python3.6/site-packages/rest_framework/views.py", line 495, in dispatch
    response = self.handle_exception(exc)
  File "/home/mobilitysqr/.local/lib/python3.6/site-packages/rest_framework/views.py", line 455, in handle_exception
    self.raise_uncaught_exception(exc)
  File "/home/mobilitysqr/.local/lib/python3.6/site-packages/rest_framework/views.py", line 492, in dispatch
    response = handler(request, *args, **kwargs)
  File "/var/www/html/mobilitysqrapi/mobility_apps/letter/views.py", line 108, in get
    datas['AssignmentStartDate']=self.date_format(date=data['Actual_Start_Date'])
  File "/var/www/html/mobilitysqrapi/mobility_apps/letter/views.py", line 518, in date_format
    utc = datetime.datetime.strftime(date, "%m/%d/%Y")
AttributeError: type object 'datetime.datetime' has no attribute 'datetime'
ERROR|23/Nov/2020 18:57:54|basehttp|60437|139932022183680|"GET /getassignmentletter/?travel_req_id=TR185141 HTTP/1.1" 500 17604
ERROR|23/Nov/2020 18:59:53|log|60610|139720132994816|Internal Server Error: /getassignmentletter/
Traceback (most recent call last):
  File "/home/mobilitysqr/.local/lib/python3.6/site-packages/django/core/handlers/exception.py", line 34, in inner
    response = get_response(request)
  File "/home/mobilitysqr/.local/lib/python3.6/site-packages/django/core/handlers/base.py", line 126, in _get_response
    response = self.process_exception_by_middleware(e, request)
  File "/home/mobilitysqr/.local/lib/python3.6/site-packages/django/core/handlers/base.py", line 124, in _get_response
    response = wrapped_callback(request, *callback_args, **callback_kwargs)
  File "/home/mobilitysqr/.local/lib/python3.6/site-packages/django/views/decorators/csrf.py", line 54, in wrapped_view
    return view_func(*args, **kwargs)
  File "/home/mobilitysqr/.local/lib/python3.6/site-packages/django/views/generic/base.py", line 68, in view
    return self.dispatch(request, *args, **kwargs)
  File "/home/mobilitysqr/.local/lib/python3.6/site-packages/rest_framework/views.py", line 495, in dispatch
    response = self.handle_exception(exc)
  File "/home/mobilitysqr/.local/lib/python3.6/site-packages/rest_framework/views.py", line 455, in handle_exception
    self.raise_uncaught_exception(exc)
  File "/home/mobilitysqr/.local/lib/python3.6/site-packages/rest_framework/views.py", line 492, in dispatch
    response = handler(request, *args, **kwargs)
  File "/var/www/html/mobilitysqrapi/mobility_apps/letter/views.py", line 108, in get
    datas['AssignmentStartDate']=self.date_format(date=data['Actual_Start_Date'])
  File "/var/www/html/mobilitysqrapi/mobility_apps/letter/views.py", line 518, in date_format
    utc = datetime.strftime(date, "%m/%d/%Y")
TypeError: descriptor 'strftime' requires a 'datetime.date' object but received a 'str'
ERROR|23/Nov/2020 18:59:53|basehttp|60610|139720132994816|"GET /getassignmentletter/?travel_req_id=TR185141 HTTP/1.1" 500 17619
ERROR|23/Nov/2020 19:01:27|log|60610|139720132994816|Internal Server Error: /getassignmentletter/
Traceback (most recent call last):
  File "/home/mobilitysqr/.local/lib/python3.6/site-packages/django/core/handlers/exception.py", line 34, in inner
    response = get_response(request)
  File "/home/mobilitysqr/.local/lib/python3.6/site-packages/django/core/handlers/base.py", line 126, in _get_response
    response = self.process_exception_by_middleware(e, request)
  File "/home/mobilitysqr/.local/lib/python3.6/site-packages/django/core/handlers/base.py", line 124, in _get_response
    response = wrapped_callback(request, *callback_args, **callback_kwargs)
  File "/home/mobilitysqr/.local/lib/python3.6/site-packages/django/views/decorators/csrf.py", line 54, in wrapped_view
    return view_func(*args, **kwargs)
  File "/home/mobilitysqr/.local/lib/python3.6/site-packages/django/views/generic/base.py", line 68, in view
    return self.dispatch(request, *args, **kwargs)
  File "/home/mobilitysqr/.local/lib/python3.6/site-packages/rest_framework/views.py", line 495, in dispatch
    response = self.handle_exception(exc)
  File "/home/mobilitysqr/.local/lib/python3.6/site-packages/rest_framework/views.py", line 455, in handle_exception
    self.raise_uncaught_exception(exc)
  File "/home/mobilitysqr/.local/lib/python3.6/site-packages/rest_framework/views.py", line 492, in dispatch
    response = handler(request, *args, **kwargs)
  File "/var/www/html/mobilitysqrapi/mobility_apps/letter/views.py", line 108, in get
    datas['AssignmentStartDate']=self.date_format(date=data['Actual_Start_Date'])
  File "/var/www/html/mobilitysqrapi/mobility_apps/letter/views.py", line 518, in date_format
    utc = datetime.strftime(date, "%m/%d/%Y")
TypeError: descriptor 'strftime' requires a 'datetime.date' object but received a 'str'
ERROR|23/Nov/2020 19:01:27|basehttp|60610|139720132994816|"GET /getassignmentletter/?travel_req_id=TR185141 HTTP/1.1" 500 17620
ERROR|23/Nov/2020 19:02:30|log|60610|139720050865920|Internal Server Error: /getassignmentletter/
Traceback (most recent call last):
  File "/home/mobilitysqr/.local/lib/python3.6/site-packages/django/core/handlers/exception.py", line 34, in inner
    response = get_response(request)
  File "/home/mobilitysqr/.local/lib/python3.6/site-packages/django/core/handlers/base.py", line 126, in _get_response
    response = self.process_exception_by_middleware(e, request)
  File "/home/mobilitysqr/.local/lib/python3.6/site-packages/django/core/handlers/base.py", line 124, in _get_response
    response = wrapped_callback(request, *callback_args, **callback_kwargs)
  File "/home/mobilitysqr/.local/lib/python3.6/site-packages/django/views/decorators/csrf.py", line 54, in wrapped_view
    return view_func(*args, **kwargs)
  File "/home/mobilitysqr/.local/lib/python3.6/site-packages/django/views/generic/base.py", line 68, in view
    return self.dispatch(request, *args, **kwargs)
  File "/home/mobilitysqr/.local/lib/python3.6/site-packages/rest_framework/views.py", line 495, in dispatch
    response = self.handle_exception(exc)
  File "/home/mobilitysqr/.local/lib/python3.6/site-packages/rest_framework/views.py", line 455, in handle_exception
    self.raise_uncaught_exception(exc)
  File "/home/mobilitysqr/.local/lib/python3.6/site-packages/rest_framework/views.py", line 492, in dispatch
    response = handler(request, *args, **kwargs)
  File "/var/www/html/mobilitysqrapi/mobility_apps/letter/views.py", line 108, in get
    datas['AssignmentStartDate']=self.date_format(date=data['Actual_Start_Date'])
  File "/var/www/html/mobilitysqrapi/mobility_apps/letter/views.py", line 518, in date_format
    utc = datetime.strftime(date, "%m/%d/%Y")
TypeError: descriptor 'strftime' requires a 'datetime.date' object but received a 'str'
ERROR|23/Nov/2020 19:02:30|basehttp|60610|139720050865920|"GET /getassignmentletter/?travel_req_id=TR185141 HTTP/1.1" 500 17619
