ERROR|12/Feb/2021 17:49:28|exception|13824|140129247500032|Invalid HTTP_HOST header: ''. The domain name provided is not valid according to RFC 1034/1035.
ERROR|12/Feb/2021 18:03:48|log|15708|140392557430528|Internal Server Error: /emoloyeeinfo/
Traceback (most recent call last):
  File "/home/mobilitysqr/.local/lib/python3.6/site-packages/django/core/handlers/exception.py", line 34, in inner
    response = get_response(request)
  File "/home/mobilitysqr/.local/lib/python3.6/site-packages/django/core/handlers/base.py", line 126, in _get_response
    response = self.process_exception_by_middleware(e, request)
  File "/home/mobilitysqr/.local/lib/python3.6/site-packages/django/core/handlers/base.py", line 124, in _get_response
    response = wrapped_callback(request, *callback_args, **callback_kwargs)
  File "/home/mobilitysqr/.local/lib/python3.6/site-packages/django/views/decorators/csrf.py", line 54, in wrapped_view
    return view_func(*args, **kwargs)
  File "/home/mobilitysqr/.local/lib/python3.6/site-packages/django/views/generic/base.py", line 68, in view
    return self.dispatch(request, *args, **kwargs)
  File "/home/mobilitysqr/.local/lib/python3.6/site-packages/rest_framework/views.py", line 495, in dispatch
    response = self.handle_exception(exc)
  File "/home/mobilitysqr/.local/lib/python3.6/site-packages/rest_framework/views.py", line 455, in handle_exception
    self.raise_uncaught_exception(exc)
  File "/home/mobilitysqr/.local/lib/python3.6/site-packages/rest_framework/views.py", line 492, in dispatch
    response = handler(request, *args, **kwargs)
  File "/var/www/html/mobilitysqr_staging/mobility_apps/employee/views.py", line 82, in post
    emp_serializer = EmployeeSerializers(employee, many=True)
UnboundLocalError: local variable 'employee' referenced before assignment
ERROR|12/Feb/2021 18:03:48|basehttp|15708|140392557430528|"POST /emoloyeeinfo/ HTTP/1.1" 500 17171
ERROR|12/Feb/2021 18:04:07|log|15708|140392557430528|Internal Server Error: /emoloyeeinfo/
Traceback (most recent call last):
  File "/home/mobilitysqr/.local/lib/python3.6/site-packages/django/core/handlers/exception.py", line 34, in inner
    response = get_response(request)
  File "/home/mobilitysqr/.local/lib/python3.6/site-packages/django/core/handlers/base.py", line 126, in _get_response
    response = self.process_exception_by_middleware(e, request)
  File "/home/mobilitysqr/.local/lib/python3.6/site-packages/django/core/handlers/base.py", line 124, in _get_response
    response = wrapped_callback(request, *callback_args, **callback_kwargs)
  File "/home/mobilitysqr/.local/lib/python3.6/site-packages/django/views/decorators/csrf.py", line 54, in wrapped_view
    return view_func(*args, **kwargs)
  File "/home/mobilitysqr/.local/lib/python3.6/site-packages/django/views/generic/base.py", line 68, in view
    return self.dispatch(request, *args, **kwargs)
  File "/home/mobilitysqr/.local/lib/python3.6/site-packages/rest_framework/views.py", line 495, in dispatch
    response = self.handle_exception(exc)
  File "/home/mobilitysqr/.local/lib/python3.6/site-packages/rest_framework/views.py", line 455, in handle_exception
    self.raise_uncaught_exception(exc)
  File "/home/mobilitysqr/.local/lib/python3.6/site-packages/rest_framework/views.py", line 492, in dispatch
    response = handler(request, *args, **kwargs)
  File "/var/www/html/mobilitysqr_staging/mobility_apps/employee/views.py", line 82, in post
    emp_serializer = EmployeeSerializers(employee, many=True)
UnboundLocalError: local variable 'employee' referenced before assignment
ERROR|12/Feb/2021 18:04:07|basehttp|15708|140392557430528|"POST /emoloyeeinfo/ HTTP/1.1" 500 17171
ERROR|12/Feb/2021 18:05:55|log|15936|140059089442560|Internal Server Error: /emoloyeeinfo/
Traceback (most recent call last):
  File "/home/mobilitysqr/.local/lib/python3.6/site-packages/django/core/handlers/exception.py", line 34, in inner
    response = get_response(request)
  File "/home/mobilitysqr/.local/lib/python3.6/site-packages/django/core/handlers/base.py", line 126, in _get_response
    response = self.process_exception_by_middleware(e, request)
  File "/home/mobilitysqr/.local/lib/python3.6/site-packages/django/core/handlers/base.py", line 124, in _get_response
    response = wrapped_callback(request, *callback_args, **callback_kwargs)
  File "/home/mobilitysqr/.local/lib/python3.6/site-packages/django/views/decorators/csrf.py", line 54, in wrapped_view
    return view_func(*args, **kwargs)
  File "/home/mobilitysqr/.local/lib/python3.6/site-packages/django/views/generic/base.py", line 68, in view
    return self.dispatch(request, *args, **kwargs)
  File "/home/mobilitysqr/.local/lib/python3.6/site-packages/rest_framework/views.py", line 495, in dispatch
    response = self.handle_exception(exc)
  File "/home/mobilitysqr/.local/lib/python3.6/site-packages/rest_framework/views.py", line 455, in handle_exception
    self.raise_uncaught_exception(exc)
  File "/home/mobilitysqr/.local/lib/python3.6/site-packages/rest_framework/views.py", line 492, in dispatch
    response = handler(request, *args, **kwargs)
  File "/var/www/html/mobilitysqr_staging/mobility_apps/employee/views.py", line 82, in post
    emp_serializer = EmployeeSerializers(employee, many=True)
UnboundLocalError: local variable 'employee' referenced before assignment
ERROR|12/Feb/2021 18:05:55|basehttp|15936|140059089442560|"POST /emoloyeeinfo/ HTTP/1.1" 500 17194
ERROR|12/Feb/2021 18:05:56|exception|15936|140059089442560|Invalid HTTP_HOST header: ''. The domain name provided is not valid according to RFC 1034/1035.
ERROR|12/Feb/2021 18:05:56|basehttp|15936|140059089442560|"GET /script HTTP/1.1" 500 59
ERROR|12/Feb/2021 18:07:03|log|16080|140348782167808|Internal Server Error: /emoloyeeinfo/
Traceback (most recent call last):
  File "/home/mobilitysqr/.local/lib/python3.6/site-packages/django/core/handlers/exception.py", line 34, in inner
    response = get_response(request)
  File "/home/mobilitysqr/.local/lib/python3.6/site-packages/django/core/handlers/base.py", line 126, in _get_response
    response = self.process_exception_by_middleware(e, request)
  File "/home/mobilitysqr/.local/lib/python3.6/site-packages/django/core/handlers/base.py", line 124, in _get_response
    response = wrapped_callback(request, *callback_args, **callback_kwargs)
  File "/home/mobilitysqr/.local/lib/python3.6/site-packages/django/views/decorators/csrf.py", line 54, in wrapped_view
    return view_func(*args, **kwargs)
  File "/home/mobilitysqr/.local/lib/python3.6/site-packages/django/views/generic/base.py", line 68, in view
    return self.dispatch(request, *args, **kwargs)
  File "/home/mobilitysqr/.local/lib/python3.6/site-packages/rest_framework/views.py", line 495, in dispatch
    response = self.handle_exception(exc)
  File "/home/mobilitysqr/.local/lib/python3.6/site-packages/rest_framework/views.py", line 455, in handle_exception
    self.raise_uncaught_exception(exc)
  File "/home/mobilitysqr/.local/lib/python3.6/site-packages/rest_framework/views.py", line 492, in dispatch
    response = handler(request, *args, **kwargs)
  File "/var/www/html/mobilitysqr_staging/mobility_apps/employee/views.py", line 81, in post
    emp_serializer = EmployeeSerializers(employee, many=True)
UnboundLocalError: local variable 'employee' referenced before assignment
ERROR|12/Feb/2021 18:07:03|basehttp|16080|140348782167808|"POST /emoloyeeinfo/ HTTP/1.1" 500 17194
ERROR|12/Feb/2021 18:08:37|log|16080|140348782167808|Internal Server Error: /emoloyeeinfo/
Traceback (most recent call last):
  File "/home/mobilitysqr/.local/lib/python3.6/site-packages/django/core/handlers/exception.py", line 34, in inner
    response = get_response(request)
  File "/home/mobilitysqr/.local/lib/python3.6/site-packages/django/core/handlers/base.py", line 126, in _get_response
    response = self.process_exception_by_middleware(e, request)
  File "/home/mobilitysqr/.local/lib/python3.6/site-packages/django/core/handlers/base.py", line 124, in _get_response
    response = wrapped_callback(request, *callback_args, **callback_kwargs)
  File "/home/mobilitysqr/.local/lib/python3.6/site-packages/django/views/decorators/csrf.py", line 54, in wrapped_view
    return view_func(*args, **kwargs)
  File "/home/mobilitysqr/.local/lib/python3.6/site-packages/django/views/generic/base.py", line 68, in view
    return self.dispatch(request, *args, **kwargs)
  File "/home/mobilitysqr/.local/lib/python3.6/site-packages/rest_framework/views.py", line 495, in dispatch
    response = self.handle_exception(exc)
  File "/home/mobilitysqr/.local/lib/python3.6/site-packages/rest_framework/views.py", line 455, in handle_exception
    self.raise_uncaught_exception(exc)
  File "/home/mobilitysqr/.local/lib/python3.6/site-packages/rest_framework/views.py", line 492, in dispatch
    response = handler(request, *args, **kwargs)
  File "/var/www/html/mobilitysqr_staging/mobility_apps/employee/views.py", line 81, in post
    emp_serializer = EmployeeSerializers(employee, many=True)
UnboundLocalError: local variable 'employee' referenced before assignment
ERROR|12/Feb/2021 18:08:37|basehttp|16080|140348782167808|"POST /emoloyeeinfo/ HTTP/1.1" 500 17115
ERROR|12/Feb/2021 18:09:14|exception|16080|140348782167808|Invalid HTTP_HOST header: ''. The domain name provided is not valid according to RFC 1034/1035.
ERROR|12/Feb/2021 18:09:18|log|16080|140348782167808|Internal Server Error: /emoloyeeinfo/
Traceback (most recent call last):
  File "/home/mobilitysqr/.local/lib/python3.6/site-packages/django/core/handlers/exception.py", line 34, in inner
    response = get_response(request)
  File "/home/mobilitysqr/.local/lib/python3.6/site-packages/django/core/handlers/base.py", line 126, in _get_response
    response = self.process_exception_by_middleware(e, request)
  File "/home/mobilitysqr/.local/lib/python3.6/site-packages/django/core/handlers/base.py", line 124, in _get_response
    response = wrapped_callback(request, *callback_args, **callback_kwargs)
  File "/home/mobilitysqr/.local/lib/python3.6/site-packages/django/views/decorators/csrf.py", line 54, in wrapped_view
    return view_func(*args, **kwargs)
  File "/home/mobilitysqr/.local/lib/python3.6/site-packages/django/views/generic/base.py", line 68, in view
    return self.dispatch(request, *args, **kwargs)
  File "/home/mobilitysqr/.local/lib/python3.6/site-packages/rest_framework/views.py", line 495, in dispatch
    response = self.handle_exception(exc)
  File "/home/mobilitysqr/.local/lib/python3.6/site-packages/rest_framework/views.py", line 455, in handle_exception
    self.raise_uncaught_exception(exc)
  File "/home/mobilitysqr/.local/lib/python3.6/site-packages/rest_framework/views.py", line 492, in dispatch
    response = handler(request, *args, **kwargs)
  File "/var/www/html/mobilitysqr_staging/mobility_apps/employee/views.py", line 81, in post
    emp_serializer = EmployeeSerializers(employee, many=True)
UnboundLocalError: local variable 'employee' referenced before assignment
ERROR|12/Feb/2021 18:09:18|basehttp|16080|140348782167808|"POST /emoloyeeinfo/ HTTP/1.1" 500 17115
ERROR|12/Feb/2021 18:09:22|log|16080|140348773250816|Internal Server Error: /emoloyeeinfo/
Traceback (most recent call last):
  File "/home/mobilitysqr/.local/lib/python3.6/site-packages/django/core/handlers/exception.py", line 34, in inner
    response = get_response(request)
  File "/home/mobilitysqr/.local/lib/python3.6/site-packages/django/core/handlers/base.py", line 126, in _get_response
    response = self.process_exception_by_middleware(e, request)
  File "/home/mobilitysqr/.local/lib/python3.6/site-packages/django/core/handlers/base.py", line 124, in _get_response
    response = wrapped_callback(request, *callback_args, **callback_kwargs)
  File "/home/mobilitysqr/.local/lib/python3.6/site-packages/django/views/decorators/csrf.py", line 54, in wrapped_view
    return view_func(*args, **kwargs)
  File "/home/mobilitysqr/.local/lib/python3.6/site-packages/django/views/generic/base.py", line 68, in view
    return self.dispatch(request, *args, **kwargs)
  File "/home/mobilitysqr/.local/lib/python3.6/site-packages/rest_framework/views.py", line 495, in dispatch
    response = self.handle_exception(exc)
  File "/home/mobilitysqr/.local/lib/python3.6/site-packages/rest_framework/views.py", line 455, in handle_exception
    self.raise_uncaught_exception(exc)
  File "/home/mobilitysqr/.local/lib/python3.6/site-packages/rest_framework/views.py", line 492, in dispatch
    response = handler(request, *args, **kwargs)
  File "/var/www/html/mobilitysqr_staging/mobility_apps/employee/views.py", line 81, in post
    emp_serializer = EmployeeSerializers(employee, many=True)
UnboundLocalError: local variable 'employee' referenced before assignment
ERROR|12/Feb/2021 18:09:22|basehttp|16080|140348773250816|"POST /emoloyeeinfo/ HTTP/1.1" 500 17116
ERROR|12/Feb/2021 18:09:22|log|16080|140348782167808|Internal Server Error: /emoloyeeinfo/
Traceback (most recent call last):
  File "/home/mobilitysqr/.local/lib/python3.6/site-packages/django/core/handlers/exception.py", line 34, in inner
    response = get_response(request)
  File "/home/mobilitysqr/.local/lib/python3.6/site-packages/django/core/handlers/base.py", line 126, in _get_response
    response = self.process_exception_by_middleware(e, request)
  File "/home/mobilitysqr/.local/lib/python3.6/site-packages/django/core/handlers/base.py", line 124, in _get_response
    response = wrapped_callback(request, *callback_args, **callback_kwargs)
  File "/home/mobilitysqr/.local/lib/python3.6/site-packages/django/views/decorators/csrf.py", line 54, in wrapped_view
    return view_func(*args, **kwargs)
  File "/home/mobilitysqr/.local/lib/python3.6/site-packages/django/views/generic/base.py", line 68, in view
    return self.dispatch(request, *args, **kwargs)
  File "/home/mobilitysqr/.local/lib/python3.6/site-packages/rest_framework/views.py", line 495, in dispatch
    response = self.handle_exception(exc)
  File "/home/mobilitysqr/.local/lib/python3.6/site-packages/rest_framework/views.py", line 455, in handle_exception
    self.raise_uncaught_exception(exc)
  File "/home/mobilitysqr/.local/lib/python3.6/site-packages/rest_framework/views.py", line 492, in dispatch
    response = handler(request, *args, **kwargs)
  File "/var/www/html/mobilitysqr_staging/mobility_apps/employee/views.py", line 81, in post
    emp_serializer = EmployeeSerializers(employee, many=True)
UnboundLocalError: local variable 'employee' referenced before assignment
ERROR|12/Feb/2021 18:09:22|basehttp|16080|140348782167808|"POST /emoloyeeinfo/ HTTP/1.1" 500 17115
ERROR|12/Feb/2021 18:11:55|log|16387|140275996362496|Internal Server Error: /emoloyeeinfo/
Traceback (most recent call last):
  File "/home/mobilitysqr/.local/lib/python3.6/site-packages/django/core/handlers/exception.py", line 34, in inner
    response = get_response(request)
  File "/home/mobilitysqr/.local/lib/python3.6/site-packages/django/core/handlers/base.py", line 126, in _get_response
    response = self.process_exception_by_middleware(e, request)
  File "/home/mobilitysqr/.local/lib/python3.6/site-packages/django/core/handlers/base.py", line 124, in _get_response
    response = wrapped_callback(request, *callback_args, **callback_kwargs)
  File "/home/mobilitysqr/.local/lib/python3.6/site-packages/django/views/decorators/csrf.py", line 54, in wrapped_view
    return view_func(*args, **kwargs)
  File "/home/mobilitysqr/.local/lib/python3.6/site-packages/django/views/generic/base.py", line 68, in view
    return self.dispatch(request, *args, **kwargs)
  File "/home/mobilitysqr/.local/lib/python3.6/site-packages/rest_framework/views.py", line 495, in dispatch
    response = self.handle_exception(exc)
  File "/home/mobilitysqr/.local/lib/python3.6/site-packages/rest_framework/views.py", line 455, in handle_exception
    self.raise_uncaught_exception(exc)
  File "/home/mobilitysqr/.local/lib/python3.6/site-packages/rest_framework/views.py", line 492, in dispatch
    response = handler(request, *args, **kwargs)
  File "/var/www/html/mobilitysqr_staging/mobility_apps/employee/views.py", line 79, in post
    logindata['recent_login']=date.now()
AttributeError: type object 'datetime.date' has no attribute 'now'
ERROR|12/Feb/2021 18:11:55|basehttp|16387|140275996362496|"POST /emoloyeeinfo/ HTTP/1.1" 500 17159
ERROR|12/Feb/2021 18:12:46|log|16422|139931830966016|Internal Server Error: /emoloyeeinfo/
Traceback (most recent call last):
  File "/home/mobilitysqr/.local/lib/python3.6/site-packages/django/core/handlers/exception.py", line 34, in inner
    response = get_response(request)
  File "/home/mobilitysqr/.local/lib/python3.6/site-packages/django/core/handlers/base.py", line 126, in _get_response
    response = self.process_exception_by_middleware(e, request)
  File "/home/mobilitysqr/.local/lib/python3.6/site-packages/django/core/handlers/base.py", line 124, in _get_response
    response = wrapped_callback(request, *callback_args, **callback_kwargs)
  File "/home/mobilitysqr/.local/lib/python3.6/site-packages/django/views/decorators/csrf.py", line 54, in wrapped_view
    return view_func(*args, **kwargs)
  File "/home/mobilitysqr/.local/lib/python3.6/site-packages/django/views/generic/base.py", line 68, in view
    return self.dispatch(request, *args, **kwargs)
  File "/home/mobilitysqr/.local/lib/python3.6/site-packages/rest_framework/views.py", line 495, in dispatch
    response = self.handle_exception(exc)
  File "/home/mobilitysqr/.local/lib/python3.6/site-packages/rest_framework/views.py", line 455, in handle_exception
    self.raise_uncaught_exception(exc)
  File "/home/mobilitysqr/.local/lib/python3.6/site-packages/rest_framework/views.py", line 492, in dispatch
    response = handler(request, *args, **kwargs)
  File "/var/www/html/mobilitysqr_staging/mobility_apps/employee/views.py", line 79, in post
    logindata['recent_login']=today()
NameError: name 'today' is not defined
ERROR|12/Feb/2021 18:12:46|basehttp|16422|139931830966016|"POST /emoloyeeinfo/ HTTP/1.1" 500 17100
ERROR|12/Feb/2021 18:36:43|log|18095|139913939060480|Internal Server Error: /emoloyeeinfo/
Traceback (most recent call last):
  File "/home/mobilitysqr/.local/lib/python3.6/site-packages/django/core/handlers/exception.py", line 34, in inner
    response = get_response(request)
  File "/home/mobilitysqr/.local/lib/python3.6/site-packages/django/core/handlers/base.py", line 126, in _get_response
    response = self.process_exception_by_middleware(e, request)
  File "/home/mobilitysqr/.local/lib/python3.6/site-packages/django/core/handlers/base.py", line 124, in _get_response
    response = wrapped_callback(request, *callback_args, **callback_kwargs)
  File "/home/mobilitysqr/.local/lib/python3.6/site-packages/django/views/decorators/csrf.py", line 54, in wrapped_view
    return view_func(*args, **kwargs)
  File "/home/mobilitysqr/.local/lib/python3.6/site-packages/django/views/generic/base.py", line 68, in view
    return self.dispatch(request, *args, **kwargs)
  File "/home/mobilitysqr/.local/lib/python3.6/site-packages/rest_framework/views.py", line 495, in dispatch
    response = self.handle_exception(exc)
  File "/home/mobilitysqr/.local/lib/python3.6/site-packages/rest_framework/views.py", line 455, in handle_exception
    self.raise_uncaught_exception(exc)
  File "/home/mobilitysqr/.local/lib/python3.6/site-packages/rest_framework/views.py", line 492, in dispatch
    response = handler(request, *args, **kwargs)
  File "/var/www/html/mobilitysqr_staging/mobility_apps/employee/views.py", line 83, in post
    if emp_serializer_date.is_valid():
  File "/home/mobilitysqr/.local/lib/python3.6/site-packages/rest_framework/serializers.py", line 236, in is_valid
    self._validated_data = self.run_validation(self.initial_data)
  File "/home/mobilitysqr/.local/lib/python3.6/site-packages/rest_framework/serializers.py", line 434, in run_validation
    value = self.to_internal_value(data)
  File "/home/mobilitysqr/.local/lib/python3.6/site-packages/rest_framework/serializers.py", line 491, in to_internal_value
    validated_value = field.run_validation(primitive_value)
  File "/home/mobilitysqr/.local/lib/python3.6/site-packages/rest_framework/fields.py", line 794, in run_validation
    return super(CharField, self).run_validation(data)
  File "/home/mobilitysqr/.local/lib/python3.6/site-packages/rest_framework/fields.py", line 537, in run_validation
    self.run_validators(value)
  File "/home/mobilitysqr/.local/lib/python3.6/site-packages/rest_framework/fields.py", line 551, in run_validators
    validator(value)
  File "/home/mobilitysqr/.local/lib/python3.6/site-packages/rest_framework/validators.py", line 80, in __call__
    queryset = self.exclude_current_instance(queryset)
  File "/home/mobilitysqr/.local/lib/python3.6/site-packages/rest_framework/validators.py", line 74, in exclude_current_instance
    return queryset.exclude(pk=self.instance.pk)
AttributeError: 'QuerySet' object has no attribute 'pk'
ERROR|12/Feb/2021 18:36:43|basehttp|18095|139913939060480|"POST /emoloyeeinfo/ HTTP/1.1" 500 18483
ERROR|12/Feb/2021 18:36:46|log|18095|139913939060480|Internal Server Error: /emoloyeeinfo/
Traceback (most recent call last):
  File "/home/mobilitysqr/.local/lib/python3.6/site-packages/django/core/handlers/exception.py", line 34, in inner
    response = get_response(request)
  File "/home/mobilitysqr/.local/lib/python3.6/site-packages/django/core/handlers/base.py", line 126, in _get_response
    response = self.process_exception_by_middleware(e, request)
  File "/home/mobilitysqr/.local/lib/python3.6/site-packages/django/core/handlers/base.py", line 124, in _get_response
    response = wrapped_callback(request, *callback_args, **callback_kwargs)
  File "/home/mobilitysqr/.local/lib/python3.6/site-packages/django/views/decorators/csrf.py", line 54, in wrapped_view
    return view_func(*args, **kwargs)
  File "/home/mobilitysqr/.local/lib/python3.6/site-packages/django/views/generic/base.py", line 68, in view
    return self.dispatch(request, *args, **kwargs)
  File "/home/mobilitysqr/.local/lib/python3.6/site-packages/rest_framework/views.py", line 495, in dispatch
    response = self.handle_exception(exc)
  File "/home/mobilitysqr/.local/lib/python3.6/site-packages/rest_framework/views.py", line 455, in handle_exception
    self.raise_uncaught_exception(exc)
  File "/home/mobilitysqr/.local/lib/python3.6/site-packages/rest_framework/views.py", line 492, in dispatch
    response = handler(request, *args, **kwargs)
  File "/var/www/html/mobilitysqr_staging/mobility_apps/employee/views.py", line 83, in post
    if emp_serializer_date.is_valid():
  File "/home/mobilitysqr/.local/lib/python3.6/site-packages/rest_framework/serializers.py", line 236, in is_valid
    self._validated_data = self.run_validation(self.initial_data)
  File "/home/mobilitysqr/.local/lib/python3.6/site-packages/rest_framework/serializers.py", line 434, in run_validation
    value = self.to_internal_value(data)
  File "/home/mobilitysqr/.local/lib/python3.6/site-packages/rest_framework/serializers.py", line 491, in to_internal_value
    validated_value = field.run_validation(primitive_value)
  File "/home/mobilitysqr/.local/lib/python3.6/site-packages/rest_framework/fields.py", line 794, in run_validation
    return super(CharField, self).run_validation(data)
  File "/home/mobilitysqr/.local/lib/python3.6/site-packages/rest_framework/fields.py", line 537, in run_validation
    self.run_validators(value)
  File "/home/mobilitysqr/.local/lib/python3.6/site-packages/rest_framework/fields.py", line 551, in run_validators
    validator(value)
  File "/home/mobilitysqr/.local/lib/python3.6/site-packages/rest_framework/validators.py", line 80, in __call__
    queryset = self.exclude_current_instance(queryset)
  File "/home/mobilitysqr/.local/lib/python3.6/site-packages/rest_framework/validators.py", line 74, in exclude_current_instance
    return queryset.exclude(pk=self.instance.pk)
AttributeError: 'QuerySet' object has no attribute 'pk'
ERROR|12/Feb/2021 18:36:46|basehttp|18095|139913939060480|"POST /emoloyeeinfo/ HTTP/1.1" 500 18483
ERROR|12/Feb/2021 19:00:36|log|19612|140596835239680|Internal Server Error: /emoloyeeinfo/
Traceback (most recent call last):
  File "/home/mobilitysqr/.local/lib/python3.6/site-packages/django/core/handlers/exception.py", line 34, in inner
    response = get_response(request)
  File "/home/mobilitysqr/.local/lib/python3.6/site-packages/django/core/handlers/base.py", line 126, in _get_response
    response = self.process_exception_by_middleware(e, request)
  File "/home/mobilitysqr/.local/lib/python3.6/site-packages/django/core/handlers/base.py", line 124, in _get_response
    response = wrapped_callback(request, *callback_args, **callback_kwargs)
  File "/home/mobilitysqr/.local/lib/python3.6/site-packages/django/views/decorators/csrf.py", line 54, in wrapped_view
    return view_func(*args, **kwargs)
  File "/home/mobilitysqr/.local/lib/python3.6/site-packages/django/views/generic/base.py", line 68, in view
    return self.dispatch(request, *args, **kwargs)
  File "/home/mobilitysqr/.local/lib/python3.6/site-packages/rest_framework/views.py", line 495, in dispatch
    response = self.handle_exception(exc)
  File "/home/mobilitysqr/.local/lib/python3.6/site-packages/rest_framework/views.py", line 455, in handle_exception
    self.raise_uncaught_exception(exc)
  File "/home/mobilitysqr/.local/lib/python3.6/site-packages/rest_framework/views.py", line 492, in dispatch
    response = handler(request, *args, **kwargs)
  File "/var/www/html/mobilitysqr_staging/mobility_apps/employee/views.py", line 84, in post
    if not employees_recent['0']['last_login']:
  File "/home/mobilitysqr/.local/lib/python3.6/site-packages/django/db/models/query.py", line 278, in __getitem__
    raise TypeError
TypeError
ERROR|12/Feb/2021 19:00:36|basehttp|19612|140596835239680|"POST /emoloyeeinfo/ HTTP/1.1" 500 17123
ERROR|12/Feb/2021 19:00:57|log|19612|140596835239680|Internal Server Error: /emoloyeeinfo/
Traceback (most recent call last):
  File "/home/mobilitysqr/.local/lib/python3.6/site-packages/django/core/handlers/exception.py", line 34, in inner
    response = get_response(request)
  File "/home/mobilitysqr/.local/lib/python3.6/site-packages/django/core/handlers/base.py", line 126, in _get_response
    response = self.process_exception_by_middleware(e, request)
  File "/home/mobilitysqr/.local/lib/python3.6/site-packages/django/core/handlers/base.py", line 124, in _get_response
    response = wrapped_callback(request, *callback_args, **callback_kwargs)
  File "/home/mobilitysqr/.local/lib/python3.6/site-packages/django/views/decorators/csrf.py", line 54, in wrapped_view
    return view_func(*args, **kwargs)
  File "/home/mobilitysqr/.local/lib/python3.6/site-packages/django/views/generic/base.py", line 68, in view
    return self.dispatch(request, *args, **kwargs)
  File "/home/mobilitysqr/.local/lib/python3.6/site-packages/rest_framework/views.py", line 495, in dispatch
    response = self.handle_exception(exc)
  File "/home/mobilitysqr/.local/lib/python3.6/site-packages/rest_framework/views.py", line 455, in handle_exception
    self.raise_uncaught_exception(exc)
  File "/home/mobilitysqr/.local/lib/python3.6/site-packages/rest_framework/views.py", line 492, in dispatch
    response = handler(request, *args, **kwargs)
  File "/var/www/html/mobilitysqr_staging/mobility_apps/employee/views.py", line 84, in post
    if not employees_recent['0']['last_login']:
  File "/home/mobilitysqr/.local/lib/python3.6/site-packages/django/db/models/query.py", line 278, in __getitem__
    raise TypeError
TypeError
ERROR|12/Feb/2021 19:00:57|basehttp|19612|140596835239680|"POST /emoloyeeinfo/ HTTP/1.1" 500 17205
ERROR|12/Feb/2021 19:01:02|log|19612|140596809275136|Internal Server Error: /emoloyeeinfo/
Traceback (most recent call last):
  File "/home/mobilitysqr/.local/lib/python3.6/site-packages/django/core/handlers/exception.py", line 34, in inner
    response = get_response(request)
  File "/home/mobilitysqr/.local/lib/python3.6/site-packages/django/core/handlers/base.py", line 126, in _get_response
    response = self.process_exception_by_middleware(e, request)
  File "/home/mobilitysqr/.local/lib/python3.6/site-packages/django/core/handlers/base.py", line 124, in _get_response
    response = wrapped_callback(request, *callback_args, **callback_kwargs)
  File "/home/mobilitysqr/.local/lib/python3.6/site-packages/django/views/decorators/csrf.py", line 54, in wrapped_view
    return view_func(*args, **kwargs)
  File "/home/mobilitysqr/.local/lib/python3.6/site-packages/django/views/generic/base.py", line 68, in view
    return self.dispatch(request, *args, **kwargs)
  File "/home/mobilitysqr/.local/lib/python3.6/site-packages/rest_framework/views.py", line 495, in dispatch
    response = self.handle_exception(exc)
  File "/home/mobilitysqr/.local/lib/python3.6/site-packages/rest_framework/views.py", line 455, in handle_exception
    self.raise_uncaught_exception(exc)
  File "/home/mobilitysqr/.local/lib/python3.6/site-packages/rest_framework/views.py", line 492, in dispatch
    response = handler(request, *args, **kwargs)
  File "/var/www/html/mobilitysqr_staging/mobility_apps/employee/views.py", line 84, in post
    if not employees_recent['0']['last_login']:
  File "/home/mobilitysqr/.local/lib/python3.6/site-packages/django/db/models/query.py", line 278, in __getitem__
    raise TypeError
TypeError
ERROR|12/Feb/2021 19:01:02|basehttp|19612|140596809275136|"POST /emoloyeeinfo/ HTTP/1.1" 500 17206
ERROR|12/Feb/2021 19:01:34|log|19612|140596809275136|Internal Server Error: /emoloyeeinfo/
Traceback (most recent call last):
  File "/home/mobilitysqr/.local/lib/python3.6/site-packages/django/core/handlers/exception.py", line 34, in inner
    response = get_response(request)
  File "/home/mobilitysqr/.local/lib/python3.6/site-packages/django/core/handlers/base.py", line 126, in _get_response
    response = self.process_exception_by_middleware(e, request)
  File "/home/mobilitysqr/.local/lib/python3.6/site-packages/django/core/handlers/base.py", line 124, in _get_response
    response = wrapped_callback(request, *callback_args, **callback_kwargs)
  File "/home/mobilitysqr/.local/lib/python3.6/site-packages/django/views/decorators/csrf.py", line 54, in wrapped_view
    return view_func(*args, **kwargs)
  File "/home/mobilitysqr/.local/lib/python3.6/site-packages/django/views/generic/base.py", line 68, in view
    return self.dispatch(request, *args, **kwargs)
  File "/home/mobilitysqr/.local/lib/python3.6/site-packages/rest_framework/views.py", line 495, in dispatch
    response = self.handle_exception(exc)
  File "/home/mobilitysqr/.local/lib/python3.6/site-packages/rest_framework/views.py", line 455, in handle_exception
    self.raise_uncaught_exception(exc)
  File "/home/mobilitysqr/.local/lib/python3.6/site-packages/rest_framework/views.py", line 492, in dispatch
    response = handler(request, *args, **kwargs)
  File "/var/www/html/mobilitysqr_staging/mobility_apps/employee/views.py", line 84, in post
    if not employees_recent['0']['last_login']:
  File "/home/mobilitysqr/.local/lib/python3.6/site-packages/django/db/models/query.py", line 278, in __getitem__
    raise TypeError
TypeError
ERROR|12/Feb/2021 19:01:34|basehttp|19612|140596809275136|"POST /emoloyeeinfo/ HTTP/1.1" 500 17206
ERROR|12/Feb/2021 19:01:37|log|19612|140596817929984|Internal Server Error: /emoloyeeinfo/
Traceback (most recent call last):
  File "/home/mobilitysqr/.local/lib/python3.6/site-packages/django/core/handlers/exception.py", line 34, in inner
    response = get_response(request)
  File "/home/mobilitysqr/.local/lib/python3.6/site-packages/django/core/handlers/base.py", line 126, in _get_response
    response = self.process_exception_by_middleware(e, request)
  File "/home/mobilitysqr/.local/lib/python3.6/site-packages/django/core/handlers/base.py", line 124, in _get_response
    response = wrapped_callback(request, *callback_args, **callback_kwargs)
  File "/home/mobilitysqr/.local/lib/python3.6/site-packages/django/views/decorators/csrf.py", line 54, in wrapped_view
    return view_func(*args, **kwargs)
  File "/home/mobilitysqr/.local/lib/python3.6/site-packages/django/views/generic/base.py", line 68, in view
    return self.dispatch(request, *args, **kwargs)
  File "/home/mobilitysqr/.local/lib/python3.6/site-packages/rest_framework/views.py", line 495, in dispatch
    response = self.handle_exception(exc)
  File "/home/mobilitysqr/.local/lib/python3.6/site-packages/rest_framework/views.py", line 455, in handle_exception
    self.raise_uncaught_exception(exc)
  File "/home/mobilitysqr/.local/lib/python3.6/site-packages/rest_framework/views.py", line 492, in dispatch
    response = handler(request, *args, **kwargs)
  File "/var/www/html/mobilitysqr_staging/mobility_apps/employee/views.py", line 84, in post
    if not employees_recent['0']['last_login']:
  File "/home/mobilitysqr/.local/lib/python3.6/site-packages/django/db/models/query.py", line 278, in __getitem__
    raise TypeError
TypeError
ERROR|12/Feb/2021 19:01:37|basehttp|19612|140596817929984|"POST /emoloyeeinfo/ HTTP/1.1" 500 17205
ERROR|12/Feb/2021 19:02:23|log|19612|140596817929984|Internal Server Error: /emoloyeeinfo/
Traceback (most recent call last):
  File "/home/mobilitysqr/.local/lib/python3.6/site-packages/django/core/handlers/exception.py", line 34, in inner
    response = get_response(request)
  File "/home/mobilitysqr/.local/lib/python3.6/site-packages/django/core/handlers/base.py", line 126, in _get_response
    response = self.process_exception_by_middleware(e, request)
  File "/home/mobilitysqr/.local/lib/python3.6/site-packages/django/core/handlers/base.py", line 124, in _get_response
    response = wrapped_callback(request, *callback_args, **callback_kwargs)
  File "/home/mobilitysqr/.local/lib/python3.6/site-packages/django/views/decorators/csrf.py", line 54, in wrapped_view
    return view_func(*args, **kwargs)
  File "/home/mobilitysqr/.local/lib/python3.6/site-packages/django/views/generic/base.py", line 68, in view
    return self.dispatch(request, *args, **kwargs)
  File "/home/mobilitysqr/.local/lib/python3.6/site-packages/rest_framework/views.py", line 495, in dispatch
    response = self.handle_exception(exc)
  File "/home/mobilitysqr/.local/lib/python3.6/site-packages/rest_framework/views.py", line 455, in handle_exception
    self.raise_uncaught_exception(exc)
  File "/home/mobilitysqr/.local/lib/python3.6/site-packages/rest_framework/views.py", line 492, in dispatch
    response = handler(request, *args, **kwargs)
  File "/var/www/html/mobilitysqr_staging/mobility_apps/employee/views.py", line 84, in post
    if not employees_recent['0']['last_login']:
  File "/home/mobilitysqr/.local/lib/python3.6/site-packages/django/db/models/query.py", line 278, in __getitem__
    raise TypeError
TypeError
ERROR|12/Feb/2021 19:02:23|basehttp|19612|140596817929984|"POST /emoloyeeinfo/ HTTP/1.1" 500 17126
ERROR|12/Feb/2021 19:04:00|log|19612|140596817929984|Internal Server Error: /emoloyeeinfo/
Traceback (most recent call last):
  File "/home/mobilitysqr/.local/lib/python3.6/site-packages/django/core/handlers/exception.py", line 34, in inner
    response = get_response(request)
  File "/home/mobilitysqr/.local/lib/python3.6/site-packages/django/core/handlers/base.py", line 126, in _get_response
    response = self.process_exception_by_middleware(e, request)
  File "/home/mobilitysqr/.local/lib/python3.6/site-packages/django/core/handlers/base.py", line 124, in _get_response
    response = wrapped_callback(request, *callback_args, **callback_kwargs)
  File "/home/mobilitysqr/.local/lib/python3.6/site-packages/django/views/decorators/csrf.py", line 54, in wrapped_view
    return view_func(*args, **kwargs)
  File "/home/mobilitysqr/.local/lib/python3.6/site-packages/django/views/generic/base.py", line 68, in view
    return self.dispatch(request, *args, **kwargs)
  File "/home/mobilitysqr/.local/lib/python3.6/site-packages/rest_framework/views.py", line 495, in dispatch
    response = self.handle_exception(exc)
  File "/home/mobilitysqr/.local/lib/python3.6/site-packages/rest_framework/views.py", line 455, in handle_exception
    self.raise_uncaught_exception(exc)
  File "/home/mobilitysqr/.local/lib/python3.6/site-packages/rest_framework/views.py", line 492, in dispatch
    response = handler(request, *args, **kwargs)
  File "/var/www/html/mobilitysqr_staging/mobility_apps/employee/views.py", line 84, in post
    if not employees_recent['0']['last_login']:
  File "/home/mobilitysqr/.local/lib/python3.6/site-packages/django/db/models/query.py", line 278, in __getitem__
    raise TypeError
TypeError
ERROR|12/Feb/2021 19:04:00|basehttp|19612|140596817929984|"POST /emoloyeeinfo/ HTTP/1.1" 500 17126
ERROR|12/Feb/2021 19:04:22|log|19612|140596826322688|Internal Server Error: /emoloyeeinfo/
Traceback (most recent call last):
  File "/home/mobilitysqr/.local/lib/python3.6/site-packages/django/core/handlers/exception.py", line 34, in inner
    response = get_response(request)
  File "/home/mobilitysqr/.local/lib/python3.6/site-packages/django/core/handlers/base.py", line 126, in _get_response
    response = self.process_exception_by_middleware(e, request)
  File "/home/mobilitysqr/.local/lib/python3.6/site-packages/django/core/handlers/base.py", line 124, in _get_response
    response = wrapped_callback(request, *callback_args, **callback_kwargs)
  File "/home/mobilitysqr/.local/lib/python3.6/site-packages/django/views/decorators/csrf.py", line 54, in wrapped_view
    return view_func(*args, **kwargs)
  File "/home/mobilitysqr/.local/lib/python3.6/site-packages/django/views/generic/base.py", line 68, in view
    return self.dispatch(request, *args, **kwargs)
  File "/home/mobilitysqr/.local/lib/python3.6/site-packages/rest_framework/views.py", line 495, in dispatch
    response = self.handle_exception(exc)
  File "/home/mobilitysqr/.local/lib/python3.6/site-packages/rest_framework/views.py", line 455, in handle_exception
    self.raise_uncaught_exception(exc)
  File "/home/mobilitysqr/.local/lib/python3.6/site-packages/rest_framework/views.py", line 492, in dispatch
    response = handler(request, *args, **kwargs)
  File "/var/www/html/mobilitysqr_staging/mobility_apps/employee/views.py", line 84, in post
    if not employees_recent['0']['last_login']:
  File "/home/mobilitysqr/.local/lib/python3.6/site-packages/django/db/models/query.py", line 278, in __getitem__
    raise TypeError
TypeError
ERROR|12/Feb/2021 19:04:22|basehttp|19612|140596826322688|"POST /emoloyeeinfo/ HTTP/1.1" 500 17125
ERROR|12/Feb/2021 19:08:48|log|20212|139839711065856|Internal Server Error: /emoloyeeinfo/
Traceback (most recent call last):
  File "/home/mobilitysqr/.local/lib/python3.6/site-packages/django/core/handlers/exception.py", line 34, in inner
    response = get_response(request)
  File "/home/mobilitysqr/.local/lib/python3.6/site-packages/django/core/handlers/base.py", line 126, in _get_response
    response = self.process_exception_by_middleware(e, request)
  File "/home/mobilitysqr/.local/lib/python3.6/site-packages/django/core/handlers/base.py", line 124, in _get_response
    response = wrapped_callback(request, *callback_args, **callback_kwargs)
  File "/home/mobilitysqr/.local/lib/python3.6/site-packages/django/views/decorators/csrf.py", line 54, in wrapped_view
    return view_func(*args, **kwargs)
  File "/home/mobilitysqr/.local/lib/python3.6/site-packages/django/views/generic/base.py", line 68, in view
    return self.dispatch(request, *args, **kwargs)
  File "/home/mobilitysqr/.local/lib/python3.6/site-packages/rest_framework/views.py", line 495, in dispatch
    response = self.handle_exception(exc)
  File "/home/mobilitysqr/.local/lib/python3.6/site-packages/rest_framework/views.py", line 455, in handle_exception
    self.raise_uncaught_exception(exc)
  File "/home/mobilitysqr/.local/lib/python3.6/site-packages/rest_framework/views.py", line 492, in dispatch
    response = handler(request, *args, **kwargs)
  File "/var/www/html/mobilitysqr_staging/mobility_apps/employee/views.py", line 84, in post
    print(employees_recent['0']['last_login'])
  File "/home/mobilitysqr/.local/lib/python3.6/site-packages/django/db/models/query.py", line 278, in __getitem__
    raise TypeError
TypeError
ERROR|12/Feb/2021 19:08:48|basehttp|20212|139839711065856|"POST /emoloyeeinfo/ HTTP/1.1" 500 17204
ERROR|12/Feb/2021 19:09:07|log|20212|139839711065856|Internal Server Error: /emoloyeeinfo/
Traceback (most recent call last):
  File "/home/mobilitysqr/.local/lib/python3.6/site-packages/django/core/handlers/exception.py", line 34, in inner
    response = get_response(request)
  File "/home/mobilitysqr/.local/lib/python3.6/site-packages/django/core/handlers/base.py", line 126, in _get_response
    response = self.process_exception_by_middleware(e, request)
  File "/home/mobilitysqr/.local/lib/python3.6/site-packages/django/core/handlers/base.py", line 124, in _get_response
    response = wrapped_callback(request, *callback_args, **callback_kwargs)
  File "/home/mobilitysqr/.local/lib/python3.6/site-packages/django/views/decorators/csrf.py", line 54, in wrapped_view
    return view_func(*args, **kwargs)
  File "/home/mobilitysqr/.local/lib/python3.6/site-packages/django/views/generic/base.py", line 68, in view
    return self.dispatch(request, *args, **kwargs)
  File "/home/mobilitysqr/.local/lib/python3.6/site-packages/rest_framework/views.py", line 495, in dispatch
    response = self.handle_exception(exc)
  File "/home/mobilitysqr/.local/lib/python3.6/site-packages/rest_framework/views.py", line 455, in handle_exception
    self.raise_uncaught_exception(exc)
  File "/home/mobilitysqr/.local/lib/python3.6/site-packages/rest_framework/views.py", line 492, in dispatch
    response = handler(request, *args, **kwargs)
  File "/var/www/html/mobilitysqr_staging/mobility_apps/employee/views.py", line 84, in post
    print(employees_recent['0']['last_login'])
  File "/home/mobilitysqr/.local/lib/python3.6/site-packages/django/db/models/query.py", line 278, in __getitem__
    raise TypeError
TypeError
ERROR|12/Feb/2021 19:09:07|basehttp|20212|139839711065856|"POST /emoloyeeinfo/ HTTP/1.1" 500 17204
ERROR|12/Feb/2021 19:09:58|log|20212|139839711065856|Internal Server Error: /emoloyeeinfo/
Traceback (most recent call last):
  File "/home/mobilitysqr/.local/lib/python3.6/site-packages/django/core/handlers/exception.py", line 34, in inner
    response = get_response(request)
  File "/home/mobilitysqr/.local/lib/python3.6/site-packages/django/core/handlers/base.py", line 126, in _get_response
    response = self.process_exception_by_middleware(e, request)
  File "/home/mobilitysqr/.local/lib/python3.6/site-packages/django/core/handlers/base.py", line 124, in _get_response
    response = wrapped_callback(request, *callback_args, **callback_kwargs)
  File "/home/mobilitysqr/.local/lib/python3.6/site-packages/django/views/decorators/csrf.py", line 54, in wrapped_view
    return view_func(*args, **kwargs)
  File "/home/mobilitysqr/.local/lib/python3.6/site-packages/django/views/generic/base.py", line 68, in view
    return self.dispatch(request, *args, **kwargs)
  File "/home/mobilitysqr/.local/lib/python3.6/site-packages/rest_framework/views.py", line 495, in dispatch
    response = self.handle_exception(exc)
  File "/home/mobilitysqr/.local/lib/python3.6/site-packages/rest_framework/views.py", line 455, in handle_exception
    self.raise_uncaught_exception(exc)
  File "/home/mobilitysqr/.local/lib/python3.6/site-packages/rest_framework/views.py", line 492, in dispatch
    response = handler(request, *args, **kwargs)
  File "/var/www/html/mobilitysqr_staging/mobility_apps/employee/views.py", line 84, in post
    print(employees_recent['0']['last_login'])
  File "/home/mobilitysqr/.local/lib/python3.6/site-packages/django/db/models/query.py", line 278, in __getitem__
    raise TypeError
TypeError
ERROR|12/Feb/2021 19:09:58|basehttp|20212|139839711065856|"POST /emoloyeeinfo/ HTTP/1.1" 500 17125
ERROR|12/Feb/2021 19:11:26|exception|20212|139839711065856|Invalid HTTP_HOST header: ''. The domain name provided is not valid according to RFC 1034/1035.
ERROR|12/Feb/2021 19:13:29|log|20523|140490134980352|Internal Server Error: /emoloyeeinfo/
Traceback (most recent call last):
  File "/home/mobilitysqr/.local/lib/python3.6/site-packages/django/core/handlers/exception.py", line 34, in inner
    response = get_response(request)
  File "/home/mobilitysqr/.local/lib/python3.6/site-packages/django/core/handlers/base.py", line 126, in _get_response
    response = self.process_exception_by_middleware(e, request)
  File "/home/mobilitysqr/.local/lib/python3.6/site-packages/django/core/handlers/base.py", line 124, in _get_response
    response = wrapped_callback(request, *callback_args, **callback_kwargs)
  File "/home/mobilitysqr/.local/lib/python3.6/site-packages/django/views/decorators/csrf.py", line 54, in wrapped_view
    return view_func(*args, **kwargs)
  File "/home/mobilitysqr/.local/lib/python3.6/site-packages/django/views/generic/base.py", line 68, in view
    return self.dispatch(request, *args, **kwargs)
  File "/home/mobilitysqr/.local/lib/python3.6/site-packages/rest_framework/views.py", line 495, in dispatch
    response = self.handle_exception(exc)
  File "/home/mobilitysqr/.local/lib/python3.6/site-packages/rest_framework/views.py", line 455, in handle_exception
    self.raise_uncaught_exception(exc)
  File "/home/mobilitysqr/.local/lib/python3.6/site-packages/rest_framework/views.py", line 492, in dispatch
    response = handler(request, *args, **kwargs)
  File "/var/www/html/mobilitysqr_staging/mobility_apps/employee/views.py", line 84, in post
    if not employees_recent[0]['last_login']:
  File "/home/mobilitysqr/.local/lib/python3.6/site-packages/django/db/models/query.py", line 303, in __getitem__
    return qs._result_cache[0]
IndexError: list index out of range
ERROR|12/Feb/2021 19:13:29|basehttp|20523|140490134980352|"POST /emoloyeeinfo/ HTTP/1.1" 500 17167
ERROR|12/Feb/2021 19:21:49|log|21076|140283113432832|Internal Server Error: /emoloyeeinfo/
Traceback (most recent call last):
  File "/home/mobilitysqr/.local/lib/python3.6/site-packages/django/core/handlers/exception.py", line 34, in inner
    response = get_response(request)
  File "/home/mobilitysqr/.local/lib/python3.6/site-packages/django/core/handlers/base.py", line 126, in _get_response
    response = self.process_exception_by_middleware(e, request)
  File "/home/mobilitysqr/.local/lib/python3.6/site-packages/django/core/handlers/base.py", line 124, in _get_response
    response = wrapped_callback(request, *callback_args, **callback_kwargs)
  File "/home/mobilitysqr/.local/lib/python3.6/site-packages/django/views/decorators/csrf.py", line 54, in wrapped_view
    return view_func(*args, **kwargs)
  File "/home/mobilitysqr/.local/lib/python3.6/site-packages/django/views/generic/base.py", line 68, in view
    return self.dispatch(request, *args, **kwargs)
  File "/home/mobilitysqr/.local/lib/python3.6/site-packages/rest_framework/views.py", line 495, in dispatch
    response = self.handle_exception(exc)
  File "/home/mobilitysqr/.local/lib/python3.6/site-packages/rest_framework/views.py", line 455, in handle_exception
    self.raise_uncaught_exception(exc)
  File "/home/mobilitysqr/.local/lib/python3.6/site-packages/rest_framework/views.py", line 492, in dispatch
    response = handler(request, *args, **kwargs)
  File "/var/www/html/mobilitysqr_staging/mobility_apps/employee/views.py", line 84, in post
    print(employees_recent[0]['recent_login'])
  File "/home/mobilitysqr/.local/lib/python3.6/site-packages/django/db/models/query.py", line 303, in __getitem__
    return qs._result_cache[0]
IndexError: list index out of range
ERROR|12/Feb/2021 19:21:49|basehttp|21076|140283113432832|"POST /emoloyeeinfo/ HTTP/1.1" 500 17168
ERROR|12/Feb/2021 19:25:06|log|21292|139627568785152|Internal Server Error: /emoloyeeinfo/
Traceback (most recent call last):
  File "/home/mobilitysqr/.local/lib/python3.6/site-packages/django/core/handlers/exception.py", line 34, in inner
    response = get_response(request)
  File "/home/mobilitysqr/.local/lib/python3.6/site-packages/django/core/handlers/base.py", line 126, in _get_response
    response = self.process_exception_by_middleware(e, request)
  File "/home/mobilitysqr/.local/lib/python3.6/site-packages/django/core/handlers/base.py", line 124, in _get_response
    response = wrapped_callback(request, *callback_args, **callback_kwargs)
  File "/home/mobilitysqr/.local/lib/python3.6/site-packages/django/views/decorators/csrf.py", line 54, in wrapped_view
    return view_func(*args, **kwargs)
  File "/home/mobilitysqr/.local/lib/python3.6/site-packages/django/views/generic/base.py", line 68, in view
    return self.dispatch(request, *args, **kwargs)
  File "/home/mobilitysqr/.local/lib/python3.6/site-packages/rest_framework/views.py", line 495, in dispatch
    response = self.handle_exception(exc)
  File "/home/mobilitysqr/.local/lib/python3.6/site-packages/rest_framework/views.py", line 455, in handle_exception
    self.raise_uncaught_exception(exc)
  File "/home/mobilitysqr/.local/lib/python3.6/site-packages/rest_framework/views.py", line 492, in dispatch
    response = handler(request, *args, **kwargs)
  File "/var/www/html/mobilitysqr_staging/mobility_apps/employee/views.py", line 84, in post
    print(employees_recent[0]['recent_login'])
  File "/home/mobilitysqr/.local/lib/python3.6/site-packages/django/db/models/query.py", line 303, in __getitem__
    return qs._result_cache[0]
IndexError: list index out of range
ERROR|12/Feb/2021 19:25:06|basehttp|21292|139627568785152|"POST /emoloyeeinfo/ HTTP/1.1" 500 17168
ERROR|12/Feb/2021 19:27:40|log|21292|139627568785152|Internal Server Error: /emoloyeeinfo/
Traceback (most recent call last):
  File "/home/mobilitysqr/.local/lib/python3.6/site-packages/django/core/handlers/exception.py", line 34, in inner
    response = get_response(request)
  File "/home/mobilitysqr/.local/lib/python3.6/site-packages/django/core/handlers/base.py", line 126, in _get_response
    response = self.process_exception_by_middleware(e, request)
  File "/home/mobilitysqr/.local/lib/python3.6/site-packages/django/core/handlers/base.py", line 124, in _get_response
    response = wrapped_callback(request, *callback_args, **callback_kwargs)
  File "/home/mobilitysqr/.local/lib/python3.6/site-packages/django/views/decorators/csrf.py", line 54, in wrapped_view
    return view_func(*args, **kwargs)
  File "/home/mobilitysqr/.local/lib/python3.6/site-packages/django/views/generic/base.py", line 68, in view
    return self.dispatch(request, *args, **kwargs)
  File "/home/mobilitysqr/.local/lib/python3.6/site-packages/rest_framework/views.py", line 495, in dispatch
    response = self.handle_exception(exc)
  File "/home/mobilitysqr/.local/lib/python3.6/site-packages/rest_framework/views.py", line 455, in handle_exception
    self.raise_uncaught_exception(exc)
  File "/home/mobilitysqr/.local/lib/python3.6/site-packages/rest_framework/views.py", line 492, in dispatch
    response = handler(request, *args, **kwargs)
  File "/var/www/html/mobilitysqr_staging/mobility_apps/employee/views.py", line 84, in post
    print(employees_recent[0]['recent_login'])
  File "/home/mobilitysqr/.local/lib/python3.6/site-packages/django/db/models/query.py", line 303, in __getitem__
    return qs._result_cache[0]
IndexError: list index out of range
ERROR|12/Feb/2021 19:27:40|basehttp|21292|139627568785152|"POST /emoloyeeinfo/ HTTP/1.1" 500 17168
ERROR|12/Feb/2021 19:28:58|log|21543|140015343757056|Internal Server Error: /emoloyeeinfo/
Traceback (most recent call last):
  File "/home/mobilitysqr/.local/lib/python3.6/site-packages/django/core/handlers/exception.py", line 34, in inner
    response = get_response(request)
  File "/home/mobilitysqr/.local/lib/python3.6/site-packages/django/core/handlers/base.py", line 126, in _get_response
    response = self.process_exception_by_middleware(e, request)
  File "/home/mobilitysqr/.local/lib/python3.6/site-packages/django/core/handlers/base.py", line 124, in _get_response
    response = wrapped_callback(request, *callback_args, **callback_kwargs)
  File "/home/mobilitysqr/.local/lib/python3.6/site-packages/django/views/decorators/csrf.py", line 54, in wrapped_view
    return view_func(*args, **kwargs)
  File "/home/mobilitysqr/.local/lib/python3.6/site-packages/django/views/generic/base.py", line 68, in view
    return self.dispatch(request, *args, **kwargs)
  File "/home/mobilitysqr/.local/lib/python3.6/site-packages/rest_framework/views.py", line 495, in dispatch
    response = self.handle_exception(exc)
  File "/home/mobilitysqr/.local/lib/python3.6/site-packages/rest_framework/views.py", line 455, in handle_exception
    self.raise_uncaught_exception(exc)
  File "/home/mobilitysqr/.local/lib/python3.6/site-packages/rest_framework/views.py", line 492, in dispatch
    response = handler(request, *args, **kwargs)
  File "/var/www/html/mobilitysqr_staging/mobility_apps/employee/views.py", line 84, in post
    print(employees_recent[0]['recent_login'])
  File "/home/mobilitysqr/.local/lib/python3.6/site-packages/django/db/models/query.py", line 303, in __getitem__
    return qs._result_cache[0]
IndexError: list index out of range
ERROR|12/Feb/2021 19:28:58|basehttp|21543|140015343757056|"POST /emoloyeeinfo/ HTTP/1.1" 500 17166
ERROR|12/Feb/2021 19:29:35|log|21543|140015343757056|Internal Server Error: /emoloyeeinfo/
Traceback (most recent call last):
  File "/home/mobilitysqr/.local/lib/python3.6/site-packages/django/core/handlers/exception.py", line 34, in inner
    response = get_response(request)
  File "/home/mobilitysqr/.local/lib/python3.6/site-packages/django/core/handlers/base.py", line 126, in _get_response
    response = self.process_exception_by_middleware(e, request)
  File "/home/mobilitysqr/.local/lib/python3.6/site-packages/django/core/handlers/base.py", line 124, in _get_response
    response = wrapped_callback(request, *callback_args, **callback_kwargs)
  File "/home/mobilitysqr/.local/lib/python3.6/site-packages/django/views/decorators/csrf.py", line 54, in wrapped_view
    return view_func(*args, **kwargs)
  File "/home/mobilitysqr/.local/lib/python3.6/site-packages/django/views/generic/base.py", line 68, in view
    return self.dispatch(request, *args, **kwargs)
  File "/home/mobilitysqr/.local/lib/python3.6/site-packages/rest_framework/views.py", line 495, in dispatch
    response = self.handle_exception(exc)
  File "/home/mobilitysqr/.local/lib/python3.6/site-packages/rest_framework/views.py", line 455, in handle_exception
    self.raise_uncaught_exception(exc)
  File "/home/mobilitysqr/.local/lib/python3.6/site-packages/rest_framework/views.py", line 492, in dispatch
    response = handler(request, *args, **kwargs)
  File "/var/www/html/mobilitysqr_staging/mobility_apps/employee/views.py", line 84, in post
    print(employees_recent[0]['recent_login'])
  File "/home/mobilitysqr/.local/lib/python3.6/site-packages/django/db/models/query.py", line 303, in __getitem__
    return qs._result_cache[0]
IndexError: list index out of range
ERROR|12/Feb/2021 19:29:35|basehttp|21543|140015343757056|"POST /emoloyeeinfo/ HTTP/1.1" 500 17166
ERROR|12/Feb/2021 19:32:06|exception|21543|140015343757056|Invalid HTTP_HOST header: ''. The domain name provided is not valid according to RFC 1034/1035.
ERROR|12/Feb/2021 19:34:27|log|21543|140015343757056|Internal Server Error: /emoloyeeinfo/
Traceback (most recent call last):
  File "/home/mobilitysqr/.local/lib/python3.6/site-packages/django/core/handlers/exception.py", line 34, in inner
    response = get_response(request)
  File "/home/mobilitysqr/.local/lib/python3.6/site-packages/django/core/handlers/base.py", line 126, in _get_response
    response = self.process_exception_by_middleware(e, request)
  File "/home/mobilitysqr/.local/lib/python3.6/site-packages/django/core/handlers/base.py", line 124, in _get_response
    response = wrapped_callback(request, *callback_args, **callback_kwargs)
  File "/home/mobilitysqr/.local/lib/python3.6/site-packages/django/views/decorators/csrf.py", line 54, in wrapped_view
    return view_func(*args, **kwargs)
  File "/home/mobilitysqr/.local/lib/python3.6/site-packages/django/views/generic/base.py", line 68, in view
    return self.dispatch(request, *args, **kwargs)
  File "/home/mobilitysqr/.local/lib/python3.6/site-packages/rest_framework/views.py", line 495, in dispatch
    response = self.handle_exception(exc)
  File "/home/mobilitysqr/.local/lib/python3.6/site-packages/rest_framework/views.py", line 455, in handle_exception
    self.raise_uncaught_exception(exc)
  File "/home/mobilitysqr/.local/lib/python3.6/site-packages/rest_framework/views.py", line 492, in dispatch
    response = handler(request, *args, **kwargs)
  File "/var/www/html/mobilitysqr_staging/mobility_apps/employee/views.py", line 84, in post
    print(employees_recent[0]['recent_login'])
  File "/home/mobilitysqr/.local/lib/python3.6/site-packages/django/db/models/query.py", line 303, in __getitem__
    return qs._result_cache[0]
IndexError: list index out of range
ERROR|12/Feb/2021 19:34:27|basehttp|21543|140015343757056|"POST /emoloyeeinfo/ HTTP/1.1" 500 17166
ERROR|12/Feb/2021 19:38:38|log|21543|140015343757056|Internal Server Error: /emoloyeeinfo/
Traceback (most recent call last):
  File "/home/mobilitysqr/.local/lib/python3.6/site-packages/django/core/handlers/exception.py", line 34, in inner
    response = get_response(request)
  File "/home/mobilitysqr/.local/lib/python3.6/site-packages/django/core/handlers/base.py", line 126, in _get_response
    response = self.process_exception_by_middleware(e, request)
  File "/home/mobilitysqr/.local/lib/python3.6/site-packages/django/core/handlers/base.py", line 124, in _get_response
    response = wrapped_callback(request, *callback_args, **callback_kwargs)
  File "/home/mobilitysqr/.local/lib/python3.6/site-packages/django/views/decorators/csrf.py", line 54, in wrapped_view
    return view_func(*args, **kwargs)
  File "/home/mobilitysqr/.local/lib/python3.6/site-packages/django/views/generic/base.py", line 68, in view
    return self.dispatch(request, *args, **kwargs)
  File "/home/mobilitysqr/.local/lib/python3.6/site-packages/rest_framework/views.py", line 495, in dispatch
    response = self.handle_exception(exc)
  File "/home/mobilitysqr/.local/lib/python3.6/site-packages/rest_framework/views.py", line 455, in handle_exception
    self.raise_uncaught_exception(exc)
  File "/home/mobilitysqr/.local/lib/python3.6/site-packages/rest_framework/views.py", line 492, in dispatch
    response = handler(request, *args, **kwargs)
  File "/var/www/html/mobilitysqr_staging/mobility_apps/employee/views.py", line 84, in post
    print(employees_recent[0]['recent_login'])
  File "/home/mobilitysqr/.local/lib/python3.6/site-packages/django/db/models/query.py", line 303, in __getitem__
    return qs._result_cache[0]
IndexError: list index out of range
ERROR|12/Feb/2021 19:38:38|basehttp|21543|140015343757056|"POST /emoloyeeinfo/ HTTP/1.1" 500 17421
ERROR|12/Feb/2021 19:38:43|log|21543|140015343757056|Internal Server Error: /emoloyeeinfo/
Traceback (most recent call last):
  File "/home/mobilitysqr/.local/lib/python3.6/site-packages/django/core/handlers/exception.py", line 34, in inner
    response = get_response(request)
  File "/home/mobilitysqr/.local/lib/python3.6/site-packages/django/core/handlers/base.py", line 126, in _get_response
    response = self.process_exception_by_middleware(e, request)
  File "/home/mobilitysqr/.local/lib/python3.6/site-packages/django/core/handlers/base.py", line 124, in _get_response
    response = wrapped_callback(request, *callback_args, **callback_kwargs)
  File "/home/mobilitysqr/.local/lib/python3.6/site-packages/django/views/decorators/csrf.py", line 54, in wrapped_view
    return view_func(*args, **kwargs)
  File "/home/mobilitysqr/.local/lib/python3.6/site-packages/django/views/generic/base.py", line 68, in view
    return self.dispatch(request, *args, **kwargs)
  File "/home/mobilitysqr/.local/lib/python3.6/site-packages/rest_framework/views.py", line 495, in dispatch
    response = self.handle_exception(exc)
  File "/home/mobilitysqr/.local/lib/python3.6/site-packages/rest_framework/views.py", line 455, in handle_exception
    self.raise_uncaught_exception(exc)
  File "/home/mobilitysqr/.local/lib/python3.6/site-packages/rest_framework/views.py", line 492, in dispatch
    response = handler(request, *args, **kwargs)
  File "/var/www/html/mobilitysqr_staging/mobility_apps/employee/views.py", line 84, in post
    print(employees_recent[0]['recent_login'])
  File "/home/mobilitysqr/.local/lib/python3.6/site-packages/django/db/models/query.py", line 303, in __getitem__
    return qs._result_cache[0]
IndexError: list index out of range
ERROR|12/Feb/2021 19:38:43|basehttp|21543|140015343757056|"POST /emoloyeeinfo/ HTTP/1.1" 500 17421
ERROR|12/Feb/2021 19:39:09|log|21543|140015343757056|Internal Server Error: /emoloyeeinfo/
Traceback (most recent call last):
  File "/home/mobilitysqr/.local/lib/python3.6/site-packages/django/core/handlers/exception.py", line 34, in inner
    response = get_response(request)
  File "/home/mobilitysqr/.local/lib/python3.6/site-packages/django/core/handlers/base.py", line 126, in _get_response
    response = self.process_exception_by_middleware(e, request)
  File "/home/mobilitysqr/.local/lib/python3.6/site-packages/django/core/handlers/base.py", line 124, in _get_response
    response = wrapped_callback(request, *callback_args, **callback_kwargs)
  File "/home/mobilitysqr/.local/lib/python3.6/site-packages/django/views/decorators/csrf.py", line 54, in wrapped_view
    return view_func(*args, **kwargs)
  File "/home/mobilitysqr/.local/lib/python3.6/site-packages/django/views/generic/base.py", line 68, in view
    return self.dispatch(request, *args, **kwargs)
  File "/home/mobilitysqr/.local/lib/python3.6/site-packages/rest_framework/views.py", line 495, in dispatch
    response = self.handle_exception(exc)
  File "/home/mobilitysqr/.local/lib/python3.6/site-packages/rest_framework/views.py", line 455, in handle_exception
    self.raise_uncaught_exception(exc)
  File "/home/mobilitysqr/.local/lib/python3.6/site-packages/rest_framework/views.py", line 492, in dispatch
    response = handler(request, *args, **kwargs)
  File "/var/www/html/mobilitysqr_staging/mobility_apps/employee/views.py", line 84, in post
    print(employees_recent[0]['recent_login'])
  File "/home/mobilitysqr/.local/lib/python3.6/site-packages/django/db/models/query.py", line 303, in __getitem__
    return qs._result_cache[0]
IndexError: list index out of range
ERROR|12/Feb/2021 19:39:09|basehttp|21543|140015343757056|"POST /emoloyeeinfo/ HTTP/1.1" 500 17421
ERROR|12/Feb/2021 19:39:14|log|21543|140015343757056|Internal Server Error: /emoloyeeinfo/
Traceback (most recent call last):
  File "/home/mobilitysqr/.local/lib/python3.6/site-packages/django/core/handlers/exception.py", line 34, in inner
    response = get_response(request)
  File "/home/mobilitysqr/.local/lib/python3.6/site-packages/django/core/handlers/base.py", line 126, in _get_response
    response = self.process_exception_by_middleware(e, request)
  File "/home/mobilitysqr/.local/lib/python3.6/site-packages/django/core/handlers/base.py", line 124, in _get_response
    response = wrapped_callback(request, *callback_args, **callback_kwargs)
  File "/home/mobilitysqr/.local/lib/python3.6/site-packages/django/views/decorators/csrf.py", line 54, in wrapped_view
    return view_func(*args, **kwargs)
  File "/home/mobilitysqr/.local/lib/python3.6/site-packages/django/views/generic/base.py", line 68, in view
    return self.dispatch(request, *args, **kwargs)
  File "/home/mobilitysqr/.local/lib/python3.6/site-packages/rest_framework/views.py", line 495, in dispatch
    response = self.handle_exception(exc)
  File "/home/mobilitysqr/.local/lib/python3.6/site-packages/rest_framework/views.py", line 455, in handle_exception
    self.raise_uncaught_exception(exc)
  File "/home/mobilitysqr/.local/lib/python3.6/site-packages/rest_framework/views.py", line 492, in dispatch
    response = handler(request, *args, **kwargs)
  File "/var/www/html/mobilitysqr_staging/mobility_apps/employee/views.py", line 84, in post
    print(employees_recent[0]['recent_login'])
  File "/home/mobilitysqr/.local/lib/python3.6/site-packages/django/db/models/query.py", line 303, in __getitem__
    return qs._result_cache[0]
IndexError: list index out of range
ERROR|12/Feb/2021 19:39:14|basehttp|21543|140015343757056|"POST /emoloyeeinfo/ HTTP/1.1" 500 17421
ERROR|12/Feb/2021 19:39:26|log|21543|140015343757056|Internal Server Error: /emoloyeeinfo/
Traceback (most recent call last):
  File "/home/mobilitysqr/.local/lib/python3.6/site-packages/django/core/handlers/exception.py", line 34, in inner
    response = get_response(request)
  File "/home/mobilitysqr/.local/lib/python3.6/site-packages/django/core/handlers/base.py", line 126, in _get_response
    response = self.process_exception_by_middleware(e, request)
  File "/home/mobilitysqr/.local/lib/python3.6/site-packages/django/core/handlers/base.py", line 124, in _get_response
    response = wrapped_callback(request, *callback_args, **callback_kwargs)
  File "/home/mobilitysqr/.local/lib/python3.6/site-packages/django/views/decorators/csrf.py", line 54, in wrapped_view
    return view_func(*args, **kwargs)
  File "/home/mobilitysqr/.local/lib/python3.6/site-packages/django/views/generic/base.py", line 68, in view
    return self.dispatch(request, *args, **kwargs)
  File "/home/mobilitysqr/.local/lib/python3.6/site-packages/rest_framework/views.py", line 495, in dispatch
    response = self.handle_exception(exc)
  File "/home/mobilitysqr/.local/lib/python3.6/site-packages/rest_framework/views.py", line 455, in handle_exception
    self.raise_uncaught_exception(exc)
  File "/home/mobilitysqr/.local/lib/python3.6/site-packages/rest_framework/views.py", line 492, in dispatch
    response = handler(request, *args, **kwargs)
  File "/var/www/html/mobilitysqr_staging/mobility_apps/employee/views.py", line 84, in post
    print(employees_recent[0]['recent_login'])
  File "/home/mobilitysqr/.local/lib/python3.6/site-packages/django/db/models/query.py", line 303, in __getitem__
    return qs._result_cache[0]
IndexError: list index out of range
ERROR|12/Feb/2021 19:39:26|basehttp|21543|140015343757056|"POST /emoloyeeinfo/ HTTP/1.1" 500 17421
ERROR|12/Feb/2021 19:39:39|log|21543|140015343757056|Internal Server Error: /emoloyeeinfo/
Traceback (most recent call last):
  File "/home/mobilitysqr/.local/lib/python3.6/site-packages/django/core/handlers/exception.py", line 34, in inner
    response = get_response(request)
  File "/home/mobilitysqr/.local/lib/python3.6/site-packages/django/core/handlers/base.py", line 126, in _get_response
    response = self.process_exception_by_middleware(e, request)
  File "/home/mobilitysqr/.local/lib/python3.6/site-packages/django/core/handlers/base.py", line 124, in _get_response
    response = wrapped_callback(request, *callback_args, **callback_kwargs)
  File "/home/mobilitysqr/.local/lib/python3.6/site-packages/django/views/decorators/csrf.py", line 54, in wrapped_view
    return view_func(*args, **kwargs)
  File "/home/mobilitysqr/.local/lib/python3.6/site-packages/django/views/generic/base.py", line 68, in view
    return self.dispatch(request, *args, **kwargs)
  File "/home/mobilitysqr/.local/lib/python3.6/site-packages/rest_framework/views.py", line 495, in dispatch
    response = self.handle_exception(exc)
  File "/home/mobilitysqr/.local/lib/python3.6/site-packages/rest_framework/views.py", line 455, in handle_exception
    self.raise_uncaught_exception(exc)
  File "/home/mobilitysqr/.local/lib/python3.6/site-packages/rest_framework/views.py", line 492, in dispatch
    response = handler(request, *args, **kwargs)
  File "/var/www/html/mobilitysqr_staging/mobility_apps/employee/views.py", line 84, in post
    print(employees_recent[0]['recent_login'])
  File "/home/mobilitysqr/.local/lib/python3.6/site-packages/django/db/models/query.py", line 303, in __getitem__
    return qs._result_cache[0]
IndexError: list index out of range
ERROR|12/Feb/2021 19:39:39|basehttp|21543|140015343757056|"POST /emoloyeeinfo/ HTTP/1.1" 500 17421
ERROR|12/Feb/2021 19:39:53|log|21543|140015343757056|Internal Server Error: /emoloyeeinfo/
Traceback (most recent call last):
  File "/home/mobilitysqr/.local/lib/python3.6/site-packages/django/core/handlers/exception.py", line 34, in inner
    response = get_response(request)
  File "/home/mobilitysqr/.local/lib/python3.6/site-packages/django/core/handlers/base.py", line 126, in _get_response
    response = self.process_exception_by_middleware(e, request)
  File "/home/mobilitysqr/.local/lib/python3.6/site-packages/django/core/handlers/base.py", line 124, in _get_response
    response = wrapped_callback(request, *callback_args, **callback_kwargs)
  File "/home/mobilitysqr/.local/lib/python3.6/site-packages/django/views/decorators/csrf.py", line 54, in wrapped_view
    return view_func(*args, **kwargs)
  File "/home/mobilitysqr/.local/lib/python3.6/site-packages/django/views/generic/base.py", line 68, in view
    return self.dispatch(request, *args, **kwargs)
  File "/home/mobilitysqr/.local/lib/python3.6/site-packages/rest_framework/views.py", line 495, in dispatch
    response = self.handle_exception(exc)
  File "/home/mobilitysqr/.local/lib/python3.6/site-packages/rest_framework/views.py", line 455, in handle_exception
    self.raise_uncaught_exception(exc)
  File "/home/mobilitysqr/.local/lib/python3.6/site-packages/rest_framework/views.py", line 492, in dispatch
    response = handler(request, *args, **kwargs)
  File "/var/www/html/mobilitysqr_staging/mobility_apps/employee/views.py", line 84, in post
    print(employees_recent[0]['recent_login'])
  File "/home/mobilitysqr/.local/lib/python3.6/site-packages/django/db/models/query.py", line 303, in __getitem__
    return qs._result_cache[0]
IndexError: list index out of range
ERROR|12/Feb/2021 19:39:53|basehttp|21543|140015343757056|"POST /emoloyeeinfo/ HTTP/1.1" 500 17421
ERROR|12/Feb/2021 19:40:15|log|21543|140015343757056|Internal Server Error: /emoloyeeinfo/
Traceback (most recent call last):
  File "/home/mobilitysqr/.local/lib/python3.6/site-packages/django/core/handlers/exception.py", line 34, in inner
    response = get_response(request)
  File "/home/mobilitysqr/.local/lib/python3.6/site-packages/django/core/handlers/base.py", line 126, in _get_response
    response = self.process_exception_by_middleware(e, request)
  File "/home/mobilitysqr/.local/lib/python3.6/site-packages/django/core/handlers/base.py", line 124, in _get_response
    response = wrapped_callback(request, *callback_args, **callback_kwargs)
  File "/home/mobilitysqr/.local/lib/python3.6/site-packages/django/views/decorators/csrf.py", line 54, in wrapped_view
    return view_func(*args, **kwargs)
  File "/home/mobilitysqr/.local/lib/python3.6/site-packages/django/views/generic/base.py", line 68, in view
    return self.dispatch(request, *args, **kwargs)
  File "/home/mobilitysqr/.local/lib/python3.6/site-packages/rest_framework/views.py", line 495, in dispatch
    response = self.handle_exception(exc)
  File "/home/mobilitysqr/.local/lib/python3.6/site-packages/rest_framework/views.py", line 455, in handle_exception
    self.raise_uncaught_exception(exc)
  File "/home/mobilitysqr/.local/lib/python3.6/site-packages/rest_framework/views.py", line 492, in dispatch
    response = handler(request, *args, **kwargs)
  File "/var/www/html/mobilitysqr_staging/mobility_apps/employee/views.py", line 84, in post
    print(employees_recent[0]['recent_login'])
  File "/home/mobilitysqr/.local/lib/python3.6/site-packages/django/db/models/query.py", line 303, in __getitem__
    return qs._result_cache[0]
IndexError: list index out of range
ERROR|12/Feb/2021 19:40:15|basehttp|21543|140015343757056|"POST /emoloyeeinfo/ HTTP/1.1" 500 17424
ERROR|12/Feb/2021 19:40:56|log|21543|140015343757056|Internal Server Error: /emoloyeeinfo/
Traceback (most recent call last):
  File "/home/mobilitysqr/.local/lib/python3.6/site-packages/django/core/handlers/exception.py", line 34, in inner
    response = get_response(request)
  File "/home/mobilitysqr/.local/lib/python3.6/site-packages/django/core/handlers/base.py", line 126, in _get_response
    response = self.process_exception_by_middleware(e, request)
  File "/home/mobilitysqr/.local/lib/python3.6/site-packages/django/core/handlers/base.py", line 124, in _get_response
    response = wrapped_callback(request, *callback_args, **callback_kwargs)
  File "/home/mobilitysqr/.local/lib/python3.6/site-packages/django/views/decorators/csrf.py", line 54, in wrapped_view
    return view_func(*args, **kwargs)
  File "/home/mobilitysqr/.local/lib/python3.6/site-packages/django/views/generic/base.py", line 68, in view
    return self.dispatch(request, *args, **kwargs)
  File "/home/mobilitysqr/.local/lib/python3.6/site-packages/rest_framework/views.py", line 495, in dispatch
    response = self.handle_exception(exc)
  File "/home/mobilitysqr/.local/lib/python3.6/site-packages/rest_framework/views.py", line 455, in handle_exception
    self.raise_uncaught_exception(exc)
  File "/home/mobilitysqr/.local/lib/python3.6/site-packages/rest_framework/views.py", line 492, in dispatch
    response = handler(request, *args, **kwargs)
  File "/var/www/html/mobilitysqr_staging/mobility_apps/employee/views.py", line 84, in post
    print(employees_recent[0]['recent_login'])
  File "/home/mobilitysqr/.local/lib/python3.6/site-packages/django/db/models/query.py", line 303, in __getitem__
    return qs._result_cache[0]
IndexError: list index out of range
ERROR|12/Feb/2021 19:40:56|basehttp|21543|140015343757056|"POST /emoloyeeinfo/ HTTP/1.1" 500 17424
ERROR|12/Feb/2021 19:42:40|log|21543|140015343757056|Internal Server Error: /emoloyeeinfo/
Traceback (most recent call last):
  File "/home/mobilitysqr/.local/lib/python3.6/site-packages/django/core/handlers/exception.py", line 34, in inner
    response = get_response(request)
  File "/home/mobilitysqr/.local/lib/python3.6/site-packages/django/core/handlers/base.py", line 126, in _get_response
    response = self.process_exception_by_middleware(e, request)
  File "/home/mobilitysqr/.local/lib/python3.6/site-packages/django/core/handlers/base.py", line 124, in _get_response
    response = wrapped_callback(request, *callback_args, **callback_kwargs)
  File "/home/mobilitysqr/.local/lib/python3.6/site-packages/django/views/decorators/csrf.py", line 54, in wrapped_view
    return view_func(*args, **kwargs)
  File "/home/mobilitysqr/.local/lib/python3.6/site-packages/django/views/generic/base.py", line 68, in view
    return self.dispatch(request, *args, **kwargs)
  File "/home/mobilitysqr/.local/lib/python3.6/site-packages/rest_framework/views.py", line 495, in dispatch
    response = self.handle_exception(exc)
  File "/home/mobilitysqr/.local/lib/python3.6/site-packages/rest_framework/views.py", line 455, in handle_exception
    self.raise_uncaught_exception(exc)
  File "/home/mobilitysqr/.local/lib/python3.6/site-packages/rest_framework/views.py", line 492, in dispatch
    response = handler(request, *args, **kwargs)
  File "/var/www/html/mobilitysqr_staging/mobility_apps/employee/views.py", line 84, in post
    print(employees_recent[0]['recent_login'])
  File "/home/mobilitysqr/.local/lib/python3.6/site-packages/django/db/models/query.py", line 303, in __getitem__
    return qs._result_cache[0]
IndexError: list index out of range
ERROR|12/Feb/2021 19:42:40|basehttp|21543|140015343757056|"POST /emoloyeeinfo/ HTTP/1.1" 500 17424
ERROR|12/Feb/2021 19:43:55|log|21543|140015343757056|Internal Server Error: /emoloyeeinfo/
Traceback (most recent call last):
  File "/home/mobilitysqr/.local/lib/python3.6/site-packages/django/core/handlers/exception.py", line 34, in inner
    response = get_response(request)
  File "/home/mobilitysqr/.local/lib/python3.6/site-packages/django/core/handlers/base.py", line 126, in _get_response
    response = self.process_exception_by_middleware(e, request)
  File "/home/mobilitysqr/.local/lib/python3.6/site-packages/django/core/handlers/base.py", line 124, in _get_response
    response = wrapped_callback(request, *callback_args, **callback_kwargs)
  File "/home/mobilitysqr/.local/lib/python3.6/site-packages/django/views/decorators/csrf.py", line 54, in wrapped_view
    return view_func(*args, **kwargs)
  File "/home/mobilitysqr/.local/lib/python3.6/site-packages/django/views/generic/base.py", line 68, in view
    return self.dispatch(request, *args, **kwargs)
  File "/home/mobilitysqr/.local/lib/python3.6/site-packages/rest_framework/views.py", line 495, in dispatch
    response = self.handle_exception(exc)
  File "/home/mobilitysqr/.local/lib/python3.6/site-packages/rest_framework/views.py", line 455, in handle_exception
    self.raise_uncaught_exception(exc)
  File "/home/mobilitysqr/.local/lib/python3.6/site-packages/rest_framework/views.py", line 492, in dispatch
    response = handler(request, *args, **kwargs)
  File "/var/www/html/mobilitysqr_staging/mobility_apps/employee/views.py", line 84, in post
    print(employees_recent[0]['recent_login'])
  File "/home/mobilitysqr/.local/lib/python3.6/site-packages/django/db/models/query.py", line 303, in __getitem__
    return qs._result_cache[0]
IndexError: list index out of range
ERROR|12/Feb/2021 19:43:55|basehttp|21543|140015343757056|"POST /emoloyeeinfo/ HTTP/1.1" 500 17424
ERROR|12/Feb/2021 19:44:37|log|21543|140015262758656|Internal Server Error: /emoloyeeinfo/
Traceback (most recent call last):
  File "/home/mobilitysqr/.local/lib/python3.6/site-packages/django/core/handlers/exception.py", line 34, in inner
    response = get_response(request)
  File "/home/mobilitysqr/.local/lib/python3.6/site-packages/django/core/handlers/base.py", line 126, in _get_response
    response = self.process_exception_by_middleware(e, request)
  File "/home/mobilitysqr/.local/lib/python3.6/site-packages/django/core/handlers/base.py", line 124, in _get_response
    response = wrapped_callback(request, *callback_args, **callback_kwargs)
  File "/home/mobilitysqr/.local/lib/python3.6/site-packages/django/views/decorators/csrf.py", line 54, in wrapped_view
    return view_func(*args, **kwargs)
  File "/home/mobilitysqr/.local/lib/python3.6/site-packages/django/views/generic/base.py", line 68, in view
    return self.dispatch(request, *args, **kwargs)
  File "/home/mobilitysqr/.local/lib/python3.6/site-packages/rest_framework/views.py", line 495, in dispatch
    response = self.handle_exception(exc)
  File "/home/mobilitysqr/.local/lib/python3.6/site-packages/rest_framework/views.py", line 455, in handle_exception
    self.raise_uncaught_exception(exc)
  File "/home/mobilitysqr/.local/lib/python3.6/site-packages/rest_framework/views.py", line 492, in dispatch
    response = handler(request, *args, **kwargs)
  File "/var/www/html/mobilitysqr_staging/mobility_apps/employee/views.py", line 84, in post
    print(employees_recent[0]['recent_login'])
  File "/home/mobilitysqr/.local/lib/python3.6/site-packages/django/db/models/query.py", line 303, in __getitem__
    return qs._result_cache[0]
IndexError: list index out of range
ERROR|12/Feb/2021 19:44:37|basehttp|21543|140015262758656|"POST /emoloyeeinfo/ HTTP/1.1" 500 17422
ERROR|12/Feb/2021 19:45:04|log|21543|140015262758656|Internal Server Error: /emoloyeeinfo/
Traceback (most recent call last):
  File "/home/mobilitysqr/.local/lib/python3.6/site-packages/django/core/handlers/exception.py", line 34, in inner
    response = get_response(request)
  File "/home/mobilitysqr/.local/lib/python3.6/site-packages/django/core/handlers/base.py", line 126, in _get_response
    response = self.process_exception_by_middleware(e, request)
  File "/home/mobilitysqr/.local/lib/python3.6/site-packages/django/core/handlers/base.py", line 124, in _get_response
    response = wrapped_callback(request, *callback_args, **callback_kwargs)
  File "/home/mobilitysqr/.local/lib/python3.6/site-packages/django/views/decorators/csrf.py", line 54, in wrapped_view
    return view_func(*args, **kwargs)
  File "/home/mobilitysqr/.local/lib/python3.6/site-packages/django/views/generic/base.py", line 68, in view
    return self.dispatch(request, *args, **kwargs)
  File "/home/mobilitysqr/.local/lib/python3.6/site-packages/rest_framework/views.py", line 495, in dispatch
    response = self.handle_exception(exc)
  File "/home/mobilitysqr/.local/lib/python3.6/site-packages/rest_framework/views.py", line 455, in handle_exception
    self.raise_uncaught_exception(exc)
  File "/home/mobilitysqr/.local/lib/python3.6/site-packages/rest_framework/views.py", line 492, in dispatch
    response = handler(request, *args, **kwargs)
  File "/var/www/html/mobilitysqr_staging/mobility_apps/employee/views.py", line 84, in post
    print(employees_recent[0]['recent_login'])
  File "/home/mobilitysqr/.local/lib/python3.6/site-packages/django/db/models/query.py", line 303, in __getitem__
    return qs._result_cache[0]
IndexError: list index out of range
ERROR|12/Feb/2021 19:45:04|basehttp|21543|140015262758656|"POST /emoloyeeinfo/ HTTP/1.1" 500 17422
ERROR|12/Feb/2021 19:50:13|exception|22258|140375996565248|Invalid HTTP_HOST header: ''. The domain name provided is not valid according to RFC 1034/1035.
ERROR|12/Feb/2021 20:27:31|basehttp|22258|140375987123968|"GET /media/Koala_74ufFrT.jpg HTTP/1.1" 500 59
ERROR|12/Feb/2021 20:55:54|exception|22258|140375996565248|Invalid HTTP_HOST header: ''. The domain name provided is not valid according to RFC 1034/1035.
ERROR|12/Feb/2021 22:01:01|exception|22258|140375890327296|Invalid HTTP_HOST header: ''. The domain name provided is not valid according to RFC 1034/1035.
ERROR|12/Feb/2021 22:01:02|basehttp|22258|140375890327296|"GET /script HTTP/1.1" 500 59
ERROR|12/Feb/2021 22:03:15|exception|22258|140375890327296|Invalid HTTP_HOST header: ''. The domain name provided is not valid according to RFC 1034/1035.
ERROR|12/Feb/2021 22:03:15|basehttp|22258|140375890327296|"GET /script HTTP/1.1" 500 59
ERROR|12/Feb/2021 22:37:22|exception|22258|140375890327296|Invalid HTTP_HOST header: ''. The domain name provided is not valid according to RFC 1034/1035.
ERROR|12/Feb/2021 22:38:10|exception|22258|140375890327296|Invalid HTTP_HOST header: ''. The domain name provided is not valid according to RFC 1034/1035.
ERROR|12/Feb/2021 22:53:29|exception|22258|140375890327296|Invalid HTTP_HOST header: ''. The domain name provided is not valid according to RFC 1034/1035.
ERROR|12/Feb/2021 23:13:27|exception|22258|140375890327296|Invalid HTTP_HOST header: ''. The domain name provided is not valid according to RFC 1034/1035.
ERROR|13/Feb/2021 00:34:53|exception|22258|140375890327296|Invalid HTTP_HOST header: ''. The domain name provided is not valid according to RFC 1034/1035.
ERROR|13/Feb/2021 00:36:05|exception|22258|140375890327296|Invalid HTTP_HOST header: ''. The domain name provided is not valid according to RFC 1034/1035.
ERROR|13/Feb/2021 00:47:49|exception|22258|140375890327296|Invalid HTTP_HOST header: ''. The domain name provided is not valid according to RFC 1034/1035.
ERROR|13/Feb/2021 00:55:47|exception|22258|140375890327296|Invalid HTTP_HOST header: ''. The domain name provided is not valid according to RFC 1034/1035.
ERROR|13/Feb/2021 01:11:27|exception|22258|140375890327296|Invalid HTTP_HOST header: ''. The domain name provided is not valid according to RFC 1034/1035.
ERROR|13/Feb/2021 03:16:49|exception|22258|140375890327296|Invalid HTTP_HOST header: ''. The domain name provided is not valid according to RFC 1034/1035.
ERROR|13/Feb/2021 03:16:49|basehttp|22258|140375890327296|"GET /manager/html HTTP/1.1" 500 59
ERROR|13/Feb/2021 04:08:15|exception|22258|140375996565248|Invalid HTTP_HOST header: ''. The domain name provided is not valid according to RFC 1034/1035.
ERROR|13/Feb/2021 04:09:11|basehttp|22258|140375996565248|You're accessing the development server over HTTPS, but it only supports HTTP.

ERROR|13/Feb/2021 05:01:54|exception|22258|140375890327296|Invalid HTTP_HOST header: ''. The domain name provided is not valid according to RFC 1034/1035.
ERROR|13/Feb/2021 05:03:34|exception|22258|140375890327296|Invalid HTTP_HOST header: ''. The domain name provided is not valid according to RFC 1034/1035.
ERROR|13/Feb/2021 06:03:22|exception|22258|140375890327296|Invalid HTTP_HOST header: ''. The domain name provided is not valid according to RFC 1034/1035.
ERROR|13/Feb/2021 07:15:50|exception|22258|140375890327296|Invalid HTTP_HOST header: ''. The domain name provided is not valid according to RFC 1034/1035.
ERROR|13/Feb/2021 07:27:01|exception|22258|140375890327296|Invalid HTTP_HOST header: ''. The domain name provided is not valid according to RFC 1034/1035.
ERROR|13/Feb/2021 07:27:01|basehttp|22258|140375890327296|"GET /script HTTP/1.1" 500 59
ERROR|13/Feb/2021 08:51:50|exception|22258|140375996565248|Invalid HTTP_HOST header: ''. The domain name provided is not valid according to RFC 1034/1035.
ERROR|13/Feb/2021 08:51:50|basehttp|22258|140375996565248|"GET /script HTTP/1.1" 500 59
ERROR|13/Feb/2021 09:04:18|exception|22258|140375996565248|Invalid HTTP_HOST header: ''. The domain name provided is not valid according to RFC 1034/1035.
ERROR|13/Feb/2021 10:04:13|exception|22258|140375996565248|Invalid HTTP_HOST header: ''. The domain name provided is not valid according to RFC 1034/1035.
ERROR|13/Feb/2021 11:05:28|exception|22258|140375850473216|Invalid HTTP_HOST header: ''. The domain name provided is not valid according to RFC 1034/1035.
ERROR|13/Feb/2021 11:24:20|exception|22258|140375850473216|Invalid HTTP_HOST header: ''. The domain name provided is not valid according to RFC 1034/1035.
ERROR|13/Feb/2021 12:53:16|exception|22258|140375850473216|Invalid HTTP_HOST header: ''. The domain name provided is not valid according to RFC 1034/1035.
ERROR|13/Feb/2021 15:04:05|exception|22258|140375850473216|Invalid HTTP_HOST header: ''. The domain name provided is not valid according to RFC 1034/1035.
ERROR|13/Feb/2021 15:34:20|log|22258|140375850473216|Internal Server Error: /users
Traceback (most recent call last):
  File "/home/mobilitysqr/.local/lib/python3.6/site-packages/django/core/handlers/exception.py", line 34, in inner
    response = get_response(request)
  File "/home/mobilitysqr/.local/lib/python3.6/site-packages/django/utils/deprecation.py", line 90, in __call__
    response = self.process_request(request)
  File "/home/mobilitysqr/.local/lib/python3.6/site-packages/django/middleware/common.py", line 53, in process_request
    path = self.get_full_path_with_slash(request)
  File "/home/mobilitysqr/.local/lib/python3.6/site-packages/django/middleware/common.py", line 93, in get_full_path_with_slash
    'url': request.get_host() + new_path,
RuntimeError: You called this URL via POST, but the URL doesn't end in a slash and you have APPEND_SLASH set. Django can't redirect to the slash URL while maintaining POST data. Change your form to point to 52.165.220.40:8080/users/?page=&size=5 (note the trailing slash), or set APPEND_SLASH=False in your Django settings.
ERROR|13/Feb/2021 15:34:20|basehttp|22258|140375850473216|"POST /users?page=&size=5 HTTP/1.1" 500 65452
ERROR|13/Feb/2021 17:57:56|exception|22258|140375996565248|Invalid HTTP_HOST header: ''. The domain name provided is not valid according to RFC 1034/1035.
ERROR|13/Feb/2021 20:24:02|exception|22258|140375850473216|Invalid HTTP_HOST header: ''. The domain name provided is not valid according to RFC 1034/1035.
ERROR|13/Feb/2021 20:24:02|basehttp|22258|140375850473216|"GET /manager/html HTTP/1.1" 500 59
ERROR|13/Feb/2021 22:34:53|exception|22258|140375850473216|Invalid HTTP_HOST header: ''. The domain name provided is not valid according to RFC 1034/1035.
ERROR|13/Feb/2021 22:55:27|exception|22258|140375850473216|Invalid HTTP_HOST header: ''. The domain name provided is not valid according to RFC 1034/1035.
ERROR|13/Feb/2021 23:28:11|exception|22258|140375850473216|Invalid HTTP_HOST header: ''. The domain name provided is not valid according to RFC 1034/1035.
ERROR|13/Feb/2021 23:28:11|basehttp|22258|140375850473216|"GET /script HTTP/1.1" 500 59
ERROR|13/Feb/2021 23:33:41|exception|22258|140375850473216|Invalid HTTP_HOST header: ''. The domain name provided is not valid according to RFC 1034/1035.
ERROR|13/Feb/2021 23:47:55|exception|22258|140375850473216|Invalid HTTP_HOST header: ''. The domain name provided is not valid according to RFC 1034/1035.
ERROR|13/Feb/2021 23:50:40|exception|22258|140375850473216|Invalid HTTP_HOST header: ''. The domain name provided is not valid according to RFC 1034/1035.
ERROR|14/Feb/2021 00:51:53|exception|22258|140375850473216|Invalid HTTP_HOST header: ''. The domain name provided is not valid according to RFC 1034/1035.
ERROR|14/Feb/2021 01:29:16|exception|22258|140375850473216|Invalid HTTP_HOST header: ''. The domain name provided is not valid according to RFC 1034/1035.
ERROR|14/Feb/2021 01:30:53|basehttp|22258|140375850473216|You're accessing the development server over HTTPS, but it only supports HTTP.

ERROR|14/Feb/2021 01:31:45|exception|22258|140375850473216|Invalid HTTP_HOST header: ''. The domain name provided is not valid according to RFC 1034/1035.
ERROR|14/Feb/2021 01:38:44|exception|22258|140375850473216|Invalid HTTP_HOST header: ''. The domain name provided is not valid according to RFC 1034/1035.
ERROR|14/Feb/2021 02:48:14|exception|22258|140375996565248|Invalid HTTP_HOST header: ''. The domain name provided is not valid according to RFC 1034/1035.
ERROR|14/Feb/2021 05:28:26|exception|22258|140375996565248|Invalid HTTP_HOST header: ''. The domain name provided is not valid according to RFC 1034/1035.
ERROR|14/Feb/2021 05:33:40|exception|22258|140375996565248|Invalid HTTP_HOST header: ''. The domain name provided is not valid according to RFC 1034/1035.
ERROR|14/Feb/2021 07:41:05|exception|22258|140375996565248|Invalid HTTP_HOST header: ''. The domain name provided is not valid according to RFC 1034/1035.
ERROR|14/Feb/2021 08:00:31|exception|22258|140375996565248|Invalid HTTP_HOST header: ''. The domain name provided is not valid according to RFC 1034/1035.
ERROR|14/Feb/2021 08:04:55|exception|22258|140375996565248|Invalid HTTP_HOST header: ''. The domain name provided is not valid according to RFC 1034/1035.
ERROR|14/Feb/2021 08:24:10|exception|22258|140375996565248|Invalid HTTP_HOST header: ''. The domain name provided is not valid according to RFC 1034/1035.
ERROR|14/Feb/2021 09:42:44|exception|22258|140375996565248|Invalid HTTP_HOST header: ''. The domain name provided is not valid according to RFC 1034/1035.
ERROR|14/Feb/2021 11:42:05|exception|22258|140375996565248|Invalid HTTP_HOST header: ''. The domain name provided is not valid according to RFC 1034/1035.
ERROR|14/Feb/2021 13:13:01|exception|22258|140375890327296|Invalid HTTP_HOST header: ''. The domain name provided is not valid according to RFC 1034/1035.
ERROR|14/Feb/2021 13:58:00|exception|22258|140375890327296|Invalid HTTP_HOST header: ''. The domain name provided is not valid according to RFC 1034/1035.
ERROR|14/Feb/2021 14:02:38|exception|22258|140375890327296|Invalid HTTP_HOST header: ''. The domain name provided is not valid according to RFC 1034/1035.
ERROR|14/Feb/2021 14:46:21|exception|22258|140375890327296|Invalid HTTP_HOST header: ''. The domain name provided is not valid according to RFC 1034/1035.
ERROR|14/Feb/2021 15:31:27|exception|22258|140375850473216|Invalid HTTP_HOST header: ''. The domain name provided is not valid according to RFC 1034/1035.
ERROR|14/Feb/2021 16:30:53|exception|22258|140375850473216|Invalid HTTP_HOST header: ''. The domain name provided is not valid according to RFC 1034/1035.
ERROR|14/Feb/2021 16:30:53|basehttp|22258|140375850473216|"GET /manager/html HTTP/1.1" 500 59
ERROR|14/Feb/2021 17:02:07|exception|22258|140375890327296|Invalid HTTP_HOST header: ''. The domain name provided is not valid according to RFC 1034/1035.
ERROR|14/Feb/2021 17:07:44|exception|22258|140375890327296|Invalid HTTP_HOST header: ''. The domain name provided is not valid according to RFC 1034/1035.
ERROR|14/Feb/2021 18:35:25|exception|22258|140375890327296|Invalid HTTP_HOST header: ''. The domain name provided is not valid according to RFC 1034/1035.
ERROR|14/Feb/2021 20:08:54|exception|22258|140375890327296|Invalid HTTP_HOST header: ''. The domain name provided is not valid according to RFC 1034/1035.
ERROR|14/Feb/2021 20:08:54|basehttp|22258|140375890327296|"GET /manager/html HTTP/1.1" 500 59
ERROR|14/Feb/2021 21:44:23|exception|22258|140375890327296|Invalid HTTP_HOST header: ''. The domain name provided is not valid according to RFC 1034/1035.
ERROR|14/Feb/2021 21:44:42|exception|22258|140375890327296|Invalid HTTP_HOST header: ''. The domain name provided is not valid according to RFC 1034/1035.
ERROR|14/Feb/2021 22:20:57|exception|22258|140375890327296|Invalid HTTP_HOST header: ''. The domain name provided is not valid according to RFC 1034/1035.
ERROR|14/Feb/2021 23:20:35|exception|22258|140375890327296|Invalid HTTP_HOST header: ''. The domain name provided is not valid according to RFC 1034/1035.
ERROR|14/Feb/2021 23:20:35|basehttp|22258|140375890327296|"GET /manager/html HTTP/1.1" 500 59
ERROR|14/Feb/2021 23:25:33|exception|22258|140375890327296|Invalid HTTP_HOST header: ''. The domain name provided is not valid according to RFC 1034/1035.
ERROR|14/Feb/2021 23:40:18|exception|22258|140375890327296|Invalid HTTP_HOST header: ''. The domain name provided is not valid according to RFC 1034/1035.
ERROR|15/Feb/2021 00:07:30|exception|22258|140375890327296|Invalid HTTP_HOST header: ''. The domain name provided is not valid according to RFC 1034/1035.
ERROR|15/Feb/2021 01:10:54|exception|22258|140375890327296|Invalid HTTP_HOST header: ''. The domain name provided is not valid according to RFC 1034/1035.
ERROR|15/Feb/2021 01:59:51|exception|22258|140375890327296|Invalid HTTP_HOST header: ''. The domain name provided is not valid according to RFC 1034/1035.
ERROR|15/Feb/2021 02:03:58|exception|22258|140375890327296|Invalid HTTP_HOST header: ''. The domain name provided is not valid according to RFC 1034/1035.
ERROR|15/Feb/2021 03:48:09|exception|22258|140375890327296|Invalid HTTP_HOST header: ''. The domain name provided is not valid according to RFC 1034/1035.
ERROR|15/Feb/2021 05:05:33|exception|22258|140375890327296|Invalid HTTP_HOST header: ''. The domain name provided is not valid according to RFC 1034/1035.
ERROR|15/Feb/2021 05:33:00|exception|22258|140375890327296|Invalid HTTP_HOST header: ''. The domain name provided is not valid according to RFC 1034/1035.
ERROR|15/Feb/2021 05:49:20|exception|22258|140375890327296|Invalid HTTP_HOST header: ''. The domain name provided is not valid according to RFC 1034/1035.
ERROR|15/Feb/2021 07:33:57|exception|22258|140375850473216|Invalid HTTP_HOST header: ''. The domain name provided is not valid according to RFC 1034/1035.
ERROR|15/Feb/2021 08:08:30|exception|22258|140375850473216|Invalid HTTP_HOST header: ''. The domain name provided is not valid according to RFC 1034/1035.
ERROR|15/Feb/2021 08:43:39|log|22258|140375850473216|Internal Server Error: /users
Traceback (most recent call last):
  File "/home/mobilitysqr/.local/lib/python3.6/site-packages/django/core/handlers/exception.py", line 34, in inner
    response = get_response(request)
  File "/home/mobilitysqr/.local/lib/python3.6/site-packages/django/utils/deprecation.py", line 90, in __call__
    response = self.process_request(request)
  File "/home/mobilitysqr/.local/lib/python3.6/site-packages/django/middleware/common.py", line 53, in process_request
    path = self.get_full_path_with_slash(request)
  File "/home/mobilitysqr/.local/lib/python3.6/site-packages/django/middleware/common.py", line 93, in get_full_path_with_slash
    'url': request.get_host() + new_path,
RuntimeError: You called this URL via POST, but the URL doesn't end in a slash and you have APPEND_SLASH set. Django can't redirect to the slash URL while maintaining POST data. Change your form to point to 52.165.220.40:8080/users/?page=&size=5 (note the trailing slash), or set APPEND_SLASH=False in your Django settings.
ERROR|15/Feb/2021 08:43:39|basehttp|22258|140375850473216|"POST /users?page=&size=5 HTTP/1.1" 500 65450
ERROR|15/Feb/2021 09:33:16|exception|22258|140375996565248|Invalid HTTP_HOST header: ''. The domain name provided is not valid according to RFC 1034/1035.
ERROR|15/Feb/2021 10:17:24|exception|22258|140375996565248|Invalid HTTP_HOST header: ''. The domain name provided is not valid according to RFC 1034/1035.
ERROR|15/Feb/2021 12:50:21|exception|22258|140375553464064|Invalid HTTP_HOST header: ''. The domain name provided is not valid according to RFC 1034/1035.
ERROR|15/Feb/2021 13:52:55|exception|22258|140375890327296|Invalid HTTP_HOST header: ''. The domain name provided is not valid according to RFC 1034/1035.
ERROR|15/Feb/2021 15:08:31|basehttp|22258|140375513097984|"GET /emoloyee_search_info/?employee= HTTP/1.1" 500 59
ERROR|15/Feb/2021 15:08:31|basehttp|22258|140375858865920|"GET /emoloyee_search_info/?employee= HTTP/1.1" 500 59
ERROR|15/Feb/2021 15:41:38|log|22258|140375888492288|Internal Server Error: /Otp_Generate/
Traceback (most recent call last):
  File "/home/mobilitysqr/.local/lib/python3.6/site-packages/django/core/handlers/exception.py", line 34, in inner
    response = get_response(request)
  File "/home/mobilitysqr/.local/lib/python3.6/site-packages/django/core/handlers/base.py", line 126, in _get_response
    response = self.process_exception_by_middleware(e, request)
  File "/home/mobilitysqr/.local/lib/python3.6/site-packages/django/core/handlers/base.py", line 124, in _get_response
    response = wrapped_callback(request, *callback_args, **callback_kwargs)
  File "/home/mobilitysqr/.local/lib/python3.6/site-packages/django/views/decorators/csrf.py", line 54, in wrapped_view
    return view_func(*args, **kwargs)
  File "/home/mobilitysqr/.local/lib/python3.6/site-packages/django/views/generic/base.py", line 68, in view
    return self.dispatch(request, *args, **kwargs)
  File "/home/mobilitysqr/.local/lib/python3.6/site-packages/rest_framework/views.py", line 495, in dispatch
    response = self.handle_exception(exc)
  File "/home/mobilitysqr/.local/lib/python3.6/site-packages/rest_framework/views.py", line 455, in handle_exception
    self.raise_uncaught_exception(exc)
  File "/home/mobilitysqr/.local/lib/python3.6/site-packages/rest_framework/views.py", line 492, in dispatch
    response = handler(request, *args, **kwargs)
  File "/var/www/html/mobilitysqr_staging/mobility_apps/employee/views.py", line 1848, in post
    'email': self.employee_name(email=email[0]['email'])
  File "/home/mobilitysqr/.local/lib/python3.6/site-packages/django/db/models/query.py", line 303, in __getitem__
    return qs._result_cache[0]
IndexError: list index out of range
ERROR|15/Feb/2021 15:41:38|basehttp|22258|140375888492288|"POST /Otp_Generate/ HTTP/1.1" 500 17220
ERROR|15/Feb/2021 15:44:26|log|22258|140375888492288|Internal Server Error: /Otp_Generate/
Traceback (most recent call last):
  File "/home/mobilitysqr/.local/lib/python3.6/site-packages/django/core/handlers/exception.py", line 34, in inner
    response = get_response(request)
  File "/home/mobilitysqr/.local/lib/python3.6/site-packages/django/core/handlers/base.py", line 126, in _get_response
    response = self.process_exception_by_middleware(e, request)
  File "/home/mobilitysqr/.local/lib/python3.6/site-packages/django/core/handlers/base.py", line 124, in _get_response
    response = wrapped_callback(request, *callback_args, **callback_kwargs)
  File "/home/mobilitysqr/.local/lib/python3.6/site-packages/django/views/decorators/csrf.py", line 54, in wrapped_view
    return view_func(*args, **kwargs)
  File "/home/mobilitysqr/.local/lib/python3.6/site-packages/django/views/generic/base.py", line 68, in view
    return self.dispatch(request, *args, **kwargs)
  File "/home/mobilitysqr/.local/lib/python3.6/site-packages/rest_framework/views.py", line 495, in dispatch
    response = self.handle_exception(exc)
  File "/home/mobilitysqr/.local/lib/python3.6/site-packages/rest_framework/views.py", line 455, in handle_exception
    self.raise_uncaught_exception(exc)
  File "/home/mobilitysqr/.local/lib/python3.6/site-packages/rest_framework/views.py", line 492, in dispatch
    response = handler(request, *args, **kwargs)
  File "/var/www/html/mobilitysqr_staging/mobility_apps/employee/views.py", line 1848, in post
    'email': self.employee_name(email=email[0]['email'])
  File "/home/mobilitysqr/.local/lib/python3.6/site-packages/django/db/models/query.py", line 303, in __getitem__
    return qs._result_cache[0]
IndexError: list index out of range
ERROR|15/Feb/2021 15:44:26|basehttp|22258|140375888492288|"POST /Otp_Generate/ HTTP/1.1" 500 17195
ERROR|15/Feb/2021 15:46:09|log|22258|140375888492288|Internal Server Error: /Otp_Generate/
Traceback (most recent call last):
  File "/home/mobilitysqr/.local/lib/python3.6/site-packages/django/core/handlers/exception.py", line 34, in inner
    response = get_response(request)
  File "/home/mobilitysqr/.local/lib/python3.6/site-packages/django/core/handlers/base.py", line 126, in _get_response
    response = self.process_exception_by_middleware(e, request)
  File "/home/mobilitysqr/.local/lib/python3.6/site-packages/django/core/handlers/base.py", line 124, in _get_response
    response = wrapped_callback(request, *callback_args, **callback_kwargs)
  File "/home/mobilitysqr/.local/lib/python3.6/site-packages/django/views/decorators/csrf.py", line 54, in wrapped_view
    return view_func(*args, **kwargs)
  File "/home/mobilitysqr/.local/lib/python3.6/site-packages/django/views/generic/base.py", line 68, in view
    return self.dispatch(request, *args, **kwargs)
  File "/home/mobilitysqr/.local/lib/python3.6/site-packages/rest_framework/views.py", line 495, in dispatch
    response = self.handle_exception(exc)
  File "/home/mobilitysqr/.local/lib/python3.6/site-packages/rest_framework/views.py", line 455, in handle_exception
    self.raise_uncaught_exception(exc)
  File "/home/mobilitysqr/.local/lib/python3.6/site-packages/rest_framework/views.py", line 492, in dispatch
    response = handler(request, *args, **kwargs)
  File "/var/www/html/mobilitysqr_staging/mobility_apps/employee/views.py", line 1848, in post
    'email': self.employee_name(email=email[0]['email'])
  File "/home/mobilitysqr/.local/lib/python3.6/site-packages/django/db/models/query.py", line 303, in __getitem__
    return qs._result_cache[0]
IndexError: list index out of range
ERROR|15/Feb/2021 15:46:09|basehttp|22258|140375888492288|"POST /Otp_Generate/ HTTP/1.1" 500 17217
ERROR|15/Feb/2021 15:47:02|log|22258|140375888492288|Internal Server Error: /Otp_Generate/
Traceback (most recent call last):
  File "/home/mobilitysqr/.local/lib/python3.6/site-packages/django/core/handlers/exception.py", line 34, in inner
    response = get_response(request)
  File "/home/mobilitysqr/.local/lib/python3.6/site-packages/django/core/handlers/base.py", line 126, in _get_response
    response = self.process_exception_by_middleware(e, request)
  File "/home/mobilitysqr/.local/lib/python3.6/site-packages/django/core/handlers/base.py", line 124, in _get_response
    response = wrapped_callback(request, *callback_args, **callback_kwargs)
  File "/home/mobilitysqr/.local/lib/python3.6/site-packages/django/views/decorators/csrf.py", line 54, in wrapped_view
    return view_func(*args, **kwargs)
  File "/home/mobilitysqr/.local/lib/python3.6/site-packages/django/views/generic/base.py", line 68, in view
    return self.dispatch(request, *args, **kwargs)
  File "/home/mobilitysqr/.local/lib/python3.6/site-packages/rest_framework/views.py", line 495, in dispatch
    response = self.handle_exception(exc)
  File "/home/mobilitysqr/.local/lib/python3.6/site-packages/rest_framework/views.py", line 455, in handle_exception
    self.raise_uncaught_exception(exc)
  File "/home/mobilitysqr/.local/lib/python3.6/site-packages/rest_framework/views.py", line 492, in dispatch
    response = handler(request, *args, **kwargs)
  File "/var/www/html/mobilitysqr_staging/mobility_apps/employee/views.py", line 1848, in post
    'email': self.employee_name(email=email[0]['email'])
  File "/home/mobilitysqr/.local/lib/python3.6/site-packages/django/db/models/query.py", line 303, in __getitem__
    return qs._result_cache[0]
IndexError: list index out of range
ERROR|15/Feb/2021 15:47:02|basehttp|22258|140375888492288|"POST /Otp_Generate/ HTTP/1.1" 500 17232
ERROR|15/Feb/2021 15:49:25|log|22258|140375888492288|Internal Server Error: /Otp_Generate/
Traceback (most recent call last):
  File "/home/mobilitysqr/.local/lib/python3.6/site-packages/django/core/handlers/exception.py", line 34, in inner
    response = get_response(request)
  File "/home/mobilitysqr/.local/lib/python3.6/site-packages/django/core/handlers/base.py", line 126, in _get_response
    response = self.process_exception_by_middleware(e, request)
  File "/home/mobilitysqr/.local/lib/python3.6/site-packages/django/core/handlers/base.py", line 124, in _get_response
    response = wrapped_callback(request, *callback_args, **callback_kwargs)
  File "/home/mobilitysqr/.local/lib/python3.6/site-packages/django/views/decorators/csrf.py", line 54, in wrapped_view
    return view_func(*args, **kwargs)
  File "/home/mobilitysqr/.local/lib/python3.6/site-packages/django/views/generic/base.py", line 68, in view
    return self.dispatch(request, *args, **kwargs)
  File "/home/mobilitysqr/.local/lib/python3.6/site-packages/rest_framework/views.py", line 495, in dispatch
    response = self.handle_exception(exc)
  File "/home/mobilitysqr/.local/lib/python3.6/site-packages/rest_framework/views.py", line 455, in handle_exception
    self.raise_uncaught_exception(exc)
  File "/home/mobilitysqr/.local/lib/python3.6/site-packages/rest_framework/views.py", line 492, in dispatch
    response = handler(request, *args, **kwargs)
  File "/var/www/html/mobilitysqr_staging/mobility_apps/employee/views.py", line 1848, in post
    'email': self.employee_name(email=email[0]['email'])
  File "/home/mobilitysqr/.local/lib/python3.6/site-packages/django/db/models/query.py", line 303, in __getitem__
    return qs._result_cache[0]
IndexError: list index out of range
ERROR|15/Feb/2021 15:49:25|basehttp|22258|140375888492288|"POST /Otp_Generate/ HTTP/1.1" 500 17232
ERROR|15/Feb/2021 15:52:44|log|22258|140375888492288|Internal Server Error: /Otp_Generate/
Traceback (most recent call last):
  File "/home/mobilitysqr/.local/lib/python3.6/site-packages/django/core/handlers/exception.py", line 34, in inner
    response = get_response(request)
  File "/home/mobilitysqr/.local/lib/python3.6/site-packages/django/core/handlers/base.py", line 126, in _get_response
    response = self.process_exception_by_middleware(e, request)
  File "/home/mobilitysqr/.local/lib/python3.6/site-packages/django/core/handlers/base.py", line 124, in _get_response
    response = wrapped_callback(request, *callback_args, **callback_kwargs)
  File "/home/mobilitysqr/.local/lib/python3.6/site-packages/django/views/decorators/csrf.py", line 54, in wrapped_view
    return view_func(*args, **kwargs)
  File "/home/mobilitysqr/.local/lib/python3.6/site-packages/django/views/generic/base.py", line 68, in view
    return self.dispatch(request, *args, **kwargs)
  File "/home/mobilitysqr/.local/lib/python3.6/site-packages/rest_framework/views.py", line 495, in dispatch
    response = self.handle_exception(exc)
  File "/home/mobilitysqr/.local/lib/python3.6/site-packages/rest_framework/views.py", line 455, in handle_exception
    self.raise_uncaught_exception(exc)
  File "/home/mobilitysqr/.local/lib/python3.6/site-packages/rest_framework/views.py", line 492, in dispatch
    response = handler(request, *args, **kwargs)
  File "/var/www/html/mobilitysqr_staging/mobility_apps/employee/views.py", line 1848, in post
    'email': self.employee_name(email=email[0]['email'])
  File "/home/mobilitysqr/.local/lib/python3.6/site-packages/django/db/models/query.py", line 303, in __getitem__
    return qs._result_cache[0]
IndexError: list index out of range
ERROR|15/Feb/2021 15:52:44|basehttp|22258|140375888492288|"POST /Otp_Generate/ HTTP/1.1" 500 17232
ERROR|15/Feb/2021 15:57:29|log|22258|140375858865920|Internal Server Error: /Otp_Generate/
Traceback (most recent call last):
  File "/home/mobilitysqr/.local/lib/python3.6/site-packages/django/core/handlers/exception.py", line 34, in inner
    response = get_response(request)
  File "/home/mobilitysqr/.local/lib/python3.6/site-packages/django/core/handlers/base.py", line 126, in _get_response
    response = self.process_exception_by_middleware(e, request)
  File "/home/mobilitysqr/.local/lib/python3.6/site-packages/django/core/handlers/base.py", line 124, in _get_response
    response = wrapped_callback(request, *callback_args, **callback_kwargs)
  File "/home/mobilitysqr/.local/lib/python3.6/site-packages/django/views/decorators/csrf.py", line 54, in wrapped_view
    return view_func(*args, **kwargs)
  File "/home/mobilitysqr/.local/lib/python3.6/site-packages/django/views/generic/base.py", line 68, in view
    return self.dispatch(request, *args, **kwargs)
  File "/home/mobilitysqr/.local/lib/python3.6/site-packages/rest_framework/views.py", line 495, in dispatch
    response = self.handle_exception(exc)
  File "/home/mobilitysqr/.local/lib/python3.6/site-packages/rest_framework/views.py", line 455, in handle_exception
    self.raise_uncaught_exception(exc)
  File "/home/mobilitysqr/.local/lib/python3.6/site-packages/rest_framework/views.py", line 492, in dispatch
    response = handler(request, *args, **kwargs)
  File "/var/www/html/mobilitysqr_staging/mobility_apps/employee/views.py", line 1848, in post
    'email': self.employee_name(email=email[0]['email'])
  File "/home/mobilitysqr/.local/lib/python3.6/site-packages/django/db/models/query.py", line 303, in __getitem__
    return qs._result_cache[0]
IndexError: list index out of range
ERROR|15/Feb/2021 15:57:29|basehttp|22258|140375858865920|"POST /Otp_Generate/ HTTP/1.1" 500 17281
ERROR|15/Feb/2021 15:57:40|log|22258|140375858865920|Internal Server Error: /Otp_Generate/
Traceback (most recent call last):
  File "/home/mobilitysqr/.local/lib/python3.6/site-packages/django/core/handlers/exception.py", line 34, in inner
    response = get_response(request)
  File "/home/mobilitysqr/.local/lib/python3.6/site-packages/django/core/handlers/base.py", line 126, in _get_response
    response = self.process_exception_by_middleware(e, request)
  File "/home/mobilitysqr/.local/lib/python3.6/site-packages/django/core/handlers/base.py", line 124, in _get_response
    response = wrapped_callback(request, *callback_args, **callback_kwargs)
  File "/home/mobilitysqr/.local/lib/python3.6/site-packages/django/views/decorators/csrf.py", line 54, in wrapped_view
    return view_func(*args, **kwargs)
  File "/home/mobilitysqr/.local/lib/python3.6/site-packages/django/views/generic/base.py", line 68, in view
    return self.dispatch(request, *args, **kwargs)
  File "/home/mobilitysqr/.local/lib/python3.6/site-packages/rest_framework/views.py", line 495, in dispatch
    response = self.handle_exception(exc)
  File "/home/mobilitysqr/.local/lib/python3.6/site-packages/rest_framework/views.py", line 455, in handle_exception
    self.raise_uncaught_exception(exc)
  File "/home/mobilitysqr/.local/lib/python3.6/site-packages/rest_framework/views.py", line 492, in dispatch
    response = handler(request, *args, **kwargs)
  File "/var/www/html/mobilitysqr_staging/mobility_apps/employee/views.py", line 1848, in post
    'email': self.employee_name(email=email[0]['email'])
  File "/home/mobilitysqr/.local/lib/python3.6/site-packages/django/db/models/query.py", line 303, in __getitem__
    return qs._result_cache[0]
IndexError: list index out of range
ERROR|15/Feb/2021 15:57:40|basehttp|22258|140375858865920|"POST /Otp_Generate/ HTTP/1.1" 500 17281
ERROR|15/Feb/2021 15:59:44|log|22258|140375858865920|Internal Server Error: /Otp_Generate/
Traceback (most recent call last):
  File "/home/mobilitysqr/.local/lib/python3.6/site-packages/django/core/handlers/exception.py", line 34, in inner
    response = get_response(request)
  File "/home/mobilitysqr/.local/lib/python3.6/site-packages/django/core/handlers/base.py", line 126, in _get_response
    response = self.process_exception_by_middleware(e, request)
  File "/home/mobilitysqr/.local/lib/python3.6/site-packages/django/core/handlers/base.py", line 124, in _get_response
    response = wrapped_callback(request, *callback_args, **callback_kwargs)
  File "/home/mobilitysqr/.local/lib/python3.6/site-packages/django/views/decorators/csrf.py", line 54, in wrapped_view
    return view_func(*args, **kwargs)
  File "/home/mobilitysqr/.local/lib/python3.6/site-packages/django/views/generic/base.py", line 68, in view
    return self.dispatch(request, *args, **kwargs)
  File "/home/mobilitysqr/.local/lib/python3.6/site-packages/rest_framework/views.py", line 495, in dispatch
    response = self.handle_exception(exc)
  File "/home/mobilitysqr/.local/lib/python3.6/site-packages/rest_framework/views.py", line 455, in handle_exception
    self.raise_uncaught_exception(exc)
  File "/home/mobilitysqr/.local/lib/python3.6/site-packages/rest_framework/views.py", line 492, in dispatch
    response = handler(request, *args, **kwargs)
  File "/var/www/html/mobilitysqr_staging/mobility_apps/employee/views.py", line 1848, in post
    'email': self.employee_name(email=email[0]['email'])
  File "/home/mobilitysqr/.local/lib/python3.6/site-packages/django/db/models/query.py", line 303, in __getitem__
    return qs._result_cache[0]
IndexError: list index out of range
ERROR|15/Feb/2021 15:59:44|basehttp|22258|140375858865920|"POST /Otp_Generate/ HTTP/1.1" 500 17281
ERROR|15/Feb/2021 15:59:57|log|22258|140375858865920|Internal Server Error: /Otp_Generate/
Traceback (most recent call last):
  File "/home/mobilitysqr/.local/lib/python3.6/site-packages/django/core/handlers/exception.py", line 34, in inner
    response = get_response(request)
  File "/home/mobilitysqr/.local/lib/python3.6/site-packages/django/core/handlers/base.py", line 126, in _get_response
    response = self.process_exception_by_middleware(e, request)
  File "/home/mobilitysqr/.local/lib/python3.6/site-packages/django/core/handlers/base.py", line 124, in _get_response
    response = wrapped_callback(request, *callback_args, **callback_kwargs)
  File "/home/mobilitysqr/.local/lib/python3.6/site-packages/django/views/decorators/csrf.py", line 54, in wrapped_view
    return view_func(*args, **kwargs)
  File "/home/mobilitysqr/.local/lib/python3.6/site-packages/django/views/generic/base.py", line 68, in view
    return self.dispatch(request, *args, **kwargs)
  File "/home/mobilitysqr/.local/lib/python3.6/site-packages/rest_framework/views.py", line 495, in dispatch
    response = self.handle_exception(exc)
  File "/home/mobilitysqr/.local/lib/python3.6/site-packages/rest_framework/views.py", line 455, in handle_exception
    self.raise_uncaught_exception(exc)
  File "/home/mobilitysqr/.local/lib/python3.6/site-packages/rest_framework/views.py", line 492, in dispatch
    response = handler(request, *args, **kwargs)
  File "/var/www/html/mobilitysqr_staging/mobility_apps/employee/views.py", line 1848, in post
    'email': self.employee_name(email=email[0]['email'])
  File "/home/mobilitysqr/.local/lib/python3.6/site-packages/django/db/models/query.py", line 303, in __getitem__
    return qs._result_cache[0]
IndexError: list index out of range
ERROR|15/Feb/2021 15:59:57|basehttp|22258|140375858865920|"POST /Otp_Generate/ HTTP/1.1" 500 17281
ERROR|15/Feb/2021 16:01:43|log|22258|140375858865920|Internal Server Error: /Otp_Generate/
Traceback (most recent call last):
  File "/home/mobilitysqr/.local/lib/python3.6/site-packages/django/core/handlers/exception.py", line 34, in inner
    response = get_response(request)
  File "/home/mobilitysqr/.local/lib/python3.6/site-packages/django/core/handlers/base.py", line 126, in _get_response
    response = self.process_exception_by_middleware(e, request)
  File "/home/mobilitysqr/.local/lib/python3.6/site-packages/django/core/handlers/base.py", line 124, in _get_response
    response = wrapped_callback(request, *callback_args, **callback_kwargs)
  File "/home/mobilitysqr/.local/lib/python3.6/site-packages/django/views/decorators/csrf.py", line 54, in wrapped_view
    return view_func(*args, **kwargs)
  File "/home/mobilitysqr/.local/lib/python3.6/site-packages/django/views/generic/base.py", line 68, in view
    return self.dispatch(request, *args, **kwargs)
  File "/home/mobilitysqr/.local/lib/python3.6/site-packages/rest_framework/views.py", line 495, in dispatch
    response = self.handle_exception(exc)
  File "/home/mobilitysqr/.local/lib/python3.6/site-packages/rest_framework/views.py", line 455, in handle_exception
    self.raise_uncaught_exception(exc)
  File "/home/mobilitysqr/.local/lib/python3.6/site-packages/rest_framework/views.py", line 492, in dispatch
    response = handler(request, *args, **kwargs)
  File "/var/www/html/mobilitysqr_staging/mobility_apps/employee/views.py", line 1848, in post
    'email': self.employee_name(email=email[0]['email'])
  File "/home/mobilitysqr/.local/lib/python3.6/site-packages/django/db/models/query.py", line 303, in __getitem__
    return qs._result_cache[0]
IndexError: list index out of range
ERROR|15/Feb/2021 16:01:43|basehttp|22258|140375858865920|"POST /Otp_Generate/ HTTP/1.1" 500 17236
ERROR|15/Feb/2021 16:17:19|exception|22258|140375858865920|Invalid HTTP_HOST header: ''. The domain name provided is not valid according to RFC 1034/1035.
ERROR|15/Feb/2021 16:36:46|exception|22258|140375850473216|Invalid HTTP_HOST header: ''. The domain name provided is not valid according to RFC 1034/1035.
ERROR|15/Feb/2021 17:31:52|exception|22258|140375553464064|Invalid HTTP_HOST header: ''. The domain name provided is not valid according to RFC 1034/1035.
ERROR|15/Feb/2021 18:02:30|log|22258|140375561856768|Internal Server Error: /Otp_Generate/
Traceback (most recent call last):
  File "/home/mobilitysqr/.local/lib/python3.6/site-packages/django/core/handlers/exception.py", line 34, in inner
    response = get_response(request)
  File "/home/mobilitysqr/.local/lib/python3.6/site-packages/django/core/handlers/base.py", line 126, in _get_response
    response = self.process_exception_by_middleware(e, request)
  File "/home/mobilitysqr/.local/lib/python3.6/site-packages/django/core/handlers/base.py", line 124, in _get_response
    response = wrapped_callback(request, *callback_args, **callback_kwargs)
  File "/home/mobilitysqr/.local/lib/python3.6/site-packages/django/views/decorators/csrf.py", line 54, in wrapped_view
    return view_func(*args, **kwargs)
  File "/home/mobilitysqr/.local/lib/python3.6/site-packages/django/views/generic/base.py", line 68, in view
    return self.dispatch(request, *args, **kwargs)
  File "/home/mobilitysqr/.local/lib/python3.6/site-packages/rest_framework/views.py", line 495, in dispatch
    response = self.handle_exception(exc)
  File "/home/mobilitysqr/.local/lib/python3.6/site-packages/rest_framework/views.py", line 455, in handle_exception
    self.raise_uncaught_exception(exc)
  File "/home/mobilitysqr/.local/lib/python3.6/site-packages/rest_framework/views.py", line 492, in dispatch
    response = handler(request, *args, **kwargs)
  File "/var/www/html/mobilitysqr_staging/mobility_apps/employee/views.py", line 1848, in post
    'email': self.employee_name(email=email[0]['email'])
  File "/home/mobilitysqr/.local/lib/python3.6/site-packages/django/db/models/query.py", line 303, in __getitem__
    return qs._result_cache[0]
IndexError: list index out of range
ERROR|15/Feb/2021 18:02:30|basehttp|22258|140375561856768|"POST /Otp_Generate/ HTTP/1.1" 500 17232
ERROR|15/Feb/2021 18:17:09|exception|22258|140375858865920|Invalid HTTP_HOST header: ''. The domain name provided is not valid according to RFC 1034/1035.
ERROR|15/Feb/2021 19:20:44|log|22258|140375570249472|Internal Server Error: /Otp_Generate/
Traceback (most recent call last):
  File "/home/mobilitysqr/.local/lib/python3.6/site-packages/django/core/handlers/exception.py", line 34, in inner
    response = get_response(request)
  File "/home/mobilitysqr/.local/lib/python3.6/site-packages/django/core/handlers/base.py", line 126, in _get_response
    response = self.process_exception_by_middleware(e, request)
  File "/home/mobilitysqr/.local/lib/python3.6/site-packages/django/core/handlers/base.py", line 124, in _get_response
    response = wrapped_callback(request, *callback_args, **callback_kwargs)
  File "/home/mobilitysqr/.local/lib/python3.6/site-packages/django/views/decorators/csrf.py", line 54, in wrapped_view
    return view_func(*args, **kwargs)
  File "/home/mobilitysqr/.local/lib/python3.6/site-packages/django/views/generic/base.py", line 68, in view
    return self.dispatch(request, *args, **kwargs)
  File "/home/mobilitysqr/.local/lib/python3.6/site-packages/rest_framework/views.py", line 495, in dispatch
    response = self.handle_exception(exc)
  File "/home/mobilitysqr/.local/lib/python3.6/site-packages/rest_framework/views.py", line 455, in handle_exception
    self.raise_uncaught_exception(exc)
  File "/home/mobilitysqr/.local/lib/python3.6/site-packages/rest_framework/views.py", line 492, in dispatch
    response = handler(request, *args, **kwargs)
  File "/var/www/html/mobilitysqr_staging/mobility_apps/employee/views.py", line 1848, in post
    'email': self.employee_name(email=email[0]['email'])
  File "/home/mobilitysqr/.local/lib/python3.6/site-packages/django/db/models/query.py", line 303, in __getitem__
    return qs._result_cache[0]
IndexError: list index out of range
ERROR|15/Feb/2021 19:20:44|basehttp|22258|140375570249472|"POST /Otp_Generate/ HTTP/1.1" 500 17232
ERROR|15/Feb/2021 20:04:06|exception|22258|140375570249472|Invalid HTTP_HOST header: ''. The domain name provided is not valid according to RFC 1034/1035.
ERROR|15/Feb/2021 21:26:06|exception|22258|140375570249472|Invalid HTTP_HOST header: ''. The domain name provided is not valid according to RFC 1034/1035.
ERROR|15/Feb/2021 23:10:33|exception|22258|140375570249472|Invalid HTTP_HOST header: ''. The domain name provided is not valid according to RFC 1034/1035.
ERROR|15/Feb/2021 23:23:44|exception|22258|140375570249472|Invalid HTTP_HOST header: ''. The domain name provided is not valid according to RFC 1034/1035.
ERROR|16/Feb/2021 01:42:28|basehttp|22258|140375570249472|You're accessing the development server over HTTPS, but it only supports HTTP.

ERROR|16/Feb/2021 01:56:56|exception|22258|140375570249472|Invalid HTTP_HOST header: ''. The domain name provided is not valid according to RFC 1034/1035.
ERROR|16/Feb/2021 02:47:11|exception|22258|140375570249472|Invalid HTTP_HOST header: ''. The domain name provided is not valid according to RFC 1034/1035.
ERROR|16/Feb/2021 02:50:16|exception|22258|140375570249472|Invalid HTTP_HOST header: ''. The domain name provided is not valid according to RFC 1034/1035.
ERROR|16/Feb/2021 04:40:50|exception|22258|140375858865920|Invalid HTTP_HOST header: ''. The domain name provided is not valid according to RFC 1034/1035.
ERROR|16/Feb/2021 04:53:01|exception|22258|140375858865920|Invalid HTTP_HOST header: ''. The domain name provided is not valid according to RFC 1034/1035.
ERROR|16/Feb/2021 05:10:14|exception|22258|140375858865920|Invalid HTTP_HOST header: ''. The domain name provided is not valid according to RFC 1034/1035.
ERROR|16/Feb/2021 05:22:10|exception|22258|140375858865920|Invalid HTTP_HOST header: ''. The domain name provided is not valid according to RFC 1034/1035.
ERROR|16/Feb/2021 05:22:29|exception|22258|140375858865920|Invalid HTTP_HOST header: ''. The domain name provided is not valid according to RFC 1034/1035.
ERROR|16/Feb/2021 05:41:20|basehttp|22258|140375858865920|You're accessing the development server over HTTPS, but it only supports HTTP.

ERROR|16/Feb/2021 06:17:37|exception|22258|140375858865920|Invalid HTTP_HOST header: ''. The domain name provided is not valid according to RFC 1034/1035.
ERROR|16/Feb/2021 06:20:02|exception|22258|140375858865920|Invalid HTTP_HOST header: ''. The domain name provided is not valid according to RFC 1034/1035.
ERROR|16/Feb/2021 07:14:41|exception|22258|140375858865920|Invalid HTTP_HOST header: ''. The domain name provided is not valid according to RFC 1034/1035.
ERROR|16/Feb/2021 08:10:17|exception|22258|140375858865920|Invalid HTTP_HOST header: ''. The domain name provided is not valid according to RFC 1034/1035.
ERROR|16/Feb/2021 08:33:06|exception|22258|140375858865920|Invalid HTTP_HOST header: ''. The domain name provided is not valid according to RFC 1034/1035.
ERROR|16/Feb/2021 08:47:51|exception|22258|140375858865920|Invalid HTTP_HOST header: ''. The domain name provided is not valid according to RFC 1034/1035.
ERROR|16/Feb/2021 09:28:05|exception|22258|140375858865920|Invalid HTTP_HOST header: ''. The domain name provided is not valid according to RFC 1034/1035.
ERROR|16/Feb/2021 11:00:39|exception|22258|140375561856768|Invalid HTTP_HOST header: ''. The domain name provided is not valid according to RFC 1034/1035.
ERROR|16/Feb/2021 11:07:04|exception|22258|140375561856768|Invalid HTTP_HOST header: ''. The domain name provided is not valid according to RFC 1034/1035.
ERROR|16/Feb/2021 15:53:25|exception|22258|140375561856768|Invalid HTTP_HOST header: ''. The domain name provided is not valid according to RFC 1034/1035.
ERROR|16/Feb/2021 15:57:39|exception|22258|140375561856768|Invalid HTTP_HOST header: ''. The domain name provided is not valid according to RFC 1034/1035.
ERROR|16/Feb/2021 17:31:13|exception|22258|140375850473216|Invalid HTTP_HOST header: ''. The domain name provided is not valid according to RFC 1034/1035.
ERROR|16/Feb/2021 17:39:06|exception|22258|140375850473216|Invalid HTTP_HOST header: ''. The domain name provided is not valid according to RFC 1034/1035.
ERROR|16/Feb/2021 18:30:04|log|22258|140375553464064|Internal Server Error: /getassignmentletter/
Traceback (most recent call last):
  File "/home/mobilitysqr/.local/lib/python3.6/site-packages/django/core/handlers/exception.py", line 34, in inner
    response = get_response(request)
  File "/home/mobilitysqr/.local/lib/python3.6/site-packages/django/core/handlers/base.py", line 126, in _get_response
    response = self.process_exception_by_middleware(e, request)
  File "/home/mobilitysqr/.local/lib/python3.6/site-packages/django/core/handlers/base.py", line 124, in _get_response
    response = wrapped_callback(request, *callback_args, **callback_kwargs)
  File "/home/mobilitysqr/.local/lib/python3.6/site-packages/django/views/decorators/csrf.py", line 54, in wrapped_view
    return view_func(*args, **kwargs)
  File "/home/mobilitysqr/.local/lib/python3.6/site-packages/django/views/generic/base.py", line 68, in view
    return self.dispatch(request, *args, **kwargs)
  File "/home/mobilitysqr/.local/lib/python3.6/site-packages/rest_framework/views.py", line 495, in dispatch
    response = self.handle_exception(exc)
  File "/home/mobilitysqr/.local/lib/python3.6/site-packages/rest_framework/views.py", line 455, in handle_exception
    self.raise_uncaught_exception(exc)
  File "/home/mobilitysqr/.local/lib/python3.6/site-packages/rest_framework/views.py", line 492, in dispatch
    response = handler(request, *args, **kwargs)
  File "/var/www/html/mobilitysqr_staging/mobility_apps/letter/views.py", line 316, in get
    template = get_template(lettername)
  File "/home/mobilitysqr/.local/lib/python3.6/site-packages/django/template/loader.py", line 19, in get_template
    raise TemplateDoesNotExist(template_name, chain=chain)
django.template.exceptions.TemplateDoesNotExist: Short_Term_Assignment_ORG150866_x2G6NWV.html
ERROR|16/Feb/2021 18:30:04|basehttp|22258|140375553464064|"GET /getassignmentletter/?travel_req_id=TR439513 HTTP/1.1" 500 18681
ERROR|16/Feb/2021 18:30:33|log|22258|140375858865920|Internal Server Error: /getassignmentletter/
Traceback (most recent call last):
  File "/home/mobilitysqr/.local/lib/python3.6/site-packages/django/core/handlers/exception.py", line 34, in inner
    response = get_response(request)
  File "/home/mobilitysqr/.local/lib/python3.6/site-packages/django/core/handlers/base.py", line 126, in _get_response
    response = self.process_exception_by_middleware(e, request)
  File "/home/mobilitysqr/.local/lib/python3.6/site-packages/django/core/handlers/base.py", line 124, in _get_response
    response = wrapped_callback(request, *callback_args, **callback_kwargs)
  File "/home/mobilitysqr/.local/lib/python3.6/site-packages/django/views/decorators/csrf.py", line 54, in wrapped_view
    return view_func(*args, **kwargs)
  File "/home/mobilitysqr/.local/lib/python3.6/site-packages/django/views/generic/base.py", line 68, in view
    return self.dispatch(request, *args, **kwargs)
  File "/home/mobilitysqr/.local/lib/python3.6/site-packages/rest_framework/views.py", line 495, in dispatch
    response = self.handle_exception(exc)
  File "/home/mobilitysqr/.local/lib/python3.6/site-packages/rest_framework/views.py", line 455, in handle_exception
    self.raise_uncaught_exception(exc)
  File "/home/mobilitysqr/.local/lib/python3.6/site-packages/rest_framework/views.py", line 492, in dispatch
    response = handler(request, *args, **kwargs)
  File "/var/www/html/mobilitysqr_staging/mobility_apps/letter/views.py", line 316, in get
    template = get_template(lettername)
  File "/home/mobilitysqr/.local/lib/python3.6/site-packages/django/template/loader.py", line 19, in get_template
    raise TemplateDoesNotExist(template_name, chain=chain)
django.template.exceptions.TemplateDoesNotExist: Short_Term_Assignment_ORG150866_x2G6NWV.html
ERROR|16/Feb/2021 18:30:33|basehttp|22258|140375858865920|"GET /getassignmentletter/?travel_req_id=TR108929 HTTP/1.1" 500 18681
ERROR|16/Feb/2021 18:30:40|log|22258|140375553464064|Internal Server Error: /getassignmentletter/
Traceback (most recent call last):
  File "/home/mobilitysqr/.local/lib/python3.6/site-packages/django/core/handlers/exception.py", line 34, in inner
    response = get_response(request)
  File "/home/mobilitysqr/.local/lib/python3.6/site-packages/django/core/handlers/base.py", line 126, in _get_response
    response = self.process_exception_by_middleware(e, request)
  File "/home/mobilitysqr/.local/lib/python3.6/site-packages/django/core/handlers/base.py", line 124, in _get_response
    response = wrapped_callback(request, *callback_args, **callback_kwargs)
  File "/home/mobilitysqr/.local/lib/python3.6/site-packages/django/views/decorators/csrf.py", line 54, in wrapped_view
    return view_func(*args, **kwargs)
  File "/home/mobilitysqr/.local/lib/python3.6/site-packages/django/views/generic/base.py", line 68, in view
    return self.dispatch(request, *args, **kwargs)
  File "/home/mobilitysqr/.local/lib/python3.6/site-packages/rest_framework/views.py", line 495, in dispatch
    response = self.handle_exception(exc)
  File "/home/mobilitysqr/.local/lib/python3.6/site-packages/rest_framework/views.py", line 455, in handle_exception
    self.raise_uncaught_exception(exc)
  File "/home/mobilitysqr/.local/lib/python3.6/site-packages/rest_framework/views.py", line 492, in dispatch
    response = handler(request, *args, **kwargs)
  File "/var/www/html/mobilitysqr_staging/mobility_apps/letter/views.py", line 316, in get
    template = get_template(lettername)
  File "/home/mobilitysqr/.local/lib/python3.6/site-packages/django/template/loader.py", line 19, in get_template
    raise TemplateDoesNotExist(template_name, chain=chain)
django.template.exceptions.TemplateDoesNotExist: Short_Term_Assignment_ORG150866_x2G6NWV.html
ERROR|16/Feb/2021 18:30:40|basehttp|22258|140375553464064|"GET /getassignmentletter/?travel_req_id=TR216783 HTTP/1.1" 500 18681
ERROR|16/Feb/2021 18:30:41|log|22258|140375553464064|Internal Server Error: /getassignmentletter/
Traceback (most recent call last):
  File "/home/mobilitysqr/.local/lib/python3.6/site-packages/django/core/handlers/exception.py", line 34, in inner
    response = get_response(request)
  File "/home/mobilitysqr/.local/lib/python3.6/site-packages/django/core/handlers/base.py", line 126, in _get_response
    response = self.process_exception_by_middleware(e, request)
  File "/home/mobilitysqr/.local/lib/python3.6/site-packages/django/core/handlers/base.py", line 124, in _get_response
    response = wrapped_callback(request, *callback_args, **callback_kwargs)
  File "/home/mobilitysqr/.local/lib/python3.6/site-packages/django/views/decorators/csrf.py", line 54, in wrapped_view
    return view_func(*args, **kwargs)
  File "/home/mobilitysqr/.local/lib/python3.6/site-packages/django/views/generic/base.py", line 68, in view
    return self.dispatch(request, *args, **kwargs)
  File "/home/mobilitysqr/.local/lib/python3.6/site-packages/rest_framework/views.py", line 495, in dispatch
    response = self.handle_exception(exc)
  File "/home/mobilitysqr/.local/lib/python3.6/site-packages/rest_framework/views.py", line 455, in handle_exception
    self.raise_uncaught_exception(exc)
  File "/home/mobilitysqr/.local/lib/python3.6/site-packages/rest_framework/views.py", line 492, in dispatch
    response = handler(request, *args, **kwargs)
  File "/var/www/html/mobilitysqr_staging/mobility_apps/letter/views.py", line 316, in get
    template = get_template(lettername)
  File "/home/mobilitysqr/.local/lib/python3.6/site-packages/django/template/loader.py", line 19, in get_template
    raise TemplateDoesNotExist(template_name, chain=chain)
django.template.exceptions.TemplateDoesNotExist: Short_Term_Assignment_ORG150866_x2G6NWV.html
ERROR|16/Feb/2021 18:30:41|basehttp|22258|140375553464064|"GET /getassignmentletter/?travel_req_id=TR216783 HTTP/1.1" 500 18681
ERROR|16/Feb/2021 19:22:17|exception|22258|140375858865920|Invalid HTTP_HOST header: ''. The domain name provided is not valid according to RFC 1034/1035.
ERROR|16/Feb/2021 20:45:30|basehttp|22258|140375858865920|You're accessing the development server over HTTPS, but it only supports HTTP.

ERROR|16/Feb/2021 22:26:45|exception|22258|140375858865920|Invalid HTTP_HOST header: ''. The domain name provided is not valid according to RFC 1034/1035.
ERROR|17/Feb/2021 00:54:08|exception|22258|140375858865920|Invalid HTTP_HOST header: ''. The domain name provided is not valid according to RFC 1034/1035.
ERROR|17/Feb/2021 01:12:56|exception|22258|140375858865920|Invalid HTTP_HOST header: ''. The domain name provided is not valid according to RFC 1034/1035.
ERROR|17/Feb/2021 01:42:15|exception|22258|140375858865920|Invalid HTTP_HOST header: ''. The domain name provided is not valid according to RFC 1034/1035.
ERROR|17/Feb/2021 02:28:13|exception|22258|140375858865920|Invalid HTTP_HOST header: ''. The domain name provided is not valid according to RFC 1034/1035.
ERROR|17/Feb/2021 02:28:45|exception|22258|140375858865920|Invalid HTTP_HOST header: ''. The domain name provided is not valid according to RFC 1034/1035.
ERROR|17/Feb/2021 02:35:37|exception|22258|140375858865920|Invalid HTTP_HOST header: ''. The domain name provided is not valid according to RFC 1034/1035.
ERROR|17/Feb/2021 02:55:51|exception|22258|140375858865920|Invalid HTTP_HOST header: ''. The domain name provided is not valid according to RFC 1034/1035.
ERROR|17/Feb/2021 02:59:04|exception|22258|140375858865920|Invalid HTTP_HOST header: ''. The domain name provided is not valid according to RFC 1034/1035.
ERROR|17/Feb/2021 03:09:26|basehttp|22258|140375858865920|You're accessing the development server over HTTPS, but it only supports HTTP.

ERROR|17/Feb/2021 03:40:09|exception|22258|140375858865920|Invalid HTTP_HOST header: ''. The domain name provided is not valid according to RFC 1034/1035.
ERROR|17/Feb/2021 04:00:22|exception|22258|140375858865920|Invalid HTTP_HOST header: ''. The domain name provided is not valid according to RFC 1034/1035.
ERROR|17/Feb/2021 04:39:56|exception|22258|140375858865920|Invalid HTTP_HOST header: ''. The domain name provided is not valid according to RFC 1034/1035.
ERROR|17/Feb/2021 04:46:33|exception|22258|140375858865920|Invalid HTTP_HOST header: ''. The domain name provided is not valid according to RFC 1034/1035.
ERROR|17/Feb/2021 04:46:33|basehttp|22258|140375858865920|"GET /script HTTP/1.1" 500 59
ERROR|17/Feb/2021 05:01:44|exception|22258|140375858865920|Invalid HTTP_HOST header: ''. The domain name provided is not valid according to RFC 1034/1035.
ERROR|17/Feb/2021 05:02:03|exception|22258|140375858865920|Invalid HTTP_HOST header: ''. The domain name provided is not valid according to RFC 1034/1035.
ERROR|17/Feb/2021 05:32:37|exception|22258|140375858865920|Invalid HTTP_HOST header: ''. The domain name provided is not valid according to RFC 1034/1035.
ERROR|17/Feb/2021 05:33:12|exception|22258|140375858865920|Invalid HTTP_HOST header: ''. The domain name provided is not valid according to RFC 1034/1035.
ERROR|17/Feb/2021 05:52:43|exception|22258|140375858865920|Invalid HTTP_HOST header: ''. The domain name provided is not valid according to RFC 1034/1035.
ERROR|17/Feb/2021 05:52:43|basehttp|22258|140375858865920|"GET /script HTTP/1.1" 500 59
ERROR|17/Feb/2021 06:03:11|exception|22258|140375858865920|Invalid HTTP_HOST header: ''. The domain name provided is not valid according to RFC 1034/1035.
ERROR|17/Feb/2021 06:08:50|exception|22258|140375858865920|Invalid HTTP_HOST header: ''. The domain name provided is not valid according to RFC 1034/1035.
ERROR|17/Feb/2021 06:29:29|exception|22258|140375858865920|Invalid HTTP_HOST header: ''. The domain name provided is not valid according to RFC 1034/1035.
ERROR|17/Feb/2021 06:31:39|exception|22258|140375858865920|Invalid HTTP_HOST header: ''. The domain name provided is not valid according to RFC 1034/1035.
ERROR|17/Feb/2021 06:31:39|basehttp|22258|140375858865920|"GET /script HTTP/1.1" 500 59
ERROR|17/Feb/2021 06:35:48|basehttp|22258|140375858865920|You're accessing the development server over HTTPS, but it only supports HTTP.

ERROR|17/Feb/2021 07:50:16|exception|22258|140375858865920|Invalid HTTP_HOST header: ''. The domain name provided is not valid according to RFC 1034/1035.
ERROR|17/Feb/2021 07:54:54|exception|22258|140375858865920|Invalid HTTP_HOST header: ''. The domain name provided is not valid according to RFC 1034/1035.
ERROR|17/Feb/2021 08:15:12|exception|22258|140375858865920|Invalid HTTP_HOST header: ''. The domain name provided is not valid according to RFC 1034/1035.
ERROR|17/Feb/2021 08:15:12|basehttp|22258|140375858865920|"GET /manager/html HTTP/1.1" 500 59
ERROR|17/Feb/2021 08:29:22|exception|22258|140375858865920|Invalid HTTP_HOST header: ''. The domain name provided is not valid according to RFC 1034/1035.
ERROR|17/Feb/2021 08:29:22|basehttp|22258|140375858865920|"GET /script HTTP/1.1" 500 59
ERROR|17/Feb/2021 08:32:25|basehttp|22258|140375858865920|You're accessing the development server over HTTPS, but it only supports HTTP.

ERROR|17/Feb/2021 08:33:28|exception|22258|140375858865920|Invalid HTTP_HOST header: ''. The domain name provided is not valid according to RFC 1034/1035.
ERROR|17/Feb/2021 11:30:17|exception|22258|140375850473216|Invalid HTTP_HOST header: ''. The domain name provided is not valid according to RFC 1034/1035.
ERROR|17/Feb/2021 12:09:19|exception|22258|140375858865920|Invalid HTTP_HOST header: ''. The domain name provided is not valid according to RFC 1034/1035.
ERROR|17/Feb/2021 13:22:38|exception|22258|140375570249472|Invalid HTTP_HOST header: ''. The domain name provided is not valid according to RFC 1034/1035.
ERROR|17/Feb/2021 14:27:53|exception|22258|140375561856768|Invalid HTTP_HOST header: ''. The domain name provided is not valid according to RFC 1034/1035.
ERROR|17/Feb/2021 14:46:21|exception|22258|140375561856768|Invalid HTTP_HOST header: ''. The domain name provided is not valid according to RFC 1034/1035.
ERROR|17/Feb/2021 14:46:21|basehttp|22258|140375561856768|"GET /manager/html HTTP/1.1" 500 59
ERROR|17/Feb/2021 14:52:58|exception|22258|140375561856768|Invalid HTTP_HOST header: ''. The domain name provided is not valid according to RFC 1034/1035.
ERROR|17/Feb/2021 16:09:32|exception|22258|140375570249472|Invalid HTTP_HOST header: ''. The domain name provided is not valid according to RFC 1034/1035.
ERROR|17/Feb/2021 16:24:44|basehttp|22258|140375570249472|"GET /media/Koala_74ufFrT.jpg HTTP/1.1" 500 59
ERROR|17/Feb/2021 16:37:32|exception|22258|140375570249472|Invalid HTTP_HOST header: ''. The domain name provided is not valid according to RFC 1034/1035.
ERROR|17/Feb/2021 16:37:32|basehttp|22258|140375570249472|"GET /manager/html HTTP/1.1" 500 59
ERROR|17/Feb/2021 17:32:58|basehttp|22258|140375570249472|You're accessing the development server over HTTPS, but it only supports HTTP.

ERROR|17/Feb/2021 17:53:37|exception|22258|140375553464064|Invalid HTTP_HOST header: ''. The domain name provided is not valid according to RFC 1034/1035.
ERROR|17/Feb/2021 18:02:42|exception|22258|140375553464064|Invalid HTTP_HOST header: ''. The domain name provided is not valid according to RFC 1034/1035.
ERROR|17/Feb/2021 19:17:49|exception|22258|140375850473216|Invalid HTTP_HOST header: ''. The domain name provided is not valid according to RFC 1034/1035.
ERROR|17/Feb/2021 19:17:49|basehttp|22258|140375850473216|"GET /manager/html HTTP/1.1" 500 59
ERROR|17/Feb/2021 19:31:29|basehttp|22258|140375850473216|You're accessing the development server over HTTPS, but it only supports HTTP.

ERROR|17/Feb/2021 20:48:41|exception|22258|140375850473216|Invalid HTTP_HOST header: ''. The domain name provided is not valid according to RFC 1034/1035.
ERROR|17/Feb/2021 20:48:41|basehttp|22258|140375850473216|"GET /script HTTP/1.1" 500 59
ERROR|17/Feb/2021 20:57:05|exception|22258|140375850473216|Invalid HTTP_HOST header: ''. The domain name provided is not valid according to RFC 1034/1035.
ERROR|17/Feb/2021 21:21:55|exception|22258|140375850473216|Invalid HTTP_HOST header: ''. The domain name provided is not valid according to RFC 1034/1035.
ERROR|17/Feb/2021 22:25:09|exception|22258|140375850473216|Invalid HTTP_HOST header: ''. The domain name provided is not valid according to RFC 1034/1035.
ERROR|18/Feb/2021 00:20:16|exception|22258|140375850473216|Invalid HTTP_HOST header: ''. The domain name provided is not valid according to RFC 1034/1035.
ERROR|18/Feb/2021 00:32:03|exception|22258|140375850473216|Invalid HTTP_HOST header: ''. The domain name provided is not valid according to RFC 1034/1035.
ERROR|18/Feb/2021 00:55:26|log|22258|140375850473216|Internal Server Error: /users
Traceback (most recent call last):
  File "/home/mobilitysqr/.local/lib/python3.6/site-packages/django/core/handlers/exception.py", line 34, in inner
    response = get_response(request)
  File "/home/mobilitysqr/.local/lib/python3.6/site-packages/django/utils/deprecation.py", line 90, in __call__
    response = self.process_request(request)
  File "/home/mobilitysqr/.local/lib/python3.6/site-packages/django/middleware/common.py", line 53, in process_request
    path = self.get_full_path_with_slash(request)
  File "/home/mobilitysqr/.local/lib/python3.6/site-packages/django/middleware/common.py", line 93, in get_full_path_with_slash
    'url': request.get_host() + new_path,
RuntimeError: You called this URL via POST, but the URL doesn't end in a slash and you have APPEND_SLASH set. Django can't redirect to the slash URL while maintaining POST data. Change your form to point to 52.165.220.40:8080/users/?page=&size=5 (note the trailing slash), or set APPEND_SLASH=False in your Django settings.
ERROR|18/Feb/2021 00:55:26|basehttp|22258|140375850473216|"POST /users?page=&size=5 HTTP/1.1" 500 65450
ERROR|18/Feb/2021 02:12:37|exception|22258|140375850473216|Invalid HTTP_HOST header: ''. The domain name provided is not valid according to RFC 1034/1035.
ERROR|18/Feb/2021 02:12:37|basehttp|22258|140375850473216|"GET /manager/html HTTP/1.1" 500 59
ERROR|18/Feb/2021 03:29:31|exception|22258|140375850473216|Invalid HTTP_HOST header: ''. The domain name provided is not valid according to RFC 1034/1035.
ERROR|18/Feb/2021 03:29:32|basehttp|22258|140375850473216|"GET /manager/html HTTP/1.1" 500 59
ERROR|18/Feb/2021 04:04:50|exception|22258|140375561856768|Invalid HTTP_HOST header: ''. The domain name provided is not valid according to RFC 1034/1035.
ERROR|18/Feb/2021 04:47:33|exception|22258|140375561856768|Invalid HTTP_HOST header: ''. The domain name provided is not valid according to RFC 1034/1035.
ERROR|18/Feb/2021 06:22:12|exception|22258|140375561856768|Invalid HTTP_HOST header: ''. The domain name provided is not valid according to RFC 1034/1035.
ERROR|18/Feb/2021 06:30:28|exception|22258|140375561856768|Invalid HTTP_HOST header: ''. The domain name provided is not valid according to RFC 1034/1035.
ERROR|18/Feb/2021 06:41:56|exception|22258|140375561856768|Invalid HTTP_HOST header: ''. The domain name provided is not valid according to RFC 1034/1035.
ERROR|18/Feb/2021 06:41:56|basehttp|22258|140375561856768|"GET /manager/html HTTP/1.1" 500 59
ERROR|18/Feb/2021 07:56:05|exception|22258|140375561856768|Invalid HTTP_HOST header: ''. The domain name provided is not valid according to RFC 1034/1035.
ERROR|18/Feb/2021 08:16:09|exception|22258|140375561856768|Invalid HTTP_HOST header: ''. The domain name provided is not valid according to RFC 1034/1035.
ERROR|18/Feb/2021 09:18:58|exception|22258|140375561856768|Invalid HTTP_HOST header: ''. The domain name provided is not valid according to RFC 1034/1035.
ERROR|18/Feb/2021 10:13:19|log|22258|140375553464064|Internal Server Error: /emoloyeeinfo/
Traceback (most recent call last):
  File "/home/mobilitysqr/.local/lib/python3.6/site-packages/django/core/handlers/exception.py", line 34, in inner
    response = get_response(request)
  File "/home/mobilitysqr/.local/lib/python3.6/site-packages/django/core/handlers/base.py", line 126, in _get_response
    response = self.process_exception_by_middleware(e, request)
  File "/home/mobilitysqr/.local/lib/python3.6/site-packages/django/core/handlers/base.py", line 124, in _get_response
    response = wrapped_callback(request, *callback_args, **callback_kwargs)
  File "/home/mobilitysqr/.local/lib/python3.6/site-packages/django/views/decorators/csrf.py", line 54, in wrapped_view
    return view_func(*args, **kwargs)
  File "/home/mobilitysqr/.local/lib/python3.6/site-packages/django/views/generic/base.py", line 68, in view
    return self.dispatch(request, *args, **kwargs)
  File "/home/mobilitysqr/.local/lib/python3.6/site-packages/rest_framework/views.py", line 495, in dispatch
    response = self.handle_exception(exc)
  File "/home/mobilitysqr/.local/lib/python3.6/site-packages/rest_framework/views.py", line 455, in handle_exception
    self.raise_uncaught_exception(exc)
  File "/home/mobilitysqr/.local/lib/python3.6/site-packages/rest_framework/views.py", line 492, in dispatch
    response = handler(request, *args, **kwargs)
  File "/var/www/html/mobilitysqr_staging/mobility_apps/employee/views.py", line 84, in post
    if not employees_recent[0]['last_login']:
  File "/home/mobilitysqr/.local/lib/python3.6/site-packages/django/db/models/query.py", line 303, in __getitem__
    return qs._result_cache[0]
IndexError: list index out of range
ERROR|18/Feb/2021 10:13:19|basehttp|22258|140375553464064|"POST /emoloyeeinfo/ HTTP/1.1" 500 17451
ERROR|18/Feb/2021 10:13:33|log|22258|140375553464064|Internal Server Error: /emoloyeeinfo/
Traceback (most recent call last):
  File "/home/mobilitysqr/.local/lib/python3.6/site-packages/django/core/handlers/exception.py", line 34, in inner
    response = get_response(request)
  File "/home/mobilitysqr/.local/lib/python3.6/site-packages/django/core/handlers/base.py", line 126, in _get_response
    response = self.process_exception_by_middleware(e, request)
  File "/home/mobilitysqr/.local/lib/python3.6/site-packages/django/core/handlers/base.py", line 124, in _get_response
    response = wrapped_callback(request, *callback_args, **callback_kwargs)
  File "/home/mobilitysqr/.local/lib/python3.6/site-packages/django/views/decorators/csrf.py", line 54, in wrapped_view
    return view_func(*args, **kwargs)
  File "/home/mobilitysqr/.local/lib/python3.6/site-packages/django/views/generic/base.py", line 68, in view
    return self.dispatch(request, *args, **kwargs)
  File "/home/mobilitysqr/.local/lib/python3.6/site-packages/rest_framework/views.py", line 495, in dispatch
    response = self.handle_exception(exc)
  File "/home/mobilitysqr/.local/lib/python3.6/site-packages/rest_framework/views.py", line 455, in handle_exception
    self.raise_uncaught_exception(exc)
  File "/home/mobilitysqr/.local/lib/python3.6/site-packages/rest_framework/views.py", line 492, in dispatch
    response = handler(request, *args, **kwargs)
  File "/var/www/html/mobilitysqr_staging/mobility_apps/employee/views.py", line 84, in post
    if not employees_recent[0]['last_login']:
  File "/home/mobilitysqr/.local/lib/python3.6/site-packages/django/db/models/query.py", line 303, in __getitem__
    return qs._result_cache[0]
IndexError: list index out of range
ERROR|18/Feb/2021 10:13:33|basehttp|22258|140375553464064|"POST /emoloyeeinfo/ HTTP/1.1" 500 17451
ERROR|18/Feb/2021 10:53:45|exception|22258|140375359223552|Invalid HTTP_HOST header: ''. The domain name provided is not valid according to RFC 1034/1035.
ERROR|18/Feb/2021 12:15:32|exception|22258|140375551112960|Invalid HTTP_HOST header: ''. The domain name provided is not valid according to RFC 1034/1035.
