ERROR|12/Nov/2020 11:17:40|log|74788|140330072872704|Internal Server Error: /import_employee/
Traceback (most recent call last):
  File "/home/mobilitysqr/.local/lib/python3.6/site-packages/django/core/handlers/exception.py", line 34, in inner
    response = get_response(request)
  File "/home/mobilitysqr/.local/lib/python3.6/site-packages/django/core/handlers/base.py", line 126, in _get_response
    response = self.process_exception_by_middleware(e, request)
  File "/home/mobilitysqr/.local/lib/python3.6/site-packages/django/core/handlers/base.py", line 124, in _get_response
    response = wrapped_callback(request, *callback_args, **callback_kwargs)
  File "/home/mobilitysqr/.local/lib/python3.6/site-packages/django/views/decorators/csrf.py", line 54, in wrapped_view
    return view_func(*args, **kwargs)
  File "/home/mobilitysqr/.local/lib/python3.6/site-packages/django/views/generic/base.py", line 68, in view
    return self.dispatch(request, *args, **kwargs)
  File "/home/mobilitysqr/.local/lib/python3.6/site-packages/rest_framework/views.py", line 495, in dispatch
    response = self.handle_exception(exc)
  File "/home/mobilitysqr/.local/lib/python3.6/site-packages/rest_framework/views.py", line 455, in handle_exception
    self.raise_uncaught_exception(exc)
  File "/home/mobilitysqr/.local/lib/python3.6/site-packages/rest_framework/views.py", line 492, in dispatch
    response = handler(request, *args, **kwargs)
  File "/var/www/html/mobilitysqrapi/mobility_apps/employee/views.py", line 1523, in get
    dataemailss['emapcode']
KeyError: 'emapcode'
ERROR|12/Nov/2020 11:17:40|basehttp|74788|140330072872704|"GET /import_employee/ HTTP/1.1" 500 16998
ERROR|12/Nov/2020 11:17:44|log|74788|140330072872704|Internal Server Error: /import_employee/
Traceback (most recent call last):
  File "/home/mobilitysqr/.local/lib/python3.6/site-packages/django/core/handlers/exception.py", line 34, in inner
    response = get_response(request)
  File "/home/mobilitysqr/.local/lib/python3.6/site-packages/django/core/handlers/base.py", line 126, in _get_response
    response = self.process_exception_by_middleware(e, request)
  File "/home/mobilitysqr/.local/lib/python3.6/site-packages/django/core/handlers/base.py", line 124, in _get_response
    response = wrapped_callback(request, *callback_args, **callback_kwargs)
  File "/home/mobilitysqr/.local/lib/python3.6/site-packages/django/views/decorators/csrf.py", line 54, in wrapped_view
    return view_func(*args, **kwargs)
  File "/home/mobilitysqr/.local/lib/python3.6/site-packages/django/views/generic/base.py", line 68, in view
    return self.dispatch(request, *args, **kwargs)
  File "/home/mobilitysqr/.local/lib/python3.6/site-packages/rest_framework/views.py", line 495, in dispatch
    response = self.handle_exception(exc)
  File "/home/mobilitysqr/.local/lib/python3.6/site-packages/rest_framework/views.py", line 455, in handle_exception
    self.raise_uncaught_exception(exc)
  File "/home/mobilitysqr/.local/lib/python3.6/site-packages/rest_framework/views.py", line 492, in dispatch
    response = handler(request, *args, **kwargs)
  File "/var/www/html/mobilitysqrapi/mobility_apps/employee/views.py", line 1523, in get
    dataemailss['emapcode']
KeyError: 'emapcode'
ERROR|12/Nov/2020 11:17:44|basehttp|74788|140330072872704|"GET /import_employee/ HTTP/1.1" 500 16998
ERROR|12/Nov/2020 12:25:39|log|78282|140295868724992|Internal Server Error: /import_employee/
Traceback (most recent call last):
  File "/home/mobilitysqr/.local/lib/python3.6/site-packages/django/core/handlers/exception.py", line 34, in inner
    response = get_response(request)
  File "/home/mobilitysqr/.local/lib/python3.6/site-packages/django/core/handlers/base.py", line 126, in _get_response
    response = self.process_exception_by_middleware(e, request)
  File "/home/mobilitysqr/.local/lib/python3.6/site-packages/django/core/handlers/base.py", line 124, in _get_response
    response = wrapped_callback(request, *callback_args, **callback_kwargs)
  File "/home/mobilitysqr/.local/lib/python3.6/site-packages/django/views/decorators/csrf.py", line 54, in wrapped_view
    return view_func(*args, **kwargs)
  File "/home/mobilitysqr/.local/lib/python3.6/site-packages/django/views/generic/base.py", line 68, in view
    return self.dispatch(request, *args, **kwargs)
  File "/home/mobilitysqr/.local/lib/python3.6/site-packages/rest_framework/views.py", line 495, in dispatch
    response = self.handle_exception(exc)
  File "/home/mobilitysqr/.local/lib/python3.6/site-packages/rest_framework/views.py", line 455, in handle_exception
    self.raise_uncaught_exception(exc)
  File "/home/mobilitysqr/.local/lib/python3.6/site-packages/rest_framework/views.py", line 492, in dispatch
    response = handler(request, *args, **kwargs)
  File "/var/www/html/mobilitysqrapi/mobility_apps/employee/views.py", line 1467, in get
    emp_code=employeeserializer['emp_code']
  File "/home/mobilitysqr/.local/lib/python3.6/site-packages/rest_framework/serializers.py", line 550, in __getitem__
    value = self.data.get(key)
  File "/home/mobilitysqr/.local/lib/python3.6/site-packages/rest_framework/serializers.py", line 563, in data
    ret = super(Serializer, self).data
  File "/home/mobilitysqr/.local/lib/python3.6/site-packages/rest_framework/serializers.py", line 258, in data
    raise AssertionError(msg)
AssertionError: When a serializer is passed a `data` keyword argument you must call `.is_valid()` before attempting to access the serialized `.data` representation.
You should either call `.is_valid()` first, or access `.initial_data` instead.
ERROR|12/Nov/2020 12:25:39|basehttp|78282|140295868724992|"GET /import_employee/ HTTP/1.1" 500 17909
ERROR|12/Nov/2020 12:27:16|log|78346|140679253665536|Internal Server Error: /import_employee/
Traceback (most recent call last):
  File "/home/mobilitysqr/.local/lib/python3.6/site-packages/django/core/handlers/exception.py", line 34, in inner
    response = get_response(request)
  File "/home/mobilitysqr/.local/lib/python3.6/site-packages/django/core/handlers/base.py", line 126, in _get_response
    response = self.process_exception_by_middleware(e, request)
  File "/home/mobilitysqr/.local/lib/python3.6/site-packages/django/core/handlers/base.py", line 124, in _get_response
    response = wrapped_callback(request, *callback_args, **callback_kwargs)
  File "/home/mobilitysqr/.local/lib/python3.6/site-packages/django/views/decorators/csrf.py", line 54, in wrapped_view
    return view_func(*args, **kwargs)
  File "/home/mobilitysqr/.local/lib/python3.6/site-packages/django/views/generic/base.py", line 68, in view
    return self.dispatch(request, *args, **kwargs)
  File "/home/mobilitysqr/.local/lib/python3.6/site-packages/rest_framework/views.py", line 495, in dispatch
    response = self.handle_exception(exc)
  File "/home/mobilitysqr/.local/lib/python3.6/site-packages/rest_framework/views.py", line 455, in handle_exception
    self.raise_uncaught_exception(exc)
  File "/home/mobilitysqr/.local/lib/python3.6/site-packages/rest_framework/views.py", line 492, in dispatch
    response = handler(request, *args, **kwargs)
  File "/var/www/html/mobilitysqrapi/mobility_apps/employee/views.py", line 1467, in get
    emp_code=employeeserializer['emp_code']
  File "/home/mobilitysqr/.local/lib/python3.6/site-packages/rest_framework/serializers.py", line 550, in __getitem__
    value = self.data.get(key)
  File "/home/mobilitysqr/.local/lib/python3.6/site-packages/rest_framework/serializers.py", line 563, in data
    ret = super(Serializer, self).data
  File "/home/mobilitysqr/.local/lib/python3.6/site-packages/rest_framework/serializers.py", line 258, in data
    raise AssertionError(msg)
AssertionError: When a serializer is passed a `data` keyword argument you must call `.is_valid()` before attempting to access the serialized `.data` representation.
You should either call `.is_valid()` first, or access `.initial_data` instead.
ERROR|12/Nov/2020 12:27:16|basehttp|78346|140679253665536|"GET /import_employee/ HTTP/1.1" 500 17909
ERROR|12/Nov/2020 12:27:19|log|78346|140679253665536|Internal Server Error: /import_employee/
Traceback (most recent call last):
  File "/home/mobilitysqr/.local/lib/python3.6/site-packages/django/core/handlers/exception.py", line 34, in inner
    response = get_response(request)
  File "/home/mobilitysqr/.local/lib/python3.6/site-packages/django/core/handlers/base.py", line 126, in _get_response
    response = self.process_exception_by_middleware(e, request)
  File "/home/mobilitysqr/.local/lib/python3.6/site-packages/django/core/handlers/base.py", line 124, in _get_response
    response = wrapped_callback(request, *callback_args, **callback_kwargs)
  File "/home/mobilitysqr/.local/lib/python3.6/site-packages/django/views/decorators/csrf.py", line 54, in wrapped_view
    return view_func(*args, **kwargs)
  File "/home/mobilitysqr/.local/lib/python3.6/site-packages/django/views/generic/base.py", line 68, in view
    return self.dispatch(request, *args, **kwargs)
  File "/home/mobilitysqr/.local/lib/python3.6/site-packages/rest_framework/views.py", line 495, in dispatch
    response = self.handle_exception(exc)
  File "/home/mobilitysqr/.local/lib/python3.6/site-packages/rest_framework/views.py", line 455, in handle_exception
    self.raise_uncaught_exception(exc)
  File "/home/mobilitysqr/.local/lib/python3.6/site-packages/rest_framework/views.py", line 492, in dispatch
    response = handler(request, *args, **kwargs)
  File "/var/www/html/mobilitysqrapi/mobility_apps/employee/views.py", line 1467, in get
    emp_code=employeeserializer['emp_code']
  File "/home/mobilitysqr/.local/lib/python3.6/site-packages/rest_framework/serializers.py", line 550, in __getitem__
    value = self.data.get(key)
  File "/home/mobilitysqr/.local/lib/python3.6/site-packages/rest_framework/serializers.py", line 563, in data
    ret = super(Serializer, self).data
  File "/home/mobilitysqr/.local/lib/python3.6/site-packages/rest_framework/serializers.py", line 258, in data
    raise AssertionError(msg)
AssertionError: When a serializer is passed a `data` keyword argument you must call `.is_valid()` before attempting to access the serialized `.data` representation.
You should either call `.is_valid()` first, or access `.initial_data` instead.
ERROR|12/Nov/2020 12:27:19|basehttp|78346|140679253665536|"GET /import_employee/ HTTP/1.1" 500 17909
ERROR|12/Nov/2020 12:31:40|log|78548|140417168774912|Internal Server Error: /import_employee/
Traceback (most recent call last):
  File "/home/mobilitysqr/.local/lib/python3.6/site-packages/django/core/handlers/exception.py", line 34, in inner
    response = get_response(request)
  File "/home/mobilitysqr/.local/lib/python3.6/site-packages/django/core/handlers/base.py", line 156, in _get_response
    response = self.process_exception_by_middleware(e, request)
  File "/home/mobilitysqr/.local/lib/python3.6/site-packages/django/core/handlers/base.py", line 154, in _get_response
    response = response.render()
  File "/home/mobilitysqr/.local/lib/python3.6/site-packages/django/template/response.py", line 106, in render
    self.content = self.rendered_content
  File "/home/mobilitysqr/.local/lib/python3.6/site-packages/rest_framework/response.py", line 72, in rendered_content
    ret = renderer.render(self.data, accepted_media_type, context)
  File "/home/mobilitysqr/.local/lib/python3.6/site-packages/rest_framework/renderers.py", line 107, in render
    allow_nan=not self.strict, separators=separators
  File "/home/mobilitysqr/.local/lib/python3.6/site-packages/rest_framework/utils/json.py", line 28, in dumps
    return json.dumps(*args, **kwargs)
  File "/usr/lib/python3.6/json/__init__.py", line 238, in dumps
    **kw).encode(obj)
  File "/usr/lib/python3.6/json/encoder.py", line 199, in encode
    chunks = self.iterencode(o, _one_shot=True)
  File "/usr/lib/python3.6/json/encoder.py", line 257, in iterencode
    return _iterencode(o, 0)
  File "/home/mobilitysqr/.local/lib/python3.6/site-packages/rest_framework/utils/encoders.py", line 68, in default
    return super(JSONEncoder, self).default(obj)
  File "/usr/lib/python3.6/json/encoder.py", line 180, in default
    o.__class__.__name__)
TypeError: Object of type 'Employee_PhonesSerializers' is not JSON serializable
ERROR|12/Nov/2020 12:31:40|basehttp|78548|140417168774912|"GET /import_employee/ HTTP/1.1" 500 134931
ERROR|12/Nov/2020 12:55:15|log|79544|140488434489088|Internal Server Error: /import_employee/
Traceback (most recent call last):
  File "/home/mobilitysqr/.local/lib/python3.6/site-packages/django/core/handlers/exception.py", line 34, in inner
    response = get_response(request)
  File "/home/mobilitysqr/.local/lib/python3.6/site-packages/django/core/handlers/base.py", line 126, in _get_response
    response = self.process_exception_by_middleware(e, request)
  File "/home/mobilitysqr/.local/lib/python3.6/site-packages/django/core/handlers/base.py", line 124, in _get_response
    response = wrapped_callback(request, *callback_args, **callback_kwargs)
  File "/home/mobilitysqr/.local/lib/python3.6/site-packages/django/views/decorators/csrf.py", line 54, in wrapped_view
    return view_func(*args, **kwargs)
  File "/home/mobilitysqr/.local/lib/python3.6/site-packages/django/views/generic/base.py", line 68, in view
    return self.dispatch(request, *args, **kwargs)
  File "/home/mobilitysqr/.local/lib/python3.6/site-packages/rest_framework/views.py", line 495, in dispatch
    response = self.handle_exception(exc)
  File "/home/mobilitysqr/.local/lib/python3.6/site-packages/rest_framework/views.py", line 455, in handle_exception
    self.raise_uncaught_exception(exc)
  File "/home/mobilitysqr/.local/lib/python3.6/site-packages/rest_framework/views.py", line 492, in dispatch
    response = handler(request, *args, **kwargs)
  File "/var/www/html/mobilitysqrapi/mobility_apps/employee/views.py", line 1606, in get
    phone_data.append(phonerror)
AttributeError: 'dict' object has no attribute 'append'
ERROR|12/Nov/2020 12:55:15|basehttp|79544|140488434489088|"GET /import_employee/ HTTP/1.1" 500 17077
ERROR|12/Nov/2020 14:03:36|basehttp|79685|140539143251712|You're accessing the development server over HTTPS, but it only supports HTTP.

ERROR|12/Nov/2020 14:51:57|views|83150|139947996677888|[{'Personal_Info_Error': []}, {'Address_Errors': []}, {'Emails_Errors': [{'Emp9867546': {'email_address': [ErrorDetail(string='Employee Emails with this email address already exists.', code='unique')]}}, {'Emp9867547': {'email_address': [ErrorDetail(string='Employee Emails with this email address already exists.', code='unique')]}}, {'Emp9867548': {'email_address': [ErrorDetail(string='Employee Emails with this email address already exists.', code='unique')]}}, {'Emp9867549': {'email_address': [ErrorDetail(string='Employee Emails with this email address already exists.', code='unique')]}}, {'Emp9867550': {'email_address': [ErrorDetail(string='Employee Emails with this email address already exists.', code='unique')]}}, {'Emp9867551': {'email_address': [ErrorDetail(string='Employee Emails with this email address already exists.', code='unique')]}}, {'Emp9867552': {'email_address': [ErrorDetail(string='Employee Emails with this email address already exists.', code='unique')]}}, {'Emp9867553': {'email_address': [ErrorDetail(string='Employee Emails with this email address already exists.', code='unique')]}}]}, {'Emergency_Contact_Error': []}, {'Phone': [{'Emp986754612': {'emp_code': [ErrorDetail(string='Object with emp_code=Emp986754612 does not exist.', code='does_not_exist')]}}]}, {'Passport_Error': []}, {'Visa_Error': []}, {'Organization_Error': []}, {'NationalID_Error': []}]
ERROR|12/Nov/2020 17:32:14|log|87905|140520354109184|Internal Server Error: /get_update_project/
Traceback (most recent call last):
  File "/home/mobilitysqr/.local/lib/python3.6/site-packages/django/core/handlers/exception.py", line 34, in inner
    response = get_response(request)
  File "/home/mobilitysqr/.local/lib/python3.6/site-packages/django/core/handlers/base.py", line 126, in _get_response
    response = self.process_exception_by_middleware(e, request)
  File "/home/mobilitysqr/.local/lib/python3.6/site-packages/django/core/handlers/base.py", line 124, in _get_response
    response = wrapped_callback(request, *callback_args, **callback_kwargs)
  File "/home/mobilitysqr/.local/lib/python3.6/site-packages/django/views/decorators/csrf.py", line 54, in wrapped_view
    return view_func(*args, **kwargs)
  File "/home/mobilitysqr/.local/lib/python3.6/site-packages/django/views/generic/base.py", line 68, in view
    return self.dispatch(request, *args, **kwargs)
  File "/home/mobilitysqr/.local/lib/python3.6/site-packages/rest_framework/views.py", line 495, in dispatch
    response = self.handle_exception(exc)
  File "/home/mobilitysqr/.local/lib/python3.6/site-packages/rest_framework/views.py", line 455, in handle_exception
    self.raise_uncaught_exception(exc)
  File "/home/mobilitysqr/.local/lib/python3.6/site-packages/rest_framework/views.py", line 492, in dispatch
    response = handler(request, *args, **kwargs)
  File "/var/www/html/mobilitysqrapi/mobility_apps/master/views/project.py", line 114, in post
    return Response(dict, status=status.HTTP_201_CREATED)
UnboundLocalError: local variable 'dict' referenced before assignment
ERROR|12/Nov/2020 17:32:14|basehttp|87905|140520354109184|"POST /get_update_project/ HTTP/1.1" 500 17143
ERROR|12/Nov/2020 17:32:16|log|87905|140520354109184|Internal Server Error: /get_update_project/
Traceback (most recent call last):
  File "/home/mobilitysqr/.local/lib/python3.6/site-packages/django/core/handlers/exception.py", line 34, in inner
    response = get_response(request)
  File "/home/mobilitysqr/.local/lib/python3.6/site-packages/django/core/handlers/base.py", line 126, in _get_response
    response = self.process_exception_by_middleware(e, request)
  File "/home/mobilitysqr/.local/lib/python3.6/site-packages/django/core/handlers/base.py", line 124, in _get_response
    response = wrapped_callback(request, *callback_args, **callback_kwargs)
  File "/home/mobilitysqr/.local/lib/python3.6/site-packages/django/views/decorators/csrf.py", line 54, in wrapped_view
    return view_func(*args, **kwargs)
  File "/home/mobilitysqr/.local/lib/python3.6/site-packages/django/views/generic/base.py", line 68, in view
    return self.dispatch(request, *args, **kwargs)
  File "/home/mobilitysqr/.local/lib/python3.6/site-packages/rest_framework/views.py", line 495, in dispatch
    response = self.handle_exception(exc)
  File "/home/mobilitysqr/.local/lib/python3.6/site-packages/rest_framework/views.py", line 455, in handle_exception
    self.raise_uncaught_exception(exc)
  File "/home/mobilitysqr/.local/lib/python3.6/site-packages/rest_framework/views.py", line 492, in dispatch
    response = handler(request, *args, **kwargs)
  File "/var/www/html/mobilitysqrapi/mobility_apps/master/views/project.py", line 114, in post
    return Response(dict, status=status.HTTP_201_CREATED)
UnboundLocalError: local variable 'dict' referenced before assignment
ERROR|12/Nov/2020 17:32:16|basehttp|87905|140520354109184|"POST /get_update_project/ HTTP/1.1" 500 17143
ERROR|12/Nov/2020 17:34:18|log|88062|139786474452736|Internal Server Error: /get_update_project/
Traceback (most recent call last):
  File "/home/mobilitysqr/.local/lib/python3.6/site-packages/django/core/handlers/exception.py", line 34, in inner
    response = get_response(request)
  File "/home/mobilitysqr/.local/lib/python3.6/site-packages/django/core/handlers/base.py", line 126, in _get_response
    response = self.process_exception_by_middleware(e, request)
  File "/home/mobilitysqr/.local/lib/python3.6/site-packages/django/core/handlers/base.py", line 124, in _get_response
    response = wrapped_callback(request, *callback_args, **callback_kwargs)
  File "/home/mobilitysqr/.local/lib/python3.6/site-packages/django/views/decorators/csrf.py", line 54, in wrapped_view
    return view_func(*args, **kwargs)
  File "/home/mobilitysqr/.local/lib/python3.6/site-packages/django/views/generic/base.py", line 68, in view
    return self.dispatch(request, *args, **kwargs)
  File "/home/mobilitysqr/.local/lib/python3.6/site-packages/rest_framework/views.py", line 495, in dispatch
    response = self.handle_exception(exc)
  File "/home/mobilitysqr/.local/lib/python3.6/site-packages/rest_framework/views.py", line 455, in handle_exception
    self.raise_uncaught_exception(exc)
  File "/home/mobilitysqr/.local/lib/python3.6/site-packages/rest_framework/views.py", line 492, in dispatch
    response = handler(request, *args, **kwargs)
  File "/var/www/html/mobilitysqrapi/mobility_apps/master/views/project.py", line 113, in post
    return Response(dict, status=status.HTTP_201_CREATED)
UnboundLocalError: local variable 'dict' referenced before assignment
ERROR|12/Nov/2020 17:34:18|basehttp|88062|139786474452736|"POST /get_update_project/ HTTP/1.1" 500 17143
ERROR|12/Nov/2020 17:34:20|log|88062|139786474452736|Internal Server Error: /get_update_project/
Traceback (most recent call last):
  File "/home/mobilitysqr/.local/lib/python3.6/site-packages/django/core/handlers/exception.py", line 34, in inner
    response = get_response(request)
  File "/home/mobilitysqr/.local/lib/python3.6/site-packages/django/core/handlers/base.py", line 126, in _get_response
    response = self.process_exception_by_middleware(e, request)
  File "/home/mobilitysqr/.local/lib/python3.6/site-packages/django/core/handlers/base.py", line 124, in _get_response
    response = wrapped_callback(request, *callback_args, **callback_kwargs)
  File "/home/mobilitysqr/.local/lib/python3.6/site-packages/django/views/decorators/csrf.py", line 54, in wrapped_view
    return view_func(*args, **kwargs)
  File "/home/mobilitysqr/.local/lib/python3.6/site-packages/django/views/generic/base.py", line 68, in view
    return self.dispatch(request, *args, **kwargs)
  File "/home/mobilitysqr/.local/lib/python3.6/site-packages/rest_framework/views.py", line 495, in dispatch
    response = self.handle_exception(exc)
  File "/home/mobilitysqr/.local/lib/python3.6/site-packages/rest_framework/views.py", line 455, in handle_exception
    self.raise_uncaught_exception(exc)
  File "/home/mobilitysqr/.local/lib/python3.6/site-packages/rest_framework/views.py", line 492, in dispatch
    response = handler(request, *args, **kwargs)
  File "/var/www/html/mobilitysqrapi/mobility_apps/master/views/project.py", line 113, in post
    return Response(dict, status=status.HTTP_201_CREATED)
UnboundLocalError: local variable 'dict' referenced before assignment
ERROR|12/Nov/2020 17:34:20|basehttp|88062|139786474452736|"POST /get_update_project/ HTTP/1.1" 500 17143
ERROR|12/Nov/2020 17:34:23|log|88062|139786474452736|Internal Server Error: /get_update_project/
Traceback (most recent call last):
  File "/home/mobilitysqr/.local/lib/python3.6/site-packages/django/core/handlers/exception.py", line 34, in inner
    response = get_response(request)
  File "/home/mobilitysqr/.local/lib/python3.6/site-packages/django/core/handlers/base.py", line 126, in _get_response
    response = self.process_exception_by_middleware(e, request)
  File "/home/mobilitysqr/.local/lib/python3.6/site-packages/django/core/handlers/base.py", line 124, in _get_response
    response = wrapped_callback(request, *callback_args, **callback_kwargs)
  File "/home/mobilitysqr/.local/lib/python3.6/site-packages/django/views/decorators/csrf.py", line 54, in wrapped_view
    return view_func(*args, **kwargs)
  File "/home/mobilitysqr/.local/lib/python3.6/site-packages/django/views/generic/base.py", line 68, in view
    return self.dispatch(request, *args, **kwargs)
  File "/home/mobilitysqr/.local/lib/python3.6/site-packages/rest_framework/views.py", line 495, in dispatch
    response = self.handle_exception(exc)
  File "/home/mobilitysqr/.local/lib/python3.6/site-packages/rest_framework/views.py", line 455, in handle_exception
    self.raise_uncaught_exception(exc)
  File "/home/mobilitysqr/.local/lib/python3.6/site-packages/rest_framework/views.py", line 492, in dispatch
    response = handler(request, *args, **kwargs)
  File "/var/www/html/mobilitysqrapi/mobility_apps/master/views/project.py", line 113, in post
    return Response(dict, status=status.HTTP_201_CREATED)
UnboundLocalError: local variable 'dict' referenced before assignment
ERROR|12/Nov/2020 17:34:23|basehttp|88062|139786474452736|"POST /get_update_project/ HTTP/1.1" 500 17143
ERROR|12/Nov/2020 17:34:24|log|88062|139786474452736|Internal Server Error: /get_update_project/
Traceback (most recent call last):
  File "/home/mobilitysqr/.local/lib/python3.6/site-packages/django/core/handlers/exception.py", line 34, in inner
    response = get_response(request)
  File "/home/mobilitysqr/.local/lib/python3.6/site-packages/django/core/handlers/base.py", line 126, in _get_response
    response = self.process_exception_by_middleware(e, request)
  File "/home/mobilitysqr/.local/lib/python3.6/site-packages/django/core/handlers/base.py", line 124, in _get_response
    response = wrapped_callback(request, *callback_args, **callback_kwargs)
  File "/home/mobilitysqr/.local/lib/python3.6/site-packages/django/views/decorators/csrf.py", line 54, in wrapped_view
    return view_func(*args, **kwargs)
  File "/home/mobilitysqr/.local/lib/python3.6/site-packages/django/views/generic/base.py", line 68, in view
    return self.dispatch(request, *args, **kwargs)
  File "/home/mobilitysqr/.local/lib/python3.6/site-packages/rest_framework/views.py", line 495, in dispatch
    response = self.handle_exception(exc)
  File "/home/mobilitysqr/.local/lib/python3.6/site-packages/rest_framework/views.py", line 455, in handle_exception
    self.raise_uncaught_exception(exc)
  File "/home/mobilitysqr/.local/lib/python3.6/site-packages/rest_framework/views.py", line 492, in dispatch
    response = handler(request, *args, **kwargs)
  File "/var/www/html/mobilitysqrapi/mobility_apps/master/views/project.py", line 113, in post
    return Response(dict, status=status.HTTP_201_CREATED)
UnboundLocalError: local variable 'dict' referenced before assignment
ERROR|12/Nov/2020 17:34:24|basehttp|88062|139786474452736|"POST /get_update_project/ HTTP/1.1" 500 17143
ERROR|12/Nov/2020 17:35:06|log|88087|140010620188416|Internal Server Error: /get_update_project/
Traceback (most recent call last):
  File "/home/mobilitysqr/.local/lib/python3.6/site-packages/django/core/handlers/exception.py", line 34, in inner
    response = get_response(request)
  File "/home/mobilitysqr/.local/lib/python3.6/site-packages/django/core/handlers/base.py", line 126, in _get_response
    response = self.process_exception_by_middleware(e, request)
  File "/home/mobilitysqr/.local/lib/python3.6/site-packages/django/core/handlers/base.py", line 124, in _get_response
    response = wrapped_callback(request, *callback_args, **callback_kwargs)
  File "/home/mobilitysqr/.local/lib/python3.6/site-packages/django/views/decorators/csrf.py", line 54, in wrapped_view
    return view_func(*args, **kwargs)
  File "/home/mobilitysqr/.local/lib/python3.6/site-packages/django/views/generic/base.py", line 68, in view
    return self.dispatch(request, *args, **kwargs)
  File "/home/mobilitysqr/.local/lib/python3.6/site-packages/rest_framework/views.py", line 495, in dispatch
    response = self.handle_exception(exc)
  File "/home/mobilitysqr/.local/lib/python3.6/site-packages/rest_framework/views.py", line 455, in handle_exception
    self.raise_uncaught_exception(exc)
  File "/home/mobilitysqr/.local/lib/python3.6/site-packages/rest_framework/views.py", line 492, in dispatch
    response = handler(request, *args, **kwargs)
  File "/var/www/html/mobilitysqrapi/mobility_apps/master/views/project.py", line 113, in post
    return Response(dicts, status=status.HTTP_201_CREATED)
UnboundLocalError: local variable 'dicts' referenced before assignment
ERROR|12/Nov/2020 17:35:06|basehttp|88087|140010620188416|"POST /get_update_project/ HTTP/1.1" 500 17146
ERROR|12/Nov/2020 17:35:10|log|88087|140010620188416|Internal Server Error: /get_update_project/
Traceback (most recent call last):
  File "/home/mobilitysqr/.local/lib/python3.6/site-packages/django/core/handlers/exception.py", line 34, in inner
    response = get_response(request)
  File "/home/mobilitysqr/.local/lib/python3.6/site-packages/django/core/handlers/base.py", line 126, in _get_response
    response = self.process_exception_by_middleware(e, request)
  File "/home/mobilitysqr/.local/lib/python3.6/site-packages/django/core/handlers/base.py", line 124, in _get_response
    response = wrapped_callback(request, *callback_args, **callback_kwargs)
  File "/home/mobilitysqr/.local/lib/python3.6/site-packages/django/views/decorators/csrf.py", line 54, in wrapped_view
    return view_func(*args, **kwargs)
  File "/home/mobilitysqr/.local/lib/python3.6/site-packages/django/views/generic/base.py", line 68, in view
    return self.dispatch(request, *args, **kwargs)
  File "/home/mobilitysqr/.local/lib/python3.6/site-packages/rest_framework/views.py", line 495, in dispatch
    response = self.handle_exception(exc)
  File "/home/mobilitysqr/.local/lib/python3.6/site-packages/rest_framework/views.py", line 455, in handle_exception
    self.raise_uncaught_exception(exc)
  File "/home/mobilitysqr/.local/lib/python3.6/site-packages/rest_framework/views.py", line 492, in dispatch
    response = handler(request, *args, **kwargs)
  File "/var/www/html/mobilitysqrapi/mobility_apps/master/views/project.py", line 113, in post
    return Response(dicts, status=status.HTTP_201_CREATED)
UnboundLocalError: local variable 'dicts' referenced before assignment
ERROR|12/Nov/2020 17:35:10|basehttp|88087|140010620188416|"POST /get_update_project/ HTTP/1.1" 500 17146
ERROR|12/Nov/2020 17:37:00|log|88228|139716648552192|Internal Server Error: /get_update_project/
Traceback (most recent call last):
  File "/home/mobilitysqr/.local/lib/python3.6/site-packages/django/core/handlers/exception.py", line 34, in inner
    response = get_response(request)
  File "/home/mobilitysqr/.local/lib/python3.6/site-packages/django/core/handlers/base.py", line 126, in _get_response
    response = self.process_exception_by_middleware(e, request)
  File "/home/mobilitysqr/.local/lib/python3.6/site-packages/django/core/handlers/base.py", line 124, in _get_response
    response = wrapped_callback(request, *callback_args, **callback_kwargs)
  File "/home/mobilitysqr/.local/lib/python3.6/site-packages/django/views/decorators/csrf.py", line 54, in wrapped_view
    return view_func(*args, **kwargs)
  File "/home/mobilitysqr/.local/lib/python3.6/site-packages/django/views/generic/base.py", line 68, in view
    return self.dispatch(request, *args, **kwargs)
  File "/home/mobilitysqr/.local/lib/python3.6/site-packages/rest_framework/views.py", line 497, in dispatch
    self.response = self.finalize_response(request, response, *args, **kwargs)
  File "/home/mobilitysqr/.local/lib/python3.6/site-packages/rest_framework/views.py", line 412, in finalize_response
    % type(response)
AssertionError: Expected a `Response`, `HttpResponse` or `HttpStreamingResponse` to be returned from the view, but received a `<class 'NoneType'>`
ERROR|12/Nov/2020 17:37:00|basehttp|88228|139716648552192|"POST /get_update_project/ HTTP/1.1" 500 80465
ERROR|12/Nov/2020 17:37:34|log|88228|139716648552192|Internal Server Error: /get_update_project/
Traceback (most recent call last):
  File "/home/mobilitysqr/.local/lib/python3.6/site-packages/django/core/handlers/exception.py", line 34, in inner
    response = get_response(request)
  File "/home/mobilitysqr/.local/lib/python3.6/site-packages/django/core/handlers/base.py", line 126, in _get_response
    response = self.process_exception_by_middleware(e, request)
  File "/home/mobilitysqr/.local/lib/python3.6/site-packages/django/core/handlers/base.py", line 124, in _get_response
    response = wrapped_callback(request, *callback_args, **callback_kwargs)
  File "/home/mobilitysqr/.local/lib/python3.6/site-packages/django/views/decorators/csrf.py", line 54, in wrapped_view
    return view_func(*args, **kwargs)
  File "/home/mobilitysqr/.local/lib/python3.6/site-packages/django/views/generic/base.py", line 68, in view
    return self.dispatch(request, *args, **kwargs)
  File "/home/mobilitysqr/.local/lib/python3.6/site-packages/rest_framework/views.py", line 497, in dispatch
    self.response = self.finalize_response(request, response, *args, **kwargs)
  File "/home/mobilitysqr/.local/lib/python3.6/site-packages/rest_framework/views.py", line 412, in finalize_response
    % type(response)
AssertionError: Expected a `Response`, `HttpResponse` or `HttpStreamingResponse` to be returned from the view, but received a `<class 'NoneType'>`
ERROR|12/Nov/2020 17:37:34|basehttp|88228|139716648552192|"POST /get_update_project/ HTTP/1.1" 500 80465
ERROR|12/Nov/2020 17:37:38|log|88228|139716648552192|Internal Server Error: /get_update_project/
Traceback (most recent call last):
  File "/home/mobilitysqr/.local/lib/python3.6/site-packages/django/core/handlers/exception.py", line 34, in inner
    response = get_response(request)
  File "/home/mobilitysqr/.local/lib/python3.6/site-packages/django/core/handlers/base.py", line 126, in _get_response
    response = self.process_exception_by_middleware(e, request)
  File "/home/mobilitysqr/.local/lib/python3.6/site-packages/django/core/handlers/base.py", line 124, in _get_response
    response = wrapped_callback(request, *callback_args, **callback_kwargs)
  File "/home/mobilitysqr/.local/lib/python3.6/site-packages/django/views/decorators/csrf.py", line 54, in wrapped_view
    return view_func(*args, **kwargs)
  File "/home/mobilitysqr/.local/lib/python3.6/site-packages/django/views/generic/base.py", line 68, in view
    return self.dispatch(request, *args, **kwargs)
  File "/home/mobilitysqr/.local/lib/python3.6/site-packages/rest_framework/views.py", line 497, in dispatch
    self.response = self.finalize_response(request, response, *args, **kwargs)
  File "/home/mobilitysqr/.local/lib/python3.6/site-packages/rest_framework/views.py", line 412, in finalize_response
    % type(response)
AssertionError: Expected a `Response`, `HttpResponse` or `HttpStreamingResponse` to be returned from the view, but received a `<class 'NoneType'>`
ERROR|12/Nov/2020 17:37:38|basehttp|88228|139716648552192|"POST /get_update_project/ HTTP/1.1" 500 80465
ERROR|12/Nov/2020 17:50:01|log|88637|140124646364928|Internal Server Error: /get_update_project/
Traceback (most recent call last):
  File "/home/mobilitysqr/.local/lib/python3.6/site-packages/django/core/handlers/exception.py", line 34, in inner
    response = get_response(request)
  File "/home/mobilitysqr/.local/lib/python3.6/site-packages/django/core/handlers/base.py", line 126, in _get_response
    response = self.process_exception_by_middleware(e, request)
  File "/home/mobilitysqr/.local/lib/python3.6/site-packages/django/core/handlers/base.py", line 124, in _get_response
    response = wrapped_callback(request, *callback_args, **callback_kwargs)
  File "/home/mobilitysqr/.local/lib/python3.6/site-packages/django/views/decorators/csrf.py", line 54, in wrapped_view
    return view_func(*args, **kwargs)
  File "/home/mobilitysqr/.local/lib/python3.6/site-packages/django/views/generic/base.py", line 68, in view
    return self.dispatch(request, *args, **kwargs)
  File "/home/mobilitysqr/.local/lib/python3.6/site-packages/rest_framework/views.py", line 495, in dispatch
    response = self.handle_exception(exc)
  File "/home/mobilitysqr/.local/lib/python3.6/site-packages/rest_framework/views.py", line 455, in handle_exception
    self.raise_uncaught_exception(exc)
  File "/home/mobilitysqr/.local/lib/python3.6/site-packages/rest_framework/views.py", line 492, in dispatch
    response = handler(request, *args, **kwargs)
  File "/var/www/html/mobilitysqrapi/mobility_apps/master/views/project.py", line 112, in post
    return Response(dict, status=status.HTTP_201_CREATED)
UnboundLocalError: local variable 'dict' referenced before assignment
ERROR|12/Nov/2020 17:50:01|basehttp|88637|140124646364928|"POST /get_update_project/ HTTP/1.1" 500 17143
ERROR|12/Nov/2020 17:53:07|log|88817|140471235331840|Internal Server Error: /get_update_project/
Traceback (most recent call last):
  File "/home/mobilitysqr/.local/lib/python3.6/site-packages/django/core/handlers/exception.py", line 34, in inner
    response = get_response(request)
  File "/home/mobilitysqr/.local/lib/python3.6/site-packages/django/core/handlers/base.py", line 126, in _get_response
    response = self.process_exception_by_middleware(e, request)
  File "/home/mobilitysqr/.local/lib/python3.6/site-packages/django/core/handlers/base.py", line 124, in _get_response
    response = wrapped_callback(request, *callback_args, **callback_kwargs)
  File "/home/mobilitysqr/.local/lib/python3.6/site-packages/django/views/decorators/csrf.py", line 54, in wrapped_view
    return view_func(*args, **kwargs)
  File "/home/mobilitysqr/.local/lib/python3.6/site-packages/django/views/generic/base.py", line 68, in view
    return self.dispatch(request, *args, **kwargs)
  File "/home/mobilitysqr/.local/lib/python3.6/site-packages/rest_framework/views.py", line 495, in dispatch
    response = self.handle_exception(exc)
  File "/home/mobilitysqr/.local/lib/python3.6/site-packages/rest_framework/views.py", line 455, in handle_exception
    self.raise_uncaught_exception(exc)
  File "/home/mobilitysqr/.local/lib/python3.6/site-packages/rest_framework/views.py", line 492, in dispatch
    response = handler(request, *args, **kwargs)
  File "/var/www/html/mobilitysqrapi/mobility_apps/master/views/project.py", line 104, in post
    projectpid = Project.objects.filter(id=request.data['uid']).first()
KeyError: 'uid'
ERROR|12/Nov/2020 17:53:07|basehttp|88817|140471235331840|"POST /get_update_project/ HTTP/1.1" 500 17049
ERROR|12/Nov/2020 17:53:10|log|88817|140471235331840|Internal Server Error: /get_update_project/
Traceback (most recent call last):
  File "/home/mobilitysqr/.local/lib/python3.6/site-packages/django/core/handlers/exception.py", line 34, in inner
    response = get_response(request)
  File "/home/mobilitysqr/.local/lib/python3.6/site-packages/django/core/handlers/base.py", line 126, in _get_response
    response = self.process_exception_by_middleware(e, request)
  File "/home/mobilitysqr/.local/lib/python3.6/site-packages/django/core/handlers/base.py", line 124, in _get_response
    response = wrapped_callback(request, *callback_args, **callback_kwargs)
  File "/home/mobilitysqr/.local/lib/python3.6/site-packages/django/views/decorators/csrf.py", line 54, in wrapped_view
    return view_func(*args, **kwargs)
  File "/home/mobilitysqr/.local/lib/python3.6/site-packages/django/views/generic/base.py", line 68, in view
    return self.dispatch(request, *args, **kwargs)
  File "/home/mobilitysqr/.local/lib/python3.6/site-packages/rest_framework/views.py", line 495, in dispatch
    response = self.handle_exception(exc)
  File "/home/mobilitysqr/.local/lib/python3.6/site-packages/rest_framework/views.py", line 455, in handle_exception
    self.raise_uncaught_exception(exc)
  File "/home/mobilitysqr/.local/lib/python3.6/site-packages/rest_framework/views.py", line 492, in dispatch
    response = handler(request, *args, **kwargs)
  File "/var/www/html/mobilitysqrapi/mobility_apps/master/views/project.py", line 104, in post
    projectpid = Project.objects.filter(id=request.data['uid']).first()
KeyError: 'uid'
ERROR|12/Nov/2020 17:53:10|basehttp|88817|140471235331840|"POST /get_update_project/ HTTP/1.1" 500 17049
ERROR|12/Nov/2020 17:54:00|log|88817|140471235331840|Internal Server Error: /get_update_project/
Traceback (most recent call last):
  File "/home/mobilitysqr/.local/lib/python3.6/site-packages/django/core/handlers/exception.py", line 34, in inner
    response = get_response(request)
  File "/home/mobilitysqr/.local/lib/python3.6/site-packages/django/core/handlers/base.py", line 126, in _get_response
    response = self.process_exception_by_middleware(e, request)
  File "/home/mobilitysqr/.local/lib/python3.6/site-packages/django/core/handlers/base.py", line 124, in _get_response
    response = wrapped_callback(request, *callback_args, **callback_kwargs)
  File "/home/mobilitysqr/.local/lib/python3.6/site-packages/django/views/decorators/csrf.py", line 54, in wrapped_view
    return view_func(*args, **kwargs)
  File "/home/mobilitysqr/.local/lib/python3.6/site-packages/django/views/generic/base.py", line 68, in view
    return self.dispatch(request, *args, **kwargs)
  File "/home/mobilitysqr/.local/lib/python3.6/site-packages/rest_framework/views.py", line 495, in dispatch
    response = self.handle_exception(exc)
  File "/home/mobilitysqr/.local/lib/python3.6/site-packages/rest_framework/views.py", line 455, in handle_exception
    self.raise_uncaught_exception(exc)
  File "/home/mobilitysqr/.local/lib/python3.6/site-packages/rest_framework/views.py", line 492, in dispatch
    response = handler(request, *args, **kwargs)
  File "/var/www/html/mobilitysqrapi/mobility_apps/master/views/project.py", line 113, in post
    return Response(dict, status=status.HTTP_201_CREATED)
UnboundLocalError: local variable 'dict' referenced before assignment
ERROR|12/Nov/2020 17:54:00|basehttp|88817|140471235331840|"POST /get_update_project/ HTTP/1.1" 500 17150
ERROR|12/Nov/2020 17:54:03|log|88817|140471235331840|Internal Server Error: /get_update_project/
Traceback (most recent call last):
  File "/home/mobilitysqr/.local/lib/python3.6/site-packages/django/core/handlers/exception.py", line 34, in inner
    response = get_response(request)
  File "/home/mobilitysqr/.local/lib/python3.6/site-packages/django/core/handlers/base.py", line 126, in _get_response
    response = self.process_exception_by_middleware(e, request)
  File "/home/mobilitysqr/.local/lib/python3.6/site-packages/django/core/handlers/base.py", line 124, in _get_response
    response = wrapped_callback(request, *callback_args, **callback_kwargs)
  File "/home/mobilitysqr/.local/lib/python3.6/site-packages/django/views/decorators/csrf.py", line 54, in wrapped_view
    return view_func(*args, **kwargs)
  File "/home/mobilitysqr/.local/lib/python3.6/site-packages/django/views/generic/base.py", line 68, in view
    return self.dispatch(request, *args, **kwargs)
  File "/home/mobilitysqr/.local/lib/python3.6/site-packages/rest_framework/views.py", line 495, in dispatch
    response = self.handle_exception(exc)
  File "/home/mobilitysqr/.local/lib/python3.6/site-packages/rest_framework/views.py", line 455, in handle_exception
    self.raise_uncaught_exception(exc)
  File "/home/mobilitysqr/.local/lib/python3.6/site-packages/rest_framework/views.py", line 492, in dispatch
    response = handler(request, *args, **kwargs)
  File "/var/www/html/mobilitysqrapi/mobility_apps/master/views/project.py", line 113, in post
    return Response(dict, status=status.HTTP_201_CREATED)
UnboundLocalError: local variable 'dict' referenced before assignment
ERROR|12/Nov/2020 17:54:03|basehttp|88817|140471235331840|"POST /get_update_project/ HTTP/1.1" 500 17150
