ERROR|02/Feb/2021 12:48:02|exception|14779|140376593700608|Invalid HTTP_HOST header: ''. The domain name provided is not valid according to RFC 1034/1035.
ERROR|02/Feb/2021 13:00:37|log|16491|140196745398016|Internal Server Error: /tax_grid_country_update/
Traceback (most recent call last):
  File "/home/mobilitysqr/.local/lib/python3.6/site-packages/django/db/backends/utils.py", line 83, in _execute
    return self.cursor.execute(sql)
  File "/home/mobilitysqr/.local/lib/python3.6/site-packages/sql_server/pyodbc/base.py", line 546, in execute
    return self.cursor.execute(sql, params)
pyodbc.ProgrammingError: ('42000', "[42000] [Microsoft][ODBC Driver 17 for SQL Server][SQL Server]Incorrect syntax near the keyword 'group'. (156) (SQLExecDirectW)")

The above exception was the direct cause of the following exception:

Traceback (most recent call last):
  File "/home/mobilitysqr/.local/lib/python3.6/site-packages/django/core/handlers/exception.py", line 34, in inner
    response = get_response(request)
  File "/home/mobilitysqr/.local/lib/python3.6/site-packages/django/core/handlers/base.py", line 126, in _get_response
    response = self.process_exception_by_middleware(e, request)
  File "/home/mobilitysqr/.local/lib/python3.6/site-packages/django/core/handlers/base.py", line 124, in _get_response
    response = wrapped_callback(request, *callback_args, **callback_kwargs)
  File "/home/mobilitysqr/.local/lib/python3.6/site-packages/django/views/decorators/csrf.py", line 54, in wrapped_view
    return view_func(*args, **kwargs)
  File "/home/mobilitysqr/.local/lib/python3.6/site-packages/django/views/generic/base.py", line 68, in view
    return self.dispatch(request, *args, **kwargs)
  File "/home/mobilitysqr/.local/lib/python3.6/site-packages/rest_framework/views.py", line 495, in dispatch
    response = self.handle_exception(exc)
  File "/home/mobilitysqr/.local/lib/python3.6/site-packages/rest_framework/views.py", line 455, in handle_exception
    self.raise_uncaught_exception(exc)
  File "/home/mobilitysqr/.local/lib/python3.6/site-packages/rest_framework/views.py", line 492, in dispatch
    response = handler(request, *args, **kwargs)
  File "/var/www/html/mobilitysqr_staging/mobility_apps/master/views/country.py", line 651, in post
    cursor.execute(sql)
  File "/home/mobilitysqr/.local/lib/python3.6/site-packages/django/db/backends/utils.py", line 100, in execute
    return super().execute(sql, params)
  File "/home/mobilitysqr/.local/lib/python3.6/site-packages/django/db/backends/utils.py", line 68, in execute
    return self._execute_with_wrappers(sql, params, many=False, executor=self._execute)
  File "/home/mobilitysqr/.local/lib/python3.6/site-packages/django/db/backends/utils.py", line 77, in _execute_with_wrappers
    return executor(sql, params, many, context)
  File "/home/mobilitysqr/.local/lib/python3.6/site-packages/django/db/backends/utils.py", line 85, in _execute
    return self.cursor.execute(sql, params)
  File "/home/mobilitysqr/.local/lib/python3.6/site-packages/django/db/utils.py", line 89, in __exit__
    raise dj_exc_value.with_traceback(traceback) from exc_value
  File "/home/mobilitysqr/.local/lib/python3.6/site-packages/django/db/backends/utils.py", line 83, in _execute
    return self.cursor.execute(sql)
  File "/home/mobilitysqr/.local/lib/python3.6/site-packages/sql_server/pyodbc/base.py", line 546, in execute
    return self.cursor.execute(sql, params)
django.db.utils.ProgrammingError: ('42000', "[42000] [Microsoft][ODBC Driver 17 for SQL Server][SQL Server]Incorrect syntax near the keyword 'group'. (156) (SQLExecDirectW)")
ERROR|02/Feb/2021 13:00:37|basehttp|16491|140196745398016|"POST /tax_grid_country_update/ HTTP/1.1" 500 18795
ERROR|02/Feb/2021 13:02:04|log|16654|139643028850432|Internal Server Error: /tax_grid_country_update/
Traceback (most recent call last):
  File "/home/mobilitysqr/.local/lib/python3.6/site-packages/django/db/backends/utils.py", line 83, in _execute
    return self.cursor.execute(sql)
  File "/home/mobilitysqr/.local/lib/python3.6/site-packages/sql_server/pyodbc/base.py", line 546, in execute
    return self.cursor.execute(sql, params)
pyodbc.ProgrammingError: ('42000', "[42000] [Microsoft][ODBC Driver 17 for SQL Server][SQL Server]Incorrect syntax near the keyword 'group'. (156) (SQLExecDirectW)")

The above exception was the direct cause of the following exception:

Traceback (most recent call last):
  File "/home/mobilitysqr/.local/lib/python3.6/site-packages/django/core/handlers/exception.py", line 34, in inner
    response = get_response(request)
  File "/home/mobilitysqr/.local/lib/python3.6/site-packages/django/core/handlers/base.py", line 126, in _get_response
    response = self.process_exception_by_middleware(e, request)
  File "/home/mobilitysqr/.local/lib/python3.6/site-packages/django/core/handlers/base.py", line 124, in _get_response
    response = wrapped_callback(request, *callback_args, **callback_kwargs)
  File "/home/mobilitysqr/.local/lib/python3.6/site-packages/django/views/decorators/csrf.py", line 54, in wrapped_view
    return view_func(*args, **kwargs)
  File "/home/mobilitysqr/.local/lib/python3.6/site-packages/django/views/generic/base.py", line 68, in view
    return self.dispatch(request, *args, **kwargs)
  File "/home/mobilitysqr/.local/lib/python3.6/site-packages/rest_framework/views.py", line 495, in dispatch
    response = self.handle_exception(exc)
  File "/home/mobilitysqr/.local/lib/python3.6/site-packages/rest_framework/views.py", line 455, in handle_exception
    self.raise_uncaught_exception(exc)
  File "/home/mobilitysqr/.local/lib/python3.6/site-packages/rest_framework/views.py", line 492, in dispatch
    response = handler(request, *args, **kwargs)
  File "/var/www/html/mobilitysqr_staging/mobility_apps/master/views/country.py", line 651, in post
    cursor.execute(sql)
  File "/home/mobilitysqr/.local/lib/python3.6/site-packages/django/db/backends/utils.py", line 100, in execute
    return super().execute(sql, params)
  File "/home/mobilitysqr/.local/lib/python3.6/site-packages/django/db/backends/utils.py", line 68, in execute
    return self._execute_with_wrappers(sql, params, many=False, executor=self._execute)
  File "/home/mobilitysqr/.local/lib/python3.6/site-packages/django/db/backends/utils.py", line 77, in _execute_with_wrappers
    return executor(sql, params, many, context)
  File "/home/mobilitysqr/.local/lib/python3.6/site-packages/django/db/backends/utils.py", line 85, in _execute
    return self.cursor.execute(sql, params)
  File "/home/mobilitysqr/.local/lib/python3.6/site-packages/django/db/utils.py", line 89, in __exit__
    raise dj_exc_value.with_traceback(traceback) from exc_value
  File "/home/mobilitysqr/.local/lib/python3.6/site-packages/django/db/backends/utils.py", line 83, in _execute
    return self.cursor.execute(sql)
  File "/home/mobilitysqr/.local/lib/python3.6/site-packages/sql_server/pyodbc/base.py", line 546, in execute
    return self.cursor.execute(sql, params)
django.db.utils.ProgrammingError: ('42000', "[42000] [Microsoft][ODBC Driver 17 for SQL Server][SQL Server]Incorrect syntax near the keyword 'group'. (156) (SQLExecDirectW)")
ERROR|02/Feb/2021 13:02:04|basehttp|16654|139643028850432|"POST /tax_grid_country_update/ HTTP/1.1" 500 18795
ERROR|02/Feb/2021 13:03:22|log|16745|140032534972160|Internal Server Error: /tax_grid_country_update/
Traceback (most recent call last):
  File "/home/mobilitysqr/.local/lib/python3.6/site-packages/django/db/backends/utils.py", line 83, in _execute
    return self.cursor.execute(sql)
  File "/home/mobilitysqr/.local/lib/python3.6/site-packages/sql_server/pyodbc/base.py", line 546, in execute
    return self.cursor.execute(sql, params)
pyodbc.ProgrammingError: ('42000', "[42000] [Microsoft][ODBC Driver 17 for SQL Server][SQL Server]Incorrect syntax near the keyword 'group'. (156) (SQLExecDirectW)")

The above exception was the direct cause of the following exception:

Traceback (most recent call last):
  File "/home/mobilitysqr/.local/lib/python3.6/site-packages/django/core/handlers/exception.py", line 34, in inner
    response = get_response(request)
  File "/home/mobilitysqr/.local/lib/python3.6/site-packages/django/core/handlers/base.py", line 126, in _get_response
    response = self.process_exception_by_middleware(e, request)
  File "/home/mobilitysqr/.local/lib/python3.6/site-packages/django/core/handlers/base.py", line 124, in _get_response
    response = wrapped_callback(request, *callback_args, **callback_kwargs)
  File "/home/mobilitysqr/.local/lib/python3.6/site-packages/django/views/decorators/csrf.py", line 54, in wrapped_view
    return view_func(*args, **kwargs)
  File "/home/mobilitysqr/.local/lib/python3.6/site-packages/django/views/generic/base.py", line 68, in view
    return self.dispatch(request, *args, **kwargs)
  File "/home/mobilitysqr/.local/lib/python3.6/site-packages/rest_framework/views.py", line 495, in dispatch
    response = self.handle_exception(exc)
  File "/home/mobilitysqr/.local/lib/python3.6/site-packages/rest_framework/views.py", line 455, in handle_exception
    self.raise_uncaught_exception(exc)
  File "/home/mobilitysqr/.local/lib/python3.6/site-packages/rest_framework/views.py", line 492, in dispatch
    response = handler(request, *args, **kwargs)
  File "/var/www/html/mobilitysqr_staging/mobility_apps/master/views/country.py", line 651, in post
    cursor.execute(sql)
  File "/home/mobilitysqr/.local/lib/python3.6/site-packages/django/db/backends/utils.py", line 100, in execute
    return super().execute(sql, params)
  File "/home/mobilitysqr/.local/lib/python3.6/site-packages/django/db/backends/utils.py", line 68, in execute
    return self._execute_with_wrappers(sql, params, many=False, executor=self._execute)
  File "/home/mobilitysqr/.local/lib/python3.6/site-packages/django/db/backends/utils.py", line 77, in _execute_with_wrappers
    return executor(sql, params, many, context)
  File "/home/mobilitysqr/.local/lib/python3.6/site-packages/django/db/backends/utils.py", line 85, in _execute
    return self.cursor.execute(sql, params)
  File "/home/mobilitysqr/.local/lib/python3.6/site-packages/django/db/utils.py", line 89, in __exit__
    raise dj_exc_value.with_traceback(traceback) from exc_value
  File "/home/mobilitysqr/.local/lib/python3.6/site-packages/django/db/backends/utils.py", line 83, in _execute
    return self.cursor.execute(sql)
  File "/home/mobilitysqr/.local/lib/python3.6/site-packages/sql_server/pyodbc/base.py", line 546, in execute
    return self.cursor.execute(sql, params)
django.db.utils.ProgrammingError: ('42000', "[42000] [Microsoft][ODBC Driver 17 for SQL Server][SQL Server]Incorrect syntax near the keyword 'group'. (156) (SQLExecDirectW)")
ERROR|02/Feb/2021 13:03:22|basehttp|16745|140032534972160|"POST /tax_grid_country_update/ HTTP/1.1" 500 18795
ERROR|02/Feb/2021 13:03:24|log|16745|140032534972160|Internal Server Error: /tax_grid_country_update/
Traceback (most recent call last):
  File "/home/mobilitysqr/.local/lib/python3.6/site-packages/django/db/backends/utils.py", line 83, in _execute
    return self.cursor.execute(sql)
  File "/home/mobilitysqr/.local/lib/python3.6/site-packages/sql_server/pyodbc/base.py", line 546, in execute
    return self.cursor.execute(sql, params)
pyodbc.ProgrammingError: ('42000', "[42000] [Microsoft][ODBC Driver 17 for SQL Server][SQL Server]Incorrect syntax near the keyword 'group'. (156) (SQLExecDirectW)")

The above exception was the direct cause of the following exception:

Traceback (most recent call last):
  File "/home/mobilitysqr/.local/lib/python3.6/site-packages/django/core/handlers/exception.py", line 34, in inner
    response = get_response(request)
  File "/home/mobilitysqr/.local/lib/python3.6/site-packages/django/core/handlers/base.py", line 126, in _get_response
    response = self.process_exception_by_middleware(e, request)
  File "/home/mobilitysqr/.local/lib/python3.6/site-packages/django/core/handlers/base.py", line 124, in _get_response
    response = wrapped_callback(request, *callback_args, **callback_kwargs)
  File "/home/mobilitysqr/.local/lib/python3.6/site-packages/django/views/decorators/csrf.py", line 54, in wrapped_view
    return view_func(*args, **kwargs)
  File "/home/mobilitysqr/.local/lib/python3.6/site-packages/django/views/generic/base.py", line 68, in view
    return self.dispatch(request, *args, **kwargs)
  File "/home/mobilitysqr/.local/lib/python3.6/site-packages/rest_framework/views.py", line 495, in dispatch
    response = self.handle_exception(exc)
  File "/home/mobilitysqr/.local/lib/python3.6/site-packages/rest_framework/views.py", line 455, in handle_exception
    self.raise_uncaught_exception(exc)
  File "/home/mobilitysqr/.local/lib/python3.6/site-packages/rest_framework/views.py", line 492, in dispatch
    response = handler(request, *args, **kwargs)
  File "/var/www/html/mobilitysqr_staging/mobility_apps/master/views/country.py", line 651, in post
    cursor.execute(sql)
  File "/home/mobilitysqr/.local/lib/python3.6/site-packages/django/db/backends/utils.py", line 100, in execute
    return super().execute(sql, params)
  File "/home/mobilitysqr/.local/lib/python3.6/site-packages/django/db/backends/utils.py", line 68, in execute
    return self._execute_with_wrappers(sql, params, many=False, executor=self._execute)
  File "/home/mobilitysqr/.local/lib/python3.6/site-packages/django/db/backends/utils.py", line 77, in _execute_with_wrappers
    return executor(sql, params, many, context)
  File "/home/mobilitysqr/.local/lib/python3.6/site-packages/django/db/backends/utils.py", line 85, in _execute
    return self.cursor.execute(sql, params)
  File "/home/mobilitysqr/.local/lib/python3.6/site-packages/django/db/utils.py", line 89, in __exit__
    raise dj_exc_value.with_traceback(traceback) from exc_value
  File "/home/mobilitysqr/.local/lib/python3.6/site-packages/django/db/backends/utils.py", line 83, in _execute
    return self.cursor.execute(sql)
  File "/home/mobilitysqr/.local/lib/python3.6/site-packages/sql_server/pyodbc/base.py", line 546, in execute
    return self.cursor.execute(sql, params)
django.db.utils.ProgrammingError: ('42000', "[42000] [Microsoft][ODBC Driver 17 for SQL Server][SQL Server]Incorrect syntax near the keyword 'group'. (156) (SQLExecDirectW)")
ERROR|02/Feb/2021 13:03:24|basehttp|16745|140032534972160|"POST /tax_grid_country_update/ HTTP/1.1" 500 18795
ERROR|02/Feb/2021 13:03:26|log|16745|140032534972160|Internal Server Error: /tax_grid_country_update/
Traceback (most recent call last):
  File "/home/mobilitysqr/.local/lib/python3.6/site-packages/django/db/backends/utils.py", line 83, in _execute
    return self.cursor.execute(sql)
  File "/home/mobilitysqr/.local/lib/python3.6/site-packages/sql_server/pyodbc/base.py", line 546, in execute
    return self.cursor.execute(sql, params)
pyodbc.ProgrammingError: ('42000', "[42000] [Microsoft][ODBC Driver 17 for SQL Server][SQL Server]Incorrect syntax near the keyword 'group'. (156) (SQLExecDirectW)")

The above exception was the direct cause of the following exception:

Traceback (most recent call last):
  File "/home/mobilitysqr/.local/lib/python3.6/site-packages/django/core/handlers/exception.py", line 34, in inner
    response = get_response(request)
  File "/home/mobilitysqr/.local/lib/python3.6/site-packages/django/core/handlers/base.py", line 126, in _get_response
    response = self.process_exception_by_middleware(e, request)
  File "/home/mobilitysqr/.local/lib/python3.6/site-packages/django/core/handlers/base.py", line 124, in _get_response
    response = wrapped_callback(request, *callback_args, **callback_kwargs)
  File "/home/mobilitysqr/.local/lib/python3.6/site-packages/django/views/decorators/csrf.py", line 54, in wrapped_view
    return view_func(*args, **kwargs)
  File "/home/mobilitysqr/.local/lib/python3.6/site-packages/django/views/generic/base.py", line 68, in view
    return self.dispatch(request, *args, **kwargs)
  File "/home/mobilitysqr/.local/lib/python3.6/site-packages/rest_framework/views.py", line 495, in dispatch
    response = self.handle_exception(exc)
  File "/home/mobilitysqr/.local/lib/python3.6/site-packages/rest_framework/views.py", line 455, in handle_exception
    self.raise_uncaught_exception(exc)
  File "/home/mobilitysqr/.local/lib/python3.6/site-packages/rest_framework/views.py", line 492, in dispatch
    response = handler(request, *args, **kwargs)
  File "/var/www/html/mobilitysqr_staging/mobility_apps/master/views/country.py", line 651, in post
    cursor.execute(sql)
  File "/home/mobilitysqr/.local/lib/python3.6/site-packages/django/db/backends/utils.py", line 100, in execute
    return super().execute(sql, params)
  File "/home/mobilitysqr/.local/lib/python3.6/site-packages/django/db/backends/utils.py", line 68, in execute
    return self._execute_with_wrappers(sql, params, many=False, executor=self._execute)
  File "/home/mobilitysqr/.local/lib/python3.6/site-packages/django/db/backends/utils.py", line 77, in _execute_with_wrappers
    return executor(sql, params, many, context)
  File "/home/mobilitysqr/.local/lib/python3.6/site-packages/django/db/backends/utils.py", line 85, in _execute
    return self.cursor.execute(sql, params)
  File "/home/mobilitysqr/.local/lib/python3.6/site-packages/django/db/utils.py", line 89, in __exit__
    raise dj_exc_value.with_traceback(traceback) from exc_value
  File "/home/mobilitysqr/.local/lib/python3.6/site-packages/django/db/backends/utils.py", line 83, in _execute
    return self.cursor.execute(sql)
  File "/home/mobilitysqr/.local/lib/python3.6/site-packages/sql_server/pyodbc/base.py", line 546, in execute
    return self.cursor.execute(sql, params)
django.db.utils.ProgrammingError: ('42000', "[42000] [Microsoft][ODBC Driver 17 for SQL Server][SQL Server]Incorrect syntax near the keyword 'group'. (156) (SQLExecDirectW)")
ERROR|02/Feb/2021 13:03:26|basehttp|16745|140032534972160|"POST /tax_grid_country_update/ HTTP/1.1" 500 18795
ERROR|02/Feb/2021 13:08:16|log|16956|140101182879488|Internal Server Error: /tax_grid_country_update/
Traceback (most recent call last):
  File "/home/mobilitysqr/.local/lib/python3.6/site-packages/django/db/backends/utils.py", line 83, in _execute
    return self.cursor.execute(sql)
  File "/home/mobilitysqr/.local/lib/python3.6/site-packages/sql_server/pyodbc/base.py", line 546, in execute
    return self.cursor.execute(sql, params)
pyodbc.ProgrammingError: ('42000', "[42000] [Microsoft][ODBC Driver 17 for SQL Server][SQL Server]Incorrect syntax near the keyword 'group'. (156) (SQLExecDirectW)")

The above exception was the direct cause of the following exception:

Traceback (most recent call last):
  File "/home/mobilitysqr/.local/lib/python3.6/site-packages/django/core/handlers/exception.py", line 34, in inner
    response = get_response(request)
  File "/home/mobilitysqr/.local/lib/python3.6/site-packages/django/core/handlers/base.py", line 126, in _get_response
    response = self.process_exception_by_middleware(e, request)
  File "/home/mobilitysqr/.local/lib/python3.6/site-packages/django/core/handlers/base.py", line 124, in _get_response
    response = wrapped_callback(request, *callback_args, **callback_kwargs)
  File "/home/mobilitysqr/.local/lib/python3.6/site-packages/django/views/decorators/csrf.py", line 54, in wrapped_view
    return view_func(*args, **kwargs)
  File "/home/mobilitysqr/.local/lib/python3.6/site-packages/django/views/generic/base.py", line 68, in view
    return self.dispatch(request, *args, **kwargs)
  File "/home/mobilitysqr/.local/lib/python3.6/site-packages/rest_framework/views.py", line 495, in dispatch
    response = self.handle_exception(exc)
  File "/home/mobilitysqr/.local/lib/python3.6/site-packages/rest_framework/views.py", line 455, in handle_exception
    self.raise_uncaught_exception(exc)
  File "/home/mobilitysqr/.local/lib/python3.6/site-packages/rest_framework/views.py", line 492, in dispatch
    response = handler(request, *args, **kwargs)
  File "/var/www/html/mobilitysqr_staging/mobility_apps/master/views/country.py", line 651, in post
    cursor.execute(sql)
  File "/home/mobilitysqr/.local/lib/python3.6/site-packages/django/db/backends/utils.py", line 100, in execute
    return super().execute(sql, params)
  File "/home/mobilitysqr/.local/lib/python3.6/site-packages/django/db/backends/utils.py", line 68, in execute
    return self._execute_with_wrappers(sql, params, many=False, executor=self._execute)
  File "/home/mobilitysqr/.local/lib/python3.6/site-packages/django/db/backends/utils.py", line 77, in _execute_with_wrappers
    return executor(sql, params, many, context)
  File "/home/mobilitysqr/.local/lib/python3.6/site-packages/django/db/backends/utils.py", line 85, in _execute
    return self.cursor.execute(sql, params)
  File "/home/mobilitysqr/.local/lib/python3.6/site-packages/django/db/utils.py", line 89, in __exit__
    raise dj_exc_value.with_traceback(traceback) from exc_value
  File "/home/mobilitysqr/.local/lib/python3.6/site-packages/django/db/backends/utils.py", line 83, in _execute
    return self.cursor.execute(sql)
  File "/home/mobilitysqr/.local/lib/python3.6/site-packages/sql_server/pyodbc/base.py", line 546, in execute
    return self.cursor.execute(sql, params)
django.db.utils.ProgrammingError: ('42000', "[42000] [Microsoft][ODBC Driver 17 for SQL Server][SQL Server]Incorrect syntax near the keyword 'group'. (156) (SQLExecDirectW)")
ERROR|02/Feb/2021 13:08:16|basehttp|16956|140101182879488|"POST /tax_grid_country_update/ HTTP/1.1" 500 18795
ERROR|02/Feb/2021 13:16:40|log|17412|140239230260992|Internal Server Error: /tax_grid_country_update/
Traceback (most recent call last):
  File "/home/mobilitysqr/.local/lib/python3.6/site-packages/django/db/backends/utils.py", line 83, in _execute
    return self.cursor.execute(sql)
  File "/home/mobilitysqr/.local/lib/python3.6/site-packages/sql_server/pyodbc/base.py", line 546, in execute
    return self.cursor.execute(sql, params)
pyodbc.ProgrammingError: ('42000', "[42000] [Microsoft][ODBC Driver 17 for SQL Server][SQL Server]Incorrect syntax near the keyword 'group'. (156) (SQLExecDirectW)")

The above exception was the direct cause of the following exception:

Traceback (most recent call last):
  File "/home/mobilitysqr/.local/lib/python3.6/site-packages/django/core/handlers/exception.py", line 34, in inner
    response = get_response(request)
  File "/home/mobilitysqr/.local/lib/python3.6/site-packages/django/core/handlers/base.py", line 126, in _get_response
    response = self.process_exception_by_middleware(e, request)
  File "/home/mobilitysqr/.local/lib/python3.6/site-packages/django/core/handlers/base.py", line 124, in _get_response
    response = wrapped_callback(request, *callback_args, **callback_kwargs)
  File "/home/mobilitysqr/.local/lib/python3.6/site-packages/django/views/decorators/csrf.py", line 54, in wrapped_view
    return view_func(*args, **kwargs)
  File "/home/mobilitysqr/.local/lib/python3.6/site-packages/django/views/generic/base.py", line 68, in view
    return self.dispatch(request, *args, **kwargs)
  File "/home/mobilitysqr/.local/lib/python3.6/site-packages/rest_framework/views.py", line 495, in dispatch
    response = self.handle_exception(exc)
  File "/home/mobilitysqr/.local/lib/python3.6/site-packages/rest_framework/views.py", line 455, in handle_exception
    self.raise_uncaught_exception(exc)
  File "/home/mobilitysqr/.local/lib/python3.6/site-packages/rest_framework/views.py", line 492, in dispatch
    response = handler(request, *args, **kwargs)
  File "/var/www/html/mobilitysqr_staging/mobility_apps/master/views/country.py", line 651, in post
    cursor.execute(sql)
  File "/home/mobilitysqr/.local/lib/python3.6/site-packages/django/db/backends/utils.py", line 100, in execute
    return super().execute(sql, params)
  File "/home/mobilitysqr/.local/lib/python3.6/site-packages/django/db/backends/utils.py", line 68, in execute
    return self._execute_with_wrappers(sql, params, many=False, executor=self._execute)
  File "/home/mobilitysqr/.local/lib/python3.6/site-packages/django/db/backends/utils.py", line 77, in _execute_with_wrappers
    return executor(sql, params, many, context)
  File "/home/mobilitysqr/.local/lib/python3.6/site-packages/django/db/backends/utils.py", line 85, in _execute
    return self.cursor.execute(sql, params)
  File "/home/mobilitysqr/.local/lib/python3.6/site-packages/django/db/utils.py", line 89, in __exit__
    raise dj_exc_value.with_traceback(traceback) from exc_value
  File "/home/mobilitysqr/.local/lib/python3.6/site-packages/django/db/backends/utils.py", line 83, in _execute
    return self.cursor.execute(sql)
  File "/home/mobilitysqr/.local/lib/python3.6/site-packages/sql_server/pyodbc/base.py", line 546, in execute
    return self.cursor.execute(sql, params)
django.db.utils.ProgrammingError: ('42000', "[42000] [Microsoft][ODBC Driver 17 for SQL Server][SQL Server]Incorrect syntax near the keyword 'group'. (156) (SQLExecDirectW)")
ERROR|02/Feb/2021 13:16:40|basehttp|17412|140239230260992|"POST /tax_grid_country_update/ HTTP/1.1" 500 18795
ERROR|02/Feb/2021 13:16:42|log|17412|140239230260992|Internal Server Error: /tax_grid_country_update/
Traceback (most recent call last):
  File "/home/mobilitysqr/.local/lib/python3.6/site-packages/django/db/backends/utils.py", line 83, in _execute
    return self.cursor.execute(sql)
  File "/home/mobilitysqr/.local/lib/python3.6/site-packages/sql_server/pyodbc/base.py", line 546, in execute
    return self.cursor.execute(sql, params)
pyodbc.ProgrammingError: ('42000', "[42000] [Microsoft][ODBC Driver 17 for SQL Server][SQL Server]Incorrect syntax near the keyword 'group'. (156) (SQLExecDirectW)")

The above exception was the direct cause of the following exception:

Traceback (most recent call last):
  File "/home/mobilitysqr/.local/lib/python3.6/site-packages/django/core/handlers/exception.py", line 34, in inner
    response = get_response(request)
  File "/home/mobilitysqr/.local/lib/python3.6/site-packages/django/core/handlers/base.py", line 126, in _get_response
    response = self.process_exception_by_middleware(e, request)
  File "/home/mobilitysqr/.local/lib/python3.6/site-packages/django/core/handlers/base.py", line 124, in _get_response
    response = wrapped_callback(request, *callback_args, **callback_kwargs)
  File "/home/mobilitysqr/.local/lib/python3.6/site-packages/django/views/decorators/csrf.py", line 54, in wrapped_view
    return view_func(*args, **kwargs)
  File "/home/mobilitysqr/.local/lib/python3.6/site-packages/django/views/generic/base.py", line 68, in view
    return self.dispatch(request, *args, **kwargs)
  File "/home/mobilitysqr/.local/lib/python3.6/site-packages/rest_framework/views.py", line 495, in dispatch
    response = self.handle_exception(exc)
  File "/home/mobilitysqr/.local/lib/python3.6/site-packages/rest_framework/views.py", line 455, in handle_exception
    self.raise_uncaught_exception(exc)
  File "/home/mobilitysqr/.local/lib/python3.6/site-packages/rest_framework/views.py", line 492, in dispatch
    response = handler(request, *args, **kwargs)
  File "/var/www/html/mobilitysqr_staging/mobility_apps/master/views/country.py", line 651, in post
    cursor.execute(sql)
  File "/home/mobilitysqr/.local/lib/python3.6/site-packages/django/db/backends/utils.py", line 100, in execute
    return super().execute(sql, params)
  File "/home/mobilitysqr/.local/lib/python3.6/site-packages/django/db/backends/utils.py", line 68, in execute
    return self._execute_with_wrappers(sql, params, many=False, executor=self._execute)
  File "/home/mobilitysqr/.local/lib/python3.6/site-packages/django/db/backends/utils.py", line 77, in _execute_with_wrappers
    return executor(sql, params, many, context)
  File "/home/mobilitysqr/.local/lib/python3.6/site-packages/django/db/backends/utils.py", line 85, in _execute
    return self.cursor.execute(sql, params)
  File "/home/mobilitysqr/.local/lib/python3.6/site-packages/django/db/utils.py", line 89, in __exit__
    raise dj_exc_value.with_traceback(traceback) from exc_value
  File "/home/mobilitysqr/.local/lib/python3.6/site-packages/django/db/backends/utils.py", line 83, in _execute
    return self.cursor.execute(sql)
  File "/home/mobilitysqr/.local/lib/python3.6/site-packages/sql_server/pyodbc/base.py", line 546, in execute
    return self.cursor.execute(sql, params)
django.db.utils.ProgrammingError: ('42000', "[42000] [Microsoft][ODBC Driver 17 for SQL Server][SQL Server]Incorrect syntax near the keyword 'group'. (156) (SQLExecDirectW)")
ERROR|02/Feb/2021 13:16:42|basehttp|17412|140239230260992|"POST /tax_grid_country_update/ HTTP/1.1" 500 18795
ERROR|02/Feb/2021 13:16:48|log|17412|140239230260992|Internal Server Error: /tax_grid_country_update/
Traceback (most recent call last):
  File "/home/mobilitysqr/.local/lib/python3.6/site-packages/django/db/backends/utils.py", line 83, in _execute
    return self.cursor.execute(sql)
  File "/home/mobilitysqr/.local/lib/python3.6/site-packages/sql_server/pyodbc/base.py", line 546, in execute
    return self.cursor.execute(sql, params)
pyodbc.ProgrammingError: ('42000', "[42000] [Microsoft][ODBC Driver 17 for SQL Server][SQL Server]Incorrect syntax near the keyword 'group'. (156) (SQLExecDirectW)")

The above exception was the direct cause of the following exception:

Traceback (most recent call last):
  File "/home/mobilitysqr/.local/lib/python3.6/site-packages/django/core/handlers/exception.py", line 34, in inner
    response = get_response(request)
  File "/home/mobilitysqr/.local/lib/python3.6/site-packages/django/core/handlers/base.py", line 126, in _get_response
    response = self.process_exception_by_middleware(e, request)
  File "/home/mobilitysqr/.local/lib/python3.6/site-packages/django/core/handlers/base.py", line 124, in _get_response
    response = wrapped_callback(request, *callback_args, **callback_kwargs)
  File "/home/mobilitysqr/.local/lib/python3.6/site-packages/django/views/decorators/csrf.py", line 54, in wrapped_view
    return view_func(*args, **kwargs)
  File "/home/mobilitysqr/.local/lib/python3.6/site-packages/django/views/generic/base.py", line 68, in view
    return self.dispatch(request, *args, **kwargs)
  File "/home/mobilitysqr/.local/lib/python3.6/site-packages/rest_framework/views.py", line 495, in dispatch
    response = self.handle_exception(exc)
  File "/home/mobilitysqr/.local/lib/python3.6/site-packages/rest_framework/views.py", line 455, in handle_exception
    self.raise_uncaught_exception(exc)
  File "/home/mobilitysqr/.local/lib/python3.6/site-packages/rest_framework/views.py", line 492, in dispatch
    response = handler(request, *args, **kwargs)
  File "/var/www/html/mobilitysqr_staging/mobility_apps/master/views/country.py", line 651, in post
    cursor.execute(sql)
  File "/home/mobilitysqr/.local/lib/python3.6/site-packages/django/db/backends/utils.py", line 100, in execute
    return super().execute(sql, params)
  File "/home/mobilitysqr/.local/lib/python3.6/site-packages/django/db/backends/utils.py", line 68, in execute
    return self._execute_with_wrappers(sql, params, many=False, executor=self._execute)
  File "/home/mobilitysqr/.local/lib/python3.6/site-packages/django/db/backends/utils.py", line 77, in _execute_with_wrappers
    return executor(sql, params, many, context)
  File "/home/mobilitysqr/.local/lib/python3.6/site-packages/django/db/backends/utils.py", line 85, in _execute
    return self.cursor.execute(sql, params)
  File "/home/mobilitysqr/.local/lib/python3.6/site-packages/django/db/utils.py", line 89, in __exit__
    raise dj_exc_value.with_traceback(traceback) from exc_value
  File "/home/mobilitysqr/.local/lib/python3.6/site-packages/django/db/backends/utils.py", line 83, in _execute
    return self.cursor.execute(sql)
  File "/home/mobilitysqr/.local/lib/python3.6/site-packages/sql_server/pyodbc/base.py", line 546, in execute
    return self.cursor.execute(sql, params)
django.db.utils.ProgrammingError: ('42000', "[42000] [Microsoft][ODBC Driver 17 for SQL Server][SQL Server]Incorrect syntax near the keyword 'group'. (156) (SQLExecDirectW)")
ERROR|02/Feb/2021 13:16:48|basehttp|17412|140239230260992|"POST /tax_grid_country_update/ HTTP/1.1" 500 18795
ERROR|02/Feb/2021 13:16:50|log|17412|140239230260992|Internal Server Error: /tax_grid_country_update/
Traceback (most recent call last):
  File "/home/mobilitysqr/.local/lib/python3.6/site-packages/django/db/backends/utils.py", line 83, in _execute
    return self.cursor.execute(sql)
  File "/home/mobilitysqr/.local/lib/python3.6/site-packages/sql_server/pyodbc/base.py", line 546, in execute
    return self.cursor.execute(sql, params)
pyodbc.ProgrammingError: ('42000', "[42000] [Microsoft][ODBC Driver 17 for SQL Server][SQL Server]Incorrect syntax near the keyword 'group'. (156) (SQLExecDirectW)")

The above exception was the direct cause of the following exception:

Traceback (most recent call last):
  File "/home/mobilitysqr/.local/lib/python3.6/site-packages/django/core/handlers/exception.py", line 34, in inner
    response = get_response(request)
  File "/home/mobilitysqr/.local/lib/python3.6/site-packages/django/core/handlers/base.py", line 126, in _get_response
    response = self.process_exception_by_middleware(e, request)
  File "/home/mobilitysqr/.local/lib/python3.6/site-packages/django/core/handlers/base.py", line 124, in _get_response
    response = wrapped_callback(request, *callback_args, **callback_kwargs)
  File "/home/mobilitysqr/.local/lib/python3.6/site-packages/django/views/decorators/csrf.py", line 54, in wrapped_view
    return view_func(*args, **kwargs)
  File "/home/mobilitysqr/.local/lib/python3.6/site-packages/django/views/generic/base.py", line 68, in view
    return self.dispatch(request, *args, **kwargs)
  File "/home/mobilitysqr/.local/lib/python3.6/site-packages/rest_framework/views.py", line 495, in dispatch
    response = self.handle_exception(exc)
  File "/home/mobilitysqr/.local/lib/python3.6/site-packages/rest_framework/views.py", line 455, in handle_exception
    self.raise_uncaught_exception(exc)
  File "/home/mobilitysqr/.local/lib/python3.6/site-packages/rest_framework/views.py", line 492, in dispatch
    response = handler(request, *args, **kwargs)
  File "/var/www/html/mobilitysqr_staging/mobility_apps/master/views/country.py", line 651, in post
    cursor.execute(sql)
  File "/home/mobilitysqr/.local/lib/python3.6/site-packages/django/db/backends/utils.py", line 100, in execute
    return super().execute(sql, params)
  File "/home/mobilitysqr/.local/lib/python3.6/site-packages/django/db/backends/utils.py", line 68, in execute
    return self._execute_with_wrappers(sql, params, many=False, executor=self._execute)
  File "/home/mobilitysqr/.local/lib/python3.6/site-packages/django/db/backends/utils.py", line 77, in _execute_with_wrappers
    return executor(sql, params, many, context)
  File "/home/mobilitysqr/.local/lib/python3.6/site-packages/django/db/backends/utils.py", line 85, in _execute
    return self.cursor.execute(sql, params)
  File "/home/mobilitysqr/.local/lib/python3.6/site-packages/django/db/utils.py", line 89, in __exit__
    raise dj_exc_value.with_traceback(traceback) from exc_value
  File "/home/mobilitysqr/.local/lib/python3.6/site-packages/django/db/backends/utils.py", line 83, in _execute
    return self.cursor.execute(sql)
  File "/home/mobilitysqr/.local/lib/python3.6/site-packages/sql_server/pyodbc/base.py", line 546, in execute
    return self.cursor.execute(sql, params)
django.db.utils.ProgrammingError: ('42000', "[42000] [Microsoft][ODBC Driver 17 for SQL Server][SQL Server]Incorrect syntax near the keyword 'group'. (156) (SQLExecDirectW)")
ERROR|02/Feb/2021 13:16:50|basehttp|17412|140239230260992|"POST /tax_grid_country_update/ HTTP/1.1" 500 18795
ERROR|02/Feb/2021 13:17:46|exception|17412|140239230260992|Invalid HTTP_HOST header: ''. The domain name provided is not valid according to RFC 1034/1035.
ERROR|02/Feb/2021 13:18:11|log|17545|140545567713024|Internal Server Error: /tax_grid_country_update/
Traceback (most recent call last):
  File "/home/mobilitysqr/.local/lib/python3.6/site-packages/django/db/backends/utils.py", line 83, in _execute
    return self.cursor.execute(sql)
  File "/home/mobilitysqr/.local/lib/python3.6/site-packages/sql_server/pyodbc/base.py", line 546, in execute
    return self.cursor.execute(sql, params)
pyodbc.ProgrammingError: ('42000', "[42000] [Microsoft][ODBC Driver 17 for SQL Server][SQL Server]Incorrect syntax near the keyword 'group'. (156) (SQLExecDirectW)")

The above exception was the direct cause of the following exception:

Traceback (most recent call last):
  File "/home/mobilitysqr/.local/lib/python3.6/site-packages/django/core/handlers/exception.py", line 34, in inner
    response = get_response(request)
  File "/home/mobilitysqr/.local/lib/python3.6/site-packages/django/core/handlers/base.py", line 126, in _get_response
    response = self.process_exception_by_middleware(e, request)
  File "/home/mobilitysqr/.local/lib/python3.6/site-packages/django/core/handlers/base.py", line 124, in _get_response
    response = wrapped_callback(request, *callback_args, **callback_kwargs)
  File "/home/mobilitysqr/.local/lib/python3.6/site-packages/django/views/decorators/csrf.py", line 54, in wrapped_view
    return view_func(*args, **kwargs)
  File "/home/mobilitysqr/.local/lib/python3.6/site-packages/django/views/generic/base.py", line 68, in view
    return self.dispatch(request, *args, **kwargs)
  File "/home/mobilitysqr/.local/lib/python3.6/site-packages/rest_framework/views.py", line 495, in dispatch
    response = self.handle_exception(exc)
  File "/home/mobilitysqr/.local/lib/python3.6/site-packages/rest_framework/views.py", line 455, in handle_exception
    self.raise_uncaught_exception(exc)
  File "/home/mobilitysqr/.local/lib/python3.6/site-packages/rest_framework/views.py", line 492, in dispatch
    response = handler(request, *args, **kwargs)
  File "/var/www/html/mobilitysqr_staging/mobility_apps/master/views/country.py", line 651, in post
    cursor.execute(sql)
  File "/home/mobilitysqr/.local/lib/python3.6/site-packages/django/db/backends/utils.py", line 100, in execute
    return super().execute(sql, params)
  File "/home/mobilitysqr/.local/lib/python3.6/site-packages/django/db/backends/utils.py", line 68, in execute
    return self._execute_with_wrappers(sql, params, many=False, executor=self._execute)
  File "/home/mobilitysqr/.local/lib/python3.6/site-packages/django/db/backends/utils.py", line 77, in _execute_with_wrappers
    return executor(sql, params, many, context)
  File "/home/mobilitysqr/.local/lib/python3.6/site-packages/django/db/backends/utils.py", line 85, in _execute
    return self.cursor.execute(sql, params)
  File "/home/mobilitysqr/.local/lib/python3.6/site-packages/django/db/utils.py", line 89, in __exit__
    raise dj_exc_value.with_traceback(traceback) from exc_value
  File "/home/mobilitysqr/.local/lib/python3.6/site-packages/django/db/backends/utils.py", line 83, in _execute
    return self.cursor.execute(sql)
  File "/home/mobilitysqr/.local/lib/python3.6/site-packages/sql_server/pyodbc/base.py", line 546, in execute
    return self.cursor.execute(sql, params)
django.db.utils.ProgrammingError: ('42000', "[42000] [Microsoft][ODBC Driver 17 for SQL Server][SQL Server]Incorrect syntax near the keyword 'group'. (156) (SQLExecDirectW)")
ERROR|02/Feb/2021 13:18:11|basehttp|17545|140545567713024|"POST /tax_grid_country_update/ HTTP/1.1" 500 18795
ERROR|02/Feb/2021 13:18:13|log|17545|140545567713024|Internal Server Error: /tax_grid_country_update/
Traceback (most recent call last):
  File "/home/mobilitysqr/.local/lib/python3.6/site-packages/django/db/backends/utils.py", line 83, in _execute
    return self.cursor.execute(sql)
  File "/home/mobilitysqr/.local/lib/python3.6/site-packages/sql_server/pyodbc/base.py", line 546, in execute
    return self.cursor.execute(sql, params)
pyodbc.ProgrammingError: ('42000', "[42000] [Microsoft][ODBC Driver 17 for SQL Server][SQL Server]Incorrect syntax near the keyword 'group'. (156) (SQLExecDirectW)")

The above exception was the direct cause of the following exception:

Traceback (most recent call last):
  File "/home/mobilitysqr/.local/lib/python3.6/site-packages/django/core/handlers/exception.py", line 34, in inner
    response = get_response(request)
  File "/home/mobilitysqr/.local/lib/python3.6/site-packages/django/core/handlers/base.py", line 126, in _get_response
    response = self.process_exception_by_middleware(e, request)
  File "/home/mobilitysqr/.local/lib/python3.6/site-packages/django/core/handlers/base.py", line 124, in _get_response
    response = wrapped_callback(request, *callback_args, **callback_kwargs)
  File "/home/mobilitysqr/.local/lib/python3.6/site-packages/django/views/decorators/csrf.py", line 54, in wrapped_view
    return view_func(*args, **kwargs)
  File "/home/mobilitysqr/.local/lib/python3.6/site-packages/django/views/generic/base.py", line 68, in view
    return self.dispatch(request, *args, **kwargs)
  File "/home/mobilitysqr/.local/lib/python3.6/site-packages/rest_framework/views.py", line 495, in dispatch
    response = self.handle_exception(exc)
  File "/home/mobilitysqr/.local/lib/python3.6/site-packages/rest_framework/views.py", line 455, in handle_exception
    self.raise_uncaught_exception(exc)
  File "/home/mobilitysqr/.local/lib/python3.6/site-packages/rest_framework/views.py", line 492, in dispatch
    response = handler(request, *args, **kwargs)
  File "/var/www/html/mobilitysqr_staging/mobility_apps/master/views/country.py", line 651, in post
    cursor.execute(sql)
  File "/home/mobilitysqr/.local/lib/python3.6/site-packages/django/db/backends/utils.py", line 100, in execute
    return super().execute(sql, params)
  File "/home/mobilitysqr/.local/lib/python3.6/site-packages/django/db/backends/utils.py", line 68, in execute
    return self._execute_with_wrappers(sql, params, many=False, executor=self._execute)
  File "/home/mobilitysqr/.local/lib/python3.6/site-packages/django/db/backends/utils.py", line 77, in _execute_with_wrappers
    return executor(sql, params, many, context)
  File "/home/mobilitysqr/.local/lib/python3.6/site-packages/django/db/backends/utils.py", line 85, in _execute
    return self.cursor.execute(sql, params)
  File "/home/mobilitysqr/.local/lib/python3.6/site-packages/django/db/utils.py", line 89, in __exit__
    raise dj_exc_value.with_traceback(traceback) from exc_value
  File "/home/mobilitysqr/.local/lib/python3.6/site-packages/django/db/backends/utils.py", line 83, in _execute
    return self.cursor.execute(sql)
  File "/home/mobilitysqr/.local/lib/python3.6/site-packages/sql_server/pyodbc/base.py", line 546, in execute
    return self.cursor.execute(sql, params)
django.db.utils.ProgrammingError: ('42000', "[42000] [Microsoft][ODBC Driver 17 for SQL Server][SQL Server]Incorrect syntax near the keyword 'group'. (156) (SQLExecDirectW)")
ERROR|02/Feb/2021 13:18:13|basehttp|17545|140545567713024|"POST /tax_grid_country_update/ HTTP/1.1" 500 18795
ERROR|02/Feb/2021 13:41:39|exception|17545|140545489893120|Invalid HTTP_HOST header: ''. The domain name provided is not valid according to RFC 1034/1035.
ERROR|02/Feb/2021 14:05:30|exception|17545|140545567713024|Invalid HTTP_HOST header: ''. The domain name provided is not valid according to RFC 1034/1035.
ERROR|02/Feb/2021 14:27:33|exception|17545|140545567713024|Invalid HTTP_HOST header: ''. The domain name provided is not valid according to RFC 1034/1035.
ERROR|02/Feb/2021 14:37:58|exception|17545|140545567713024|Invalid HTTP_HOST header: ''. The domain name provided is not valid according to RFC 1034/1035.
ERROR|02/Feb/2021 15:06:51|exception|17545|140545437177600|Invalid HTTP_HOST header: ''. The domain name provided is not valid according to RFC 1034/1035.
ERROR|02/Feb/2021 15:23:41|exception|17545|140545078847232|Invalid HTTP_HOST header: ''. The domain name provided is not valid according to RFC 1034/1035.
ERROR|02/Feb/2021 15:41:20|exception|17545|140545437177600|Invalid HTTP_HOST header: ''. The domain name provided is not valid according to RFC 1034/1035.
ERROR|02/Feb/2021 15:57:13|log|17545|140545461044992|Internal Server Error: /users
Traceback (most recent call last):
  File "/home/mobilitysqr/.local/lib/python3.6/site-packages/django/core/handlers/exception.py", line 34, in inner
    response = get_response(request)
  File "/home/mobilitysqr/.local/lib/python3.6/site-packages/django/utils/deprecation.py", line 90, in __call__
    response = self.process_request(request)
  File "/home/mobilitysqr/.local/lib/python3.6/site-packages/django/middleware/common.py", line 53, in process_request
    path = self.get_full_path_with_slash(request)
  File "/home/mobilitysqr/.local/lib/python3.6/site-packages/django/middleware/common.py", line 93, in get_full_path_with_slash
    'url': request.get_host() + new_path,
RuntimeError: You called this URL via POST, but the URL doesn't end in a slash and you have APPEND_SLASH set. Django can't redirect to the slash URL while maintaining POST data. Change your form to point to 52.165.220.40:8080/users/?page=&size=5 (note the trailing slash), or set APPEND_SLASH=False in your Django settings.
ERROR|02/Feb/2021 15:57:13|basehttp|17545|140545461044992|"POST /users?page=&size=5 HTTP/1.1" 500 65328
ERROR|02/Feb/2021 16:12:54|exception|17545|140545437177600|Invalid HTTP_HOST header: ''. The domain name provided is not valid according to RFC 1034/1035.
ERROR|02/Feb/2021 17:39:20|exception|17545|140545078847232|Invalid HTTP_HOST header: ''. The domain name provided is not valid according to RFC 1034/1035.
ERROR|02/Feb/2021 18:04:25|exception|17545|140545078847232|Invalid HTTP_HOST header: ''. The domain name provided is not valid according to RFC 1034/1035.
ERROR|02/Feb/2021 18:04:25|basehttp|17545|140545078847232|"GET /manager/html HTTP/1.1" 500 59
ERROR|02/Feb/2021 18:22:28|exception|17545|140545437177600|Invalid HTTP_HOST header: ''. The domain name provided is not valid according to RFC 1034/1035.
ERROR|02/Feb/2021 18:43:28|exception|17545|140545070454528|Invalid HTTP_HOST header: ''. The domain name provided is not valid according to RFC 1034/1035.
ERROR|02/Feb/2021 19:04:33|exception|17545|140545087239936|Invalid HTTP_HOST header: ''. The domain name provided is not valid according to RFC 1034/1035.
ERROR|02/Feb/2021 19:32:58|exception|17545|140545087239936|Invalid HTTP_HOST header: ''. The domain name provided is not valid according to RFC 1034/1035.
ERROR|02/Feb/2021 19:32:58|basehttp|17545|140545087239936|"GET /manager/html HTTP/1.1" 500 59
ERROR|02/Feb/2021 19:42:36|exception|17545|140545087239936|Invalid HTTP_HOST header: ''. The domain name provided is not valid according to RFC 1034/1035.
ERROR|02/Feb/2021 20:07:05|exception|17545|140545087239936|Invalid HTTP_HOST header: ''. The domain name provided is not valid according to RFC 1034/1035.
ERROR|02/Feb/2021 20:26:50|exception|17545|140545087239936|Invalid HTTP_HOST header: ''. The domain name provided is not valid according to RFC 1034/1035.
ERROR|02/Feb/2021 20:39:17|exception|17545|140545087239936|Invalid HTTP_HOST header: ''. The domain name provided is not valid according to RFC 1034/1035.
ERROR|02/Feb/2021 20:43:14|exception|17545|140545087239936|Invalid HTTP_HOST header: ''. The domain name provided is not valid according to RFC 1034/1035.
ERROR|02/Feb/2021 20:46:39|exception|17545|140545087239936|Invalid HTTP_HOST header: ''. The domain name provided is not valid according to RFC 1034/1035.
ERROR|02/Feb/2021 22:06:51|exception|17545|140545445570304|Invalid HTTP_HOST header: ''. The domain name provided is not valid according to RFC 1034/1035.
ERROR|02/Feb/2021 22:48:06|exception|17545|140545461044992|Invalid HTTP_HOST header: ''. The domain name provided is not valid according to RFC 1034/1035.
ERROR|02/Feb/2021 22:49:42|exception|17545|140545461044992|Invalid HTTP_HOST header: ''. The domain name provided is not valid according to RFC 1034/1035.
ERROR|02/Feb/2021 23:00:12|exception|17545|140545461044992|Invalid HTTP_HOST header: ''. The domain name provided is not valid according to RFC 1034/1035.
ERROR|02/Feb/2021 23:25:02|exception|17545|140545461044992|Invalid HTTP_HOST header: ''. The domain name provided is not valid according to RFC 1034/1035.
ERROR|02/Feb/2021 23:50:18|exception|17545|140545445570304|Invalid HTTP_HOST header: ''. The domain name provided is not valid according to RFC 1034/1035.
ERROR|03/Feb/2021 00:04:36|log|17545|140545445570304|Internal Server Error: /checkemployeeuser/
Traceback (most recent call last):
  File "/home/mobilitysqr/.local/lib/python3.6/site-packages/django/utils/datastructures.py", line 77, in __getitem__
    list_ = super().__getitem__(key)
KeyError: 'user_name'

During handling of the above exception, another exception occurred:

Traceback (most recent call last):
  File "/home/mobilitysqr/.local/lib/python3.6/site-packages/django/core/handlers/exception.py", line 34, in inner
    response = get_response(request)
  File "/home/mobilitysqr/.local/lib/python3.6/site-packages/django/core/handlers/base.py", line 126, in _get_response
    response = self.process_exception_by_middleware(e, request)
  File "/home/mobilitysqr/.local/lib/python3.6/site-packages/django/core/handlers/base.py", line 124, in _get_response
    response = wrapped_callback(request, *callback_args, **callback_kwargs)
  File "/home/mobilitysqr/.local/lib/python3.6/site-packages/django/views/decorators/csrf.py", line 54, in wrapped_view
    return view_func(*args, **kwargs)
  File "/home/mobilitysqr/.local/lib/python3.6/site-packages/django/views/generic/base.py", line 68, in view
    return self.dispatch(request, *args, **kwargs)
  File "/home/mobilitysqr/.local/lib/python3.6/site-packages/rest_framework/views.py", line 495, in dispatch
    response = self.handle_exception(exc)
  File "/home/mobilitysqr/.local/lib/python3.6/site-packages/rest_framework/views.py", line 455, in handle_exception
    self.raise_uncaught_exception(exc)
  File "/home/mobilitysqr/.local/lib/python3.6/site-packages/rest_framework/views.py", line 492, in dispatch
    response = handler(request, *args, **kwargs)
  File "/var/www/html/mobilitysqr_staging/mobility_apps/employee/views.py", line 1292, in get
    employees1 = Employee.objects.filter(user_name=request.GET['user_name'])
  File "/home/mobilitysqr/.local/lib/python3.6/site-packages/django/utils/datastructures.py", line 79, in __getitem__
    raise MultiValueDictKeyError(key)
django.utils.datastructures.MultiValueDictKeyError: 'user_name'
ERROR|03/Feb/2021 00:04:36|basehttp|17545|140545445570304|"GET /checkemployeeuser/ HTTP/1.1" 500 96562
ERROR|03/Feb/2021 00:14:06|exception|17545|140545445570304|Invalid HTTP_HOST header: ''. The domain name provided is not valid according to RFC 1034/1035.
ERROR|03/Feb/2021 00:17:05|exception|17545|140545445570304|Invalid HTTP_HOST header: ''. The domain name provided is not valid according to RFC 1034/1035.
ERROR|03/Feb/2021 00:26:19|exception|17545|140545437177600|Invalid HTTP_HOST header: ''. The domain name provided is not valid according to RFC 1034/1035.
ERROR|03/Feb/2021 00:26:19|basehttp|17545|140545437177600|"GET /script HTTP/1.1" 500 59
ERROR|03/Feb/2021 00:35:18|exception|17545|140545437177600|Invalid HTTP_HOST header: ''. The domain name provided is not valid according to RFC 1034/1035.
ERROR|03/Feb/2021 00:48:24|exception|17545|140545437177600|Invalid HTTP_HOST header: ''. The domain name provided is not valid according to RFC 1034/1035.
ERROR|03/Feb/2021 01:20:00|exception|17545|140545437177600|Invalid HTTP_HOST header: ''. The domain name provided is not valid according to RFC 1034/1035.
ERROR|03/Feb/2021 01:34:30|exception|17545|140545437177600|Invalid HTTP_HOST header: ''. The domain name provided is not valid according to RFC 1034/1035.
ERROR|03/Feb/2021 01:53:27|exception|17545|140545437177600|Invalid HTTP_HOST header: ''. The domain name provided is not valid according to RFC 1034/1035.
ERROR|03/Feb/2021 03:05:34|exception|17545|140545070454528|Invalid HTTP_HOST header: ''. The domain name provided is not valid according to RFC 1034/1035.
ERROR|03/Feb/2021 03:25:04|exception|17545|140545445570304|Invalid HTTP_HOST header: ''. The domain name provided is not valid according to RFC 1034/1035.
ERROR|03/Feb/2021 03:51:26|exception|17545|140545070454528|Invalid HTTP_HOST header: ''. The domain name provided is not valid according to RFC 1034/1035.
ERROR|03/Feb/2021 04:06:11|exception|17545|140545070454528|Invalid HTTP_HOST header: ''. The domain name provided is not valid according to RFC 1034/1035.
ERROR|03/Feb/2021 04:37:53|exception|17545|140545070454528|Invalid HTTP_HOST header: ''. The domain name provided is not valid according to RFC 1034/1035.
ERROR|03/Feb/2021 05:07:06|exception|17545|140545070454528|Invalid HTTP_HOST header: ''. The domain name provided is not valid according to RFC 1034/1035.
ERROR|03/Feb/2021 05:16:25|exception|17545|140545070454528|Invalid HTTP_HOST header: ''. The domain name provided is not valid according to RFC 1034/1035.
ERROR|03/Feb/2021 05:16:25|basehttp|17545|140545070454528|"GET /manager/html HTTP/1.1" 500 59
ERROR|03/Feb/2021 05:46:17|exception|17545|140545070454528|Invalid HTTP_HOST header: ''. The domain name provided is not valid according to RFC 1034/1035.
ERROR|03/Feb/2021 05:46:17|basehttp|17545|140545070454528|"GET /manager/html HTTP/1.1" 500 59
ERROR|03/Feb/2021 05:54:33|exception|17545|140545070454528|Invalid HTTP_HOST header: ''. The domain name provided is not valid according to RFC 1034/1035.
ERROR|03/Feb/2021 06:09:06|exception|17545|140545070454528|Invalid HTTP_HOST header: ''. The domain name provided is not valid according to RFC 1034/1035.
ERROR|03/Feb/2021 06:23:15|exception|17545|140545070454528|Invalid HTTP_HOST header: ''. The domain name provided is not valid according to RFC 1034/1035.
ERROR|03/Feb/2021 06:29:56|exception|17545|140545070454528|Invalid HTTP_HOST header: ''. The domain name provided is not valid according to RFC 1034/1035.
ERROR|03/Feb/2021 06:31:00|exception|17545|140545070454528|Invalid HTTP_HOST header: ''. The domain name provided is not valid according to RFC 1034/1035.
ERROR|03/Feb/2021 06:39:02|exception|17545|140545070454528|Invalid HTTP_HOST header: ''. The domain name provided is not valid according to RFC 1034/1035.
ERROR|03/Feb/2021 07:02:49|exception|17545|140545070454528|Invalid HTTP_HOST header: ''. The domain name provided is not valid according to RFC 1034/1035.
ERROR|03/Feb/2021 07:28:53|exception|17545|140545070454528|Invalid HTTP_HOST header: ''. The domain name provided is not valid according to RFC 1034/1035.
ERROR|03/Feb/2021 08:43:49|exception|17545|140545070454528|Invalid HTTP_HOST header: ''. The domain name provided is not valid according to RFC 1034/1035.
ERROR|03/Feb/2021 08:48:46|exception|17545|140545070454528|Invalid HTTP_HOST header: ''. The domain name provided is not valid according to RFC 1034/1035.
ERROR|03/Feb/2021 09:24:36|exception|17545|140545070454528|Invalid HTTP_HOST header: ''. The domain name provided is not valid according to RFC 1034/1035.
ERROR|03/Feb/2021 09:32:51|exception|17545|140545070454528|Invalid HTTP_HOST header: ''. The domain name provided is not valid according to RFC 1034/1035.
ERROR|03/Feb/2021 10:05:33|exception|17545|140545070454528|Invalid HTTP_HOST header: ''. The domain name provided is not valid according to RFC 1034/1035.
ERROR|03/Feb/2021 10:05:33|basehttp|17545|140545070454528|"GET /manager/html HTTP/1.1" 500 59
ERROR|03/Feb/2021 10:23:28|exception|17545|140545070454528|Invalid HTTP_HOST header: ''. The domain name provided is not valid according to RFC 1034/1035.
ERROR|03/Feb/2021 10:57:33|exception|17545|140545087239936|Invalid HTTP_HOST header: ''. The domain name provided is not valid according to RFC 1034/1035.
ERROR|03/Feb/2021 10:59:52|exception|17545|140545437177600|Invalid HTTP_HOST header: ''. The domain name provided is not valid according to RFC 1034/1035.
ERROR|03/Feb/2021 11:32:49|exception|17545|140545461044992|Invalid HTTP_HOST header: ''. The domain name provided is not valid according to RFC 1034/1035.
ERROR|03/Feb/2021 11:37:14|exception|17545|140545045276416|Invalid HTTP_HOST header: ''. The domain name provided is not valid according to RFC 1034/1035.
ERROR|03/Feb/2021 11:37:14|basehttp|17545|140545045276416|"GET /manager/html HTTP/1.1" 500 59
ERROR|03/Feb/2021 11:49:59|exception|17545|140545070454528|Invalid HTTP_HOST header: ''. The domain name provided is not valid according to RFC 1034/1035.
ERROR|03/Feb/2021 12:10:43|exception|17545|140545461044992|Invalid HTTP_HOST header: ''. The domain name provided is not valid according to RFC 1034/1035.
