ERROR|22/Dec/2020 11:35:17|log|13813|139627029587712|Internal Server Error: /get_add/employee_emails/
Traceback (most recent call last):
  File "/home/mobilitysqr/.local/lib/python3.6/site-packages/django/core/handlers/exception.py", line 34, in inner
    response = get_response(request)
  File "/home/mobilitysqr/.local/lib/python3.6/site-packages/django/core/handlers/base.py", line 126, in _get_response
    response = self.process_exception_by_middleware(e, request)
  File "/home/mobilitysqr/.local/lib/python3.6/site-packages/django/core/handlers/base.py", line 124, in _get_response
    response = wrapped_callback(request, *callback_args, **callback_kwargs)
  File "/home/mobilitysqr/.local/lib/python3.6/site-packages/django/views/decorators/csrf.py", line 54, in wrapped_view
    return view_func(*args, **kwargs)
  File "/home/mobilitysqr/.local/lib/python3.6/site-packages/django/views/generic/base.py", line 68, in view
    return self.dispatch(request, *args, **kwargs)
  File "/home/mobilitysqr/.local/lib/python3.6/site-packages/rest_framework/views.py", line 495, in dispatch
    response = self.handle_exception(exc)
  File "/home/mobilitysqr/.local/lib/python3.6/site-packages/rest_framework/views.py", line 455, in handle_exception
    self.raise_uncaught_exception(exc)
  File "/home/mobilitysqr/.local/lib/python3.6/site-packages/rest_framework/views.py", line 492, in dispatch
    response = handler(request, *args, **kwargs)
  File "/var/www/html/mobilitysqrapi/mobility_apps/employee/views.py", line 640, in post
    sql ="UPDATE employee_employee SET email="+empdata['email_type']+" WHERE emp_code="+empdata['email_code']
KeyError: 'email_code'
ERROR|22/Dec/2020 11:35:17|basehttp|13813|139627029587712|"POST /get_add/employee_emails/ HTTP/1.1" 500 17310
ERROR|22/Dec/2020 11:36:38|log|13873|140536123172608|Internal Server Error: /get_add/employee_emails/
Traceback (most recent call last):
  File "/home/mobilitysqr/.local/lib/python3.6/site-packages/django/db/backends/utils.py", line 83, in _execute
    return self.cursor.execute(sql)
  File "/home/mobilitysqr/.local/lib/python3.6/site-packages/sql_server/pyodbc/base.py", line 546, in execute
    return self.cursor.execute(sql, params)
pyodbc.ProgrammingError: ('42S22', "[42S22] [Microsoft][ODBC Driver 17 for SQL Server][SQL Server]Invalid column name 'nitesh002'. (207) (SQLExecDirectW)")

The above exception was the direct cause of the following exception:

Traceback (most recent call last):
  File "/home/mobilitysqr/.local/lib/python3.6/site-packages/django/core/handlers/exception.py", line 34, in inner
    response = get_response(request)
  File "/home/mobilitysqr/.local/lib/python3.6/site-packages/django/core/handlers/base.py", line 126, in _get_response
    response = self.process_exception_by_middleware(e, request)
  File "/home/mobilitysqr/.local/lib/python3.6/site-packages/django/core/handlers/base.py", line 124, in _get_response
    response = wrapped_callback(request, *callback_args, **callback_kwargs)
  File "/home/mobilitysqr/.local/lib/python3.6/site-packages/django/views/decorators/csrf.py", line 54, in wrapped_view
    return view_func(*args, **kwargs)
  File "/home/mobilitysqr/.local/lib/python3.6/site-packages/django/views/generic/base.py", line 68, in view
    return self.dispatch(request, *args, **kwargs)
  File "/home/mobilitysqr/.local/lib/python3.6/site-packages/rest_framework/views.py", line 495, in dispatch
    response = self.handle_exception(exc)
  File "/home/mobilitysqr/.local/lib/python3.6/site-packages/rest_framework/views.py", line 455, in handle_exception
    self.raise_uncaught_exception(exc)
  File "/home/mobilitysqr/.local/lib/python3.6/site-packages/rest_framework/views.py", line 492, in dispatch
    response = handler(request, *args, **kwargs)
  File "/var/www/html/mobilitysqrapi/mobility_apps/employee/views.py", line 641, in post
    cursor.execute(sql)
  File "/home/mobilitysqr/.local/lib/python3.6/site-packages/django/db/backends/utils.py", line 100, in execute
    return super().execute(sql, params)
  File "/home/mobilitysqr/.local/lib/python3.6/site-packages/django/db/backends/utils.py", line 68, in execute
    return self._execute_with_wrappers(sql, params, many=False, executor=self._execute)
  File "/home/mobilitysqr/.local/lib/python3.6/site-packages/django/db/backends/utils.py", line 77, in _execute_with_wrappers
    return executor(sql, params, many, context)
  File "/home/mobilitysqr/.local/lib/python3.6/site-packages/django/db/backends/utils.py", line 85, in _execute
    return self.cursor.execute(sql, params)
  File "/home/mobilitysqr/.local/lib/python3.6/site-packages/django/db/utils.py", line 89, in __exit__
    raise dj_exc_value.with_traceback(traceback) from exc_value
  File "/home/mobilitysqr/.local/lib/python3.6/site-packages/django/db/backends/utils.py", line 83, in _execute
    return self.cursor.execute(sql)
  File "/home/mobilitysqr/.local/lib/python3.6/site-packages/sql_server/pyodbc/base.py", line 546, in execute
    return self.cursor.execute(sql, params)
django.db.utils.ProgrammingError: ('42S22', "[42S22] [Microsoft][ODBC Driver 17 for SQL Server][SQL Server]Invalid column name 'nitesh002'. (207) (SQLExecDirectW)")
ERROR|22/Dec/2020 11:36:38|basehttp|13873|140536123172608|"POST /get_add/employee_emails/ HTTP/1.1" 500 19166
ERROR|22/Dec/2020 11:37:37|log|14091|140235493521152|Internal Server Error: /get_add/employee_emails/
Traceback (most recent call last):
  File "/home/mobilitysqr/.local/lib/python3.6/site-packages/django/db/backends/utils.py", line 83, in _execute
    return self.cursor.execute(sql)
  File "/home/mobilitysqr/.local/lib/python3.6/site-packages/sql_server/pyodbc/base.py", line 546, in execute
    return self.cursor.execute(sql, params)
pyodbc.ProgrammingError: ('42S22', "[42S22] [Microsoft][ODBC Driver 17 for SQL Server][SQL Server]Invalid column name 'nitesh002'. (207) (SQLExecDirectW)")

The above exception was the direct cause of the following exception:

Traceback (most recent call last):
  File "/home/mobilitysqr/.local/lib/python3.6/site-packages/django/core/handlers/exception.py", line 34, in inner
    response = get_response(request)
  File "/home/mobilitysqr/.local/lib/python3.6/site-packages/django/core/handlers/base.py", line 126, in _get_response
    response = self.process_exception_by_middleware(e, request)
  File "/home/mobilitysqr/.local/lib/python3.6/site-packages/django/core/handlers/base.py", line 124, in _get_response
    response = wrapped_callback(request, *callback_args, **callback_kwargs)
  File "/home/mobilitysqr/.local/lib/python3.6/site-packages/django/views/decorators/csrf.py", line 54, in wrapped_view
    return view_func(*args, **kwargs)
  File "/home/mobilitysqr/.local/lib/python3.6/site-packages/django/views/generic/base.py", line 68, in view
    return self.dispatch(request, *args, **kwargs)
  File "/home/mobilitysqr/.local/lib/python3.6/site-packages/rest_framework/views.py", line 495, in dispatch
    response = self.handle_exception(exc)
  File "/home/mobilitysqr/.local/lib/python3.6/site-packages/rest_framework/views.py", line 455, in handle_exception
    self.raise_uncaught_exception(exc)
  File "/home/mobilitysqr/.local/lib/python3.6/site-packages/rest_framework/views.py", line 492, in dispatch
    response = handler(request, *args, **kwargs)
  File "/var/www/html/mobilitysqrapi/mobility_apps/employee/views.py", line 641, in post
    cursor.execute(sql)
  File "/home/mobilitysqr/.local/lib/python3.6/site-packages/django/db/backends/utils.py", line 100, in execute
    return super().execute(sql, params)
  File "/home/mobilitysqr/.local/lib/python3.6/site-packages/django/db/backends/utils.py", line 68, in execute
    return self._execute_with_wrappers(sql, params, many=False, executor=self._execute)
  File "/home/mobilitysqr/.local/lib/python3.6/site-packages/django/db/backends/utils.py", line 77, in _execute_with_wrappers
    return executor(sql, params, many, context)
  File "/home/mobilitysqr/.local/lib/python3.6/site-packages/django/db/backends/utils.py", line 85, in _execute
    return self.cursor.execute(sql, params)
  File "/home/mobilitysqr/.local/lib/python3.6/site-packages/django/db/utils.py", line 89, in __exit__
    raise dj_exc_value.with_traceback(traceback) from exc_value
  File "/home/mobilitysqr/.local/lib/python3.6/site-packages/django/db/backends/utils.py", line 83, in _execute
    return self.cursor.execute(sql)
  File "/home/mobilitysqr/.local/lib/python3.6/site-packages/sql_server/pyodbc/base.py", line 546, in execute
    return self.cursor.execute(sql, params)
django.db.utils.ProgrammingError: ('42S22', "[42S22] [Microsoft][ODBC Driver 17 for SQL Server][SQL Server]Invalid column name 'nitesh002'. (207) (SQLExecDirectW)")
ERROR|22/Dec/2020 11:37:37|basehttp|14091|140235493521152|"POST /get_add/employee_emails/ HTTP/1.1" 500 19166
ERROR|22/Dec/2020 11:38:18|log|14116|140483042281216|Internal Server Error: /get_add/employee_emails/
Traceback (most recent call last):
  File "/home/mobilitysqr/.local/lib/python3.6/site-packages/django/db/backends/utils.py", line 83, in _execute
    return self.cursor.execute(sql)
  File "/home/mobilitysqr/.local/lib/python3.6/site-packages/sql_server/pyodbc/base.py", line 546, in execute
    return self.cursor.execute(sql, params)
pyodbc.ProgrammingError: ('42S22', "[42S22] [Microsoft][ODBC Driver 17 for SQL Server][SQL Server]Invalid column name 'nitesh002'. (207) (SQLExecDirectW)")

The above exception was the direct cause of the following exception:

Traceback (most recent call last):
  File "/home/mobilitysqr/.local/lib/python3.6/site-packages/django/core/handlers/exception.py", line 34, in inner
    response = get_response(request)
  File "/home/mobilitysqr/.local/lib/python3.6/site-packages/django/core/handlers/base.py", line 126, in _get_response
    response = self.process_exception_by_middleware(e, request)
  File "/home/mobilitysqr/.local/lib/python3.6/site-packages/django/core/handlers/base.py", line 124, in _get_response
    response = wrapped_callback(request, *callback_args, **callback_kwargs)
  File "/home/mobilitysqr/.local/lib/python3.6/site-packages/django/views/decorators/csrf.py", line 54, in wrapped_view
    return view_func(*args, **kwargs)
  File "/home/mobilitysqr/.local/lib/python3.6/site-packages/django/views/generic/base.py", line 68, in view
    return self.dispatch(request, *args, **kwargs)
  File "/home/mobilitysqr/.local/lib/python3.6/site-packages/rest_framework/views.py", line 495, in dispatch
    response = self.handle_exception(exc)
  File "/home/mobilitysqr/.local/lib/python3.6/site-packages/rest_framework/views.py", line 455, in handle_exception
    self.raise_uncaught_exception(exc)
  File "/home/mobilitysqr/.local/lib/python3.6/site-packages/rest_framework/views.py", line 492, in dispatch
    response = handler(request, *args, **kwargs)
  File "/var/www/html/mobilitysqrapi/mobility_apps/employee/views.py", line 642, in post
    cursor.execute(sql)
  File "/home/mobilitysqr/.local/lib/python3.6/site-packages/django/db/backends/utils.py", line 100, in execute
    return super().execute(sql, params)
  File "/home/mobilitysqr/.local/lib/python3.6/site-packages/django/db/backends/utils.py", line 68, in execute
    return self._execute_with_wrappers(sql, params, many=False, executor=self._execute)
  File "/home/mobilitysqr/.local/lib/python3.6/site-packages/django/db/backends/utils.py", line 77, in _execute_with_wrappers
    return executor(sql, params, many, context)
  File "/home/mobilitysqr/.local/lib/python3.6/site-packages/django/db/backends/utils.py", line 85, in _execute
    return self.cursor.execute(sql, params)
  File "/home/mobilitysqr/.local/lib/python3.6/site-packages/django/db/utils.py", line 89, in __exit__
    raise dj_exc_value.with_traceback(traceback) from exc_value
  File "/home/mobilitysqr/.local/lib/python3.6/site-packages/django/db/backends/utils.py", line 83, in _execute
    return self.cursor.execute(sql)
  File "/home/mobilitysqr/.local/lib/python3.6/site-packages/sql_server/pyodbc/base.py", line 546, in execute
    return self.cursor.execute(sql, params)
django.db.utils.ProgrammingError: ('42S22', "[42S22] [Microsoft][ODBC Driver 17 for SQL Server][SQL Server]Invalid column name 'nitesh002'. (207) (SQLExecDirectW)")
ERROR|22/Dec/2020 11:38:18|basehttp|14116|140483042281216|"POST /get_add/employee_emails/ HTTP/1.1" 500 19166
ERROR|22/Dec/2020 11:40:03|log|14116|140483042281216|Internal Server Error: /get_add/employee_emails/
Traceback (most recent call last):
  File "/home/mobilitysqr/.local/lib/python3.6/site-packages/django/db/backends/utils.py", line 83, in _execute
    return self.cursor.execute(sql)
  File "/home/mobilitysqr/.local/lib/python3.6/site-packages/sql_server/pyodbc/base.py", line 546, in execute
    return self.cursor.execute(sql, params)
pyodbc.ProgrammingError: ('42S22', "[42S22] [Microsoft][ODBC Driver 17 for SQL Server][SQL Server]Invalid column name 'nitesh002'. (207) (SQLExecDirectW)")

The above exception was the direct cause of the following exception:

Traceback (most recent call last):
  File "/home/mobilitysqr/.local/lib/python3.6/site-packages/django/core/handlers/exception.py", line 34, in inner
    response = get_response(request)
  File "/home/mobilitysqr/.local/lib/python3.6/site-packages/django/core/handlers/base.py", line 126, in _get_response
    response = self.process_exception_by_middleware(e, request)
  File "/home/mobilitysqr/.local/lib/python3.6/site-packages/django/core/handlers/base.py", line 124, in _get_response
    response = wrapped_callback(request, *callback_args, **callback_kwargs)
  File "/home/mobilitysqr/.local/lib/python3.6/site-packages/django/views/decorators/csrf.py", line 54, in wrapped_view
    return view_func(*args, **kwargs)
  File "/home/mobilitysqr/.local/lib/python3.6/site-packages/django/views/generic/base.py", line 68, in view
    return self.dispatch(request, *args, **kwargs)
  File "/home/mobilitysqr/.local/lib/python3.6/site-packages/rest_framework/views.py", line 495, in dispatch
    response = self.handle_exception(exc)
  File "/home/mobilitysqr/.local/lib/python3.6/site-packages/rest_framework/views.py", line 455, in handle_exception
    self.raise_uncaught_exception(exc)
  File "/home/mobilitysqr/.local/lib/python3.6/site-packages/rest_framework/views.py", line 492, in dispatch
    response = handler(request, *args, **kwargs)
  File "/var/www/html/mobilitysqrapi/mobility_apps/employee/views.py", line 642, in post
    cursor.execute(sql)
  File "/home/mobilitysqr/.local/lib/python3.6/site-packages/django/db/backends/utils.py", line 100, in execute
    return super().execute(sql, params)
  File "/home/mobilitysqr/.local/lib/python3.6/site-packages/django/db/backends/utils.py", line 68, in execute
    return self._execute_with_wrappers(sql, params, many=False, executor=self._execute)
  File "/home/mobilitysqr/.local/lib/python3.6/site-packages/django/db/backends/utils.py", line 77, in _execute_with_wrappers
    return executor(sql, params, many, context)
  File "/home/mobilitysqr/.local/lib/python3.6/site-packages/django/db/backends/utils.py", line 85, in _execute
    return self.cursor.execute(sql, params)
  File "/home/mobilitysqr/.local/lib/python3.6/site-packages/django/db/utils.py", line 89, in __exit__
    raise dj_exc_value.with_traceback(traceback) from exc_value
  File "/home/mobilitysqr/.local/lib/python3.6/site-packages/django/db/backends/utils.py", line 83, in _execute
    return self.cursor.execute(sql)
  File "/home/mobilitysqr/.local/lib/python3.6/site-packages/sql_server/pyodbc/base.py", line 546, in execute
    return self.cursor.execute(sql, params)
django.db.utils.ProgrammingError: ('42S22', "[42S22] [Microsoft][ODBC Driver 17 for SQL Server][SQL Server]Invalid column name 'nitesh002'. (207) (SQLExecDirectW)")
ERROR|22/Dec/2020 11:40:03|basehttp|14116|140483042281216|"POST /get_add/employee_emails/ HTTP/1.1" 500 19166
ERROR|22/Dec/2020 12:04:39|log|16314|139718679115520|Internal Server Error: /get_add/employee/
Traceback (most recent call last):
  File "/home/mobilitysqr/.local/lib/python3.6/site-packages/django/core/handlers/exception.py", line 34, in inner
    response = get_response(request)
  File "/home/mobilitysqr/.local/lib/python3.6/site-packages/django/core/handlers/base.py", line 126, in _get_response
    response = self.process_exception_by_middleware(e, request)
  File "/home/mobilitysqr/.local/lib/python3.6/site-packages/django/core/handlers/base.py", line 124, in _get_response
    response = wrapped_callback(request, *callback_args, **callback_kwargs)
  File "/home/mobilitysqr/.local/lib/python3.6/site-packages/django/views/decorators/csrf.py", line 54, in wrapped_view
    return view_func(*args, **kwargs)
  File "/home/mobilitysqr/.local/lib/python3.6/site-packages/django/views/generic/base.py", line 68, in view
    return self.dispatch(request, *args, **kwargs)
  File "/home/mobilitysqr/.local/lib/python3.6/site-packages/rest_framework/views.py", line 495, in dispatch
    response = self.handle_exception(exc)
  File "/home/mobilitysqr/.local/lib/python3.6/site-packages/rest_framework/views.py", line 455, in handle_exception
    self.raise_uncaught_exception(exc)
  File "/home/mobilitysqr/.local/lib/python3.6/site-packages/rest_framework/views.py", line 492, in dispatch
    response = handler(request, *args, **kwargs)
  File "/var/www/html/mobilitysqrapi/mobility_apps/employee/views.py", line 448, in post
    sqlemails ="UPDATE employee_employee_emails SET email_address='"+request.data['email']+"' WHERE id='"+businessemail[0]['id']+"'"
TypeError: must be str, not int
ERROR|22/Dec/2020 12:04:39|basehttp|16314|139718679115520|"POST /get_add/employee/ HTTP/1.1" 500 17323
ERROR|22/Dec/2020 12:05:11|log|16337|140017695917824|Internal Server Error: /get_add/employee/
Traceback (most recent call last):
  File "/home/mobilitysqr/.local/lib/python3.6/site-packages/django/core/handlers/exception.py", line 34, in inner
    response = get_response(request)
  File "/home/mobilitysqr/.local/lib/python3.6/site-packages/django/core/handlers/base.py", line 126, in _get_response
    response = self.process_exception_by_middleware(e, request)
  File "/home/mobilitysqr/.local/lib/python3.6/site-packages/django/core/handlers/base.py", line 124, in _get_response
    response = wrapped_callback(request, *callback_args, **callback_kwargs)
  File "/home/mobilitysqr/.local/lib/python3.6/site-packages/django/views/decorators/csrf.py", line 54, in wrapped_view
    return view_func(*args, **kwargs)
  File "/home/mobilitysqr/.local/lib/python3.6/site-packages/django/views/generic/base.py", line 68, in view
    return self.dispatch(request, *args, **kwargs)
  File "/home/mobilitysqr/.local/lib/python3.6/site-packages/rest_framework/views.py", line 495, in dispatch
    response = self.handle_exception(exc)
  File "/home/mobilitysqr/.local/lib/python3.6/site-packages/rest_framework/views.py", line 455, in handle_exception
    self.raise_uncaught_exception(exc)
  File "/home/mobilitysqr/.local/lib/python3.6/site-packages/rest_framework/views.py", line 492, in dispatch
    response = handler(request, *args, **kwargs)
  File "/var/www/html/mobilitysqrapi/mobility_apps/employee/views.py", line 448, in post
    sqlemails ="UPDATE employee_employee_emails SET email_address='"+request.data['email']+"' WHERE id='"+businessemail[0]['id']+"'"
TypeError: must be str, not int
ERROR|22/Dec/2020 12:05:11|basehttp|16337|140017695917824|"POST /get_add/employee/ HTTP/1.1" 500 17323
ERROR|22/Dec/2020 12:07:58|log|16446|139972804667136|Internal Server Error: /get_add/employee/
Traceback (most recent call last):
  File "/home/mobilitysqr/.local/lib/python3.6/site-packages/django/core/handlers/exception.py", line 34, in inner
    response = get_response(request)
  File "/home/mobilitysqr/.local/lib/python3.6/site-packages/django/core/handlers/base.py", line 126, in _get_response
    response = self.process_exception_by_middleware(e, request)
  File "/home/mobilitysqr/.local/lib/python3.6/site-packages/django/core/handlers/base.py", line 124, in _get_response
    response = wrapped_callback(request, *callback_args, **callback_kwargs)
  File "/home/mobilitysqr/.local/lib/python3.6/site-packages/django/views/decorators/csrf.py", line 54, in wrapped_view
    return view_func(*args, **kwargs)
  File "/home/mobilitysqr/.local/lib/python3.6/site-packages/django/views/generic/base.py", line 68, in view
    return self.dispatch(request, *args, **kwargs)
  File "/home/mobilitysqr/.local/lib/python3.6/site-packages/rest_framework/views.py", line 495, in dispatch
    response = self.handle_exception(exc)
  File "/home/mobilitysqr/.local/lib/python3.6/site-packages/rest_framework/views.py", line 455, in handle_exception
    self.raise_uncaught_exception(exc)
  File "/home/mobilitysqr/.local/lib/python3.6/site-packages/rest_framework/views.py", line 492, in dispatch
    response = handler(request, *args, **kwargs)
  File "/var/www/html/mobilitysqrapi/mobility_apps/employee/views.py", line 448, in post
    sqlemails ="UPDATE employee_employee_emails SET email_address='"+request.data['email']+"' WHERE id="+businessemail[0]['id']
TypeError: must be str, not int
ERROR|22/Dec/2020 12:07:58|basehttp|16446|139972804667136|"POST /get_add/employee/ HTTP/1.1" 500 17318
ERROR|22/Dec/2020 13:09:56|log|16654|139683252393728|Internal Server Error: /currency_conversion_history/
Traceback (most recent call last):
  File "/home/mobilitysqr/.local/lib/python3.6/site-packages/django/db/models/fields/__init__.py", line 1380, in to_python
    parsed = parse_date(value)
  File "/home/mobilitysqr/.local/lib/python3.6/site-packages/django/utils/dateparse.py", line 77, in parse_date
    return datetime.date(**kw)
ValueError: month must be in 1..12

During handling of the above exception, another exception occurred:

Traceback (most recent call last):
  File "/home/mobilitysqr/.local/lib/python3.6/site-packages/django/core/handlers/exception.py", line 34, in inner
    response = get_response(request)
  File "/home/mobilitysqr/.local/lib/python3.6/site-packages/django/core/handlers/base.py", line 126, in _get_response
    response = self.process_exception_by_middleware(e, request)
  File "/home/mobilitysqr/.local/lib/python3.6/site-packages/django/core/handlers/base.py", line 124, in _get_response
    response = wrapped_callback(request, *callback_args, **callback_kwargs)
  File "/home/mobilitysqr/.local/lib/python3.6/site-packages/django/views/decorators/csrf.py", line 54, in wrapped_view
    return view_func(*args, **kwargs)
  File "/home/mobilitysqr/.local/lib/python3.6/site-packages/django/views/generic/base.py", line 68, in view
    return self.dispatch(request, *args, **kwargs)
  File "/home/mobilitysqr/.local/lib/python3.6/site-packages/rest_framework/views.py", line 495, in dispatch
    response = self.handle_exception(exc)
  File "/home/mobilitysqr/.local/lib/python3.6/site-packages/rest_framework/views.py", line 455, in handle_exception
    self.raise_uncaught_exception(exc)
  File "/home/mobilitysqr/.local/lib/python3.6/site-packages/rest_framework/views.py", line 492, in dispatch
    response = handler(request, *args, **kwargs)
  File "/var/www/html/mobilitysqrapi/mobility_apps/master/views/currency.py", line 305, in get
    currency = Currency_Conversion_History.objects.filter(from_currency=request.GET['from_currency'],to_currency=request.GET['to_currency'],conversion_date__gte=request.GET['from_date'],conversion_date__lte=request.GET['to_date'])
  File "/home/mobilitysqr/.local/lib/python3.6/site-packages/django/db/models/manager.py", line 82, in manager_method
    return getattr(self.get_queryset(), name)(*args, **kwargs)
  File "/home/mobilitysqr/.local/lib/python3.6/site-packages/django/db/models/query.py", line 841, in filter
    return self._filter_or_exclude(False, *args, **kwargs)
  File "/home/mobilitysqr/.local/lib/python3.6/site-packages/django/db/models/query.py", line 859, in _filter_or_exclude
    clone.query.add_q(Q(*args, **kwargs))
  File "/home/mobilitysqr/.local/lib/python3.6/site-packages/django/db/models/sql/query.py", line 1263, in add_q
    clause, _ = self._add_q(q_object, self.used_aliases)
  File "/home/mobilitysqr/.local/lib/python3.6/site-packages/django/db/models/sql/query.py", line 1287, in _add_q
    split_subq=split_subq,
  File "/home/mobilitysqr/.local/lib/python3.6/site-packages/django/db/models/sql/query.py", line 1225, in build_filter
    condition = self.build_lookup(lookups, col, value)
  File "/home/mobilitysqr/.local/lib/python3.6/site-packages/django/db/models/sql/query.py", line 1096, in build_lookup
    lookup = lookup_class(lhs, rhs)
  File "/home/mobilitysqr/.local/lib/python3.6/site-packages/django/db/models/lookups.py", line 20, in __init__
    self.rhs = self.get_prep_lookup()
  File "/home/mobilitysqr/.local/lib/python3.6/site-packages/django/db/models/lookups.py", line 70, in get_prep_lookup
    return self.lhs.output_field.get_prep_value(self.rhs)
  File "/home/mobilitysqr/.local/lib/python3.6/site-packages/django/db/models/fields/__init__.py", line 1408, in get_prep_value
    value = super().get_prep_value(value)
  File "/home/mobilitysqr/.local/lib/python3.6/site-packages/django/db/models/fields/__init__.py", line 1268, in get_prep_value
    return self.to_python(value)
  File "/home/mobilitysqr/.local/lib/python3.6/site-packages/django/db/models/fields/__init__.py", line 1387, in to_python
    params={'value': value},
django.core.exceptions.ValidationError: ["'2000-28-12' value has the correct format (YYYY-MM-DD) but it is an invalid date."]
ERROR|22/Dec/2020 13:09:56|basehttp|16654|139683252393728|"GET /currency_conversion_history/?from_date=2000-28-12&to_date=2020-22-12&from_currency=USD&to_currency=DEM HTTP/1.1" 500 20192
ERROR|22/Dec/2020 13:15:27|log|16654|139682872555264|Internal Server Error: /currency_conversion_history/
Traceback (most recent call last):
  File "/home/mobilitysqr/.local/lib/python3.6/site-packages/django/db/models/fields/__init__.py", line 1380, in to_python
    parsed = parse_date(value)
  File "/home/mobilitysqr/.local/lib/python3.6/site-packages/django/utils/dateparse.py", line 77, in parse_date
    return datetime.date(**kw)
ValueError: month must be in 1..12

During handling of the above exception, another exception occurred:

Traceback (most recent call last):
  File "/home/mobilitysqr/.local/lib/python3.6/site-packages/django/core/handlers/exception.py", line 34, in inner
    response = get_response(request)
  File "/home/mobilitysqr/.local/lib/python3.6/site-packages/django/core/handlers/base.py", line 126, in _get_response
    response = self.process_exception_by_middleware(e, request)
  File "/home/mobilitysqr/.local/lib/python3.6/site-packages/django/core/handlers/base.py", line 124, in _get_response
    response = wrapped_callback(request, *callback_args, **callback_kwargs)
  File "/home/mobilitysqr/.local/lib/python3.6/site-packages/django/views/decorators/csrf.py", line 54, in wrapped_view
    return view_func(*args, **kwargs)
  File "/home/mobilitysqr/.local/lib/python3.6/site-packages/django/views/generic/base.py", line 68, in view
    return self.dispatch(request, *args, **kwargs)
  File "/home/mobilitysqr/.local/lib/python3.6/site-packages/rest_framework/views.py", line 495, in dispatch
    response = self.handle_exception(exc)
  File "/home/mobilitysqr/.local/lib/python3.6/site-packages/rest_framework/views.py", line 455, in handle_exception
    self.raise_uncaught_exception(exc)
  File "/home/mobilitysqr/.local/lib/python3.6/site-packages/rest_framework/views.py", line 492, in dispatch
    response = handler(request, *args, **kwargs)
  File "/var/www/html/mobilitysqrapi/mobility_apps/master/views/currency.py", line 305, in get
    currency = Currency_Conversion_History.objects.filter(from_currency=request.GET['from_currency'],to_currency=request.GET['to_currency'],conversion_date__gte=request.GET['from_date'],conversion_date__lte=request.GET['to_date'])
  File "/home/mobilitysqr/.local/lib/python3.6/site-packages/django/db/models/manager.py", line 82, in manager_method
    return getattr(self.get_queryset(), name)(*args, **kwargs)
  File "/home/mobilitysqr/.local/lib/python3.6/site-packages/django/db/models/query.py", line 841, in filter
    return self._filter_or_exclude(False, *args, **kwargs)
  File "/home/mobilitysqr/.local/lib/python3.6/site-packages/django/db/models/query.py", line 859, in _filter_or_exclude
    clone.query.add_q(Q(*args, **kwargs))
  File "/home/mobilitysqr/.local/lib/python3.6/site-packages/django/db/models/sql/query.py", line 1263, in add_q
    clause, _ = self._add_q(q_object, self.used_aliases)
  File "/home/mobilitysqr/.local/lib/python3.6/site-packages/django/db/models/sql/query.py", line 1287, in _add_q
    split_subq=split_subq,
  File "/home/mobilitysqr/.local/lib/python3.6/site-packages/django/db/models/sql/query.py", line 1225, in build_filter
    condition = self.build_lookup(lookups, col, value)
  File "/home/mobilitysqr/.local/lib/python3.6/site-packages/django/db/models/sql/query.py", line 1096, in build_lookup
    lookup = lookup_class(lhs, rhs)
  File "/home/mobilitysqr/.local/lib/python3.6/site-packages/django/db/models/lookups.py", line 20, in __init__
    self.rhs = self.get_prep_lookup()
  File "/home/mobilitysqr/.local/lib/python3.6/site-packages/django/db/models/lookups.py", line 70, in get_prep_lookup
    return self.lhs.output_field.get_prep_value(self.rhs)
  File "/home/mobilitysqr/.local/lib/python3.6/site-packages/django/db/models/fields/__init__.py", line 1408, in get_prep_value
    value = super().get_prep_value(value)
  File "/home/mobilitysqr/.local/lib/python3.6/site-packages/django/db/models/fields/__init__.py", line 1268, in get_prep_value
    return self.to_python(value)
  File "/home/mobilitysqr/.local/lib/python3.6/site-packages/django/db/models/fields/__init__.py", line 1387, in to_python
    params={'value': value},
django.core.exceptions.ValidationError: ["'2020-21-12' value has the correct format (YYYY-MM-DD) but it is an invalid date."]
ERROR|22/Dec/2020 13:15:27|basehttp|16654|139682872555264|"GET /currency_conversion_history/?from_date=2020-21-12&to_date=2020-23-12&from_currency=USD&to_currency=INR HTTP/1.1" 500 20192
ERROR|22/Dec/2020 13:24:03|log|16654|139683242952448|Internal Server Error: /currency_conversion_history/
Traceback (most recent call last):
  File "/home/mobilitysqr/.local/lib/python3.6/site-packages/django/db/models/fields/__init__.py", line 1380, in to_python
    parsed = parse_date(value)
  File "/home/mobilitysqr/.local/lib/python3.6/site-packages/django/utils/dateparse.py", line 77, in parse_date
    return datetime.date(**kw)
ValueError: month must be in 1..12

During handling of the above exception, another exception occurred:

Traceback (most recent call last):
  File "/home/mobilitysqr/.local/lib/python3.6/site-packages/django/core/handlers/exception.py", line 34, in inner
    response = get_response(request)
  File "/home/mobilitysqr/.local/lib/python3.6/site-packages/django/core/handlers/base.py", line 126, in _get_response
    response = self.process_exception_by_middleware(e, request)
  File "/home/mobilitysqr/.local/lib/python3.6/site-packages/django/core/handlers/base.py", line 124, in _get_response
    response = wrapped_callback(request, *callback_args, **callback_kwargs)
  File "/home/mobilitysqr/.local/lib/python3.6/site-packages/django/views/decorators/csrf.py", line 54, in wrapped_view
    return view_func(*args, **kwargs)
  File "/home/mobilitysqr/.local/lib/python3.6/site-packages/django/views/generic/base.py", line 68, in view
    return self.dispatch(request, *args, **kwargs)
  File "/home/mobilitysqr/.local/lib/python3.6/site-packages/rest_framework/views.py", line 495, in dispatch
    response = self.handle_exception(exc)
  File "/home/mobilitysqr/.local/lib/python3.6/site-packages/rest_framework/views.py", line 455, in handle_exception
    self.raise_uncaught_exception(exc)
  File "/home/mobilitysqr/.local/lib/python3.6/site-packages/rest_framework/views.py", line 492, in dispatch
    response = handler(request, *args, **kwargs)
  File "/var/www/html/mobilitysqrapi/mobility_apps/master/views/currency.py", line 305, in get
    currency = Currency_Conversion_History.objects.filter(from_currency=request.GET['from_currency'],to_currency=request.GET['to_currency'],conversion_date__gte=request.GET['from_date'],conversion_date__lte=request.GET['to_date'])
  File "/home/mobilitysqr/.local/lib/python3.6/site-packages/django/db/models/manager.py", line 82, in manager_method
    return getattr(self.get_queryset(), name)(*args, **kwargs)
  File "/home/mobilitysqr/.local/lib/python3.6/site-packages/django/db/models/query.py", line 841, in filter
    return self._filter_or_exclude(False, *args, **kwargs)
  File "/home/mobilitysqr/.local/lib/python3.6/site-packages/django/db/models/query.py", line 859, in _filter_or_exclude
    clone.query.add_q(Q(*args, **kwargs))
  File "/home/mobilitysqr/.local/lib/python3.6/site-packages/django/db/models/sql/query.py", line 1263, in add_q
    clause, _ = self._add_q(q_object, self.used_aliases)
  File "/home/mobilitysqr/.local/lib/python3.6/site-packages/django/db/models/sql/query.py", line 1287, in _add_q
    split_subq=split_subq,
  File "/home/mobilitysqr/.local/lib/python3.6/site-packages/django/db/models/sql/query.py", line 1225, in build_filter
    condition = self.build_lookup(lookups, col, value)
  File "/home/mobilitysqr/.local/lib/python3.6/site-packages/django/db/models/sql/query.py", line 1096, in build_lookup
    lookup = lookup_class(lhs, rhs)
  File "/home/mobilitysqr/.local/lib/python3.6/site-packages/django/db/models/lookups.py", line 20, in __init__
    self.rhs = self.get_prep_lookup()
  File "/home/mobilitysqr/.local/lib/python3.6/site-packages/django/db/models/lookups.py", line 70, in get_prep_lookup
    return self.lhs.output_field.get_prep_value(self.rhs)
  File "/home/mobilitysqr/.local/lib/python3.6/site-packages/django/db/models/fields/__init__.py", line 1408, in get_prep_value
    value = super().get_prep_value(value)
  File "/home/mobilitysqr/.local/lib/python3.6/site-packages/django/db/models/fields/__init__.py", line 1268, in get_prep_value
    return self.to_python(value)
  File "/home/mobilitysqr/.local/lib/python3.6/site-packages/django/db/models/fields/__init__.py", line 1387, in to_python
    params={'value': value},
django.core.exceptions.ValidationError: ["'2020-21-12' value has the correct format (YYYY-MM-DD) but it is an invalid date."]
ERROR|22/Dec/2020 13:24:03|basehttp|16654|139683242952448|"GET /currency_conversion_history/?from_date=2020-21-12&to_date=2020-23-12&from_currency=USD&to_currency=INR HTTP/1.1" 500 20192
ERROR|22/Dec/2020 13:25:36|log|16654|139683252393728|Internal Server Error: /currency_conversion_history/
Traceback (most recent call last):
  File "/home/mobilitysqr/.local/lib/python3.6/site-packages/django/db/models/fields/__init__.py", line 1380, in to_python
    parsed = parse_date(value)
  File "/home/mobilitysqr/.local/lib/python3.6/site-packages/django/utils/dateparse.py", line 77, in parse_date
    return datetime.date(**kw)
ValueError: month must be in 1..12

During handling of the above exception, another exception occurred:

Traceback (most recent call last):
  File "/home/mobilitysqr/.local/lib/python3.6/site-packages/django/core/handlers/exception.py", line 34, in inner
    response = get_response(request)
  File "/home/mobilitysqr/.local/lib/python3.6/site-packages/django/core/handlers/base.py", line 126, in _get_response
    response = self.process_exception_by_middleware(e, request)
  File "/home/mobilitysqr/.local/lib/python3.6/site-packages/django/core/handlers/base.py", line 124, in _get_response
    response = wrapped_callback(request, *callback_args, **callback_kwargs)
  File "/home/mobilitysqr/.local/lib/python3.6/site-packages/django/views/decorators/csrf.py", line 54, in wrapped_view
    return view_func(*args, **kwargs)
  File "/home/mobilitysqr/.local/lib/python3.6/site-packages/django/views/generic/base.py", line 68, in view
    return self.dispatch(request, *args, **kwargs)
  File "/home/mobilitysqr/.local/lib/python3.6/site-packages/rest_framework/views.py", line 495, in dispatch
    response = self.handle_exception(exc)
  File "/home/mobilitysqr/.local/lib/python3.6/site-packages/rest_framework/views.py", line 455, in handle_exception
    self.raise_uncaught_exception(exc)
  File "/home/mobilitysqr/.local/lib/python3.6/site-packages/rest_framework/views.py", line 492, in dispatch
    response = handler(request, *args, **kwargs)
  File "/var/www/html/mobilitysqrapi/mobility_apps/master/views/currency.py", line 305, in get
    currency = Currency_Conversion_History.objects.filter(from_currency=request.GET['from_currency'],to_currency=request.GET['to_currency'],conversion_date__gte=request.GET['from_date'],conversion_date__lte=request.GET['to_date'])
  File "/home/mobilitysqr/.local/lib/python3.6/site-packages/django/db/models/manager.py", line 82, in manager_method
    return getattr(self.get_queryset(), name)(*args, **kwargs)
  File "/home/mobilitysqr/.local/lib/python3.6/site-packages/django/db/models/query.py", line 841, in filter
    return self._filter_or_exclude(False, *args, **kwargs)
  File "/home/mobilitysqr/.local/lib/python3.6/site-packages/django/db/models/query.py", line 859, in _filter_or_exclude
    clone.query.add_q(Q(*args, **kwargs))
  File "/home/mobilitysqr/.local/lib/python3.6/site-packages/django/db/models/sql/query.py", line 1263, in add_q
    clause, _ = self._add_q(q_object, self.used_aliases)
  File "/home/mobilitysqr/.local/lib/python3.6/site-packages/django/db/models/sql/query.py", line 1287, in _add_q
    split_subq=split_subq,
  File "/home/mobilitysqr/.local/lib/python3.6/site-packages/django/db/models/sql/query.py", line 1225, in build_filter
    condition = self.build_lookup(lookups, col, value)
  File "/home/mobilitysqr/.local/lib/python3.6/site-packages/django/db/models/sql/query.py", line 1096, in build_lookup
    lookup = lookup_class(lhs, rhs)
  File "/home/mobilitysqr/.local/lib/python3.6/site-packages/django/db/models/lookups.py", line 20, in __init__
    self.rhs = self.get_prep_lookup()
  File "/home/mobilitysqr/.local/lib/python3.6/site-packages/django/db/models/lookups.py", line 70, in get_prep_lookup
    return self.lhs.output_field.get_prep_value(self.rhs)
  File "/home/mobilitysqr/.local/lib/python3.6/site-packages/django/db/models/fields/__init__.py", line 1408, in get_prep_value
    value = super().get_prep_value(value)
  File "/home/mobilitysqr/.local/lib/python3.6/site-packages/django/db/models/fields/__init__.py", line 1268, in get_prep_value
    return self.to_python(value)
  File "/home/mobilitysqr/.local/lib/python3.6/site-packages/django/db/models/fields/__init__.py", line 1387, in to_python
    params={'value': value},
django.core.exceptions.ValidationError: ["'2020-21-12' value has the correct format (YYYY-MM-DD) but it is an invalid date."]
ERROR|22/Dec/2020 13:25:36|basehttp|16654|139683252393728|"GET /currency_conversion_history/?from_date=2020-21-12&to_date=2020-23-12&from_currency=USD&to_currency=INR HTTP/1.1" 500 20193
ERROR|22/Dec/2020 13:34:43|log|16654|139683242952448|Internal Server Error: /getassignmentletter/
Traceback (most recent call last):
  File "/home/mobilitysqr/.local/lib/python3.6/site-packages/django/core/handlers/exception.py", line 34, in inner
    response = get_response(request)
  File "/home/mobilitysqr/.local/lib/python3.6/site-packages/django/core/handlers/base.py", line 126, in _get_response
    response = self.process_exception_by_middleware(e, request)
  File "/home/mobilitysqr/.local/lib/python3.6/site-packages/django/core/handlers/base.py", line 124, in _get_response
    response = wrapped_callback(request, *callback_args, **callback_kwargs)
  File "/home/mobilitysqr/.local/lib/python3.6/site-packages/django/views/decorators/csrf.py", line 54, in wrapped_view
    return view_func(*args, **kwargs)
  File "/home/mobilitysqr/.local/lib/python3.6/site-packages/django/views/generic/base.py", line 68, in view
    return self.dispatch(request, *args, **kwargs)
  File "/home/mobilitysqr/.local/lib/python3.6/site-packages/rest_framework/views.py", line 495, in dispatch
    response = self.handle_exception(exc)
  File "/home/mobilitysqr/.local/lib/python3.6/site-packages/rest_framework/views.py", line 455, in handle_exception
    self.raise_uncaught_exception(exc)
  File "/home/mobilitysqr/.local/lib/python3.6/site-packages/rest_framework/views.py", line 492, in dispatch
    response = handler(request, *args, **kwargs)
  File "/var/www/html/mobilitysqrapi/mobility_apps/letter/views.py", line 72, in get
    empcode=emp_serializer.data[0]['emp_code']
IndexError: list index out of range
ERROR|22/Dec/2020 13:34:43|basehttp|16654|139683242952448|"GET /getassignmentletter/?travel_req_id=TR237920 HTTP/1.1" 500 17295
ERROR|22/Dec/2020 13:42:34|log|16654|139683242952448|Internal Server Error: /getassignmentletter/
Traceback (most recent call last):
  File "/home/mobilitysqr/.local/lib/python3.6/site-packages/django/core/handlers/exception.py", line 34, in inner
    response = get_response(request)
  File "/home/mobilitysqr/.local/lib/python3.6/site-packages/django/core/handlers/base.py", line 126, in _get_response
    response = self.process_exception_by_middleware(e, request)
  File "/home/mobilitysqr/.local/lib/python3.6/site-packages/django/core/handlers/base.py", line 124, in _get_response
    response = wrapped_callback(request, *callback_args, **callback_kwargs)
  File "/home/mobilitysqr/.local/lib/python3.6/site-packages/django/views/decorators/csrf.py", line 54, in wrapped_view
    return view_func(*args, **kwargs)
  File "/home/mobilitysqr/.local/lib/python3.6/site-packages/django/views/generic/base.py", line 68, in view
    return self.dispatch(request, *args, **kwargs)
  File "/home/mobilitysqr/.local/lib/python3.6/site-packages/rest_framework/views.py", line 495, in dispatch
    response = self.handle_exception(exc)
  File "/home/mobilitysqr/.local/lib/python3.6/site-packages/rest_framework/views.py", line 455, in handle_exception
    self.raise_uncaught_exception(exc)
  File "/home/mobilitysqr/.local/lib/python3.6/site-packages/rest_framework/views.py", line 492, in dispatch
    response = handler(request, *args, **kwargs)
  File "/var/www/html/mobilitysqrapi/mobility_apps/letter/views.py", line 72, in get
    empcode=emp_serializer.data[0]['emp_code']
IndexError: list index out of range
ERROR|22/Dec/2020 13:42:34|basehttp|16654|139683242952448|"GET /getassignmentletter/?travel_req_id=TR298741 HTTP/1.1" 500 17296
ERROR|22/Dec/2020 13:44:26|log|16654|139683242952448|Internal Server Error: /getassignmentletter/
Traceback (most recent call last):
  File "/home/mobilitysqr/.local/lib/python3.6/site-packages/django/core/handlers/exception.py", line 34, in inner
    response = get_response(request)
  File "/home/mobilitysqr/.local/lib/python3.6/site-packages/django/core/handlers/base.py", line 126, in _get_response
    response = self.process_exception_by_middleware(e, request)
  File "/home/mobilitysqr/.local/lib/python3.6/site-packages/django/core/handlers/base.py", line 124, in _get_response
    response = wrapped_callback(request, *callback_args, **callback_kwargs)
  File "/home/mobilitysqr/.local/lib/python3.6/site-packages/django/views/decorators/csrf.py", line 54, in wrapped_view
    return view_func(*args, **kwargs)
  File "/home/mobilitysqr/.local/lib/python3.6/site-packages/django/views/generic/base.py", line 68, in view
    return self.dispatch(request, *args, **kwargs)
  File "/home/mobilitysqr/.local/lib/python3.6/site-packages/rest_framework/views.py", line 495, in dispatch
    response = self.handle_exception(exc)
  File "/home/mobilitysqr/.local/lib/python3.6/site-packages/rest_framework/views.py", line 455, in handle_exception
    self.raise_uncaught_exception(exc)
  File "/home/mobilitysqr/.local/lib/python3.6/site-packages/rest_framework/views.py", line 492, in dispatch
    response = handler(request, *args, **kwargs)
  File "/var/www/html/mobilitysqrapi/mobility_apps/letter/views.py", line 72, in get
    empcode=emp_serializer.data[0]['emp_code']
IndexError: list index out of range
ERROR|22/Dec/2020 13:44:26|basehttp|16654|139683242952448|"GET /getassignmentletter/?travel_req_id=TR298741 HTTP/1.1" 500 17296
ERROR|22/Dec/2020 13:46:38|log|16654|139683252393728|Internal Server Error: /getassignmentletter/
Traceback (most recent call last):
  File "/home/mobilitysqr/.local/lib/python3.6/site-packages/django/core/handlers/exception.py", line 34, in inner
    response = get_response(request)
  File "/home/mobilitysqr/.local/lib/python3.6/site-packages/django/core/handlers/base.py", line 126, in _get_response
    response = self.process_exception_by_middleware(e, request)
  File "/home/mobilitysqr/.local/lib/python3.6/site-packages/django/core/handlers/base.py", line 124, in _get_response
    response = wrapped_callback(request, *callback_args, **callback_kwargs)
  File "/home/mobilitysqr/.local/lib/python3.6/site-packages/django/views/decorators/csrf.py", line 54, in wrapped_view
    return view_func(*args, **kwargs)
  File "/home/mobilitysqr/.local/lib/python3.6/site-packages/django/views/generic/base.py", line 68, in view
    return self.dispatch(request, *args, **kwargs)
  File "/home/mobilitysqr/.local/lib/python3.6/site-packages/rest_framework/views.py", line 495, in dispatch
    response = self.handle_exception(exc)
  File "/home/mobilitysqr/.local/lib/python3.6/site-packages/rest_framework/views.py", line 455, in handle_exception
    self.raise_uncaught_exception(exc)
  File "/home/mobilitysqr/.local/lib/python3.6/site-packages/rest_framework/views.py", line 492, in dispatch
    response = handler(request, *args, **kwargs)
  File "/var/www/html/mobilitysqrapi/mobility_apps/letter/views.py", line 72, in get
    empcode=emp_serializer.data[0]['emp_code']
IndexError: list index out of range
ERROR|22/Dec/2020 13:46:38|basehttp|16654|139683252393728|"GET /getassignmentletter/?travel_req_id=TR298741 HTTP/1.1" 500 17300
ERROR|22/Dec/2020 13:50:53|log|20480|139975625668352|Internal Server Error: /getassignmentletter/
Traceback (most recent call last):
  File "/home/mobilitysqr/.local/lib/python3.6/site-packages/django/core/handlers/exception.py", line 34, in inner
    response = get_response(request)
  File "/home/mobilitysqr/.local/lib/python3.6/site-packages/django/core/handlers/base.py", line 126, in _get_response
    response = self.process_exception_by_middleware(e, request)
  File "/home/mobilitysqr/.local/lib/python3.6/site-packages/django/core/handlers/base.py", line 124, in _get_response
    response = wrapped_callback(request, *callback_args, **callback_kwargs)
  File "/home/mobilitysqr/.local/lib/python3.6/site-packages/django/views/decorators/csrf.py", line 54, in wrapped_view
    return view_func(*args, **kwargs)
  File "/home/mobilitysqr/.local/lib/python3.6/site-packages/django/views/generic/base.py", line 68, in view
    return self.dispatch(request, *args, **kwargs)
  File "/home/mobilitysqr/.local/lib/python3.6/site-packages/rest_framework/views.py", line 495, in dispatch
    response = self.handle_exception(exc)
  File "/home/mobilitysqr/.local/lib/python3.6/site-packages/rest_framework/views.py", line 455, in handle_exception
    self.raise_uncaught_exception(exc)
  File "/home/mobilitysqr/.local/lib/python3.6/site-packages/rest_framework/views.py", line 492, in dispatch
    response = handler(request, *args, **kwargs)
  File "/var/www/html/mobilitysqrapi/mobility_apps/letter/views.py", line 72, in get
    empcode=emp_serializer.data[0]['emp_code']
IndexError: list index out of range
ERROR|22/Dec/2020 13:50:53|basehttp|20480|139975625668352|"GET /getassignmentletter/?travel_req_id=TR298741 HTTP/1.1" 500 17300
ERROR|22/Dec/2020 13:52:00|log|20617|140260908332800|Internal Server Error: /getassignmentletter/
Traceback (most recent call last):
  File "/home/mobilitysqr/.local/lib/python3.6/site-packages/django/core/handlers/exception.py", line 34, in inner
    response = get_response(request)
  File "/home/mobilitysqr/.local/lib/python3.6/site-packages/django/core/handlers/base.py", line 126, in _get_response
    response = self.process_exception_by_middleware(e, request)
  File "/home/mobilitysqr/.local/lib/python3.6/site-packages/django/core/handlers/base.py", line 124, in _get_response
    response = wrapped_callback(request, *callback_args, **callback_kwargs)
  File "/home/mobilitysqr/.local/lib/python3.6/site-packages/django/views/decorators/csrf.py", line 54, in wrapped_view
    return view_func(*args, **kwargs)
  File "/home/mobilitysqr/.local/lib/python3.6/site-packages/django/views/generic/base.py", line 68, in view
    return self.dispatch(request, *args, **kwargs)
  File "/home/mobilitysqr/.local/lib/python3.6/site-packages/rest_framework/views.py", line 495, in dispatch
    response = self.handle_exception(exc)
  File "/home/mobilitysqr/.local/lib/python3.6/site-packages/rest_framework/views.py", line 455, in handle_exception
    self.raise_uncaught_exception(exc)
  File "/home/mobilitysqr/.local/lib/python3.6/site-packages/rest_framework/views.py", line 492, in dispatch
    response = handler(request, *args, **kwargs)
  File "/var/www/html/mobilitysqrapi/mobility_apps/letter/views.py", line 188, in get
    if data['emp_passport'][0]['passort_number']:
KeyError: 'passort_number'
ERROR|22/Dec/2020 13:52:00|basehttp|20617|140260908332800|"GET /getassignmentletter/?travel_req_id=TR298741 HTTP/1.1" 500 17292
ERROR|22/Dec/2020 13:52:55|log|20668|139733457594112|Internal Server Error: /getassignmentletter/
Traceback (most recent call last):
  File "/home/mobilitysqr/.local/lib/python3.6/site-packages/django/core/handlers/exception.py", line 34, in inner
    response = get_response(request)
  File "/home/mobilitysqr/.local/lib/python3.6/site-packages/django/core/handlers/base.py", line 126, in _get_response
    response = self.process_exception_by_middleware(e, request)
  File "/home/mobilitysqr/.local/lib/python3.6/site-packages/django/core/handlers/base.py", line 124, in _get_response
    response = wrapped_callback(request, *callback_args, **callback_kwargs)
  File "/home/mobilitysqr/.local/lib/python3.6/site-packages/django/views/decorators/csrf.py", line 54, in wrapped_view
    return view_func(*args, **kwargs)
  File "/home/mobilitysqr/.local/lib/python3.6/site-packages/django/views/generic/base.py", line 68, in view
    return self.dispatch(request, *args, **kwargs)
  File "/home/mobilitysqr/.local/lib/python3.6/site-packages/rest_framework/views.py", line 495, in dispatch
    response = self.handle_exception(exc)
  File "/home/mobilitysqr/.local/lib/python3.6/site-packages/rest_framework/views.py", line 455, in handle_exception
    self.raise_uncaught_exception(exc)
  File "/home/mobilitysqr/.local/lib/python3.6/site-packages/rest_framework/views.py", line 492, in dispatch
    response = handler(request, *args, **kwargs)
  File "/var/www/html/mobilitysqrapi/mobility_apps/letter/views.py", line 317, in get
    template = get_template(lettername)
  File "/home/mobilitysqr/.local/lib/python3.6/site-packages/django/template/loader.py", line 15, in get_template
    return engine.get_template(template_name)
  File "/home/mobilitysqr/.local/lib/python3.6/site-packages/django/template/backends/django.py", line 34, in get_template
    return Template(self.engine.get_template(template_name), self)
  File "/home/mobilitysqr/.local/lib/python3.6/site-packages/django/template/engine.py", line 144, in get_template
    template, origin = self.find_template(template_name)
  File "/home/mobilitysqr/.local/lib/python3.6/site-packages/django/template/engine.py", line 126, in find_template
    template = loader.get_template(name, skip=skip)
  File "/home/mobilitysqr/.local/lib/python3.6/site-packages/django/template/loaders/base.py", line 30, in get_template
    contents, origin, origin.template_name, self.engine,
  File "/home/mobilitysqr/.local/lib/python3.6/site-packages/django/template/base.py", line 156, in __init__
    self.nodelist = self.compile_nodelist()
  File "/home/mobilitysqr/.local/lib/python3.6/site-packages/django/template/base.py", line 194, in compile_nodelist
    return parser.parse()
  File "/home/mobilitysqr/.local/lib/python3.6/site-packages/django/template/base.py", line 449, in parse
    raise self.error(token, e)
  File "/home/mobilitysqr/.local/lib/python3.6/site-packages/django/template/base.py", line 447, in parse
    filter_expression = self.compile_filter(token.contents)
  File "/home/mobilitysqr/.local/lib/python3.6/site-packages/django/template/base.py", line 563, in compile_filter
    return FilterExpression(token, self)
  File "/home/mobilitysqr/.local/lib/python3.6/site-packages/django/template/base.py", line 663, in __init__
    "from '%s'" % (token[upto:], token))
django.template.exceptions.TemplateSyntaxError: Could not parse the remainder: '</span><span style="background-color: transparent; font-size: 1rem;">JobTitle' from 'AssigneeName</span><span style="background-color: transparent; font-size: 1rem;">JobTitle'
ERROR|22/Dec/2020 13:52:55|basehttp|20668|139733457594112|"GET /getassignmentletter/?travel_req_id=TR298741 HTTP/1.1" 500 35274
ERROR|22/Dec/2020 13:59:56|log|2045|139917586929408|Internal Server Error: /getassignmentletter/
Traceback (most recent call last):
  File "/home/mobilitysqr/.local/lib/python3.6/site-packages/django/core/handlers/exception.py", line 34, in inner
    response = get_response(request)
  File "/home/mobilitysqr/.local/lib/python3.6/site-packages/django/core/handlers/base.py", line 126, in _get_response
    response = self.process_exception_by_middleware(e, request)
  File "/home/mobilitysqr/.local/lib/python3.6/site-packages/django/core/handlers/base.py", line 124, in _get_response
    response = wrapped_callback(request, *callback_args, **callback_kwargs)
  File "/home/mobilitysqr/.local/lib/python3.6/site-packages/django/views/decorators/csrf.py", line 54, in wrapped_view
    return view_func(*args, **kwargs)
  File "/home/mobilitysqr/.local/lib/python3.6/site-packages/django/views/generic/base.py", line 68, in view
    return self.dispatch(request, *args, **kwargs)
  File "/home/mobilitysqr/.local/lib/python3.6/site-packages/rest_framework/views.py", line 495, in dispatch
    response = self.handle_exception(exc)
  File "/home/mobilitysqr/.local/lib/python3.6/site-packages/rest_framework/views.py", line 455, in handle_exception
    self.raise_uncaught_exception(exc)
  File "/home/mobilitysqr/.local/lib/python3.6/site-packages/rest_framework/views.py", line 492, in dispatch
    response = handler(request, *args, **kwargs)
  File "/var/www/html/mobilitysqrapi/mobility_apps/letter/views.py", line 317, in get
    template = get_template(lettername)
  File "/home/mobilitysqr/.local/lib/python3.6/site-packages/django/template/loader.py", line 15, in get_template
    return engine.get_template(template_name)
  File "/home/mobilitysqr/.local/lib/python3.6/site-packages/django/template/backends/django.py", line 34, in get_template
    return Template(self.engine.get_template(template_name), self)
  File "/home/mobilitysqr/.local/lib/python3.6/site-packages/django/template/engine.py", line 144, in get_template
    template, origin = self.find_template(template_name)
  File "/home/mobilitysqr/.local/lib/python3.6/site-packages/django/template/engine.py", line 126, in find_template
    template = loader.get_template(name, skip=skip)
  File "/home/mobilitysqr/.local/lib/python3.6/site-packages/django/template/loaders/base.py", line 30, in get_template
    contents, origin, origin.template_name, self.engine,
  File "/home/mobilitysqr/.local/lib/python3.6/site-packages/django/template/base.py", line 156, in __init__
    self.nodelist = self.compile_nodelist()
  File "/home/mobilitysqr/.local/lib/python3.6/site-packages/django/template/base.py", line 194, in compile_nodelist
    return parser.parse()
  File "/home/mobilitysqr/.local/lib/python3.6/site-packages/django/template/base.py", line 449, in parse
    raise self.error(token, e)
  File "/home/mobilitysqr/.local/lib/python3.6/site-packages/django/template/base.py", line 447, in parse
    filter_expression = self.compile_filter(token.contents)
  File "/home/mobilitysqr/.local/lib/python3.6/site-packages/django/template/base.py", line 563, in compile_filter
    return FilterExpression(token, self)
  File "/home/mobilitysqr/.local/lib/python3.6/site-packages/django/template/base.py", line 663, in __init__
    "from '%s'" % (token[upto:], token))
django.template.exceptions.TemplateSyntaxError: Could not parse the remainder: '</span><span style="background-color: transparent; font-size: 1rem;">JobTitle' from 'AssigneeName</span><span style="background-color: transparent; font-size: 1rem;">JobTitle'
ERROR|22/Dec/2020 13:59:56|basehttp|2045|139917586929408|"GET /getassignmentletter/?travel_req_id=TR298741 HTTP/1.1" 500 35270
ERROR|22/Dec/2020 14:01:16|log|2045|139917586929408|Internal Server Error: /getassignmentletter/
Traceback (most recent call last):
  File "/home/mobilitysqr/.local/lib/python3.6/site-packages/django/core/handlers/exception.py", line 34, in inner
    response = get_response(request)
  File "/home/mobilitysqr/.local/lib/python3.6/site-packages/django/core/handlers/base.py", line 126, in _get_response
    response = self.process_exception_by_middleware(e, request)
  File "/home/mobilitysqr/.local/lib/python3.6/site-packages/django/core/handlers/base.py", line 124, in _get_response
    response = wrapped_callback(request, *callback_args, **callback_kwargs)
  File "/home/mobilitysqr/.local/lib/python3.6/site-packages/django/views/decorators/csrf.py", line 54, in wrapped_view
    return view_func(*args, **kwargs)
  File "/home/mobilitysqr/.local/lib/python3.6/site-packages/django/views/generic/base.py", line 68, in view
    return self.dispatch(request, *args, **kwargs)
  File "/home/mobilitysqr/.local/lib/python3.6/site-packages/rest_framework/views.py", line 495, in dispatch
    response = self.handle_exception(exc)
  File "/home/mobilitysqr/.local/lib/python3.6/site-packages/rest_framework/views.py", line 455, in handle_exception
    self.raise_uncaught_exception(exc)
  File "/home/mobilitysqr/.local/lib/python3.6/site-packages/rest_framework/views.py", line 492, in dispatch
    response = handler(request, *args, **kwargs)
  File "/var/www/html/mobilitysqrapi/mobility_apps/letter/views.py", line 317, in get
    template = get_template(lettername)
  File "/home/mobilitysqr/.local/lib/python3.6/site-packages/django/template/loader.py", line 15, in get_template
    return engine.get_template(template_name)
  File "/home/mobilitysqr/.local/lib/python3.6/site-packages/django/template/backends/django.py", line 34, in get_template
    return Template(self.engine.get_template(template_name), self)
  File "/home/mobilitysqr/.local/lib/python3.6/site-packages/django/template/engine.py", line 144, in get_template
    template, origin = self.find_template(template_name)
  File "/home/mobilitysqr/.local/lib/python3.6/site-packages/django/template/engine.py", line 126, in find_template
    template = loader.get_template(name, skip=skip)
  File "/home/mobilitysqr/.local/lib/python3.6/site-packages/django/template/loaders/base.py", line 30, in get_template
    contents, origin, origin.template_name, self.engine,
  File "/home/mobilitysqr/.local/lib/python3.6/site-packages/django/template/base.py", line 156, in __init__
    self.nodelist = self.compile_nodelist()
  File "/home/mobilitysqr/.local/lib/python3.6/site-packages/django/template/base.py", line 194, in compile_nodelist
    return parser.parse()
  File "/home/mobilitysqr/.local/lib/python3.6/site-packages/django/template/base.py", line 449, in parse
    raise self.error(token, e)
  File "/home/mobilitysqr/.local/lib/python3.6/site-packages/django/template/base.py", line 447, in parse
    filter_expression = self.compile_filter(token.contents)
  File "/home/mobilitysqr/.local/lib/python3.6/site-packages/django/template/base.py", line 563, in compile_filter
    return FilterExpression(token, self)
  File "/home/mobilitysqr/.local/lib/python3.6/site-packages/django/template/base.py", line 663, in __init__
    "from '%s'" % (token[upto:], token))
django.template.exceptions.TemplateSyntaxError: Could not parse the remainder: '</span><span style="background-color: transparent; font-size: 1rem;">' from 'AssigneeName</span><span style="background-color: transparent; font-size: 1rem;">'
ERROR|22/Dec/2020 14:01:16|basehttp|2045|139917586929408|"GET /getassignmentletter/?travel_req_id=TR298741 HTTP/1.1" 500 35213
ERROR|22/Dec/2020 14:02:24|log|2045|139917586929408|Internal Server Error: /getassignmentletter/
Traceback (most recent call last):
  File "/home/mobilitysqr/.local/lib/python3.6/site-packages/django/core/handlers/exception.py", line 34, in inner
    response = get_response(request)
  File "/home/mobilitysqr/.local/lib/python3.6/site-packages/django/core/handlers/base.py", line 126, in _get_response
    response = self.process_exception_by_middleware(e, request)
  File "/home/mobilitysqr/.local/lib/python3.6/site-packages/django/core/handlers/base.py", line 124, in _get_response
    response = wrapped_callback(request, *callback_args, **callback_kwargs)
  File "/home/mobilitysqr/.local/lib/python3.6/site-packages/django/views/decorators/csrf.py", line 54, in wrapped_view
    return view_func(*args, **kwargs)
  File "/home/mobilitysqr/.local/lib/python3.6/site-packages/django/views/generic/base.py", line 68, in view
    return self.dispatch(request, *args, **kwargs)
  File "/home/mobilitysqr/.local/lib/python3.6/site-packages/rest_framework/views.py", line 495, in dispatch
    response = self.handle_exception(exc)
  File "/home/mobilitysqr/.local/lib/python3.6/site-packages/rest_framework/views.py", line 455, in handle_exception
    self.raise_uncaught_exception(exc)
  File "/home/mobilitysqr/.local/lib/python3.6/site-packages/rest_framework/views.py", line 492, in dispatch
    response = handler(request, *args, **kwargs)
  File "/var/www/html/mobilitysqrapi/mobility_apps/letter/views.py", line 317, in get
    template = get_template(lettername)
  File "/home/mobilitysqr/.local/lib/python3.6/site-packages/django/template/loader.py", line 15, in get_template
    return engine.get_template(template_name)
  File "/home/mobilitysqr/.local/lib/python3.6/site-packages/django/template/backends/django.py", line 34, in get_template
    return Template(self.engine.get_template(template_name), self)
  File "/home/mobilitysqr/.local/lib/python3.6/site-packages/django/template/engine.py", line 144, in get_template
    template, origin = self.find_template(template_name)
  File "/home/mobilitysqr/.local/lib/python3.6/site-packages/django/template/engine.py", line 126, in find_template
    template = loader.get_template(name, skip=skip)
  File "/home/mobilitysqr/.local/lib/python3.6/site-packages/django/template/loaders/base.py", line 30, in get_template
    contents, origin, origin.template_name, self.engine,
  File "/home/mobilitysqr/.local/lib/python3.6/site-packages/django/template/base.py", line 156, in __init__
    self.nodelist = self.compile_nodelist()
  File "/home/mobilitysqr/.local/lib/python3.6/site-packages/django/template/base.py", line 194, in compile_nodelist
    return parser.parse()
  File "/home/mobilitysqr/.local/lib/python3.6/site-packages/django/template/base.py", line 449, in parse
    raise self.error(token, e)
  File "/home/mobilitysqr/.local/lib/python3.6/site-packages/django/template/base.py", line 447, in parse
    filter_expression = self.compile_filter(token.contents)
  File "/home/mobilitysqr/.local/lib/python3.6/site-packages/django/template/base.py", line 563, in compile_filter
    return FilterExpression(token, self)
  File "/home/mobilitysqr/.local/lib/python3.6/site-packages/django/template/base.py", line 663, in __init__
    "from '%s'" % (token[upto:], token))
django.template.exceptions.TemplateSyntaxError: Could not parse the remainder: ' Housing Allowance' from 'Host Housing Allowance'
ERROR|22/Dec/2020 14:02:24|basehttp|2045|139917586929408|"GET /getassignmentletter/?travel_req_id=TR298741 HTTP/1.1" 500 34379
ERROR|22/Dec/2020 14:46:46|log|2045|139917586929408|Internal Server Error: /currency_conversion_history/
Traceback (most recent call last):
  File "/home/mobilitysqr/.local/lib/python3.6/site-packages/django/db/models/fields/__init__.py", line 1380, in to_python
    parsed = parse_date(value)
  File "/home/mobilitysqr/.local/lib/python3.6/site-packages/django/utils/dateparse.py", line 77, in parse_date
    return datetime.date(**kw)
ValueError: month must be in 1..12

During handling of the above exception, another exception occurred:

Traceback (most recent call last):
  File "/home/mobilitysqr/.local/lib/python3.6/site-packages/django/core/handlers/exception.py", line 34, in inner
    response = get_response(request)
  File "/home/mobilitysqr/.local/lib/python3.6/site-packages/django/core/handlers/base.py", line 126, in _get_response
    response = self.process_exception_by_middleware(e, request)
  File "/home/mobilitysqr/.local/lib/python3.6/site-packages/django/core/handlers/base.py", line 124, in _get_response
    response = wrapped_callback(request, *callback_args, **callback_kwargs)
  File "/home/mobilitysqr/.local/lib/python3.6/site-packages/django/views/decorators/csrf.py", line 54, in wrapped_view
    return view_func(*args, **kwargs)
  File "/home/mobilitysqr/.local/lib/python3.6/site-packages/django/views/generic/base.py", line 68, in view
    return self.dispatch(request, *args, **kwargs)
  File "/home/mobilitysqr/.local/lib/python3.6/site-packages/rest_framework/views.py", line 495, in dispatch
    response = self.handle_exception(exc)
  File "/home/mobilitysqr/.local/lib/python3.6/site-packages/rest_framework/views.py", line 455, in handle_exception
    self.raise_uncaught_exception(exc)
  File "/home/mobilitysqr/.local/lib/python3.6/site-packages/rest_framework/views.py", line 492, in dispatch
    response = handler(request, *args, **kwargs)
  File "/var/www/html/mobilitysqrapi/mobility_apps/master/views/currency.py", line 305, in get
    currency = Currency_Conversion_History.objects.filter(from_currency=request.GET['from_currency'],to_currency=request.GET['to_currency'],conversion_date__gte=request.GET['from_date'],conversion_date__lte=request.GET['to_date'])
  File "/home/mobilitysqr/.local/lib/python3.6/site-packages/django/db/models/manager.py", line 82, in manager_method
    return getattr(self.get_queryset(), name)(*args, **kwargs)
  File "/home/mobilitysqr/.local/lib/python3.6/site-packages/django/db/models/query.py", line 841, in filter
    return self._filter_or_exclude(False, *args, **kwargs)
  File "/home/mobilitysqr/.local/lib/python3.6/site-packages/django/db/models/query.py", line 859, in _filter_or_exclude
    clone.query.add_q(Q(*args, **kwargs))
  File "/home/mobilitysqr/.local/lib/python3.6/site-packages/django/db/models/sql/query.py", line 1263, in add_q
    clause, _ = self._add_q(q_object, self.used_aliases)
  File "/home/mobilitysqr/.local/lib/python3.6/site-packages/django/db/models/sql/query.py", line 1287, in _add_q
    split_subq=split_subq,
  File "/home/mobilitysqr/.local/lib/python3.6/site-packages/django/db/models/sql/query.py", line 1225, in build_filter
    condition = self.build_lookup(lookups, col, value)
  File "/home/mobilitysqr/.local/lib/python3.6/site-packages/django/db/models/sql/query.py", line 1096, in build_lookup
    lookup = lookup_class(lhs, rhs)
  File "/home/mobilitysqr/.local/lib/python3.6/site-packages/django/db/models/lookups.py", line 20, in __init__
    self.rhs = self.get_prep_lookup()
  File "/home/mobilitysqr/.local/lib/python3.6/site-packages/django/db/models/lookups.py", line 70, in get_prep_lookup
    return self.lhs.output_field.get_prep_value(self.rhs)
  File "/home/mobilitysqr/.local/lib/python3.6/site-packages/django/db/models/fields/__init__.py", line 1408, in get_prep_value
    value = super().get_prep_value(value)
  File "/home/mobilitysqr/.local/lib/python3.6/site-packages/django/db/models/fields/__init__.py", line 1268, in get_prep_value
    return self.to_python(value)
  File "/home/mobilitysqr/.local/lib/python3.6/site-packages/django/db/models/fields/__init__.py", line 1387, in to_python
    params={'value': value},
django.core.exceptions.ValidationError: ["'2000-28-12' value has the correct format (YYYY-MM-DD) but it is an invalid date."]
ERROR|22/Dec/2020 14:46:46|basehttp|2045|139917586929408|"GET /currency_conversion_history/?from_date=2000-28-12&to_date=2020-22-12&from_currency=USD&to_currency=DEM HTTP/1.1" 500 20190
ERROR|22/Dec/2020 14:46:59|log|2045|139917586929408|Internal Server Error: /currency_conversion_history/
Traceback (most recent call last):
  File "/home/mobilitysqr/.local/lib/python3.6/site-packages/django/db/models/fields/__init__.py", line 1380, in to_python
    parsed = parse_date(value)
  File "/home/mobilitysqr/.local/lib/python3.6/site-packages/django/utils/dateparse.py", line 77, in parse_date
    return datetime.date(**kw)
ValueError: month must be in 1..12

During handling of the above exception, another exception occurred:

Traceback (most recent call last):
  File "/home/mobilitysqr/.local/lib/python3.6/site-packages/django/core/handlers/exception.py", line 34, in inner
    response = get_response(request)
  File "/home/mobilitysqr/.local/lib/python3.6/site-packages/django/core/handlers/base.py", line 126, in _get_response
    response = self.process_exception_by_middleware(e, request)
  File "/home/mobilitysqr/.local/lib/python3.6/site-packages/django/core/handlers/base.py", line 124, in _get_response
    response = wrapped_callback(request, *callback_args, **callback_kwargs)
  File "/home/mobilitysqr/.local/lib/python3.6/site-packages/django/views/decorators/csrf.py", line 54, in wrapped_view
    return view_func(*args, **kwargs)
  File "/home/mobilitysqr/.local/lib/python3.6/site-packages/django/views/generic/base.py", line 68, in view
    return self.dispatch(request, *args, **kwargs)
  File "/home/mobilitysqr/.local/lib/python3.6/site-packages/rest_framework/views.py", line 495, in dispatch
    response = self.handle_exception(exc)
  File "/home/mobilitysqr/.local/lib/python3.6/site-packages/rest_framework/views.py", line 455, in handle_exception
    self.raise_uncaught_exception(exc)
  File "/home/mobilitysqr/.local/lib/python3.6/site-packages/rest_framework/views.py", line 492, in dispatch
    response = handler(request, *args, **kwargs)
  File "/var/www/html/mobilitysqrapi/mobility_apps/master/views/currency.py", line 305, in get
    currency = Currency_Conversion_History.objects.filter(from_currency=request.GET['from_currency'],to_currency=request.GET['to_currency'],conversion_date__gte=request.GET['from_date'],conversion_date__lte=request.GET['to_date'])
  File "/home/mobilitysqr/.local/lib/python3.6/site-packages/django/db/models/manager.py", line 82, in manager_method
    return getattr(self.get_queryset(), name)(*args, **kwargs)
  File "/home/mobilitysqr/.local/lib/python3.6/site-packages/django/db/models/query.py", line 841, in filter
    return self._filter_or_exclude(False, *args, **kwargs)
  File "/home/mobilitysqr/.local/lib/python3.6/site-packages/django/db/models/query.py", line 859, in _filter_or_exclude
    clone.query.add_q(Q(*args, **kwargs))
  File "/home/mobilitysqr/.local/lib/python3.6/site-packages/django/db/models/sql/query.py", line 1263, in add_q
    clause, _ = self._add_q(q_object, self.used_aliases)
  File "/home/mobilitysqr/.local/lib/python3.6/site-packages/django/db/models/sql/query.py", line 1287, in _add_q
    split_subq=split_subq,
  File "/home/mobilitysqr/.local/lib/python3.6/site-packages/django/db/models/sql/query.py", line 1225, in build_filter
    condition = self.build_lookup(lookups, col, value)
  File "/home/mobilitysqr/.local/lib/python3.6/site-packages/django/db/models/sql/query.py", line 1096, in build_lookup
    lookup = lookup_class(lhs, rhs)
  File "/home/mobilitysqr/.local/lib/python3.6/site-packages/django/db/models/lookups.py", line 20, in __init__
    self.rhs = self.get_prep_lookup()
  File "/home/mobilitysqr/.local/lib/python3.6/site-packages/django/db/models/lookups.py", line 70, in get_prep_lookup
    return self.lhs.output_field.get_prep_value(self.rhs)
  File "/home/mobilitysqr/.local/lib/python3.6/site-packages/django/db/models/fields/__init__.py", line 1408, in get_prep_value
    value = super().get_prep_value(value)
  File "/home/mobilitysqr/.local/lib/python3.6/site-packages/django/db/models/fields/__init__.py", line 1268, in get_prep_value
    return self.to_python(value)
  File "/home/mobilitysqr/.local/lib/python3.6/site-packages/django/db/models/fields/__init__.py", line 1387, in to_python
    params={'value': value},
django.core.exceptions.ValidationError: ["'2000-28-12' value has the correct format (YYYY-MM-DD) but it is an invalid date."]
ERROR|22/Dec/2020 14:46:59|basehttp|2045|139917586929408|"GET /currency_conversion_history/?from_date=2000-28-12&to_date=2020-22-12&from_currency=USD&to_currency=DEM HTTP/1.1" 500 20210
ERROR|22/Dec/2020 15:02:55|log|2045|139917334140672|Internal Server Error: /currency_conversion_history/
Traceback (most recent call last):
  File "/home/mobilitysqr/.local/lib/python3.6/site-packages/django/db/models/fields/__init__.py", line 1380, in to_python
    parsed = parse_date(value)
  File "/home/mobilitysqr/.local/lib/python3.6/site-packages/django/utils/dateparse.py", line 77, in parse_date
    return datetime.date(**kw)
ValueError: month must be in 1..12

During handling of the above exception, another exception occurred:

Traceback (most recent call last):
  File "/home/mobilitysqr/.local/lib/python3.6/site-packages/django/core/handlers/exception.py", line 34, in inner
    response = get_response(request)
  File "/home/mobilitysqr/.local/lib/python3.6/site-packages/django/core/handlers/base.py", line 126, in _get_response
    response = self.process_exception_by_middleware(e, request)
  File "/home/mobilitysqr/.local/lib/python3.6/site-packages/django/core/handlers/base.py", line 124, in _get_response
    response = wrapped_callback(request, *callback_args, **callback_kwargs)
  File "/home/mobilitysqr/.local/lib/python3.6/site-packages/django/views/decorators/csrf.py", line 54, in wrapped_view
    return view_func(*args, **kwargs)
  File "/home/mobilitysqr/.local/lib/python3.6/site-packages/django/views/generic/base.py", line 68, in view
    return self.dispatch(request, *args, **kwargs)
  File "/home/mobilitysqr/.local/lib/python3.6/site-packages/rest_framework/views.py", line 495, in dispatch
    response = self.handle_exception(exc)
  File "/home/mobilitysqr/.local/lib/python3.6/site-packages/rest_framework/views.py", line 455, in handle_exception
    self.raise_uncaught_exception(exc)
  File "/home/mobilitysqr/.local/lib/python3.6/site-packages/rest_framework/views.py", line 492, in dispatch
    response = handler(request, *args, **kwargs)
  File "/var/www/html/mobilitysqrapi/mobility_apps/master/views/currency.py", line 305, in get
    currency = Currency_Conversion_History.objects.filter(from_currency=request.GET['from_currency'],to_currency=request.GET['to_currency'],conversion_date__gte=request.GET['from_date'],conversion_date__lte=request.GET['to_date'])
  File "/home/mobilitysqr/.local/lib/python3.6/site-packages/django/db/models/manager.py", line 82, in manager_method
    return getattr(self.get_queryset(), name)(*args, **kwargs)
  File "/home/mobilitysqr/.local/lib/python3.6/site-packages/django/db/models/query.py", line 841, in filter
    return self._filter_or_exclude(False, *args, **kwargs)
  File "/home/mobilitysqr/.local/lib/python3.6/site-packages/django/db/models/query.py", line 859, in _filter_or_exclude
    clone.query.add_q(Q(*args, **kwargs))
  File "/home/mobilitysqr/.local/lib/python3.6/site-packages/django/db/models/sql/query.py", line 1263, in add_q
    clause, _ = self._add_q(q_object, self.used_aliases)
  File "/home/mobilitysqr/.local/lib/python3.6/site-packages/django/db/models/sql/query.py", line 1287, in _add_q
    split_subq=split_subq,
  File "/home/mobilitysqr/.local/lib/python3.6/site-packages/django/db/models/sql/query.py", line 1225, in build_filter
    condition = self.build_lookup(lookups, col, value)
  File "/home/mobilitysqr/.local/lib/python3.6/site-packages/django/db/models/sql/query.py", line 1096, in build_lookup
    lookup = lookup_class(lhs, rhs)
  File "/home/mobilitysqr/.local/lib/python3.6/site-packages/django/db/models/lookups.py", line 20, in __init__
    self.rhs = self.get_prep_lookup()
  File "/home/mobilitysqr/.local/lib/python3.6/site-packages/django/db/models/lookups.py", line 70, in get_prep_lookup
    return self.lhs.output_field.get_prep_value(self.rhs)
  File "/home/mobilitysqr/.local/lib/python3.6/site-packages/django/db/models/fields/__init__.py", line 1408, in get_prep_value
    value = super().get_prep_value(value)
  File "/home/mobilitysqr/.local/lib/python3.6/site-packages/django/db/models/fields/__init__.py", line 1268, in get_prep_value
    return self.to_python(value)
  File "/home/mobilitysqr/.local/lib/python3.6/site-packages/django/db/models/fields/__init__.py", line 1387, in to_python
    params={'value': value},
django.core.exceptions.ValidationError: ["'2020-21-12' value has the correct format (YYYY-MM-DD) but it is an invalid date."]
ERROR|22/Dec/2020 15:02:55|basehttp|2045|139917334140672|"GET /currency_conversion_history/?from_date=2020-21-12&to_date=2020-23-12&from_currency=USD&to_currency=INR HTTP/1.1" 500 20189
ERROR|22/Dec/2020 15:03:02|log|2045|139917334140672|Internal Server Error: /currency_conversion_history/
Traceback (most recent call last):
  File "/home/mobilitysqr/.local/lib/python3.6/site-packages/django/db/models/fields/__init__.py", line 1380, in to_python
    parsed = parse_date(value)
  File "/home/mobilitysqr/.local/lib/python3.6/site-packages/django/utils/dateparse.py", line 77, in parse_date
    return datetime.date(**kw)
ValueError: month must be in 1..12

During handling of the above exception, another exception occurred:

Traceback (most recent call last):
  File "/home/mobilitysqr/.local/lib/python3.6/site-packages/django/core/handlers/exception.py", line 34, in inner
    response = get_response(request)
  File "/home/mobilitysqr/.local/lib/python3.6/site-packages/django/core/handlers/base.py", line 126, in _get_response
    response = self.process_exception_by_middleware(e, request)
  File "/home/mobilitysqr/.local/lib/python3.6/site-packages/django/core/handlers/base.py", line 124, in _get_response
    response = wrapped_callback(request, *callback_args, **callback_kwargs)
  File "/home/mobilitysqr/.local/lib/python3.6/site-packages/django/views/decorators/csrf.py", line 54, in wrapped_view
    return view_func(*args, **kwargs)
  File "/home/mobilitysqr/.local/lib/python3.6/site-packages/django/views/generic/base.py", line 68, in view
    return self.dispatch(request, *args, **kwargs)
  File "/home/mobilitysqr/.local/lib/python3.6/site-packages/rest_framework/views.py", line 495, in dispatch
    response = self.handle_exception(exc)
  File "/home/mobilitysqr/.local/lib/python3.6/site-packages/rest_framework/views.py", line 455, in handle_exception
    self.raise_uncaught_exception(exc)
  File "/home/mobilitysqr/.local/lib/python3.6/site-packages/rest_framework/views.py", line 492, in dispatch
    response = handler(request, *args, **kwargs)
  File "/var/www/html/mobilitysqrapi/mobility_apps/master/views/currency.py", line 305, in get
    currency = Currency_Conversion_History.objects.filter(from_currency=request.GET['from_currency'],to_currency=request.GET['to_currency'],conversion_date__gte=request.GET['from_date'],conversion_date__lte=request.GET['to_date'])
  File "/home/mobilitysqr/.local/lib/python3.6/site-packages/django/db/models/manager.py", line 82, in manager_method
    return getattr(self.get_queryset(), name)(*args, **kwargs)
  File "/home/mobilitysqr/.local/lib/python3.6/site-packages/django/db/models/query.py", line 841, in filter
    return self._filter_or_exclude(False, *args, **kwargs)
  File "/home/mobilitysqr/.local/lib/python3.6/site-packages/django/db/models/query.py", line 859, in _filter_or_exclude
    clone.query.add_q(Q(*args, **kwargs))
  File "/home/mobilitysqr/.local/lib/python3.6/site-packages/django/db/models/sql/query.py", line 1263, in add_q
    clause, _ = self._add_q(q_object, self.used_aliases)
  File "/home/mobilitysqr/.local/lib/python3.6/site-packages/django/db/models/sql/query.py", line 1287, in _add_q
    split_subq=split_subq,
  File "/home/mobilitysqr/.local/lib/python3.6/site-packages/django/db/models/sql/query.py", line 1225, in build_filter
    condition = self.build_lookup(lookups, col, value)
  File "/home/mobilitysqr/.local/lib/python3.6/site-packages/django/db/models/sql/query.py", line 1096, in build_lookup
    lookup = lookup_class(lhs, rhs)
  File "/home/mobilitysqr/.local/lib/python3.6/site-packages/django/db/models/lookups.py", line 20, in __init__
    self.rhs = self.get_prep_lookup()
  File "/home/mobilitysqr/.local/lib/python3.6/site-packages/django/db/models/lookups.py", line 70, in get_prep_lookup
    return self.lhs.output_field.get_prep_value(self.rhs)
  File "/home/mobilitysqr/.local/lib/python3.6/site-packages/django/db/models/fields/__init__.py", line 1408, in get_prep_value
    value = super().get_prep_value(value)
  File "/home/mobilitysqr/.local/lib/python3.6/site-packages/django/db/models/fields/__init__.py", line 1268, in get_prep_value
    return self.to_python(value)
  File "/home/mobilitysqr/.local/lib/python3.6/site-packages/django/db/models/fields/__init__.py", line 1387, in to_python
    params={'value': value},
django.core.exceptions.ValidationError: ["'2020-21-12' value has the correct format (YYYY-MM-DD) but it is an invalid date."]
ERROR|22/Dec/2020 15:03:02|basehttp|2045|139917334140672|"GET /currency_conversion_history/?from_date=2020-21-12&to_date=2020-23-12&from_currency=USD&to_currency=INR HTTP/1.1" 500 20188
ERROR|22/Dec/2020 15:54:45|log|8598|140612144461568|Internal Server Error: /getassignmentletter/
Traceback (most recent call last):
  File "/home/mobilitysqr/.local/lib/python3.6/site-packages/django/core/handlers/exception.py", line 34, in inner
    response = get_response(request)
  File "/home/mobilitysqr/.local/lib/python3.6/site-packages/django/core/handlers/base.py", line 126, in _get_response
    response = self.process_exception_by_middleware(e, request)
  File "/home/mobilitysqr/.local/lib/python3.6/site-packages/django/core/handlers/base.py", line 124, in _get_response
    response = wrapped_callback(request, *callback_args, **callback_kwargs)
  File "/home/mobilitysqr/.local/lib/python3.6/site-packages/django/views/decorators/csrf.py", line 54, in wrapped_view
    return view_func(*args, **kwargs)
  File "/home/mobilitysqr/.local/lib/python3.6/site-packages/django/views/generic/base.py", line 68, in view
    return self.dispatch(request, *args, **kwargs)
  File "/home/mobilitysqr/.local/lib/python3.6/site-packages/rest_framework/views.py", line 495, in dispatch
    response = self.handle_exception(exc)
  File "/home/mobilitysqr/.local/lib/python3.6/site-packages/rest_framework/views.py", line 455, in handle_exception
    self.raise_uncaught_exception(exc)
  File "/home/mobilitysqr/.local/lib/python3.6/site-packages/rest_framework/views.py", line 492, in dispatch
    response = handler(request, *args, **kwargs)
  File "/var/www/html/mobilitysqrapi/mobility_apps/letter/views.py", line 163, in get
    datas['VisaValidity']=self.date_format(date=data['details'][i]['visa_expiry_date'])
  File "/var/www/html/mobilitysqrapi/mobility_apps/letter/views.py", line 648, in date_format
    dt = datetime(str(date))
TypeError: an integer is required (got type str)
ERROR|22/Dec/2020 15:54:45|basehttp|8598|140612144461568|"GET /getassignmentletter/?travel_req_id=TR325676 HTTP/1.1" 500 17490
ERROR|22/Dec/2020 15:54:51|log|8598|140612144461568|Internal Server Error: /getassignmentletter/
Traceback (most recent call last):
  File "/home/mobilitysqr/.local/lib/python3.6/site-packages/django/core/handlers/exception.py", line 34, in inner
    response = get_response(request)
  File "/home/mobilitysqr/.local/lib/python3.6/site-packages/django/core/handlers/base.py", line 126, in _get_response
    response = self.process_exception_by_middleware(e, request)
  File "/home/mobilitysqr/.local/lib/python3.6/site-packages/django/core/handlers/base.py", line 124, in _get_response
    response = wrapped_callback(request, *callback_args, **callback_kwargs)
  File "/home/mobilitysqr/.local/lib/python3.6/site-packages/django/views/decorators/csrf.py", line 54, in wrapped_view
    return view_func(*args, **kwargs)
  File "/home/mobilitysqr/.local/lib/python3.6/site-packages/django/views/generic/base.py", line 68, in view
    return self.dispatch(request, *args, **kwargs)
  File "/home/mobilitysqr/.local/lib/python3.6/site-packages/rest_framework/views.py", line 495, in dispatch
    response = self.handle_exception(exc)
  File "/home/mobilitysqr/.local/lib/python3.6/site-packages/rest_framework/views.py", line 455, in handle_exception
    self.raise_uncaught_exception(exc)
  File "/home/mobilitysqr/.local/lib/python3.6/site-packages/rest_framework/views.py", line 492, in dispatch
    response = handler(request, *args, **kwargs)
  File "/var/www/html/mobilitysqrapi/mobility_apps/letter/views.py", line 163, in get
    datas['VisaValidity']=self.date_format(date=data['details'][i]['visa_expiry_date'])
  File "/var/www/html/mobilitysqrapi/mobility_apps/letter/views.py", line 648, in date_format
    dt = datetime(str(date))
TypeError: an integer is required (got type str)
ERROR|22/Dec/2020 15:54:51|basehttp|8598|140612144461568|"GET /getassignmentletter/?travel_req_id=TR325676 HTTP/1.1" 500 17490
ERROR|22/Dec/2020 15:55:11|log|8598|140612061886208|Internal Server Error: /getassignmentletter/
Traceback (most recent call last):
  File "/home/mobilitysqr/.local/lib/python3.6/site-packages/django/core/handlers/exception.py", line 34, in inner
    response = get_response(request)
  File "/home/mobilitysqr/.local/lib/python3.6/site-packages/django/core/handlers/base.py", line 126, in _get_response
    response = self.process_exception_by_middleware(e, request)
  File "/home/mobilitysqr/.local/lib/python3.6/site-packages/django/core/handlers/base.py", line 124, in _get_response
    response = wrapped_callback(request, *callback_args, **callback_kwargs)
  File "/home/mobilitysqr/.local/lib/python3.6/site-packages/django/views/decorators/csrf.py", line 54, in wrapped_view
    return view_func(*args, **kwargs)
  File "/home/mobilitysqr/.local/lib/python3.6/site-packages/django/views/generic/base.py", line 68, in view
    return self.dispatch(request, *args, **kwargs)
  File "/home/mobilitysqr/.local/lib/python3.6/site-packages/rest_framework/views.py", line 495, in dispatch
    response = self.handle_exception(exc)
  File "/home/mobilitysqr/.local/lib/python3.6/site-packages/rest_framework/views.py", line 455, in handle_exception
    self.raise_uncaught_exception(exc)
  File "/home/mobilitysqr/.local/lib/python3.6/site-packages/rest_framework/views.py", line 492, in dispatch
    response = handler(request, *args, **kwargs)
  File "/var/www/html/mobilitysqrapi/mobility_apps/letter/views.py", line 163, in get
    datas['VisaValidity']=self.date_format(date=data['details'][i]['visa_expiry_date'])
  File "/var/www/html/mobilitysqrapi/mobility_apps/letter/views.py", line 648, in date_format
    dt = datetime(str(date))
TypeError: an integer is required (got type str)
ERROR|22/Dec/2020 15:55:11|basehttp|8598|140612061886208|"GET /getassignmentletter/?travel_req_id=TR325676 HTTP/1.1" 500 17490
ERROR|22/Dec/2020 15:55:50|log|8598|140612144461568|Internal Server Error: /getassignmentletter/
Traceback (most recent call last):
  File "/home/mobilitysqr/.local/lib/python3.6/site-packages/django/core/handlers/exception.py", line 34, in inner
    response = get_response(request)
  File "/home/mobilitysqr/.local/lib/python3.6/site-packages/django/core/handlers/base.py", line 126, in _get_response
    response = self.process_exception_by_middleware(e, request)
  File "/home/mobilitysqr/.local/lib/python3.6/site-packages/django/core/handlers/base.py", line 124, in _get_response
    response = wrapped_callback(request, *callback_args, **callback_kwargs)
  File "/home/mobilitysqr/.local/lib/python3.6/site-packages/django/views/decorators/csrf.py", line 54, in wrapped_view
    return view_func(*args, **kwargs)
  File "/home/mobilitysqr/.local/lib/python3.6/site-packages/django/views/generic/base.py", line 68, in view
    return self.dispatch(request, *args, **kwargs)
  File "/home/mobilitysqr/.local/lib/python3.6/site-packages/rest_framework/views.py", line 495, in dispatch
    response = self.handle_exception(exc)
  File "/home/mobilitysqr/.local/lib/python3.6/site-packages/rest_framework/views.py", line 455, in handle_exception
    self.raise_uncaught_exception(exc)
  File "/home/mobilitysqr/.local/lib/python3.6/site-packages/rest_framework/views.py", line 492, in dispatch
    response = handler(request, *args, **kwargs)
  File "/var/www/html/mobilitysqrapi/mobility_apps/letter/views.py", line 163, in get
    datas['VisaValidity']=self.date_format(date=data['details'][i]['visa_expiry_date'])
  File "/var/www/html/mobilitysqrapi/mobility_apps/letter/views.py", line 648, in date_format
    dt = datetime(str(date))
TypeError: an integer is required (got type str)
ERROR|22/Dec/2020 15:55:50|basehttp|8598|140612144461568|"GET /getassignmentletter/?travel_req_id=TR325676 HTTP/1.1" 500 17491
ERROR|22/Dec/2020 16:00:12|log|9676|139983218083584|Internal Server Error: /get_add/group/
Traceback (most recent call last):
  File "/home/mobilitysqr/.local/lib/python3.6/site-packages/django/core/handlers/exception.py", line 34, in inner
    response = get_response(request)
  File "/home/mobilitysqr/.local/lib/python3.6/site-packages/django/core/handlers/base.py", line 126, in _get_response
    response = self.process_exception_by_middleware(e, request)
  File "/home/mobilitysqr/.local/lib/python3.6/site-packages/django/core/handlers/base.py", line 124, in _get_response
    response = wrapped_callback(request, *callback_args, **callback_kwargs)
  File "/home/mobilitysqr/.local/lib/python3.6/site-packages/django/views/decorators/csrf.py", line 54, in wrapped_view
    return view_func(*args, **kwargs)
  File "/home/mobilitysqr/.local/lib/python3.6/site-packages/django/views/generic/base.py", line 68, in view
    return self.dispatch(request, *args, **kwargs)
  File "/home/mobilitysqr/.local/lib/python3.6/site-packages/rest_framework/views.py", line 495, in dispatch
    response = self.handle_exception(exc)
  File "/home/mobilitysqr/.local/lib/python3.6/site-packages/rest_framework/views.py", line 455, in handle_exception
    self.raise_uncaught_exception(exc)
  File "/home/mobilitysqr/.local/lib/python3.6/site-packages/rest_framework/views.py", line 492, in dispatch
    response = handler(request, *args, **kwargs)
  File "/var/www/html/mobilitysqrapi/mobility_apps/master/views/assignment_group.py", line 88, in get
    emp_code=Employee.objects.filter(emp_code=serializer.data[i]['emp_email']).values('email','emp_code','first_name','last_name')
  File "/home/mobilitysqr/.local/lib/python3.6/site-packages/rest_framework/serializers.py", line 768, in data
    ret = super(ListSerializer, self).data
  File "/home/mobilitysqr/.local/lib/python3.6/site-packages/rest_framework/serializers.py", line 262, in data
    self._data = self.to_representation(self.instance)
  File "/home/mobilitysqr/.local/lib/python3.6/site-packages/rest_framework/serializers.py", line 686, in to_representation
    self.child.to_representation(item) for item in iterable
TypeError: 'Assignment_Group' object is not iterable
ERROR|22/Dec/2020 16:00:12|basehttp|9676|139983218083584|"GET /get_add/group/ HTTP/1.1" 500 17855
ERROR|22/Dec/2020 16:01:02|log|9730|140528636491520|Internal Server Error: /get_add/group/
Traceback (most recent call last):
  File "/home/mobilitysqr/.local/lib/python3.6/site-packages/django/core/handlers/exception.py", line 34, in inner
    response = get_response(request)
  File "/home/mobilitysqr/.local/lib/python3.6/site-packages/django/core/handlers/base.py", line 126, in _get_response
    response = self.process_exception_by_middleware(e, request)
  File "/home/mobilitysqr/.local/lib/python3.6/site-packages/django/core/handlers/base.py", line 124, in _get_response
    response = wrapped_callback(request, *callback_args, **callback_kwargs)
  File "/home/mobilitysqr/.local/lib/python3.6/site-packages/django/views/decorators/csrf.py", line 54, in wrapped_view
    return view_func(*args, **kwargs)
  File "/home/mobilitysqr/.local/lib/python3.6/site-packages/django/views/generic/base.py", line 68, in view
    return self.dispatch(request, *args, **kwargs)
  File "/home/mobilitysqr/.local/lib/python3.6/site-packages/rest_framework/views.py", line 495, in dispatch
    response = self.handle_exception(exc)
  File "/home/mobilitysqr/.local/lib/python3.6/site-packages/rest_framework/views.py", line 455, in handle_exception
    self.raise_uncaught_exception(exc)
  File "/home/mobilitysqr/.local/lib/python3.6/site-packages/rest_framework/views.py", line 492, in dispatch
    response = handler(request, *args, **kwargs)
  File "/var/www/html/mobilitysqrapi/mobility_apps/master/views/assignment_group.py", line 88, in get
    emp_code=Employee.objects.filter(emp_code=serializer.data[i]['emp_email']).values('email','emp_code','first_name','last_name')
KeyError: 0
ERROR|22/Dec/2020 16:01:02|basehttp|9730|140528636491520|"GET /get_add/group/ HTTP/1.1" 500 17260
ERROR|22/Dec/2020 16:02:55|log|9927|140334721750784|Internal Server Error: /get_add/group/
Traceback (most recent call last):
  File "/home/mobilitysqr/.local/lib/python3.6/site-packages/django/core/handlers/exception.py", line 34, in inner
    response = get_response(request)
  File "/home/mobilitysqr/.local/lib/python3.6/site-packages/django/core/handlers/base.py", line 126, in _get_response
    response = self.process_exception_by_middleware(e, request)
  File "/home/mobilitysqr/.local/lib/python3.6/site-packages/django/core/handlers/base.py", line 124, in _get_response
    response = wrapped_callback(request, *callback_args, **callback_kwargs)
  File "/home/mobilitysqr/.local/lib/python3.6/site-packages/django/views/decorators/csrf.py", line 54, in wrapped_view
    return view_func(*args, **kwargs)
  File "/home/mobilitysqr/.local/lib/python3.6/site-packages/django/views/generic/base.py", line 68, in view
    return self.dispatch(request, *args, **kwargs)
  File "/home/mobilitysqr/.local/lib/python3.6/site-packages/rest_framework/views.py", line 495, in dispatch
    response = self.handle_exception(exc)
  File "/home/mobilitysqr/.local/lib/python3.6/site-packages/rest_framework/views.py", line 455, in handle_exception
    self.raise_uncaught_exception(exc)
  File "/home/mobilitysqr/.local/lib/python3.6/site-packages/rest_framework/views.py", line 492, in dispatch
    response = handler(request, *args, **kwargs)
  File "/var/www/html/mobilitysqrapi/mobility_apps/master/views/assignment_group.py", line 88, in get
    assigndata=Assignment_Group.objects.filter(id=data)
  File "/home/mobilitysqr/.local/lib/python3.6/site-packages/django/db/models/manager.py", line 82, in manager_method
    return getattr(self.get_queryset(), name)(*args, **kwargs)
  File "/home/mobilitysqr/.local/lib/python3.6/site-packages/django/db/models/query.py", line 841, in filter
    return self._filter_or_exclude(False, *args, **kwargs)
  File "/home/mobilitysqr/.local/lib/python3.6/site-packages/django/db/models/query.py", line 859, in _filter_or_exclude
    clone.query.add_q(Q(*args, **kwargs))
  File "/home/mobilitysqr/.local/lib/python3.6/site-packages/django/db/models/sql/query.py", line 1263, in add_q
    clause, _ = self._add_q(q_object, self.used_aliases)
  File "/home/mobilitysqr/.local/lib/python3.6/site-packages/django/db/models/sql/query.py", line 1287, in _add_q
    split_subq=split_subq,
  File "/home/mobilitysqr/.local/lib/python3.6/site-packages/django/db/models/sql/query.py", line 1225, in build_filter
    condition = self.build_lookup(lookups, col, value)
  File "/home/mobilitysqr/.local/lib/python3.6/site-packages/django/db/models/sql/query.py", line 1096, in build_lookup
    lookup = lookup_class(lhs, rhs)
  File "/home/mobilitysqr/.local/lib/python3.6/site-packages/django/db/models/lookups.py", line 20, in __init__
    self.rhs = self.get_prep_lookup()
  File "/home/mobilitysqr/.local/lib/python3.6/site-packages/django/db/models/lookups.py", line 70, in get_prep_lookup
    return self.lhs.output_field.get_prep_value(self.rhs)
  File "/home/mobilitysqr/.local/lib/python3.6/site-packages/django/db/models/fields/__init__.py", line 965, in get_prep_value
    return int(value)
TypeError: int() argument must be a string, a bytes-like object or a number, not 'Assignment_Group'
ERROR|22/Dec/2020 16:02:55|basehttp|9927|140334721750784|"GET /get_add/group/ HTTP/1.1" 500 19009
ERROR|22/Dec/2020 16:04:36|log|10110|139755936536320|Internal Server Error: /get_add/group/
Traceback (most recent call last):
  File "/home/mobilitysqr/.local/lib/python3.6/site-packages/django/core/handlers/exception.py", line 34, in inner
    response = get_response(request)
  File "/home/mobilitysqr/.local/lib/python3.6/site-packages/django/core/handlers/base.py", line 126, in _get_response
    response = self.process_exception_by_middleware(e, request)
  File "/home/mobilitysqr/.local/lib/python3.6/site-packages/django/core/handlers/base.py", line 124, in _get_response
    response = wrapped_callback(request, *callback_args, **callback_kwargs)
  File "/home/mobilitysqr/.local/lib/python3.6/site-packages/django/views/decorators/csrf.py", line 54, in wrapped_view
    return view_func(*args, **kwargs)
  File "/home/mobilitysqr/.local/lib/python3.6/site-packages/django/views/generic/base.py", line 68, in view
    return self.dispatch(request, *args, **kwargs)
  File "/home/mobilitysqr/.local/lib/python3.6/site-packages/rest_framework/views.py", line 495, in dispatch
    response = self.handle_exception(exc)
  File "/home/mobilitysqr/.local/lib/python3.6/site-packages/rest_framework/views.py", line 455, in handle_exception
    self.raise_uncaught_exception(exc)
  File "/home/mobilitysqr/.local/lib/python3.6/site-packages/rest_framework/views.py", line 492, in dispatch
    response = handler(request, *args, **kwargs)
  File "/var/www/html/mobilitysqrapi/mobility_apps/master/views/assignment_group.py", line 86, in get
    assignment_group=serializer.data
UnboundLocalError: local variable 'serializer' referenced before assignment
ERROR|22/Dec/2020 16:04:36|basehttp|10110|139755936536320|"GET /get_add/group/ HTTP/1.1" 500 17290
ERROR|22/Dec/2020 16:06:32|log|10283|140006311839488|Internal Server Error: /get_add/group/
Traceback (most recent call last):
  File "/home/mobilitysqr/.local/lib/python3.6/site-packages/django/core/handlers/exception.py", line 34, in inner
    response = get_response(request)
  File "/home/mobilitysqr/.local/lib/python3.6/site-packages/django/core/handlers/base.py", line 126, in _get_response
    response = self.process_exception_by_middleware(e, request)
  File "/home/mobilitysqr/.local/lib/python3.6/site-packages/django/core/handlers/base.py", line 124, in _get_response
    response = wrapped_callback(request, *callback_args, **callback_kwargs)
  File "/home/mobilitysqr/.local/lib/python3.6/site-packages/django/views/decorators/csrf.py", line 54, in wrapped_view
    return view_func(*args, **kwargs)
  File "/home/mobilitysqr/.local/lib/python3.6/site-packages/django/views/generic/base.py", line 68, in view
    return self.dispatch(request, *args, **kwargs)
  File "/home/mobilitysqr/.local/lib/python3.6/site-packages/rest_framework/views.py", line 495, in dispatch
    response = self.handle_exception(exc)
  File "/home/mobilitysqr/.local/lib/python3.6/site-packages/rest_framework/views.py", line 455, in handle_exception
    self.raise_uncaught_exception(exc)
  File "/home/mobilitysqr/.local/lib/python3.6/site-packages/rest_framework/views.py", line 492, in dispatch
    response = handler(request, *args, **kwargs)
  File "/var/www/html/mobilitysqrapi/mobility_apps/master/views/assignment_group.py", line 86, in get
    serializer=Assignment_GroupSerializers(assignment_group,many=True)
NameError: name 'assignment_group' is not defined
ERROR|22/Dec/2020 16:06:32|basehttp|10283|140006311839488|"GET /get_add/group/ HTTP/1.1" 500 17272
ERROR|22/Dec/2020 16:07:37|log|10283|140006320494336|Internal Server Error: /get_add/group/
Traceback (most recent call last):
  File "/home/mobilitysqr/.local/lib/python3.6/site-packages/django/core/handlers/exception.py", line 34, in inner
    response = get_response(request)
  File "/home/mobilitysqr/.local/lib/python3.6/site-packages/django/core/handlers/base.py", line 126, in _get_response
    response = self.process_exception_by_middleware(e, request)
  File "/home/mobilitysqr/.local/lib/python3.6/site-packages/django/core/handlers/base.py", line 124, in _get_response
    response = wrapped_callback(request, *callback_args, **callback_kwargs)
  File "/home/mobilitysqr/.local/lib/python3.6/site-packages/django/views/decorators/csrf.py", line 54, in wrapped_view
    return view_func(*args, **kwargs)
  File "/home/mobilitysqr/.local/lib/python3.6/site-packages/django/views/generic/base.py", line 68, in view
    return self.dispatch(request, *args, **kwargs)
  File "/home/mobilitysqr/.local/lib/python3.6/site-packages/rest_framework/views.py", line 495, in dispatch
    response = self.handle_exception(exc)
  File "/home/mobilitysqr/.local/lib/python3.6/site-packages/rest_framework/views.py", line 455, in handle_exception
    self.raise_uncaught_exception(exc)
  File "/home/mobilitysqr/.local/lib/python3.6/site-packages/rest_framework/views.py", line 492, in dispatch
    response = handler(request, *args, **kwargs)
  File "/var/www/html/mobilitysqrapi/mobility_apps/master/views/assignment_group.py", line 86, in get
    serializer=Assignment_GroupSerializers(assignment_group,many=True)
NameError: name 'assignment_group' is not defined
ERROR|22/Dec/2020 16:07:37|basehttp|10283|140006320494336|"GET /get_add/group/ HTTP/1.1" 500 17272
ERROR|22/Dec/2020 16:08:55|log|10654|140153708345088|Internal Server Error: /get_add/group/
Traceback (most recent call last):
  File "/home/mobilitysqr/.local/lib/python3.6/site-packages/django/core/handlers/exception.py", line 34, in inner
    response = get_response(request)
  File "/home/mobilitysqr/.local/lib/python3.6/site-packages/django/core/handlers/base.py", line 126, in _get_response
    response = self.process_exception_by_middleware(e, request)
  File "/home/mobilitysqr/.local/lib/python3.6/site-packages/django/core/handlers/base.py", line 124, in _get_response
    response = wrapped_callback(request, *callback_args, **callback_kwargs)
  File "/home/mobilitysqr/.local/lib/python3.6/site-packages/django/views/decorators/csrf.py", line 54, in wrapped_view
    return view_func(*args, **kwargs)
  File "/home/mobilitysqr/.local/lib/python3.6/site-packages/django/views/generic/base.py", line 68, in view
    return self.dispatch(request, *args, **kwargs)
  File "/home/mobilitysqr/.local/lib/python3.6/site-packages/rest_framework/views.py", line 495, in dispatch
    response = self.handle_exception(exc)
  File "/home/mobilitysqr/.local/lib/python3.6/site-packages/rest_framework/views.py", line 455, in handle_exception
    self.raise_uncaught_exception(exc)
  File "/home/mobilitysqr/.local/lib/python3.6/site-packages/rest_framework/views.py", line 492, in dispatch
    response = handler(request, *args, **kwargs)
  File "/var/www/html/mobilitysqrapi/mobility_apps/master/views/assignment_group.py", line 89, in get
    print(data['email'])
TypeError: 'Assignment_Group' object is not subscriptable
ERROR|22/Dec/2020 16:08:55|basehttp|10654|140153708345088|"GET /get_add/group/ HTTP/1.1" 500 17246
ERROR|22/Dec/2020 16:09:43|log|10716|140203019450112|Internal Server Error: /get_add/group/
Traceback (most recent call last):
  File "/home/mobilitysqr/.local/lib/python3.6/site-packages/django/core/handlers/exception.py", line 34, in inner
    response = get_response(request)
  File "/home/mobilitysqr/.local/lib/python3.6/site-packages/django/core/handlers/base.py", line 126, in _get_response
    response = self.process_exception_by_middleware(e, request)
  File "/home/mobilitysqr/.local/lib/python3.6/site-packages/django/core/handlers/base.py", line 124, in _get_response
    response = wrapped_callback(request, *callback_args, **callback_kwargs)
  File "/home/mobilitysqr/.local/lib/python3.6/site-packages/django/views/decorators/csrf.py", line 54, in wrapped_view
    return view_func(*args, **kwargs)
  File "/home/mobilitysqr/.local/lib/python3.6/site-packages/django/views/generic/base.py", line 68, in view
    return self.dispatch(request, *args, **kwargs)
  File "/home/mobilitysqr/.local/lib/python3.6/site-packages/rest_framework/views.py", line 495, in dispatch
    response = self.handle_exception(exc)
  File "/home/mobilitysqr/.local/lib/python3.6/site-packages/rest_framework/views.py", line 455, in handle_exception
    self.raise_uncaught_exception(exc)
  File "/home/mobilitysqr/.local/lib/python3.6/site-packages/rest_framework/views.py", line 492, in dispatch
    response = handler(request, *args, **kwargs)
  File "/var/www/html/mobilitysqrapi/mobility_apps/master/views/assignment_group.py", line 89, in get
    print(data['email'])
KeyError: 'email'
ERROR|22/Dec/2020 16:09:43|basehttp|10716|140203019450112|"GET /get_add/group/ HTTP/1.1" 500 17166
ERROR|22/Dec/2020 16:12:22|log|10957|140069238036224|Internal Server Error: /get_add/group/
Traceback (most recent call last):
  File "/home/mobilitysqr/.local/lib/python3.6/site-packages/django/core/handlers/exception.py", line 34, in inner
    response = get_response(request)
  File "/home/mobilitysqr/.local/lib/python3.6/site-packages/django/core/handlers/base.py", line 126, in _get_response
    response = self.process_exception_by_middleware(e, request)
  File "/home/mobilitysqr/.local/lib/python3.6/site-packages/django/core/handlers/base.py", line 124, in _get_response
    response = wrapped_callback(request, *callback_args, **callback_kwargs)
  File "/home/mobilitysqr/.local/lib/python3.6/site-packages/django/views/decorators/csrf.py", line 54, in wrapped_view
    return view_func(*args, **kwargs)
  File "/home/mobilitysqr/.local/lib/python3.6/site-packages/django/views/generic/base.py", line 68, in view
    return self.dispatch(request, *args, **kwargs)
  File "/home/mobilitysqr/.local/lib/python3.6/site-packages/rest_framework/views.py", line 495, in dispatch
    response = self.handle_exception(exc)
  File "/home/mobilitysqr/.local/lib/python3.6/site-packages/rest_framework/views.py", line 455, in handle_exception
    self.raise_uncaught_exception(exc)
  File "/home/mobilitysqr/.local/lib/python3.6/site-packages/rest_framework/views.py", line 492, in dispatch
    response = handler(request, *args, **kwargs)
  File "/var/www/html/mobilitysqrapi/mobility_apps/master/views/assignment_group.py", line 92, in get
    emp_code=Employee.objects.filter(emp_code=data[i]['emp_email']).values('email','emp_code','first_name','last_name')
KeyError: 0
ERROR|22/Dec/2020 16:12:22|basehttp|10957|140069238036224|"GET /get_add/group/ HTTP/1.1" 500 17249
ERROR|22/Dec/2020 16:18:38|log|11010|140447905212160|Internal Server Error: /getassignmentletter/
Traceback (most recent call last):
  File "/home/mobilitysqr/.local/lib/python3.6/site-packages/django/core/handlers/exception.py", line 34, in inner
    response = get_response(request)
  File "/home/mobilitysqr/.local/lib/python3.6/site-packages/django/core/handlers/base.py", line 126, in _get_response
    response = self.process_exception_by_middleware(e, request)
  File "/home/mobilitysqr/.local/lib/python3.6/site-packages/django/core/handlers/base.py", line 124, in _get_response
    response = wrapped_callback(request, *callback_args, **callback_kwargs)
  File "/home/mobilitysqr/.local/lib/python3.6/site-packages/django/views/decorators/csrf.py", line 54, in wrapped_view
    return view_func(*args, **kwargs)
  File "/home/mobilitysqr/.local/lib/python3.6/site-packages/django/views/generic/base.py", line 68, in view
    return self.dispatch(request, *args, **kwargs)
  File "/home/mobilitysqr/.local/lib/python3.6/site-packages/rest_framework/views.py", line 495, in dispatch
    response = self.handle_exception(exc)
  File "/home/mobilitysqr/.local/lib/python3.6/site-packages/rest_framework/views.py", line 455, in handle_exception
    self.raise_uncaught_exception(exc)
  File "/home/mobilitysqr/.local/lib/python3.6/site-packages/rest_framework/views.py", line 492, in dispatch
    response = handler(request, *args, **kwargs)
  File "/var/www/html/mobilitysqrapi/mobility_apps/letter/views.py", line 163, in get
    datas['VisaValidity']=self.date_format(date=data['details'][i]['visa_expiry_date'])
  File "/var/www/html/mobilitysqrapi/mobility_apps/letter/views.py", line 648, in date_format
    dt = datetime(str(date))
TypeError: an integer is required (got type str)
ERROR|22/Dec/2020 16:18:38|basehttp|11010|140447905212160|"GET /getassignmentletter/?travel_req_id=TR325676 HTTP/1.1" 500 17491
ERROR|22/Dec/2020 16:18:47|log|11010|140447913604864|Internal Server Error: /getassignmentletter/
Traceback (most recent call last):
  File "/home/mobilitysqr/.local/lib/python3.6/site-packages/django/core/handlers/exception.py", line 34, in inner
    response = get_response(request)
  File "/home/mobilitysqr/.local/lib/python3.6/site-packages/django/core/handlers/base.py", line 126, in _get_response
    response = self.process_exception_by_middleware(e, request)
  File "/home/mobilitysqr/.local/lib/python3.6/site-packages/django/core/handlers/base.py", line 124, in _get_response
    response = wrapped_callback(request, *callback_args, **callback_kwargs)
  File "/home/mobilitysqr/.local/lib/python3.6/site-packages/django/views/decorators/csrf.py", line 54, in wrapped_view
    return view_func(*args, **kwargs)
  File "/home/mobilitysqr/.local/lib/python3.6/site-packages/django/views/generic/base.py", line 68, in view
    return self.dispatch(request, *args, **kwargs)
  File "/home/mobilitysqr/.local/lib/python3.6/site-packages/rest_framework/views.py", line 495, in dispatch
    response = self.handle_exception(exc)
  File "/home/mobilitysqr/.local/lib/python3.6/site-packages/rest_framework/views.py", line 455, in handle_exception
    self.raise_uncaught_exception(exc)
  File "/home/mobilitysqr/.local/lib/python3.6/site-packages/rest_framework/views.py", line 492, in dispatch
    response = handler(request, *args, **kwargs)
  File "/var/www/html/mobilitysqrapi/mobility_apps/letter/views.py", line 163, in get
    datas['VisaValidity']=self.date_format(date=data['details'][i]['visa_expiry_date'])
  File "/var/www/html/mobilitysqrapi/mobility_apps/letter/views.py", line 648, in date_format
    dt = datetime(str(date))
TypeError: an integer is required (got type str)
ERROR|22/Dec/2020 16:18:47|basehttp|11010|140447913604864|"GET /getassignmentletter/?travel_req_id=TR325676 HTTP/1.1" 500 17491
ERROR|22/Dec/2020 16:22:51|log|11010|140448131225344|Internal Server Error: /getassignmentletter/
Traceback (most recent call last):
  File "/home/mobilitysqr/.local/lib/python3.6/site-packages/django/core/handlers/exception.py", line 34, in inner
    response = get_response(request)
  File "/home/mobilitysqr/.local/lib/python3.6/site-packages/django/core/handlers/base.py", line 126, in _get_response
    response = self.process_exception_by_middleware(e, request)
  File "/home/mobilitysqr/.local/lib/python3.6/site-packages/django/core/handlers/base.py", line 124, in _get_response
    response = wrapped_callback(request, *callback_args, **callback_kwargs)
  File "/home/mobilitysqr/.local/lib/python3.6/site-packages/django/views/decorators/csrf.py", line 54, in wrapped_view
    return view_func(*args, **kwargs)
  File "/home/mobilitysqr/.local/lib/python3.6/site-packages/django/views/generic/base.py", line 68, in view
    return self.dispatch(request, *args, **kwargs)
  File "/home/mobilitysqr/.local/lib/python3.6/site-packages/rest_framework/views.py", line 495, in dispatch
    response = self.handle_exception(exc)
  File "/home/mobilitysqr/.local/lib/python3.6/site-packages/rest_framework/views.py", line 455, in handle_exception
    self.raise_uncaught_exception(exc)
  File "/home/mobilitysqr/.local/lib/python3.6/site-packages/rest_framework/views.py", line 492, in dispatch
    response = handler(request, *args, **kwargs)
  File "/var/www/html/mobilitysqrapi/mobility_apps/letter/views.py", line 163, in get
    datas['VisaValidity']=self.date_format(date=data['details'][i]['visa_expiry_date'])
  File "/var/www/html/mobilitysqrapi/mobility_apps/letter/views.py", line 648, in date_format
    dt = datetime(str(date))
TypeError: an integer is required (got type str)
ERROR|22/Dec/2020 16:22:51|basehttp|11010|140448131225344|"GET /getassignmentletter/?travel_req_id=TR325676 HTTP/1.1" 500 17490
ERROR|22/Dec/2020 16:23:05|log|11010|140447913604864|Internal Server Error: /getassignmentletter/
Traceback (most recent call last):
  File "/home/mobilitysqr/.local/lib/python3.6/site-packages/django/core/handlers/exception.py", line 34, in inner
    response = get_response(request)
  File "/home/mobilitysqr/.local/lib/python3.6/site-packages/django/core/handlers/base.py", line 126, in _get_response
    response = self.process_exception_by_middleware(e, request)
  File "/home/mobilitysqr/.local/lib/python3.6/site-packages/django/core/handlers/base.py", line 124, in _get_response
    response = wrapped_callback(request, *callback_args, **callback_kwargs)
  File "/home/mobilitysqr/.local/lib/python3.6/site-packages/django/views/decorators/csrf.py", line 54, in wrapped_view
    return view_func(*args, **kwargs)
  File "/home/mobilitysqr/.local/lib/python3.6/site-packages/django/views/generic/base.py", line 68, in view
    return self.dispatch(request, *args, **kwargs)
  File "/home/mobilitysqr/.local/lib/python3.6/site-packages/rest_framework/views.py", line 495, in dispatch
    response = self.handle_exception(exc)
  File "/home/mobilitysqr/.local/lib/python3.6/site-packages/rest_framework/views.py", line 455, in handle_exception
    self.raise_uncaught_exception(exc)
  File "/home/mobilitysqr/.local/lib/python3.6/site-packages/rest_framework/views.py", line 492, in dispatch
    response = handler(request, *args, **kwargs)
  File "/var/www/html/mobilitysqrapi/mobility_apps/letter/views.py", line 163, in get
    datas['VisaValidity']=self.date_format(date=data['details'][i]['visa_expiry_date'])
  File "/var/www/html/mobilitysqrapi/mobility_apps/letter/views.py", line 648, in date_format
    dt = datetime(str(date))
TypeError: an integer is required (got type str)
ERROR|22/Dec/2020 16:23:05|basehttp|11010|140447913604864|"GET /getassignmentletter/?travel_req_id=TR325676 HTTP/1.1" 500 17491
ERROR|22/Dec/2020 18:48:57|log|16961|140012757264128|Internal Server Error: /getassignmentletter/
Traceback (most recent call last):
  File "/home/mobilitysqr/.local/lib/python3.6/site-packages/django/core/handlers/exception.py", line 34, in inner
    response = get_response(request)
  File "/home/mobilitysqr/.local/lib/python3.6/site-packages/django/core/handlers/base.py", line 126, in _get_response
    response = self.process_exception_by_middleware(e, request)
  File "/home/mobilitysqr/.local/lib/python3.6/site-packages/django/core/handlers/base.py", line 124, in _get_response
    response = wrapped_callback(request, *callback_args, **callback_kwargs)
  File "/home/mobilitysqr/.local/lib/python3.6/site-packages/django/views/decorators/csrf.py", line 54, in wrapped_view
    return view_func(*args, **kwargs)
  File "/home/mobilitysqr/.local/lib/python3.6/site-packages/django/views/generic/base.py", line 68, in view
    return self.dispatch(request, *args, **kwargs)
  File "/home/mobilitysqr/.local/lib/python3.6/site-packages/rest_framework/views.py", line 495, in dispatch
    response = self.handle_exception(exc)
  File "/home/mobilitysqr/.local/lib/python3.6/site-packages/rest_framework/views.py", line 455, in handle_exception
    self.raise_uncaught_exception(exc)
  File "/home/mobilitysqr/.local/lib/python3.6/site-packages/rest_framework/views.py", line 492, in dispatch
    response = handler(request, *args, **kwargs)
  File "/var/www/html/mobilitysqrapi/mobility_apps/letter/views.py", line 163, in get
    datas['VisaValidity']=self.date_format(date=data['details'][i]['visa_expiry_date'])
  File "/var/www/html/mobilitysqrapi/mobility_apps/letter/views.py", line 647, in date_format
    dt = datetime(str(date))
TypeError: an integer is required (got type str)
ERROR|22/Dec/2020 18:48:57|basehttp|16961|140012757264128|"GET /getassignmentletter/?travel_req_id=TR325676 HTTP/1.1" 500 17490
