ERROR|26/Apr/2021 12:57:16|exception|13614|140059546216192|Invalid HTTP_HOST header: ''. The domain name provided is not valid according to RFC 1034/1035.
ERROR|26/Apr/2021 13:05:11|log|13614|140059526547200|Internal Server Error: /bulk_approve_travelvisa_request/
Traceback (most recent call last):
  File "/home/mobilitysqr/.local/lib/python3.6/site-packages/django/core/handlers/exception.py", line 34, in inner
    response = get_response(request)
  File "/home/mobilitysqr/.local/lib/python3.6/site-packages/django/core/handlers/base.py", line 126, in _get_response
    response = self.process_exception_by_middleware(e, request)
  File "/home/mobilitysqr/.local/lib/python3.6/site-packages/django/core/handlers/base.py", line 124, in _get_response
    response = wrapped_callback(request, *callback_args, **callback_kwargs)
  File "/home/mobilitysqr/.local/lib/python3.6/site-packages/django/views/decorators/csrf.py", line 54, in wrapped_view
    return view_func(*args, **kwargs)
  File "/home/mobilitysqr/.local/lib/python3.6/site-packages/django/views/generic/base.py", line 68, in view
    return self.dispatch(request, *args, **kwargs)
  File "/home/mobilitysqr/.local/lib/python3.6/site-packages/rest_framework/views.py", line 495, in dispatch
    response = self.handle_exception(exc)
  File "/home/mobilitysqr/.local/lib/python3.6/site-packages/rest_framework/views.py", line 455, in handle_exception
    self.raise_uncaught_exception(exc)
  File "/home/mobilitysqr/.local/lib/python3.6/site-packages/rest_framework/views.py", line 492, in dispatch
    response = handler(request, *args, **kwargs)
  File "/var/www/html/mobilitysqr_staging/mobility_apps/travel/views.py", line 3754, in post
    request.data['Entity_Type'] = "Travel"
TypeError: list indices must be integers or slices, not str
ERROR|26/Apr/2021 13:05:11|basehttp|13614|140059526547200|"POST /bulk_approve_travelvisa_request/ HTTP/1.1" 500 17441
ERROR|26/Apr/2021 13:07:28|log|13614|140059772552960|Internal Server Error: /bulk_approve_travelvisa_request/
Traceback (most recent call last):
  File "/home/mobilitysqr/.local/lib/python3.6/site-packages/django/core/handlers/exception.py", line 34, in inner
    response = get_response(request)
  File "/home/mobilitysqr/.local/lib/python3.6/site-packages/django/core/handlers/base.py", line 126, in _get_response
    response = self.process_exception_by_middleware(e, request)
  File "/home/mobilitysqr/.local/lib/python3.6/site-packages/django/core/handlers/base.py", line 124, in _get_response
    response = wrapped_callback(request, *callback_args, **callback_kwargs)
  File "/home/mobilitysqr/.local/lib/python3.6/site-packages/django/views/decorators/csrf.py", line 54, in wrapped_view
    return view_func(*args, **kwargs)
  File "/home/mobilitysqr/.local/lib/python3.6/site-packages/django/views/generic/base.py", line 68, in view
    return self.dispatch(request, *args, **kwargs)
  File "/home/mobilitysqr/.local/lib/python3.6/site-packages/rest_framework/views.py", line 495, in dispatch
    response = self.handle_exception(exc)
  File "/home/mobilitysqr/.local/lib/python3.6/site-packages/rest_framework/views.py", line 455, in handle_exception
    self.raise_uncaught_exception(exc)
  File "/home/mobilitysqr/.local/lib/python3.6/site-packages/rest_framework/views.py", line 492, in dispatch
    response = handler(request, *args, **kwargs)
  File "/var/www/html/mobilitysqr_staging/mobility_apps/travel/views.py", line 3754, in post
    request.data['Entity_Type'] = "Travel"
TypeError: list indices must be integers or slices, not str
ERROR|26/Apr/2021 13:07:28|basehttp|13614|140059772552960|"POST /bulk_approve_travelvisa_request/ HTTP/1.1" 500 17441
ERROR|26/Apr/2021 13:07:28|log|13614|140059526547200|Internal Server Error: /bulk_approve_travelvisa_request/
Traceback (most recent call last):
  File "/home/mobilitysqr/.local/lib/python3.6/site-packages/django/core/handlers/exception.py", line 34, in inner
    response = get_response(request)
  File "/home/mobilitysqr/.local/lib/python3.6/site-packages/django/core/handlers/base.py", line 126, in _get_response
    response = self.process_exception_by_middleware(e, request)
  File "/home/mobilitysqr/.local/lib/python3.6/site-packages/django/core/handlers/base.py", line 124, in _get_response
    response = wrapped_callback(request, *callback_args, **callback_kwargs)
  File "/home/mobilitysqr/.local/lib/python3.6/site-packages/django/views/decorators/csrf.py", line 54, in wrapped_view
    return view_func(*args, **kwargs)
  File "/home/mobilitysqr/.local/lib/python3.6/site-packages/django/views/generic/base.py", line 68, in view
    return self.dispatch(request, *args, **kwargs)
  File "/home/mobilitysqr/.local/lib/python3.6/site-packages/rest_framework/views.py", line 495, in dispatch
    response = self.handle_exception(exc)
  File "/home/mobilitysqr/.local/lib/python3.6/site-packages/rest_framework/views.py", line 455, in handle_exception
    self.raise_uncaught_exception(exc)
  File "/home/mobilitysqr/.local/lib/python3.6/site-packages/rest_framework/views.py", line 492, in dispatch
    response = handler(request, *args, **kwargs)
  File "/var/www/html/mobilitysqr_staging/mobility_apps/travel/views.py", line 3754, in post
    request.data['Entity_Type'] = "Travel"
TypeError: list indices must be integers or slices, not str
ERROR|26/Apr/2021 13:07:28|basehttp|13614|140059526547200|"POST /bulk_approve_travelvisa_request/ HTTP/1.1" 500 17442
ERROR|26/Apr/2021 13:07:29|log|13614|140059554608896|Internal Server Error: /bulk_approve_travelvisa_request/
Traceback (most recent call last):
  File "/home/mobilitysqr/.local/lib/python3.6/site-packages/django/core/handlers/exception.py", line 34, in inner
    response = get_response(request)
  File "/home/mobilitysqr/.local/lib/python3.6/site-packages/django/core/handlers/base.py", line 126, in _get_response
    response = self.process_exception_by_middleware(e, request)
  File "/home/mobilitysqr/.local/lib/python3.6/site-packages/django/core/handlers/base.py", line 124, in _get_response
    response = wrapped_callback(request, *callback_args, **callback_kwargs)
  File "/home/mobilitysqr/.local/lib/python3.6/site-packages/django/views/decorators/csrf.py", line 54, in wrapped_view
    return view_func(*args, **kwargs)
  File "/home/mobilitysqr/.local/lib/python3.6/site-packages/django/views/generic/base.py", line 68, in view
    return self.dispatch(request, *args, **kwargs)
  File "/home/mobilitysqr/.local/lib/python3.6/site-packages/rest_framework/views.py", line 495, in dispatch
    response = self.handle_exception(exc)
  File "/home/mobilitysqr/.local/lib/python3.6/site-packages/rest_framework/views.py", line 455, in handle_exception
    self.raise_uncaught_exception(exc)
  File "/home/mobilitysqr/.local/lib/python3.6/site-packages/rest_framework/views.py", line 492, in dispatch
    response = handler(request, *args, **kwargs)
  File "/var/www/html/mobilitysqr_staging/mobility_apps/travel/views.py", line 3754, in post
    request.data['Entity_Type'] = "Travel"
TypeError: list indices must be integers or slices, not str
ERROR|26/Apr/2021 13:07:29|basehttp|13614|140059554608896|"POST /bulk_approve_travelvisa_request/ HTTP/1.1" 500 17442
ERROR|26/Apr/2021 13:07:29|log|13614|140059526547200|Internal Server Error: /bulk_approve_travelvisa_request/
Traceback (most recent call last):
  File "/home/mobilitysqr/.local/lib/python3.6/site-packages/django/core/handlers/exception.py", line 34, in inner
    response = get_response(request)
  File "/home/mobilitysqr/.local/lib/python3.6/site-packages/django/core/handlers/base.py", line 126, in _get_response
    response = self.process_exception_by_middleware(e, request)
  File "/home/mobilitysqr/.local/lib/python3.6/site-packages/django/core/handlers/base.py", line 124, in _get_response
    response = wrapped_callback(request, *callback_args, **callback_kwargs)
  File "/home/mobilitysqr/.local/lib/python3.6/site-packages/django/views/decorators/csrf.py", line 54, in wrapped_view
    return view_func(*args, **kwargs)
  File "/home/mobilitysqr/.local/lib/python3.6/site-packages/django/views/generic/base.py", line 68, in view
    return self.dispatch(request, *args, **kwargs)
  File "/home/mobilitysqr/.local/lib/python3.6/site-packages/rest_framework/views.py", line 495, in dispatch
    response = self.handle_exception(exc)
  File "/home/mobilitysqr/.local/lib/python3.6/site-packages/rest_framework/views.py", line 455, in handle_exception
    self.raise_uncaught_exception(exc)
  File "/home/mobilitysqr/.local/lib/python3.6/site-packages/rest_framework/views.py", line 492, in dispatch
    response = handler(request, *args, **kwargs)
  File "/var/www/html/mobilitysqr_staging/mobility_apps/travel/views.py", line 3754, in post
    request.data['Entity_Type'] = "Travel"
TypeError: list indices must be integers or slices, not str
ERROR|26/Apr/2021 13:07:29|basehttp|13614|140059526547200|"POST /bulk_approve_travelvisa_request/ HTTP/1.1" 500 17442
ERROR|26/Apr/2021 13:07:30|log|13614|140059772552960|Internal Server Error: /bulk_approve_travelvisa_request/
Traceback (most recent call last):
  File "/home/mobilitysqr/.local/lib/python3.6/site-packages/django/core/handlers/exception.py", line 34, in inner
    response = get_response(request)
  File "/home/mobilitysqr/.local/lib/python3.6/site-packages/django/core/handlers/base.py", line 126, in _get_response
    response = self.process_exception_by_middleware(e, request)
  File "/home/mobilitysqr/.local/lib/python3.6/site-packages/django/core/handlers/base.py", line 124, in _get_response
    response = wrapped_callback(request, *callback_args, **callback_kwargs)
  File "/home/mobilitysqr/.local/lib/python3.6/site-packages/django/views/decorators/csrf.py", line 54, in wrapped_view
    return view_func(*args, **kwargs)
  File "/home/mobilitysqr/.local/lib/python3.6/site-packages/django/views/generic/base.py", line 68, in view
    return self.dispatch(request, *args, **kwargs)
  File "/home/mobilitysqr/.local/lib/python3.6/site-packages/rest_framework/views.py", line 495, in dispatch
    response = self.handle_exception(exc)
  File "/home/mobilitysqr/.local/lib/python3.6/site-packages/rest_framework/views.py", line 455, in handle_exception
    self.raise_uncaught_exception(exc)
  File "/home/mobilitysqr/.local/lib/python3.6/site-packages/rest_framework/views.py", line 492, in dispatch
    response = handler(request, *args, **kwargs)
  File "/var/www/html/mobilitysqr_staging/mobility_apps/travel/views.py", line 3754, in post
    request.data['Entity_Type'] = "Travel"
TypeError: list indices must be integers or slices, not str
ERROR|26/Apr/2021 13:07:30|basehttp|13614|140059772552960|"POST /bulk_approve_travelvisa_request/ HTTP/1.1" 500 17442
ERROR|26/Apr/2021 13:12:46|log|13614|140059526547200|Internal Server Error: /bulk_approve_travelvisa_request/
Traceback (most recent call last):
  File "/home/mobilitysqr/.local/lib/python3.6/site-packages/django/core/handlers/exception.py", line 34, in inner
    response = get_response(request)
  File "/home/mobilitysqr/.local/lib/python3.6/site-packages/django/core/handlers/base.py", line 126, in _get_response
    response = self.process_exception_by_middleware(e, request)
  File "/home/mobilitysqr/.local/lib/python3.6/site-packages/django/core/handlers/base.py", line 124, in _get_response
    response = wrapped_callback(request, *callback_args, **callback_kwargs)
  File "/home/mobilitysqr/.local/lib/python3.6/site-packages/django/views/decorators/csrf.py", line 54, in wrapped_view
    return view_func(*args, **kwargs)
  File "/home/mobilitysqr/.local/lib/python3.6/site-packages/django/views/generic/base.py", line 68, in view
    return self.dispatch(request, *args, **kwargs)
  File "/home/mobilitysqr/.local/lib/python3.6/site-packages/rest_framework/views.py", line 495, in dispatch
    response = self.handle_exception(exc)
  File "/home/mobilitysqr/.local/lib/python3.6/site-packages/rest_framework/views.py", line 455, in handle_exception
    self.raise_uncaught_exception(exc)
  File "/home/mobilitysqr/.local/lib/python3.6/site-packages/rest_framework/views.py", line 492, in dispatch
    response = handler(request, *args, **kwargs)
  File "/var/www/html/mobilitysqr_staging/mobility_apps/travel/views.py", line 3754, in post
    request.data['Entity_Type'] = "Travel"
TypeError: list indices must be integers or slices, not str
ERROR|26/Apr/2021 13:12:46|basehttp|13614|140059526547200|"POST /bulk_approve_travelvisa_request/ HTTP/1.1" 500 17442
ERROR|26/Apr/2021 13:20:46|log|13614|140059772552960|Internal Server Error: /bulk_approve_travelvisa_request/
Traceback (most recent call last):
  File "/home/mobilitysqr/.local/lib/python3.6/site-packages/django/core/handlers/exception.py", line 34, in inner
    response = get_response(request)
  File "/home/mobilitysqr/.local/lib/python3.6/site-packages/django/core/handlers/base.py", line 126, in _get_response
    response = self.process_exception_by_middleware(e, request)
  File "/home/mobilitysqr/.local/lib/python3.6/site-packages/django/core/handlers/base.py", line 124, in _get_response
    response = wrapped_callback(request, *callback_args, **callback_kwargs)
  File "/home/mobilitysqr/.local/lib/python3.6/site-packages/django/views/decorators/csrf.py", line 54, in wrapped_view
    return view_func(*args, **kwargs)
  File "/home/mobilitysqr/.local/lib/python3.6/site-packages/django/views/generic/base.py", line 68, in view
    return self.dispatch(request, *args, **kwargs)
  File "/home/mobilitysqr/.local/lib/python3.6/site-packages/rest_framework/views.py", line 495, in dispatch
    response = self.handle_exception(exc)
  File "/home/mobilitysqr/.local/lib/python3.6/site-packages/rest_framework/views.py", line 455, in handle_exception
    self.raise_uncaught_exception(exc)
  File "/home/mobilitysqr/.local/lib/python3.6/site-packages/rest_framework/views.py", line 492, in dispatch
    response = handler(request, *args, **kwargs)
  File "/var/www/html/mobilitysqr_staging/mobility_apps/travel/views.py", line 3754, in post
    request.data['Entity_Type'] = "Travel"
TypeError: list indices must be integers or slices, not str
ERROR|26/Apr/2021 13:20:46|basehttp|13614|140059772552960|"POST /bulk_approve_travelvisa_request/ HTTP/1.1" 500 17441
ERROR|26/Apr/2021 13:23:46|log|14714|140376740218624|Internal Server Error: /bulk_approve_travelvisa_request/
Traceback (most recent call last):
  File "/home/mobilitysqr/.local/lib/python3.6/site-packages/django/core/handlers/exception.py", line 34, in inner
    response = get_response(request)
  File "/home/mobilitysqr/.local/lib/python3.6/site-packages/django/core/handlers/base.py", line 126, in _get_response
    response = self.process_exception_by_middleware(e, request)
  File "/home/mobilitysqr/.local/lib/python3.6/site-packages/django/core/handlers/base.py", line 124, in _get_response
    response = wrapped_callback(request, *callback_args, **callback_kwargs)
  File "/home/mobilitysqr/.local/lib/python3.6/site-packages/django/views/decorators/csrf.py", line 54, in wrapped_view
    return view_func(*args, **kwargs)
  File "/home/mobilitysqr/.local/lib/python3.6/site-packages/django/views/generic/base.py", line 68, in view
    return self.dispatch(request, *args, **kwargs)
  File "/home/mobilitysqr/.local/lib/python3.6/site-packages/rest_framework/views.py", line 495, in dispatch
    response = self.handle_exception(exc)
  File "/home/mobilitysqr/.local/lib/python3.6/site-packages/rest_framework/views.py", line 455, in handle_exception
    self.raise_uncaught_exception(exc)
  File "/home/mobilitysqr/.local/lib/python3.6/site-packages/rest_framework/views.py", line 492, in dispatch
    response = handler(request, *args, **kwargs)
  File "/var/www/html/mobilitysqr_staging/mobility_apps/travel/views.py", line 3715, in post
    serializernotificationss = NotificationSerializers(data=approvel_data)
NameError: name 'Notificatio' is not defined
ERROR|26/Apr/2021 13:23:46|basehttp|14714|140376740218624|"POST /bulk_approve_travelvisa_request/ HTTP/1.1" 500 17436
ERROR|26/Apr/2021 13:53:31|log|15404|139777294726912|Internal Server Error: /bulk_approve_travelvisa_request/
Traceback (most recent call last):
  File "/home/mobilitysqr/.local/lib/python3.6/site-packages/django/core/handlers/exception.py", line 34, in inner
    response = get_response(request)
  File "/home/mobilitysqr/.local/lib/python3.6/site-packages/django/core/handlers/base.py", line 126, in _get_response
    response = self.process_exception_by_middleware(e, request)
  File "/home/mobilitysqr/.local/lib/python3.6/site-packages/django/core/handlers/base.py", line 124, in _get_response
    response = wrapped_callback(request, *callback_args, **callback_kwargs)
  File "/home/mobilitysqr/.local/lib/python3.6/site-packages/django/views/decorators/csrf.py", line 54, in wrapped_view
    return view_func(*args, **kwargs)
  File "/home/mobilitysqr/.local/lib/python3.6/site-packages/django/views/generic/base.py", line 68, in view
    return self.dispatch(request, *args, **kwargs)
  File "/home/mobilitysqr/.local/lib/python3.6/site-packages/rest_framework/views.py", line 495, in dispatch
    response = self.handle_exception(exc)
  File "/home/mobilitysqr/.local/lib/python3.6/site-packages/rest_framework/views.py", line 455, in handle_exception
    self.raise_uncaught_exception(exc)
  File "/home/mobilitysqr/.local/lib/python3.6/site-packages/rest_framework/views.py", line 492, in dispatch
    response = handler(request, *args, **kwargs)
  File "/var/www/html/mobilitysqr_staging/mobility_apps/travel/views.py", line 4024, in post
    if request.data['approve_action'] == "A":
TypeError: list indices must be integers or slices, not str
ERROR|26/Apr/2021 13:53:31|basehttp|15404|139777294726912|"POST /bulk_approve_travelvisa_request/ HTTP/1.1" 500 17437
ERROR|26/Apr/2021 15:17:00|exception|16244|139771808601856|Invalid HTTP_HOST header: ''. The domain name provided is not valid according to RFC 1034/1035.
ERROR|26/Apr/2021 15:45:13|exception|16244|139771863414528|Invalid HTTP_HOST header: ''. The domain name provided is not valid according to RFC 1034/1035.
ERROR|26/Apr/2021 17:01:53|exception|16244|139771824338688|Invalid HTTP_HOST header: ''. The domain name provided is not valid according to RFC 1034/1035.
ERROR|26/Apr/2021 17:35:14|exception|16244|139771861579520|Invalid HTTP_HOST header: ''. The domain name provided is not valid according to RFC 1034/1035.
ERROR|26/Apr/2021 18:43:28|exception|16244|139771808601856|Invalid HTTP_HOST header: ''. The domain name provided is not valid according to RFC 1034/1035.
ERROR|26/Apr/2021 19:00:06|exception|16244|139771447863040|Invalid HTTP_HOST header: ''. The domain name provided is not valid according to RFC 1034/1035.
ERROR|26/Apr/2021 20:01:52|exception|16244|139771447863040|Invalid HTTP_HOST header: ''. The domain name provided is not valid according to RFC 1034/1035.
ERROR|26/Apr/2021 21:39:32|exception|16244|139771800209152|Invalid HTTP_HOST header: ''. The domain name provided is not valid according to RFC 1034/1035.
ERROR|26/Apr/2021 21:39:32|basehttp|16244|139771800209152|"GET /manager/html HTTP/1.1" 500 59
ERROR|26/Apr/2021 22:30:07|exception|16244|139771808601856|Invalid HTTP_HOST header: ''. The domain name provided is not valid according to RFC 1034/1035.
ERROR|26/Apr/2021 22:52:28|exception|16244|139771808601856|Invalid HTTP_HOST header: ''. The domain name provided is not valid according to RFC 1034/1035.
ERROR|26/Apr/2021 23:07:09|basehttp|16244|139771808601856|You're accessing the development server over HTTPS, but it only supports HTTP.

ERROR|27/Apr/2021 00:42:08|exception|16244|139771808601856|Invalid HTTP_HOST header: ''. The domain name provided is not valid according to RFC 1034/1035.
ERROR|27/Apr/2021 00:56:49|exception|16244|139771808601856|Invalid HTTP_HOST header: ''. The domain name provided is not valid according to RFC 1034/1035.
ERROR|27/Apr/2021 02:28:41|basehttp|16244|139771808601856|"GET /config/getuser?index=0 HTTP/1.1" 500 59
ERROR|27/Apr/2021 03:10:59|basehttp|16244|139771808601856|You're accessing the development server over HTTPS, but it only supports HTTP.

ERROR|27/Apr/2021 03:10:59|basehttp|16244|139771808601856|You're accessing the development server over HTTPS, but it only supports HTTP.

ERROR|27/Apr/2021 03:11:00|basehttp|16244|139771808601856|You're accessing the development server over HTTPS, but it only supports HTTP.

ERROR|27/Apr/2021 03:11:00|basehttp|16244|139771808601856|You're accessing the development server over HTTPS, but it only supports HTTP.

ERROR|27/Apr/2021 03:11:01|basehttp|16244|139771808601856|You're accessing the development server over HTTPS, but it only supports HTTP.

ERROR|27/Apr/2021 03:11:01|basehttp|16244|139771808601856|You're accessing the development server over HTTPS, but it only supports HTTP.

ERROR|27/Apr/2021 03:11:02|basehttp|16244|139771808601856|You're accessing the development server over HTTPS, but it only supports HTTP.

ERROR|27/Apr/2021 03:11:02|basehttp|16244|139771808601856|You're accessing the development server over HTTPS, but it only supports HTTP.

ERROR|27/Apr/2021 03:11:03|basehttp|16244|139771808601856|You're accessing the development server over HTTPS, but it only supports HTTP.

ERROR|27/Apr/2021 03:11:03|basehttp|16244|139771808601856|You're accessing the development server over HTTPS, but it only supports HTTP.

ERROR|27/Apr/2021 03:12:32|basehttp|16244|139771808601856|You're accessing the development server over HTTPS, but it only supports HTTP.

ERROR|27/Apr/2021 03:14:49|exception|16244|139771808601856|Invalid HTTP_HOST header: ''. The domain name provided is not valid according to RFC 1034/1035.
ERROR|27/Apr/2021 03:20:17|exception|16244|139771808601856|Invalid HTTP_HOST header: ''. The domain name provided is not valid according to RFC 1034/1035.
ERROR|27/Apr/2021 03:31:56|exception|16244|139771808601856|Invalid HTTP_HOST header: ''. The domain name provided is not valid according to RFC 1034/1035.
ERROR|27/Apr/2021 03:31:56|basehttp|16244|139771808601856|"GET /manager/html HTTP/1.1" 500 59
ERROR|27/Apr/2021 04:57:18|exception|16244|139771808601856|Invalid HTTP_HOST header: ''. The domain name provided is not valid according to RFC 1034/1035.
ERROR|27/Apr/2021 05:41:51|exception|16244|139771808601856|Invalid HTTP_HOST header: ''. The domain name provided is not valid according to RFC 1034/1035.
ERROR|27/Apr/2021 06:23:58|exception|16244|139771808601856|Invalid HTTP_HOST header: ''. The domain name provided is not valid according to RFC 1034/1035.
ERROR|27/Apr/2021 07:59:36|exception|16244|139771808601856|Invalid HTTP_HOST header: ''. The domain name provided is not valid according to RFC 1034/1035.
ERROR|27/Apr/2021 08:18:11|basehttp|16244|139771808601856|"GET /config/getuser?index=0 HTTP/1.1" 500 59
ERROR|27/Apr/2021 09:05:35|exception|16244|139771808601856|Invalid HTTP_HOST header: ''. The domain name provided is not valid according to RFC 1034/1035.
ERROR|27/Apr/2021 09:59:26|log|16244|139771447863040|Internal Server Error: /getassignmentletter/
Traceback (most recent call last):
  File "/home/mobilitysqr/.local/lib/python3.6/site-packages/django/core/handlers/exception.py", line 34, in inner
    response = get_response(request)
  File "/home/mobilitysqr/.local/lib/python3.6/site-packages/django/core/handlers/base.py", line 126, in _get_response
    response = self.process_exception_by_middleware(e, request)
  File "/home/mobilitysqr/.local/lib/python3.6/site-packages/django/core/handlers/base.py", line 124, in _get_response
    response = wrapped_callback(request, *callback_args, **callback_kwargs)
  File "/home/mobilitysqr/.local/lib/python3.6/site-packages/django/views/decorators/csrf.py", line 54, in wrapped_view
    return view_func(*args, **kwargs)
  File "/home/mobilitysqr/.local/lib/python3.6/site-packages/django/views/generic/base.py", line 68, in view
    return self.dispatch(request, *args, **kwargs)
  File "/home/mobilitysqr/.local/lib/python3.6/site-packages/rest_framework/views.py", line 495, in dispatch
    response = self.handle_exception(exc)
  File "/home/mobilitysqr/.local/lib/python3.6/site-packages/rest_framework/views.py", line 455, in handle_exception
    self.raise_uncaught_exception(exc)
  File "/home/mobilitysqr/.local/lib/python3.6/site-packages/rest_framework/views.py", line 492, in dispatch
    response = handler(request, *args, **kwargs)
  File "/var/www/html/mobilitysqr_staging/mobility_apps/letter/views.py", line 306, in get
    datas['SchoolTuitionSelf']=school[0]['annual_ammount']
  File "/home/mobilitysqr/.local/lib/python3.6/site-packages/django/db/models/query.py", line 303, in __getitem__
    return qs._result_cache[0]
IndexError: list index out of range
ERROR|27/Apr/2021 09:59:26|basehttp|16244|139771447863040|"GET /getassignmentletter/?travel_req_id=TR101700 HTTP/1.1" 500 17548
ERROR|27/Apr/2021 10:16:59|exception|16244|139771447863040|Invalid HTTP_HOST header: ''. The domain name provided is not valid according to RFC 1034/1035.
ERROR|27/Apr/2021 10:35:34|exception|16244|139771447863040|Invalid HTTP_HOST header: ''. The domain name provided is not valid according to RFC 1034/1035.
