ERROR|07/Jan/2021 11:38:32|log|2780|140637447247616|Internal Server Error: /get_upcoming_travel_request/
Traceback (most recent call last):
  File "/home/mobilitysqr/.local/lib/python3.6/site-packages/django/utils/datastructures.py", line 77, in __getitem__
    list_ = super().__getitem__(key)
KeyError: 'emp_email'

During handling of the above exception, another exception occurred:

Traceback (most recent call last):
  File "/home/mobilitysqr/.local/lib/python3.6/site-packages/django/core/handlers/exception.py", line 34, in inner
    response = get_response(request)
  File "/home/mobilitysqr/.local/lib/python3.6/site-packages/django/core/handlers/base.py", line 126, in _get_response
    response = self.process_exception_by_middleware(e, request)
  File "/home/mobilitysqr/.local/lib/python3.6/site-packages/django/core/handlers/base.py", line 124, in _get_response
    response = wrapped_callback(request, *callback_args, **callback_kwargs)
  File "/home/mobilitysqr/.local/lib/python3.6/site-packages/django/views/decorators/csrf.py", line 54, in wrapped_view
    return view_func(*args, **kwargs)
  File "/home/mobilitysqr/.local/lib/python3.6/site-packages/django/views/generic/base.py", line 68, in view
    return self.dispatch(request, *args, **kwargs)
  File "/home/mobilitysqr/.local/lib/python3.6/site-packages/rest_framework/views.py", line 495, in dispatch
    response = self.handle_exception(exc)
  File "/home/mobilitysqr/.local/lib/python3.6/site-packages/rest_framework/views.py", line 455, in handle_exception
    self.raise_uncaught_exception(exc)
  File "/home/mobilitysqr/.local/lib/python3.6/site-packages/rest_framework/views.py", line 492, in dispatch
    response = handler(request, *args, **kwargs)
  File "/var/www/html/mobilitysqr_staging/mobility_apps/travel/views.py", line 2419, in get
    travel_request = self.get_queryset(request.GET["emp_email"],request.GET["org_id"])
  File "/home/mobilitysqr/.local/lib/python3.6/site-packages/django/utils/datastructures.py", line 79, in __getitem__
    raise MultiValueDictKeyError(key)
django.utils.datastructures.MultiValueDictKeyError: 'emp_email'
ERROR|07/Jan/2021 11:38:32|basehttp|2780|140637447247616|"GET /get_upcoming_travel_request/ HTTP/1.1" 500 17566
ERROR|07/Jan/2021 11:40:14|log|2780|140637328361216|Internal Server Error: /get_upcoming_travel_request/
Traceback (most recent call last):
  File "/home/mobilitysqr/.local/lib/python3.6/site-packages/django/core/handlers/exception.py", line 34, in inner
    response = get_response(request)
  File "/home/mobilitysqr/.local/lib/python3.6/site-packages/django/core/handlers/base.py", line 126, in _get_response
    response = self.process_exception_by_middleware(e, request)
  File "/home/mobilitysqr/.local/lib/python3.6/site-packages/django/core/handlers/base.py", line 124, in _get_response
    response = wrapped_callback(request, *callback_args, **callback_kwargs)
  File "/home/mobilitysqr/.local/lib/python3.6/site-packages/django/views/decorators/csrf.py", line 54, in wrapped_view
    return view_func(*args, **kwargs)
  File "/home/mobilitysqr/.local/lib/python3.6/site-packages/django/views/generic/base.py", line 68, in view
    return self.dispatch(request, *args, **kwargs)
  File "/home/mobilitysqr/.local/lib/python3.6/site-packages/rest_framework/views.py", line 495, in dispatch
    response = self.handle_exception(exc)
  File "/home/mobilitysqr/.local/lib/python3.6/site-packages/rest_framework/views.py", line 455, in handle_exception
    self.raise_uncaught_exception(exc)
  File "/home/mobilitysqr/.local/lib/python3.6/site-packages/rest_framework/views.py", line 492, in dispatch
    response = handler(request, *args, **kwargs)
  File "/var/www/html/mobilitysqr_staging/mobility_apps/travel/views.py", line 2419, in get
    travel_request = self.get_queryset(request.GET["emp_email"],request.GET["org_id"])
TypeError: get_queryset() missing 1 required positional argument: 'org_id'
ERROR|07/Jan/2021 11:40:14|basehttp|2780|140637328361216|"GET /get_upcoming_travel_request/?emp_email=div944&org_id=ORG150866 HTTP/1.1" 500 17342
ERROR|07/Jan/2021 11:40:27|log|2780|140637328361216|Internal Server Error: /get_upcoming_travel_request/
Traceback (most recent call last):
  File "/home/mobilitysqr/.local/lib/python3.6/site-packages/django/core/handlers/exception.py", line 34, in inner
    response = get_response(request)
  File "/home/mobilitysqr/.local/lib/python3.6/site-packages/django/core/handlers/base.py", line 126, in _get_response
    response = self.process_exception_by_middleware(e, request)
  File "/home/mobilitysqr/.local/lib/python3.6/site-packages/django/core/handlers/base.py", line 124, in _get_response
    response = wrapped_callback(request, *callback_args, **callback_kwargs)
  File "/home/mobilitysqr/.local/lib/python3.6/site-packages/django/views/decorators/csrf.py", line 54, in wrapped_view
    return view_func(*args, **kwargs)
  File "/home/mobilitysqr/.local/lib/python3.6/site-packages/django/views/generic/base.py", line 68, in view
    return self.dispatch(request, *args, **kwargs)
  File "/home/mobilitysqr/.local/lib/python3.6/site-packages/rest_framework/views.py", line 495, in dispatch
    response = self.handle_exception(exc)
  File "/home/mobilitysqr/.local/lib/python3.6/site-packages/rest_framework/views.py", line 455, in handle_exception
    self.raise_uncaught_exception(exc)
  File "/home/mobilitysqr/.local/lib/python3.6/site-packages/rest_framework/views.py", line 492, in dispatch
    response = handler(request, *args, **kwargs)
  File "/var/www/html/mobilitysqr_staging/mobility_apps/travel/views.py", line 2419, in get
    travel_request = self.get_queryset(request.GET["emp_email"],request.GET["org_id"])
TypeError: get_queryset() missing 1 required positional argument: 'org_id'
ERROR|07/Jan/2021 11:40:27|basehttp|2780|140637328361216|"GET /get_upcoming_travel_request/?emp_email=div944&org_id=ORG150866 HTTP/1.1" 500 17342
ERROR|07/Jan/2021 12:05:53|exception|3004|139846781105920|Invalid HTTP_HOST header: ''. The domain name provided is not valid according to RFC 1034/1035.
ERROR|07/Jan/2021 13:13:29|exception|6167|140105101072128|Invalid HTTP_HOST header: ''. The domain name provided is not valid according to RFC 1034/1035.
ERROR|07/Jan/2021 14:40:29|exception|6167|140105101072128|Invalid HTTP_HOST header: ''. The domain name provided is not valid according to RFC 1034/1035.
ERROR|07/Jan/2021 14:46:42|exception|6167|140105101072128|Invalid HTTP_HOST header: ''. The domain name provided is not valid according to RFC 1034/1035.
