ERROR|01/Apr/2021 09:49:24|exception|5139|139821623080704|Invalid HTTP_HOST header: ''. The domain name provided is not valid according to RFC 1034/1035.
ERROR|01/Apr/2021 10:19:48|exception|5139|139821623080704|Invalid HTTP_HOST header: ''. The domain name provided is not valid according to RFC 1034/1035.
ERROR|01/Apr/2021 10:19:48|basehttp|5139|139821623080704|"GET /manager/html HTTP/1.1" 500 59
ERROR|01/Apr/2021 11:42:19|exception|5139|139821623080704|Invalid HTTP_HOST header: ''. The domain name provided is not valid according to RFC 1034/1035.
ERROR|01/Apr/2021 11:42:19|basehttp|5139|139821623080704|"GET /manager/html HTTP/1.1" 500 59
ERROR|01/Apr/2021 13:03:17|exception|5139|139821494290176|Invalid HTTP_HOST header: ''. The domain name provided is not valid according to RFC 1034/1035.
ERROR|01/Apr/2021 13:03:17|basehttp|5139|139821494290176|"GET /manager/html HTTP/1.1" 500 59
ERROR|01/Apr/2021 13:13:00|log|15712|139861507958528|Internal Server Error: /employee_chat/
Traceback (most recent call last):
  File "/home/mobilitysqr/.local/lib/python3.6/site-packages/django/db/backends/utils.py", line 85, in _execute
    return self.cursor.execute(sql, params)
  File "/home/mobilitysqr/.local/lib/python3.6/site-packages/sql_server/pyodbc/base.py", line 546, in execute
    return self.cursor.execute(sql, params)
pyodbc.ProgrammingError: ('42S22', "[42S22] [Microsoft][ODBC Driver 17 for SQL Server][SQL Server]Invalid column name 'ticket_id'. (207) (SQLExecDirectW)")

The above exception was the direct cause of the following exception:

Traceback (most recent call last):
  File "/home/mobilitysqr/.local/lib/python3.6/site-packages/django/core/handlers/exception.py", line 34, in inner
    response = get_response(request)
  File "/home/mobilitysqr/.local/lib/python3.6/site-packages/django/core/handlers/base.py", line 126, in _get_response
    response = self.process_exception_by_middleware(e, request)
  File "/home/mobilitysqr/.local/lib/python3.6/site-packages/django/core/handlers/base.py", line 124, in _get_response
    response = wrapped_callback(request, *callback_args, **callback_kwargs)
  File "/home/mobilitysqr/.local/lib/python3.6/site-packages/django/views/decorators/csrf.py", line 54, in wrapped_view
    return view_func(*args, **kwargs)
  File "/home/mobilitysqr/.local/lib/python3.6/site-packages/django/views/generic/base.py", line 68, in view
    return self.dispatch(request, *args, **kwargs)
  File "/home/mobilitysqr/.local/lib/python3.6/site-packages/rest_framework/views.py", line 495, in dispatch
    response = self.handle_exception(exc)
  File "/home/mobilitysqr/.local/lib/python3.6/site-packages/rest_framework/views.py", line 455, in handle_exception
    self.raise_uncaught_exception(exc)
  File "/home/mobilitysqr/.local/lib/python3.6/site-packages/rest_framework/views.py", line 492, in dispatch
    response = handler(request, *args, **kwargs)
  File "/var/www/html/mobilitysqr_staging/mobility_apps/employee/views.py", line 2773, in get
    if serializer.data:
  File "/home/mobilitysqr/.local/lib/python3.6/site-packages/rest_framework/serializers.py", line 768, in data
    ret = super(ListSerializer, self).data
  File "/home/mobilitysqr/.local/lib/python3.6/site-packages/rest_framework/serializers.py", line 262, in data
    self._data = self.to_representation(self.instance)
  File "/home/mobilitysqr/.local/lib/python3.6/site-packages/rest_framework/serializers.py", line 686, in to_representation
    self.child.to_representation(item) for item in iterable
  File "/home/mobilitysqr/.local/lib/python3.6/site-packages/django/db/models/query.py", line 268, in __iter__
    self._fetch_all()
  File "/home/mobilitysqr/.local/lib/python3.6/site-packages/django/db/models/query.py", line 1183, in _fetch_all
    self._result_cache = list(self._iterable_class(self))
  File "/home/mobilitysqr/.local/lib/python3.6/site-packages/django/db/models/query.py", line 54, in __iter__
    results = compiler.execute_sql(chunked_fetch=self.chunked_fetch, chunk_size=self.chunk_size)
  File "/home/mobilitysqr/.local/lib/python3.6/site-packages/django/db/models/sql/compiler.py", line 1061, in execute_sql
    cursor.execute(sql, params)
  File "/home/mobilitysqr/.local/lib/python3.6/site-packages/django/db/backends/utils.py", line 100, in execute
    return super().execute(sql, params)
  File "/home/mobilitysqr/.local/lib/python3.6/site-packages/django/db/backends/utils.py", line 68, in execute
    return self._execute_with_wrappers(sql, params, many=False, executor=self._execute)
  File "/home/mobilitysqr/.local/lib/python3.6/site-packages/django/db/backends/utils.py", line 77, in _execute_with_wrappers
    return executor(sql, params, many, context)
  File "/home/mobilitysqr/.local/lib/python3.6/site-packages/django/db/backends/utils.py", line 85, in _execute
    return self.cursor.execute(sql, params)
  File "/home/mobilitysqr/.local/lib/python3.6/site-packages/django/db/utils.py", line 89, in __exit__
    raise dj_exc_value.with_traceback(traceback) from exc_value
  File "/home/mobilitysqr/.local/lib/python3.6/site-packages/django/db/backends/utils.py", line 85, in _execute
    return self.cursor.execute(sql, params)
  File "/home/mobilitysqr/.local/lib/python3.6/site-packages/sql_server/pyodbc/base.py", line 546, in execute
    return self.cursor.execute(sql, params)
django.db.utils.ProgrammingError: ('42S22', "[42S22] [Microsoft][ODBC Driver 17 for SQL Server][SQL Server]Invalid column name 'ticket_id'. (207) (SQLExecDirectW)")
ERROR|01/Apr/2021 13:13:00|basehttp|15712|139861507958528|"GET /employee_chat/?sender_emp_code=div944&receiver_emp_code=VN30 HTTP/1.1" 500 20520
ERROR|01/Apr/2021 13:14:13|log|15783|139819461932800|Internal Server Error: /employee_chat/
Traceback (most recent call last):
  File "/home/mobilitysqr/.local/lib/python3.6/site-packages/django/utils/datastructures.py", line 77, in __getitem__
    list_ = super().__getitem__(key)
KeyError: 'ticket_id'

During handling of the above exception, another exception occurred:

Traceback (most recent call last):
  File "/home/mobilitysqr/.local/lib/python3.6/site-packages/django/core/handlers/exception.py", line 34, in inner
    response = get_response(request)
  File "/home/mobilitysqr/.local/lib/python3.6/site-packages/django/core/handlers/base.py", line 126, in _get_response
    response = self.process_exception_by_middleware(e, request)
  File "/home/mobilitysqr/.local/lib/python3.6/site-packages/django/core/handlers/base.py", line 124, in _get_response
    response = wrapped_callback(request, *callback_args, **callback_kwargs)
  File "/home/mobilitysqr/.local/lib/python3.6/site-packages/django/views/decorators/csrf.py", line 54, in wrapped_view
    return view_func(*args, **kwargs)
  File "/home/mobilitysqr/.local/lib/python3.6/site-packages/django/views/generic/base.py", line 68, in view
    return self.dispatch(request, *args, **kwargs)
  File "/home/mobilitysqr/.local/lib/python3.6/site-packages/rest_framework/views.py", line 495, in dispatch
    response = self.handle_exception(exc)
  File "/home/mobilitysqr/.local/lib/python3.6/site-packages/rest_framework/views.py", line 455, in handle_exception
    self.raise_uncaught_exception(exc)
  File "/home/mobilitysqr/.local/lib/python3.6/site-packages/rest_framework/views.py", line 492, in dispatch
    response = handler(request, *args, **kwargs)
  File "/var/www/html/mobilitysqr_staging/mobility_apps/employee/views.py", line 2764, in get
    ticket_id = request.GET['ticket_id']
  File "/home/mobilitysqr/.local/lib/python3.6/site-packages/django/utils/datastructures.py", line 79, in __getitem__
    raise MultiValueDictKeyError(key)
django.utils.datastructures.MultiValueDictKeyError: 'ticket_id'
ERROR|01/Apr/2021 13:14:13|basehttp|15783|139819461932800|"GET /employee_chat/?sender_emp_code=div944&receiver_emp_code=VN30 HTTP/1.1" 500 17818
ERROR|01/Apr/2021 13:16:43|log|15783|139819237766912|Internal Server Error: /employee_chat/
Traceback (most recent call last):
  File "/home/mobilitysqr/.local/lib/python3.6/site-packages/django/utils/datastructures.py", line 77, in __getitem__
    list_ = super().__getitem__(key)
KeyError: 'ticket_id'

During handling of the above exception, another exception occurred:

Traceback (most recent call last):
  File "/home/mobilitysqr/.local/lib/python3.6/site-packages/django/core/handlers/exception.py", line 34, in inner
    response = get_response(request)
  File "/home/mobilitysqr/.local/lib/python3.6/site-packages/django/core/handlers/base.py", line 126, in _get_response
    response = self.process_exception_by_middleware(e, request)
  File "/home/mobilitysqr/.local/lib/python3.6/site-packages/django/core/handlers/base.py", line 124, in _get_response
    response = wrapped_callback(request, *callback_args, **callback_kwargs)
  File "/home/mobilitysqr/.local/lib/python3.6/site-packages/django/views/decorators/csrf.py", line 54, in wrapped_view
    return view_func(*args, **kwargs)
  File "/home/mobilitysqr/.local/lib/python3.6/site-packages/django/views/generic/base.py", line 68, in view
    return self.dispatch(request, *args, **kwargs)
  File "/home/mobilitysqr/.local/lib/python3.6/site-packages/rest_framework/views.py", line 495, in dispatch
    response = self.handle_exception(exc)
  File "/home/mobilitysqr/.local/lib/python3.6/site-packages/rest_framework/views.py", line 455, in handle_exception
    self.raise_uncaught_exception(exc)
  File "/home/mobilitysqr/.local/lib/python3.6/site-packages/rest_framework/views.py", line 492, in dispatch
    response = handler(request, *args, **kwargs)
  File "/var/www/html/mobilitysqr_staging/mobility_apps/employee/views.py", line 2764, in get
    ticket_id = request.GET['ticket_id']
  File "/home/mobilitysqr/.local/lib/python3.6/site-packages/django/utils/datastructures.py", line 79, in __getitem__
    raise MultiValueDictKeyError(key)
django.utils.datastructures.MultiValueDictKeyError: 'ticket_id'
ERROR|01/Apr/2021 13:16:43|basehttp|15783|139819237766912|"GET /employee_chat/?sender_emp_code=div944&receiver_emp_code=VN30&ticket_idTR176590 HTTP/1.1" 500 17877
ERROR|01/Apr/2021 13:37:52|log|15783|139819462194944|Internal Server Error: /bulk_json_upload/employee/
Traceback (most recent call last):
  File "/home/mobilitysqr/.local/lib/python3.6/site-packages/django/core/handlers/exception.py", line 34, in inner
    response = get_response(request)
  File "/home/mobilitysqr/.local/lib/python3.6/site-packages/django/core/handlers/base.py", line 156, in _get_response
    response = self.process_exception_by_middleware(e, request)
  File "/home/mobilitysqr/.local/lib/python3.6/site-packages/django/core/handlers/base.py", line 154, in _get_response
    response = response.render()
  File "/home/mobilitysqr/.local/lib/python3.6/site-packages/django/template/response.py", line 106, in render
    self.content = self.rendered_content
  File "/home/mobilitysqr/.local/lib/python3.6/site-packages/rest_framework/response.py", line 72, in rendered_content
    ret = renderer.render(self.data, accepted_media_type, context)
  File "/home/mobilitysqr/.local/lib/python3.6/site-packages/rest_framework/renderers.py", line 107, in render
    allow_nan=not self.strict, separators=separators
  File "/home/mobilitysqr/.local/lib/python3.6/site-packages/rest_framework/utils/json.py", line 28, in dumps
    return json.dumps(*args, **kwargs)
  File "/usr/lib/python3.6/json/__init__.py", line 238, in dumps
    **kw).encode(obj)
  File "/usr/lib/python3.6/json/encoder.py", line 199, in encode
    chunks = self.iterencode(o, _one_shot=True)
  File "/usr/lib/python3.6/json/encoder.py", line 257, in iterencode
    return _iterencode(o, 0)
  File "/home/mobilitysqr/.local/lib/python3.6/site-packages/rest_framework/utils/encoders.py", line 68, in default
    return super(JSONEncoder, self).default(obj)
  File "/usr/lib/python3.6/json/encoder.py", line 180, in default
    o.__class__.__name__)
TypeError: Object of type 'KeyError' is not JSON serializable
ERROR|01/Apr/2021 13:37:52|basehttp|15783|139819462194944|"POST /bulk_json_upload/employee/ HTTP/1.1" 500 118715
ERROR|01/Apr/2021 13:39:01|log|15783|139819462194944|Internal Server Error: /bulk_json_upload/employee/
Traceback (most recent call last):
  File "/home/mobilitysqr/.local/lib/python3.6/site-packages/django/core/handlers/exception.py", line 34, in inner
    response = get_response(request)
  File "/home/mobilitysqr/.local/lib/python3.6/site-packages/django/core/handlers/base.py", line 156, in _get_response
    response = self.process_exception_by_middleware(e, request)
  File "/home/mobilitysqr/.local/lib/python3.6/site-packages/django/core/handlers/base.py", line 154, in _get_response
    response = response.render()
  File "/home/mobilitysqr/.local/lib/python3.6/site-packages/django/template/response.py", line 106, in render
    self.content = self.rendered_content
  File "/home/mobilitysqr/.local/lib/python3.6/site-packages/rest_framework/response.py", line 72, in rendered_content
    ret = renderer.render(self.data, accepted_media_type, context)
  File "/home/mobilitysqr/.local/lib/python3.6/site-packages/rest_framework/renderers.py", line 107, in render
    allow_nan=not self.strict, separators=separators
  File "/home/mobilitysqr/.local/lib/python3.6/site-packages/rest_framework/utils/json.py", line 28, in dumps
    return json.dumps(*args, **kwargs)
  File "/usr/lib/python3.6/json/__init__.py", line 238, in dumps
    **kw).encode(obj)
  File "/usr/lib/python3.6/json/encoder.py", line 199, in encode
    chunks = self.iterencode(o, _one_shot=True)
  File "/usr/lib/python3.6/json/encoder.py", line 257, in iterencode
    return _iterencode(o, 0)
  File "/home/mobilitysqr/.local/lib/python3.6/site-packages/rest_framework/utils/encoders.py", line 68, in default
    return super(JSONEncoder, self).default(obj)
  File "/usr/lib/python3.6/json/encoder.py", line 180, in default
    o.__class__.__name__)
TypeError: Object of type 'KeyError' is not JSON serializable
ERROR|01/Apr/2021 13:39:02|basehttp|15783|139819462194944|"POST /bulk_json_upload/employee/ HTTP/1.1" 500 120587
ERROR|01/Apr/2021 14:14:49|basehttp|15783|139819229374208|"GET /config/getuser?index=0 HTTP/1.1" 500 59
ERROR|01/Apr/2021 14:21:30|exception|15783|139819229374208|Invalid HTTP_HOST header: ''. The domain name provided is not valid according to RFC 1034/1035.
ERROR|01/Apr/2021 14:21:30|basehttp|15783|139819229374208|"GET /manager/html HTTP/1.1" 500 59
ERROR|01/Apr/2021 17:29:43|basehttp|15783|139819229374208|You're accessing the development server over HTTPS, but it only supports HTTP.

ERROR|01/Apr/2021 18:01:33|exception|15783|139819229374208|Invalid HTTP_HOST header: ''. The domain name provided is not valid according to RFC 1034/1035.
ERROR|01/Apr/2021 18:01:33|basehttp|15783|139819229374208|"GET /manager/html HTTP/1.1" 500 59
ERROR|01/Apr/2021 20:17:13|exception|15783|139819229374208|Invalid HTTP_HOST header: ''. The domain name provided is not valid according to RFC 1034/1035.
ERROR|01/Apr/2021 20:54:06|exception|15783|139819229374208|Invalid HTTP_HOST header: ''. The domain name provided is not valid according to RFC 1034/1035.
ERROR|01/Apr/2021 21:56:15|log|15783|139819229374208|Internal Server Error: /bulk_json_upload/employee/
Traceback (most recent call last):
  File "/home/mobilitysqr/.local/lib/python3.6/site-packages/django/core/handlers/exception.py", line 34, in inner
    response = get_response(request)
  File "/home/mobilitysqr/.local/lib/python3.6/site-packages/django/core/handlers/base.py", line 156, in _get_response
    response = self.process_exception_by_middleware(e, request)
  File "/home/mobilitysqr/.local/lib/python3.6/site-packages/django/core/handlers/base.py", line 154, in _get_response
    response = response.render()
  File "/home/mobilitysqr/.local/lib/python3.6/site-packages/django/template/response.py", line 106, in render
    self.content = self.rendered_content
  File "/home/mobilitysqr/.local/lib/python3.6/site-packages/rest_framework/response.py", line 72, in rendered_content
    ret = renderer.render(self.data, accepted_media_type, context)
  File "/home/mobilitysqr/.local/lib/python3.6/site-packages/rest_framework/renderers.py", line 107, in render
    allow_nan=not self.strict, separators=separators
  File "/home/mobilitysqr/.local/lib/python3.6/site-packages/rest_framework/utils/json.py", line 28, in dumps
    return json.dumps(*args, **kwargs)
  File "/usr/lib/python3.6/json/__init__.py", line 238, in dumps
    **kw).encode(obj)
  File "/usr/lib/python3.6/json/encoder.py", line 199, in encode
    chunks = self.iterencode(o, _one_shot=True)
  File "/usr/lib/python3.6/json/encoder.py", line 257, in iterencode
    return _iterencode(o, 0)
  File "/home/mobilitysqr/.local/lib/python3.6/site-packages/rest_framework/utils/encoders.py", line 68, in default
    return super(JSONEncoder, self).default(obj)
  File "/usr/lib/python3.6/json/encoder.py", line 180, in default
    o.__class__.__name__)
TypeError: Object of type 'KeyError' is not JSON serializable
ERROR|01/Apr/2021 21:56:15|basehttp|15783|139819229374208|"POST /bulk_json_upload/employee/ HTTP/1.1" 500 120587
ERROR|01/Apr/2021 21:56:42|log|15783|139819229374208|Internal Server Error: /bulk_json_upload/employee/
Traceback (most recent call last):
  File "/home/mobilitysqr/.local/lib/python3.6/site-packages/django/core/handlers/exception.py", line 34, in inner
    response = get_response(request)
  File "/home/mobilitysqr/.local/lib/python3.6/site-packages/django/core/handlers/base.py", line 156, in _get_response
    response = self.process_exception_by_middleware(e, request)
  File "/home/mobilitysqr/.local/lib/python3.6/site-packages/django/core/handlers/base.py", line 154, in _get_response
    response = response.render()
  File "/home/mobilitysqr/.local/lib/python3.6/site-packages/django/template/response.py", line 106, in render
    self.content = self.rendered_content
  File "/home/mobilitysqr/.local/lib/python3.6/site-packages/rest_framework/response.py", line 72, in rendered_content
    ret = renderer.render(self.data, accepted_media_type, context)
  File "/home/mobilitysqr/.local/lib/python3.6/site-packages/rest_framework/renderers.py", line 107, in render
    allow_nan=not self.strict, separators=separators
  File "/home/mobilitysqr/.local/lib/python3.6/site-packages/rest_framework/utils/json.py", line 28, in dumps
    return json.dumps(*args, **kwargs)
  File "/usr/lib/python3.6/json/__init__.py", line 238, in dumps
    **kw).encode(obj)
  File "/usr/lib/python3.6/json/encoder.py", line 199, in encode
    chunks = self.iterencode(o, _one_shot=True)
  File "/usr/lib/python3.6/json/encoder.py", line 257, in iterencode
    return _iterencode(o, 0)
  File "/home/mobilitysqr/.local/lib/python3.6/site-packages/rest_framework/utils/encoders.py", line 68, in default
    return super(JSONEncoder, self).default(obj)
  File "/usr/lib/python3.6/json/encoder.py", line 180, in default
    o.__class__.__name__)
TypeError: Object of type 'KeyError' is not JSON serializable
ERROR|01/Apr/2021 21:56:42|basehttp|15783|139819229374208|"POST /bulk_json_upload/employee/ HTTP/1.1" 500 120587
ERROR|01/Apr/2021 22:25:10|log|15783|139819229374208|Internal Server Error: /bulk_json_upload/employee/
Traceback (most recent call last):
  File "/home/mobilitysqr/.local/lib/python3.6/site-packages/django/core/handlers/exception.py", line 34, in inner
    response = get_response(request)
  File "/home/mobilitysqr/.local/lib/python3.6/site-packages/django/core/handlers/base.py", line 156, in _get_response
    response = self.process_exception_by_middleware(e, request)
  File "/home/mobilitysqr/.local/lib/python3.6/site-packages/django/core/handlers/base.py", line 154, in _get_response
    response = response.render()
  File "/home/mobilitysqr/.local/lib/python3.6/site-packages/django/template/response.py", line 106, in render
    self.content = self.rendered_content
  File "/home/mobilitysqr/.local/lib/python3.6/site-packages/rest_framework/response.py", line 72, in rendered_content
    ret = renderer.render(self.data, accepted_media_type, context)
  File "/home/mobilitysqr/.local/lib/python3.6/site-packages/rest_framework/renderers.py", line 107, in render
    allow_nan=not self.strict, separators=separators
  File "/home/mobilitysqr/.local/lib/python3.6/site-packages/rest_framework/utils/json.py", line 28, in dumps
    return json.dumps(*args, **kwargs)
  File "/usr/lib/python3.6/json/__init__.py", line 238, in dumps
    **kw).encode(obj)
  File "/usr/lib/python3.6/json/encoder.py", line 199, in encode
    chunks = self.iterencode(o, _one_shot=True)
  File "/usr/lib/python3.6/json/encoder.py", line 257, in iterencode
    return _iterencode(o, 0)
  File "/home/mobilitysqr/.local/lib/python3.6/site-packages/rest_framework/utils/encoders.py", line 68, in default
    return super(JSONEncoder, self).default(obj)
  File "/usr/lib/python3.6/json/encoder.py", line 180, in default
    o.__class__.__name__)
TypeError: Object of type 'KeyError' is not JSON serializable
ERROR|01/Apr/2021 22:25:10|basehttp|15783|139819229374208|"POST /bulk_json_upload/employee/ HTTP/1.1" 500 120587
ERROR|01/Apr/2021 22:28:09|log|15783|139819229374208|Internal Server Error: /bulk_json_upload/employee/
Traceback (most recent call last):
  File "/home/mobilitysqr/.local/lib/python3.6/site-packages/django/core/handlers/exception.py", line 34, in inner
    response = get_response(request)
  File "/home/mobilitysqr/.local/lib/python3.6/site-packages/django/core/handlers/base.py", line 156, in _get_response
    response = self.process_exception_by_middleware(e, request)
  File "/home/mobilitysqr/.local/lib/python3.6/site-packages/django/core/handlers/base.py", line 154, in _get_response
    response = response.render()
  File "/home/mobilitysqr/.local/lib/python3.6/site-packages/django/template/response.py", line 106, in render
    self.content = self.rendered_content
  File "/home/mobilitysqr/.local/lib/python3.6/site-packages/rest_framework/response.py", line 72, in rendered_content
    ret = renderer.render(self.data, accepted_media_type, context)
  File "/home/mobilitysqr/.local/lib/python3.6/site-packages/rest_framework/renderers.py", line 107, in render
    allow_nan=not self.strict, separators=separators
  File "/home/mobilitysqr/.local/lib/python3.6/site-packages/rest_framework/utils/json.py", line 28, in dumps
    return json.dumps(*args, **kwargs)
  File "/usr/lib/python3.6/json/__init__.py", line 238, in dumps
    **kw).encode(obj)
  File "/usr/lib/python3.6/json/encoder.py", line 199, in encode
    chunks = self.iterencode(o, _one_shot=True)
  File "/usr/lib/python3.6/json/encoder.py", line 257, in iterencode
    return _iterencode(o, 0)
  File "/home/mobilitysqr/.local/lib/python3.6/site-packages/rest_framework/utils/encoders.py", line 68, in default
    return super(JSONEncoder, self).default(obj)
  File "/usr/lib/python3.6/json/encoder.py", line 180, in default
    o.__class__.__name__)
TypeError: Object of type 'KeyError' is not JSON serializable
ERROR|01/Apr/2021 22:28:10|basehttp|15783|139819229374208|"POST /bulk_json_upload/employee/ HTTP/1.1" 500 120587
ERROR|01/Apr/2021 22:36:07|exception|15783|139819229374208|Invalid HTTP_HOST header: ''. The domain name provided is not valid according to RFC 1034/1035.
