ERROR|23/Feb/2021 15:08:20|exception|3441|140162106877696|Invalid HTTP_HOST header: ''. The domain name provided is not valid according to RFC 1034/1035.
ERROR|23/Feb/2021 15:08:20|basehttp|3441|140162106877696|"GET /manager/html HTTP/1.1" 500 59
ERROR|23/Feb/2021 16:20:45|exception|6288|140527563433728|Invalid HTTP_HOST header: ''. The domain name provided is not valid according to RFC 1034/1035.
ERROR|23/Feb/2021 16:20:45|basehttp|6288|140527563433728|"GET /manager/html HTTP/1.1" 500 59
ERROR|23/Feb/2021 16:22:17|log|6288|140527563433728|Internal Server Error: /access_token/
Traceback (most recent call last):
  File "/home/mobilitysqr/.local/lib/python3.6/site-packages/django/core/handlers/exception.py", line 34, in inner
    response = get_response(request)
  File "/home/mobilitysqr/.local/lib/python3.6/site-packages/django/core/handlers/base.py", line 126, in _get_response
    response = self.process_exception_by_middleware(e, request)
  File "/home/mobilitysqr/.local/lib/python3.6/site-packages/django/core/handlers/base.py", line 124, in _get_response
    response = wrapped_callback(request, *callback_args, **callback_kwargs)
  File "/home/mobilitysqr/.local/lib/python3.6/site-packages/django/views/decorators/csrf.py", line 54, in wrapped_view
    return view_func(*args, **kwargs)
  File "/home/mobilitysqr/.local/lib/python3.6/site-packages/django/views/generic/base.py", line 68, in view
    return self.dispatch(request, *args, **kwargs)
  File "/home/mobilitysqr/.local/lib/python3.6/site-packages/rest_framework/views.py", line 495, in dispatch
    response = self.handle_exception(exc)
  File "/home/mobilitysqr/.local/lib/python3.6/site-packages/rest_framework/views.py", line 455, in handle_exception
    self.raise_uncaught_exception(exc)
  File "/home/mobilitysqr/.local/lib/python3.6/site-packages/rest_framework/views.py", line 492, in dispatch
    response = handler(request, *args, **kwargs)
  File "/var/www/html/mobilitysqr_staging/mobility_apps/employee/views.py", line 1918, in post
    otp=User.objects.filter(otp=otp).values("id")
  File "/home/mobilitysqr/.local/lib/python3.6/site-packages/django/db/models/manager.py", line 82, in manager_method
    return getattr(self.get_queryset(), name)(*args, **kwargs)
  File "/home/mobilitysqr/.local/lib/python3.6/site-packages/django/db/models/query.py", line 841, in filter
    return self._filter_or_exclude(False, *args, **kwargs)
  File "/home/mobilitysqr/.local/lib/python3.6/site-packages/django/db/models/query.py", line 859, in _filter_or_exclude
    clone.query.add_q(Q(*args, **kwargs))
  File "/home/mobilitysqr/.local/lib/python3.6/site-packages/django/db/models/sql/query.py", line 1263, in add_q
    clause, _ = self._add_q(q_object, self.used_aliases)
  File "/home/mobilitysqr/.local/lib/python3.6/site-packages/django/db/models/sql/query.py", line 1287, in _add_q
    split_subq=split_subq,
  File "/home/mobilitysqr/.local/lib/python3.6/site-packages/django/db/models/sql/query.py", line 1225, in build_filter
    condition = self.build_lookup(lookups, col, value)
  File "/home/mobilitysqr/.local/lib/python3.6/site-packages/django/db/models/sql/query.py", line 1096, in build_lookup
    lookup = lookup_class(lhs, rhs)
  File "/home/mobilitysqr/.local/lib/python3.6/site-packages/django/db/models/lookups.py", line 20, in __init__
    self.rhs = self.get_prep_lookup()
  File "/home/mobilitysqr/.local/lib/python3.6/site-packages/django/db/models/lookups.py", line 70, in get_prep_lookup
    return self.lhs.output_field.get_prep_value(self.rhs)
  File "/home/mobilitysqr/.local/lib/python3.6/site-packages/django/db/models/fields/__init__.py", line 1807, in get_prep_value
    return int(value)
ValueError: invalid literal for int() with base 10: 'fdfgd'
ERROR|23/Feb/2021 16:22:17|basehttp|6288|140527563433728|"POST /access_token/ HTTP/1.1" 500 18758
ERROR|23/Feb/2021 18:12:12|log|10908|140368832386816|Internal Server Error: /get_add/travel_request/
Traceback (most recent call last):
  File "/home/mobilitysqr/.local/lib/python3.6/site-packages/django/core/handlers/exception.py", line 34, in inner
    response = get_response(request)
  File "/home/mobilitysqr/.local/lib/python3.6/site-packages/django/core/handlers/base.py", line 126, in _get_response
    response = self.process_exception_by_middleware(e, request)
  File "/home/mobilitysqr/.local/lib/python3.6/site-packages/django/core/handlers/base.py", line 124, in _get_response
    response = wrapped_callback(request, *callback_args, **callback_kwargs)
  File "/home/mobilitysqr/.local/lib/python3.6/site-packages/django/views/decorators/csrf.py", line 54, in wrapped_view
    return view_func(*args, **kwargs)
  File "/home/mobilitysqr/.local/lib/python3.6/site-packages/django/views/generic/base.py", line 68, in view
    return self.dispatch(request, *args, **kwargs)
  File "/home/mobilitysqr/.local/lib/python3.6/site-packages/rest_framework/views.py", line 495, in dispatch
    response = self.handle_exception(exc)
  File "/home/mobilitysqr/.local/lib/python3.6/site-packages/rest_framework/views.py", line 455, in handle_exception
    self.raise_uncaught_exception(exc)
  File "/home/mobilitysqr/.local/lib/python3.6/site-packages/rest_framework/views.py", line 492, in dispatch
    response = handler(request, *args, **kwargs)
  File "/var/www/html/mobilitysqr_staging/mobility_apps/travel/views.py", line 122, in get
    for data in travel_request:
  File "/home/mobilitysqr/.local/lib/python3.6/site-packages/django/template/response.py", line 120, in __iter__
    'The response content must be rendered before it can be iterated over.'
django.template.response.ContentNotRenderedError: The response content must be rendered before it can be iterated over.
ERROR|23/Feb/2021 18:12:12|basehttp|10908|140368832386816|"GET /get_add/travel_request/?travel_req_status=2&org_id=ORG150866&emp_email=tushaar001 HTTP/1.1" 500 17807
ERROR|23/Feb/2021 18:12:16|log|10908|140368832386816|Internal Server Error: /get_add/travel_request/
Traceback (most recent call last):
  File "/home/mobilitysqr/.local/lib/python3.6/site-packages/django/core/handlers/exception.py", line 34, in inner
    response = get_response(request)
  File "/home/mobilitysqr/.local/lib/python3.6/site-packages/django/core/handlers/base.py", line 126, in _get_response
    response = self.process_exception_by_middleware(e, request)
  File "/home/mobilitysqr/.local/lib/python3.6/site-packages/django/core/handlers/base.py", line 124, in _get_response
    response = wrapped_callback(request, *callback_args, **callback_kwargs)
  File "/home/mobilitysqr/.local/lib/python3.6/site-packages/django/views/decorators/csrf.py", line 54, in wrapped_view
    return view_func(*args, **kwargs)
  File "/home/mobilitysqr/.local/lib/python3.6/site-packages/django/views/generic/base.py", line 68, in view
    return self.dispatch(request, *args, **kwargs)
  File "/home/mobilitysqr/.local/lib/python3.6/site-packages/rest_framework/views.py", line 495, in dispatch
    response = self.handle_exception(exc)
  File "/home/mobilitysqr/.local/lib/python3.6/site-packages/rest_framework/views.py", line 455, in handle_exception
    self.raise_uncaught_exception(exc)
  File "/home/mobilitysqr/.local/lib/python3.6/site-packages/rest_framework/views.py", line 492, in dispatch
    response = handler(request, *args, **kwargs)
  File "/var/www/html/mobilitysqr_staging/mobility_apps/travel/views.py", line 122, in get
    for data in travel_request:
  File "/home/mobilitysqr/.local/lib/python3.6/site-packages/django/template/response.py", line 120, in __iter__
    'The response content must be rendered before it can be iterated over.'
django.template.response.ContentNotRenderedError: The response content must be rendered before it can be iterated over.
ERROR|23/Feb/2021 18:12:16|basehttp|10908|140368832386816|"GET /get_add/travel_request/?travel_req_status=2&org_id=ORG150866&emp_email=tushaar001 HTTP/1.1" 500 17807
ERROR|23/Feb/2021 18:12:40|log|10908|140368725145344|Internal Server Error: /get_add/travel_request/
Traceback (most recent call last):
  File "/home/mobilitysqr/.local/lib/python3.6/site-packages/django/core/handlers/exception.py", line 34, in inner
    response = get_response(request)
  File "/home/mobilitysqr/.local/lib/python3.6/site-packages/django/core/handlers/base.py", line 126, in _get_response
    response = self.process_exception_by_middleware(e, request)
  File "/home/mobilitysqr/.local/lib/python3.6/site-packages/django/core/handlers/base.py", line 124, in _get_response
    response = wrapped_callback(request, *callback_args, **callback_kwargs)
  File "/home/mobilitysqr/.local/lib/python3.6/site-packages/django/views/decorators/csrf.py", line 54, in wrapped_view
    return view_func(*args, **kwargs)
  File "/home/mobilitysqr/.local/lib/python3.6/site-packages/django/views/generic/base.py", line 68, in view
    return self.dispatch(request, *args, **kwargs)
  File "/home/mobilitysqr/.local/lib/python3.6/site-packages/rest_framework/views.py", line 495, in dispatch
    response = self.handle_exception(exc)
  File "/home/mobilitysqr/.local/lib/python3.6/site-packages/rest_framework/views.py", line 455, in handle_exception
    self.raise_uncaught_exception(exc)
  File "/home/mobilitysqr/.local/lib/python3.6/site-packages/rest_framework/views.py", line 492, in dispatch
    response = handler(request, *args, **kwargs)
  File "/var/www/html/mobilitysqr_staging/mobility_apps/travel/views.py", line 122, in get
    for data in travel_request:
  File "/home/mobilitysqr/.local/lib/python3.6/site-packages/django/template/response.py", line 120, in __iter__
    'The response content must be rendered before it can be iterated over.'
django.template.response.ContentNotRenderedError: The response content must be rendered before it can be iterated over.
ERROR|23/Feb/2021 18:12:40|basehttp|10908|140368725145344|"GET /get_add/travel_request/?travel_req_status=2&org_id=ORG150866&emp_email=tushaar001 HTTP/1.1" 500 17807
ERROR|23/Feb/2021 18:12:55|log|10908|140368841828096|Internal Server Error: /get_add/travel_request/
Traceback (most recent call last):
  File "/home/mobilitysqr/.local/lib/python3.6/site-packages/django/core/handlers/exception.py", line 34, in inner
    response = get_response(request)
  File "/home/mobilitysqr/.local/lib/python3.6/site-packages/django/core/handlers/base.py", line 126, in _get_response
    response = self.process_exception_by_middleware(e, request)
  File "/home/mobilitysqr/.local/lib/python3.6/site-packages/django/core/handlers/base.py", line 124, in _get_response
    response = wrapped_callback(request, *callback_args, **callback_kwargs)
  File "/home/mobilitysqr/.local/lib/python3.6/site-packages/django/views/decorators/csrf.py", line 54, in wrapped_view
    return view_func(*args, **kwargs)
  File "/home/mobilitysqr/.local/lib/python3.6/site-packages/django/views/generic/base.py", line 68, in view
    return self.dispatch(request, *args, **kwargs)
  File "/home/mobilitysqr/.local/lib/python3.6/site-packages/rest_framework/views.py", line 495, in dispatch
    response = self.handle_exception(exc)
  File "/home/mobilitysqr/.local/lib/python3.6/site-packages/rest_framework/views.py", line 455, in handle_exception
    self.raise_uncaught_exception(exc)
  File "/home/mobilitysqr/.local/lib/python3.6/site-packages/rest_framework/views.py", line 492, in dispatch
    response = handler(request, *args, **kwargs)
  File "/var/www/html/mobilitysqr_staging/mobility_apps/travel/views.py", line 122, in get
    for data in travel_request:
  File "/home/mobilitysqr/.local/lib/python3.6/site-packages/django/template/response.py", line 120, in __iter__
    'The response content must be rendered before it can be iterated over.'
django.template.response.ContentNotRenderedError: The response content must be rendered before it can be iterated over.
ERROR|23/Feb/2021 18:12:55|basehttp|10908|140368841828096|"GET /get_add/travel_request/?travel_req_status=2&org_id=ORG150866&emp_email=tushaar001 HTTP/1.1" 500 17807
ERROR|23/Feb/2021 18:17:16|log|10908|140368841828096|Internal Server Error: /get_add/travel_request/
Traceback (most recent call last):
  File "/home/mobilitysqr/.local/lib/python3.6/site-packages/django/core/handlers/exception.py", line 34, in inner
    response = get_response(request)
  File "/home/mobilitysqr/.local/lib/python3.6/site-packages/django/core/handlers/base.py", line 126, in _get_response
    response = self.process_exception_by_middleware(e, request)
  File "/home/mobilitysqr/.local/lib/python3.6/site-packages/django/core/handlers/base.py", line 124, in _get_response
    response = wrapped_callback(request, *callback_args, **callback_kwargs)
  File "/home/mobilitysqr/.local/lib/python3.6/site-packages/django/views/decorators/csrf.py", line 54, in wrapped_view
    return view_func(*args, **kwargs)
  File "/home/mobilitysqr/.local/lib/python3.6/site-packages/django/views/generic/base.py", line 68, in view
    return self.dispatch(request, *args, **kwargs)
  File "/home/mobilitysqr/.local/lib/python3.6/site-packages/rest_framework/views.py", line 495, in dispatch
    response = self.handle_exception(exc)
  File "/home/mobilitysqr/.local/lib/python3.6/site-packages/rest_framework/views.py", line 455, in handle_exception
    self.raise_uncaught_exception(exc)
  File "/home/mobilitysqr/.local/lib/python3.6/site-packages/rest_framework/views.py", line 492, in dispatch
    response = handler(request, *args, **kwargs)
  File "/var/www/html/mobilitysqr_staging/mobility_apps/travel/views.py", line 122, in get
    for data in travel_request:
  File "/home/mobilitysqr/.local/lib/python3.6/site-packages/django/template/response.py", line 120, in __iter__
    'The response content must be rendered before it can be iterated over.'
django.template.response.ContentNotRenderedError: The response content must be rendered before it can be iterated over.
ERROR|23/Feb/2021 18:17:16|basehttp|10908|140368841828096|"GET /get_add/travel_request/?travel_req_status=2&org_id=ORG150866&emp_email=div944 HTTP/1.1" 500 17761
ERROR|23/Feb/2021 18:17:47|log|10908|140368841828096|Internal Server Error: /get_add/travel_request/
Traceback (most recent call last):
  File "/home/mobilitysqr/.local/lib/python3.6/site-packages/django/core/handlers/exception.py", line 34, in inner
    response = get_response(request)
  File "/home/mobilitysqr/.local/lib/python3.6/site-packages/django/core/handlers/base.py", line 126, in _get_response
    response = self.process_exception_by_middleware(e, request)
  File "/home/mobilitysqr/.local/lib/python3.6/site-packages/django/core/handlers/base.py", line 124, in _get_response
    response = wrapped_callback(request, *callback_args, **callback_kwargs)
  File "/home/mobilitysqr/.local/lib/python3.6/site-packages/django/views/decorators/csrf.py", line 54, in wrapped_view
    return view_func(*args, **kwargs)
  File "/home/mobilitysqr/.local/lib/python3.6/site-packages/django/views/generic/base.py", line 68, in view
    return self.dispatch(request, *args, **kwargs)
  File "/home/mobilitysqr/.local/lib/python3.6/site-packages/rest_framework/views.py", line 495, in dispatch
    response = self.handle_exception(exc)
  File "/home/mobilitysqr/.local/lib/python3.6/site-packages/rest_framework/views.py", line 455, in handle_exception
    self.raise_uncaught_exception(exc)
  File "/home/mobilitysqr/.local/lib/python3.6/site-packages/rest_framework/views.py", line 492, in dispatch
    response = handler(request, *args, **kwargs)
  File "/var/www/html/mobilitysqr_staging/mobility_apps/travel/views.py", line 122, in get
    for data in travel_request:
  File "/home/mobilitysqr/.local/lib/python3.6/site-packages/django/template/response.py", line 120, in __iter__
    'The response content must be rendered before it can be iterated over.'
django.template.response.ContentNotRenderedError: The response content must be rendered before it can be iterated over.
ERROR|23/Feb/2021 18:17:47|basehttp|10908|140368841828096|"GET /get_add/travel_request/?travel_req_status=2&org_id=ORG150866&emp_email=div944 HTTP/1.1" 500 17762
ERROR|23/Feb/2021 18:18:00|log|10908|140368832386816|Internal Server Error: /get_add/travel_request/
Traceback (most recent call last):
  File "/home/mobilitysqr/.local/lib/python3.6/site-packages/django/core/handlers/exception.py", line 34, in inner
    response = get_response(request)
  File "/home/mobilitysqr/.local/lib/python3.6/site-packages/django/core/handlers/base.py", line 126, in _get_response
    response = self.process_exception_by_middleware(e, request)
  File "/home/mobilitysqr/.local/lib/python3.6/site-packages/django/core/handlers/base.py", line 124, in _get_response
    response = wrapped_callback(request, *callback_args, **callback_kwargs)
  File "/home/mobilitysqr/.local/lib/python3.6/site-packages/django/views/decorators/csrf.py", line 54, in wrapped_view
    return view_func(*args, **kwargs)
  File "/home/mobilitysqr/.local/lib/python3.6/site-packages/django/views/generic/base.py", line 68, in view
    return self.dispatch(request, *args, **kwargs)
  File "/home/mobilitysqr/.local/lib/python3.6/site-packages/rest_framework/views.py", line 495, in dispatch
    response = self.handle_exception(exc)
  File "/home/mobilitysqr/.local/lib/python3.6/site-packages/rest_framework/views.py", line 455, in handle_exception
    self.raise_uncaught_exception(exc)
  File "/home/mobilitysqr/.local/lib/python3.6/site-packages/rest_framework/views.py", line 492, in dispatch
    response = handler(request, *args, **kwargs)
  File "/var/www/html/mobilitysqr_staging/mobility_apps/travel/views.py", line 122, in get
    for data in travel_request:
  File "/home/mobilitysqr/.local/lib/python3.6/site-packages/django/template/response.py", line 120, in __iter__
    'The response content must be rendered before it can be iterated over.'
django.template.response.ContentNotRenderedError: The response content must be rendered before it can be iterated over.
ERROR|23/Feb/2021 18:18:00|basehttp|10908|140368832386816|"GET /get_add/travel_request/?travel_req_status=2&org_id=ORG150866&emp_email=div944 HTTP/1.1" 500 17792
ERROR|23/Feb/2021 18:18:21|log|10908|140368832386816|Internal Server Error: /get_add/travel_request/
Traceback (most recent call last):
  File "/home/mobilitysqr/.local/lib/python3.6/site-packages/django/core/handlers/exception.py", line 34, in inner
    response = get_response(request)
  File "/home/mobilitysqr/.local/lib/python3.6/site-packages/django/core/handlers/base.py", line 126, in _get_response
    response = self.process_exception_by_middleware(e, request)
  File "/home/mobilitysqr/.local/lib/python3.6/site-packages/django/core/handlers/base.py", line 124, in _get_response
    response = wrapped_callback(request, *callback_args, **callback_kwargs)
  File "/home/mobilitysqr/.local/lib/python3.6/site-packages/django/views/decorators/csrf.py", line 54, in wrapped_view
    return view_func(*args, **kwargs)
  File "/home/mobilitysqr/.local/lib/python3.6/site-packages/django/views/generic/base.py", line 68, in view
    return self.dispatch(request, *args, **kwargs)
  File "/home/mobilitysqr/.local/lib/python3.6/site-packages/rest_framework/views.py", line 495, in dispatch
    response = self.handle_exception(exc)
  File "/home/mobilitysqr/.local/lib/python3.6/site-packages/rest_framework/views.py", line 455, in handle_exception
    self.raise_uncaught_exception(exc)
  File "/home/mobilitysqr/.local/lib/python3.6/site-packages/rest_framework/views.py", line 492, in dispatch
    response = handler(request, *args, **kwargs)
  File "/var/www/html/mobilitysqr_staging/mobility_apps/travel/views.py", line 122, in get
    for data in travel_request:
  File "/home/mobilitysqr/.local/lib/python3.6/site-packages/django/template/response.py", line 120, in __iter__
    'The response content must be rendered before it can be iterated over.'
django.template.response.ContentNotRenderedError: The response content must be rendered before it can be iterated over.
ERROR|23/Feb/2021 18:18:21|basehttp|10908|140368832386816|"GET /get_add/travel_request/?travel_req_status=2&org_id=ORG150866&emp_email=gauravg HTTP/1.1" 500 17793
ERROR|23/Feb/2021 18:20:12|log|10908|140368841828096|Internal Server Error: /get_add/travel_request/
Traceback (most recent call last):
  File "/home/mobilitysqr/.local/lib/python3.6/site-packages/django/core/handlers/exception.py", line 34, in inner
    response = get_response(request)
  File "/home/mobilitysqr/.local/lib/python3.6/site-packages/django/core/handlers/base.py", line 126, in _get_response
    response = self.process_exception_by_middleware(e, request)
  File "/home/mobilitysqr/.local/lib/python3.6/site-packages/django/core/handlers/base.py", line 124, in _get_response
    response = wrapped_callback(request, *callback_args, **callback_kwargs)
  File "/home/mobilitysqr/.local/lib/python3.6/site-packages/django/views/decorators/csrf.py", line 54, in wrapped_view
    return view_func(*args, **kwargs)
  File "/home/mobilitysqr/.local/lib/python3.6/site-packages/django/views/generic/base.py", line 68, in view
    return self.dispatch(request, *args, **kwargs)
  File "/home/mobilitysqr/.local/lib/python3.6/site-packages/rest_framework/views.py", line 495, in dispatch
    response = self.handle_exception(exc)
  File "/home/mobilitysqr/.local/lib/python3.6/site-packages/rest_framework/views.py", line 455, in handle_exception
    self.raise_uncaught_exception(exc)
  File "/home/mobilitysqr/.local/lib/python3.6/site-packages/rest_framework/views.py", line 492, in dispatch
    response = handler(request, *args, **kwargs)
  File "/var/www/html/mobilitysqr_staging/mobility_apps/travel/views.py", line 122, in get
    for data in travel_request:
  File "/home/mobilitysqr/.local/lib/python3.6/site-packages/django/template/response.py", line 120, in __iter__
    'The response content must be rendered before it can be iterated over.'
django.template.response.ContentNotRenderedError: The response content must be rendered before it can be iterated over.
ERROR|23/Feb/2021 18:20:12|basehttp|10908|140368841828096|"GET /get_add/travel_request/?travel_req_status=2&org_id=ORG150866&emp_email=gauravg HTTP/1.1" 500 17582
ERROR|23/Feb/2021 18:21:44|exception|10908|140368725145344|Invalid HTTP_HOST header: ''. The domain name provided is not valid according to RFC 1034/1035.
ERROR|23/Feb/2021 18:21:44|basehttp|10908|140368725145344|"GET /manager/html HTTP/1.1" 500 59
ERROR|23/Feb/2021 18:29:48|log|10908|140368800663296|Internal Server Error: /get_add/travel_request/
Traceback (most recent call last):
  File "/home/mobilitysqr/.local/lib/python3.6/site-packages/django/core/handlers/exception.py", line 34, in inner
    response = get_response(request)
  File "/home/mobilitysqr/.local/lib/python3.6/site-packages/django/core/handlers/base.py", line 126, in _get_response
    response = self.process_exception_by_middleware(e, request)
  File "/home/mobilitysqr/.local/lib/python3.6/site-packages/django/core/handlers/base.py", line 124, in _get_response
    response = wrapped_callback(request, *callback_args, **callback_kwargs)
  File "/home/mobilitysqr/.local/lib/python3.6/site-packages/django/views/decorators/csrf.py", line 54, in wrapped_view
    return view_func(*args, **kwargs)
  File "/home/mobilitysqr/.local/lib/python3.6/site-packages/django/views/generic/base.py", line 68, in view
    return self.dispatch(request, *args, **kwargs)
  File "/home/mobilitysqr/.local/lib/python3.6/site-packages/rest_framework/views.py", line 495, in dispatch
    response = self.handle_exception(exc)
  File "/home/mobilitysqr/.local/lib/python3.6/site-packages/rest_framework/views.py", line 455, in handle_exception
    self.raise_uncaught_exception(exc)
  File "/home/mobilitysqr/.local/lib/python3.6/site-packages/rest_framework/views.py", line 492, in dispatch
    response = handler(request, *args, **kwargs)
  File "/var/www/html/mobilitysqr_staging/mobility_apps/travel/views.py", line 122, in get
    for data in travel_request:
  File "/home/mobilitysqr/.local/lib/python3.6/site-packages/django/template/response.py", line 120, in __iter__
    'The response content must be rendered before it can be iterated over.'
django.template.response.ContentNotRenderedError: The response content must be rendered before it can be iterated over.
ERROR|23/Feb/2021 18:29:48|basehttp|10908|140368800663296|"GET /get_add/travel_request/?travel_req_status=2&org_id=ORG150866&emp_email=tushaar001 HTTP/1.1" 500 17807
ERROR|23/Feb/2021 18:32:18|log|10908|140368800663296|Internal Server Error: /get_add/travel_request/
Traceback (most recent call last):
  File "/home/mobilitysqr/.local/lib/python3.6/site-packages/django/core/handlers/exception.py", line 34, in inner
    response = get_response(request)
  File "/home/mobilitysqr/.local/lib/python3.6/site-packages/django/core/handlers/base.py", line 126, in _get_response
    response = self.process_exception_by_middleware(e, request)
  File "/home/mobilitysqr/.local/lib/python3.6/site-packages/django/core/handlers/base.py", line 124, in _get_response
    response = wrapped_callback(request, *callback_args, **callback_kwargs)
  File "/home/mobilitysqr/.local/lib/python3.6/site-packages/django/views/decorators/csrf.py", line 54, in wrapped_view
    return view_func(*args, **kwargs)
  File "/home/mobilitysqr/.local/lib/python3.6/site-packages/django/views/generic/base.py", line 68, in view
    return self.dispatch(request, *args, **kwargs)
  File "/home/mobilitysqr/.local/lib/python3.6/site-packages/rest_framework/views.py", line 495, in dispatch
    response = self.handle_exception(exc)
  File "/home/mobilitysqr/.local/lib/python3.6/site-packages/rest_framework/views.py", line 455, in handle_exception
    self.raise_uncaught_exception(exc)
  File "/home/mobilitysqr/.local/lib/python3.6/site-packages/rest_framework/views.py", line 492, in dispatch
    response = handler(request, *args, **kwargs)
  File "/var/www/html/mobilitysqr_staging/mobility_apps/travel/views.py", line 122, in get
    for data in travel_request:
  File "/home/mobilitysqr/.local/lib/python3.6/site-packages/django/template/response.py", line 120, in __iter__
    'The response content must be rendered before it can be iterated over.'
django.template.response.ContentNotRenderedError: The response content must be rendered before it can be iterated over.
ERROR|23/Feb/2021 18:32:18|basehttp|10908|140368800663296|"GET /get_add/travel_request/?travel_req_status=2&org_id=ORG150866&emp_email=tushaar001 HTTP/1.1" 500 17807
ERROR|23/Feb/2021 18:45:29|log|10908|140368699967232|Internal Server Error: /get_add/travel_request/
Traceback (most recent call last):
  File "/home/mobilitysqr/.local/lib/python3.6/site-packages/django/core/handlers/exception.py", line 34, in inner
    response = get_response(request)
  File "/home/mobilitysqr/.local/lib/python3.6/site-packages/django/core/handlers/base.py", line 126, in _get_response
    response = self.process_exception_by_middleware(e, request)
  File "/home/mobilitysqr/.local/lib/python3.6/site-packages/django/core/handlers/base.py", line 124, in _get_response
    response = wrapped_callback(request, *callback_args, **callback_kwargs)
  File "/home/mobilitysqr/.local/lib/python3.6/site-packages/django/views/decorators/csrf.py", line 54, in wrapped_view
    return view_func(*args, **kwargs)
  File "/home/mobilitysqr/.local/lib/python3.6/site-packages/django/views/generic/base.py", line 68, in view
    return self.dispatch(request, *args, **kwargs)
  File "/home/mobilitysqr/.local/lib/python3.6/site-packages/rest_framework/views.py", line 495, in dispatch
    response = self.handle_exception(exc)
  File "/home/mobilitysqr/.local/lib/python3.6/site-packages/rest_framework/views.py", line 455, in handle_exception
    self.raise_uncaught_exception(exc)
  File "/home/mobilitysqr/.local/lib/python3.6/site-packages/rest_framework/views.py", line 492, in dispatch
    response = handler(request, *args, **kwargs)
  File "/var/www/html/mobilitysqr_staging/mobility_apps/travel/views.py", line 122, in get
    for data in travel_request:
  File "/home/mobilitysqr/.local/lib/python3.6/site-packages/django/template/response.py", line 120, in __iter__
    'The response content must be rendered before it can be iterated over.'
django.template.response.ContentNotRenderedError: The response content must be rendered before it can be iterated over.
ERROR|23/Feb/2021 18:45:29|basehttp|10908|140368699967232|"GET /get_add/travel_request/?travel_req_status=2&org_id=ORG150866&emp_email=tushaar001 HTTP/1.1" 500 17807
ERROR|23/Feb/2021 18:50:13|log|10908|140368699967232|Internal Server Error: /get_add/travel_request/
Traceback (most recent call last):
  File "/home/mobilitysqr/.local/lib/python3.6/site-packages/django/core/handlers/exception.py", line 34, in inner
    response = get_response(request)
  File "/home/mobilitysqr/.local/lib/python3.6/site-packages/django/core/handlers/base.py", line 126, in _get_response
    response = self.process_exception_by_middleware(e, request)
  File "/home/mobilitysqr/.local/lib/python3.6/site-packages/django/core/handlers/base.py", line 124, in _get_response
    response = wrapped_callback(request, *callback_args, **callback_kwargs)
  File "/home/mobilitysqr/.local/lib/python3.6/site-packages/django/views/decorators/csrf.py", line 54, in wrapped_view
    return view_func(*args, **kwargs)
  File "/home/mobilitysqr/.local/lib/python3.6/site-packages/django/views/generic/base.py", line 68, in view
    return self.dispatch(request, *args, **kwargs)
  File "/home/mobilitysqr/.local/lib/python3.6/site-packages/rest_framework/views.py", line 495, in dispatch
    response = self.handle_exception(exc)
  File "/home/mobilitysqr/.local/lib/python3.6/site-packages/rest_framework/views.py", line 455, in handle_exception
    self.raise_uncaught_exception(exc)
  File "/home/mobilitysqr/.local/lib/python3.6/site-packages/rest_framework/views.py", line 492, in dispatch
    response = handler(request, *args, **kwargs)
  File "/var/www/html/mobilitysqr_staging/mobility_apps/travel/views.py", line 122, in get
    for data in travel_request:
  File "/home/mobilitysqr/.local/lib/python3.6/site-packages/django/template/response.py", line 120, in __iter__
    'The response content must be rendered before it can be iterated over.'
django.template.response.ContentNotRenderedError: The response content must be rendered before it can be iterated over.
ERROR|23/Feb/2021 18:50:13|basehttp|10908|140368699967232|"GET /get_add/travel_request/?travel_req_status=2&org_id=ORG150866&emp_email=tushaar001 HTTP/1.1" 500 17807
ERROR|23/Feb/2021 18:50:23|log|10908|140368708359936|Internal Server Error: /get_add/travel_request/
Traceback (most recent call last):
  File "/home/mobilitysqr/.local/lib/python3.6/site-packages/django/core/handlers/exception.py", line 34, in inner
    response = get_response(request)
  File "/home/mobilitysqr/.local/lib/python3.6/site-packages/django/core/handlers/base.py", line 126, in _get_response
    response = self.process_exception_by_middleware(e, request)
  File "/home/mobilitysqr/.local/lib/python3.6/site-packages/django/core/handlers/base.py", line 124, in _get_response
    response = wrapped_callback(request, *callback_args, **callback_kwargs)
  File "/home/mobilitysqr/.local/lib/python3.6/site-packages/django/views/decorators/csrf.py", line 54, in wrapped_view
    return view_func(*args, **kwargs)
  File "/home/mobilitysqr/.local/lib/python3.6/site-packages/django/views/generic/base.py", line 68, in view
    return self.dispatch(request, *args, **kwargs)
  File "/home/mobilitysqr/.local/lib/python3.6/site-packages/rest_framework/views.py", line 495, in dispatch
    response = self.handle_exception(exc)
  File "/home/mobilitysqr/.local/lib/python3.6/site-packages/rest_framework/views.py", line 455, in handle_exception
    self.raise_uncaught_exception(exc)
  File "/home/mobilitysqr/.local/lib/python3.6/site-packages/rest_framework/views.py", line 492, in dispatch
    response = handler(request, *args, **kwargs)
  File "/var/www/html/mobilitysqr_staging/mobility_apps/travel/views.py", line 122, in get
    for data in travel_request:
  File "/home/mobilitysqr/.local/lib/python3.6/site-packages/django/template/response.py", line 120, in __iter__
    'The response content must be rendered before it can be iterated over.'
django.template.response.ContentNotRenderedError: The response content must be rendered before it can be iterated over.
ERROR|23/Feb/2021 18:50:23|basehttp|10908|140368708359936|"GET /get_add/travel_request/?travel_req_status=2&org_id=ORG150866&emp_email=tushaar001 HTTP/1.1" 500 17807
ERROR|23/Feb/2021 18:50:27|log|10908|140368708359936|Internal Server Error: /get_add/travel_request/
Traceback (most recent call last):
  File "/home/mobilitysqr/.local/lib/python3.6/site-packages/django/core/handlers/exception.py", line 34, in inner
    response = get_response(request)
  File "/home/mobilitysqr/.local/lib/python3.6/site-packages/django/core/handlers/base.py", line 126, in _get_response
    response = self.process_exception_by_middleware(e, request)
  File "/home/mobilitysqr/.local/lib/python3.6/site-packages/django/core/handlers/base.py", line 124, in _get_response
    response = wrapped_callback(request, *callback_args, **callback_kwargs)
  File "/home/mobilitysqr/.local/lib/python3.6/site-packages/django/views/decorators/csrf.py", line 54, in wrapped_view
    return view_func(*args, **kwargs)
  File "/home/mobilitysqr/.local/lib/python3.6/site-packages/django/views/generic/base.py", line 68, in view
    return self.dispatch(request, *args, **kwargs)
  File "/home/mobilitysqr/.local/lib/python3.6/site-packages/rest_framework/views.py", line 495, in dispatch
    response = self.handle_exception(exc)
  File "/home/mobilitysqr/.local/lib/python3.6/site-packages/rest_framework/views.py", line 455, in handle_exception
    self.raise_uncaught_exception(exc)
  File "/home/mobilitysqr/.local/lib/python3.6/site-packages/rest_framework/views.py", line 492, in dispatch
    response = handler(request, *args, **kwargs)
  File "/var/www/html/mobilitysqr_staging/mobility_apps/travel/views.py", line 122, in get
    for data in travel_request:
  File "/home/mobilitysqr/.local/lib/python3.6/site-packages/django/template/response.py", line 120, in __iter__
    'The response content must be rendered before it can be iterated over.'
django.template.response.ContentNotRenderedError: The response content must be rendered before it can be iterated over.
ERROR|23/Feb/2021 18:50:27|basehttp|10908|140368708359936|"GET /get_add/travel_request/?travel_req_status=2&org_id=ORG150866&emp_email=tushaar001 HTTP/1.1" 500 17807
ERROR|23/Feb/2021 18:51:10|log|10908|140368708359936|Internal Server Error: /get_add/travel_request/
Traceback (most recent call last):
  File "/home/mobilitysqr/.local/lib/python3.6/site-packages/django/core/handlers/exception.py", line 34, in inner
    response = get_response(request)
  File "/home/mobilitysqr/.local/lib/python3.6/site-packages/django/core/handlers/base.py", line 126, in _get_response
    response = self.process_exception_by_middleware(e, request)
  File "/home/mobilitysqr/.local/lib/python3.6/site-packages/django/core/handlers/base.py", line 124, in _get_response
    response = wrapped_callback(request, *callback_args, **callback_kwargs)
  File "/home/mobilitysqr/.local/lib/python3.6/site-packages/django/views/decorators/csrf.py", line 54, in wrapped_view
    return view_func(*args, **kwargs)
  File "/home/mobilitysqr/.local/lib/python3.6/site-packages/django/views/generic/base.py", line 68, in view
    return self.dispatch(request, *args, **kwargs)
  File "/home/mobilitysqr/.local/lib/python3.6/site-packages/rest_framework/views.py", line 495, in dispatch
    response = self.handle_exception(exc)
  File "/home/mobilitysqr/.local/lib/python3.6/site-packages/rest_framework/views.py", line 455, in handle_exception
    self.raise_uncaught_exception(exc)
  File "/home/mobilitysqr/.local/lib/python3.6/site-packages/rest_framework/views.py", line 492, in dispatch
    response = handler(request, *args, **kwargs)
  File "/var/www/html/mobilitysqr_staging/mobility_apps/travel/views.py", line 122, in get
    for data in travel_request:
  File "/home/mobilitysqr/.local/lib/python3.6/site-packages/django/template/response.py", line 120, in __iter__
    'The response content must be rendered before it can be iterated over.'
django.template.response.ContentNotRenderedError: The response content must be rendered before it can be iterated over.
ERROR|23/Feb/2021 18:51:10|basehttp|10908|140368708359936|"GET /get_add/travel_request/?travel_req_status=2&org_id=ORG150866&emp_email=tushaar001 HTTP/1.1" 500 17807
ERROR|23/Feb/2021 18:52:11|log|10908|140368708359936|Internal Server Error: /get_add/travel_request/
Traceback (most recent call last):
  File "/home/mobilitysqr/.local/lib/python3.6/site-packages/django/core/handlers/exception.py", line 34, in inner
    response = get_response(request)
  File "/home/mobilitysqr/.local/lib/python3.6/site-packages/django/core/handlers/base.py", line 126, in _get_response
    response = self.process_exception_by_middleware(e, request)
  File "/home/mobilitysqr/.local/lib/python3.6/site-packages/django/core/handlers/base.py", line 124, in _get_response
    response = wrapped_callback(request, *callback_args, **callback_kwargs)
  File "/home/mobilitysqr/.local/lib/python3.6/site-packages/django/views/decorators/csrf.py", line 54, in wrapped_view
    return view_func(*args, **kwargs)
  File "/home/mobilitysqr/.local/lib/python3.6/site-packages/django/views/generic/base.py", line 68, in view
    return self.dispatch(request, *args, **kwargs)
  File "/home/mobilitysqr/.local/lib/python3.6/site-packages/rest_framework/views.py", line 495, in dispatch
    response = self.handle_exception(exc)
  File "/home/mobilitysqr/.local/lib/python3.6/site-packages/rest_framework/views.py", line 455, in handle_exception
    self.raise_uncaught_exception(exc)
  File "/home/mobilitysqr/.local/lib/python3.6/site-packages/rest_framework/views.py", line 492, in dispatch
    response = handler(request, *args, **kwargs)
  File "/var/www/html/mobilitysqr_staging/mobility_apps/travel/views.py", line 122, in get
    for data in travel_request:
  File "/home/mobilitysqr/.local/lib/python3.6/site-packages/django/template/response.py", line 120, in __iter__
    'The response content must be rendered before it can be iterated over.'
django.template.response.ContentNotRenderedError: The response content must be rendered before it can be iterated over.
ERROR|23/Feb/2021 18:52:11|basehttp|10908|140368708359936|"GET /get_add/travel_request/?travel_req_status=2&org_id=ORG150866&emp_email=tushaar001 HTTP/1.1" 500 17807
ERROR|23/Feb/2021 19:36:51|basehttp|13079|140144245860096|You're accessing the development server over HTTPS, but it only supports HTTP.

ERROR|23/Feb/2021 20:17:00|exception|13079|140144245860096|Invalid HTTP_HOST header: ''. The domain name provided is not valid according to RFC 1034/1035.
ERROR|23/Feb/2021 20:20:29|exception|13079|140144245860096|Invalid HTTP_HOST header: ''. The domain name provided is not valid according to RFC 1034/1035.
ERROR|23/Feb/2021 20:20:35|exception|13079|140144245860096|Invalid HTTP_HOST header: ''. The domain name provided is not valid according to RFC 1034/1035.
ERROR|23/Feb/2021 20:26:36|exception|13079|140144245860096|Invalid HTTP_HOST header: ''. The domain name provided is not valid according to RFC 1034/1035.
ERROR|23/Feb/2021 21:08:42|exception|13079|140144245860096|Invalid HTTP_HOST header: ''. The domain name provided is not valid according to RFC 1034/1035.
ERROR|23/Feb/2021 21:18:34|exception|13079|140144245860096|Invalid HTTP_HOST header: ''. The domain name provided is not valid according to RFC 1034/1035.
ERROR|23/Feb/2021 21:27:28|exception|13079|140144245860096|Invalid HTTP_HOST header: ''. The domain name provided is not valid according to RFC 1034/1035.
ERROR|23/Feb/2021 21:53:19|exception|13079|140144245860096|Invalid HTTP_HOST header: ''. The domain name provided is not valid according to RFC 1034/1035.
ERROR|23/Feb/2021 22:14:43|exception|13079|140144245860096|Invalid HTTP_HOST header: ''. The domain name provided is not valid according to RFC 1034/1035.
ERROR|23/Feb/2021 22:28:57|exception|13079|140144215176960|Invalid HTTP_HOST header: ''. The domain name provided is not valid according to RFC 1034/1035.
ERROR|23/Feb/2021 22:28:57|basehttp|13079|140144215176960|"GET /manager/html HTTP/1.1" 500 59
ERROR|23/Feb/2021 23:13:22|exception|13079|140144215176960|Invalid HTTP_HOST header: ''. The domain name provided is not valid according to RFC 1034/1035.
ERROR|23/Feb/2021 23:58:43|exception|13079|140144215176960|Invalid HTTP_HOST header: ''. The domain name provided is not valid according to RFC 1034/1035.
ERROR|23/Feb/2021 23:58:43|basehttp|13079|140144215176960|"GET /manager/html HTTP/1.1" 500 59
ERROR|24/Feb/2021 00:48:44|exception|13079|140144215176960|Invalid HTTP_HOST header: ''. The domain name provided is not valid according to RFC 1034/1035.
ERROR|24/Feb/2021 00:56:51|exception|13079|140144215176960|Invalid HTTP_HOST header: ''. The domain name provided is not valid according to RFC 1034/1035.
ERROR|24/Feb/2021 04:03:23|exception|13079|140144245860096|Invalid HTTP_HOST header: ''. The domain name provided is not valid according to RFC 1034/1035.
ERROR|24/Feb/2021 04:53:38|exception|13079|140144245860096|Invalid HTTP_HOST header: ''. The domain name provided is not valid according to RFC 1034/1035.
ERROR|24/Feb/2021 06:32:13|exception|13079|140144245860096|Invalid HTTP_HOST header: ''. The domain name provided is not valid according to RFC 1034/1035.
ERROR|24/Feb/2021 06:35:08|exception|13079|140144245860096|Invalid HTTP_HOST header: ''. The domain name provided is not valid according to RFC 1034/1035.
ERROR|24/Feb/2021 06:44:47|exception|13079|140144245860096|Invalid HTTP_HOST header: ''. The domain name provided is not valid according to RFC 1034/1035.
ERROR|24/Feb/2021 08:08:38|exception|13079|140144245860096|Invalid HTTP_HOST header: ''. The domain name provided is not valid according to RFC 1034/1035.
ERROR|24/Feb/2021 08:58:25|exception|13079|140144215176960|Invalid HTTP_HOST header: ''. The domain name provided is not valid according to RFC 1034/1035.
ERROR|24/Feb/2021 09:16:44|exception|13079|140144215176960|Invalid HTTP_HOST header: ''. The domain name provided is not valid according to RFC 1034/1035.
ERROR|24/Feb/2021 10:47:03|exception|13079|140144193410816|Invalid HTTP_HOST header: ''. The domain name provided is not valid according to RFC 1034/1035.
ERROR|24/Feb/2021 10:55:21|log|13079|140143826556672|Internal Server Error: /get_travel_status_summary/
Traceback (most recent call last):
  File "/home/mobilitysqr/.local/lib/python3.6/site-packages/django/core/handlers/exception.py", line 34, in inner
    response = get_response(request)
  File "/home/mobilitysqr/.local/lib/python3.6/site-packages/django/core/handlers/base.py", line 126, in _get_response
    response = self.process_exception_by_middleware(e, request)
  File "/home/mobilitysqr/.local/lib/python3.6/site-packages/django/core/handlers/base.py", line 124, in _get_response
    response = wrapped_callback(request, *callback_args, **callback_kwargs)
  File "/home/mobilitysqr/.local/lib/python3.6/site-packages/django/views/decorators/csrf.py", line 54, in wrapped_view
    return view_func(*args, **kwargs)
  File "/home/mobilitysqr/.local/lib/python3.6/site-packages/django/views/generic/base.py", line 68, in view
    return self.dispatch(request, *args, **kwargs)
  File "/home/mobilitysqr/.local/lib/python3.6/site-packages/rest_framework/views.py", line 495, in dispatch
    response = self.handle_exception(exc)
  File "/home/mobilitysqr/.local/lib/python3.6/site-packages/rest_framework/views.py", line 455, in handle_exception
    self.raise_uncaught_exception(exc)
  File "/home/mobilitysqr/.local/lib/python3.6/site-packages/rest_framework/views.py", line 492, in dispatch
    response = handler(request, *args, **kwargs)
  File "/var/www/html/mobilitysqr_staging/mobility_apps/travel/views.py", line 960, in get
    travelserializersssts=Travel_Request_Action_History.objects.filter(travel_req_id_id=request.GET['travel_req_id'],email_id=travelserializerss[0]['supervisor'],approval_level="0").values(
  File "/home/mobilitysqr/.local/lib/python3.6/site-packages/django/db/models/query.py", line 303, in __getitem__
    return qs._result_cache[0]
IndexError: list index out of range
ERROR|24/Feb/2021 10:55:21|basehttp|13079|140143826556672|"GET /get_travel_status_summary/?travel_req_id=TR322248&org_id=ORG150866 HTTP/1.1" 500 17714
ERROR|24/Feb/2021 12:08:58|exception|13079|140143826556672|Invalid HTTP_HOST header: ''. The domain name provided is not valid according to RFC 1034/1035.
ERROR|24/Feb/2021 12:14:10|exception|13079|140143818163968|Invalid HTTP_HOST header: ''. The domain name provided is not valid according to RFC 1034/1035.
ERROR|24/Feb/2021 13:01:38|exception|13079|140144193410816|Invalid HTTP_HOST header: ''. The domain name provided is not valid according to RFC 1034/1035.
ERROR|24/Feb/2021 13:52:34|exception|13079|140143818163968|Invalid HTTP_HOST header: ''. The domain name provided is not valid according to RFC 1034/1035.
ERROR|24/Feb/2021 14:51:00|exception|13079|140144201803520|Invalid HTTP_HOST header: ''. The domain name provided is not valid according to RFC 1034/1035.
ERROR|24/Feb/2021 15:24:17|exception|13079|140143818163968|Invalid HTTP_HOST header: ''. The domain name provided is not valid according to RFC 1034/1035.
ERROR|24/Feb/2021 16:17:17|exception|13079|140144201803520|Invalid HTTP_HOST header: ''. The domain name provided is not valid according to RFC 1034/1035.
ERROR|24/Feb/2021 16:32:26|exception|13079|140144201803520|Invalid HTTP_HOST header: ''. The domain name provided is not valid according to RFC 1034/1035.
ERROR|24/Feb/2021 17:04:40|exception|13079|140144201803520|Invalid HTTP_HOST header: ''. The domain name provided is not valid according to RFC 1034/1035.
ERROR|24/Feb/2021 18:03:48|exception|13079|140144201803520|Invalid HTTP_HOST header: ''. The domain name provided is not valid according to RFC 1034/1035.
ERROR|24/Feb/2021 20:20:15|exception|13079|140143818163968|Invalid HTTP_HOST header: ''. The domain name provided is not valid according to RFC 1034/1035.
ERROR|24/Feb/2021 22:07:27|exception|13079|140143818163968|Invalid HTTP_HOST header: ''. The domain name provided is not valid according to RFC 1034/1035.
ERROR|24/Feb/2021 22:40:04|exception|13079|140143818163968|Invalid HTTP_HOST header: ''. The domain name provided is not valid according to RFC 1034/1035.
ERROR|25/Feb/2021 00:30:16|exception|13079|140143818163968|Invalid HTTP_HOST header: ''. The domain name provided is not valid according to RFC 1034/1035.
ERROR|25/Feb/2021 00:39:52|exception|13079|140143818163968|Invalid HTTP_HOST header: ''. The domain name provided is not valid according to RFC 1034/1035.
ERROR|25/Feb/2021 01:14:40|exception|13079|140143818163968|Invalid HTTP_HOST header: ''. The domain name provided is not valid according to RFC 1034/1035.
ERROR|25/Feb/2021 01:14:40|basehttp|13079|140143818163968|You're accessing the development server over HTTPS, but it only supports HTTP.

ERROR|25/Feb/2021 01:15:48|exception|13079|140143818163968|Invalid HTTP_HOST header: ''. The domain name provided is not valid according to RFC 1034/1035.
ERROR|25/Feb/2021 02:04:10|exception|13079|140143818163968|Invalid HTTP_HOST header: ''. The domain name provided is not valid according to RFC 1034/1035.
ERROR|25/Feb/2021 02:09:15|exception|13079|140143818163968|Invalid HTTP_HOST header: ''. The domain name provided is not valid according to RFC 1034/1035.
ERROR|25/Feb/2021 02:45:53|exception|13079|140143818163968|Invalid HTTP_HOST header: ''. The domain name provided is not valid according to RFC 1034/1035.
ERROR|25/Feb/2021 02:48:16|exception|13079|140143818163968|Invalid HTTP_HOST header: ''. The domain name provided is not valid according to RFC 1034/1035.
ERROR|25/Feb/2021 02:48:59|exception|13079|140143818163968|Invalid HTTP_HOST header: ''. The domain name provided is not valid according to RFC 1034/1035.
ERROR|25/Feb/2021 03:14:14|exception|13079|140143818163968|Invalid HTTP_HOST header: ''. The domain name provided is not valid according to RFC 1034/1035.
ERROR|25/Feb/2021 04:09:35|exception|13079|140144201803520|Invalid HTTP_HOST header: ''. The domain name provided is not valid according to RFC 1034/1035.
ERROR|25/Feb/2021 04:09:35|basehttp|13079|140144201803520|"GET /manager/html HTTP/1.1" 500 59
ERROR|25/Feb/2021 04:17:22|exception|13079|140144201803520|Invalid HTTP_HOST header: ''. The domain name provided is not valid according to RFC 1034/1035.
ERROR|25/Feb/2021 04:17:22|basehttp|13079|140144201803520|"GET /manager/html HTTP/1.1" 500 59
ERROR|25/Feb/2021 04:43:43|log|13079|140143818163968|Internal Server Error: /users
Traceback (most recent call last):
  File "/home/mobilitysqr/.local/lib/python3.6/site-packages/django/core/handlers/exception.py", line 34, in inner
    response = get_response(request)
  File "/home/mobilitysqr/.local/lib/python3.6/site-packages/django/utils/deprecation.py", line 90, in __call__
    response = self.process_request(request)
  File "/home/mobilitysqr/.local/lib/python3.6/site-packages/django/middleware/common.py", line 53, in process_request
    path = self.get_full_path_with_slash(request)
  File "/home/mobilitysqr/.local/lib/python3.6/site-packages/django/middleware/common.py", line 93, in get_full_path_with_slash
    'url': request.get_host() + new_path,
RuntimeError: You called this URL via POST, but the URL doesn't end in a slash and you have APPEND_SLASH set. Django can't redirect to the slash URL while maintaining POST data. Change your form to point to 52.165.220.40:8080/users/?page=&size=5 (note the trailing slash), or set APPEND_SLASH=False in your Django settings.
ERROR|25/Feb/2021 04:43:43|basehttp|13079|140143818163968|"POST /users?page=&size=5 HTTP/1.1" 500 65447
ERROR|25/Feb/2021 04:45:26|exception|13079|140144201803520|Invalid HTTP_HOST header: ''. The domain name provided is not valid according to RFC 1034/1035.
ERROR|25/Feb/2021 05:05:26|exception|13079|140144201803520|Invalid HTTP_HOST header: ''. The domain name provided is not valid according to RFC 1034/1035.
ERROR|25/Feb/2021 05:05:26|basehttp|13079|140144201803520|"GET /script HTTP/1.1" 500 59
ERROR|25/Feb/2021 05:11:25|exception|13079|140144201803520|Invalid HTTP_HOST header: ''. The domain name provided is not valid according to RFC 1034/1035.
ERROR|25/Feb/2021 05:54:52|exception|13079|140144201803520|Invalid HTTP_HOST header: ''. The domain name provided is not valid according to RFC 1034/1035.
ERROR|25/Feb/2021 05:54:52|basehttp|13079|140144201803520|"GET /manager/html HTTP/1.1" 500 59
ERROR|25/Feb/2021 06:05:29|exception|13079|140144201803520|Invalid HTTP_HOST header: ''. The domain name provided is not valid according to RFC 1034/1035.
ERROR|25/Feb/2021 07:29:47|exception|13079|140144201803520|Invalid HTTP_HOST header: ''. The domain name provided is not valid according to RFC 1034/1035.
ERROR|25/Feb/2021 08:31:56|exception|13079|140144201803520|Invalid HTTP_HOST header: ''. The domain name provided is not valid according to RFC 1034/1035.
ERROR|25/Feb/2021 08:47:44|exception|13079|140144201803520|Invalid HTTP_HOST header: ''. The domain name provided is not valid according to RFC 1034/1035.
ERROR|25/Feb/2021 09:10:10|exception|13079|140144201803520|Invalid HTTP_HOST header: ''. The domain name provided is not valid according to RFC 1034/1035.
ERROR|25/Feb/2021 09:12:55|exception|13079|140144201803520|Invalid HTTP_HOST header: ''. The domain name provided is not valid according to RFC 1034/1035.
ERROR|25/Feb/2021 10:53:15|exception|13079|140143818163968|Invalid HTTP_HOST header: ''. The domain name provided is not valid according to RFC 1034/1035.
ERROR|25/Feb/2021 11:01:27|exception|13079|140143834949376|Invalid HTTP_HOST header: ''. The domain name provided is not valid according to RFC 1034/1035.
ERROR|25/Feb/2021 11:03:28|log|13079|140144193410816|Internal Server Error: /get_add/travel_request/
Traceback (most recent call last):
  File "/home/mobilitysqr/.local/lib/python3.6/site-packages/django/db/backends/base/base.py", line 216, in ensure_connection
    self.connect()
  File "/home/mobilitysqr/.local/lib/python3.6/site-packages/django/db/backends/base/base.py", line 194, in connect
    self.connection = self.get_new_connection(conn_params)
  File "/home/mobilitysqr/.local/lib/python3.6/site-packages/sql_server/pyodbc/base.py", line 307, in get_new_connection
    timeout=timeout)
pyodbc.ProgrammingError: ('42000', '[42000] [Microsoft][ODBC Driver 17 for SQL Server][SQL Server]Cannot open database "mobilitysqrpreprod" requested by the login. The login failed. (4060) (SQLDriverConnect)')

The above exception was the direct cause of the following exception:

Traceback (most recent call last):
  File "/home/mobilitysqr/.local/lib/python3.6/site-packages/django/core/handlers/exception.py", line 34, in inner
    response = get_response(request)
  File "/home/mobilitysqr/.local/lib/python3.6/site-packages/django/core/handlers/base.py", line 126, in _get_response
    response = self.process_exception_by_middleware(e, request)
  File "/home/mobilitysqr/.local/lib/python3.6/site-packages/django/core/handlers/base.py", line 124, in _get_response
    response = wrapped_callback(request, *callback_args, **callback_kwargs)
  File "/home/mobilitysqr/.local/lib/python3.6/site-packages/django/views/decorators/csrf.py", line 54, in wrapped_view
    return view_func(*args, **kwargs)
  File "/home/mobilitysqr/.local/lib/python3.6/site-packages/django/views/generic/base.py", line 68, in view
    return self.dispatch(request, *args, **kwargs)
  File "/home/mobilitysqr/.local/lib/python3.6/site-packages/rest_framework/views.py", line 495, in dispatch
    response = self.handle_exception(exc)
  File "/home/mobilitysqr/.local/lib/python3.6/site-packages/rest_framework/views.py", line 455, in handle_exception
    self.raise_uncaught_exception(exc)
  File "/home/mobilitysqr/.local/lib/python3.6/site-packages/rest_framework/views.py", line 483, in dispatch
    self.initial(request, *args, **kwargs)
  File "/home/mobilitysqr/.local/lib/python3.6/site-packages/rest_framework/views.py", line 400, in initial
    self.perform_authentication(request)
  File "/home/mobilitysqr/.local/lib/python3.6/site-packages/rest_framework/views.py", line 326, in perform_authentication
    request.user
  File "/home/mobilitysqr/.local/lib/python3.6/site-packages/rest_framework/request.py", line 223, in user
    self._authenticate()
  File "/home/mobilitysqr/.local/lib/python3.6/site-packages/rest_framework/request.py", line 376, in _authenticate
    user_auth_tuple = authenticator.authenticate(self)
  File "/home/mobilitysqr/.local/lib/python3.6/site-packages/rest_framework_simplejwt/authentication.py", line 38, in authenticate
    return self.get_user(validated_token), None
  File "/home/mobilitysqr/.local/lib/python3.6/site-packages/rest_framework_simplejwt/authentication.py", line 111, in get_user
    user = User.objects.get(**{api_settings.USER_ID_FIELD: user_id})
  File "/home/mobilitysqr/.local/lib/python3.6/site-packages/django/db/models/manager.py", line 82, in manager_method
    return getattr(self.get_queryset(), name)(*args, **kwargs)
  File "/home/mobilitysqr/.local/lib/python3.6/site-packages/django/db/models/query.py", line 393, in get
    num = len(clone)
  File "/home/mobilitysqr/.local/lib/python3.6/site-packages/django/db/models/query.py", line 250, in __len__
    self._fetch_all()
  File "/home/mobilitysqr/.local/lib/python3.6/site-packages/django/db/models/query.py", line 1183, in _fetch_all
    self._result_cache = list(self._iterable_class(self))
  File "/home/mobilitysqr/.local/lib/python3.6/site-packages/django/db/models/query.py", line 54, in __iter__
    results = compiler.execute_sql(chunked_fetch=self.chunked_fetch, chunk_size=self.chunk_size)
  File "/home/mobilitysqr/.local/lib/python3.6/site-packages/django/db/models/sql/compiler.py", line 1059, in execute_sql
    cursor = self.connection.cursor()
  File "/home/mobilitysqr/.local/lib/python3.6/site-packages/django/db/backends/base/base.py", line 255, in cursor
    return self._cursor()
  File "/home/mobilitysqr/.local/lib/python3.6/site-packages/django/db/backends/base/base.py", line 232, in _cursor
    self.ensure_connection()
  File "/home/mobilitysqr/.local/lib/python3.6/site-packages/django/db/backends/base/base.py", line 216, in ensure_connection
    self.connect()
  File "/home/mobilitysqr/.local/lib/python3.6/site-packages/django/db/utils.py", line 89, in __exit__
    raise dj_exc_value.with_traceback(traceback) from exc_value
  File "/home/mobilitysqr/.local/lib/python3.6/site-packages/django/db/backends/base/base.py", line 216, in ensure_connection
    self.connect()
  File "/home/mobilitysqr/.local/lib/python3.6/site-packages/django/db/backends/base/base.py", line 194, in connect
    self.connection = self.get_new_connection(conn_params)
  File "/home/mobilitysqr/.local/lib/python3.6/site-packages/sql_server/pyodbc/base.py", line 307, in get_new_connection
    timeout=timeout)
django.db.utils.ProgrammingError: ('42000', '[42000] [Microsoft][ODBC Driver 17 for SQL Server][SQL Server]Cannot open database "mobilitysqrpreprod" requested by the login. The login failed. (4060) (SQLDriverConnect)')
ERROR|25/Feb/2021 11:03:28|log|13079|140143843342080|Internal Server Error: /get_action_status/
Traceback (most recent call last):
  File "/home/mobilitysqr/.local/lib/python3.6/site-packages/django/db/backends/base/base.py", line 216, in ensure_connection
    self.connect()
  File "/home/mobilitysqr/.local/lib/python3.6/site-packages/django/db/backends/base/base.py", line 194, in connect
    self.connection = self.get_new_connection(conn_params)
  File "/home/mobilitysqr/.local/lib/python3.6/site-packages/sql_server/pyodbc/base.py", line 307, in get_new_connection
    timeout=timeout)
pyodbc.ProgrammingError: ('42000', '[42000] [Microsoft][ODBC Driver 17 for SQL Server][SQL Server]Cannot open database "mobilitysqrpreprod" requested by the login. The login failed. (4060) (SQLDriverConnect)')

The above exception was the direct cause of the following exception:

Traceback (most recent call last):
  File "/home/mobilitysqr/.local/lib/python3.6/site-packages/django/core/handlers/exception.py", line 34, in inner
    response = get_response(request)
  File "/home/mobilitysqr/.local/lib/python3.6/site-packages/django/core/handlers/base.py", line 126, in _get_response
    response = self.process_exception_by_middleware(e, request)
  File "/home/mobilitysqr/.local/lib/python3.6/site-packages/django/core/handlers/base.py", line 124, in _get_response
    response = wrapped_callback(request, *callback_args, **callback_kwargs)
  File "/home/mobilitysqr/.local/lib/python3.6/site-packages/django/views/decorators/csrf.py", line 54, in wrapped_view
    return view_func(*args, **kwargs)
  File "/home/mobilitysqr/.local/lib/python3.6/site-packages/django/views/generic/base.py", line 68, in view
    return self.dispatch(request, *args, **kwargs)
  File "/home/mobilitysqr/.local/lib/python3.6/site-packages/rest_framework/views.py", line 495, in dispatch
    response = self.handle_exception(exc)
  File "/home/mobilitysqr/.local/lib/python3.6/site-packages/rest_framework/views.py", line 455, in handle_exception
    self.raise_uncaught_exception(exc)
  File "/home/mobilitysqr/.local/lib/python3.6/site-packages/rest_framework/views.py", line 483, in dispatch
    self.initial(request, *args, **kwargs)
  File "/home/mobilitysqr/.local/lib/python3.6/site-packages/rest_framework/views.py", line 400, in initial
    self.perform_authentication(request)
  File "/home/mobilitysqr/.local/lib/python3.6/site-packages/rest_framework/views.py", line 326, in perform_authentication
    request.user
  File "/home/mobilitysqr/.local/lib/python3.6/site-packages/rest_framework/request.py", line 223, in user
    self._authenticate()
  File "/home/mobilitysqr/.local/lib/python3.6/site-packages/rest_framework/request.py", line 376, in _authenticate
    user_auth_tuple = authenticator.authenticate(self)
  File "/home/mobilitysqr/.local/lib/python3.6/site-packages/rest_framework_simplejwt/authentication.py", line 38, in authenticate
    return self.get_user(validated_token), None
  File "/home/mobilitysqr/.local/lib/python3.6/site-packages/rest_framework_simplejwt/authentication.py", line 111, in get_user
    user = User.objects.get(**{api_settings.USER_ID_FIELD: user_id})
  File "/home/mobilitysqr/.local/lib/python3.6/site-packages/django/db/models/manager.py", line 82, in manager_method
    return getattr(self.get_queryset(), name)(*args, **kwargs)
  File "/home/mobilitysqr/.local/lib/python3.6/site-packages/django/db/models/query.py", line 393, in get
    num = len(clone)
  File "/home/mobilitysqr/.local/lib/python3.6/site-packages/django/db/models/query.py", line 250, in __len__
    self._fetch_all()
  File "/home/mobilitysqr/.local/lib/python3.6/site-packages/django/db/models/query.py", line 1183, in _fetch_all
    self._result_cache = list(self._iterable_class(self))
  File "/home/mobilitysqr/.local/lib/python3.6/site-packages/django/db/models/query.py", line 54, in __iter__
    results = compiler.execute_sql(chunked_fetch=self.chunked_fetch, chunk_size=self.chunk_size)
  File "/home/mobilitysqr/.local/lib/python3.6/site-packages/django/db/models/sql/compiler.py", line 1059, in execute_sql
    cursor = self.connection.cursor()
  File "/home/mobilitysqr/.local/lib/python3.6/site-packages/django/db/backends/base/base.py", line 255, in cursor
    return self._cursor()
  File "/home/mobilitysqr/.local/lib/python3.6/site-packages/django/db/backends/base/base.py", line 232, in _cursor
    self.ensure_connection()
  File "/home/mobilitysqr/.local/lib/python3.6/site-packages/django/db/backends/base/base.py", line 216, in ensure_connection
    self.connect()
  File "/home/mobilitysqr/.local/lib/python3.6/site-packages/django/db/utils.py", line 89, in __exit__
    raise dj_exc_value.with_traceback(traceback) from exc_value
  File "/home/mobilitysqr/.local/lib/python3.6/site-packages/django/db/backends/base/base.py", line 216, in ensure_connection
    self.connect()
  File "/home/mobilitysqr/.local/lib/python3.6/site-packages/django/db/backends/base/base.py", line 194, in connect
    self.connection = self.get_new_connection(conn_params)
  File "/home/mobilitysqr/.local/lib/python3.6/site-packages/sql_server/pyodbc/base.py", line 307, in get_new_connection
    timeout=timeout)
django.db.utils.ProgrammingError: ('42000', '[42000] [Microsoft][ODBC Driver 17 for SQL Server][SQL Server]Cannot open database "mobilitysqrpreprod" requested by the login. The login failed. (4060) (SQLDriverConnect)')
ERROR|25/Feb/2021 11:03:28|log|13079|140143818163968|Internal Server Error: /get_post_notification/
Traceback (most recent call last):
  File "/home/mobilitysqr/.local/lib/python3.6/site-packages/django/db/backends/base/base.py", line 216, in ensure_connection
    self.connect()
  File "/home/mobilitysqr/.local/lib/python3.6/site-packages/django/db/backends/base/base.py", line 194, in connect
    self.connection = self.get_new_connection(conn_params)
  File "/home/mobilitysqr/.local/lib/python3.6/site-packages/sql_server/pyodbc/base.py", line 307, in get_new_connection
    timeout=timeout)
pyodbc.ProgrammingError: ('42000', '[42000] [Microsoft][ODBC Driver 17 for SQL Server][SQL Server]Cannot open database "mobilitysqrpreprod" requested by the login. The login failed. (4060) (SQLDriverConnect)')

The above exception was the direct cause of the following exception:

Traceback (most recent call last):
  File "/home/mobilitysqr/.local/lib/python3.6/site-packages/django/core/handlers/exception.py", line 34, in inner
    response = get_response(request)
  File "/home/mobilitysqr/.local/lib/python3.6/site-packages/django/core/handlers/base.py", line 126, in _get_response
    response = self.process_exception_by_middleware(e, request)
  File "/home/mobilitysqr/.local/lib/python3.6/site-packages/django/core/handlers/base.py", line 124, in _get_response
    response = wrapped_callback(request, *callback_args, **callback_kwargs)
  File "/home/mobilitysqr/.local/lib/python3.6/site-packages/django/views/decorators/csrf.py", line 54, in wrapped_view
    return view_func(*args, **kwargs)
  File "/home/mobilitysqr/.local/lib/python3.6/site-packages/django/views/generic/base.py", line 68, in view
    return self.dispatch(request, *args, **kwargs)
  File "/home/mobilitysqr/.local/lib/python3.6/site-packages/rest_framework/views.py", line 495, in dispatch
    response = self.handle_exception(exc)
  File "/home/mobilitysqr/.local/lib/python3.6/site-packages/rest_framework/views.py", line 455, in handle_exception
    self.raise_uncaught_exception(exc)
  File "/home/mobilitysqr/.local/lib/python3.6/site-packages/rest_framework/views.py", line 483, in dispatch
    self.initial(request, *args, **kwargs)
  File "/home/mobilitysqr/.local/lib/python3.6/site-packages/rest_framework/views.py", line 400, in initial
    self.perform_authentication(request)
  File "/home/mobilitysqr/.local/lib/python3.6/site-packages/rest_framework/views.py", line 326, in perform_authentication
    request.user
  File "/home/mobilitysqr/.local/lib/python3.6/site-packages/rest_framework/request.py", line 223, in user
    self._authenticate()
  File "/home/mobilitysqr/.local/lib/python3.6/site-packages/rest_framework/request.py", line 376, in _authenticate
    user_auth_tuple = authenticator.authenticate(self)
  File "/home/mobilitysqr/.local/lib/python3.6/site-packages/rest_framework_simplejwt/authentication.py", line 38, in authenticate
    return self.get_user(validated_token), None
  File "/home/mobilitysqr/.local/lib/python3.6/site-packages/rest_framework_simplejwt/authentication.py", line 111, in get_user
    user = User.objects.get(**{api_settings.USER_ID_FIELD: user_id})
  File "/home/mobilitysqr/.local/lib/python3.6/site-packages/django/db/models/manager.py", line 82, in manager_method
    return getattr(self.get_queryset(), name)(*args, **kwargs)
  File "/home/mobilitysqr/.local/lib/python3.6/site-packages/django/db/models/query.py", line 393, in get
    num = len(clone)
  File "/home/mobilitysqr/.local/lib/python3.6/site-packages/django/db/models/query.py", line 250, in __len__
    self._fetch_all()
  File "/home/mobilitysqr/.local/lib/python3.6/site-packages/django/db/models/query.py", line 1183, in _fetch_all
    self._result_cache = list(self._iterable_class(self))
  File "/home/mobilitysqr/.local/lib/python3.6/site-packages/django/db/models/query.py", line 54, in __iter__
    results = compiler.execute_sql(chunked_fetch=self.chunked_fetch, chunk_size=self.chunk_size)
  File "/home/mobilitysqr/.local/lib/python3.6/site-packages/django/db/models/sql/compiler.py", line 1059, in execute_sql
    cursor = self.connection.cursor()
  File "/home/mobilitysqr/.local/lib/python3.6/site-packages/django/db/backends/base/base.py", line 255, in cursor
    return self._cursor()
  File "/home/mobilitysqr/.local/lib/python3.6/site-packages/django/db/backends/base/base.py", line 232, in _cursor
    self.ensure_connection()
  File "/home/mobilitysqr/.local/lib/python3.6/site-packages/django/db/backends/base/base.py", line 216, in ensure_connection
    self.connect()
  File "/home/mobilitysqr/.local/lib/python3.6/site-packages/django/db/utils.py", line 89, in __exit__
    raise dj_exc_value.with_traceback(traceback) from exc_value
  File "/home/mobilitysqr/.local/lib/python3.6/site-packages/django/db/backends/base/base.py", line 216, in ensure_connection
    self.connect()
  File "/home/mobilitysqr/.local/lib/python3.6/site-packages/django/db/backends/base/base.py", line 194, in connect
    self.connection = self.get_new_connection(conn_params)
  File "/home/mobilitysqr/.local/lib/python3.6/site-packages/sql_server/pyodbc/base.py", line 307, in get_new_connection
    timeout=timeout)
django.db.utils.ProgrammingError: ('42000', '[42000] [Microsoft][ODBC Driver 17 for SQL Server][SQL Server]Cannot open database "mobilitysqrpreprod" requested by the login. The login failed. (4060) (SQLDriverConnect)')
ERROR|25/Feb/2021 11:03:28|basehttp|13079|140144193410816|"GET /get_add/travel_request/?travel_req_status=2&org_id=ORG150866&emp_email=div944 HTTP/1.1" 500 21479
ERROR|25/Feb/2021 11:03:28|basehttp|13079|140143843342080|"GET /get_action_status/?module=T, HTTP/1.1" 500 21319
ERROR|25/Feb/2021 11:03:28|basehttp|13079|140143818163968|"GET /get_post_notification/?email=div944&org_id=ORG150866 HTTP/1.1" 500 21399
ERROR|25/Feb/2021 11:07:28|log|13079|140144193410816|Internal Server Error: /get_action_status/
Traceback (most recent call last):
  File "/home/mobilitysqr/.local/lib/python3.6/site-packages/django/db/backends/base/base.py", line 216, in ensure_connection
    self.connect()
  File "/home/mobilitysqr/.local/lib/python3.6/site-packages/django/db/backends/base/base.py", line 194, in connect
    self.connection = self.get_new_connection(conn_params)
  File "/home/mobilitysqr/.local/lib/python3.6/site-packages/sql_server/pyodbc/base.py", line 307, in get_new_connection
    timeout=timeout)
pyodbc.ProgrammingError: ('42000', '[42000] [Microsoft][ODBC Driver 17 for SQL Server][SQL Server]Cannot open database "mobilitysqrpreprod" requested by the login. The login failed. (4060) (SQLDriverConnect)')

The above exception was the direct cause of the following exception:

Traceback (most recent call last):
  File "/home/mobilitysqr/.local/lib/python3.6/site-packages/django/core/handlers/exception.py", line 34, in inner
    response = get_response(request)
  File "/home/mobilitysqr/.local/lib/python3.6/site-packages/django/core/handlers/base.py", line 126, in _get_response
    response = self.process_exception_by_middleware(e, request)
  File "/home/mobilitysqr/.local/lib/python3.6/site-packages/django/core/handlers/base.py", line 124, in _get_response
    response = wrapped_callback(request, *callback_args, **callback_kwargs)
  File "/home/mobilitysqr/.local/lib/python3.6/site-packages/django/views/decorators/csrf.py", line 54, in wrapped_view
    return view_func(*args, **kwargs)
  File "/home/mobilitysqr/.local/lib/python3.6/site-packages/django/views/generic/base.py", line 68, in view
    return self.dispatch(request, *args, **kwargs)
  File "/home/mobilitysqr/.local/lib/python3.6/site-packages/rest_framework/views.py", line 495, in dispatch
    response = self.handle_exception(exc)
  File "/home/mobilitysqr/.local/lib/python3.6/site-packages/rest_framework/views.py", line 455, in handle_exception
    self.raise_uncaught_exception(exc)
  File "/home/mobilitysqr/.local/lib/python3.6/site-packages/rest_framework/views.py", line 483, in dispatch
    self.initial(request, *args, **kwargs)
  File "/home/mobilitysqr/.local/lib/python3.6/site-packages/rest_framework/views.py", line 400, in initial
    self.perform_authentication(request)
  File "/home/mobilitysqr/.local/lib/python3.6/site-packages/rest_framework/views.py", line 326, in perform_authentication
    request.user
  File "/home/mobilitysqr/.local/lib/python3.6/site-packages/rest_framework/request.py", line 223, in user
    self._authenticate()
  File "/home/mobilitysqr/.local/lib/python3.6/site-packages/rest_framework/request.py", line 376, in _authenticate
    user_auth_tuple = authenticator.authenticate(self)
  File "/home/mobilitysqr/.local/lib/python3.6/site-packages/rest_framework_simplejwt/authentication.py", line 38, in authenticate
    return self.get_user(validated_token), None
  File "/home/mobilitysqr/.local/lib/python3.6/site-packages/rest_framework_simplejwt/authentication.py", line 111, in get_user
    user = User.objects.get(**{api_settings.USER_ID_FIELD: user_id})
  File "/home/mobilitysqr/.local/lib/python3.6/site-packages/django/db/models/manager.py", line 82, in manager_method
    return getattr(self.get_queryset(), name)(*args, **kwargs)
  File "/home/mobilitysqr/.local/lib/python3.6/site-packages/django/db/models/query.py", line 393, in get
    num = len(clone)
  File "/home/mobilitysqr/.local/lib/python3.6/site-packages/django/db/models/query.py", line 250, in __len__
    self._fetch_all()
  File "/home/mobilitysqr/.local/lib/python3.6/site-packages/django/db/models/query.py", line 1183, in _fetch_all
    self._result_cache = list(self._iterable_class(self))
  File "/home/mobilitysqr/.local/lib/python3.6/site-packages/django/db/models/query.py", line 54, in __iter__
    results = compiler.execute_sql(chunked_fetch=self.chunked_fetch, chunk_size=self.chunk_size)
  File "/home/mobilitysqr/.local/lib/python3.6/site-packages/django/db/models/sql/compiler.py", line 1059, in execute_sql
    cursor = self.connection.cursor()
  File "/home/mobilitysqr/.local/lib/python3.6/site-packages/django/db/backends/base/base.py", line 255, in cursor
    return self._cursor()
  File "/home/mobilitysqr/.local/lib/python3.6/site-packages/django/db/backends/base/base.py", line 232, in _cursor
    self.ensure_connection()
  File "/home/mobilitysqr/.local/lib/python3.6/site-packages/django/db/backends/base/base.py", line 216, in ensure_connection
    self.connect()
  File "/home/mobilitysqr/.local/lib/python3.6/site-packages/django/db/utils.py", line 89, in __exit__
    raise dj_exc_value.with_traceback(traceback) from exc_value
  File "/home/mobilitysqr/.local/lib/python3.6/site-packages/django/db/backends/base/base.py", line 216, in ensure_connection
    self.connect()
  File "/home/mobilitysqr/.local/lib/python3.6/site-packages/django/db/backends/base/base.py", line 194, in connect
    self.connection = self.get_new_connection(conn_params)
  File "/home/mobilitysqr/.local/lib/python3.6/site-packages/sql_server/pyodbc/base.py", line 307, in get_new_connection
    timeout=timeout)
django.db.utils.ProgrammingError: ('42000', '[42000] [Microsoft][ODBC Driver 17 for SQL Server][SQL Server]Cannot open database "mobilitysqrpreprod" requested by the login. The login failed. (4060) (SQLDriverConnect)')
ERROR|25/Feb/2021 11:07:28|log|13079|140143818163968|Internal Server Error: /get_post_notification/
Traceback (most recent call last):
  File "/home/mobilitysqr/.local/lib/python3.6/site-packages/django/db/backends/base/base.py", line 216, in ensure_connection
    self.connect()
  File "/home/mobilitysqr/.local/lib/python3.6/site-packages/django/db/backends/base/base.py", line 194, in connect
    self.connection = self.get_new_connection(conn_params)
  File "/home/mobilitysqr/.local/lib/python3.6/site-packages/sql_server/pyodbc/base.py", line 307, in get_new_connection
    timeout=timeout)
pyodbc.ProgrammingError: ('42000', '[42000] [Microsoft][ODBC Driver 17 for SQL Server][SQL Server]Cannot open database "mobilitysqrpreprod" requested by the login. The login failed. (4060) (SQLDriverConnect)')

The above exception was the direct cause of the following exception:

Traceback (most recent call last):
  File "/home/mobilitysqr/.local/lib/python3.6/site-packages/django/core/handlers/exception.py", line 34, in inner
    response = get_response(request)
  File "/home/mobilitysqr/.local/lib/python3.6/site-packages/django/core/handlers/base.py", line 126, in _get_response
    response = self.process_exception_by_middleware(e, request)
  File "/home/mobilitysqr/.local/lib/python3.6/site-packages/django/core/handlers/base.py", line 124, in _get_response
    response = wrapped_callback(request, *callback_args, **callback_kwargs)
  File "/home/mobilitysqr/.local/lib/python3.6/site-packages/django/views/decorators/csrf.py", line 54, in wrapped_view
    return view_func(*args, **kwargs)
  File "/home/mobilitysqr/.local/lib/python3.6/site-packages/django/views/generic/base.py", line 68, in view
    return self.dispatch(request, *args, **kwargs)
  File "/home/mobilitysqr/.local/lib/python3.6/site-packages/rest_framework/views.py", line 495, in dispatch
    response = self.handle_exception(exc)
  File "/home/mobilitysqr/.local/lib/python3.6/site-packages/rest_framework/views.py", line 455, in handle_exception
    self.raise_uncaught_exception(exc)
  File "/home/mobilitysqr/.local/lib/python3.6/site-packages/rest_framework/views.py", line 483, in dispatch
    self.initial(request, *args, **kwargs)
  File "/home/mobilitysqr/.local/lib/python3.6/site-packages/rest_framework/views.py", line 400, in initial
    self.perform_authentication(request)
  File "/home/mobilitysqr/.local/lib/python3.6/site-packages/rest_framework/views.py", line 326, in perform_authentication
    request.user
  File "/home/mobilitysqr/.local/lib/python3.6/site-packages/rest_framework/request.py", line 223, in user
    self._authenticate()
  File "/home/mobilitysqr/.local/lib/python3.6/site-packages/rest_framework/request.py", line 376, in _authenticate
    user_auth_tuple = authenticator.authenticate(self)
  File "/home/mobilitysqr/.local/lib/python3.6/site-packages/rest_framework_simplejwt/authentication.py", line 38, in authenticate
    return self.get_user(validated_token), None
  File "/home/mobilitysqr/.local/lib/python3.6/site-packages/rest_framework_simplejwt/authentication.py", line 111, in get_user
    user = User.objects.get(**{api_settings.USER_ID_FIELD: user_id})
  File "/home/mobilitysqr/.local/lib/python3.6/site-packages/django/db/models/manager.py", line 82, in manager_method
    return getattr(self.get_queryset(), name)(*args, **kwargs)
  File "/home/mobilitysqr/.local/lib/python3.6/site-packages/django/db/models/query.py", line 393, in get
    num = len(clone)
  File "/home/mobilitysqr/.local/lib/python3.6/site-packages/django/db/models/query.py", line 250, in __len__
    self._fetch_all()
  File "/home/mobilitysqr/.local/lib/python3.6/site-packages/django/db/models/query.py", line 1183, in _fetch_all
    self._result_cache = list(self._iterable_class(self))
  File "/home/mobilitysqr/.local/lib/python3.6/site-packages/django/db/models/query.py", line 54, in __iter__
    results = compiler.execute_sql(chunked_fetch=self.chunked_fetch, chunk_size=self.chunk_size)
  File "/home/mobilitysqr/.local/lib/python3.6/site-packages/django/db/models/sql/compiler.py", line 1059, in execute_sql
    cursor = self.connection.cursor()
  File "/home/mobilitysqr/.local/lib/python3.6/site-packages/django/db/backends/base/base.py", line 255, in cursor
    return self._cursor()
  File "/home/mobilitysqr/.local/lib/python3.6/site-packages/django/db/backends/base/base.py", line 232, in _cursor
    self.ensure_connection()
  File "/home/mobilitysqr/.local/lib/python3.6/site-packages/django/db/backends/base/base.py", line 216, in ensure_connection
    self.connect()
  File "/home/mobilitysqr/.local/lib/python3.6/site-packages/django/db/utils.py", line 89, in __exit__
    raise dj_exc_value.with_traceback(traceback) from exc_value
  File "/home/mobilitysqr/.local/lib/python3.6/site-packages/django/db/backends/base/base.py", line 216, in ensure_connection
    self.connect()
  File "/home/mobilitysqr/.local/lib/python3.6/site-packages/django/db/backends/base/base.py", line 194, in connect
    self.connection = self.get_new_connection(conn_params)
  File "/home/mobilitysqr/.local/lib/python3.6/site-packages/sql_server/pyodbc/base.py", line 307, in get_new_connection
    timeout=timeout)
django.db.utils.ProgrammingError: ('42000', '[42000] [Microsoft][ODBC Driver 17 for SQL Server][SQL Server]Cannot open database "mobilitysqrpreprod" requested by the login. The login failed. (4060) (SQLDriverConnect)')
ERROR|25/Feb/2021 11:07:28|log|13079|140143843342080|Internal Server Error: /get_add/travel_request/
Traceback (most recent call last):
  File "/home/mobilitysqr/.local/lib/python3.6/site-packages/django/db/backends/base/base.py", line 216, in ensure_connection
    self.connect()
  File "/home/mobilitysqr/.local/lib/python3.6/site-packages/django/db/backends/base/base.py", line 194, in connect
    self.connection = self.get_new_connection(conn_params)
  File "/home/mobilitysqr/.local/lib/python3.6/site-packages/sql_server/pyodbc/base.py", line 307, in get_new_connection
    timeout=timeout)
pyodbc.ProgrammingError: ('42000', '[42000] [Microsoft][ODBC Driver 17 for SQL Server][SQL Server]Cannot open database "mobilitysqrpreprod" requested by the login. The login failed. (4060) (SQLDriverConnect)')

The above exception was the direct cause of the following exception:

Traceback (most recent call last):
  File "/home/mobilitysqr/.local/lib/python3.6/site-packages/django/core/handlers/exception.py", line 34, in inner
    response = get_response(request)
  File "/home/mobilitysqr/.local/lib/python3.6/site-packages/django/core/handlers/base.py", line 126, in _get_response
    response = self.process_exception_by_middleware(e, request)
  File "/home/mobilitysqr/.local/lib/python3.6/site-packages/django/core/handlers/base.py", line 124, in _get_response
    response = wrapped_callback(request, *callback_args, **callback_kwargs)
  File "/home/mobilitysqr/.local/lib/python3.6/site-packages/django/views/decorators/csrf.py", line 54, in wrapped_view
    return view_func(*args, **kwargs)
  File "/home/mobilitysqr/.local/lib/python3.6/site-packages/django/views/generic/base.py", line 68, in view
    return self.dispatch(request, *args, **kwargs)
  File "/home/mobilitysqr/.local/lib/python3.6/site-packages/rest_framework/views.py", line 495, in dispatch
    response = self.handle_exception(exc)
  File "/home/mobilitysqr/.local/lib/python3.6/site-packages/rest_framework/views.py", line 455, in handle_exception
    self.raise_uncaught_exception(exc)
  File "/home/mobilitysqr/.local/lib/python3.6/site-packages/rest_framework/views.py", line 483, in dispatch
    self.initial(request, *args, **kwargs)
  File "/home/mobilitysqr/.local/lib/python3.6/site-packages/rest_framework/views.py", line 400, in initial
    self.perform_authentication(request)
  File "/home/mobilitysqr/.local/lib/python3.6/site-packages/rest_framework/views.py", line 326, in perform_authentication
    request.user
  File "/home/mobilitysqr/.local/lib/python3.6/site-packages/rest_framework/request.py", line 223, in user
    self._authenticate()
  File "/home/mobilitysqr/.local/lib/python3.6/site-packages/rest_framework/request.py", line 376, in _authenticate
    user_auth_tuple = authenticator.authenticate(self)
  File "/home/mobilitysqr/.local/lib/python3.6/site-packages/rest_framework_simplejwt/authentication.py", line 38, in authenticate
    return self.get_user(validated_token), None
  File "/home/mobilitysqr/.local/lib/python3.6/site-packages/rest_framework_simplejwt/authentication.py", line 111, in get_user
    user = User.objects.get(**{api_settings.USER_ID_FIELD: user_id})
  File "/home/mobilitysqr/.local/lib/python3.6/site-packages/django/db/models/manager.py", line 82, in manager_method
    return getattr(self.get_queryset(), name)(*args, **kwargs)
  File "/home/mobilitysqr/.local/lib/python3.6/site-packages/django/db/models/query.py", line 393, in get
    num = len(clone)
  File "/home/mobilitysqr/.local/lib/python3.6/site-packages/django/db/models/query.py", line 250, in __len__
    self._fetch_all()
  File "/home/mobilitysqr/.local/lib/python3.6/site-packages/django/db/models/query.py", line 1183, in _fetch_all
    self._result_cache = list(self._iterable_class(self))
  File "/home/mobilitysqr/.local/lib/python3.6/site-packages/django/db/models/query.py", line 54, in __iter__
    results = compiler.execute_sql(chunked_fetch=self.chunked_fetch, chunk_size=self.chunk_size)
  File "/home/mobilitysqr/.local/lib/python3.6/site-packages/django/db/models/sql/compiler.py", line 1059, in execute_sql
    cursor = self.connection.cursor()
  File "/home/mobilitysqr/.local/lib/python3.6/site-packages/django/db/backends/base/base.py", line 255, in cursor
    return self._cursor()
  File "/home/mobilitysqr/.local/lib/python3.6/site-packages/django/db/backends/base/base.py", line 232, in _cursor
    self.ensure_connection()
  File "/home/mobilitysqr/.local/lib/python3.6/site-packages/django/db/backends/base/base.py", line 216, in ensure_connection
    self.connect()
  File "/home/mobilitysqr/.local/lib/python3.6/site-packages/django/db/utils.py", line 89, in __exit__
    raise dj_exc_value.with_traceback(traceback) from exc_value
  File "/home/mobilitysqr/.local/lib/python3.6/site-packages/django/db/backends/base/base.py", line 216, in ensure_connection
    self.connect()
  File "/home/mobilitysqr/.local/lib/python3.6/site-packages/django/db/backends/base/base.py", line 194, in connect
    self.connection = self.get_new_connection(conn_params)
  File "/home/mobilitysqr/.local/lib/python3.6/site-packages/sql_server/pyodbc/base.py", line 307, in get_new_connection
    timeout=timeout)
django.db.utils.ProgrammingError: ('42000', '[42000] [Microsoft][ODBC Driver 17 for SQL Server][SQL Server]Cannot open database "mobilitysqrpreprod" requested by the login. The login failed. (4060) (SQLDriverConnect)')
ERROR|25/Feb/2021 11:07:28|basehttp|13079|140144193410816|"GET /get_action_status/?module=T, HTTP/1.1" 500 21319
ERROR|25/Feb/2021 11:07:28|basehttp|13079|140143818163968|"GET /get_post_notification/?email=div944&org_id=ORG150866 HTTP/1.1" 500 21399
ERROR|25/Feb/2021 11:07:28|basehttp|13079|140143843342080|"GET /get_add/travel_request/?travel_req_status=2&org_id=ORG150866&emp_email=div944 HTTP/1.1" 500 21479
ERROR|25/Feb/2021 11:08:16|log|13079|140143834949376|Internal Server Error: /get_post_notification/
Traceback (most recent call last):
  File "/home/mobilitysqr/.local/lib/python3.6/site-packages/django/db/backends/base/base.py", line 216, in ensure_connection
    self.connect()
  File "/home/mobilitysqr/.local/lib/python3.6/site-packages/django/db/backends/base/base.py", line 194, in connect
    self.connection = self.get_new_connection(conn_params)
  File "/home/mobilitysqr/.local/lib/python3.6/site-packages/sql_server/pyodbc/base.py", line 307, in get_new_connection
    timeout=timeout)
pyodbc.ProgrammingError: ('42000', '[42000] [Microsoft][ODBC Driver 17 for SQL Server][SQL Server]Cannot open database "mobilitysqrpreprod" requested by the login. The login failed. (4060) (SQLDriverConnect)')

The above exception was the direct cause of the following exception:

Traceback (most recent call last):
  File "/home/mobilitysqr/.local/lib/python3.6/site-packages/django/core/handlers/exception.py", line 34, in inner
    response = get_response(request)
  File "/home/mobilitysqr/.local/lib/python3.6/site-packages/django/core/handlers/base.py", line 126, in _get_response
    response = self.process_exception_by_middleware(e, request)
  File "/home/mobilitysqr/.local/lib/python3.6/site-packages/django/core/handlers/base.py", line 124, in _get_response
    response = wrapped_callback(request, *callback_args, **callback_kwargs)
  File "/home/mobilitysqr/.local/lib/python3.6/site-packages/django/views/decorators/csrf.py", line 54, in wrapped_view
    return view_func(*args, **kwargs)
  File "/home/mobilitysqr/.local/lib/python3.6/site-packages/django/views/generic/base.py", line 68, in view
    return self.dispatch(request, *args, **kwargs)
  File "/home/mobilitysqr/.local/lib/python3.6/site-packages/rest_framework/views.py", line 495, in dispatch
    response = self.handle_exception(exc)
  File "/home/mobilitysqr/.local/lib/python3.6/site-packages/rest_framework/views.py", line 455, in handle_exception
    self.raise_uncaught_exception(exc)
  File "/home/mobilitysqr/.local/lib/python3.6/site-packages/rest_framework/views.py", line 483, in dispatch
    self.initial(request, *args, **kwargs)
  File "/home/mobilitysqr/.local/lib/python3.6/site-packages/rest_framework/views.py", line 400, in initial
    self.perform_authentication(request)
  File "/home/mobilitysqr/.local/lib/python3.6/site-packages/rest_framework/views.py", line 326, in perform_authentication
    request.user
  File "/home/mobilitysqr/.local/lib/python3.6/site-packages/rest_framework/request.py", line 223, in user
    self._authenticate()
  File "/home/mobilitysqr/.local/lib/python3.6/site-packages/rest_framework/request.py", line 376, in _authenticate
    user_auth_tuple = authenticator.authenticate(self)
  File "/home/mobilitysqr/.local/lib/python3.6/site-packages/rest_framework_simplejwt/authentication.py", line 38, in authenticate
    return self.get_user(validated_token), None
  File "/home/mobilitysqr/.local/lib/python3.6/site-packages/rest_framework_simplejwt/authentication.py", line 111, in get_user
    user = User.objects.get(**{api_settings.USER_ID_FIELD: user_id})
  File "/home/mobilitysqr/.local/lib/python3.6/site-packages/django/db/models/manager.py", line 82, in manager_method
    return getattr(self.get_queryset(), name)(*args, **kwargs)
  File "/home/mobilitysqr/.local/lib/python3.6/site-packages/django/db/models/query.py", line 393, in get
    num = len(clone)
  File "/home/mobilitysqr/.local/lib/python3.6/site-packages/django/db/models/query.py", line 250, in __len__
    self._fetch_all()
  File "/home/mobilitysqr/.local/lib/python3.6/site-packages/django/db/models/query.py", line 1183, in _fetch_all
    self._result_cache = list(self._iterable_class(self))
  File "/home/mobilitysqr/.local/lib/python3.6/site-packages/django/db/models/query.py", line 54, in __iter__
    results = compiler.execute_sql(chunked_fetch=self.chunked_fetch, chunk_size=self.chunk_size)
  File "/home/mobilitysqr/.local/lib/python3.6/site-packages/django/db/models/sql/compiler.py", line 1059, in execute_sql
    cursor = self.connection.cursor()
  File "/home/mobilitysqr/.local/lib/python3.6/site-packages/django/db/backends/base/base.py", line 255, in cursor
    return self._cursor()
  File "/home/mobilitysqr/.local/lib/python3.6/site-packages/django/db/backends/base/base.py", line 232, in _cursor
    self.ensure_connection()
  File "/home/mobilitysqr/.local/lib/python3.6/site-packages/django/db/backends/base/base.py", line 216, in ensure_connection
    self.connect()
  File "/home/mobilitysqr/.local/lib/python3.6/site-packages/django/db/utils.py", line 89, in __exit__
    raise dj_exc_value.with_traceback(traceback) from exc_value
  File "/home/mobilitysqr/.local/lib/python3.6/site-packages/django/db/backends/base/base.py", line 216, in ensure_connection
    self.connect()
  File "/home/mobilitysqr/.local/lib/python3.6/site-packages/django/db/backends/base/base.py", line 194, in connect
    self.connection = self.get_new_connection(conn_params)
  File "/home/mobilitysqr/.local/lib/python3.6/site-packages/sql_server/pyodbc/base.py", line 307, in get_new_connection
    timeout=timeout)
django.db.utils.ProgrammingError: ('42000', '[42000] [Microsoft][ODBC Driver 17 for SQL Server][SQL Server]Cannot open database "mobilitysqrpreprod" requested by the login. The login failed. (4060) (SQLDriverConnect)')
ERROR|25/Feb/2021 11:08:16|basehttp|13079|140143834949376|"GET /get_post_notification/?email=div944&org_id=ORG150866 HTTP/1.1" 500 21399
ERROR|25/Feb/2021 11:08:16|log|13079|140143809771264|Internal Server Error: /get_action_status/
Traceback (most recent call last):
  File "/home/mobilitysqr/.local/lib/python3.6/site-packages/django/db/backends/base/base.py", line 216, in ensure_connection
    self.connect()
  File "/home/mobilitysqr/.local/lib/python3.6/site-packages/django/db/backends/base/base.py", line 194, in connect
    self.connection = self.get_new_connection(conn_params)
  File "/home/mobilitysqr/.local/lib/python3.6/site-packages/sql_server/pyodbc/base.py", line 307, in get_new_connection
    timeout=timeout)
pyodbc.ProgrammingError: ('42000', '[42000] [Microsoft][ODBC Driver 17 for SQL Server][SQL Server]Cannot open database "mobilitysqrpreprod" requested by the login. The login failed. (4060) (SQLDriverConnect)')

The above exception was the direct cause of the following exception:

Traceback (most recent call last):
  File "/home/mobilitysqr/.local/lib/python3.6/site-packages/django/core/handlers/exception.py", line 34, in inner
    response = get_response(request)
  File "/home/mobilitysqr/.local/lib/python3.6/site-packages/django/core/handlers/base.py", line 126, in _get_response
    response = self.process_exception_by_middleware(e, request)
  File "/home/mobilitysqr/.local/lib/python3.6/site-packages/django/core/handlers/base.py", line 124, in _get_response
    response = wrapped_callback(request, *callback_args, **callback_kwargs)
  File "/home/mobilitysqr/.local/lib/python3.6/site-packages/django/views/decorators/csrf.py", line 54, in wrapped_view
    return view_func(*args, **kwargs)
  File "/home/mobilitysqr/.local/lib/python3.6/site-packages/django/views/generic/base.py", line 68, in view
    return self.dispatch(request, *args, **kwargs)
  File "/home/mobilitysqr/.local/lib/python3.6/site-packages/rest_framework/views.py", line 495, in dispatch
    response = self.handle_exception(exc)
  File "/home/mobilitysqr/.local/lib/python3.6/site-packages/rest_framework/views.py", line 455, in handle_exception
    self.raise_uncaught_exception(exc)
  File "/home/mobilitysqr/.local/lib/python3.6/site-packages/rest_framework/views.py", line 483, in dispatch
    self.initial(request, *args, **kwargs)
  File "/home/mobilitysqr/.local/lib/python3.6/site-packages/rest_framework/views.py", line 400, in initial
    self.perform_authentication(request)
  File "/home/mobilitysqr/.local/lib/python3.6/site-packages/rest_framework/views.py", line 326, in perform_authentication
    request.user
  File "/home/mobilitysqr/.local/lib/python3.6/site-packages/rest_framework/request.py", line 223, in user
    self._authenticate()
  File "/home/mobilitysqr/.local/lib/python3.6/site-packages/rest_framework/request.py", line 376, in _authenticate
    user_auth_tuple = authenticator.authenticate(self)
  File "/home/mobilitysqr/.local/lib/python3.6/site-packages/rest_framework_simplejwt/authentication.py", line 38, in authenticate
    return self.get_user(validated_token), None
  File "/home/mobilitysqr/.local/lib/python3.6/site-packages/rest_framework_simplejwt/authentication.py", line 111, in get_user
    user = User.objects.get(**{api_settings.USER_ID_FIELD: user_id})
  File "/home/mobilitysqr/.local/lib/python3.6/site-packages/django/db/models/manager.py", line 82, in manager_method
    return getattr(self.get_queryset(), name)(*args, **kwargs)
  File "/home/mobilitysqr/.local/lib/python3.6/site-packages/django/db/models/query.py", line 393, in get
    num = len(clone)
  File "/home/mobilitysqr/.local/lib/python3.6/site-packages/django/db/models/query.py", line 250, in __len__
    self._fetch_all()
  File "/home/mobilitysqr/.local/lib/python3.6/site-packages/django/db/models/query.py", line 1183, in _fetch_all
    self._result_cache = list(self._iterable_class(self))
  File "/home/mobilitysqr/.local/lib/python3.6/site-packages/django/db/models/query.py", line 54, in __iter__
    results = compiler.execute_sql(chunked_fetch=self.chunked_fetch, chunk_size=self.chunk_size)
  File "/home/mobilitysqr/.local/lib/python3.6/site-packages/django/db/models/sql/compiler.py", line 1059, in execute_sql
    cursor = self.connection.cursor()
  File "/home/mobilitysqr/.local/lib/python3.6/site-packages/django/db/backends/base/base.py", line 255, in cursor
    return self._cursor()
  File "/home/mobilitysqr/.local/lib/python3.6/site-packages/django/db/backends/base/base.py", line 232, in _cursor
    self.ensure_connection()
  File "/home/mobilitysqr/.local/lib/python3.6/site-packages/django/db/backends/base/base.py", line 216, in ensure_connection
    self.connect()
  File "/home/mobilitysqr/.local/lib/python3.6/site-packages/django/db/utils.py", line 89, in __exit__
    raise dj_exc_value.with_traceback(traceback) from exc_value
  File "/home/mobilitysqr/.local/lib/python3.6/site-packages/django/db/backends/base/base.py", line 216, in ensure_connection
    self.connect()
  File "/home/mobilitysqr/.local/lib/python3.6/site-packages/django/db/backends/base/base.py", line 194, in connect
    self.connection = self.get_new_connection(conn_params)
  File "/home/mobilitysqr/.local/lib/python3.6/site-packages/sql_server/pyodbc/base.py", line 307, in get_new_connection
    timeout=timeout)
django.db.utils.ProgrammingError: ('42000', '[42000] [Microsoft][ODBC Driver 17 for SQL Server][SQL Server]Cannot open database "mobilitysqrpreprod" requested by the login. The login failed. (4060) (SQLDriverConnect)')
ERROR|25/Feb/2021 11:08:16|log|13079|140143826556672|Internal Server Error: /get_add/travel_request/
Traceback (most recent call last):
  File "/home/mobilitysqr/.local/lib/python3.6/site-packages/django/db/backends/base/base.py", line 216, in ensure_connection
    self.connect()
  File "/home/mobilitysqr/.local/lib/python3.6/site-packages/django/db/backends/base/base.py", line 194, in connect
    self.connection = self.get_new_connection(conn_params)
  File "/home/mobilitysqr/.local/lib/python3.6/site-packages/sql_server/pyodbc/base.py", line 307, in get_new_connection
    timeout=timeout)
pyodbc.ProgrammingError: ('42000', '[42000] [Microsoft][ODBC Driver 17 for SQL Server][SQL Server]Cannot open database "mobilitysqrpreprod" requested by the login. The login failed. (4060) (SQLDriverConnect)')

The above exception was the direct cause of the following exception:

Traceback (most recent call last):
  File "/home/mobilitysqr/.local/lib/python3.6/site-packages/django/core/handlers/exception.py", line 34, in inner
    response = get_response(request)
  File "/home/mobilitysqr/.local/lib/python3.6/site-packages/django/core/handlers/base.py", line 126, in _get_response
    response = self.process_exception_by_middleware(e, request)
  File "/home/mobilitysqr/.local/lib/python3.6/site-packages/django/core/handlers/base.py", line 124, in _get_response
    response = wrapped_callback(request, *callback_args, **callback_kwargs)
  File "/home/mobilitysqr/.local/lib/python3.6/site-packages/django/views/decorators/csrf.py", line 54, in wrapped_view
    return view_func(*args, **kwargs)
  File "/home/mobilitysqr/.local/lib/python3.6/site-packages/django/views/generic/base.py", line 68, in view
    return self.dispatch(request, *args, **kwargs)
  File "/home/mobilitysqr/.local/lib/python3.6/site-packages/rest_framework/views.py", line 495, in dispatch
    response = self.handle_exception(exc)
  File "/home/mobilitysqr/.local/lib/python3.6/site-packages/rest_framework/views.py", line 455, in handle_exception
    self.raise_uncaught_exception(exc)
  File "/home/mobilitysqr/.local/lib/python3.6/site-packages/rest_framework/views.py", line 483, in dispatch
    self.initial(request, *args, **kwargs)
  File "/home/mobilitysqr/.local/lib/python3.6/site-packages/rest_framework/views.py", line 400, in initial
    self.perform_authentication(request)
  File "/home/mobilitysqr/.local/lib/python3.6/site-packages/rest_framework/views.py", line 326, in perform_authentication
    request.user
  File "/home/mobilitysqr/.local/lib/python3.6/site-packages/rest_framework/request.py", line 223, in user
    self._authenticate()
  File "/home/mobilitysqr/.local/lib/python3.6/site-packages/rest_framework/request.py", line 376, in _authenticate
    user_auth_tuple = authenticator.authenticate(self)
  File "/home/mobilitysqr/.local/lib/python3.6/site-packages/rest_framework_simplejwt/authentication.py", line 38, in authenticate
    return self.get_user(validated_token), None
  File "/home/mobilitysqr/.local/lib/python3.6/site-packages/rest_framework_simplejwt/authentication.py", line 111, in get_user
    user = User.objects.get(**{api_settings.USER_ID_FIELD: user_id})
  File "/home/mobilitysqr/.local/lib/python3.6/site-packages/django/db/models/manager.py", line 82, in manager_method
    return getattr(self.get_queryset(), name)(*args, **kwargs)
  File "/home/mobilitysqr/.local/lib/python3.6/site-packages/django/db/models/query.py", line 393, in get
    num = len(clone)
  File "/home/mobilitysqr/.local/lib/python3.6/site-packages/django/db/models/query.py", line 250, in __len__
    self._fetch_all()
  File "/home/mobilitysqr/.local/lib/python3.6/site-packages/django/db/models/query.py", line 1183, in _fetch_all
    self._result_cache = list(self._iterable_class(self))
  File "/home/mobilitysqr/.local/lib/python3.6/site-packages/django/db/models/query.py", line 54, in __iter__
    results = compiler.execute_sql(chunked_fetch=self.chunked_fetch, chunk_size=self.chunk_size)
  File "/home/mobilitysqr/.local/lib/python3.6/site-packages/django/db/models/sql/compiler.py", line 1059, in execute_sql
    cursor = self.connection.cursor()
  File "/home/mobilitysqr/.local/lib/python3.6/site-packages/django/db/backends/base/base.py", line 255, in cursor
    return self._cursor()
  File "/home/mobilitysqr/.local/lib/python3.6/site-packages/django/db/backends/base/base.py", line 232, in _cursor
    self.ensure_connection()
  File "/home/mobilitysqr/.local/lib/python3.6/site-packages/django/db/backends/base/base.py", line 216, in ensure_connection
    self.connect()
  File "/home/mobilitysqr/.local/lib/python3.6/site-packages/django/db/utils.py", line 89, in __exit__
    raise dj_exc_value.with_traceback(traceback) from exc_value
  File "/home/mobilitysqr/.local/lib/python3.6/site-packages/django/db/backends/base/base.py", line 216, in ensure_connection
    self.connect()
  File "/home/mobilitysqr/.local/lib/python3.6/site-packages/django/db/backends/base/base.py", line 194, in connect
    self.connection = self.get_new_connection(conn_params)
  File "/home/mobilitysqr/.local/lib/python3.6/site-packages/sql_server/pyodbc/base.py", line 307, in get_new_connection
    timeout=timeout)
django.db.utils.ProgrammingError: ('42000', '[42000] [Microsoft][ODBC Driver 17 for SQL Server][SQL Server]Cannot open database "mobilitysqrpreprod" requested by the login. The login failed. (4060) (SQLDriverConnect)')
ERROR|25/Feb/2021 11:08:16|basehttp|13079|140143809771264|"GET /get_action_status/?module=T, HTTP/1.1" 500 21319
ERROR|25/Feb/2021 11:08:16|basehttp|13079|140143826556672|"GET /get_add/travel_request/?travel_req_status=2&org_id=ORG150866&emp_email=div944 HTTP/1.1" 500 21479
ERROR|25/Feb/2021 11:09:58|log|13079|140143801378560|Internal Server Error: /get_post_notification/
Traceback (most recent call last):
  File "/home/mobilitysqr/.local/lib/python3.6/site-packages/django/db/backends/base/base.py", line 216, in ensure_connection
    self.connect()
  File "/home/mobilitysqr/.local/lib/python3.6/site-packages/django/db/backends/base/base.py", line 194, in connect
    self.connection = self.get_new_connection(conn_params)
  File "/home/mobilitysqr/.local/lib/python3.6/site-packages/sql_server/pyodbc/base.py", line 307, in get_new_connection
    timeout=timeout)
pyodbc.ProgrammingError: ('42000', '[42000] [Microsoft][ODBC Driver 17 for SQL Server][SQL Server]Cannot open database "mobilitysqrpreprod" requested by the login. The login failed. (4060) (SQLDriverConnect)')

The above exception was the direct cause of the following exception:

Traceback (most recent call last):
  File "/home/mobilitysqr/.local/lib/python3.6/site-packages/django/core/handlers/exception.py", line 34, in inner
    response = get_response(request)
  File "/home/mobilitysqr/.local/lib/python3.6/site-packages/django/core/handlers/base.py", line 126, in _get_response
    response = self.process_exception_by_middleware(e, request)
  File "/home/mobilitysqr/.local/lib/python3.6/site-packages/django/core/handlers/base.py", line 124, in _get_response
    response = wrapped_callback(request, *callback_args, **callback_kwargs)
  File "/home/mobilitysqr/.local/lib/python3.6/site-packages/django/views/decorators/csrf.py", line 54, in wrapped_view
    return view_func(*args, **kwargs)
  File "/home/mobilitysqr/.local/lib/python3.6/site-packages/django/views/generic/base.py", line 68, in view
    return self.dispatch(request, *args, **kwargs)
  File "/home/mobilitysqr/.local/lib/python3.6/site-packages/rest_framework/views.py", line 495, in dispatch
    response = self.handle_exception(exc)
  File "/home/mobilitysqr/.local/lib/python3.6/site-packages/rest_framework/views.py", line 455, in handle_exception
    self.raise_uncaught_exception(exc)
  File "/home/mobilitysqr/.local/lib/python3.6/site-packages/rest_framework/views.py", line 483, in dispatch
    self.initial(request, *args, **kwargs)
  File "/home/mobilitysqr/.local/lib/python3.6/site-packages/rest_framework/views.py", line 400, in initial
    self.perform_authentication(request)
  File "/home/mobilitysqr/.local/lib/python3.6/site-packages/rest_framework/views.py", line 326, in perform_authentication
    request.user
  File "/home/mobilitysqr/.local/lib/python3.6/site-packages/rest_framework/request.py", line 223, in user
    self._authenticate()
  File "/home/mobilitysqr/.local/lib/python3.6/site-packages/rest_framework/request.py", line 376, in _authenticate
    user_auth_tuple = authenticator.authenticate(self)
  File "/home/mobilitysqr/.local/lib/python3.6/site-packages/rest_framework_simplejwt/authentication.py", line 38, in authenticate
    return self.get_user(validated_token), None
  File "/home/mobilitysqr/.local/lib/python3.6/site-packages/rest_framework_simplejwt/authentication.py", line 111, in get_user
    user = User.objects.get(**{api_settings.USER_ID_FIELD: user_id})
  File "/home/mobilitysqr/.local/lib/python3.6/site-packages/django/db/models/manager.py", line 82, in manager_method
    return getattr(self.get_queryset(), name)(*args, **kwargs)
  File "/home/mobilitysqr/.local/lib/python3.6/site-packages/django/db/models/query.py", line 393, in get
    num = len(clone)
  File "/home/mobilitysqr/.local/lib/python3.6/site-packages/django/db/models/query.py", line 250, in __len__
    self._fetch_all()
  File "/home/mobilitysqr/.local/lib/python3.6/site-packages/django/db/models/query.py", line 1183, in _fetch_all
    self._result_cache = list(self._iterable_class(self))
  File "/home/mobilitysqr/.local/lib/python3.6/site-packages/django/db/models/query.py", line 54, in __iter__
    results = compiler.execute_sql(chunked_fetch=self.chunked_fetch, chunk_size=self.chunk_size)
  File "/home/mobilitysqr/.local/lib/python3.6/site-packages/django/db/models/sql/compiler.py", line 1059, in execute_sql
    cursor = self.connection.cursor()
  File "/home/mobilitysqr/.local/lib/python3.6/site-packages/django/db/backends/base/base.py", line 255, in cursor
    return self._cursor()
  File "/home/mobilitysqr/.local/lib/python3.6/site-packages/django/db/backends/base/base.py", line 232, in _cursor
    self.ensure_connection()
  File "/home/mobilitysqr/.local/lib/python3.6/site-packages/django/db/backends/base/base.py", line 216, in ensure_connection
    self.connect()
  File "/home/mobilitysqr/.local/lib/python3.6/site-packages/django/db/utils.py", line 89, in __exit__
    raise dj_exc_value.with_traceback(traceback) from exc_value
  File "/home/mobilitysqr/.local/lib/python3.6/site-packages/django/db/backends/base/base.py", line 216, in ensure_connection
    self.connect()
  File "/home/mobilitysqr/.local/lib/python3.6/site-packages/django/db/backends/base/base.py", line 194, in connect
    self.connection = self.get_new_connection(conn_params)
  File "/home/mobilitysqr/.local/lib/python3.6/site-packages/sql_server/pyodbc/base.py", line 307, in get_new_connection
    timeout=timeout)
django.db.utils.ProgrammingError: ('42000', '[42000] [Microsoft][ODBC Driver 17 for SQL Server][SQL Server]Cannot open database "mobilitysqrpreprod" requested by the login. The login failed. (4060) (SQLDriverConnect)')
ERROR|25/Feb/2021 11:09:58|log|13079|140143373580032|Internal Server Error: /get_add/travel_request/
Traceback (most recent call last):
  File "/home/mobilitysqr/.local/lib/python3.6/site-packages/django/db/backends/base/base.py", line 216, in ensure_connection
    self.connect()
  File "/home/mobilitysqr/.local/lib/python3.6/site-packages/django/db/backends/base/base.py", line 194, in connect
    self.connection = self.get_new_connection(conn_params)
  File "/home/mobilitysqr/.local/lib/python3.6/site-packages/sql_server/pyodbc/base.py", line 307, in get_new_connection
    timeout=timeout)
pyodbc.ProgrammingError: ('42000', '[42000] [Microsoft][ODBC Driver 17 for SQL Server][SQL Server]Cannot open database "mobilitysqrpreprod" requested by the login. The login failed. (4060) (SQLDriverConnect)')

The above exception was the direct cause of the following exception:

Traceback (most recent call last):
  File "/home/mobilitysqr/.local/lib/python3.6/site-packages/django/core/handlers/exception.py", line 34, in inner
    response = get_response(request)
  File "/home/mobilitysqr/.local/lib/python3.6/site-packages/django/core/handlers/base.py", line 126, in _get_response
    response = self.process_exception_by_middleware(e, request)
  File "/home/mobilitysqr/.local/lib/python3.6/site-packages/django/core/handlers/base.py", line 124, in _get_response
    response = wrapped_callback(request, *callback_args, **callback_kwargs)
  File "/home/mobilitysqr/.local/lib/python3.6/site-packages/django/views/decorators/csrf.py", line 54, in wrapped_view
    return view_func(*args, **kwargs)
  File "/home/mobilitysqr/.local/lib/python3.6/site-packages/django/views/generic/base.py", line 68, in view
    return self.dispatch(request, *args, **kwargs)
  File "/home/mobilitysqr/.local/lib/python3.6/site-packages/rest_framework/views.py", line 495, in dispatch
    response = self.handle_exception(exc)
  File "/home/mobilitysqr/.local/lib/python3.6/site-packages/rest_framework/views.py", line 455, in handle_exception
    self.raise_uncaught_exception(exc)
  File "/home/mobilitysqr/.local/lib/python3.6/site-packages/rest_framework/views.py", line 483, in dispatch
    self.initial(request, *args, **kwargs)
  File "/home/mobilitysqr/.local/lib/python3.6/site-packages/rest_framework/views.py", line 400, in initial
    self.perform_authentication(request)
  File "/home/mobilitysqr/.local/lib/python3.6/site-packages/rest_framework/views.py", line 326, in perform_authentication
    request.user
  File "/home/mobilitysqr/.local/lib/python3.6/site-packages/rest_framework/request.py", line 223, in user
    self._authenticate()
  File "/home/mobilitysqr/.local/lib/python3.6/site-packages/rest_framework/request.py", line 376, in _authenticate
    user_auth_tuple = authenticator.authenticate(self)
  File "/home/mobilitysqr/.local/lib/python3.6/site-packages/rest_framework_simplejwt/authentication.py", line 38, in authenticate
    return self.get_user(validated_token), None
  File "/home/mobilitysqr/.local/lib/python3.6/site-packages/rest_framework_simplejwt/authentication.py", line 111, in get_user
    user = User.objects.get(**{api_settings.USER_ID_FIELD: user_id})
  File "/home/mobilitysqr/.local/lib/python3.6/site-packages/django/db/models/manager.py", line 82, in manager_method
    return getattr(self.get_queryset(), name)(*args, **kwargs)
  File "/home/mobilitysqr/.local/lib/python3.6/site-packages/django/db/models/query.py", line 393, in get
    num = len(clone)
  File "/home/mobilitysqr/.local/lib/python3.6/site-packages/django/db/models/query.py", line 250, in __len__
    self._fetch_all()
  File "/home/mobilitysqr/.local/lib/python3.6/site-packages/django/db/models/query.py", line 1183, in _fetch_all
    self._result_cache = list(self._iterable_class(self))
  File "/home/mobilitysqr/.local/lib/python3.6/site-packages/django/db/models/query.py", line 54, in __iter__
    results = compiler.execute_sql(chunked_fetch=self.chunked_fetch, chunk_size=self.chunk_size)
  File "/home/mobilitysqr/.local/lib/python3.6/site-packages/django/db/models/sql/compiler.py", line 1059, in execute_sql
    cursor = self.connection.cursor()
  File "/home/mobilitysqr/.local/lib/python3.6/site-packages/django/db/backends/base/base.py", line 255, in cursor
    return self._cursor()
  File "/home/mobilitysqr/.local/lib/python3.6/site-packages/django/db/backends/base/base.py", line 232, in _cursor
    self.ensure_connection()
  File "/home/mobilitysqr/.local/lib/python3.6/site-packages/django/db/backends/base/base.py", line 216, in ensure_connection
    self.connect()
  File "/home/mobilitysqr/.local/lib/python3.6/site-packages/django/db/utils.py", line 89, in __exit__
    raise dj_exc_value.with_traceback(traceback) from exc_value
  File "/home/mobilitysqr/.local/lib/python3.6/site-packages/django/db/backends/base/base.py", line 216, in ensure_connection
    self.connect()
  File "/home/mobilitysqr/.local/lib/python3.6/site-packages/django/db/backends/base/base.py", line 194, in connect
    self.connection = self.get_new_connection(conn_params)
  File "/home/mobilitysqr/.local/lib/python3.6/site-packages/sql_server/pyodbc/base.py", line 307, in get_new_connection
    timeout=timeout)
django.db.utils.ProgrammingError: ('42000', '[42000] [Microsoft][ODBC Driver 17 for SQL Server][SQL Server]Cannot open database "mobilitysqrpreprod" requested by the login. The login failed. (4060) (SQLDriverConnect)')
ERROR|25/Feb/2021 11:09:58|log|13079|140143792985856|Internal Server Error: /get_action_status/
Traceback (most recent call last):
  File "/home/mobilitysqr/.local/lib/python3.6/site-packages/django/db/backends/base/base.py", line 216, in ensure_connection
    self.connect()
  File "/home/mobilitysqr/.local/lib/python3.6/site-packages/django/db/backends/base/base.py", line 194, in connect
    self.connection = self.get_new_connection(conn_params)
  File "/home/mobilitysqr/.local/lib/python3.6/site-packages/sql_server/pyodbc/base.py", line 307, in get_new_connection
    timeout=timeout)
pyodbc.ProgrammingError: ('42000', '[42000] [Microsoft][ODBC Driver 17 for SQL Server][SQL Server]Cannot open database "mobilitysqrpreprod" requested by the login. The login failed. (4060) (SQLDriverConnect)')

The above exception was the direct cause of the following exception:

Traceback (most recent call last):
  File "/home/mobilitysqr/.local/lib/python3.6/site-packages/django/core/handlers/exception.py", line 34, in inner
    response = get_response(request)
  File "/home/mobilitysqr/.local/lib/python3.6/site-packages/django/core/handlers/base.py", line 126, in _get_response
    response = self.process_exception_by_middleware(e, request)
  File "/home/mobilitysqr/.local/lib/python3.6/site-packages/django/core/handlers/base.py", line 124, in _get_response
    response = wrapped_callback(request, *callback_args, **callback_kwargs)
  File "/home/mobilitysqr/.local/lib/python3.6/site-packages/django/views/decorators/csrf.py", line 54, in wrapped_view
    return view_func(*args, **kwargs)
  File "/home/mobilitysqr/.local/lib/python3.6/site-packages/django/views/generic/base.py", line 68, in view
    return self.dispatch(request, *args, **kwargs)
  File "/home/mobilitysqr/.local/lib/python3.6/site-packages/rest_framework/views.py", line 495, in dispatch
    response = self.handle_exception(exc)
  File "/home/mobilitysqr/.local/lib/python3.6/site-packages/rest_framework/views.py", line 455, in handle_exception
    self.raise_uncaught_exception(exc)
  File "/home/mobilitysqr/.local/lib/python3.6/site-packages/rest_framework/views.py", line 483, in dispatch
    self.initial(request, *args, **kwargs)
  File "/home/mobilitysqr/.local/lib/python3.6/site-packages/rest_framework/views.py", line 400, in initial
    self.perform_authentication(request)
  File "/home/mobilitysqr/.local/lib/python3.6/site-packages/rest_framework/views.py", line 326, in perform_authentication
    request.user
  File "/home/mobilitysqr/.local/lib/python3.6/site-packages/rest_framework/request.py", line 223, in user
    self._authenticate()
  File "/home/mobilitysqr/.local/lib/python3.6/site-packages/rest_framework/request.py", line 376, in _authenticate
    user_auth_tuple = authenticator.authenticate(self)
  File "/home/mobilitysqr/.local/lib/python3.6/site-packages/rest_framework_simplejwt/authentication.py", line 38, in authenticate
    return self.get_user(validated_token), None
  File "/home/mobilitysqr/.local/lib/python3.6/site-packages/rest_framework_simplejwt/authentication.py", line 111, in get_user
    user = User.objects.get(**{api_settings.USER_ID_FIELD: user_id})
  File "/home/mobilitysqr/.local/lib/python3.6/site-packages/django/db/models/manager.py", line 82, in manager_method
    return getattr(self.get_queryset(), name)(*args, **kwargs)
  File "/home/mobilitysqr/.local/lib/python3.6/site-packages/django/db/models/query.py", line 393, in get
    num = len(clone)
  File "/home/mobilitysqr/.local/lib/python3.6/site-packages/django/db/models/query.py", line 250, in __len__
    self._fetch_all()
  File "/home/mobilitysqr/.local/lib/python3.6/site-packages/django/db/models/query.py", line 1183, in _fetch_all
    self._result_cache = list(self._iterable_class(self))
  File "/home/mobilitysqr/.local/lib/python3.6/site-packages/django/db/models/query.py", line 54, in __iter__
    results = compiler.execute_sql(chunked_fetch=self.chunked_fetch, chunk_size=self.chunk_size)
  File "/home/mobilitysqr/.local/lib/python3.6/site-packages/django/db/models/sql/compiler.py", line 1059, in execute_sql
    cursor = self.connection.cursor()
  File "/home/mobilitysqr/.local/lib/python3.6/site-packages/django/db/backends/base/base.py", line 255, in cursor
    return self._cursor()
  File "/home/mobilitysqr/.local/lib/python3.6/site-packages/django/db/backends/base/base.py", line 232, in _cursor
    self.ensure_connection()
  File "/home/mobilitysqr/.local/lib/python3.6/site-packages/django/db/backends/base/base.py", line 216, in ensure_connection
    self.connect()
  File "/home/mobilitysqr/.local/lib/python3.6/site-packages/django/db/utils.py", line 89, in __exit__
    raise dj_exc_value.with_traceback(traceback) from exc_value
  File "/home/mobilitysqr/.local/lib/python3.6/site-packages/django/db/backends/base/base.py", line 216, in ensure_connection
    self.connect()
  File "/home/mobilitysqr/.local/lib/python3.6/site-packages/django/db/backends/base/base.py", line 194, in connect
    self.connection = self.get_new_connection(conn_params)
  File "/home/mobilitysqr/.local/lib/python3.6/site-packages/sql_server/pyodbc/base.py", line 307, in get_new_connection
    timeout=timeout)
django.db.utils.ProgrammingError: ('42000', '[42000] [Microsoft][ODBC Driver 17 for SQL Server][SQL Server]Cannot open database "mobilitysqrpreprod" requested by the login. The login failed. (4060) (SQLDriverConnect)')
ERROR|25/Feb/2021 11:09:58|basehttp|13079|140143801378560|"GET /get_post_notification/?email=div944&org_id=ORG150866 HTTP/1.1" 500 21399
ERROR|25/Feb/2021 11:09:58|basehttp|13079|140143373580032|"GET /get_add/travel_request/?travel_req_status=2&org_id=ORG150866&emp_email=div944 HTTP/1.1" 500 21479
ERROR|25/Feb/2021 11:09:58|basehttp|13079|140143792985856|"GET /get_action_status/?module=T, HTTP/1.1" 500 21319
ERROR|25/Feb/2021 11:10:41|log|13079|140143818163968|Internal Server Error: /api/login/
Traceback (most recent call last):
  File "/home/mobilitysqr/.local/lib/python3.6/site-packages/django/db/backends/base/base.py", line 216, in ensure_connection
    self.connect()
  File "/home/mobilitysqr/.local/lib/python3.6/site-packages/django/db/backends/base/base.py", line 194, in connect
    self.connection = self.get_new_connection(conn_params)
  File "/home/mobilitysqr/.local/lib/python3.6/site-packages/sql_server/pyodbc/base.py", line 307, in get_new_connection
    timeout=timeout)
pyodbc.ProgrammingError: ('42000', '[42000] [Microsoft][ODBC Driver 17 for SQL Server][SQL Server]Cannot open database "mobilitysqrpreprod" requested by the login. The login failed. (4060) (SQLDriverConnect)')

The above exception was the direct cause of the following exception:

Traceback (most recent call last):
  File "/home/mobilitysqr/.local/lib/python3.6/site-packages/django/core/handlers/exception.py", line 34, in inner
    response = get_response(request)
  File "/home/mobilitysqr/.local/lib/python3.6/site-packages/django/core/handlers/base.py", line 126, in _get_response
    response = self.process_exception_by_middleware(e, request)
  File "/home/mobilitysqr/.local/lib/python3.6/site-packages/django/core/handlers/base.py", line 124, in _get_response
    response = wrapped_callback(request, *callback_args, **callback_kwargs)
  File "/home/mobilitysqr/.local/lib/python3.6/site-packages/django/views/decorators/csrf.py", line 54, in wrapped_view
    return view_func(*args, **kwargs)
  File "/home/mobilitysqr/.local/lib/python3.6/site-packages/django/views/generic/base.py", line 68, in view
    return self.dispatch(request, *args, **kwargs)
  File "/home/mobilitysqr/.local/lib/python3.6/site-packages/rest_framework/views.py", line 495, in dispatch
    response = self.handle_exception(exc)
  File "/home/mobilitysqr/.local/lib/python3.6/site-packages/rest_framework/views.py", line 455, in handle_exception
    self.raise_uncaught_exception(exc)
  File "/home/mobilitysqr/.local/lib/python3.6/site-packages/rest_framework/views.py", line 492, in dispatch
    response = handler(request, *args, **kwargs)
  File "/home/mobilitysqr/.local/lib/python3.6/site-packages/rest_framework_simplejwt/views.py", line 27, in post
    serializer.is_valid(raise_exception=True)
  File "/home/mobilitysqr/.local/lib/python3.6/site-packages/rest_framework/serializers.py", line 236, in is_valid
    self._validated_data = self.run_validation(self.initial_data)
  File "/home/mobilitysqr/.local/lib/python3.6/site-packages/rest_framework/serializers.py", line 437, in run_validation
    value = self.validate(value)
  File "/home/mobilitysqr/.local/lib/python3.6/site-packages/rest_framework_simplejwt/serializers.py", line 71, in validate
    data = super().validate(attrs)
  File "/home/mobilitysqr/.local/lib/python3.6/site-packages/rest_framework_simplejwt/serializers.py", line 43, in validate
    self.user = authenticate(**authenticate_kwargs)
  File "/home/mobilitysqr/.local/lib/python3.6/site-packages/django/contrib/auth/__init__.py", line 73, in authenticate
    user = backend.authenticate(request, **credentials)
  File "/home/mobilitysqr/.local/lib/python3.6/site-packages/django/contrib/auth/backends.py", line 16, in authenticate
    user = UserModel._default_manager.get_by_natural_key(username)
  File "/home/mobilitysqr/.local/lib/python3.6/site-packages/django/contrib/auth/base_user.py", line 44, in get_by_natural_key
    return self.get(**{self.model.USERNAME_FIELD: username})
  File "/home/mobilitysqr/.local/lib/python3.6/site-packages/django/db/models/manager.py", line 82, in manager_method
    return getattr(self.get_queryset(), name)(*args, **kwargs)
  File "/home/mobilitysqr/.local/lib/python3.6/site-packages/django/db/models/query.py", line 393, in get
    num = len(clone)
  File "/home/mobilitysqr/.local/lib/python3.6/site-packages/django/db/models/query.py", line 250, in __len__
    self._fetch_all()
  File "/home/mobilitysqr/.local/lib/python3.6/site-packages/django/db/models/query.py", line 1183, in _fetch_all
    self._result_cache = list(self._iterable_class(self))
  File "/home/mobilitysqr/.local/lib/python3.6/site-packages/django/db/models/query.py", line 54, in __iter__
    results = compiler.execute_sql(chunked_fetch=self.chunked_fetch, chunk_size=self.chunk_size)
  File "/home/mobilitysqr/.local/lib/python3.6/site-packages/django/db/models/sql/compiler.py", line 1059, in execute_sql
    cursor = self.connection.cursor()
  File "/home/mobilitysqr/.local/lib/python3.6/site-packages/django/db/backends/base/base.py", line 255, in cursor
    return self._cursor()
  File "/home/mobilitysqr/.local/lib/python3.6/site-packages/django/db/backends/base/base.py", line 232, in _cursor
    self.ensure_connection()
  File "/home/mobilitysqr/.local/lib/python3.6/site-packages/django/db/backends/base/base.py", line 216, in ensure_connection
    self.connect()
  File "/home/mobilitysqr/.local/lib/python3.6/site-packages/django/db/utils.py", line 89, in __exit__
    raise dj_exc_value.with_traceback(traceback) from exc_value
  File "/home/mobilitysqr/.local/lib/python3.6/site-packages/django/db/backends/base/base.py", line 216, in ensure_connection
    self.connect()
  File "/home/mobilitysqr/.local/lib/python3.6/site-packages/django/db/backends/base/base.py", line 194, in connect
    self.connection = self.get_new_connection(conn_params)
  File "/home/mobilitysqr/.local/lib/python3.6/site-packages/sql_server/pyodbc/base.py", line 307, in get_new_connection
    timeout=timeout)
django.db.utils.ProgrammingError: ('42000', '[42000] [Microsoft][ODBC Driver 17 for SQL Server][SQL Server]Cannot open database "mobilitysqrpreprod" requested by the login. The login failed. (4060) (SQLDriverConnect)')
ERROR|25/Feb/2021 11:10:41|basehttp|13079|140143818163968|"POST /api/login/ HTTP/1.1" 500 21483
ERROR|25/Feb/2021 11:13:29|log|13079|140143818163968|Internal Server Error: /api/login/
Traceback (most recent call last):
  File "/home/mobilitysqr/.local/lib/python3.6/site-packages/django/db/backends/base/base.py", line 216, in ensure_connection
    self.connect()
  File "/home/mobilitysqr/.local/lib/python3.6/site-packages/django/db/backends/base/base.py", line 194, in connect
    self.connection = self.get_new_connection(conn_params)
  File "/home/mobilitysqr/.local/lib/python3.6/site-packages/sql_server/pyodbc/base.py", line 307, in get_new_connection
    timeout=timeout)
pyodbc.ProgrammingError: ('42000', '[42000] [Microsoft][ODBC Driver 17 for SQL Server][SQL Server]Cannot open database "mobilitysqrpreprod" requested by the login. The login failed. (4060) (SQLDriverConnect)')

The above exception was the direct cause of the following exception:

Traceback (most recent call last):
  File "/home/mobilitysqr/.local/lib/python3.6/site-packages/django/core/handlers/exception.py", line 34, in inner
    response = get_response(request)
  File "/home/mobilitysqr/.local/lib/python3.6/site-packages/django/core/handlers/base.py", line 126, in _get_response
    response = self.process_exception_by_middleware(e, request)
  File "/home/mobilitysqr/.local/lib/python3.6/site-packages/django/core/handlers/base.py", line 124, in _get_response
    response = wrapped_callback(request, *callback_args, **callback_kwargs)
  File "/home/mobilitysqr/.local/lib/python3.6/site-packages/django/views/decorators/csrf.py", line 54, in wrapped_view
    return view_func(*args, **kwargs)
  File "/home/mobilitysqr/.local/lib/python3.6/site-packages/django/views/generic/base.py", line 68, in view
    return self.dispatch(request, *args, **kwargs)
  File "/home/mobilitysqr/.local/lib/python3.6/site-packages/rest_framework/views.py", line 495, in dispatch
    response = self.handle_exception(exc)
  File "/home/mobilitysqr/.local/lib/python3.6/site-packages/rest_framework/views.py", line 455, in handle_exception
    self.raise_uncaught_exception(exc)
  File "/home/mobilitysqr/.local/lib/python3.6/site-packages/rest_framework/views.py", line 492, in dispatch
    response = handler(request, *args, **kwargs)
  File "/home/mobilitysqr/.local/lib/python3.6/site-packages/rest_framework_simplejwt/views.py", line 27, in post
    serializer.is_valid(raise_exception=True)
  File "/home/mobilitysqr/.local/lib/python3.6/site-packages/rest_framework/serializers.py", line 236, in is_valid
    self._validated_data = self.run_validation(self.initial_data)
  File "/home/mobilitysqr/.local/lib/python3.6/site-packages/rest_framework/serializers.py", line 437, in run_validation
    value = self.validate(value)
  File "/home/mobilitysqr/.local/lib/python3.6/site-packages/rest_framework_simplejwt/serializers.py", line 71, in validate
    data = super().validate(attrs)
  File "/home/mobilitysqr/.local/lib/python3.6/site-packages/rest_framework_simplejwt/serializers.py", line 43, in validate
    self.user = authenticate(**authenticate_kwargs)
  File "/home/mobilitysqr/.local/lib/python3.6/site-packages/django/contrib/auth/__init__.py", line 73, in authenticate
    user = backend.authenticate(request, **credentials)
  File "/home/mobilitysqr/.local/lib/python3.6/site-packages/django/contrib/auth/backends.py", line 16, in authenticate
    user = UserModel._default_manager.get_by_natural_key(username)
  File "/home/mobilitysqr/.local/lib/python3.6/site-packages/django/contrib/auth/base_user.py", line 44, in get_by_natural_key
    return self.get(**{self.model.USERNAME_FIELD: username})
  File "/home/mobilitysqr/.local/lib/python3.6/site-packages/django/db/models/manager.py", line 82, in manager_method
    return getattr(self.get_queryset(), name)(*args, **kwargs)
  File "/home/mobilitysqr/.local/lib/python3.6/site-packages/django/db/models/query.py", line 393, in get
    num = len(clone)
  File "/home/mobilitysqr/.local/lib/python3.6/site-packages/django/db/models/query.py", line 250, in __len__
    self._fetch_all()
  File "/home/mobilitysqr/.local/lib/python3.6/site-packages/django/db/models/query.py", line 1183, in _fetch_all
    self._result_cache = list(self._iterable_class(self))
  File "/home/mobilitysqr/.local/lib/python3.6/site-packages/django/db/models/query.py", line 54, in __iter__
    results = compiler.execute_sql(chunked_fetch=self.chunked_fetch, chunk_size=self.chunk_size)
  File "/home/mobilitysqr/.local/lib/python3.6/site-packages/django/db/models/sql/compiler.py", line 1059, in execute_sql
    cursor = self.connection.cursor()
  File "/home/mobilitysqr/.local/lib/python3.6/site-packages/django/db/backends/base/base.py", line 255, in cursor
    return self._cursor()
  File "/home/mobilitysqr/.local/lib/python3.6/site-packages/django/db/backends/base/base.py", line 232, in _cursor
    self.ensure_connection()
  File "/home/mobilitysqr/.local/lib/python3.6/site-packages/django/db/backends/base/base.py", line 216, in ensure_connection
    self.connect()
  File "/home/mobilitysqr/.local/lib/python3.6/site-packages/django/db/utils.py", line 89, in __exit__
    raise dj_exc_value.with_traceback(traceback) from exc_value
  File "/home/mobilitysqr/.local/lib/python3.6/site-packages/django/db/backends/base/base.py", line 216, in ensure_connection
    self.connect()
  File "/home/mobilitysqr/.local/lib/python3.6/site-packages/django/db/backends/base/base.py", line 194, in connect
    self.connection = self.get_new_connection(conn_params)
  File "/home/mobilitysqr/.local/lib/python3.6/site-packages/sql_server/pyodbc/base.py", line 307, in get_new_connection
    timeout=timeout)
django.db.utils.ProgrammingError: ('42000', '[42000] [Microsoft][ODBC Driver 17 for SQL Server][SQL Server]Cannot open database "mobilitysqrpreprod" requested by the login. The login failed. (4060) (SQLDriverConnect)')
ERROR|25/Feb/2021 11:13:29|basehttp|13079|140143818163968|"POST /api/login/ HTTP/1.1" 500 21483
ERROR|25/Feb/2021 11:15:47|log|13079|140143818163968|Internal Server Error: /api/login
Traceback (most recent call last):
  File "/home/mobilitysqr/.local/lib/python3.6/site-packages/django/core/handlers/exception.py", line 34, in inner
    response = get_response(request)
  File "/home/mobilitysqr/.local/lib/python3.6/site-packages/django/utils/deprecation.py", line 90, in __call__
    response = self.process_request(request)
  File "/home/mobilitysqr/.local/lib/python3.6/site-packages/django/middleware/common.py", line 53, in process_request
    path = self.get_full_path_with_slash(request)
  File "/home/mobilitysqr/.local/lib/python3.6/site-packages/django/middleware/common.py", line 93, in get_full_path_with_slash
    'url': request.get_host() + new_path,
RuntimeError: You called this URL via POST, but the URL doesn't end in a slash and you have APPEND_SLASH set. Django can't redirect to the slash URL while maintaining POST data. Change your form to point to 52.165.220.40:8080/api/login/ (note the trailing slash), or set APPEND_SLASH=False in your Django settings.
ERROR|25/Feb/2021 11:15:47|basehttp|13079|140143818163968|"POST /api/login HTTP/1.1" 500 64460
ERROR|25/Feb/2021 11:21:20|log|13079|140143843342080|Internal Server Error: /api/login
Traceback (most recent call last):
  File "/home/mobilitysqr/.local/lib/python3.6/site-packages/django/core/handlers/exception.py", line 34, in inner
    response = get_response(request)
  File "/home/mobilitysqr/.local/lib/python3.6/site-packages/django/utils/deprecation.py", line 90, in __call__
    response = self.process_request(request)
  File "/home/mobilitysqr/.local/lib/python3.6/site-packages/django/middleware/common.py", line 53, in process_request
    path = self.get_full_path_with_slash(request)
  File "/home/mobilitysqr/.local/lib/python3.6/site-packages/django/middleware/common.py", line 93, in get_full_path_with_slash
    'url': request.get_host() + new_path,
RuntimeError: You called this URL via POST, but the URL doesn't end in a slash and you have APPEND_SLASH set. Django can't redirect to the slash URL while maintaining POST data. Change your form to point to 52.165.220.40:8080/api/login/ (note the trailing slash), or set APPEND_SLASH=False in your Django settings.
ERROR|25/Feb/2021 11:21:20|basehttp|13079|140143843342080|"POST /api/login HTTP/1.1" 500 64460
ERROR|25/Feb/2021 11:23:55|log|13079|140143792985856|Internal Server Error: /api/login
Traceback (most recent call last):
  File "/home/mobilitysqr/.local/lib/python3.6/site-packages/django/core/handlers/exception.py", line 34, in inner
    response = get_response(request)
  File "/home/mobilitysqr/.local/lib/python3.6/site-packages/django/utils/deprecation.py", line 90, in __call__
    response = self.process_request(request)
  File "/home/mobilitysqr/.local/lib/python3.6/site-packages/django/middleware/common.py", line 53, in process_request
    path = self.get_full_path_with_slash(request)
  File "/home/mobilitysqr/.local/lib/python3.6/site-packages/django/middleware/common.py", line 93, in get_full_path_with_slash
    'url': request.get_host() + new_path,
RuntimeError: You called this URL via POST, but the URL doesn't end in a slash and you have APPEND_SLASH set. Django can't redirect to the slash URL while maintaining POST data. Change your form to point to 52.165.220.40:8080/api/login/ (note the trailing slash), or set APPEND_SLASH=False in your Django settings.
ERROR|25/Feb/2021 11:23:55|basehttp|13079|140143792985856|"POST /api/login HTTP/1.1" 500 64460
ERROR|25/Feb/2021 11:24:56|log|13079|140143792985856|Internal Server Error: /api/login
Traceback (most recent call last):
  File "/home/mobilitysqr/.local/lib/python3.6/site-packages/django/core/handlers/exception.py", line 34, in inner
    response = get_response(request)
  File "/home/mobilitysqr/.local/lib/python3.6/site-packages/django/utils/deprecation.py", line 90, in __call__
    response = self.process_request(request)
  File "/home/mobilitysqr/.local/lib/python3.6/site-packages/django/middleware/common.py", line 53, in process_request
    path = self.get_full_path_with_slash(request)
  File "/home/mobilitysqr/.local/lib/python3.6/site-packages/django/middleware/common.py", line 93, in get_full_path_with_slash
    'url': request.get_host() + new_path,
RuntimeError: You called this URL via POST, but the URL doesn't end in a slash and you have APPEND_SLASH set. Django can't redirect to the slash URL while maintaining POST data. Change your form to point to 52.165.220.40:8080/api/login/ (note the trailing slash), or set APPEND_SLASH=False in your Django settings.
ERROR|25/Feb/2021 11:24:56|basehttp|13079|140143792985856|"POST /api/login HTTP/1.1" 500 64460
ERROR|25/Feb/2021 11:26:20|log|13079|140143843342080|Internal Server Error: /api/login/
Traceback (most recent call last):
  File "/home/mobilitysqr/.local/lib/python3.6/site-packages/django/db/backends/base/base.py", line 216, in ensure_connection
    self.connect()
  File "/home/mobilitysqr/.local/lib/python3.6/site-packages/django/db/backends/base/base.py", line 194, in connect
    self.connection = self.get_new_connection(conn_params)
  File "/home/mobilitysqr/.local/lib/python3.6/site-packages/sql_server/pyodbc/base.py", line 307, in get_new_connection
    timeout=timeout)
pyodbc.ProgrammingError: ('42000', '[42000] [Microsoft][ODBC Driver 17 for SQL Server][SQL Server]Cannot open database "mobilitysqrpreprod" requested by the login. The login failed. (4060) (SQLDriverConnect)')

The above exception was the direct cause of the following exception:

Traceback (most recent call last):
  File "/home/mobilitysqr/.local/lib/python3.6/site-packages/django/core/handlers/exception.py", line 34, in inner
    response = get_response(request)
  File "/home/mobilitysqr/.local/lib/python3.6/site-packages/django/core/handlers/base.py", line 126, in _get_response
    response = self.process_exception_by_middleware(e, request)
  File "/home/mobilitysqr/.local/lib/python3.6/site-packages/django/core/handlers/base.py", line 124, in _get_response
    response = wrapped_callback(request, *callback_args, **callback_kwargs)
  File "/home/mobilitysqr/.local/lib/python3.6/site-packages/django/views/decorators/csrf.py", line 54, in wrapped_view
    return view_func(*args, **kwargs)
  File "/home/mobilitysqr/.local/lib/python3.6/site-packages/django/views/generic/base.py", line 68, in view
    return self.dispatch(request, *args, **kwargs)
  File "/home/mobilitysqr/.local/lib/python3.6/site-packages/rest_framework/views.py", line 495, in dispatch
    response = self.handle_exception(exc)
  File "/home/mobilitysqr/.local/lib/python3.6/site-packages/rest_framework/views.py", line 455, in handle_exception
    self.raise_uncaught_exception(exc)
  File "/home/mobilitysqr/.local/lib/python3.6/site-packages/rest_framework/views.py", line 492, in dispatch
    response = handler(request, *args, **kwargs)
  File "/home/mobilitysqr/.local/lib/python3.6/site-packages/rest_framework_simplejwt/views.py", line 27, in post
    serializer.is_valid(raise_exception=True)
  File "/home/mobilitysqr/.local/lib/python3.6/site-packages/rest_framework/serializers.py", line 236, in is_valid
    self._validated_data = self.run_validation(self.initial_data)
  File "/home/mobilitysqr/.local/lib/python3.6/site-packages/rest_framework/serializers.py", line 437, in run_validation
    value = self.validate(value)
  File "/home/mobilitysqr/.local/lib/python3.6/site-packages/rest_framework_simplejwt/serializers.py", line 71, in validate
    data = super().validate(attrs)
  File "/home/mobilitysqr/.local/lib/python3.6/site-packages/rest_framework_simplejwt/serializers.py", line 43, in validate
    self.user = authenticate(**authenticate_kwargs)
  File "/home/mobilitysqr/.local/lib/python3.6/site-packages/django/contrib/auth/__init__.py", line 73, in authenticate
    user = backend.authenticate(request, **credentials)
  File "/home/mobilitysqr/.local/lib/python3.6/site-packages/django/contrib/auth/backends.py", line 16, in authenticate
    user = UserModel._default_manager.get_by_natural_key(username)
  File "/home/mobilitysqr/.local/lib/python3.6/site-packages/django/contrib/auth/base_user.py", line 44, in get_by_natural_key
    return self.get(**{self.model.USERNAME_FIELD: username})
  File "/home/mobilitysqr/.local/lib/python3.6/site-packages/django/db/models/manager.py", line 82, in manager_method
    return getattr(self.get_queryset(), name)(*args, **kwargs)
  File "/home/mobilitysqr/.local/lib/python3.6/site-packages/django/db/models/query.py", line 393, in get
    num = len(clone)
  File "/home/mobilitysqr/.local/lib/python3.6/site-packages/django/db/models/query.py", line 250, in __len__
    self._fetch_all()
  File "/home/mobilitysqr/.local/lib/python3.6/site-packages/django/db/models/query.py", line 1183, in _fetch_all
    self._result_cache = list(self._iterable_class(self))
  File "/home/mobilitysqr/.local/lib/python3.6/site-packages/django/db/models/query.py", line 54, in __iter__
    results = compiler.execute_sql(chunked_fetch=self.chunked_fetch, chunk_size=self.chunk_size)
  File "/home/mobilitysqr/.local/lib/python3.6/site-packages/django/db/models/sql/compiler.py", line 1059, in execute_sql
    cursor = self.connection.cursor()
  File "/home/mobilitysqr/.local/lib/python3.6/site-packages/django/db/backends/base/base.py", line 255, in cursor
    return self._cursor()
  File "/home/mobilitysqr/.local/lib/python3.6/site-packages/django/db/backends/base/base.py", line 232, in _cursor
    self.ensure_connection()
  File "/home/mobilitysqr/.local/lib/python3.6/site-packages/django/db/backends/base/base.py", line 216, in ensure_connection
    self.connect()
  File "/home/mobilitysqr/.local/lib/python3.6/site-packages/django/db/utils.py", line 89, in __exit__
    raise dj_exc_value.with_traceback(traceback) from exc_value
  File "/home/mobilitysqr/.local/lib/python3.6/site-packages/django/db/backends/base/base.py", line 216, in ensure_connection
    self.connect()
  File "/home/mobilitysqr/.local/lib/python3.6/site-packages/django/db/backends/base/base.py", line 194, in connect
    self.connection = self.get_new_connection(conn_params)
  File "/home/mobilitysqr/.local/lib/python3.6/site-packages/sql_server/pyodbc/base.py", line 307, in get_new_connection
    timeout=timeout)
django.db.utils.ProgrammingError: ('42000', '[42000] [Microsoft][ODBC Driver 17 for SQL Server][SQL Server]Cannot open database "mobilitysqrpreprod" requested by the login. The login failed. (4060) (SQLDriverConnect)')
ERROR|25/Feb/2021 11:26:20|basehttp|13079|140143843342080|"POST /api/login/ HTTP/1.1" 500 21483
ERROR|25/Feb/2021 11:27:12|log|13079|140143843342080|Internal Server Error: /api/login
Traceback (most recent call last):
  File "/home/mobilitysqr/.local/lib/python3.6/site-packages/django/core/handlers/exception.py", line 34, in inner
    response = get_response(request)
  File "/home/mobilitysqr/.local/lib/python3.6/site-packages/django/utils/deprecation.py", line 90, in __call__
    response = self.process_request(request)
  File "/home/mobilitysqr/.local/lib/python3.6/site-packages/django/middleware/common.py", line 53, in process_request
    path = self.get_full_path_with_slash(request)
  File "/home/mobilitysqr/.local/lib/python3.6/site-packages/django/middleware/common.py", line 93, in get_full_path_with_slash
    'url': request.get_host() + new_path,
RuntimeError: You called this URL via POST, but the URL doesn't end in a slash and you have APPEND_SLASH set. Django can't redirect to the slash URL while maintaining POST data. Change your form to point to 52.165.220.40:8080/api/login/ (note the trailing slash), or set APPEND_SLASH=False in your Django settings.
ERROR|25/Feb/2021 11:27:12|basehttp|13079|140143843342080|"POST /api/login HTTP/1.1" 500 64460
ERROR|25/Feb/2021 11:27:22|log|13079|140143843342080|Internal Server Error: /api/login
Traceback (most recent call last):
  File "/home/mobilitysqr/.local/lib/python3.6/site-packages/django/core/handlers/exception.py", line 34, in inner
    response = get_response(request)
  File "/home/mobilitysqr/.local/lib/python3.6/site-packages/django/utils/deprecation.py", line 90, in __call__
    response = self.process_request(request)
  File "/home/mobilitysqr/.local/lib/python3.6/site-packages/django/middleware/common.py", line 53, in process_request
    path = self.get_full_path_with_slash(request)
  File "/home/mobilitysqr/.local/lib/python3.6/site-packages/django/middleware/common.py", line 93, in get_full_path_with_slash
    'url': request.get_host() + new_path,
RuntimeError: You called this URL via POST, but the URL doesn't end in a slash and you have APPEND_SLASH set. Django can't redirect to the slash URL while maintaining POST data. Change your form to point to 52.165.220.40:8080/api/login/ (note the trailing slash), or set APPEND_SLASH=False in your Django settings.
ERROR|25/Feb/2021 11:27:22|basehttp|13079|140143843342080|"POST /api/login HTTP/1.1" 500 64460
ERROR|25/Feb/2021 11:29:53|log|13079|140143843342080|Internal Server Error: /api/login/
Traceback (most recent call last):
  File "/home/mobilitysqr/.local/lib/python3.6/site-packages/django/db/backends/base/base.py", line 216, in ensure_connection
    self.connect()
  File "/home/mobilitysqr/.local/lib/python3.6/site-packages/django/db/backends/base/base.py", line 194, in connect
    self.connection = self.get_new_connection(conn_params)
  File "/home/mobilitysqr/.local/lib/python3.6/site-packages/sql_server/pyodbc/base.py", line 307, in get_new_connection
    timeout=timeout)
pyodbc.ProgrammingError: ('42000', '[42000] [Microsoft][ODBC Driver 17 for SQL Server][SQL Server]Cannot open database "mobilitysqrpreprod" requested by the login. The login failed. (4060) (SQLDriverConnect)')

The above exception was the direct cause of the following exception:

Traceback (most recent call last):
  File "/home/mobilitysqr/.local/lib/python3.6/site-packages/django/core/handlers/exception.py", line 34, in inner
    response = get_response(request)
  File "/home/mobilitysqr/.local/lib/python3.6/site-packages/django/core/handlers/base.py", line 126, in _get_response
    response = self.process_exception_by_middleware(e, request)
  File "/home/mobilitysqr/.local/lib/python3.6/site-packages/django/core/handlers/base.py", line 124, in _get_response
    response = wrapped_callback(request, *callback_args, **callback_kwargs)
  File "/home/mobilitysqr/.local/lib/python3.6/site-packages/django/views/decorators/csrf.py", line 54, in wrapped_view
    return view_func(*args, **kwargs)
  File "/home/mobilitysqr/.local/lib/python3.6/site-packages/django/views/generic/base.py", line 68, in view
    return self.dispatch(request, *args, **kwargs)
  File "/home/mobilitysqr/.local/lib/python3.6/site-packages/rest_framework/views.py", line 495, in dispatch
    response = self.handle_exception(exc)
  File "/home/mobilitysqr/.local/lib/python3.6/site-packages/rest_framework/views.py", line 455, in handle_exception
    self.raise_uncaught_exception(exc)
  File "/home/mobilitysqr/.local/lib/python3.6/site-packages/rest_framework/views.py", line 492, in dispatch
    response = handler(request, *args, **kwargs)
  File "/home/mobilitysqr/.local/lib/python3.6/site-packages/rest_framework_simplejwt/views.py", line 27, in post
    serializer.is_valid(raise_exception=True)
  File "/home/mobilitysqr/.local/lib/python3.6/site-packages/rest_framework/serializers.py", line 236, in is_valid
    self._validated_data = self.run_validation(self.initial_data)
  File "/home/mobilitysqr/.local/lib/python3.6/site-packages/rest_framework/serializers.py", line 437, in run_validation
    value = self.validate(value)
  File "/home/mobilitysqr/.local/lib/python3.6/site-packages/rest_framework_simplejwt/serializers.py", line 71, in validate
    data = super().validate(attrs)
  File "/home/mobilitysqr/.local/lib/python3.6/site-packages/rest_framework_simplejwt/serializers.py", line 43, in validate
    self.user = authenticate(**authenticate_kwargs)
  File "/home/mobilitysqr/.local/lib/python3.6/site-packages/django/contrib/auth/__init__.py", line 73, in authenticate
    user = backend.authenticate(request, **credentials)
  File "/home/mobilitysqr/.local/lib/python3.6/site-packages/django/contrib/auth/backends.py", line 16, in authenticate
    user = UserModel._default_manager.get_by_natural_key(username)
  File "/home/mobilitysqr/.local/lib/python3.6/site-packages/django/contrib/auth/base_user.py", line 44, in get_by_natural_key
    return self.get(**{self.model.USERNAME_FIELD: username})
  File "/home/mobilitysqr/.local/lib/python3.6/site-packages/django/db/models/manager.py", line 82, in manager_method
    return getattr(self.get_queryset(), name)(*args, **kwargs)
  File "/home/mobilitysqr/.local/lib/python3.6/site-packages/django/db/models/query.py", line 393, in get
    num = len(clone)
  File "/home/mobilitysqr/.local/lib/python3.6/site-packages/django/db/models/query.py", line 250, in __len__
    self._fetch_all()
  File "/home/mobilitysqr/.local/lib/python3.6/site-packages/django/db/models/query.py", line 1183, in _fetch_all
    self._result_cache = list(self._iterable_class(self))
  File "/home/mobilitysqr/.local/lib/python3.6/site-packages/django/db/models/query.py", line 54, in __iter__
    results = compiler.execute_sql(chunked_fetch=self.chunked_fetch, chunk_size=self.chunk_size)
  File "/home/mobilitysqr/.local/lib/python3.6/site-packages/django/db/models/sql/compiler.py", line 1059, in execute_sql
    cursor = self.connection.cursor()
  File "/home/mobilitysqr/.local/lib/python3.6/site-packages/django/db/backends/base/base.py", line 255, in cursor
    return self._cursor()
  File "/home/mobilitysqr/.local/lib/python3.6/site-packages/django/db/backends/base/base.py", line 232, in _cursor
    self.ensure_connection()
  File "/home/mobilitysqr/.local/lib/python3.6/site-packages/django/db/backends/base/base.py", line 216, in ensure_connection
    self.connect()
  File "/home/mobilitysqr/.local/lib/python3.6/site-packages/django/db/utils.py", line 89, in __exit__
    raise dj_exc_value.with_traceback(traceback) from exc_value
  File "/home/mobilitysqr/.local/lib/python3.6/site-packages/django/db/backends/base/base.py", line 216, in ensure_connection
    self.connect()
  File "/home/mobilitysqr/.local/lib/python3.6/site-packages/django/db/backends/base/base.py", line 194, in connect
    self.connection = self.get_new_connection(conn_params)
  File "/home/mobilitysqr/.local/lib/python3.6/site-packages/sql_server/pyodbc/base.py", line 307, in get_new_connection
    timeout=timeout)
django.db.utils.ProgrammingError: ('42000', '[42000] [Microsoft][ODBC Driver 17 for SQL Server][SQL Server]Cannot open database "mobilitysqrpreprod" requested by the login. The login failed. (4060) (SQLDriverConnect)')
ERROR|25/Feb/2021 11:29:53|basehttp|13079|140143843342080|"POST /api/login/ HTTP/1.1" 500 21483
ERROR|25/Feb/2021 11:35:26|log|13079|140143843342080|Internal Server Error: /checkemployeeuser/
Traceback (most recent call last):
  File "/home/mobilitysqr/.local/lib/python3.6/site-packages/django/db/backends/base/base.py", line 216, in ensure_connection
    self.connect()
  File "/home/mobilitysqr/.local/lib/python3.6/site-packages/django/db/backends/base/base.py", line 194, in connect
    self.connection = self.get_new_connection(conn_params)
  File "/home/mobilitysqr/.local/lib/python3.6/site-packages/sql_server/pyodbc/base.py", line 307, in get_new_connection
    timeout=timeout)
pyodbc.ProgrammingError: ('42000', '[42000] [Microsoft][ODBC Driver 17 for SQL Server][SQL Server]Cannot open database "mobilitysqrpreprod" requested by the login. The login failed. (4060) (SQLDriverConnect)')

The above exception was the direct cause of the following exception:

Traceback (most recent call last):
  File "/home/mobilitysqr/.local/lib/python3.6/site-packages/django/core/handlers/exception.py", line 34, in inner
    response = get_response(request)
  File "/home/mobilitysqr/.local/lib/python3.6/site-packages/django/core/handlers/base.py", line 126, in _get_response
    response = self.process_exception_by_middleware(e, request)
  File "/home/mobilitysqr/.local/lib/python3.6/site-packages/django/core/handlers/base.py", line 124, in _get_response
    response = wrapped_callback(request, *callback_args, **callback_kwargs)
  File "/home/mobilitysqr/.local/lib/python3.6/site-packages/django/views/decorators/csrf.py", line 54, in wrapped_view
    return view_func(*args, **kwargs)
  File "/home/mobilitysqr/.local/lib/python3.6/site-packages/django/views/generic/base.py", line 68, in view
    return self.dispatch(request, *args, **kwargs)
  File "/home/mobilitysqr/.local/lib/python3.6/site-packages/rest_framework/views.py", line 495, in dispatch
    response = self.handle_exception(exc)
  File "/home/mobilitysqr/.local/lib/python3.6/site-packages/rest_framework/views.py", line 455, in handle_exception
    self.raise_uncaught_exception(exc)
  File "/home/mobilitysqr/.local/lib/python3.6/site-packages/rest_framework/views.py", line 492, in dispatch
    response = handler(request, *args, **kwargs)
  File "/var/www/html/mobilitysqr_staging/mobility_apps/employee/views.py", line 1320, in get
    if employees1:
  File "/home/mobilitysqr/.local/lib/python3.6/site-packages/django/db/models/query.py", line 272, in __bool__
    self._fetch_all()
  File "/home/mobilitysqr/.local/lib/python3.6/site-packages/django/db/models/query.py", line 1183, in _fetch_all
    self._result_cache = list(self._iterable_class(self))
  File "/home/mobilitysqr/.local/lib/python3.6/site-packages/django/db/models/query.py", line 54, in __iter__
    results = compiler.execute_sql(chunked_fetch=self.chunked_fetch, chunk_size=self.chunk_size)
  File "/home/mobilitysqr/.local/lib/python3.6/site-packages/django/db/models/sql/compiler.py", line 1059, in execute_sql
    cursor = self.connection.cursor()
  File "/home/mobilitysqr/.local/lib/python3.6/site-packages/django/db/backends/base/base.py", line 255, in cursor
    return self._cursor()
  File "/home/mobilitysqr/.local/lib/python3.6/site-packages/django/db/backends/base/base.py", line 232, in _cursor
    self.ensure_connection()
  File "/home/mobilitysqr/.local/lib/python3.6/site-packages/django/db/backends/base/base.py", line 216, in ensure_connection
    self.connect()
  File "/home/mobilitysqr/.local/lib/python3.6/site-packages/django/db/utils.py", line 89, in __exit__
    raise dj_exc_value.with_traceback(traceback) from exc_value
  File "/home/mobilitysqr/.local/lib/python3.6/site-packages/django/db/backends/base/base.py", line 216, in ensure_connection
    self.connect()
  File "/home/mobilitysqr/.local/lib/python3.6/site-packages/django/db/backends/base/base.py", line 194, in connect
    self.connection = self.get_new_connection(conn_params)
  File "/home/mobilitysqr/.local/lib/python3.6/site-packages/sql_server/pyodbc/base.py", line 307, in get_new_connection
    timeout=timeout)
django.db.utils.ProgrammingError: ('42000', '[42000] [Microsoft][ODBC Driver 17 for SQL Server][SQL Server]Cannot open database "mobilitysqrpreprod" requested by the login. The login failed. (4060) (SQLDriverConnect)')
ERROR|25/Feb/2021 11:35:26|basehttp|13079|140143843342080|"GET /checkemployeeuser/?user_name=divyanshu094 HTTP/1.1" 500 19659
ERROR|25/Feb/2021 11:37:59|log|13079|140143843342080|Internal Server Error: /checkemployeeuser/
Traceback (most recent call last):
  File "/home/mobilitysqr/.local/lib/python3.6/site-packages/django/db/backends/base/base.py", line 216, in ensure_connection
    self.connect()
  File "/home/mobilitysqr/.local/lib/python3.6/site-packages/django/db/backends/base/base.py", line 194, in connect
    self.connection = self.get_new_connection(conn_params)
  File "/home/mobilitysqr/.local/lib/python3.6/site-packages/sql_server/pyodbc/base.py", line 307, in get_new_connection
    timeout=timeout)
pyodbc.ProgrammingError: ('42000', '[42000] [Microsoft][ODBC Driver 17 for SQL Server][SQL Server]Cannot open database "mobilitysqrpreprod" requested by the login. The login failed. (4060) (SQLDriverConnect)')

The above exception was the direct cause of the following exception:

Traceback (most recent call last):
  File "/home/mobilitysqr/.local/lib/python3.6/site-packages/django/core/handlers/exception.py", line 34, in inner
    response = get_response(request)
  File "/home/mobilitysqr/.local/lib/python3.6/site-packages/django/core/handlers/base.py", line 126, in _get_response
    response = self.process_exception_by_middleware(e, request)
  File "/home/mobilitysqr/.local/lib/python3.6/site-packages/django/core/handlers/base.py", line 124, in _get_response
    response = wrapped_callback(request, *callback_args, **callback_kwargs)
  File "/home/mobilitysqr/.local/lib/python3.6/site-packages/django/views/decorators/csrf.py", line 54, in wrapped_view
    return view_func(*args, **kwargs)
  File "/home/mobilitysqr/.local/lib/python3.6/site-packages/django/views/generic/base.py", line 68, in view
    return self.dispatch(request, *args, **kwargs)
  File "/home/mobilitysqr/.local/lib/python3.6/site-packages/rest_framework/views.py", line 495, in dispatch
    response = self.handle_exception(exc)
  File "/home/mobilitysqr/.local/lib/python3.6/site-packages/rest_framework/views.py", line 455, in handle_exception
    self.raise_uncaught_exception(exc)
  File "/home/mobilitysqr/.local/lib/python3.6/site-packages/rest_framework/views.py", line 492, in dispatch
    response = handler(request, *args, **kwargs)
  File "/var/www/html/mobilitysqr_staging/mobility_apps/employee/views.py", line 1320, in get
    if employees1:
  File "/home/mobilitysqr/.local/lib/python3.6/site-packages/django/db/models/query.py", line 272, in __bool__
    self._fetch_all()
  File "/home/mobilitysqr/.local/lib/python3.6/site-packages/django/db/models/query.py", line 1183, in _fetch_all
    self._result_cache = list(self._iterable_class(self))
  File "/home/mobilitysqr/.local/lib/python3.6/site-packages/django/db/models/query.py", line 54, in __iter__
    results = compiler.execute_sql(chunked_fetch=self.chunked_fetch, chunk_size=self.chunk_size)
  File "/home/mobilitysqr/.local/lib/python3.6/site-packages/django/db/models/sql/compiler.py", line 1059, in execute_sql
    cursor = self.connection.cursor()
  File "/home/mobilitysqr/.local/lib/python3.6/site-packages/django/db/backends/base/base.py", line 255, in cursor
    return self._cursor()
  File "/home/mobilitysqr/.local/lib/python3.6/site-packages/django/db/backends/base/base.py", line 232, in _cursor
    self.ensure_connection()
  File "/home/mobilitysqr/.local/lib/python3.6/site-packages/django/db/backends/base/base.py", line 216, in ensure_connection
    self.connect()
  File "/home/mobilitysqr/.local/lib/python3.6/site-packages/django/db/utils.py", line 89, in __exit__
    raise dj_exc_value.with_traceback(traceback) from exc_value
  File "/home/mobilitysqr/.local/lib/python3.6/site-packages/django/db/backends/base/base.py", line 216, in ensure_connection
    self.connect()
  File "/home/mobilitysqr/.local/lib/python3.6/site-packages/django/db/backends/base/base.py", line 194, in connect
    self.connection = self.get_new_connection(conn_params)
  File "/home/mobilitysqr/.local/lib/python3.6/site-packages/sql_server/pyodbc/base.py", line 307, in get_new_connection
    timeout=timeout)
django.db.utils.ProgrammingError: ('42000', '[42000] [Microsoft][ODBC Driver 17 for SQL Server][SQL Server]Cannot open database "mobilitysqrpreprod" requested by the login. The login failed. (4060) (SQLDriverConnect)')
ERROR|25/Feb/2021 11:37:59|basehttp|13079|140143843342080|"GET /checkemployeeuser/?user_name=divyanshu094 HTTP/1.1" 500 19659
ERROR|25/Feb/2021 11:41:40|log|13079|140143843342080|Internal Server Error: /api/login/
Traceback (most recent call last):
  File "/home/mobilitysqr/.local/lib/python3.6/site-packages/django/db/backends/base/base.py", line 216, in ensure_connection
    self.connect()
  File "/home/mobilitysqr/.local/lib/python3.6/site-packages/django/db/backends/base/base.py", line 194, in connect
    self.connection = self.get_new_connection(conn_params)
  File "/home/mobilitysqr/.local/lib/python3.6/site-packages/sql_server/pyodbc/base.py", line 307, in get_new_connection
    timeout=timeout)
pyodbc.ProgrammingError: ('42000', '[42000] [Microsoft][ODBC Driver 17 for SQL Server][SQL Server]Cannot open database "mobilitysqrpreprod" requested by the login. The login failed. (4060) (SQLDriverConnect)')

The above exception was the direct cause of the following exception:

Traceback (most recent call last):
  File "/home/mobilitysqr/.local/lib/python3.6/site-packages/django/core/handlers/exception.py", line 34, in inner
    response = get_response(request)
  File "/home/mobilitysqr/.local/lib/python3.6/site-packages/django/core/handlers/base.py", line 126, in _get_response
    response = self.process_exception_by_middleware(e, request)
  File "/home/mobilitysqr/.local/lib/python3.6/site-packages/django/core/handlers/base.py", line 124, in _get_response
    response = wrapped_callback(request, *callback_args, **callback_kwargs)
  File "/home/mobilitysqr/.local/lib/python3.6/site-packages/django/views/decorators/csrf.py", line 54, in wrapped_view
    return view_func(*args, **kwargs)
  File "/home/mobilitysqr/.local/lib/python3.6/site-packages/django/views/generic/base.py", line 68, in view
    return self.dispatch(request, *args, **kwargs)
  File "/home/mobilitysqr/.local/lib/python3.6/site-packages/rest_framework/views.py", line 495, in dispatch
    response = self.handle_exception(exc)
  File "/home/mobilitysqr/.local/lib/python3.6/site-packages/rest_framework/views.py", line 455, in handle_exception
    self.raise_uncaught_exception(exc)
  File "/home/mobilitysqr/.local/lib/python3.6/site-packages/rest_framework/views.py", line 492, in dispatch
    response = handler(request, *args, **kwargs)
  File "/home/mobilitysqr/.local/lib/python3.6/site-packages/rest_framework_simplejwt/views.py", line 27, in post
    serializer.is_valid(raise_exception=True)
  File "/home/mobilitysqr/.local/lib/python3.6/site-packages/rest_framework/serializers.py", line 236, in is_valid
    self._validated_data = self.run_validation(self.initial_data)
  File "/home/mobilitysqr/.local/lib/python3.6/site-packages/rest_framework/serializers.py", line 437, in run_validation
    value = self.validate(value)
  File "/home/mobilitysqr/.local/lib/python3.6/site-packages/rest_framework_simplejwt/serializers.py", line 71, in validate
    data = super().validate(attrs)
  File "/home/mobilitysqr/.local/lib/python3.6/site-packages/rest_framework_simplejwt/serializers.py", line 43, in validate
    self.user = authenticate(**authenticate_kwargs)
  File "/home/mobilitysqr/.local/lib/python3.6/site-packages/django/contrib/auth/__init__.py", line 73, in authenticate
    user = backend.authenticate(request, **credentials)
  File "/home/mobilitysqr/.local/lib/python3.6/site-packages/django/contrib/auth/backends.py", line 16, in authenticate
    user = UserModel._default_manager.get_by_natural_key(username)
  File "/home/mobilitysqr/.local/lib/python3.6/site-packages/django/contrib/auth/base_user.py", line 44, in get_by_natural_key
    return self.get(**{self.model.USERNAME_FIELD: username})
  File "/home/mobilitysqr/.local/lib/python3.6/site-packages/django/db/models/manager.py", line 82, in manager_method
    return getattr(self.get_queryset(), name)(*args, **kwargs)
  File "/home/mobilitysqr/.local/lib/python3.6/site-packages/django/db/models/query.py", line 393, in get
    num = len(clone)
  File "/home/mobilitysqr/.local/lib/python3.6/site-packages/django/db/models/query.py", line 250, in __len__
    self._fetch_all()
  File "/home/mobilitysqr/.local/lib/python3.6/site-packages/django/db/models/query.py", line 1183, in _fetch_all
    self._result_cache = list(self._iterable_class(self))
  File "/home/mobilitysqr/.local/lib/python3.6/site-packages/django/db/models/query.py", line 54, in __iter__
    results = compiler.execute_sql(chunked_fetch=self.chunked_fetch, chunk_size=self.chunk_size)
  File "/home/mobilitysqr/.local/lib/python3.6/site-packages/django/db/models/sql/compiler.py", line 1059, in execute_sql
    cursor = self.connection.cursor()
  File "/home/mobilitysqr/.local/lib/python3.6/site-packages/django/db/backends/base/base.py", line 255, in cursor
    return self._cursor()
  File "/home/mobilitysqr/.local/lib/python3.6/site-packages/django/db/backends/base/base.py", line 232, in _cursor
    self.ensure_connection()
  File "/home/mobilitysqr/.local/lib/python3.6/site-packages/django/db/backends/base/base.py", line 216, in ensure_connection
    self.connect()
  File "/home/mobilitysqr/.local/lib/python3.6/site-packages/django/db/utils.py", line 89, in __exit__
    raise dj_exc_value.with_traceback(traceback) from exc_value
  File "/home/mobilitysqr/.local/lib/python3.6/site-packages/django/db/backends/base/base.py", line 216, in ensure_connection
    self.connect()
  File "/home/mobilitysqr/.local/lib/python3.6/site-packages/django/db/backends/base/base.py", line 194, in connect
    self.connection = self.get_new_connection(conn_params)
  File "/home/mobilitysqr/.local/lib/python3.6/site-packages/sql_server/pyodbc/base.py", line 307, in get_new_connection
    timeout=timeout)
django.db.utils.ProgrammingError: ('42000', '[42000] [Microsoft][ODBC Driver 17 for SQL Server][SQL Server]Cannot open database "mobilitysqrpreprod" requested by the login. The login failed. (4060) (SQLDriverConnect)')
ERROR|25/Feb/2021 11:41:40|basehttp|13079|140143843342080|"POST /api/login/ HTTP/1.1" 500 21483
ERROR|25/Feb/2021 11:47:43|log|13079|140143843342080|Internal Server Error: /api/login/
Traceback (most recent call last):
  File "/home/mobilitysqr/.local/lib/python3.6/site-packages/django/db/backends/base/base.py", line 216, in ensure_connection
    self.connect()
  File "/home/mobilitysqr/.local/lib/python3.6/site-packages/django/db/backends/base/base.py", line 194, in connect
    self.connection = self.get_new_connection(conn_params)
  File "/home/mobilitysqr/.local/lib/python3.6/site-packages/sql_server/pyodbc/base.py", line 307, in get_new_connection
    timeout=timeout)
pyodbc.ProgrammingError: ('42000', '[42000] [Microsoft][ODBC Driver 17 for SQL Server][SQL Server]Cannot open database "mobilitysqrpreprod" requested by the login. The login failed. (4060) (SQLDriverConnect)')

The above exception was the direct cause of the following exception:

Traceback (most recent call last):
  File "/home/mobilitysqr/.local/lib/python3.6/site-packages/django/core/handlers/exception.py", line 34, in inner
    response = get_response(request)
  File "/home/mobilitysqr/.local/lib/python3.6/site-packages/django/core/handlers/base.py", line 126, in _get_response
    response = self.process_exception_by_middleware(e, request)
  File "/home/mobilitysqr/.local/lib/python3.6/site-packages/django/core/handlers/base.py", line 124, in _get_response
    response = wrapped_callback(request, *callback_args, **callback_kwargs)
  File "/home/mobilitysqr/.local/lib/python3.6/site-packages/django/views/decorators/csrf.py", line 54, in wrapped_view
    return view_func(*args, **kwargs)
  File "/home/mobilitysqr/.local/lib/python3.6/site-packages/django/views/generic/base.py", line 68, in view
    return self.dispatch(request, *args, **kwargs)
  File "/home/mobilitysqr/.local/lib/python3.6/site-packages/rest_framework/views.py", line 495, in dispatch
    response = self.handle_exception(exc)
  File "/home/mobilitysqr/.local/lib/python3.6/site-packages/rest_framework/views.py", line 455, in handle_exception
    self.raise_uncaught_exception(exc)
  File "/home/mobilitysqr/.local/lib/python3.6/site-packages/rest_framework/views.py", line 492, in dispatch
    response = handler(request, *args, **kwargs)
  File "/home/mobilitysqr/.local/lib/python3.6/site-packages/rest_framework_simplejwt/views.py", line 27, in post
    serializer.is_valid(raise_exception=True)
  File "/home/mobilitysqr/.local/lib/python3.6/site-packages/rest_framework/serializers.py", line 236, in is_valid
    self._validated_data = self.run_validation(self.initial_data)
  File "/home/mobilitysqr/.local/lib/python3.6/site-packages/rest_framework/serializers.py", line 437, in run_validation
    value = self.validate(value)
  File "/home/mobilitysqr/.local/lib/python3.6/site-packages/rest_framework_simplejwt/serializers.py", line 71, in validate
    data = super().validate(attrs)
  File "/home/mobilitysqr/.local/lib/python3.6/site-packages/rest_framework_simplejwt/serializers.py", line 43, in validate
    self.user = authenticate(**authenticate_kwargs)
  File "/home/mobilitysqr/.local/lib/python3.6/site-packages/django/contrib/auth/__init__.py", line 73, in authenticate
    user = backend.authenticate(request, **credentials)
  File "/home/mobilitysqr/.local/lib/python3.6/site-packages/django/contrib/auth/backends.py", line 16, in authenticate
    user = UserModel._default_manager.get_by_natural_key(username)
  File "/home/mobilitysqr/.local/lib/python3.6/site-packages/django/contrib/auth/base_user.py", line 44, in get_by_natural_key
    return self.get(**{self.model.USERNAME_FIELD: username})
  File "/home/mobilitysqr/.local/lib/python3.6/site-packages/django/db/models/manager.py", line 82, in manager_method
    return getattr(self.get_queryset(), name)(*args, **kwargs)
  File "/home/mobilitysqr/.local/lib/python3.6/site-packages/django/db/models/query.py", line 393, in get
    num = len(clone)
  File "/home/mobilitysqr/.local/lib/python3.6/site-packages/django/db/models/query.py", line 250, in __len__
    self._fetch_all()
  File "/home/mobilitysqr/.local/lib/python3.6/site-packages/django/db/models/query.py", line 1183, in _fetch_all
    self._result_cache = list(self._iterable_class(self))
  File "/home/mobilitysqr/.local/lib/python3.6/site-packages/django/db/models/query.py", line 54, in __iter__
    results = compiler.execute_sql(chunked_fetch=self.chunked_fetch, chunk_size=self.chunk_size)
  File "/home/mobilitysqr/.local/lib/python3.6/site-packages/django/db/models/sql/compiler.py", line 1059, in execute_sql
    cursor = self.connection.cursor()
  File "/home/mobilitysqr/.local/lib/python3.6/site-packages/django/db/backends/base/base.py", line 255, in cursor
    return self._cursor()
  File "/home/mobilitysqr/.local/lib/python3.6/site-packages/django/db/backends/base/base.py", line 232, in _cursor
    self.ensure_connection()
  File "/home/mobilitysqr/.local/lib/python3.6/site-packages/django/db/backends/base/base.py", line 216, in ensure_connection
    self.connect()
  File "/home/mobilitysqr/.local/lib/python3.6/site-packages/django/db/utils.py", line 89, in __exit__
    raise dj_exc_value.with_traceback(traceback) from exc_value
  File "/home/mobilitysqr/.local/lib/python3.6/site-packages/django/db/backends/base/base.py", line 216, in ensure_connection
    self.connect()
  File "/home/mobilitysqr/.local/lib/python3.6/site-packages/django/db/backends/base/base.py", line 194, in connect
    self.connection = self.get_new_connection(conn_params)
  File "/home/mobilitysqr/.local/lib/python3.6/site-packages/sql_server/pyodbc/base.py", line 307, in get_new_connection
    timeout=timeout)
django.db.utils.ProgrammingError: ('42000', '[42000] [Microsoft][ODBC Driver 17 for SQL Server][SQL Server]Cannot open database "mobilitysqrpreprod" requested by the login. The login failed. (4060) (SQLDriverConnect)')
ERROR|25/Feb/2021 11:47:43|basehttp|13079|140143843342080|"POST /api/login/ HTTP/1.1" 500 21279
ERROR|25/Feb/2021 11:52:54|log|13079|140143843342080|Internal Server Error: /api/login/
Traceback (most recent call last):
  File "/home/mobilitysqr/.local/lib/python3.6/site-packages/django/db/backends/base/base.py", line 216, in ensure_connection
    self.connect()
  File "/home/mobilitysqr/.local/lib/python3.6/site-packages/django/db/backends/base/base.py", line 194, in connect
    self.connection = self.get_new_connection(conn_params)
  File "/home/mobilitysqr/.local/lib/python3.6/site-packages/sql_server/pyodbc/base.py", line 307, in get_new_connection
    timeout=timeout)
pyodbc.ProgrammingError: ('42000', '[42000] [Microsoft][ODBC Driver 17 for SQL Server][SQL Server]Cannot open database "mobilitysqrpreprod" requested by the login. The login failed. (4060) (SQLDriverConnect)')

The above exception was the direct cause of the following exception:

Traceback (most recent call last):
  File "/home/mobilitysqr/.local/lib/python3.6/site-packages/django/core/handlers/exception.py", line 34, in inner
    response = get_response(request)
  File "/home/mobilitysqr/.local/lib/python3.6/site-packages/django/core/handlers/base.py", line 126, in _get_response
    response = self.process_exception_by_middleware(e, request)
  File "/home/mobilitysqr/.local/lib/python3.6/site-packages/django/core/handlers/base.py", line 124, in _get_response
    response = wrapped_callback(request, *callback_args, **callback_kwargs)
  File "/home/mobilitysqr/.local/lib/python3.6/site-packages/django/views/decorators/csrf.py", line 54, in wrapped_view
    return view_func(*args, **kwargs)
  File "/home/mobilitysqr/.local/lib/python3.6/site-packages/django/views/generic/base.py", line 68, in view
    return self.dispatch(request, *args, **kwargs)
  File "/home/mobilitysqr/.local/lib/python3.6/site-packages/rest_framework/views.py", line 495, in dispatch
    response = self.handle_exception(exc)
  File "/home/mobilitysqr/.local/lib/python3.6/site-packages/rest_framework/views.py", line 455, in handle_exception
    self.raise_uncaught_exception(exc)
  File "/home/mobilitysqr/.local/lib/python3.6/site-packages/rest_framework/views.py", line 492, in dispatch
    response = handler(request, *args, **kwargs)
  File "/home/mobilitysqr/.local/lib/python3.6/site-packages/rest_framework_simplejwt/views.py", line 27, in post
    serializer.is_valid(raise_exception=True)
  File "/home/mobilitysqr/.local/lib/python3.6/site-packages/rest_framework/serializers.py", line 236, in is_valid
    self._validated_data = self.run_validation(self.initial_data)
  File "/home/mobilitysqr/.local/lib/python3.6/site-packages/rest_framework/serializers.py", line 437, in run_validation
    value = self.validate(value)
  File "/home/mobilitysqr/.local/lib/python3.6/site-packages/rest_framework_simplejwt/serializers.py", line 71, in validate
    data = super().validate(attrs)
  File "/home/mobilitysqr/.local/lib/python3.6/site-packages/rest_framework_simplejwt/serializers.py", line 43, in validate
    self.user = authenticate(**authenticate_kwargs)
  File "/home/mobilitysqr/.local/lib/python3.6/site-packages/django/contrib/auth/__init__.py", line 73, in authenticate
    user = backend.authenticate(request, **credentials)
  File "/home/mobilitysqr/.local/lib/python3.6/site-packages/django/contrib/auth/backends.py", line 16, in authenticate
    user = UserModel._default_manager.get_by_natural_key(username)
  File "/home/mobilitysqr/.local/lib/python3.6/site-packages/django/contrib/auth/base_user.py", line 44, in get_by_natural_key
    return self.get(**{self.model.USERNAME_FIELD: username})
  File "/home/mobilitysqr/.local/lib/python3.6/site-packages/django/db/models/manager.py", line 82, in manager_method
    return getattr(self.get_queryset(), name)(*args, **kwargs)
  File "/home/mobilitysqr/.local/lib/python3.6/site-packages/django/db/models/query.py", line 393, in get
    num = len(clone)
  File "/home/mobilitysqr/.local/lib/python3.6/site-packages/django/db/models/query.py", line 250, in __len__
    self._fetch_all()
  File "/home/mobilitysqr/.local/lib/python3.6/site-packages/django/db/models/query.py", line 1183, in _fetch_all
    self._result_cache = list(self._iterable_class(self))
  File "/home/mobilitysqr/.local/lib/python3.6/site-packages/django/db/models/query.py", line 54, in __iter__
    results = compiler.execute_sql(chunked_fetch=self.chunked_fetch, chunk_size=self.chunk_size)
  File "/home/mobilitysqr/.local/lib/python3.6/site-packages/django/db/models/sql/compiler.py", line 1059, in execute_sql
    cursor = self.connection.cursor()
  File "/home/mobilitysqr/.local/lib/python3.6/site-packages/django/db/backends/base/base.py", line 255, in cursor
    return self._cursor()
  File "/home/mobilitysqr/.local/lib/python3.6/site-packages/django/db/backends/base/base.py", line 232, in _cursor
    self.ensure_connection()
  File "/home/mobilitysqr/.local/lib/python3.6/site-packages/django/db/backends/base/base.py", line 216, in ensure_connection
    self.connect()
  File "/home/mobilitysqr/.local/lib/python3.6/site-packages/django/db/utils.py", line 89, in __exit__
    raise dj_exc_value.with_traceback(traceback) from exc_value
  File "/home/mobilitysqr/.local/lib/python3.6/site-packages/django/db/backends/base/base.py", line 216, in ensure_connection
    self.connect()
  File "/home/mobilitysqr/.local/lib/python3.6/site-packages/django/db/backends/base/base.py", line 194, in connect
    self.connection = self.get_new_connection(conn_params)
  File "/home/mobilitysqr/.local/lib/python3.6/site-packages/sql_server/pyodbc/base.py", line 307, in get_new_connection
    timeout=timeout)
django.db.utils.ProgrammingError: ('42000', '[42000] [Microsoft][ODBC Driver 17 for SQL Server][SQL Server]Cannot open database "mobilitysqrpreprod" requested by the login. The login failed. (4060) (SQLDriverConnect)')
ERROR|25/Feb/2021 11:52:54|basehttp|13079|140143843342080|"POST /api/login/ HTTP/1.1" 500 21483
ERROR|25/Feb/2021 11:53:15|log|13079|140143792985856|Internal Server Error: /api/login/
Traceback (most recent call last):
  File "/home/mobilitysqr/.local/lib/python3.6/site-packages/django/db/backends/base/base.py", line 216, in ensure_connection
    self.connect()
  File "/home/mobilitysqr/.local/lib/python3.6/site-packages/django/db/backends/base/base.py", line 194, in connect
    self.connection = self.get_new_connection(conn_params)
  File "/home/mobilitysqr/.local/lib/python3.6/site-packages/sql_server/pyodbc/base.py", line 307, in get_new_connection
    timeout=timeout)
pyodbc.ProgrammingError: ('42000', '[42000] [Microsoft][ODBC Driver 17 for SQL Server][SQL Server]Cannot open database "mobilitysqrpreprod" requested by the login. The login failed. (4060) (SQLDriverConnect)')

The above exception was the direct cause of the following exception:

Traceback (most recent call last):
  File "/home/mobilitysqr/.local/lib/python3.6/site-packages/django/core/handlers/exception.py", line 34, in inner
    response = get_response(request)
  File "/home/mobilitysqr/.local/lib/python3.6/site-packages/django/core/handlers/base.py", line 126, in _get_response
    response = self.process_exception_by_middleware(e, request)
  File "/home/mobilitysqr/.local/lib/python3.6/site-packages/django/core/handlers/base.py", line 124, in _get_response
    response = wrapped_callback(request, *callback_args, **callback_kwargs)
  File "/home/mobilitysqr/.local/lib/python3.6/site-packages/django/views/decorators/csrf.py", line 54, in wrapped_view
    return view_func(*args, **kwargs)
  File "/home/mobilitysqr/.local/lib/python3.6/site-packages/django/views/generic/base.py", line 68, in view
    return self.dispatch(request, *args, **kwargs)
  File "/home/mobilitysqr/.local/lib/python3.6/site-packages/rest_framework/views.py", line 495, in dispatch
    response = self.handle_exception(exc)
  File "/home/mobilitysqr/.local/lib/python3.6/site-packages/rest_framework/views.py", line 455, in handle_exception
    self.raise_uncaught_exception(exc)
  File "/home/mobilitysqr/.local/lib/python3.6/site-packages/rest_framework/views.py", line 492, in dispatch
    response = handler(request, *args, **kwargs)
  File "/home/mobilitysqr/.local/lib/python3.6/site-packages/rest_framework_simplejwt/views.py", line 27, in post
    serializer.is_valid(raise_exception=True)
  File "/home/mobilitysqr/.local/lib/python3.6/site-packages/rest_framework/serializers.py", line 236, in is_valid
    self._validated_data = self.run_validation(self.initial_data)
  File "/home/mobilitysqr/.local/lib/python3.6/site-packages/rest_framework/serializers.py", line 437, in run_validation
    value = self.validate(value)
  File "/home/mobilitysqr/.local/lib/python3.6/site-packages/rest_framework_simplejwt/serializers.py", line 71, in validate
    data = super().validate(attrs)
  File "/home/mobilitysqr/.local/lib/python3.6/site-packages/rest_framework_simplejwt/serializers.py", line 43, in validate
    self.user = authenticate(**authenticate_kwargs)
  File "/home/mobilitysqr/.local/lib/python3.6/site-packages/django/contrib/auth/__init__.py", line 73, in authenticate
    user = backend.authenticate(request, **credentials)
  File "/home/mobilitysqr/.local/lib/python3.6/site-packages/django/contrib/auth/backends.py", line 16, in authenticate
    user = UserModel._default_manager.get_by_natural_key(username)
  File "/home/mobilitysqr/.local/lib/python3.6/site-packages/django/contrib/auth/base_user.py", line 44, in get_by_natural_key
    return self.get(**{self.model.USERNAME_FIELD: username})
  File "/home/mobilitysqr/.local/lib/python3.6/site-packages/django/db/models/manager.py", line 82, in manager_method
    return getattr(self.get_queryset(), name)(*args, **kwargs)
  File "/home/mobilitysqr/.local/lib/python3.6/site-packages/django/db/models/query.py", line 393, in get
    num = len(clone)
  File "/home/mobilitysqr/.local/lib/python3.6/site-packages/django/db/models/query.py", line 250, in __len__
    self._fetch_all()
  File "/home/mobilitysqr/.local/lib/python3.6/site-packages/django/db/models/query.py", line 1183, in _fetch_all
    self._result_cache = list(self._iterable_class(self))
  File "/home/mobilitysqr/.local/lib/python3.6/site-packages/django/db/models/query.py", line 54, in __iter__
    results = compiler.execute_sql(chunked_fetch=self.chunked_fetch, chunk_size=self.chunk_size)
  File "/home/mobilitysqr/.local/lib/python3.6/site-packages/django/db/models/sql/compiler.py", line 1059, in execute_sql
    cursor = self.connection.cursor()
  File "/home/mobilitysqr/.local/lib/python3.6/site-packages/django/db/backends/base/base.py", line 255, in cursor
    return self._cursor()
  File "/home/mobilitysqr/.local/lib/python3.6/site-packages/django/db/backends/base/base.py", line 232, in _cursor
    self.ensure_connection()
  File "/home/mobilitysqr/.local/lib/python3.6/site-packages/django/db/backends/base/base.py", line 216, in ensure_connection
    self.connect()
  File "/home/mobilitysqr/.local/lib/python3.6/site-packages/django/db/utils.py", line 89, in __exit__
    raise dj_exc_value.with_traceback(traceback) from exc_value
  File "/home/mobilitysqr/.local/lib/python3.6/site-packages/django/db/backends/base/base.py", line 216, in ensure_connection
    self.connect()
  File "/home/mobilitysqr/.local/lib/python3.6/site-packages/django/db/backends/base/base.py", line 194, in connect
    self.connection = self.get_new_connection(conn_params)
  File "/home/mobilitysqr/.local/lib/python3.6/site-packages/sql_server/pyodbc/base.py", line 307, in get_new_connection
    timeout=timeout)
django.db.utils.ProgrammingError: ('42000', '[42000] [Microsoft][ODBC Driver 17 for SQL Server][SQL Server]Cannot open database "mobilitysqrpreprod" requested by the login. The login failed. (4060) (SQLDriverConnect)')
ERROR|25/Feb/2021 11:53:15|basehttp|13079|140143792985856|"POST /api/login/ HTTP/1.1" 500 21279
ERROR|25/Feb/2021 11:55:39|log|13079|140143843342080|Internal Server Error: /api/login/
Traceback (most recent call last):
  File "/home/mobilitysqr/.local/lib/python3.6/site-packages/django/db/backends/base/base.py", line 216, in ensure_connection
    self.connect()
  File "/home/mobilitysqr/.local/lib/python3.6/site-packages/django/db/backends/base/base.py", line 194, in connect
    self.connection = self.get_new_connection(conn_params)
  File "/home/mobilitysqr/.local/lib/python3.6/site-packages/sql_server/pyodbc/base.py", line 307, in get_new_connection
    timeout=timeout)
pyodbc.ProgrammingError: ('42000', '[42000] [Microsoft][ODBC Driver 17 for SQL Server][SQL Server]Cannot open database "mobilitysqrpreprod" requested by the login. The login failed. (4060) (SQLDriverConnect)')

The above exception was the direct cause of the following exception:

Traceback (most recent call last):
  File "/home/mobilitysqr/.local/lib/python3.6/site-packages/django/core/handlers/exception.py", line 34, in inner
    response = get_response(request)
  File "/home/mobilitysqr/.local/lib/python3.6/site-packages/django/core/handlers/base.py", line 126, in _get_response
    response = self.process_exception_by_middleware(e, request)
  File "/home/mobilitysqr/.local/lib/python3.6/site-packages/django/core/handlers/base.py", line 124, in _get_response
    response = wrapped_callback(request, *callback_args, **callback_kwargs)
  File "/home/mobilitysqr/.local/lib/python3.6/site-packages/django/views/decorators/csrf.py", line 54, in wrapped_view
    return view_func(*args, **kwargs)
  File "/home/mobilitysqr/.local/lib/python3.6/site-packages/django/views/generic/base.py", line 68, in view
    return self.dispatch(request, *args, **kwargs)
  File "/home/mobilitysqr/.local/lib/python3.6/site-packages/rest_framework/views.py", line 495, in dispatch
    response = self.handle_exception(exc)
  File "/home/mobilitysqr/.local/lib/python3.6/site-packages/rest_framework/views.py", line 455, in handle_exception
    self.raise_uncaught_exception(exc)
  File "/home/mobilitysqr/.local/lib/python3.6/site-packages/rest_framework/views.py", line 492, in dispatch
    response = handler(request, *args, **kwargs)
  File "/home/mobilitysqr/.local/lib/python3.6/site-packages/rest_framework_simplejwt/views.py", line 27, in post
    serializer.is_valid(raise_exception=True)
  File "/home/mobilitysqr/.local/lib/python3.6/site-packages/rest_framework/serializers.py", line 236, in is_valid
    self._validated_data = self.run_validation(self.initial_data)
  File "/home/mobilitysqr/.local/lib/python3.6/site-packages/rest_framework/serializers.py", line 437, in run_validation
    value = self.validate(value)
  File "/home/mobilitysqr/.local/lib/python3.6/site-packages/rest_framework_simplejwt/serializers.py", line 71, in validate
    data = super().validate(attrs)
  File "/home/mobilitysqr/.local/lib/python3.6/site-packages/rest_framework_simplejwt/serializers.py", line 43, in validate
    self.user = authenticate(**authenticate_kwargs)
  File "/home/mobilitysqr/.local/lib/python3.6/site-packages/django/contrib/auth/__init__.py", line 73, in authenticate
    user = backend.authenticate(request, **credentials)
  File "/home/mobilitysqr/.local/lib/python3.6/site-packages/django/contrib/auth/backends.py", line 16, in authenticate
    user = UserModel._default_manager.get_by_natural_key(username)
  File "/home/mobilitysqr/.local/lib/python3.6/site-packages/django/contrib/auth/base_user.py", line 44, in get_by_natural_key
    return self.get(**{self.model.USERNAME_FIELD: username})
  File "/home/mobilitysqr/.local/lib/python3.6/site-packages/django/db/models/manager.py", line 82, in manager_method
    return getattr(self.get_queryset(), name)(*args, **kwargs)
  File "/home/mobilitysqr/.local/lib/python3.6/site-packages/django/db/models/query.py", line 393, in get
    num = len(clone)
  File "/home/mobilitysqr/.local/lib/python3.6/site-packages/django/db/models/query.py", line 250, in __len__
    self._fetch_all()
  File "/home/mobilitysqr/.local/lib/python3.6/site-packages/django/db/models/query.py", line 1183, in _fetch_all
    self._result_cache = list(self._iterable_class(self))
  File "/home/mobilitysqr/.local/lib/python3.6/site-packages/django/db/models/query.py", line 54, in __iter__
    results = compiler.execute_sql(chunked_fetch=self.chunked_fetch, chunk_size=self.chunk_size)
  File "/home/mobilitysqr/.local/lib/python3.6/site-packages/django/db/models/sql/compiler.py", line 1059, in execute_sql
    cursor = self.connection.cursor()
  File "/home/mobilitysqr/.local/lib/python3.6/site-packages/django/db/backends/base/base.py", line 255, in cursor
    return self._cursor()
  File "/home/mobilitysqr/.local/lib/python3.6/site-packages/django/db/backends/base/base.py", line 232, in _cursor
    self.ensure_connection()
  File "/home/mobilitysqr/.local/lib/python3.6/site-packages/django/db/backends/base/base.py", line 216, in ensure_connection
    self.connect()
  File "/home/mobilitysqr/.local/lib/python3.6/site-packages/django/db/utils.py", line 89, in __exit__
    raise dj_exc_value.with_traceback(traceback) from exc_value
  File "/home/mobilitysqr/.local/lib/python3.6/site-packages/django/db/backends/base/base.py", line 216, in ensure_connection
    self.connect()
  File "/home/mobilitysqr/.local/lib/python3.6/site-packages/django/db/backends/base/base.py", line 194, in connect
    self.connection = self.get_new_connection(conn_params)
  File "/home/mobilitysqr/.local/lib/python3.6/site-packages/sql_server/pyodbc/base.py", line 307, in get_new_connection
    timeout=timeout)
django.db.utils.ProgrammingError: ('42000', '[42000] [Microsoft][ODBC Driver 17 for SQL Server][SQL Server]Cannot open database "mobilitysqrpreprod" requested by the login. The login failed. (4060) (SQLDriverConnect)')
ERROR|25/Feb/2021 11:55:39|basehttp|13079|140143843342080|"POST /api/login/ HTTP/1.1" 500 21279
ERROR|25/Feb/2021 11:55:41|exception|13079|140143843342080|Invalid HTTP_HOST header: ''. The domain name provided is not valid according to RFC 1034/1035.
