INFO|19/Mar/2021 10:29:47|basehttp|5005|140372072195840|"POST /api/custom/login/ HTTP/1.1" 200 452
ERROR|19/Mar/2021 10:30:20|log|5005|140372072195840|Internal Server Error: /vault_document_upload/
Traceback (most recent call last):
  File "/media/tspl26/D/raju_python/mobility_env/lib/python3.7/site-packages/django/db/backends/utils.py", line 85, in _execute
    return self.cursor.execute(sql, params)
  File "/media/tspl26/D/raju_python/mobility_env/lib/python3.7/site-packages/sql_server/pyodbc/base.py", line 546, in execute
    return self.cursor.execute(sql, params)
pyodbc.ProgrammingError: ('42000', '[42000] [Microsoft][ODBC Driver 17 for SQL Server][SQL Server]Error converting data type nvarchar to bigint. (8114) (SQLExecDirectW)')

The above exception was the direct cause of the following exception:

Traceback (most recent call last):
  File "/media/tspl26/D/raju_python/mobility_env/lib/python3.7/site-packages/django/core/handlers/exception.py", line 34, in inner
    response = get_response(request)
  File "/media/tspl26/D/raju_python/mobility_env/lib/python3.7/site-packages/django/core/handlers/base.py", line 126, in _get_response
    response = self.process_exception_by_middleware(e, request)
  File "/media/tspl26/D/raju_python/mobility_env/lib/python3.7/site-packages/django/core/handlers/base.py", line 124, in _get_response
    response = wrapped_callback(request, *callback_args, **callback_kwargs)
  File "/media/tspl26/D/raju_python/mobility_env/lib/python3.7/site-packages/django/views/decorators/csrf.py", line 54, in wrapped_view
    return view_func(*args, **kwargs)
  File "/media/tspl26/D/raju_python/mobility_env/lib/python3.7/site-packages/django/views/generic/base.py", line 68, in view
    return self.dispatch(request, *args, **kwargs)
  File "/media/tspl26/D/raju_python/mobility_env/lib/python3.7/site-packages/rest_framework/views.py", line 509, in dispatch
    response = self.handle_exception(exc)
  File "/media/tspl26/D/raju_python/mobility_env/lib/python3.7/site-packages/rest_framework/views.py", line 469, in handle_exception
    self.raise_uncaught_exception(exc)
  File "/media/tspl26/D/raju_python/mobility_env/lib/python3.7/site-packages/rest_framework/views.py", line 480, in raise_uncaught_exception
    raise exc
  File "/media/tspl26/D/raju_python/mobility_env/lib/python3.7/site-packages/rest_framework/views.py", line 506, in dispatch
    response = handler(request, *args, **kwargs)
  File "/media/tspl26/D/raju_python/mobility_env/mobilitysqr_live/mobility_apps/vault/views.py", line 78, in post
    serializer.save()
  File "/media/tspl26/D/raju_python/mobility_env/lib/python3.7/site-packages/rest_framework/serializers.py", line 205, in save
    self.instance = self.create(validated_data)
  File "/media/tspl26/D/raju_python/mobility_env/lib/python3.7/site-packages/rest_framework/serializers.py", line 939, in create
    instance = ModelClass._default_manager.create(**validated_data)
  File "/media/tspl26/D/raju_python/mobility_env/lib/python3.7/site-packages/django/db/models/manager.py", line 82, in manager_method
    return getattr(self.get_queryset(), name)(*args, **kwargs)
  File "/media/tspl26/D/raju_python/mobility_env/lib/python3.7/site-packages/django/db/models/query.py", line 413, in create
    obj.save(force_insert=True, using=self.db)
  File "/media/tspl26/D/raju_python/mobility_env/lib/python3.7/site-packages/django/db/models/base.py", line 718, in save
    force_update=force_update, update_fields=update_fields)
  File "/media/tspl26/D/raju_python/mobility_env/lib/python3.7/site-packages/django/db/models/base.py", line 748, in save_base
    updated = self._save_table(raw, cls, force_insert, force_update, using, update_fields)
  File "/media/tspl26/D/raju_python/mobility_env/lib/python3.7/site-packages/django/db/models/base.py", line 831, in _save_table
    result = self._do_insert(cls._base_manager, using, fields, update_pk, raw)
  File "/media/tspl26/D/raju_python/mobility_env/lib/python3.7/site-packages/django/db/models/base.py", line 869, in _do_insert
    using=using, raw=raw)
  File "/media/tspl26/D/raju_python/mobility_env/lib/python3.7/site-packages/django/db/models/manager.py", line 82, in manager_method
    return getattr(self.get_queryset(), name)(*args, **kwargs)
  File "/media/tspl26/D/raju_python/mobility_env/lib/python3.7/site-packages/django/db/models/query.py", line 1136, in _insert
    return query.get_compiler(using=using).execute_sql(return_id)
  File "/media/tspl26/D/raju_python/mobility_env/lib/python3.7/site-packages/django/db/models/sql/compiler.py", line 1322, in execute_sql
    cursor.execute(sql, params)
  File "/media/tspl26/D/raju_python/mobility_env/lib/python3.7/site-packages/django/db/backends/utils.py", line 100, in execute
    return super().execute(sql, params)
  File "/media/tspl26/D/raju_python/mobility_env/lib/python3.7/site-packages/django/db/backends/utils.py", line 68, in execute
    return self._execute_with_wrappers(sql, params, many=False, executor=self._execute)
  File "/media/tspl26/D/raju_python/mobility_env/lib/python3.7/site-packages/django/db/backends/utils.py", line 77, in _execute_with_wrappers
    return executor(sql, params, many, context)
  File "/media/tspl26/D/raju_python/mobility_env/lib/python3.7/site-packages/django/db/backends/utils.py", line 85, in _execute
    return self.cursor.execute(sql, params)
  File "/media/tspl26/D/raju_python/mobility_env/lib/python3.7/site-packages/django/db/utils.py", line 89, in __exit__
    raise dj_exc_value.with_traceback(traceback) from exc_value
  File "/media/tspl26/D/raju_python/mobility_env/lib/python3.7/site-packages/django/db/backends/utils.py", line 85, in _execute
    return self.cursor.execute(sql, params)
  File "/media/tspl26/D/raju_python/mobility_env/lib/python3.7/site-packages/sql_server/pyodbc/base.py", line 546, in execute
    return self.cursor.execute(sql, params)
django.db.utils.ProgrammingError: ('42000', '[42000] [Microsoft][ODBC Driver 17 for SQL Server][SQL Server]Error converting data type nvarchar to bigint. (8114) (SQLExecDirectW)')
ERROR|19/Mar/2021 10:30:20|basehttp|5005|140372072195840|"POST /vault_document_upload/ HTTP/1.1" 500 23840
ERROR|19/Mar/2021 10:33:03|log|5152|140343504430848|Internal Server Error: /vault_document_upload/
Traceback (most recent call last):
  File "/media/tspl26/D/raju_python/mobility_env/lib/python3.7/site-packages/django/db/backends/utils.py", line 85, in _execute
    return self.cursor.execute(sql, params)
  File "/media/tspl26/D/raju_python/mobility_env/lib/python3.7/site-packages/sql_server/pyodbc/base.py", line 546, in execute
    return self.cursor.execute(sql, params)
pyodbc.ProgrammingError: ('42000', '[42000] [Microsoft][ODBC Driver 17 for SQL Server][SQL Server]Error converting data type nvarchar to bigint. (8114) (SQLExecDirectW)')

The above exception was the direct cause of the following exception:

Traceback (most recent call last):
  File "/media/tspl26/D/raju_python/mobility_env/lib/python3.7/site-packages/django/core/handlers/exception.py", line 34, in inner
    response = get_response(request)
  File "/media/tspl26/D/raju_python/mobility_env/lib/python3.7/site-packages/django/core/handlers/base.py", line 126, in _get_response
    response = self.process_exception_by_middleware(e, request)
  File "/media/tspl26/D/raju_python/mobility_env/lib/python3.7/site-packages/django/core/handlers/base.py", line 124, in _get_response
    response = wrapped_callback(request, *callback_args, **callback_kwargs)
  File "/media/tspl26/D/raju_python/mobility_env/lib/python3.7/site-packages/django/views/decorators/csrf.py", line 54, in wrapped_view
    return view_func(*args, **kwargs)
  File "/media/tspl26/D/raju_python/mobility_env/lib/python3.7/site-packages/django/views/generic/base.py", line 68, in view
    return self.dispatch(request, *args, **kwargs)
  File "/media/tspl26/D/raju_python/mobility_env/lib/python3.7/site-packages/rest_framework/views.py", line 509, in dispatch
    response = self.handle_exception(exc)
  File "/media/tspl26/D/raju_python/mobility_env/lib/python3.7/site-packages/rest_framework/views.py", line 469, in handle_exception
    self.raise_uncaught_exception(exc)
  File "/media/tspl26/D/raju_python/mobility_env/lib/python3.7/site-packages/rest_framework/views.py", line 480, in raise_uncaught_exception
    raise exc
  File "/media/tspl26/D/raju_python/mobility_env/lib/python3.7/site-packages/rest_framework/views.py", line 506, in dispatch
    response = handler(request, *args, **kwargs)
  File "/media/tspl26/D/raju_python/mobility_env/mobilitysqr_live/mobility_apps/vault/views.py", line 79, in post
    serializer.save()
  File "/media/tspl26/D/raju_python/mobility_env/lib/python3.7/site-packages/rest_framework/serializers.py", line 205, in save
    self.instance = self.create(validated_data)
  File "/media/tspl26/D/raju_python/mobility_env/lib/python3.7/site-packages/rest_framework/serializers.py", line 939, in create
    instance = ModelClass._default_manager.create(**validated_data)
  File "/media/tspl26/D/raju_python/mobility_env/lib/python3.7/site-packages/django/db/models/manager.py", line 82, in manager_method
    return getattr(self.get_queryset(), name)(*args, **kwargs)
  File "/media/tspl26/D/raju_python/mobility_env/lib/python3.7/site-packages/django/db/models/query.py", line 413, in create
    obj.save(force_insert=True, using=self.db)
  File "/media/tspl26/D/raju_python/mobility_env/lib/python3.7/site-packages/django/db/models/base.py", line 718, in save
    force_update=force_update, update_fields=update_fields)
  File "/media/tspl26/D/raju_python/mobility_env/lib/python3.7/site-packages/django/db/models/base.py", line 748, in save_base
    updated = self._save_table(raw, cls, force_insert, force_update, using, update_fields)
  File "/media/tspl26/D/raju_python/mobility_env/lib/python3.7/site-packages/django/db/models/base.py", line 831, in _save_table
    result = self._do_insert(cls._base_manager, using, fields, update_pk, raw)
  File "/media/tspl26/D/raju_python/mobility_env/lib/python3.7/site-packages/django/db/models/base.py", line 869, in _do_insert
    using=using, raw=raw)
  File "/media/tspl26/D/raju_python/mobility_env/lib/python3.7/site-packages/django/db/models/manager.py", line 82, in manager_method
    return getattr(self.get_queryset(), name)(*args, **kwargs)
  File "/media/tspl26/D/raju_python/mobility_env/lib/python3.7/site-packages/django/db/models/query.py", line 1136, in _insert
    return query.get_compiler(using=using).execute_sql(return_id)
  File "/media/tspl26/D/raju_python/mobility_env/lib/python3.7/site-packages/django/db/models/sql/compiler.py", line 1322, in execute_sql
    cursor.execute(sql, params)
  File "/media/tspl26/D/raju_python/mobility_env/lib/python3.7/site-packages/django/db/backends/utils.py", line 100, in execute
    return super().execute(sql, params)
  File "/media/tspl26/D/raju_python/mobility_env/lib/python3.7/site-packages/django/db/backends/utils.py", line 68, in execute
    return self._execute_with_wrappers(sql, params, many=False, executor=self._execute)
  File "/media/tspl26/D/raju_python/mobility_env/lib/python3.7/site-packages/django/db/backends/utils.py", line 77, in _execute_with_wrappers
    return executor(sql, params, many, context)
  File "/media/tspl26/D/raju_python/mobility_env/lib/python3.7/site-packages/django/db/backends/utils.py", line 85, in _execute
    return self.cursor.execute(sql, params)
  File "/media/tspl26/D/raju_python/mobility_env/lib/python3.7/site-packages/django/db/utils.py", line 89, in __exit__
    raise dj_exc_value.with_traceback(traceback) from exc_value
  File "/media/tspl26/D/raju_python/mobility_env/lib/python3.7/site-packages/django/db/backends/utils.py", line 85, in _execute
    return self.cursor.execute(sql, params)
  File "/media/tspl26/D/raju_python/mobility_env/lib/python3.7/site-packages/sql_server/pyodbc/base.py", line 546, in execute
    return self.cursor.execute(sql, params)
django.db.utils.ProgrammingError: ('42000', '[42000] [Microsoft][ODBC Driver 17 for SQL Server][SQL Server]Error converting data type nvarchar to bigint. (8114) (SQLExecDirectW)')
ERROR|19/Mar/2021 10:33:03|basehttp|5152|140343504430848|"POST /vault_document_upload/ HTTP/1.1" 500 23840
ERROR|19/Mar/2021 10:35:09|log|5243|140360286942976|Internal Server Error: /vault_document_upload/
Traceback (most recent call last):
  File "/media/tspl26/D/raju_python/mobility_env/lib/python3.7/site-packages/django/db/backends/utils.py", line 85, in _execute
    return self.cursor.execute(sql, params)
  File "/media/tspl26/D/raju_python/mobility_env/lib/python3.7/site-packages/sql_server/pyodbc/base.py", line 546, in execute
    return self.cursor.execute(sql, params)
pyodbc.ProgrammingError: ('42000', '[42000] [Microsoft][ODBC Driver 17 for SQL Server][SQL Server]Error converting data type nvarchar to bigint. (8114) (SQLExecDirectW)')

The above exception was the direct cause of the following exception:

Traceback (most recent call last):
  File "/media/tspl26/D/raju_python/mobility_env/lib/python3.7/site-packages/django/core/handlers/exception.py", line 34, in inner
    response = get_response(request)
  File "/media/tspl26/D/raju_python/mobility_env/lib/python3.7/site-packages/django/core/handlers/base.py", line 126, in _get_response
    response = self.process_exception_by_middleware(e, request)
  File "/media/tspl26/D/raju_python/mobility_env/lib/python3.7/site-packages/django/core/handlers/base.py", line 124, in _get_response
    response = wrapped_callback(request, *callback_args, **callback_kwargs)
  File "/media/tspl26/D/raju_python/mobility_env/lib/python3.7/site-packages/django/views/decorators/csrf.py", line 54, in wrapped_view
    return view_func(*args, **kwargs)
  File "/media/tspl26/D/raju_python/mobility_env/lib/python3.7/site-packages/django/views/generic/base.py", line 68, in view
    return self.dispatch(request, *args, **kwargs)
  File "/media/tspl26/D/raju_python/mobility_env/lib/python3.7/site-packages/rest_framework/views.py", line 509, in dispatch
    response = self.handle_exception(exc)
  File "/media/tspl26/D/raju_python/mobility_env/lib/python3.7/site-packages/rest_framework/views.py", line 469, in handle_exception
    self.raise_uncaught_exception(exc)
  File "/media/tspl26/D/raju_python/mobility_env/lib/python3.7/site-packages/rest_framework/views.py", line 480, in raise_uncaught_exception
    raise exc
  File "/media/tspl26/D/raju_python/mobility_env/lib/python3.7/site-packages/rest_framework/views.py", line 506, in dispatch
    response = handler(request, *args, **kwargs)
  File "/media/tspl26/D/raju_python/mobility_env/mobilitysqr_live/mobility_apps/vault/views.py", line 79, in post
    serializer.save()
  File "/media/tspl26/D/raju_python/mobility_env/lib/python3.7/site-packages/rest_framework/serializers.py", line 205, in save
    self.instance = self.create(validated_data)
  File "/media/tspl26/D/raju_python/mobility_env/lib/python3.7/site-packages/rest_framework/serializers.py", line 939, in create
    instance = ModelClass._default_manager.create(**validated_data)
  File "/media/tspl26/D/raju_python/mobility_env/lib/python3.7/site-packages/django/db/models/manager.py", line 82, in manager_method
    return getattr(self.get_queryset(), name)(*args, **kwargs)
  File "/media/tspl26/D/raju_python/mobility_env/lib/python3.7/site-packages/django/db/models/query.py", line 413, in create
    obj.save(force_insert=True, using=self.db)
  File "/media/tspl26/D/raju_python/mobility_env/lib/python3.7/site-packages/django/db/models/base.py", line 718, in save
    force_update=force_update, update_fields=update_fields)
  File "/media/tspl26/D/raju_python/mobility_env/lib/python3.7/site-packages/django/db/models/base.py", line 748, in save_base
    updated = self._save_table(raw, cls, force_insert, force_update, using, update_fields)
  File "/media/tspl26/D/raju_python/mobility_env/lib/python3.7/site-packages/django/db/models/base.py", line 831, in _save_table
    result = self._do_insert(cls._base_manager, using, fields, update_pk, raw)
  File "/media/tspl26/D/raju_python/mobility_env/lib/python3.7/site-packages/django/db/models/base.py", line 869, in _do_insert
    using=using, raw=raw)
  File "/media/tspl26/D/raju_python/mobility_env/lib/python3.7/site-packages/django/db/models/manager.py", line 82, in manager_method
    return getattr(self.get_queryset(), name)(*args, **kwargs)
  File "/media/tspl26/D/raju_python/mobility_env/lib/python3.7/site-packages/django/db/models/query.py", line 1136, in _insert
    return query.get_compiler(using=using).execute_sql(return_id)
  File "/media/tspl26/D/raju_python/mobility_env/lib/python3.7/site-packages/django/db/models/sql/compiler.py", line 1322, in execute_sql
    cursor.execute(sql, params)
  File "/media/tspl26/D/raju_python/mobility_env/lib/python3.7/site-packages/django/db/backends/utils.py", line 100, in execute
    return super().execute(sql, params)
  File "/media/tspl26/D/raju_python/mobility_env/lib/python3.7/site-packages/django/db/backends/utils.py", line 68, in execute
    return self._execute_with_wrappers(sql, params, many=False, executor=self._execute)
  File "/media/tspl26/D/raju_python/mobility_env/lib/python3.7/site-packages/django/db/backends/utils.py", line 77, in _execute_with_wrappers
    return executor(sql, params, many, context)
  File "/media/tspl26/D/raju_python/mobility_env/lib/python3.7/site-packages/django/db/backends/utils.py", line 85, in _execute
    return self.cursor.execute(sql, params)
  File "/media/tspl26/D/raju_python/mobility_env/lib/python3.7/site-packages/django/db/utils.py", line 89, in __exit__
    raise dj_exc_value.with_traceback(traceback) from exc_value
  File "/media/tspl26/D/raju_python/mobility_env/lib/python3.7/site-packages/django/db/backends/utils.py", line 85, in _execute
    return self.cursor.execute(sql, params)
  File "/media/tspl26/D/raju_python/mobility_env/lib/python3.7/site-packages/sql_server/pyodbc/base.py", line 546, in execute
    return self.cursor.execute(sql, params)
django.db.utils.ProgrammingError: ('42000', '[42000] [Microsoft][ODBC Driver 17 for SQL Server][SQL Server]Error converting data type nvarchar to bigint. (8114) (SQLExecDirectW)')
ERROR|19/Mar/2021 10:35:09|basehttp|5243|140360286942976|"POST /vault_document_upload/ HTTP/1.1" 500 23840
ERROR|19/Mar/2021 10:42:43|log|5781|140638537078528|Internal Server Error: /vault_document_upload/
Traceback (most recent call last):
  File "/media/tspl26/D/raju_python/mobility_env/lib/python3.7/site-packages/django/db/backends/utils.py", line 85, in _execute
    return self.cursor.execute(sql, params)
  File "/media/tspl26/D/raju_python/mobility_env/lib/python3.7/site-packages/sql_server/pyodbc/base.py", line 546, in execute
    return self.cursor.execute(sql, params)
pyodbc.ProgrammingError: ('42000', '[42000] [Microsoft][ODBC Driver 17 for SQL Server][SQL Server]Error converting data type nvarchar to bigint. (8114) (SQLExecDirectW)')

The above exception was the direct cause of the following exception:

Traceback (most recent call last):
  File "/media/tspl26/D/raju_python/mobility_env/lib/python3.7/site-packages/django/core/handlers/exception.py", line 34, in inner
    response = get_response(request)
  File "/media/tspl26/D/raju_python/mobility_env/lib/python3.7/site-packages/django/core/handlers/base.py", line 126, in _get_response
    response = self.process_exception_by_middleware(e, request)
  File "/media/tspl26/D/raju_python/mobility_env/lib/python3.7/site-packages/django/core/handlers/base.py", line 124, in _get_response
    response = wrapped_callback(request, *callback_args, **callback_kwargs)
  File "/media/tspl26/D/raju_python/mobility_env/lib/python3.7/site-packages/django/views/decorators/csrf.py", line 54, in wrapped_view
    return view_func(*args, **kwargs)
  File "/media/tspl26/D/raju_python/mobility_env/lib/python3.7/site-packages/django/views/generic/base.py", line 68, in view
    return self.dispatch(request, *args, **kwargs)
  File "/media/tspl26/D/raju_python/mobility_env/lib/python3.7/site-packages/rest_framework/views.py", line 509, in dispatch
    response = self.handle_exception(exc)
  File "/media/tspl26/D/raju_python/mobility_env/lib/python3.7/site-packages/rest_framework/views.py", line 469, in handle_exception
    self.raise_uncaught_exception(exc)
  File "/media/tspl26/D/raju_python/mobility_env/lib/python3.7/site-packages/rest_framework/views.py", line 480, in raise_uncaught_exception
    raise exc
  File "/media/tspl26/D/raju_python/mobility_env/lib/python3.7/site-packages/rest_framework/views.py", line 506, in dispatch
    response = handler(request, *args, **kwargs)
  File "/media/tspl26/D/raju_python/mobility_env/mobilitysqr_live/mobility_apps/vault/views.py", line 79, in post
    serializer.save()
  File "/media/tspl26/D/raju_python/mobility_env/lib/python3.7/site-packages/rest_framework/serializers.py", line 205, in save
    self.instance = self.create(validated_data)
  File "/media/tspl26/D/raju_python/mobility_env/lib/python3.7/site-packages/rest_framework/serializers.py", line 939, in create
    instance = ModelClass._default_manager.create(**validated_data)
  File "/media/tspl26/D/raju_python/mobility_env/lib/python3.7/site-packages/django/db/models/manager.py", line 82, in manager_method
    return getattr(self.get_queryset(), name)(*args, **kwargs)
  File "/media/tspl26/D/raju_python/mobility_env/lib/python3.7/site-packages/django/db/models/query.py", line 413, in create
    obj.save(force_insert=True, using=self.db)
  File "/media/tspl26/D/raju_python/mobility_env/lib/python3.7/site-packages/django/db/models/base.py", line 718, in save
    force_update=force_update, update_fields=update_fields)
  File "/media/tspl26/D/raju_python/mobility_env/lib/python3.7/site-packages/django/db/models/base.py", line 748, in save_base
    updated = self._save_table(raw, cls, force_insert, force_update, using, update_fields)
  File "/media/tspl26/D/raju_python/mobility_env/lib/python3.7/site-packages/django/db/models/base.py", line 831, in _save_table
    result = self._do_insert(cls._base_manager, using, fields, update_pk, raw)
  File "/media/tspl26/D/raju_python/mobility_env/lib/python3.7/site-packages/django/db/models/base.py", line 869, in _do_insert
    using=using, raw=raw)
  File "/media/tspl26/D/raju_python/mobility_env/lib/python3.7/site-packages/django/db/models/manager.py", line 82, in manager_method
    return getattr(self.get_queryset(), name)(*args, **kwargs)
  File "/media/tspl26/D/raju_python/mobility_env/lib/python3.7/site-packages/django/db/models/query.py", line 1136, in _insert
    return query.get_compiler(using=using).execute_sql(return_id)
  File "/media/tspl26/D/raju_python/mobility_env/lib/python3.7/site-packages/django/db/models/sql/compiler.py", line 1322, in execute_sql
    cursor.execute(sql, params)
  File "/media/tspl26/D/raju_python/mobility_env/lib/python3.7/site-packages/django/db/backends/utils.py", line 100, in execute
    return super().execute(sql, params)
  File "/media/tspl26/D/raju_python/mobility_env/lib/python3.7/site-packages/django/db/backends/utils.py", line 68, in execute
    return self._execute_with_wrappers(sql, params, many=False, executor=self._execute)
  File "/media/tspl26/D/raju_python/mobility_env/lib/python3.7/site-packages/django/db/backends/utils.py", line 77, in _execute_with_wrappers
    return executor(sql, params, many, context)
  File "/media/tspl26/D/raju_python/mobility_env/lib/python3.7/site-packages/django/db/backends/utils.py", line 85, in _execute
    return self.cursor.execute(sql, params)
  File "/media/tspl26/D/raju_python/mobility_env/lib/python3.7/site-packages/django/db/utils.py", line 89, in __exit__
    raise dj_exc_value.with_traceback(traceback) from exc_value
  File "/media/tspl26/D/raju_python/mobility_env/lib/python3.7/site-packages/django/db/backends/utils.py", line 85, in _execute
    return self.cursor.execute(sql, params)
  File "/media/tspl26/D/raju_python/mobility_env/lib/python3.7/site-packages/sql_server/pyodbc/base.py", line 546, in execute
    return self.cursor.execute(sql, params)
django.db.utils.ProgrammingError: ('42000', '[42000] [Microsoft][ODBC Driver 17 for SQL Server][SQL Server]Error converting data type nvarchar to bigint. (8114) (SQLExecDirectW)')
ERROR|19/Mar/2021 10:42:43|basehttp|5781|140638537078528|"POST /vault_document_upload/ HTTP/1.1" 500 23840
ERROR|19/Mar/2021 10:45:22|log|6042|139730929264384|Internal Server Error: /vault_document_upload/
Traceback (most recent call last):
  File "/media/tspl26/D/raju_python/mobility_env/lib/python3.7/site-packages/django/db/backends/utils.py", line 85, in _execute
    return self.cursor.execute(sql, params)
  File "/media/tspl26/D/raju_python/mobility_env/lib/python3.7/site-packages/sql_server/pyodbc/base.py", line 546, in execute
    return self.cursor.execute(sql, params)
pyodbc.ProgrammingError: ('42000', '[42000] [Microsoft][ODBC Driver 17 for SQL Server][SQL Server]Error converting data type nvarchar to bigint. (8114) (SQLExecDirectW)')

The above exception was the direct cause of the following exception:

Traceback (most recent call last):
  File "/media/tspl26/D/raju_python/mobility_env/lib/python3.7/site-packages/django/core/handlers/exception.py", line 34, in inner
    response = get_response(request)
  File "/media/tspl26/D/raju_python/mobility_env/lib/python3.7/site-packages/django/core/handlers/base.py", line 126, in _get_response
    response = self.process_exception_by_middleware(e, request)
  File "/media/tspl26/D/raju_python/mobility_env/lib/python3.7/site-packages/django/core/handlers/base.py", line 124, in _get_response
    response = wrapped_callback(request, *callback_args, **callback_kwargs)
  File "/media/tspl26/D/raju_python/mobility_env/lib/python3.7/site-packages/django/views/decorators/csrf.py", line 54, in wrapped_view
    return view_func(*args, **kwargs)
  File "/media/tspl26/D/raju_python/mobility_env/lib/python3.7/site-packages/django/views/generic/base.py", line 68, in view
    return self.dispatch(request, *args, **kwargs)
  File "/media/tspl26/D/raju_python/mobility_env/lib/python3.7/site-packages/rest_framework/views.py", line 509, in dispatch
    response = self.handle_exception(exc)
  File "/media/tspl26/D/raju_python/mobility_env/lib/python3.7/site-packages/rest_framework/views.py", line 469, in handle_exception
    self.raise_uncaught_exception(exc)
  File "/media/tspl26/D/raju_python/mobility_env/lib/python3.7/site-packages/rest_framework/views.py", line 480, in raise_uncaught_exception
    raise exc
  File "/media/tspl26/D/raju_python/mobility_env/lib/python3.7/site-packages/rest_framework/views.py", line 506, in dispatch
    response = handler(request, *args, **kwargs)
  File "/media/tspl26/D/raju_python/mobility_env/mobilitysqr_live/mobility_apps/vault/views.py", line 79, in post
    serializer.save()
  File "/media/tspl26/D/raju_python/mobility_env/lib/python3.7/site-packages/rest_framework/serializers.py", line 205, in save
    self.instance = self.create(validated_data)
  File "/media/tspl26/D/raju_python/mobility_env/lib/python3.7/site-packages/rest_framework/serializers.py", line 939, in create
    instance = ModelClass._default_manager.create(**validated_data)
  File "/media/tspl26/D/raju_python/mobility_env/lib/python3.7/site-packages/django/db/models/manager.py", line 82, in manager_method
    return getattr(self.get_queryset(), name)(*args, **kwargs)
  File "/media/tspl26/D/raju_python/mobility_env/lib/python3.7/site-packages/django/db/models/query.py", line 413, in create
    obj.save(force_insert=True, using=self.db)
  File "/media/tspl26/D/raju_python/mobility_env/lib/python3.7/site-packages/django/db/models/base.py", line 718, in save
    force_update=force_update, update_fields=update_fields)
  File "/media/tspl26/D/raju_python/mobility_env/lib/python3.7/site-packages/django/db/models/base.py", line 748, in save_base
    updated = self._save_table(raw, cls, force_insert, force_update, using, update_fields)
  File "/media/tspl26/D/raju_python/mobility_env/lib/python3.7/site-packages/django/db/models/base.py", line 831, in _save_table
    result = self._do_insert(cls._base_manager, using, fields, update_pk, raw)
  File "/media/tspl26/D/raju_python/mobility_env/lib/python3.7/site-packages/django/db/models/base.py", line 869, in _do_insert
    using=using, raw=raw)
  File "/media/tspl26/D/raju_python/mobility_env/lib/python3.7/site-packages/django/db/models/manager.py", line 82, in manager_method
    return getattr(self.get_queryset(), name)(*args, **kwargs)
  File "/media/tspl26/D/raju_python/mobility_env/lib/python3.7/site-packages/django/db/models/query.py", line 1136, in _insert
    return query.get_compiler(using=using).execute_sql(return_id)
  File "/media/tspl26/D/raju_python/mobility_env/lib/python3.7/site-packages/django/db/models/sql/compiler.py", line 1322, in execute_sql
    cursor.execute(sql, params)
  File "/media/tspl26/D/raju_python/mobility_env/lib/python3.7/site-packages/django/db/backends/utils.py", line 100, in execute
    return super().execute(sql, params)
  File "/media/tspl26/D/raju_python/mobility_env/lib/python3.7/site-packages/django/db/backends/utils.py", line 68, in execute
    return self._execute_with_wrappers(sql, params, many=False, executor=self._execute)
  File "/media/tspl26/D/raju_python/mobility_env/lib/python3.7/site-packages/django/db/backends/utils.py", line 77, in _execute_with_wrappers
    return executor(sql, params, many, context)
  File "/media/tspl26/D/raju_python/mobility_env/lib/python3.7/site-packages/django/db/backends/utils.py", line 85, in _execute
    return self.cursor.execute(sql, params)
  File "/media/tspl26/D/raju_python/mobility_env/lib/python3.7/site-packages/django/db/utils.py", line 89, in __exit__
    raise dj_exc_value.with_traceback(traceback) from exc_value
  File "/media/tspl26/D/raju_python/mobility_env/lib/python3.7/site-packages/django/db/backends/utils.py", line 85, in _execute
    return self.cursor.execute(sql, params)
  File "/media/tspl26/D/raju_python/mobility_env/lib/python3.7/site-packages/sql_server/pyodbc/base.py", line 546, in execute
    return self.cursor.execute(sql, params)
django.db.utils.ProgrammingError: ('42000', '[42000] [Microsoft][ODBC Driver 17 for SQL Server][SQL Server]Error converting data type nvarchar to bigint. (8114) (SQLExecDirectW)')
ERROR|19/Mar/2021 10:45:22|basehttp|6042|139730929264384|"POST /vault_document_upload/ HTTP/1.1" 500 23840
ERROR|19/Mar/2021 10:45:57|log|6088|140269404772096|Internal Server Error: /vault_document_upload/
Traceback (most recent call last):
  File "/media/tspl26/D/raju_python/mobility_env/lib/python3.7/site-packages/django/db/backends/utils.py", line 85, in _execute
    return self.cursor.execute(sql, params)
  File "/media/tspl26/D/raju_python/mobility_env/lib/python3.7/site-packages/sql_server/pyodbc/base.py", line 546, in execute
    return self.cursor.execute(sql, params)
pyodbc.ProgrammingError: ('42000', '[42000] [Microsoft][ODBC Driver 17 for SQL Server][SQL Server]Error converting data type nvarchar to bigint. (8114) (SQLExecDirectW)')

The above exception was the direct cause of the following exception:

Traceback (most recent call last):
  File "/media/tspl26/D/raju_python/mobility_env/lib/python3.7/site-packages/django/core/handlers/exception.py", line 34, in inner
    response = get_response(request)
  File "/media/tspl26/D/raju_python/mobility_env/lib/python3.7/site-packages/django/core/handlers/base.py", line 126, in _get_response
    response = self.process_exception_by_middleware(e, request)
  File "/media/tspl26/D/raju_python/mobility_env/lib/python3.7/site-packages/django/core/handlers/base.py", line 124, in _get_response
    response = wrapped_callback(request, *callback_args, **callback_kwargs)
  File "/media/tspl26/D/raju_python/mobility_env/lib/python3.7/site-packages/django/views/decorators/csrf.py", line 54, in wrapped_view
    return view_func(*args, **kwargs)
  File "/media/tspl26/D/raju_python/mobility_env/lib/python3.7/site-packages/django/views/generic/base.py", line 68, in view
    return self.dispatch(request, *args, **kwargs)
  File "/media/tspl26/D/raju_python/mobility_env/lib/python3.7/site-packages/rest_framework/views.py", line 509, in dispatch
    response = self.handle_exception(exc)
  File "/media/tspl26/D/raju_python/mobility_env/lib/python3.7/site-packages/rest_framework/views.py", line 469, in handle_exception
    self.raise_uncaught_exception(exc)
  File "/media/tspl26/D/raju_python/mobility_env/lib/python3.7/site-packages/rest_framework/views.py", line 480, in raise_uncaught_exception
    raise exc
  File "/media/tspl26/D/raju_python/mobility_env/lib/python3.7/site-packages/rest_framework/views.py", line 506, in dispatch
    response = handler(request, *args, **kwargs)
  File "/media/tspl26/D/raju_python/mobility_env/mobilitysqr_live/mobility_apps/vault/views.py", line 79, in post
    serializer.save()
  File "/media/tspl26/D/raju_python/mobility_env/lib/python3.7/site-packages/rest_framework/serializers.py", line 205, in save
    self.instance = self.create(validated_data)
  File "/media/tspl26/D/raju_python/mobility_env/lib/python3.7/site-packages/rest_framework/serializers.py", line 939, in create
    instance = ModelClass._default_manager.create(**validated_data)
  File "/media/tspl26/D/raju_python/mobility_env/lib/python3.7/site-packages/django/db/models/manager.py", line 82, in manager_method
    return getattr(self.get_queryset(), name)(*args, **kwargs)
  File "/media/tspl26/D/raju_python/mobility_env/lib/python3.7/site-packages/django/db/models/query.py", line 413, in create
    obj.save(force_insert=True, using=self.db)
  File "/media/tspl26/D/raju_python/mobility_env/lib/python3.7/site-packages/django/db/models/base.py", line 718, in save
    force_update=force_update, update_fields=update_fields)
  File "/media/tspl26/D/raju_python/mobility_env/lib/python3.7/site-packages/django/db/models/base.py", line 748, in save_base
    updated = self._save_table(raw, cls, force_insert, force_update, using, update_fields)
  File "/media/tspl26/D/raju_python/mobility_env/lib/python3.7/site-packages/django/db/models/base.py", line 831, in _save_table
    result = self._do_insert(cls._base_manager, using, fields, update_pk, raw)
  File "/media/tspl26/D/raju_python/mobility_env/lib/python3.7/site-packages/django/db/models/base.py", line 869, in _do_insert
    using=using, raw=raw)
  File "/media/tspl26/D/raju_python/mobility_env/lib/python3.7/site-packages/django/db/models/manager.py", line 82, in manager_method
    return getattr(self.get_queryset(), name)(*args, **kwargs)
  File "/media/tspl26/D/raju_python/mobility_env/lib/python3.7/site-packages/django/db/models/query.py", line 1136, in _insert
    return query.get_compiler(using=using).execute_sql(return_id)
  File "/media/tspl26/D/raju_python/mobility_env/lib/python3.7/site-packages/django/db/models/sql/compiler.py", line 1322, in execute_sql
    cursor.execute(sql, params)
  File "/media/tspl26/D/raju_python/mobility_env/lib/python3.7/site-packages/django/db/backends/utils.py", line 100, in execute
    return super().execute(sql, params)
  File "/media/tspl26/D/raju_python/mobility_env/lib/python3.7/site-packages/django/db/backends/utils.py", line 68, in execute
    return self._execute_with_wrappers(sql, params, many=False, executor=self._execute)
  File "/media/tspl26/D/raju_python/mobility_env/lib/python3.7/site-packages/django/db/backends/utils.py", line 77, in _execute_with_wrappers
    return executor(sql, params, many, context)
  File "/media/tspl26/D/raju_python/mobility_env/lib/python3.7/site-packages/django/db/backends/utils.py", line 85, in _execute
    return self.cursor.execute(sql, params)
  File "/media/tspl26/D/raju_python/mobility_env/lib/python3.7/site-packages/django/db/utils.py", line 89, in __exit__
    raise dj_exc_value.with_traceback(traceback) from exc_value
  File "/media/tspl26/D/raju_python/mobility_env/lib/python3.7/site-packages/django/db/backends/utils.py", line 85, in _execute
    return self.cursor.execute(sql, params)
  File "/media/tspl26/D/raju_python/mobility_env/lib/python3.7/site-packages/sql_server/pyodbc/base.py", line 546, in execute
    return self.cursor.execute(sql, params)
django.db.utils.ProgrammingError: ('42000', '[42000] [Microsoft][ODBC Driver 17 for SQL Server][SQL Server]Error converting data type nvarchar to bigint. (8114) (SQLExecDirectW)')
ERROR|19/Mar/2021 10:45:57|basehttp|6088|140269404772096|"POST /vault_document_upload/ HTTP/1.1" 500 23840
WARNING|19/Mar/2021 11:09:10|log|7212|140455437657856|Unauthorized: /get_post_vault_type/
WARNING|19/Mar/2021 11:09:10|basehttp|7212|140455437657856|"POST /get_post_vault_type/ HTTP/1.1" 401 183
INFO|19/Mar/2021 11:09:18|basehttp|7212|140455437657856|"POST /api/custom/login/ HTTP/1.1" 200 452
INFO|19/Mar/2021 11:09:45|basehttp|7212|140455437657856|"POST /get_post_vault_type/ HTTP/1.1" 200 275
INFO|19/Mar/2021 11:10:08|basehttp|7212|140455437657856|"POST /get_post_vault_type/ HTTP/1.1" 200 273
INFO|19/Mar/2021 11:10:30|basehttp|7212|140455437657856|"POST /get_post_vault_type/ HTTP/1.1" 200 271
INFO|19/Mar/2021 11:10:49|basehttp|7212|140455437657856|"POST /get_post_vault_type/ HTTP/1.1" 200 272
INFO|19/Mar/2021 11:11:05|basehttp|7212|140455437657856|"POST /get_post_vault_type/ HTTP/1.1" 200 276
INFO|19/Mar/2021 11:12:24|basehttp|7212|140455437657856|"POST /vault_document_upload/ HTTP/1.1" 200 357
INFO|19/Mar/2021 11:15:33|basehttp|7572|139750017378048|"POST /vault_document_upload/ HTTP/1.1" 200 365
INFO|19/Mar/2021 12:01:04|basehttp|9015|139687671932672|"POST /api/custom/login/ HTTP/1.1" 200 452
INFO|19/Mar/2021 12:01:27|basehttp|9015|139687671932672|"GET /get_post_vault_document/?emp_code=Tspl1045 HTTP/1.1" 200 679
WARNING|19/Mar/2021 12:02:24|log|9015|139687671932672|Not Found: /vault_document_upload/
WARNING|19/Mar/2021 12:02:24|basehttp|9015|139687671932672|"POST /vault_document_upload/ HTTP/1.1" 404 50951
ERROR|19/Mar/2021 12:02:40|log|9015|139687671932672|Internal Server Error: /get_post_vault_document/
Traceback (most recent call last):
  File "/media/tspl26/D/raju_python/mobility_env/lib/python3.7/site-packages/django/utils/datastructures.py", line 77, in __getitem__
    list_ = super().__getitem__(key)
KeyError: 'document_url'

During handling of the above exception, another exception occurred:

Traceback (most recent call last):
  File "/media/tspl26/D/raju_python/mobility_env/lib/python3.7/site-packages/django/core/handlers/exception.py", line 34, in inner
    response = get_response(request)
  File "/media/tspl26/D/raju_python/mobility_env/lib/python3.7/site-packages/django/core/handlers/base.py", line 126, in _get_response
    response = self.process_exception_by_middleware(e, request)
  File "/media/tspl26/D/raju_python/mobility_env/lib/python3.7/site-packages/django/core/handlers/base.py", line 124, in _get_response
    response = wrapped_callback(request, *callback_args, **callback_kwargs)
  File "/media/tspl26/D/raju_python/mobility_env/lib/python3.7/site-packages/django/views/decorators/csrf.py", line 54, in wrapped_view
    return view_func(*args, **kwargs)
  File "/media/tspl26/D/raju_python/mobility_env/lib/python3.7/site-packages/django/views/generic/base.py", line 68, in view
    return self.dispatch(request, *args, **kwargs)
  File "/media/tspl26/D/raju_python/mobility_env/lib/python3.7/site-packages/rest_framework/views.py", line 509, in dispatch
    response = self.handle_exception(exc)
  File "/media/tspl26/D/raju_python/mobility_env/lib/python3.7/site-packages/rest_framework/views.py", line 469, in handle_exception
    self.raise_uncaught_exception(exc)
  File "/media/tspl26/D/raju_python/mobility_env/lib/python3.7/site-packages/rest_framework/views.py", line 480, in raise_uncaught_exception
    raise exc
  File "/media/tspl26/D/raju_python/mobility_env/lib/python3.7/site-packages/rest_framework/views.py", line 506, in dispatch
    response = handler(request, *args, **kwargs)
  File "/media/tspl26/D/raju_python/mobility_env/mobilitysqr_live/mobility_apps/vault/views.py", line 56, in post
    file = request.FILES['document_url']
  File "/media/tspl26/D/raju_python/mobility_env/lib/python3.7/site-packages/django/utils/datastructures.py", line 79, in __getitem__
    raise MultiValueDictKeyError(key)
django.utils.datastructures.MultiValueDictKeyError: 'document_url'
ERROR|19/Mar/2021 12:02:40|basehttp|9015|139687671932672|"POST /get_post_vault_document/ HTTP/1.1" 500 20011
INFO|19/Mar/2021 12:17:23|basehttp|10046|140535852123904|"GET /get_post_vault_document/?emp_code=Tspl1045 HTTP/1.1" 200 679
WARNING|19/Mar/2021 12:17:27|log|10046|140535852123904|Unauthorized: /get_post_vault_document/
WARNING|19/Mar/2021 12:17:27|basehttp|10046|140535852123904|"POST /get_post_vault_document/ HTTP/1.1" 401 183
INFO|19/Mar/2021 12:17:34|basehttp|10046|140535852123904|"POST /api/custom/login/ HTTP/1.1" 200 452
ERROR|19/Mar/2021 12:17:48|log|10046|140535852123904|Internal Server Error: /get_post_vault_document/
Traceback (most recent call last):
  File "/media/tspl26/D/raju_python/mobility_env/lib/python3.7/site-packages/django/utils/datastructures.py", line 77, in __getitem__
    list_ = super().__getitem__(key)
KeyError: 'document_url'

During handling of the above exception, another exception occurred:

Traceback (most recent call last):
  File "/media/tspl26/D/raju_python/mobility_env/lib/python3.7/site-packages/django/core/handlers/exception.py", line 34, in inner
    response = get_response(request)
  File "/media/tspl26/D/raju_python/mobility_env/lib/python3.7/site-packages/django/core/handlers/base.py", line 126, in _get_response
    response = self.process_exception_by_middleware(e, request)
  File "/media/tspl26/D/raju_python/mobility_env/lib/python3.7/site-packages/django/core/handlers/base.py", line 124, in _get_response
    response = wrapped_callback(request, *callback_args, **callback_kwargs)
  File "/media/tspl26/D/raju_python/mobility_env/lib/python3.7/site-packages/django/views/decorators/csrf.py", line 54, in wrapped_view
    return view_func(*args, **kwargs)
  File "/media/tspl26/D/raju_python/mobility_env/lib/python3.7/site-packages/django/views/generic/base.py", line 68, in view
    return self.dispatch(request, *args, **kwargs)
  File "/media/tspl26/D/raju_python/mobility_env/lib/python3.7/site-packages/rest_framework/views.py", line 509, in dispatch
    response = self.handle_exception(exc)
  File "/media/tspl26/D/raju_python/mobility_env/lib/python3.7/site-packages/rest_framework/views.py", line 469, in handle_exception
    self.raise_uncaught_exception(exc)
  File "/media/tspl26/D/raju_python/mobility_env/lib/python3.7/site-packages/rest_framework/views.py", line 480, in raise_uncaught_exception
    raise exc
  File "/media/tspl26/D/raju_python/mobility_env/lib/python3.7/site-packages/rest_framework/views.py", line 506, in dispatch
    response = handler(request, *args, **kwargs)
  File "/media/tspl26/D/raju_python/mobility_env/mobilitysqr_live/mobility_apps/vault/views.py", line 56, in post
    file = request.FILES['document_url']
  File "/media/tspl26/D/raju_python/mobility_env/lib/python3.7/site-packages/django/utils/datastructures.py", line 79, in __getitem__
    raise MultiValueDictKeyError(key)
django.utils.datastructures.MultiValueDictKeyError: 'document_url'
ERROR|19/Mar/2021 12:17:48|basehttp|10046|140535852123904|"POST /get_post_vault_document/ HTTP/1.1" 500 20011
ERROR|19/Mar/2021 12:19:06|log|10159|140405014255360|Internal Server Error: /get_post_vault_document/
Traceback (most recent call last):
  File "/media/tspl26/D/raju_python/mobility_env/lib/python3.7/site-packages/django/utils/datastructures.py", line 77, in __getitem__
    list_ = super().__getitem__(key)
KeyError: 'document_url'

During handling of the above exception, another exception occurred:

Traceback (most recent call last):
  File "/media/tspl26/D/raju_python/mobility_env/lib/python3.7/site-packages/django/core/handlers/exception.py", line 34, in inner
    response = get_response(request)
  File "/media/tspl26/D/raju_python/mobility_env/lib/python3.7/site-packages/django/core/handlers/base.py", line 126, in _get_response
    response = self.process_exception_by_middleware(e, request)
  File "/media/tspl26/D/raju_python/mobility_env/lib/python3.7/site-packages/django/core/handlers/base.py", line 124, in _get_response
    response = wrapped_callback(request, *callback_args, **callback_kwargs)
  File "/media/tspl26/D/raju_python/mobility_env/lib/python3.7/site-packages/django/views/decorators/csrf.py", line 54, in wrapped_view
    return view_func(*args, **kwargs)
  File "/media/tspl26/D/raju_python/mobility_env/lib/python3.7/site-packages/django/views/generic/base.py", line 68, in view
    return self.dispatch(request, *args, **kwargs)
  File "/media/tspl26/D/raju_python/mobility_env/lib/python3.7/site-packages/rest_framework/views.py", line 509, in dispatch
    response = self.handle_exception(exc)
  File "/media/tspl26/D/raju_python/mobility_env/lib/python3.7/site-packages/rest_framework/views.py", line 469, in handle_exception
    self.raise_uncaught_exception(exc)
  File "/media/tspl26/D/raju_python/mobility_env/lib/python3.7/site-packages/rest_framework/views.py", line 480, in raise_uncaught_exception
    raise exc
  File "/media/tspl26/D/raju_python/mobility_env/lib/python3.7/site-packages/rest_framework/views.py", line 506, in dispatch
    response = handler(request, *args, **kwargs)
  File "/media/tspl26/D/raju_python/mobility_env/mobilitysqr_live/mobility_apps/vault/views.py", line 56, in post
    file = request.FILES['document_url']
  File "/media/tspl26/D/raju_python/mobility_env/lib/python3.7/site-packages/django/utils/datastructures.py", line 79, in __getitem__
    raise MultiValueDictKeyError(key)
django.utils.datastructures.MultiValueDictKeyError: 'document_url'
ERROR|19/Mar/2021 12:19:06|basehttp|10159|140405014255360|"POST /get_post_vault_document/ HTTP/1.1" 500 20011
INFO|19/Mar/2021 12:20:04|basehttp|10212|140378902357760|"POST /get_post_vault_document/ HTTP/1.1" 200 83
INFO|19/Mar/2021 12:20:41|basehttp|10253|140323678312192|"POST /get_post_vault_document/ HTTP/1.1" 200 82
INFO|19/Mar/2021 12:21:14|basehttp|10253|140323678312192|"POST /get_post_vault_document/ HTTP/1.1" 200 82
WARNING|19/Mar/2021 12:22:15|log|10325|140328955496192|Bad Request: /get_post_vault_document/
WARNING|19/Mar/2021 12:22:15|basehttp|10325|140328955496192|"POST /get_post_vault_document/ HTTP/1.1" 400 67
INFO|19/Mar/2021 12:24:51|basehttp|10325|140328955496192|"GET /get_post_vault_document/?emp_code=Tspl1045 HTTP/1.1" 200 679
ERROR|19/Mar/2021 12:26:32|log|10452|139956299228928|Internal Server Error: /get_post_vault_document/
Traceback (most recent call last):
  File "/media/tspl26/D/raju_python/mobility_env/lib/python3.7/site-packages/django/db/backends/utils.py", line 85, in _execute
    return self.cursor.execute(sql, params)
  File "/media/tspl26/D/raju_python/mobility_env/lib/python3.7/site-packages/sql_server/pyodbc/base.py", line 546, in execute
    return self.cursor.execute(sql, params)
pyodbc.IntegrityError: ('23000', "[23000] [Microsoft][ODBC Driver 17 for SQL Server][SQL Server]Violation of UNIQUE KEY constraint 'UQ__vault_va__15006814E550CA39'. Cannot insert duplicate key in object 'dbo.vault_vault_type_info'. The duplicate key value is (testsacsacas). (2627) (SQLExecDirectW)")

The above exception was the direct cause of the following exception:

Traceback (most recent call last):
  File "/media/tspl26/D/raju_python/mobility_env/lib/python3.7/site-packages/django/core/handlers/exception.py", line 34, in inner
    response = get_response(request)
  File "/media/tspl26/D/raju_python/mobility_env/lib/python3.7/site-packages/django/core/handlers/base.py", line 126, in _get_response
    response = self.process_exception_by_middleware(e, request)
  File "/media/tspl26/D/raju_python/mobility_env/lib/python3.7/site-packages/django/core/handlers/base.py", line 124, in _get_response
    response = wrapped_callback(request, *callback_args, **callback_kwargs)
  File "/media/tspl26/D/raju_python/mobility_env/lib/python3.7/site-packages/django/views/decorators/csrf.py", line 54, in wrapped_view
    return view_func(*args, **kwargs)
  File "/media/tspl26/D/raju_python/mobility_env/lib/python3.7/site-packages/django/views/generic/base.py", line 68, in view
    return self.dispatch(request, *args, **kwargs)
  File "/media/tspl26/D/raju_python/mobility_env/lib/python3.7/site-packages/rest_framework/views.py", line 509, in dispatch
    response = self.handle_exception(exc)
  File "/media/tspl26/D/raju_python/mobility_env/lib/python3.7/site-packages/rest_framework/views.py", line 469, in handle_exception
    self.raise_uncaught_exception(exc)
  File "/media/tspl26/D/raju_python/mobility_env/lib/python3.7/site-packages/rest_framework/views.py", line 480, in raise_uncaught_exception
    raise exc
  File "/media/tspl26/D/raju_python/mobility_env/lib/python3.7/site-packages/rest_framework/views.py", line 506, in dispatch
    response = handler(request, *args, **kwargs)
  File "/media/tspl26/D/raju_python/mobility_env/mobilitysqr_live/mobility_apps/vault/views.py", line 78, in post
    serializer.save()
  File "/media/tspl26/D/raju_python/mobility_env/lib/python3.7/site-packages/rest_framework/serializers.py", line 205, in save
    self.instance = self.create(validated_data)
  File "/media/tspl26/D/raju_python/mobility_env/lib/python3.7/site-packages/rest_framework/serializers.py", line 939, in create
    instance = ModelClass._default_manager.create(**validated_data)
  File "/media/tspl26/D/raju_python/mobility_env/lib/python3.7/site-packages/django/db/models/manager.py", line 82, in manager_method
    return getattr(self.get_queryset(), name)(*args, **kwargs)
  File "/media/tspl26/D/raju_python/mobility_env/lib/python3.7/site-packages/django/db/models/query.py", line 413, in create
    obj.save(force_insert=True, using=self.db)
  File "/media/tspl26/D/raju_python/mobility_env/lib/python3.7/site-packages/django/db/models/base.py", line 718, in save
    force_update=force_update, update_fields=update_fields)
  File "/media/tspl26/D/raju_python/mobility_env/lib/python3.7/site-packages/django/db/models/base.py", line 748, in save_base
    updated = self._save_table(raw, cls, force_insert, force_update, using, update_fields)
  File "/media/tspl26/D/raju_python/mobility_env/lib/python3.7/site-packages/django/db/models/base.py", line 831, in _save_table
    result = self._do_insert(cls._base_manager, using, fields, update_pk, raw)
  File "/media/tspl26/D/raju_python/mobility_env/lib/python3.7/site-packages/django/db/models/base.py", line 869, in _do_insert
    using=using, raw=raw)
  File "/media/tspl26/D/raju_python/mobility_env/lib/python3.7/site-packages/django/db/models/manager.py", line 82, in manager_method
    return getattr(self.get_queryset(), name)(*args, **kwargs)
  File "/media/tspl26/D/raju_python/mobility_env/lib/python3.7/site-packages/django/db/models/query.py", line 1136, in _insert
    return query.get_compiler(using=using).execute_sql(return_id)
  File "/media/tspl26/D/raju_python/mobility_env/lib/python3.7/site-packages/django/db/models/sql/compiler.py", line 1322, in execute_sql
    cursor.execute(sql, params)
  File "/media/tspl26/D/raju_python/mobility_env/lib/python3.7/site-packages/django/db/backends/utils.py", line 100, in execute
    return super().execute(sql, params)
  File "/media/tspl26/D/raju_python/mobility_env/lib/python3.7/site-packages/django/db/backends/utils.py", line 68, in execute
    return self._execute_with_wrappers(sql, params, many=False, executor=self._execute)
  File "/media/tspl26/D/raju_python/mobility_env/lib/python3.7/site-packages/django/db/backends/utils.py", line 77, in _execute_with_wrappers
    return executor(sql, params, many, context)
  File "/media/tspl26/D/raju_python/mobility_env/lib/python3.7/site-packages/django/db/backends/utils.py", line 85, in _execute
    return self.cursor.execute(sql, params)
  File "/media/tspl26/D/raju_python/mobility_env/lib/python3.7/site-packages/django/db/utils.py", line 89, in __exit__
    raise dj_exc_value.with_traceback(traceback) from exc_value
  File "/media/tspl26/D/raju_python/mobility_env/lib/python3.7/site-packages/django/db/backends/utils.py", line 85, in _execute
    return self.cursor.execute(sql, params)
  File "/media/tspl26/D/raju_python/mobility_env/lib/python3.7/site-packages/sql_server/pyodbc/base.py", line 546, in execute
    return self.cursor.execute(sql, params)
django.db.utils.IntegrityError: ('23000', "[23000] [Microsoft][ODBC Driver 17 for SQL Server][SQL Server]Violation of UNIQUE KEY constraint 'UQ__vault_va__15006814E550CA39'. Cannot insert duplicate key in object 'dbo.vault_vault_type_info'. The duplicate key value is (testsacsacas). (2627) (SQLExecDirectW)")
ERROR|19/Mar/2021 12:26:32|basehttp|10452|139956299228928|"POST /get_post_vault_document/ HTTP/1.1" 500 24246
INFO|19/Mar/2021 12:29:52|basehttp|10597|140386349827840|"POST /get_post_vault_document/ HTTP/1.1" 200 364
INFO|19/Mar/2021 12:30:07|basehttp|10597|140386349827840|"POST /get_post_vault_document/ HTTP/1.1" 200 364
INFO|19/Mar/2021 12:30:26|basehttp|10597|140386349827840|"POST /get_post_vault_document/ HTTP/1.1" 200 364
INFO|19/Mar/2021 12:32:09|basehttp|10597|140386349827840|"GET /get_post_vault_document/?emp_code=Tspl1045 HTTP/1.1" 200 1636
INFO|19/Mar/2021 12:40:37|basehttp|10987|139881716864768|"GET /get_post_vault_document/?emp_code=Tspl1045 HTTP/1.1" 200 1636
ERROR|19/Mar/2021 12:50:26|log|11278|139641567794944|Internal Server Error: /get_post_vault_document/
Traceback (most recent call last):
  File "/media/tspl26/D/raju_python/mobility_env/lib/python3.7/site-packages/django/core/handlers/exception.py", line 34, in inner
    response = get_response(request)
  File "/media/tspl26/D/raju_python/mobility_env/lib/python3.7/site-packages/django/core/handlers/base.py", line 126, in _get_response
    response = self.process_exception_by_middleware(e, request)
  File "/media/tspl26/D/raju_python/mobility_env/lib/python3.7/site-packages/django/core/handlers/base.py", line 124, in _get_response
    response = wrapped_callback(request, *callback_args, **callback_kwargs)
  File "/media/tspl26/D/raju_python/mobility_env/lib/python3.7/site-packages/django/views/decorators/csrf.py", line 54, in wrapped_view
    return view_func(*args, **kwargs)
  File "/media/tspl26/D/raju_python/mobility_env/lib/python3.7/site-packages/django/views/generic/base.py", line 68, in view
    return self.dispatch(request, *args, **kwargs)
  File "/media/tspl26/D/raju_python/mobility_env/lib/python3.7/site-packages/rest_framework/views.py", line 509, in dispatch
    response = self.handle_exception(exc)
  File "/media/tspl26/D/raju_python/mobility_env/lib/python3.7/site-packages/rest_framework/views.py", line 469, in handle_exception
    self.raise_uncaught_exception(exc)
  File "/media/tspl26/D/raju_python/mobility_env/lib/python3.7/site-packages/rest_framework/views.py", line 480, in raise_uncaught_exception
    raise exc
  File "/media/tspl26/D/raju_python/mobility_env/lib/python3.7/site-packages/rest_framework/views.py", line 506, in dispatch
    response = handler(request, *args, **kwargs)
  File "/media/tspl26/D/raju_python/mobility_env/mobilitysqr_live/mobility_apps/vault/views.py", line 103, in get
    dict = {'massage': 'data found', 'status': True, 'data': serializer.data}
  File "/media/tspl26/D/raju_python/mobility_env/lib/python3.7/site-packages/rest_framework/serializers.py", line 745, in data
    ret = super().data
  File "/media/tspl26/D/raju_python/mobility_env/lib/python3.7/site-packages/rest_framework/serializers.py", line 246, in data
    self._data = self.to_representation(self.instance)
  File "/media/tspl26/D/raju_python/mobility_env/lib/python3.7/site-packages/rest_framework/serializers.py", line 664, in to_representation
    self.child.to_representation(item) for item in iterable
  File "/media/tspl26/D/raju_python/mobility_env/lib/python3.7/site-packages/rest_framework/serializers.py", line 664, in <listcomp>
    self.child.to_representation(item) for item in iterable
  File "/media/tspl26/D/raju_python/mobility_env/lib/python3.7/site-packages/rest_framework/serializers.py", line 515, in to_representation
    ret[field.field_name] = field.to_representation(attribute)
  File "/media/tspl26/D/raju_python/mobility_env/lib/python3.7/site-packages/rest_framework/relations.py", line 467, in to_representation
    return getattr(obj, self.slug_field)
AttributeError: 'str' object has no attribute 'vault_id'
ERROR|19/Mar/2021 12:50:26|basehttp|11278|139641567794944|"GET /get_post_vault_document/?emp_code=Tspl1045 HTTP/1.1" 500 20676
ERROR|19/Mar/2021 12:53:51|log|11433|140158955800320|Internal Server Error: /get_post_vault_document/
Traceback (most recent call last):
  File "/media/tspl26/D/raju_python/mobility_env/lib/python3.7/site-packages/django/core/handlers/exception.py", line 34, in inner
    response = get_response(request)
  File "/media/tspl26/D/raju_python/mobility_env/lib/python3.7/site-packages/django/core/handlers/base.py", line 126, in _get_response
    response = self.process_exception_by_middleware(e, request)
  File "/media/tspl26/D/raju_python/mobility_env/lib/python3.7/site-packages/django/core/handlers/base.py", line 124, in _get_response
    response = wrapped_callback(request, *callback_args, **callback_kwargs)
  File "/media/tspl26/D/raju_python/mobility_env/lib/python3.7/site-packages/django/views/decorators/csrf.py", line 54, in wrapped_view
    return view_func(*args, **kwargs)
  File "/media/tspl26/D/raju_python/mobility_env/lib/python3.7/site-packages/django/views/generic/base.py", line 68, in view
    return self.dispatch(request, *args, **kwargs)
  File "/media/tspl26/D/raju_python/mobility_env/lib/python3.7/site-packages/rest_framework/views.py", line 509, in dispatch
    response = self.handle_exception(exc)
  File "/media/tspl26/D/raju_python/mobility_env/lib/python3.7/site-packages/rest_framework/views.py", line 469, in handle_exception
    self.raise_uncaught_exception(exc)
  File "/media/tspl26/D/raju_python/mobility_env/lib/python3.7/site-packages/rest_framework/views.py", line 480, in raise_uncaught_exception
    raise exc
  File "/media/tspl26/D/raju_python/mobility_env/lib/python3.7/site-packages/rest_framework/views.py", line 506, in dispatch
    response = handler(request, *args, **kwargs)
  File "/media/tspl26/D/raju_python/mobility_env/mobilitysqr_live/mobility_apps/vault/views.py", line 103, in get
    dict = {'massage': 'data found', 'status': True, 'data': serializer.data}
  File "/media/tspl26/D/raju_python/mobility_env/lib/python3.7/site-packages/rest_framework/serializers.py", line 745, in data
    ret = super().data
  File "/media/tspl26/D/raju_python/mobility_env/lib/python3.7/site-packages/rest_framework/serializers.py", line 246, in data
    self._data = self.to_representation(self.instance)
  File "/media/tspl26/D/raju_python/mobility_env/lib/python3.7/site-packages/rest_framework/serializers.py", line 664, in to_representation
    self.child.to_representation(item) for item in iterable
  File "/media/tspl26/D/raju_python/mobility_env/lib/python3.7/site-packages/rest_framework/serializers.py", line 664, in <listcomp>
    self.child.to_representation(item) for item in iterable
  File "/media/tspl26/D/raju_python/mobility_env/lib/python3.7/site-packages/rest_framework/serializers.py", line 515, in to_representation
    ret[field.field_name] = field.to_representation(attribute)
  File "/media/tspl26/D/raju_python/mobility_env/lib/python3.7/site-packages/rest_framework/relations.py", line 467, in to_representation
    return getattr(obj, self.slug_field)
AttributeError: 'str' object has no attribute 'vault_id'
ERROR|19/Mar/2021 12:53:51|basehttp|11433|140158955800320|"GET /get_post_vault_document/?emp_code=Tspl1045 HTTP/1.1" 500 20676
ERROR|19/Mar/2021 12:55:51|log|11552|140336269616896|Internal Server Error: /get_post_vault_document/
Traceback (most recent call last):
  File "/media/tspl26/D/raju_python/mobility_env/lib/python3.7/site-packages/django/core/handlers/exception.py", line 34, in inner
    response = get_response(request)
  File "/media/tspl26/D/raju_python/mobility_env/lib/python3.7/site-packages/django/core/handlers/base.py", line 126, in _get_response
    response = self.process_exception_by_middleware(e, request)
  File "/media/tspl26/D/raju_python/mobility_env/lib/python3.7/site-packages/django/core/handlers/base.py", line 124, in _get_response
    response = wrapped_callback(request, *callback_args, **callback_kwargs)
  File "/media/tspl26/D/raju_python/mobility_env/lib/python3.7/site-packages/django/views/decorators/csrf.py", line 54, in wrapped_view
    return view_func(*args, **kwargs)
  File "/media/tspl26/D/raju_python/mobility_env/lib/python3.7/site-packages/django/views/generic/base.py", line 68, in view
    return self.dispatch(request, *args, **kwargs)
  File "/media/tspl26/D/raju_python/mobility_env/lib/python3.7/site-packages/rest_framework/views.py", line 509, in dispatch
    response = self.handle_exception(exc)
  File "/media/tspl26/D/raju_python/mobility_env/lib/python3.7/site-packages/rest_framework/views.py", line 469, in handle_exception
    self.raise_uncaught_exception(exc)
  File "/media/tspl26/D/raju_python/mobility_env/lib/python3.7/site-packages/rest_framework/views.py", line 480, in raise_uncaught_exception
    raise exc
  File "/media/tspl26/D/raju_python/mobility_env/lib/python3.7/site-packages/rest_framework/views.py", line 506, in dispatch
    response = handler(request, *args, **kwargs)
  File "/media/tspl26/D/raju_python/mobility_env/mobilitysqr_live/mobility_apps/vault/views.py", line 103, in get
    dict = {'massage': 'data found', 'status': True, 'data': serializer.data}
  File "/media/tspl26/D/raju_python/mobility_env/lib/python3.7/site-packages/rest_framework/serializers.py", line 745, in data
    ret = super().data
  File "/media/tspl26/D/raju_python/mobility_env/lib/python3.7/site-packages/rest_framework/serializers.py", line 246, in data
    self._data = self.to_representation(self.instance)
  File "/media/tspl26/D/raju_python/mobility_env/lib/python3.7/site-packages/rest_framework/serializers.py", line 664, in to_representation
    self.child.to_representation(item) for item in iterable
  File "/media/tspl26/D/raju_python/mobility_env/lib/python3.7/site-packages/rest_framework/serializers.py", line 664, in <listcomp>
    self.child.to_representation(item) for item in iterable
  File "/media/tspl26/D/raju_python/mobility_env/lib/python3.7/site-packages/rest_framework/serializers.py", line 515, in to_representation
    ret[field.field_name] = field.to_representation(attribute)
  File "/media/tspl26/D/raju_python/mobility_env/lib/python3.7/site-packages/rest_framework/relations.py", line 467, in to_representation
    return getattr(obj, self.slug_field)
AttributeError: 'str' object has no attribute 'vault_id'
ERROR|19/Mar/2021 12:55:51|basehttp|11552|140336269616896|"GET /get_post_vault_document/?emp_code=Tspl1045 HTTP/1.1" 500 20676
ERROR|19/Mar/2021 12:56:43|log|11604|139779018221312|Internal Server Error: /get_post_vault_document/
Traceback (most recent call last):
  File "/media/tspl26/D/raju_python/mobility_env/lib/python3.7/site-packages/django/core/handlers/exception.py", line 34, in inner
    response = get_response(request)
  File "/media/tspl26/D/raju_python/mobility_env/lib/python3.7/site-packages/django/core/handlers/base.py", line 126, in _get_response
    response = self.process_exception_by_middleware(e, request)
  File "/media/tspl26/D/raju_python/mobility_env/lib/python3.7/site-packages/django/core/handlers/base.py", line 124, in _get_response
    response = wrapped_callback(request, *callback_args, **callback_kwargs)
  File "/media/tspl26/D/raju_python/mobility_env/lib/python3.7/site-packages/django/views/decorators/csrf.py", line 54, in wrapped_view
    return view_func(*args, **kwargs)
  File "/media/tspl26/D/raju_python/mobility_env/lib/python3.7/site-packages/django/views/generic/base.py", line 68, in view
    return self.dispatch(request, *args, **kwargs)
  File "/media/tspl26/D/raju_python/mobility_env/lib/python3.7/site-packages/rest_framework/views.py", line 509, in dispatch
    response = self.handle_exception(exc)
  File "/media/tspl26/D/raju_python/mobility_env/lib/python3.7/site-packages/rest_framework/views.py", line 469, in handle_exception
    self.raise_uncaught_exception(exc)
  File "/media/tspl26/D/raju_python/mobility_env/lib/python3.7/site-packages/rest_framework/views.py", line 480, in raise_uncaught_exception
    raise exc
  File "/media/tspl26/D/raju_python/mobility_env/lib/python3.7/site-packages/rest_framework/views.py", line 506, in dispatch
    response = handler(request, *args, **kwargs)
  File "/media/tspl26/D/raju_python/mobility_env/mobilitysqr_live/mobility_apps/vault/views.py", line 103, in get
    dict = {'massage': 'data found', 'status': True, 'data': serializer.data}
  File "/media/tspl26/D/raju_python/mobility_env/lib/python3.7/site-packages/rest_framework/serializers.py", line 745, in data
    ret = super().data
  File "/media/tspl26/D/raju_python/mobility_env/lib/python3.7/site-packages/rest_framework/serializers.py", line 246, in data
    self._data = self.to_representation(self.instance)
  File "/media/tspl26/D/raju_python/mobility_env/lib/python3.7/site-packages/rest_framework/serializers.py", line 664, in to_representation
    self.child.to_representation(item) for item in iterable
  File "/media/tspl26/D/raju_python/mobility_env/lib/python3.7/site-packages/rest_framework/serializers.py", line 664, in <listcomp>
    self.child.to_representation(item) for item in iterable
  File "/media/tspl26/D/raju_python/mobility_env/lib/python3.7/site-packages/rest_framework/serializers.py", line 515, in to_representation
    ret[field.field_name] = field.to_representation(attribute)
  File "/media/tspl26/D/raju_python/mobility_env/lib/python3.7/site-packages/rest_framework/relations.py", line 467, in to_representation
    return getattr(obj, self.slug_field)
AttributeError: 'str' object has no attribute 'vault_id'
ERROR|19/Mar/2021 12:56:43|basehttp|11604|139779018221312|"GET /get_post_vault_document/?emp_code=Tspl1045 HTTP/1.1" 500 20676
ERROR|19/Mar/2021 12:57:04|log|11649|140522205521664|Internal Server Error: /get_post_vault_document/
Traceback (most recent call last):
  File "/media/tspl26/D/raju_python/mobility_env/lib/python3.7/site-packages/django/core/handlers/exception.py", line 34, in inner
    response = get_response(request)
  File "/media/tspl26/D/raju_python/mobility_env/lib/python3.7/site-packages/django/core/handlers/base.py", line 126, in _get_response
    response = self.process_exception_by_middleware(e, request)
  File "/media/tspl26/D/raju_python/mobility_env/lib/python3.7/site-packages/django/core/handlers/base.py", line 124, in _get_response
    response = wrapped_callback(request, *callback_args, **callback_kwargs)
  File "/media/tspl26/D/raju_python/mobility_env/lib/python3.7/site-packages/django/views/decorators/csrf.py", line 54, in wrapped_view
    return view_func(*args, **kwargs)
  File "/media/tspl26/D/raju_python/mobility_env/lib/python3.7/site-packages/django/views/generic/base.py", line 68, in view
    return self.dispatch(request, *args, **kwargs)
  File "/media/tspl26/D/raju_python/mobility_env/lib/python3.7/site-packages/rest_framework/views.py", line 509, in dispatch
    response = self.handle_exception(exc)
  File "/media/tspl26/D/raju_python/mobility_env/lib/python3.7/site-packages/rest_framework/views.py", line 469, in handle_exception
    self.raise_uncaught_exception(exc)
  File "/media/tspl26/D/raju_python/mobility_env/lib/python3.7/site-packages/rest_framework/views.py", line 480, in raise_uncaught_exception
    raise exc
  File "/media/tspl26/D/raju_python/mobility_env/lib/python3.7/site-packages/rest_framework/views.py", line 506, in dispatch
    response = handler(request, *args, **kwargs)
  File "/media/tspl26/D/raju_python/mobility_env/mobilitysqr_live/mobility_apps/vault/views.py", line 103, in get
    dict = {'massage': 'data found', 'status': True, 'data': serializer.data}
  File "/media/tspl26/D/raju_python/mobility_env/lib/python3.7/site-packages/rest_framework/serializers.py", line 745, in data
    ret = super().data
  File "/media/tspl26/D/raju_python/mobility_env/lib/python3.7/site-packages/rest_framework/serializers.py", line 246, in data
    self._data = self.to_representation(self.instance)
  File "/media/tspl26/D/raju_python/mobility_env/lib/python3.7/site-packages/rest_framework/serializers.py", line 664, in to_representation
    self.child.to_representation(item) for item in iterable
  File "/media/tspl26/D/raju_python/mobility_env/lib/python3.7/site-packages/rest_framework/serializers.py", line 664, in <listcomp>
    self.child.to_representation(item) for item in iterable
  File "/media/tspl26/D/raju_python/mobility_env/lib/python3.7/site-packages/rest_framework/serializers.py", line 515, in to_representation
    ret[field.field_name] = field.to_representation(attribute)
  File "/media/tspl26/D/raju_python/mobility_env/lib/python3.7/site-packages/rest_framework/relations.py", line 467, in to_representation
    return getattr(obj, self.slug_field)
AttributeError: 'str' object has no attribute 'vault_id'
ERROR|19/Mar/2021 12:57:04|basehttp|11649|140522205521664|"GET /get_post_vault_document/?emp_code=Tspl1045 HTTP/1.1" 500 20676
INFO|19/Mar/2021 13:00:25|basehttp|11814|140118090307328|"GET /get_post_vault_document/?emp_code=Tspl1045 HTTP/1.1" 200 106
WARNING|19/Mar/2021 13:02:31|log|11904|139782668199680|Unauthorized: /get_post_vault_document/
WARNING|19/Mar/2021 13:02:31|basehttp|11904|139782668199680|"GET /get_post_vault_document/?emp_code=Tspl1045 HTTP/1.1" 401 183
INFO|19/Mar/2021 13:02:39|basehttp|11904|139782668199680|"POST /api/custom/login/ HTTP/1.1" 200 452
INFO|19/Mar/2021 13:02:59|basehttp|11904|139782668199680|"GET /get_post_vault_document/?emp_code=Tspl1045 HTTP/1.1" 200 106
INFO|19/Mar/2021 13:08:59|basehttp|12069|139635644684032|"GET /get_post_vault_document/?emp_code=Tspl1045 HTTP/1.1" 200 106
INFO|19/Mar/2021 13:14:15|basehttp|12300|140503754942208|"GET /get_post_vault_document/?emp_code=Tspl1045 HTTP/1.1" 200 1636
WARNING|19/Mar/2021 14:15:54|log|14077|140143357540096|Unauthorized: /get_post_vault_document/
WARNING|19/Mar/2021 14:15:54|basehttp|14077|140143357540096|"GET /get_post_vault_document/?emp_code=Tspl1045 HTTP/1.1" 401 183
INFO|19/Mar/2021 14:16:02|basehttp|14077|140143357540096|"POST /api/custom/login/ HTTP/1.1" 200 452
ERROR|19/Mar/2021 14:16:17|log|14077|140143357540096|Internal Server Error: /get_post_vault_document/
Traceback (most recent call last):
  File "/media/tspl26/D/raju_python/mobility_env/lib/python3.7/site-packages/rest_framework/fields.py", line 457, in get_attribute
    return get_attribute(instance, self.source_attrs)
  File "/media/tspl26/D/raju_python/mobility_env/lib/python3.7/site-packages/rest_framework/fields.py", line 97, in get_attribute
    instance = getattr(instance, attr)
AttributeError: 'Vault_type_info' object has no attribute 'vault_id'

During handling of the above exception, another exception occurred:

Traceback (most recent call last):
  File "/media/tspl26/D/raju_python/mobility_env/lib/python3.7/site-packages/django/core/handlers/exception.py", line 34, in inner
    response = get_response(request)
  File "/media/tspl26/D/raju_python/mobility_env/lib/python3.7/site-packages/django/core/handlers/base.py", line 126, in _get_response
    response = self.process_exception_by_middleware(e, request)
  File "/media/tspl26/D/raju_python/mobility_env/lib/python3.7/site-packages/django/core/handlers/base.py", line 124, in _get_response
    response = wrapped_callback(request, *callback_args, **callback_kwargs)
  File "/media/tspl26/D/raju_python/mobility_env/lib/python3.7/site-packages/django/views/decorators/csrf.py", line 54, in wrapped_view
    return view_func(*args, **kwargs)
  File "/media/tspl26/D/raju_python/mobility_env/lib/python3.7/site-packages/django/views/generic/base.py", line 68, in view
    return self.dispatch(request, *args, **kwargs)
  File "/media/tspl26/D/raju_python/mobility_env/lib/python3.7/site-packages/rest_framework/views.py", line 509, in dispatch
    response = self.handle_exception(exc)
  File "/media/tspl26/D/raju_python/mobility_env/lib/python3.7/site-packages/rest_framework/views.py", line 469, in handle_exception
    self.raise_uncaught_exception(exc)
  File "/media/tspl26/D/raju_python/mobility_env/lib/python3.7/site-packages/rest_framework/views.py", line 480, in raise_uncaught_exception
    raise exc
  File "/media/tspl26/D/raju_python/mobility_env/lib/python3.7/site-packages/rest_framework/views.py", line 506, in dispatch
    response = handler(request, *args, **kwargs)
  File "/media/tspl26/D/raju_python/mobility_env/mobilitysqr_live/mobility_apps/vault/views.py", line 104, in get
    dict = {'massage': 'data found', 'status': True, 'data': serializer.data}
  File "/media/tspl26/D/raju_python/mobility_env/lib/python3.7/site-packages/rest_framework/serializers.py", line 745, in data
    ret = super().data
  File "/media/tspl26/D/raju_python/mobility_env/lib/python3.7/site-packages/rest_framework/serializers.py", line 246, in data
    self._data = self.to_representation(self.instance)
  File "/media/tspl26/D/raju_python/mobility_env/lib/python3.7/site-packages/rest_framework/serializers.py", line 664, in to_representation
    self.child.to_representation(item) for item in iterable
  File "/media/tspl26/D/raju_python/mobility_env/lib/python3.7/site-packages/rest_framework/serializers.py", line 664, in <listcomp>
    self.child.to_representation(item) for item in iterable
  File "/media/tspl26/D/raju_python/mobility_env/lib/python3.7/site-packages/rest_framework/serializers.py", line 515, in to_representation
    ret[field.field_name] = field.to_representation(attribute)
  File "/media/tspl26/D/raju_python/mobility_env/lib/python3.7/site-packages/rest_framework/serializers.py", line 664, in to_representation
    self.child.to_representation(item) for item in iterable
  File "/media/tspl26/D/raju_python/mobility_env/lib/python3.7/site-packages/rest_framework/serializers.py", line 664, in <listcomp>
    self.child.to_representation(item) for item in iterable
  File "/media/tspl26/D/raju_python/mobility_env/lib/python3.7/site-packages/rest_framework/serializers.py", line 502, in to_representation
    attribute = field.get_attribute(instance)
  File "/media/tspl26/D/raju_python/mobility_env/lib/python3.7/site-packages/rest_framework/fields.py", line 490, in get_attribute
    raise type(exc)(msg)
AttributeError: Got AttributeError when attempting to get a value for field `vault_id` on serializer `Vault_typeSerializers`.
The serializer field might be named incorrectly and not match any attribute or key on the `Vault_type_info` instance.
Original exception text was: 'Vault_type_info' object has no attribute 'vault_id'.
ERROR|19/Mar/2021 14:16:17|basehttp|14077|140143357540096|"GET /get_post_vault_document/?emp_code=Tspl1045 HTTP/1.1" 500 22277
INFO|19/Mar/2021 14:25:51|basehttp|14487|139899416073984|"GET /get_post_vault_document/?emp_code=Tspl1045 HTTP/1.1" 200 1636
ERROR|19/Mar/2021 14:26:45|log|14529|140567955322624|Internal Server Error: /get_post_vault_document/
Traceback (most recent call last):
  File "/media/tspl26/D/raju_python/mobility_env/lib/python3.7/site-packages/django/core/handlers/exception.py", line 34, in inner
    response = get_response(request)
  File "/media/tspl26/D/raju_python/mobility_env/lib/python3.7/site-packages/django/core/handlers/base.py", line 126, in _get_response
    response = self.process_exception_by_middleware(e, request)
  File "/media/tspl26/D/raju_python/mobility_env/lib/python3.7/site-packages/django/core/handlers/base.py", line 124, in _get_response
    response = wrapped_callback(request, *callback_args, **callback_kwargs)
  File "/media/tspl26/D/raju_python/mobility_env/lib/python3.7/site-packages/django/views/decorators/csrf.py", line 54, in wrapped_view
    return view_func(*args, **kwargs)
  File "/media/tspl26/D/raju_python/mobility_env/lib/python3.7/site-packages/django/views/generic/base.py", line 68, in view
    return self.dispatch(request, *args, **kwargs)
  File "/media/tspl26/D/raju_python/mobility_env/lib/python3.7/site-packages/rest_framework/views.py", line 509, in dispatch
    response = self.handle_exception(exc)
  File "/media/tspl26/D/raju_python/mobility_env/lib/python3.7/site-packages/rest_framework/views.py", line 469, in handle_exception
    self.raise_uncaught_exception(exc)
  File "/media/tspl26/D/raju_python/mobility_env/lib/python3.7/site-packages/rest_framework/views.py", line 480, in raise_uncaught_exception
    raise exc
  File "/media/tspl26/D/raju_python/mobility_env/lib/python3.7/site-packages/rest_framework/views.py", line 506, in dispatch
    response = handler(request, *args, **kwargs)
  File "/media/tspl26/D/raju_python/mobility_env/mobilitysqr_live/mobility_apps/vault/views.py", line 104, in get
    dict = {'massage': 'data found', 'status': True, 'data': serializer.data}
  File "/media/tspl26/D/raju_python/mobility_env/lib/python3.7/site-packages/rest_framework/serializers.py", line 745, in data
    ret = super().data
  File "/media/tspl26/D/raju_python/mobility_env/lib/python3.7/site-packages/rest_framework/serializers.py", line 246, in data
    self._data = self.to_representation(self.instance)
  File "/media/tspl26/D/raju_python/mobility_env/lib/python3.7/site-packages/rest_framework/serializers.py", line 664, in to_representation
    self.child.to_representation(item) for item in iterable
  File "/media/tspl26/D/raju_python/mobility_env/lib/python3.7/site-packages/rest_framework/serializers.py", line 664, in <listcomp>
    self.child.to_representation(item) for item in iterable
  File "/media/tspl26/D/raju_python/mobility_env/lib/python3.7/site-packages/rest_framework/serializers.py", line 515, in to_representation
    ret[field.field_name] = field.to_representation(attribute)
  File "/media/tspl26/D/raju_python/mobility_env/lib/python3.7/site-packages/rest_framework/relations.py", line 467, in to_representation
    return getattr(obj, self.slug_field)
AttributeError: 'str' object has no attribute 'vault_id'
ERROR|19/Mar/2021 14:26:45|basehttp|14529|140567955322624|"GET /get_post_vault_document/?emp_code=Tspl1045 HTTP/1.1" 500 20676
ERROR|19/Mar/2021 14:27:59|log|14592|139854117590784|Internal Server Error: /get_post_vault_document/
Traceback (most recent call last):
  File "/media/tspl26/D/raju_python/mobility_env/lib/python3.7/site-packages/rest_framework/fields.py", line 457, in get_attribute
    return get_attribute(instance, self.source_attrs)
  File "/media/tspl26/D/raju_python/mobility_env/lib/python3.7/site-packages/rest_framework/fields.py", line 97, in get_attribute
    instance = getattr(instance, attr)
AttributeError: 'Vault_type_info' object has no attribute 'vault_id'

During handling of the above exception, another exception occurred:

Traceback (most recent call last):
  File "/media/tspl26/D/raju_python/mobility_env/lib/python3.7/site-packages/django/core/handlers/exception.py", line 34, in inner
    response = get_response(request)
  File "/media/tspl26/D/raju_python/mobility_env/lib/python3.7/site-packages/django/core/handlers/base.py", line 126, in _get_response
    response = self.process_exception_by_middleware(e, request)
  File "/media/tspl26/D/raju_python/mobility_env/lib/python3.7/site-packages/django/core/handlers/base.py", line 124, in _get_response
    response = wrapped_callback(request, *callback_args, **callback_kwargs)
  File "/media/tspl26/D/raju_python/mobility_env/lib/python3.7/site-packages/django/views/decorators/csrf.py", line 54, in wrapped_view
    return view_func(*args, **kwargs)
  File "/media/tspl26/D/raju_python/mobility_env/lib/python3.7/site-packages/django/views/generic/base.py", line 68, in view
    return self.dispatch(request, *args, **kwargs)
  File "/media/tspl26/D/raju_python/mobility_env/lib/python3.7/site-packages/rest_framework/views.py", line 509, in dispatch
    response = self.handle_exception(exc)
  File "/media/tspl26/D/raju_python/mobility_env/lib/python3.7/site-packages/rest_framework/views.py", line 469, in handle_exception
    self.raise_uncaught_exception(exc)
  File "/media/tspl26/D/raju_python/mobility_env/lib/python3.7/site-packages/rest_framework/views.py", line 480, in raise_uncaught_exception
    raise exc
  File "/media/tspl26/D/raju_python/mobility_env/lib/python3.7/site-packages/rest_framework/views.py", line 506, in dispatch
    response = handler(request, *args, **kwargs)
  File "/media/tspl26/D/raju_python/mobility_env/mobilitysqr_live/mobility_apps/vault/views.py", line 104, in get
    dict = {'massage': 'data found', 'status': True, 'data': serializer.data}
  File "/media/tspl26/D/raju_python/mobility_env/lib/python3.7/site-packages/rest_framework/serializers.py", line 745, in data
    ret = super().data
  File "/media/tspl26/D/raju_python/mobility_env/lib/python3.7/site-packages/rest_framework/serializers.py", line 246, in data
    self._data = self.to_representation(self.instance)
  File "/media/tspl26/D/raju_python/mobility_env/lib/python3.7/site-packages/rest_framework/serializers.py", line 664, in to_representation
    self.child.to_representation(item) for item in iterable
  File "/media/tspl26/D/raju_python/mobility_env/lib/python3.7/site-packages/rest_framework/serializers.py", line 664, in <listcomp>
    self.child.to_representation(item) for item in iterable
  File "/media/tspl26/D/raju_python/mobility_env/lib/python3.7/site-packages/rest_framework/serializers.py", line 502, in to_representation
    attribute = field.get_attribute(instance)
  File "/media/tspl26/D/raju_python/mobility_env/lib/python3.7/site-packages/rest_framework/fields.py", line 490, in get_attribute
    raise type(exc)(msg)
AttributeError: Got AttributeError when attempting to get a value for field `vault_id` on serializer `Vault_typeSerializers`.
The serializer field might be named incorrectly and not match any attribute or key on the `Vault_type_info` instance.
Original exception text was: 'Vault_type_info' object has no attribute 'vault_id'.
ERROR|19/Mar/2021 14:27:59|basehttp|14592|139854117590784|"GET /get_post_vault_document/?emp_code=Tspl1045 HTTP/1.1" 500 21668
ERROR|19/Mar/2021 14:37:57|log|15073|140414369392384|Internal Server Error: /get_post_vault_document/
Traceback (most recent call last):
  File "/media/tspl26/D/raju_python/mobility_env/lib/python3.7/site-packages/django/core/handlers/exception.py", line 34, in inner
    response = get_response(request)
  File "/media/tspl26/D/raju_python/mobility_env/lib/python3.7/site-packages/django/core/handlers/base.py", line 126, in _get_response
    response = self.process_exception_by_middleware(e, request)
  File "/media/tspl26/D/raju_python/mobility_env/lib/python3.7/site-packages/django/core/handlers/base.py", line 124, in _get_response
    response = wrapped_callback(request, *callback_args, **callback_kwargs)
  File "/media/tspl26/D/raju_python/mobility_env/lib/python3.7/site-packages/django/views/decorators/csrf.py", line 54, in wrapped_view
    return view_func(*args, **kwargs)
  File "/media/tspl26/D/raju_python/mobility_env/lib/python3.7/site-packages/django/views/generic/base.py", line 68, in view
    return self.dispatch(request, *args, **kwargs)
  File "/media/tspl26/D/raju_python/mobility_env/lib/python3.7/site-packages/rest_framework/views.py", line 509, in dispatch
    response = self.handle_exception(exc)
  File "/media/tspl26/D/raju_python/mobility_env/lib/python3.7/site-packages/rest_framework/views.py", line 469, in handle_exception
    self.raise_uncaught_exception(exc)
  File "/media/tspl26/D/raju_python/mobility_env/lib/python3.7/site-packages/rest_framework/views.py", line 480, in raise_uncaught_exception
    raise exc
  File "/media/tspl26/D/raju_python/mobility_env/lib/python3.7/site-packages/rest_framework/views.py", line 506, in dispatch
    response = handler(request, *args, **kwargs)
  File "/media/tspl26/D/raju_python/mobility_env/mobilitysqr_live/mobility_apps/vault/views.py", line 103, in get
    serializer = Vault_typeSerializers(vault_data, many=True)
NameError: name 'vault_data' is not defined
ERROR|19/Mar/2021 14:37:57|basehttp|15073|140414369392384|"GET /get_post_vault_document/?emp_code=Tspl1045 HTTP/1.1" 500 19509
ERROR|19/Mar/2021 14:39:15|log|15121|140040529991424|Internal Server Error: /get_post_vault_document/
Traceback (most recent call last):
  File "/media/tspl26/D/raju_python/mobility_env/lib/python3.7/site-packages/rest_framework/fields.py", line 457, in get_attribute
    return get_attribute(instance, self.source_attrs)
  File "/media/tspl26/D/raju_python/mobility_env/lib/python3.7/site-packages/rest_framework/fields.py", line 97, in get_attribute
    instance = getattr(instance, attr)
AttributeError: 'Vault_type_info' object has no attribute 'vault_id'

During handling of the above exception, another exception occurred:

Traceback (most recent call last):
  File "/media/tspl26/D/raju_python/mobility_env/lib/python3.7/site-packages/django/core/handlers/exception.py", line 34, in inner
    response = get_response(request)
  File "/media/tspl26/D/raju_python/mobility_env/lib/python3.7/site-packages/django/core/handlers/base.py", line 126, in _get_response
    response = self.process_exception_by_middleware(e, request)
  File "/media/tspl26/D/raju_python/mobility_env/lib/python3.7/site-packages/django/core/handlers/base.py", line 124, in _get_response
    response = wrapped_callback(request, *callback_args, **callback_kwargs)
  File "/media/tspl26/D/raju_python/mobility_env/lib/python3.7/site-packages/django/views/decorators/csrf.py", line 54, in wrapped_view
    return view_func(*args, **kwargs)
  File "/media/tspl26/D/raju_python/mobility_env/lib/python3.7/site-packages/django/views/generic/base.py", line 68, in view
    return self.dispatch(request, *args, **kwargs)
  File "/media/tspl26/D/raju_python/mobility_env/lib/python3.7/site-packages/rest_framework/views.py", line 509, in dispatch
    response = self.handle_exception(exc)
  File "/media/tspl26/D/raju_python/mobility_env/lib/python3.7/site-packages/rest_framework/views.py", line 469, in handle_exception
    self.raise_uncaught_exception(exc)
  File "/media/tspl26/D/raju_python/mobility_env/lib/python3.7/site-packages/rest_framework/views.py", line 480, in raise_uncaught_exception
    raise exc
  File "/media/tspl26/D/raju_python/mobility_env/lib/python3.7/site-packages/rest_framework/views.py", line 506, in dispatch
    response = handler(request, *args, **kwargs)
  File "/media/tspl26/D/raju_python/mobility_env/mobilitysqr_live/mobility_apps/vault/views.py", line 104, in get
    dict = {'massage': 'data found', 'status': True, 'data': serializer.data}
  File "/media/tspl26/D/raju_python/mobility_env/lib/python3.7/site-packages/rest_framework/serializers.py", line 745, in data
    ret = super().data
  File "/media/tspl26/D/raju_python/mobility_env/lib/python3.7/site-packages/rest_framework/serializers.py", line 246, in data
    self._data = self.to_representation(self.instance)
  File "/media/tspl26/D/raju_python/mobility_env/lib/python3.7/site-packages/rest_framework/serializers.py", line 664, in to_representation
    self.child.to_representation(item) for item in iterable
  File "/media/tspl26/D/raju_python/mobility_env/lib/python3.7/site-packages/rest_framework/serializers.py", line 664, in <listcomp>
    self.child.to_representation(item) for item in iterable
  File "/media/tspl26/D/raju_python/mobility_env/lib/python3.7/site-packages/rest_framework/serializers.py", line 502, in to_representation
    attribute = field.get_attribute(instance)
  File "/media/tspl26/D/raju_python/mobility_env/lib/python3.7/site-packages/rest_framework/fields.py", line 490, in get_attribute
    raise type(exc)(msg)
AttributeError: Got AttributeError when attempting to get a value for field `vault_id` on serializer `Vault_typeSerializers`.
The serializer field might be named incorrectly and not match any attribute or key on the `Vault_type_info` instance.
Original exception text was: 'Vault_type_info' object has no attribute 'vault_id'.
ERROR|19/Mar/2021 14:39:15|basehttp|15121|140040529991424|"GET /get_post_vault_document/?emp_code=Tspl1045 HTTP/1.1" 500 21668
INFO|19/Mar/2021 14:40:08|basehttp|15234|140155159045888|"GET /get_post_vault_document/?emp_code=Tspl1045 HTTP/1.1" 200 2040
INFO|19/Mar/2021 14:42:27|basehttp|15322|140650272737024|"GET /get_post_vault_document/?emp_code=Tspl1045 HTTP/1.1" 200 2040
INFO|19/Mar/2021 15:27:26|basehttp|15322|140650272737024|"POST /api/custom/login/ HTTP/1.1" 200 452
INFO|19/Mar/2021 15:28:43|basehttp|15322|140650272737024|"POST /get_post_vault_document/ HTTP/1.1" 200 364
INFO|19/Mar/2021 15:28:56|basehttp|15322|140650272737024|"POST /get_post_vault_document/ HTTP/1.1" 200 364
WARNING|19/Mar/2021 15:29:05|log|15322|140650272737024|Bad Request: /get_post_vault_document/
WARNING|19/Mar/2021 15:29:05|basehttp|15322|140650272737024|"POST /get_post_vault_document/ HTTP/1.1" 400 59
INFO|19/Mar/2021 15:29:28|basehttp|15322|140650272737024|"POST /get_post_vault_document/ HTTP/1.1" 200 364
WARNING|19/Mar/2021 15:29:35|log|15322|140650272737024|Unauthorized: /get_post_vault_document/
WARNING|19/Mar/2021 15:29:35|basehttp|15322|140650272737024|"GET /get_post_vault_document/?emp_code=Tspl1045 HTTP/1.1" 401 183
INFO|19/Mar/2021 15:30:05|basehttp|15322|140650272737024|"GET /get_post_vault_document/?emp_code=Tspl1045 HTTP/1.1" 200 2996
ERROR|19/Mar/2021 15:38:22|log|16269|140180107290368|Internal Server Error: /get_post_vault_document/
Traceback (most recent call last):
  File "/media/tspl26/D/raju_python/mobility_env/lib/python3.7/site-packages/rest_framework/fields.py", line 457, in get_attribute
    return get_attribute(instance, self.source_attrs)
  File "/media/tspl26/D/raju_python/mobility_env/lib/python3.7/site-packages/rest_framework/fields.py", line 97, in get_attribute
    instance = getattr(instance, attr)
AttributeError: 'Vault_type_info' object has no attribute 'vault_id'

During handling of the above exception, another exception occurred:

Traceback (most recent call last):
  File "/media/tspl26/D/raju_python/mobility_env/lib/python3.7/site-packages/django/core/handlers/exception.py", line 34, in inner
    response = get_response(request)
  File "/media/tspl26/D/raju_python/mobility_env/lib/python3.7/site-packages/django/core/handlers/base.py", line 126, in _get_response
    response = self.process_exception_by_middleware(e, request)
  File "/media/tspl26/D/raju_python/mobility_env/lib/python3.7/site-packages/django/core/handlers/base.py", line 124, in _get_response
    response = wrapped_callback(request, *callback_args, **callback_kwargs)
  File "/media/tspl26/D/raju_python/mobility_env/lib/python3.7/site-packages/django/views/decorators/csrf.py", line 54, in wrapped_view
    return view_func(*args, **kwargs)
  File "/media/tspl26/D/raju_python/mobility_env/lib/python3.7/site-packages/django/views/generic/base.py", line 68, in view
    return self.dispatch(request, *args, **kwargs)
  File "/media/tspl26/D/raju_python/mobility_env/lib/python3.7/site-packages/rest_framework/views.py", line 509, in dispatch
    response = self.handle_exception(exc)
  File "/media/tspl26/D/raju_python/mobility_env/lib/python3.7/site-packages/rest_framework/views.py", line 469, in handle_exception
    self.raise_uncaught_exception(exc)
  File "/media/tspl26/D/raju_python/mobility_env/lib/python3.7/site-packages/rest_framework/views.py", line 480, in raise_uncaught_exception
    raise exc
  File "/media/tspl26/D/raju_python/mobility_env/lib/python3.7/site-packages/rest_framework/views.py", line 506, in dispatch
    response = handler(request, *args, **kwargs)
  File "/media/tspl26/D/raju_python/mobility_env/mobilitysqr_live/mobility_apps/vault/views.py", line 104, in get
    dict = {'massage': 'data found', 'status': True, 'data': serializer.data}
  File "/media/tspl26/D/raju_python/mobility_env/lib/python3.7/site-packages/rest_framework/serializers.py", line 745, in data
    ret = super().data
  File "/media/tspl26/D/raju_python/mobility_env/lib/python3.7/site-packages/rest_framework/serializers.py", line 246, in data
    self._data = self.to_representation(self.instance)
  File "/media/tspl26/D/raju_python/mobility_env/lib/python3.7/site-packages/rest_framework/serializers.py", line 664, in to_representation
    self.child.to_representation(item) for item in iterable
  File "/media/tspl26/D/raju_python/mobility_env/lib/python3.7/site-packages/rest_framework/serializers.py", line 664, in <listcomp>
    self.child.to_representation(item) for item in iterable
  File "/media/tspl26/D/raju_python/mobility_env/lib/python3.7/site-packages/rest_framework/serializers.py", line 502, in to_representation
    attribute = field.get_attribute(instance)
  File "/media/tspl26/D/raju_python/mobility_env/lib/python3.7/site-packages/rest_framework/fields.py", line 490, in get_attribute
    raise type(exc)(msg)
AttributeError: Got AttributeError when attempting to get a value for field `vault_id` on serializer `Vault_typeSerializers`.
The serializer field might be named incorrectly and not match any attribute or key on the `Vault_type_info` instance.
Original exception text was: 'Vault_type_info' object has no attribute 'vault_id'.
ERROR|19/Mar/2021 15:38:22|basehttp|16269|140180107290368|"GET /get_post_vault_document/?emp_code=Tspl1045 HTTP/1.1" 500 21668
INFO|19/Mar/2021 15:40:26|basehttp|16438|140627480139520|"GET /get_post_vault_document/?emp_code=Tspl1045 HTTP/1.1" 200 1019
INFO|19/Mar/2021 16:07:01|basehttp|17687|140216237766400|"GET /get_post_vault_document/?emp_code=Tspl1045 HTTP/1.1" 200 1636
INFO|19/Mar/2021 16:07:45|basehttp|17687|140216237766400|"GET /get_post_vault_document/?emp_code=Tspl1045&vault_type=VA5 HTTP/1.1" 200 1636
INFO|19/Mar/2021 16:08:09|basehttp|17687|140216237766400|"GET /get_post_vault_document/?emp_code=Tspl1045&vault_type= HTTP/1.1" 200 1636
INFO|19/Mar/2021 16:12:34|basehttp|18023|140406910396160|"GET /get_post_vault_document/?emp_code=Tspl1045&vault_type= HTTP/1.1" 200 76
INFO|19/Mar/2021 16:12:45|basehttp|18023|140406910396160|"GET /get_post_vault_document/?emp_code=Tspl1045&vault_type=VA5 HTTP/1.1" 200 76
ERROR|19/Mar/2021 16:13:41|log|18082|140588369618688|Internal Server Error: /get_post_vault_document/
Traceback (most recent call last):
  File "/media/tspl26/D/raju_python/mobility_env/lib/python3.7/site-packages/django/core/handlers/exception.py", line 34, in inner
    response = get_response(request)
  File "/media/tspl26/D/raju_python/mobility_env/lib/python3.7/site-packages/django/core/handlers/base.py", line 126, in _get_response
    response = self.process_exception_by_middleware(e, request)
  File "/media/tspl26/D/raju_python/mobility_env/lib/python3.7/site-packages/django/core/handlers/base.py", line 124, in _get_response
    response = wrapped_callback(request, *callback_args, **callback_kwargs)
  File "/media/tspl26/D/raju_python/mobility_env/lib/python3.7/site-packages/django/views/decorators/csrf.py", line 54, in wrapped_view
    return view_func(*args, **kwargs)
  File "/media/tspl26/D/raju_python/mobility_env/lib/python3.7/site-packages/django/views/generic/base.py", line 68, in view
    return self.dispatch(request, *args, **kwargs)
  File "/media/tspl26/D/raju_python/mobility_env/lib/python3.7/site-packages/rest_framework/views.py", line 509, in dispatch
    response = self.handle_exception(exc)
  File "/media/tspl26/D/raju_python/mobility_env/lib/python3.7/site-packages/rest_framework/views.py", line 469, in handle_exception
    self.raise_uncaught_exception(exc)
  File "/media/tspl26/D/raju_python/mobility_env/lib/python3.7/site-packages/rest_framework/views.py", line 480, in raise_uncaught_exception
    raise exc
  File "/media/tspl26/D/raju_python/mobility_env/lib/python3.7/site-packages/rest_framework/views.py", line 506, in dispatch
    response = handler(request, *args, **kwargs)
  File "/media/tspl26/D/raju_python/mobility_env/mobilitysqr_live/mobility_apps/vault/views.py", line 99, in get
    vault_data = Vault_type.objects.filter(emp_code_id=emp_code,vault_type=vault_type)
  File "/media/tspl26/D/raju_python/mobility_env/lib/python3.7/site-packages/django/db/models/manager.py", line 82, in manager_method
    return getattr(self.get_queryset(), name)(*args, **kwargs)
  File "/media/tspl26/D/raju_python/mobility_env/lib/python3.7/site-packages/django/db/models/query.py", line 844, in filter
    return self._filter_or_exclude(False, *args, **kwargs)
  File "/media/tspl26/D/raju_python/mobility_env/lib/python3.7/site-packages/django/db/models/query.py", line 862, in _filter_or_exclude
    clone.query.add_q(Q(*args, **kwargs))
  File "/media/tspl26/D/raju_python/mobility_env/lib/python3.7/site-packages/django/db/models/sql/query.py", line 1263, in add_q
    clause, _ = self._add_q(q_object, self.used_aliases)
  File "/media/tspl26/D/raju_python/mobility_env/lib/python3.7/site-packages/django/db/models/sql/query.py", line 1287, in _add_q
    split_subq=split_subq,
  File "/media/tspl26/D/raju_python/mobility_env/lib/python3.7/site-packages/django/db/models/sql/query.py", line 1164, in build_filter
    lookups, parts, reffed_expression = self.solve_lookup_type(arg)
  File "/media/tspl26/D/raju_python/mobility_env/lib/python3.7/site-packages/django/db/models/sql/query.py", line 1028, in solve_lookup_type
    _, field, _, lookup_parts = self.names_to_path(lookup_splitted, self.get_meta())
  File "/media/tspl26/D/raju_python/mobility_env/lib/python3.7/site-packages/django/db/models/sql/query.py", line 1389, in names_to_path
    "Choices are: %s" % (name, ", ".join(available)))
django.core.exceptions.FieldError: Cannot resolve keyword 'emp_code_id' into field. Choices are: created_by, date_created, date_modified, id, modified_by, status, vault_id, vault_name, vault_type, vault_type_info
ERROR|19/Mar/2021 16:13:41|basehttp|18082|140588369618688|"GET /get_post_vault_document/?emp_code=Tspl1045&vault_type=VA5 HTTP/1.1" 500 21443
ERROR|19/Mar/2021 16:15:54|log|18199|139828558251776|Internal Server Error: /get_post_vault_document/
Traceback (most recent call last):
  File "/media/tspl26/D/raju_python/mobility_env/lib/python3.7/site-packages/django/core/handlers/exception.py", line 34, in inner
    response = get_response(request)
  File "/media/tspl26/D/raju_python/mobility_env/lib/python3.7/site-packages/django/core/handlers/base.py", line 126, in _get_response
    response = self.process_exception_by_middleware(e, request)
  File "/media/tspl26/D/raju_python/mobility_env/lib/python3.7/site-packages/django/core/handlers/base.py", line 124, in _get_response
    response = wrapped_callback(request, *callback_args, **callback_kwargs)
  File "/media/tspl26/D/raju_python/mobility_env/lib/python3.7/site-packages/django/views/decorators/csrf.py", line 54, in wrapped_view
    return view_func(*args, **kwargs)
  File "/media/tspl26/D/raju_python/mobility_env/lib/python3.7/site-packages/django/views/generic/base.py", line 68, in view
    return self.dispatch(request, *args, **kwargs)
  File "/media/tspl26/D/raju_python/mobility_env/lib/python3.7/site-packages/rest_framework/views.py", line 509, in dispatch
    response = self.handle_exception(exc)
  File "/media/tspl26/D/raju_python/mobility_env/lib/python3.7/site-packages/rest_framework/views.py", line 469, in handle_exception
    self.raise_uncaught_exception(exc)
  File "/media/tspl26/D/raju_python/mobility_env/lib/python3.7/site-packages/rest_framework/views.py", line 480, in raise_uncaught_exception
    raise exc
  File "/media/tspl26/D/raju_python/mobility_env/lib/python3.7/site-packages/rest_framework/views.py", line 506, in dispatch
    response = handler(request, *args, **kwargs)
  File "/media/tspl26/D/raju_python/mobility_env/mobilitysqr_live/mobility_apps/vault/views.py", line 99, in get
    vault_data = Vault_type.infoobjects.filter(emp_code_id=emp_code,vault_type=vault_type)
AttributeError: type object 'Vault_type' has no attribute 'infoobjects'
ERROR|19/Mar/2021 16:15:54|basehttp|18199|139828558251776|"GET /get_post_vault_document/?emp_code=Tspl1045&vault_type=VA5 HTTP/1.1" 500 19642
INFO|19/Mar/2021 16:16:56|basehttp|18267|140106427836160|"GET /get_post_vault_document/?emp_code=Tspl1045&vault_type=VA5 HTTP/1.1" 200 679
INFO|19/Mar/2021 16:17:12|basehttp|18267|140106427836160|"GET /get_post_vault_document/?emp_code=Tspl1045&vault_type=VA55 HTTP/1.1" 200 48
INFO|19/Mar/2021 16:17:24|basehttp|18267|140106427836160|"GET /get_post_vault_document/?emp_code=Tspl1045&vault_type=VA5 HTTP/1.1" 200 679
WARNING|19/Mar/2021 16:31:44|log|19155|140407488374528|Unauthorized: /get_post_vault_type/
WARNING|19/Mar/2021 16:31:44|basehttp|19155|140407488374528|"GET /get_post_vault_type/ HTTP/1.1" 401 183
INFO|19/Mar/2021 16:31:51|basehttp|19155|140407488374528|"POST /api/custom/login/ HTTP/1.1" 200 452
ERROR|19/Mar/2021 16:32:13|log|19155|140407488374528|Internal Server Error: /get_post_vault_type/
Traceback (most recent call last):
  File "/media/tspl26/D/raju_python/mobility_env/lib/python3.7/site-packages/rest_framework/fields.py", line 457, in get_attribute
    return get_attribute(instance, self.source_attrs)
  File "/media/tspl26/D/raju_python/mobility_env/lib/python3.7/site-packages/rest_framework/fields.py", line 97, in get_attribute
    instance = getattr(instance, attr)
AttributeError: 'QuerySet' object has no attribute 'vault_id'

During handling of the above exception, another exception occurred:

Traceback (most recent call last):
  File "/media/tspl26/D/raju_python/mobility_env/lib/python3.7/site-packages/django/core/handlers/exception.py", line 34, in inner
    response = get_response(request)
  File "/media/tspl26/D/raju_python/mobility_env/lib/python3.7/site-packages/django/core/handlers/base.py", line 126, in _get_response
    response = self.process_exception_by_middleware(e, request)
  File "/media/tspl26/D/raju_python/mobility_env/lib/python3.7/site-packages/django/core/handlers/base.py", line 124, in _get_response
    response = wrapped_callback(request, *callback_args, **callback_kwargs)
  File "/media/tspl26/D/raju_python/mobility_env/lib/python3.7/site-packages/django/views/decorators/csrf.py", line 54, in wrapped_view
    return view_func(*args, **kwargs)
  File "/media/tspl26/D/raju_python/mobility_env/lib/python3.7/site-packages/django/views/generic/base.py", line 68, in view
    return self.dispatch(request, *args, **kwargs)
  File "/media/tspl26/D/raju_python/mobility_env/lib/python3.7/site-packages/rest_framework/views.py", line 509, in dispatch
    response = self.handle_exception(exc)
  File "/media/tspl26/D/raju_python/mobility_env/lib/python3.7/site-packages/rest_framework/views.py", line 469, in handle_exception
    self.raise_uncaught_exception(exc)
  File "/media/tspl26/D/raju_python/mobility_env/lib/python3.7/site-packages/rest_framework/views.py", line 480, in raise_uncaught_exception
    raise exc
  File "/media/tspl26/D/raju_python/mobility_env/lib/python3.7/site-packages/rest_framework/views.py", line 506, in dispatch
    response = handler(request, *args, **kwargs)
  File "/media/tspl26/D/raju_python/mobility_env/mobilitysqr_live/mobility_apps/vault/views.py", line 45, in get
    dict = {'message':'Successful','status':True,'data': serializer.data}
  File "/media/tspl26/D/raju_python/mobility_env/lib/python3.7/site-packages/rest_framework/serializers.py", line 548, in data
    ret = super().data
  File "/media/tspl26/D/raju_python/mobility_env/lib/python3.7/site-packages/rest_framework/serializers.py", line 246, in data
    self._data = self.to_representation(self.instance)
  File "/media/tspl26/D/raju_python/mobility_env/lib/python3.7/site-packages/rest_framework/serializers.py", line 502, in to_representation
    attribute = field.get_attribute(instance)
  File "/media/tspl26/D/raju_python/mobility_env/lib/python3.7/site-packages/rest_framework/fields.py", line 490, in get_attribute
    raise type(exc)(msg)
AttributeError: Got AttributeError when attempting to get a value for field `vault_id` on serializer `Vault_typeSerializers`.
The serializer field might be named incorrectly and not match any attribute or key on the `QuerySet` instance.
Original exception text was: 'QuerySet' object has no attribute 'vault_id'.
ERROR|19/Mar/2021 16:32:13|basehttp|19155|140407488374528|"GET /get_post_vault_type/ HTTP/1.1" 500 21172
INFO|19/Mar/2021 16:33:02|basehttp|19253|140176173774592|"GET /get_post_vault_type/ HTTP/1.1" 200 1189
WARNING|19/Mar/2021 17:21:01|log|20883|140292842534656|Unauthorized: /get_post_vault_document/
WARNING|19/Mar/2021 17:21:01|basehttp|20883|140292842534656|"GET /get_post_vault_document/?emp_code=Tspl1045&vault_type=VA5 HTTP/1.1" 401 183
INFO|19/Mar/2021 17:22:38|basehttp|20883|140292842534656|"POST /api/custom/login/ HTTP/1.1" 200 452
WARNING|19/Mar/2021 17:25:15|log|20883|140292842534656|Unauthorized: /get_post_vault_document/
WARNING|19/Mar/2021 17:25:15|basehttp|20883|140292842534656|"GET /get_post_vault_document/?emp_code=Tspl1045&vault_type=VA5 HTTP/1.1" 401 183
INFO|19/Mar/2021 17:25:38|basehttp|20883|140292842534656|"GET /get_post_vault_document/?emp_code=Tspl1045&vault_type=VA5 HTTP/1.1" 200 679
ERROR|19/Mar/2021 17:26:23|log|20883|140292842534656|Internal Server Error: /update_delete_vault_document/1/
Traceback (most recent call last):
  File "/media/tspl26/D/raju_python/mobility_env/lib/python3.7/site-packages/django/core/handlers/exception.py", line 34, in inner
    response = get_response(request)
  File "/media/tspl26/D/raju_python/mobility_env/lib/python3.7/site-packages/django/core/handlers/base.py", line 126, in _get_response
    response = self.process_exception_by_middleware(e, request)
  File "/media/tspl26/D/raju_python/mobility_env/lib/python3.7/site-packages/django/core/handlers/base.py", line 124, in _get_response
    response = wrapped_callback(request, *callback_args, **callback_kwargs)
  File "/media/tspl26/D/raju_python/mobility_env/lib/python3.7/site-packages/django/views/decorators/csrf.py", line 54, in wrapped_view
    return view_func(*args, **kwargs)
  File "/media/tspl26/D/raju_python/mobility_env/lib/python3.7/site-packages/django/views/generic/base.py", line 68, in view
    return self.dispatch(request, *args, **kwargs)
  File "/media/tspl26/D/raju_python/mobility_env/lib/python3.7/site-packages/rest_framework/views.py", line 509, in dispatch
    response = self.handle_exception(exc)
  File "/media/tspl26/D/raju_python/mobility_env/lib/python3.7/site-packages/rest_framework/views.py", line 469, in handle_exception
    self.raise_uncaught_exception(exc)
  File "/media/tspl26/D/raju_python/mobility_env/lib/python3.7/site-packages/rest_framework/views.py", line 480, in raise_uncaught_exception
    raise exc
  File "/media/tspl26/D/raju_python/mobility_env/lib/python3.7/site-packages/rest_framework/views.py", line 506, in dispatch
    response = handler(request, *args, **kwargs)
  File "/media/tspl26/D/raju_python/mobility_env/mobilitysqr_live/mobility_apps/vault/views.py", line 145, in patch
    urlpath = self.get_upload_docurl(pk)
TypeError: get_upload_docurl() takes 1 positional argument but 2 were given
ERROR|19/Mar/2021 17:26:23|basehttp|20883|140292842534656|"PATCH /update_delete_vault_document/1/ HTTP/1.1" 500 19649
ERROR|19/Mar/2021 17:27:41|log|21129|139787529574144|Internal Server Error: /update_delete_vault_document/1/
Traceback (most recent call last):
  File "/media/tspl26/D/raju_python/mobility_env/lib/python3.7/site-packages/django/core/handlers/exception.py", line 34, in inner
    response = get_response(request)
  File "/media/tspl26/D/raju_python/mobility_env/lib/python3.7/site-packages/django/core/handlers/base.py", line 126, in _get_response
    response = self.process_exception_by_middleware(e, request)
  File "/media/tspl26/D/raju_python/mobility_env/lib/python3.7/site-packages/django/core/handlers/base.py", line 124, in _get_response
    response = wrapped_callback(request, *callback_args, **callback_kwargs)
  File "/media/tspl26/D/raju_python/mobility_env/lib/python3.7/site-packages/django/views/decorators/csrf.py", line 54, in wrapped_view
    return view_func(*args, **kwargs)
  File "/media/tspl26/D/raju_python/mobility_env/lib/python3.7/site-packages/django/views/generic/base.py", line 68, in view
    return self.dispatch(request, *args, **kwargs)
  File "/media/tspl26/D/raju_python/mobility_env/lib/python3.7/site-packages/rest_framework/views.py", line 509, in dispatch
    response = self.handle_exception(exc)
  File "/media/tspl26/D/raju_python/mobility_env/lib/python3.7/site-packages/rest_framework/views.py", line 469, in handle_exception
    self.raise_uncaught_exception(exc)
  File "/media/tspl26/D/raju_python/mobility_env/lib/python3.7/site-packages/rest_framework/views.py", line 480, in raise_uncaught_exception
    raise exc
  File "/media/tspl26/D/raju_python/mobility_env/lib/python3.7/site-packages/rest_framework/views.py", line 506, in dispatch
    response = handler(request, *args, **kwargs)
  File "/media/tspl26/D/raju_python/mobility_env/mobilitysqr_live/mobility_apps/vault/views.py", line 145, in patch
    urlpath = self.get_upload_docurl(pk)
TypeError: get_upload_docurl() takes 1 positional argument but 2 were given
ERROR|19/Mar/2021 17:27:41|basehttp|21129|139787529574144|"PATCH /update_delete_vault_document/1/ HTTP/1.1" 500 19649
ERROR|19/Mar/2021 17:28:53|log|21176|139747130038016|Internal Server Error: /update_delete_vault_document/1/
Traceback (most recent call last):
  File "/media/tspl26/D/raju_python/mobility_env/lib/python3.7/site-packages/django/core/handlers/exception.py", line 34, in inner
    response = get_response(request)
  File "/media/tspl26/D/raju_python/mobility_env/lib/python3.7/site-packages/django/core/handlers/base.py", line 126, in _get_response
    response = self.process_exception_by_middleware(e, request)
  File "/media/tspl26/D/raju_python/mobility_env/lib/python3.7/site-packages/django/core/handlers/base.py", line 124, in _get_response
    response = wrapped_callback(request, *callback_args, **callback_kwargs)
  File "/media/tspl26/D/raju_python/mobility_env/lib/python3.7/site-packages/django/views/decorators/csrf.py", line 54, in wrapped_view
    return view_func(*args, **kwargs)
  File "/media/tspl26/D/raju_python/mobility_env/lib/python3.7/site-packages/django/views/generic/base.py", line 68, in view
    return self.dispatch(request, *args, **kwargs)
  File "/media/tspl26/D/raju_python/mobility_env/lib/python3.7/site-packages/rest_framework/views.py", line 509, in dispatch
    response = self.handle_exception(exc)
  File "/media/tspl26/D/raju_python/mobility_env/lib/python3.7/site-packages/rest_framework/views.py", line 469, in handle_exception
    self.raise_uncaught_exception(exc)
  File "/media/tspl26/D/raju_python/mobility_env/lib/python3.7/site-packages/rest_framework/views.py", line 480, in raise_uncaught_exception
    raise exc
  File "/media/tspl26/D/raju_python/mobility_env/lib/python3.7/site-packages/rest_framework/views.py", line 506, in dispatch
    response = handler(request, *args, **kwargs)
  File "/media/tspl26/D/raju_python/mobility_env/mobilitysqr_live/mobility_apps/vault/views.py", line 145, in patch
    urlpath = self.get_upload_docurl(pk)
  File "/media/tspl26/D/raju_python/mobility_env/mobilitysqr_live/mobility_apps/vault/views.py", line 183, in get_upload_docurl
    data = Vault_type_info.objects.get(pk=id).values('document_url')
AttributeError: 'Vault_type_info' object has no attribute 'values'
ERROR|19/Mar/2021 17:28:53|basehttp|21176|139747130038016|"PATCH /update_delete_vault_document/1/ HTTP/1.1" 500 19827
ERROR|19/Mar/2021 17:30:13|log|21260|140218485167872|Internal Server Error: /update_delete_vault_document/1/
Traceback (most recent call last):
  File "/media/tspl26/D/raju_python/mobility_env/lib/python3.7/site-packages/django/core/handlers/exception.py", line 34, in inner
    response = get_response(request)
  File "/media/tspl26/D/raju_python/mobility_env/lib/python3.7/site-packages/django/core/handlers/base.py", line 126, in _get_response
    response = self.process_exception_by_middleware(e, request)
  File "/media/tspl26/D/raju_python/mobility_env/lib/python3.7/site-packages/django/core/handlers/base.py", line 124, in _get_response
    response = wrapped_callback(request, *callback_args, **callback_kwargs)
  File "/media/tspl26/D/raju_python/mobility_env/lib/python3.7/site-packages/django/views/decorators/csrf.py", line 54, in wrapped_view
    return view_func(*args, **kwargs)
  File "/media/tspl26/D/raju_python/mobility_env/lib/python3.7/site-packages/django/views/generic/base.py", line 68, in view
    return self.dispatch(request, *args, **kwargs)
  File "/media/tspl26/D/raju_python/mobility_env/lib/python3.7/site-packages/rest_framework/views.py", line 509, in dispatch
    response = self.handle_exception(exc)
  File "/media/tspl26/D/raju_python/mobility_env/lib/python3.7/site-packages/rest_framework/views.py", line 469, in handle_exception
    self.raise_uncaught_exception(exc)
  File "/media/tspl26/D/raju_python/mobility_env/lib/python3.7/site-packages/rest_framework/views.py", line 480, in raise_uncaught_exception
    raise exc
  File "/media/tspl26/D/raju_python/mobility_env/lib/python3.7/site-packages/rest_framework/views.py", line 506, in dispatch
    response = handler(request, *args, **kwargs)
  File "/media/tspl26/D/raju_python/mobility_env/mobilitysqr_live/mobility_apps/vault/views.py", line 147, in patch
    request.data['document_url'] = urlpath
  File "/media/tspl26/D/raju_python/mobility_env/lib/python3.7/site-packages/django/http/request.py", line 440, in __setitem__
    self._assert_mutable()
  File "/media/tspl26/D/raju_python/mobility_env/lib/python3.7/site-packages/django/http/request.py", line 437, in _assert_mutable
    raise AttributeError("This QueryDict instance is immutable")
AttributeError: This QueryDict instance is immutable
ERROR|19/Mar/2021 17:30:13|basehttp|21260|140218485167872|"PATCH /update_delete_vault_document/1/ HTTP/1.1" 500 19961
ERROR|19/Mar/2021 17:32:09|log|21371|140253490833152|Internal Server Error: /update_delete_vault_document/1/
Traceback (most recent call last):
  File "/media/tspl26/D/raju_python/mobility_env/lib/python3.7/site-packages/django/db/backends/utils.py", line 85, in _execute
    return self.cursor.execute(sql, params)
  File "/media/tspl26/D/raju_python/mobility_env/lib/python3.7/site-packages/sql_server/pyodbc/base.py", line 546, in execute
    return self.cursor.execute(sql, params)
pyodbc.IntegrityError: ('23000', '[23000] [Microsoft][ODBC Driver 17 for SQL Server][SQL Server]The INSERT statement conflicted with the FOREIGN KEY constraint "vault_vault_type_info_emp_code_id_a059f613_fk_employee_employee_emp_code". The conflict occurred in database "mob_test", table "dbo.employee_employee", column \'emp_code\'. (547) (SQLExecDirectW)')

The above exception was the direct cause of the following exception:

Traceback (most recent call last):
  File "/media/tspl26/D/raju_python/mobility_env/lib/python3.7/site-packages/django/core/handlers/exception.py", line 34, in inner
    response = get_response(request)
  File "/media/tspl26/D/raju_python/mobility_env/lib/python3.7/site-packages/django/core/handlers/base.py", line 126, in _get_response
    response = self.process_exception_by_middleware(e, request)
  File "/media/tspl26/D/raju_python/mobility_env/lib/python3.7/site-packages/django/core/handlers/base.py", line 124, in _get_response
    response = wrapped_callback(request, *callback_args, **callback_kwargs)
  File "/media/tspl26/D/raju_python/mobility_env/lib/python3.7/site-packages/django/views/decorators/csrf.py", line 54, in wrapped_view
    return view_func(*args, **kwargs)
  File "/media/tspl26/D/raju_python/mobility_env/lib/python3.7/site-packages/django/views/generic/base.py", line 68, in view
    return self.dispatch(request, *args, **kwargs)
  File "/media/tspl26/D/raju_python/mobility_env/lib/python3.7/site-packages/rest_framework/views.py", line 509, in dispatch
    response = self.handle_exception(exc)
  File "/media/tspl26/D/raju_python/mobility_env/lib/python3.7/site-packages/rest_framework/views.py", line 469, in handle_exception
    self.raise_uncaught_exception(exc)
  File "/media/tspl26/D/raju_python/mobility_env/lib/python3.7/site-packages/rest_framework/views.py", line 480, in raise_uncaught_exception
    raise exc
  File "/media/tspl26/D/raju_python/mobility_env/lib/python3.7/site-packages/rest_framework/views.py", line 506, in dispatch
    response = handler(request, *args, **kwargs)
  File "/media/tspl26/D/raju_python/mobility_env/mobilitysqr_live/mobility_apps/vault/views.py", line 168, in patch
    serializer.save()
  File "/media/tspl26/D/raju_python/mobility_env/lib/python3.7/site-packages/rest_framework/serializers.py", line 205, in save
    self.instance = self.create(validated_data)
  File "/media/tspl26/D/raju_python/mobility_env/lib/python3.7/site-packages/rest_framework/serializers.py", line 939, in create
    instance = ModelClass._default_manager.create(**validated_data)
  File "/media/tspl26/D/raju_python/mobility_env/lib/python3.7/site-packages/django/db/models/manager.py", line 82, in manager_method
    return getattr(self.get_queryset(), name)(*args, **kwargs)
  File "/media/tspl26/D/raju_python/mobility_env/lib/python3.7/site-packages/django/db/models/query.py", line 413, in create
    obj.save(force_insert=True, using=self.db)
  File "/media/tspl26/D/raju_python/mobility_env/lib/python3.7/site-packages/django/db/models/base.py", line 718, in save
    force_update=force_update, update_fields=update_fields)
  File "/media/tspl26/D/raju_python/mobility_env/lib/python3.7/site-packages/django/db/models/base.py", line 748, in save_base
    updated = self._save_table(raw, cls, force_insert, force_update, using, update_fields)
  File "/media/tspl26/D/raju_python/mobility_env/lib/python3.7/site-packages/django/db/models/base.py", line 831, in _save_table
    result = self._do_insert(cls._base_manager, using, fields, update_pk, raw)
  File "/media/tspl26/D/raju_python/mobility_env/lib/python3.7/site-packages/django/db/models/base.py", line 869, in _do_insert
    using=using, raw=raw)
  File "/media/tspl26/D/raju_python/mobility_env/lib/python3.7/site-packages/django/db/models/manager.py", line 82, in manager_method
    return getattr(self.get_queryset(), name)(*args, **kwargs)
  File "/media/tspl26/D/raju_python/mobility_env/lib/python3.7/site-packages/django/db/models/query.py", line 1136, in _insert
    return query.get_compiler(using=using).execute_sql(return_id)
  File "/media/tspl26/D/raju_python/mobility_env/lib/python3.7/site-packages/django/db/models/sql/compiler.py", line 1322, in execute_sql
    cursor.execute(sql, params)
  File "/media/tspl26/D/raju_python/mobility_env/lib/python3.7/site-packages/django/db/backends/utils.py", line 100, in execute
    return super().execute(sql, params)
  File "/media/tspl26/D/raju_python/mobility_env/lib/python3.7/site-packages/django/db/backends/utils.py", line 68, in execute
    return self._execute_with_wrappers(sql, params, many=False, executor=self._execute)
  File "/media/tspl26/D/raju_python/mobility_env/lib/python3.7/site-packages/django/db/backends/utils.py", line 77, in _execute_with_wrappers
    return executor(sql, params, many, context)
  File "/media/tspl26/D/raju_python/mobility_env/lib/python3.7/site-packages/django/db/backends/utils.py", line 85, in _execute
    return self.cursor.execute(sql, params)
  File "/media/tspl26/D/raju_python/mobility_env/lib/python3.7/site-packages/django/db/utils.py", line 89, in __exit__
    raise dj_exc_value.with_traceback(traceback) from exc_value
  File "/media/tspl26/D/raju_python/mobility_env/lib/python3.7/site-packages/django/db/backends/utils.py", line 85, in _execute
    return self.cursor.execute(sql, params)
  File "/media/tspl26/D/raju_python/mobility_env/lib/python3.7/site-packages/sql_server/pyodbc/base.py", line 546, in execute
    return self.cursor.execute(sql, params)
django.db.utils.IntegrityError: ('23000', '[23000] [Microsoft][ODBC Driver 17 for SQL Server][SQL Server]The INSERT statement conflicted with the FOREIGN KEY constraint "vault_vault_type_info_emp_code_id_a059f613_fk_employee_employee_emp_code". The conflict occurred in database "mob_test", table "dbo.employee_employee", column \'emp_code\'. (547) (SQLExecDirectW)')
ERROR|19/Mar/2021 17:32:09|basehttp|21371|140253490833152|"PATCH /update_delete_vault_document/1/ HTTP/1.1" 500 24367
ERROR|19/Mar/2021 17:32:09|log|21371|140253415331584|Internal Server Error: /update_delete_vault_document/1/
Traceback (most recent call last):
  File "/media/tspl26/D/raju_python/mobility_env/lib/python3.7/site-packages/django/db/backends/utils.py", line 85, in _execute
    return self.cursor.execute(sql, params)
  File "/media/tspl26/D/raju_python/mobility_env/lib/python3.7/site-packages/sql_server/pyodbc/base.py", line 546, in execute
    return self.cursor.execute(sql, params)
pyodbc.IntegrityError: ('23000', '[23000] [Microsoft][ODBC Driver 17 for SQL Server][SQL Server]The INSERT statement conflicted with the FOREIGN KEY constraint "vault_vault_type_info_emp_code_id_a059f613_fk_employee_employee_emp_code". The conflict occurred in database "mob_test", table "dbo.employee_employee", column \'emp_code\'. (547) (SQLExecDirectW)')

The above exception was the direct cause of the following exception:

Traceback (most recent call last):
  File "/media/tspl26/D/raju_python/mobility_env/lib/python3.7/site-packages/django/core/handlers/exception.py", line 34, in inner
    response = get_response(request)
  File "/media/tspl26/D/raju_python/mobility_env/lib/python3.7/site-packages/django/core/handlers/base.py", line 126, in _get_response
    response = self.process_exception_by_middleware(e, request)
  File "/media/tspl26/D/raju_python/mobility_env/lib/python3.7/site-packages/django/core/handlers/base.py", line 124, in _get_response
    response = wrapped_callback(request, *callback_args, **callback_kwargs)
  File "/media/tspl26/D/raju_python/mobility_env/lib/python3.7/site-packages/django/views/decorators/csrf.py", line 54, in wrapped_view
    return view_func(*args, **kwargs)
  File "/media/tspl26/D/raju_python/mobility_env/lib/python3.7/site-packages/django/views/generic/base.py", line 68, in view
    return self.dispatch(request, *args, **kwargs)
  File "/media/tspl26/D/raju_python/mobility_env/lib/python3.7/site-packages/rest_framework/views.py", line 509, in dispatch
    response = self.handle_exception(exc)
  File "/media/tspl26/D/raju_python/mobility_env/lib/python3.7/site-packages/rest_framework/views.py", line 469, in handle_exception
    self.raise_uncaught_exception(exc)
  File "/media/tspl26/D/raju_python/mobility_env/lib/python3.7/site-packages/rest_framework/views.py", line 480, in raise_uncaught_exception
    raise exc
  File "/media/tspl26/D/raju_python/mobility_env/lib/python3.7/site-packages/rest_framework/views.py", line 506, in dispatch
    response = handler(request, *args, **kwargs)
  File "/media/tspl26/D/raju_python/mobility_env/mobilitysqr_live/mobility_apps/vault/views.py", line 168, in patch
    serializer.save()
  File "/media/tspl26/D/raju_python/mobility_env/lib/python3.7/site-packages/rest_framework/serializers.py", line 205, in save
    self.instance = self.create(validated_data)
  File "/media/tspl26/D/raju_python/mobility_env/lib/python3.7/site-packages/rest_framework/serializers.py", line 939, in create
    instance = ModelClass._default_manager.create(**validated_data)
  File "/media/tspl26/D/raju_python/mobility_env/lib/python3.7/site-packages/django/db/models/manager.py", line 82, in manager_method
    return getattr(self.get_queryset(), name)(*args, **kwargs)
  File "/media/tspl26/D/raju_python/mobility_env/lib/python3.7/site-packages/django/db/models/query.py", line 413, in create
    obj.save(force_insert=True, using=self.db)
  File "/media/tspl26/D/raju_python/mobility_env/lib/python3.7/site-packages/django/db/models/base.py", line 718, in save
    force_update=force_update, update_fields=update_fields)
  File "/media/tspl26/D/raju_python/mobility_env/lib/python3.7/site-packages/django/db/models/base.py", line 748, in save_base
    updated = self._save_table(raw, cls, force_insert, force_update, using, update_fields)
  File "/media/tspl26/D/raju_python/mobility_env/lib/python3.7/site-packages/django/db/models/base.py", line 831, in _save_table
    result = self._do_insert(cls._base_manager, using, fields, update_pk, raw)
  File "/media/tspl26/D/raju_python/mobility_env/lib/python3.7/site-packages/django/db/models/base.py", line 869, in _do_insert
    using=using, raw=raw)
  File "/media/tspl26/D/raju_python/mobility_env/lib/python3.7/site-packages/django/db/models/manager.py", line 82, in manager_method
    return getattr(self.get_queryset(), name)(*args, **kwargs)
  File "/media/tspl26/D/raju_python/mobility_env/lib/python3.7/site-packages/django/db/models/query.py", line 1136, in _insert
    return query.get_compiler(using=using).execute_sql(return_id)
  File "/media/tspl26/D/raju_python/mobility_env/lib/python3.7/site-packages/django/db/models/sql/compiler.py", line 1322, in execute_sql
    cursor.execute(sql, params)
  File "/media/tspl26/D/raju_python/mobility_env/lib/python3.7/site-packages/django/db/backends/utils.py", line 100, in execute
    return super().execute(sql, params)
  File "/media/tspl26/D/raju_python/mobility_env/lib/python3.7/site-packages/django/db/backends/utils.py", line 68, in execute
    return self._execute_with_wrappers(sql, params, many=False, executor=self._execute)
  File "/media/tspl26/D/raju_python/mobility_env/lib/python3.7/site-packages/django/db/backends/utils.py", line 77, in _execute_with_wrappers
    return executor(sql, params, many, context)
  File "/media/tspl26/D/raju_python/mobility_env/lib/python3.7/site-packages/django/db/backends/utils.py", line 85, in _execute
    return self.cursor.execute(sql, params)
  File "/media/tspl26/D/raju_python/mobility_env/lib/python3.7/site-packages/django/db/utils.py", line 89, in __exit__
    raise dj_exc_value.with_traceback(traceback) from exc_value
  File "/media/tspl26/D/raju_python/mobility_env/lib/python3.7/site-packages/django/db/backends/utils.py", line 85, in _execute
    return self.cursor.execute(sql, params)
  File "/media/tspl26/D/raju_python/mobility_env/lib/python3.7/site-packages/sql_server/pyodbc/base.py", line 546, in execute
    return self.cursor.execute(sql, params)
django.db.utils.IntegrityError: ('23000', '[23000] [Microsoft][ODBC Driver 17 for SQL Server][SQL Server]The INSERT statement conflicted with the FOREIGN KEY constraint "vault_vault_type_info_emp_code_id_a059f613_fk_employee_employee_emp_code". The conflict occurred in database "mob_test", table "dbo.employee_employee", column \'emp_code\'. (547) (SQLExecDirectW)')
INFO|19/Mar/2021 17:35:18|basehttp|21941|140384439584512|"PATCH /update_delete_vault_document/1/ HTTP/1.1" 200 364
INFO|19/Mar/2021 17:42:10|basehttp|22203|140030043477760|"PATCH /update_delete_vault_document/1/ HTTP/1.1" 200 364
INFO|19/Mar/2021 17:42:26|basehttp|22203|140030043477760|"PATCH /update_delete_vault_document/1/ HTTP/1.1" 200 353
INFO|19/Mar/2021 17:42:46|basehttp|22203|140030043477760|"PATCH /update_delete_vault_document/1/ HTTP/1.1" 200 362
INFO|19/Mar/2021 17:43:03|basehttp|22203|140030043477760|"PATCH /update_delete_vault_document/1/ HTTP/1.1" 200 362
INFO|19/Mar/2021 17:43:42|basehttp|22203|140030043477760|"PATCH /update_delete_vault_document/1/ HTTP/1.1" 200 361
INFO|19/Mar/2021 17:44:13|basehttp|22203|140030043477760|"DELETE /update_delete_vault_document/1/ HTTP/1.1" 204 0
INFO|19/Mar/2021 17:44:32|basehttp|22203|140030043477760|"GET /get_post_vault_document/?emp_code=Tspl1045&vault_type=VA5 HTTP/1.1" 200 367
INFO|19/Mar/2021 17:44:50|basehttp|22203|140030043477760|"GET /get_post_vault_document/?emp_code=Tspl1045&vault_type=VA3 HTTP/1.1" 200 685
INFO|19/Mar/2021 17:46:40|basehttp|22336|139807653840640|"DELETE /update_delete_vault_document/4/ HTTP/1.1" 200 35
INFO|19/Mar/2021 17:46:53|basehttp|22336|139807653840640|"GET /get_post_vault_document/?emp_code=Tspl1045&vault_type=VA3 HTTP/1.1" 200 366
WARNING|19/Mar/2021 18:37:08|log|22413|139758286132992|Unauthorized: /update_delete_vault_document/1/
WARNING|19/Mar/2021 18:37:08|basehttp|22413|139758286132992|"PATCH /update_delete_vault_document/1/ HTTP/1.1" 401 51
